Workbook

Sheet Sheet2
B5: OB Name
A6: 1 | B6: Salman Butt
A7: 2 | B7: Qasim Khan
A8: 3 | B8: Mobeen Ahmad
A9: 4 | B9: Zahid Rafique
A10: 5 | B10: Zeeshan Meharban
A11: 6 | B11: Furqan
A12: 7 | B12: Rana Bilal Tso
A13: 8 | B13: Shakoor
A14: 9
A15: 10
A16: 11
A17: 12
A18: 13

Sheet Cust. Price List
V2: 0.18
A4: S# | B4: Code | D4: SKU | E4: SKUs Description | F4: Unit | H4: Retail Price | J4: TP Incl. | L4: TP Excl. | N4: Dist Margin | P4: Trade Offre | R4: Stale | T4: Ex-Fac | V4: S.Tax | X4: Dist. Price
B5: Bar | C5: SKU | F5: Gm | G5: CTN | H5: Ctn | I5: Pk | J5: Ctn | K5: Pk | L5: Ctn | M5: Pk | N5: 0.19 | O5: Amount | P5: 0.04 | Q5: Amount | R5: 0.005 | S5: Amount | T5: Ctn | U5: Pk | V5: Ctn | W5: Pk | X5: Ctn | Y5: Pk | AA5: Weight/ctn
A6: 1 | C6: BCN | D6: BCN | E6: Meat Masala | F6: 70 | G6: 40 | H6: =I6*G6 -> 2600 | I6: 65 | J6: =K6*G6 -> 2560.17 | K6: =M6*1.22 -> 64.00425 | L6: 2098.5 | M6: =L6/G6 -> 52.4625 | N6: 0.19 | O6: =N6*M6 -> 9.967875 | Q6: =P6*M6 -> 0 | S6: =R6*M6 -> 0 | T6: =U6*G6 -> 1699.785 | U6: =M6-O6-Q6-S6 -> 42.494625 | V6: =T6*$V$2 -> 305.9613 | W6: =U6*$V$2 -> 7.6490325 | X6: =T6+V6 -> 2005.7463 | Y6: =U6+W6 -> 50.143657 | AA6: =(F6*G6)/1000 -> 2.8
A7: =+A6+1 -> 2 | C7: VTN | D7: VTN | E7: Lemon Tarka | F7: 70 | G7: 40 | H7: =I7*G7 -> 2600 | I7: 65 | J7: =K7*G7 -> 2560.17 | K7: =M7*1.22 -> 64.00425 | L7: 2098.5 | M7: =L7/G7 -> 52.4625 | N7: =+N6 -> 0.19 | O7: =N7*M7 -> 9.967875 | Q7: =P7*M7 -> 0 | S7: =R7*M7 -> 0 | T7: =U7*G7 -> 1699.785 | U7: =M7-O7-Q7-S7 -> 42.494625 | V7: =T7*$V$2 -> 305.9613 | W7: =U7*$V$2 -> 7.6490325 | X7: =T7+V7 -> 2005.7463 | Y7: =U7+W7 -> 50.143657 | AA7: =(F7*G7)/1000 -> 2.8
A8: =+A7+1 -> 3 | C8: CCN | D8: CCN | E8: Chicken Chatkhara | F8: 70 | G8: 40 | H8: =I8*G8 -> 2600 | I8: 65 | J8: =K8*G8 -> 2560.17 | K8: =M8*1.22 -> 64.00425 | L8: 2098.5 | M8: =L8/G8 -> 52.4625 | N8: =+N7 -> 0.19 | O8: =N8*M8 -> 9.967875 | Q8: =P8*M8 -> 0 | S8: =R8*M8 -> 0 | T8: =U8*G8 -> 1699.785 | U8: =M8-O8-Q8-S8 -> 42.494625 | V8: =T8*$V$2 -> 305.9613 | W8: =U8*$V$2 -> 7.6490325 | X8: =T8+V8 -> 2005.7463 | Y8: =U8+W8 -> 50.143657 | AA8: =(F8*G8)/1000 -> 2.8
A9: =+A8+1 -> 4 | C9: BCNJ | D9: BCNJ | E9: Meat Masala (Jumbo) | F9: 120 | G9: 40 | H9: =I9*G9 -> 3600 | I9: 90 | J9: =K9*G9 -> 3544.832 | K9: =M9*1.22 -> 88.6208 | L9: 2905.6 | M9: =L9/G9 -> 72.64 | N9: =+N8 -> 0.19 | O9: =N9*M9 -> 13.8016 | Q9: =P9*M9 -> 0 | S9: =R9*M9 -> 0 | T9: =U9*G9 -> 2353.536 | U9: =M9-O9-Q9-S9 -> 58.8384 | V9: =T9*$V$2 -> 423.63648 | W9: =U9*$V$2 -> 10.590912 | X9: =T9+V9 -> 2777.1725 | Y9: =U9+W9 -> 69.429312 | AA9: =(F9*G9)/1000 -> 4.8
A10: =+A9+1 -> 5 | C10: VTNJ | D10: VTNJ | E10: Lemon Tarka (Jumbo) | F10: 120 | G10: 40 | H10: =I10*G10 -> 3600 | I10: 90 | J10: =K10*G10 -> 3544.832 | K10: =M10*1.22 -> 88.6208 | L10: 2905.6 | M10: =L10/G10 -> 72.64 | N10: =+N9 -> 0.19 | O10: =N10*M10 -> 13.8016 | Q10: =P10*M10 -> 0 | S10: =R10*M10 -> 0 | T10: =U10*G10 -> 2353.536 | U10: =M10-O10-Q10-S10 -> 58.8384 | V10: =T10*$V$2 -> 423.63648 | W10: =U10*$V$2 -> 10.590912 | X10: =T10+V10 -> 2777.1725 | Y10: =U10+W10 -> 69.429312 | AA10: =(F10*G10)/1000 -> 4.8
A11: =+A10+1 -> 6 | C11: CCNJ | D11: CCNJ | E11: Chicken Chatkhara (Jumbo) | F11: 120 | G11: 40 | H11: =I11*G11 -> 3600 | I11: 90 | J11: =K11*G11 -> 3544.832 | K11: =M11*1.22 -> 88.6208 | L11: 2905.6 | M11: =L11/G11 -> 72.64 | N11: =+N10 -> 0.19 | O11: =N11*M11 -> 13.8016 | Q11: =P11*M11 -> 0 | S11: =R11*M11 -> 0 | T11: =U11*G11 -> 2353.536 | U11: =M11-O11-Q11-S11 -> 58.8384 | V11: =T11*$V$2 -> 423.63648 | W11: =U11*$V$2 -> 10.590912 | X11: =T11+V11 -> 2777.1725 | Y11: =U11+W11 -> 69.429312 | AA11: =(F11*G11)/1000 -> 4.8
A12: =+A11+1 -> 7 | C12: CCE | D12: CCE | E12: Chicken Chatkhara (ECO) | F12: 60 | G12: 40 | H12: =I12*G12 -> 2000 | I12: 50 | J12: =K12*G12 -> 1914.424 | K12: =M12*1.22 -> 47.8606 | L12: 1569.2 | M12: =L12/G12 -> 39.23 | N12: =+N11 -> 0.19 | O12: =N12*M12 -> 7.4537 | Q12: =P12*M12 -> 0 | S12: =R12*M12 -> 0 | T12: =U12*G12 -> 1271.052 | U12: =M12-O12-Q12-S12 -> 31.7763 | V12: =T12*$V$2 -> 228.78936 | W12: =U12*$V$2 -> 5.719734 | X12: =T12+V12 -> 1499.8414 | Y12: =U12+W12 -> 37.496034 | AA12: =(F12*G12)/1000 -> 2.4
A13: =+A12+1 -> 8 | C13: VTE | D13: VTE | E13: Lemon Tarka (ECO) | F13: 60 | G13: 40 | H13: =I13*G13 -> 2000 | I13: 50 | J13: =K13*G13 -> 1914.424 | K13: =M13*1.22 -> 47.8606 | L13: 1569.2 | M13: =L13/G13 -> 39.23 | N13: =+N12 -> 0.19 | O13: =N13*M13 -> 7.4537 | Q13: =P13*M13 -> 0 | S13: =R13*M13 -> 0 | T13: =U13*G13 -> 1271.052 | U13: =M13-O13-Q13-S13 -> 31.7763 | V13: =T13*$V$2 -> 228.78936 | W13: =U13*$V$2 -> 5.719734 | X13: =T13+V13 -> 1499.8414 | Y13: =U13+W13 -> 37.496034 | AA13: =(F13*G13)/1000 -> 2.4
A14: =+A13+1 -> 9 | C14: BCE | D14: BCE | E14: Meat Masala (ECO) | F14: 60 | G14: 40 | H14: =I14*G14 -> 2000 | I14: 50 | J14: =K14*G14 -> 1914.424 | K14: =M14*1.22 -> 47.8606 | L14: 1569.2 | M14: =L14/G14 -> 39.23 | N14: =+N13 -> 0.19 | O14: =N14*M14 -> 7.4537 | Q14: =P14*M14 -> 0 | S14: =R14*M14 -> 0 | T14: =U14*G14 -> 1271.052 | U14: =M14-O14-Q14-S14 -> 31.7763 | V14: =T14*$V$2 -> 228.78936 | W14: =U14*$V$2 -> 5.719734 | X14: =T14+V14 -> 1499.8414 | Y14: =U14+W14 -> 37.496034 | AA14: =(F14*G14)/1000 -> 2.4
A15: =+A14+1 -> 10
A16: =+A15+1 -> 11
A17: =+A16+1 -> 12
A18: =+A17+1 -> 13
A19: =+A18+1 -> 14
A20: =+A19+1 -> 15
A22: =+A20+1 -> 16
A23: =+A22+1 -> 17
A24: =+A23+1 -> 18
A25: =+A24+1 -> 19
A26: =+A25+1 -> 20
A27: =+A26+1 -> 21
A28: =+A27+1 -> 22
A29: =+A28+1 -> 23
A30: =+A29+1 -> 24
A31: =+A30+1 -> 25
A32: =+A31+1 -> 26
A33: =+A32+1 -> 27
A34: =+A33+1 -> 28
A36: =+A34+1 -> 29
A37: =+A36+1 -> 30
A38: =+A37+1 -> 31
A39: =+A38+1 -> 32
A40: =+A39+1 -> 33
A41: =+A40+1 -> 34
A42: =+A41+1 -> 35
A43: =+A42+1 -> 36
A44: =+A43+1 -> 37
...

Sheet Format
A2: Elite MARKETING
A3: 44A- Gulberg Lahore | K3: Invoice No # : | N3: 1 | XFC3: Filer | XFD3: 0.005
A4: STRN / NTN :3808207-1 | K4: Date/Day : | N4: =TODAY() -> 46177 | XFC4: Non-filer | XFD4: 0.025
A5: Salman Butt | K5: Order Date : | N5: =N4-1 -> 46176
K6: Order Name : | N6: Salman Aslam | XFC6: Registered | XFD6: 0.18
XFC7: Un-registered | XFD7: 0.22
XFD9: Yes
K10: Invoice Status : | N10: Serviced | XFD10: No
K11: Order at Original Location : | N11: Yes
K12: Reference Invoice : | T12: Shop Bill Summary (Mobeen Ahmad) | XFD12: Monday/Tuesday
L13: 0.05 | XFD13: Tuesday / Wednesday
A14: Product Code/Description | C14: GM/ Pack | D14: CTN | E14: R.P Per | F14: T.P Per | G14: Sale QTY | I14: Gross Amount Excl. Taxes | J14: Trade Offer & Discount | M14: After Discount Amount | N14: GST | O14: Adv. Tax 236H | P14: Invoice | T14: =+express!A5 -> Customer Name : Express Store | U14: =+express!P35 -> 2390.3321 | XFD14: Wednesday/Thursday
D15: SIZE | E15: Unit | F15: Unit | G15: CTN | H15: Pack | J15: FOC Qty | K15: Trade Offer | L15: Pass On | N15: =IF(B12="Registered",18%,22%) -> 0.22 | O15: =IF(B11="Filer",0.5%,2.5%) -> 0.025 | P15: Amount | T15: =+'askari cash and carry'!A5 -> Customer Name : Askari Cash & Carry | U15: =+'askari cash and carry'!P35 -> 3309.6731 | XFD15: Thursday /Friday
A16: BCN | B16: =VLOOKUP($A16,'[1]Cust. Price List'!$D$6:$O$14,2,0) -> Meat Masala | C16: =VLOOKUP(A16,'[1]Cust. Price List'!D6:M14,3,0) -> 70 | D16: =VLOOKUP(A16,'[1]Cust. Price List'!D6:M14,4,0) -> 40 | E16: =VLOOKUP(A16,'[1]Cust. Price List'!D6:M14,6,0) -> 65 | F16: =VLOOKUP(A16,'[1]Cust. Price List'!D6:M14,10,0) -> 52.4625 | G16: =H16/40 -> 1.75 | H16: =+express!H16+'askari cash and carry'!H16+'Al-Makkah '!H16+sanwal!H16+'quality store'!H16+haider!H16+'six brother'!H16+'ali genera'!H16+'noor husain'!H16+'M ali super'!H16+'new kashmeer'!H16+'5 start'!H16 -> 70 | I16: =(G16*D16)*F16+H16*F16 -> 7344.75 | J16: =+express!J16+'askari cash and carry'!J16+'Al-Makkah '!J16+sanwal!J16+'quality store'!J16+haider!J16+'six brother'!J16+'ali genera'!J16+'noor husain'!J16+'M ali super'!J16+'new kashmeer'!J16+'5 start'!J16 -> 7 | K16: =+express!K16+'askari cash and carry'!K16+'Al-Makkah '!K16+sanwal!K16+'quality store'!K16+haider!K16+'six brother'!K16+'ali genera'!K16+'noor husain'!K16+'M ali super'!K16 -> 0 | L16: =+express!L16+'askari cash and carry'!L16+'Al-Makkah '!L16+sanwal!L16+'quality store'!L16+haider!L16+'six brother'!L16+'ali genera'!L16+'noor husain'!L16+'M ali super'!L16 -> 579.186 | M16: =I16-K16-L16 -> 6765.564 | N16: =+express!N16+'askari cash and carry'!N16+'Al-Makkah '!N16+sanwal!N16+'quality store'!N16+haider!N16+'six brother'!N16+'ali genera'!N16+'noor husain'!N16+'M ali super'!N16 -> 1453.1693 | O16: =+express!O16+'askari cash and carry'!O16+'Al-Makkah '!O16+sanwal!O16+'quality store'!O16+haider!O16+'six brother'!O16+'ali genera'!O16+'noor husain'!O16+'M ali super'!O16 -> 123.92986 | P16: =M16+N16+O16 -> 8342.6631 | T16: =+'Al-Makkah '!A5 -> Customer Name : Al-Makkah Cash & Carry | U16: =+'Al-Makkah '!P35 -> 6925.5096 | XFD16: Friday / Saturday
A17: VTN | B17: =VLOOKUP($A17,'[1]Cust. Price List'!$D$6:$O$14,2,0) -> Lemon Tarka | C17: =VLOOKUP(B17,'[1]Cust. Price List'!E7:P15,2,0) -> 70 | D17: =VLOOKUP(A17,'[1]Cust. Price List'!D7:M15,4,0) -> 40 | E17: =VLOOKUP(A17,'[1]Cust. Price List'!D7:M15,6,0) -> 65 | F17: =VLOOKUP(A17,'[1]Cust. Price List'!D7:M15,10,0) -> 52.4625 | G17: =H17/40 -> 0.725 | H17: =+express!H17+'askari cash and carry'!H17+'Al-Makkah '!H17+sanwal!H17+'quality store'!H17+haider!H17+'six brother'!H17+'ali genera'!H17+'noor husain'!H17+'M ali super'!H17+'new kashmeer'!H17+'5 start'!H17 -> 29 | I17: =(G17*D17)*F17+H17*F17 -> 3042.825 | J17: =+express!J17+'askari cash and carry'!J17+'Al-Makkah '!J17+sanwal!J17+'quality store'!J17+haider!J17+'six brother'!J17+'ali genera'!J17+'noor husain'!J17+'M ali super'!J17+'new kashmeer'!J17+'5 start'!J17 -> 9 | K17: =+express!K17+'askari cash and carry'!K17+'Al-Makkah '!K17+sanwal!K17+'quality store'!K17+haider!K17+'six brother'!K17+'ali genera'!K17+'noor husain'!K17+'M ali super'!K17 -> 0 | L17: =+express!L17+'askari cash and carry'!L17+'Al-Makkah '!L17+sanwal!L17+'quality store'!L17+haider!L17+'six brother'!L17+'ali genera'!L17+'noor husain'!L17+'M ali super'!L17 -> 407.109 | M17: =I17-K17-L17 -> 2635.716 | N17: =+express!N17+'askari cash and carry'!N17+'Al-Makkah '!N17+sanwal!N17+'quality store'!N17+haider!N17+'six brother'!N17+'ali genera'!N17+'noor husain'!N17+'M ali super'!N17 -> 1040.898 | O17: =+express!O17+'askari cash and carry'!O17+'Al-Makkah '!O17+sanwal!O17+'quality store'!O17+haider!O17+'six brother'!O17+'ali genera'!O17+'noor husain'!O17+'M ali super'!O17 -> 76.182055 | P17: =M17+N17+O17 -> 3752.796 | T17: =+sanwal!A5 -> Customer Name : Sanwal | U17: =+sanwal!P35 -> 1238.2769 | XFD17: Saturday /Monday
A18: CCN | B18: =VLOOKUP($A18,'[1]Cust. Price List'!$D$6:$O$14,2,0) -> Chicken Chatkhara | C18: =VLOOKUP(B18,'[1]Cust. Price List'!E8:P16,2,0) -> 70 | D18: =VLOOKUP(A18,'[1]Cust. Price List'!D8:M16,4,0) -> 40 | E18: =VLOOKUP(A18,'[1]Cust. Price List'!D8:M16,6,0) -> 65 | F18: =VLOOKUP(A18,'[1]Cust. Price List'!D8:M16,10,0) -> 52.4625 | G18: =H18/40 -> 2.325 | H18: =+express!H18+'askari cash and carry'!H18+'Al-Makkah '!H18+sanwal!H18+'quality store'!H18+haider!H18+'six brother'!H18+'ali genera'!H18+'noor husain'!H18+'M ali super'!H18+'new kashmeer'!H18+'5 start'!H18 -> 93 | I18: =(G18*D18)*F18+H18*F18 -> 9758.025 | J18: =+express!J18+'askari cash and carry'!J18+'Al-Makkah '!J18+sanwal!J18+'quality store'!J18+haider!J18+'six brother'!J18+'ali genera'!J18+'noor husain'!J18+'M ali super'!J18+'new kashmeer'!J18+'5 start'!J18 -> 5 | K18: =+express!K18+'askari cash and carry'!K18+'Al-Makkah '!K18+sanwal!K18+'quality store'!K18+haider!K18+'six brother'!K18+'ali genera'!K18+'noor husain'!K18+'M ali super'!K18 -> 0 | L18: =+express!L18+'askari cash and carry'!L18+'Al-Makkah '!L18+sanwal!L18+'quality store'!L18+haider!L18+'six brother'!L18+'ali genera'!L18+'noor husain'!L18+'M ali super'!L18 -> 658.929 | M18: =I18-K18-L18 -> 9099.096 | N18: =+express!N18+'askari cash and carry'!N18+'Al-Makkah '!N18+sanwal!N18+'quality store'!N18+haider!N18+'six brother'!N18+'ali genera'!N18+'noor husain'!N18+'M ali super'!N18 -> 1643.3773 | O18: =+express!O18+'askari cash and carry'!O18+'Al-Makkah '!O18+sanwal!O18+'quality store'!O18+haider!O18+'six brother'!O18+'ali genera'!O18+'noor husain'!O18+'M ali super'!O18 -> 129.23528 | P18: =M18+N18+O18 -> 10871.709 | T18: =+'quality store'!A5 -> Customer Name : Quality Store | U18: =+'quality store'!P35 -> 1218.9504
A19: BCNJ | B19: =VLOOKUP($A19,'[1]Cust. Price List'!$D$6:$O$14,2,0) -> Meat Masala (Jumbo) | C19: =VLOOKUP(B19,'[1]Cust. Price List'!E9:P17,2,0) -> 120 | D19: =VLOOKUP(A19,'[1]Cust. Price List'!D9:M17,4,0) -> 40 | E19: =VLOOKUP(A19,'[1]Cust. Price List'!D9:M17,6,0) -> 90 | F19: =VLOOKUP(A19,'[1]Cust. Price List'!D9:M17,10,0) -> 72.64 | G19: =H19/40 -> 1.275 | H19: =+express!H19+'askari cash and carry'!H19+'Al-Makkah '!H19+sanwal!H19+'quality store'!H19+haider!H19+'six brother'!H19+'ali genera'!H19+'noor husain'!H19+'M ali super'!H19+'new kashmeer'!H19+'5 start'!H19 -> 51 | I19: =(G19*D19)*F19+H19*F19 -> 7409.28 | J19: =+express!J19+'askari cash and carry'!J19+'Al-Makkah '!J19+sanwal!J19+'quality store'!J19+haider!J19+'six brother'!J19+'ali genera'!J19+'noor husain'!J19+'M ali super'!J19+'new kashmeer'!J19+'5 start'!J19 -> 3 | K19: =+express!K19+'askari cash and carry'!K19+'Al-Makkah '!K19+sanwal!K19+'quality store'!K19+haider!K19+'six brother'!K19+'ali genera'!K19+'noor husain'!K19+'M ali super'!K19 -> 0 | L19: =+express!L19+'askari cash and carry'!L19+'Al-Makkah '!L19+sanwal!L19+'quality store'!L19+haider!L19+'six brother'!L19+'ali genera'!L19+'noor husain'!L19+'M ali super'!L19 -> 87.168 | M19: =I19-K19-L19 -> 7322.112 | N19: =+express!N19+'askari cash and carry'!N19+'Al-Makkah '!N19+sanwal!N19+'quality store'!N19+haider!N19+'six brother'!N19+'ali genera'!N19+'noor husain'!N19+'M ali super'!N19 -> 220.53504 | O19: =+express!O19+'askari cash and carry'!O19+'Al-Makkah '!O19+sanwal!O19+'quality store'!O19+haider!O19+'six brother'!O19+'ali genera'!O19+'noor husain'!O19+'M ali super'!O19 -> 6.1148352 | P19: =M19+N19+O19 -> 7548.7619 | T19: =+haider!A5 -> Customer Name : Haider Store | U19: =+haider!P35 -> 538.64712
A20: VTNJ | B20: =VLOOKUP($A20,'[1]Cust. Price List'!$D$6:$O$14,2,0) -> Lemon Tarka (Jumbo) | C20: =VLOOKUP(B20,'[1]Cust. Price List'!E10:P18,2,0) -> 120 | D20: =VLOOKUP(A20,'[1]Cust. Price List'!D10:M18,4,0) -> 40 | E20: =VLOOKUP(A20,'[1]Cust. Price List'!D10:M18,6,0) -> 90 | F20: =VLOOKUP(A20,'[1]Cust. Price List'!D10:M18,10,0) -> 72.64 | G20: =H20/40 -> 1.075 | H20: =+express!H20+'askari cash and carry'!H20+'Al-Makkah '!H20+sanwal!H20+'quality store'!H20+haider!H20+'six brother'!H20+'ali genera'!H20+'noor husain'!H20+'M ali super'!H20+'new kashmeer'!H20+'5 start'!H20 -> 43 | I20: =(G20*D20)*F20+H20*F20 -> 6247.04 | J20: =+express!J20+'askari cash and carry'!J20+'Al-Makkah '!J20+sanwal!J20+'quality store'!J20+haider!J20+'six brother'!J20+'ali genera'!J20+'noor husain'!J20+'M ali super'!J20+'new kashmeer'!J20+'5 start'!J20 -> 4 | K20: =+express!K20+'askari cash and carry'!K20+'Al-Makkah '!K20+sanwal!K20+'quality store'!K20+haider!K20+'six brother'!K20+'ali genera'!K20+'noor husain'!K20+'M ali super'!K20 -> 0 | L20: =+express!L20+'askari cash and carry'!L20+'Al-Makkah '!L20+sanwal!L20+'quality store'!L20+haider!L20+'six brother'!L20+'ali genera'!L20+'noor husain'!L20+'M ali super'!L20 -> 87.168 | M20: =I20-K20-L20 -> 6159.872 | N20: =+express!N20+'askari cash and carry'!N20+'Al-Makkah '!N20+sanwal!N20+'quality store'!N20+haider!N20+'six brother'!N20+'ali genera'!N20+'noor husain'!N20+'M ali super'!N20 -> 268.47744 | O20: =+express!O20+'askari cash and carry'!O20+'Al-Makkah '!O20+sanwal!O20+'quality store'!O20+haider!O20+'six brother'!O20+'ali genera'!O20+'noor husain'!O20+'M ali super'!O20 -> 6.3545472 | P20: =M20+N20+O20 -> 6434.704 | T20: =+'six brother'!A5 -> Customer Name : Six Brother Mart | U20: =+'six brother'!P35 -> 3290.1167
A21: CCNJ | B21: =VLOOKUP($A21,'[1]Cust. Price List'!$D$6:$O$14,2,0) -> Chicken Chatkhara (Jumbo) | C21: =VLOOKUP(B21,'[1]Cust. Price List'!E11:P19,2,0) -> 120 | D21: =VLOOKUP(A21,'[1]Cust. Price List'!D11:M19,4,0) -> 40 | E21: =VLOOKUP(A21,'[1]Cust. Price List'!D11:M19,6,0) -> 90 | F21: =VLOOKUP(A21,'[1]Cust. Price List'!D11:M19,10,0) -> 72.64 | G21: =H21/40 -> 1.15 | H21: =+express!H21+'askari cash and carry'!H21+'Al-Makkah '!H21+sanwal!H21+'quality store'!H21+haider!H21+'six brother'!H21+'ali genera'!H21+'noor husain'!H21+'M ali super'!H21+'new kashmeer'!H21+'5 start'!H21 -> 46 | I21: =(G21*D21)*F21+H21*F21 -> 6682.88 | J21: =+express!J21+'askari cash and carry'!J21+'Al-Makkah '!J21+sanwal!J21+'quality store'!J21+haider!J21+'six brother'!J21+'ali genera'!J21+'noor husain'!J21+'M ali super'!J21+'new kashmeer'!J21+'5 start'!J21 -> 0 | K21: =+express!K21+'askari cash and carry'!K21+'Al-Makkah '!K21+sanwal!K21+'quality store'!K21+haider!K21+'six brother'!K21+'ali genera'!K21+'noor husain'!K21+'M ali super'!K21 -> 0 | L21: =+express!L21+'askari cash and carry'!L21+'Al-Makkah '!L21+sanwal!L21+'quality store'!L21+haider!L21+'six brother'!L21+'ali genera'!L21+'noor husain'!L21+'M ali super'!L21 -> 174.336 | M21: =I21-K21-L21 -> 6508.544 | N21: =+express!N21+'askari cash and carry'!N21+'Al-Makkah '!N21+sanwal!N21+'quality store'!N21+haider!N21+'six brother'!N21+'ali genera'!N21+'noor husain'!N21+'M ali super'!N21 -> 441.07008 | O21: =+express!O21+'askari cash and carry'!O21+'Al-Makkah '!O21+sanwal!O21+'quality store'!O21+haider!O21+'six brother'!O21+'ali genera'!O21+'noor husain'!O21+'M ali super'!O21 -> 12.22967 | P21: =M21+N21+O21 -> 6961.8438 | T21: =+'ali genera'!A5 -> Customer Name : Ali General Store | U21: =+'ali genera'!P35 -> 2437.9009
A22: CCE | B22: =VLOOKUP($A22,'[1]Cust. Price List'!$D$6:$O$14,2,0) -> Chicken Chatkhara (ECO) | C22: =VLOOKUP(B22,'[1]Cust. Price List'!E12:P20,2,0) -> 60 | D22: =VLOOKUP(A22,'[1]Cust. Price List'!D12:M20,4,0) -> 40 | E22: =VLOOKUP(A22,'[1]Cust. Price List'!D12:M20,6,0) -> 50 | F22: =VLOOKUP(A22,'[1]Cust. Price List'!D12:M20,10,0) -> 39.23 | G22: =H22/40 -> 0.975 | H22: =+express!H22+'askari cash and carry'!H22+'Al-Makkah '!H22+sanwal!H22+'quality store'!H22+haider!H22+'six brother'!H22+'ali genera'!H22+'noor husain'!H22+'M ali super'!H22+'new kashmeer'!H22+'5 start'!H22 -> 39 | I22: =(G22*D22)*F22+H22*F22 -> 3059.94 | J22: =+express!J22+'askari cash and carry'!J22+'Al-Makkah '!J22+sanwal!J22+'quality store'!J22+haider!J22+'six brother'!J22+'ali genera'!J22+'noor husain'!J22+'M ali super'!J22+'new kashmeer'!J22+'5 start'!J22 -> 0 | K22: =+express!K22+'askari cash and carry'!K22+'Al-Makkah '!K22+sanwal!K22+'quality store'!K22+haider!K22+'six brother'!K22+'ali genera'!K22+'noor husain'!K22+'M ali super'!K22 -> 53.54895 | L22: =+express!L22+'askari cash and carry'!L22+'Al-Makkah '!L22+sanwal!L22+'quality store'!L22+haider!L22+'six brother'!L22+'ali genera'!L22+'noor husain'!L22+'M ali super'!L22 -> 76.4985 | M22: =I22-K22-L22 -> 2929.8926 | N22: =+express!N22+'askari cash and carry'!N22+'Al-Makkah '!N22+sanwal!N22+'quality store'!N22+haider!N22+'six brother'!N22+'ali genera'!N22+'noor husain'!N22+'M ali super'!N22 -> 307.98296 | O22: =+express!O22+'askari cash and carry'!O22+'Al-Makkah '!O22+sanwal!O22+'quality store'!O22+haider!O22+'six brother'!O22+'ali genera'!O22+'noor husain'!O22+'M ali super'!O22 -> 19.049715 | P22: =M22+N22+O22 -> 3256.9252 | T22: =+'noor husain'!A5 -> Customer Name : Noor Husain GS | U22: =+'noor husain'!P35 -> 1415.2231
A23: VTE | B23: =VLOOKUP($A23,'[1]Cust. Price List'!$D$6:$O$14,2,0) -> Lemon Tarka (ECO) | C23: =VLOOKUP(B23,'[1]Cust. Price List'!E13:P21,2,0) -> 60 | D23: =VLOOKUP(A23,'[1]Cust. Price List'!D13:M21,4,0) -> 40 | E23: =VLOOKUP(A23,'[1]Cust. Price List'!D13:M21,6,0) -> 50 | F23: =VLOOKUP(A23,'[1]Cust. Price List'!D13:M21,10,0) -> 39.23 | G23: =H23/40 -> 0 | H23: =+express!H23+'askari cash and carry'!H23+'Al-Makkah '!H23+sanwal!H23+'quality store'!H23+haider!H23+'six brother'!H23+'ali genera'!H23+'noor husain'!H23+'M ali super'!H23+'new kashmeer'!H23+'5 start'!H23 -> 0 | I23: =(G23*D23)*F23+H23*F23 -> 0 | J23: =+express!J23+'askari cash and carry'!J23+'Al-Makkah '!J23+sanwal!J23+'quality store'!J23+haider!J23+'six brother'!J23+'ali genera'!J23+'noor husain'!J23+'M ali super'!J23+'new kashmeer'!J23+'5 start'!J23 -> 0 | K23: =+express!K23+'askari cash and carry'!K23+'Al-Makkah '!K23+sanwal!K23+'quality store'!K23+haider!K23+'six brother'!K23+'ali genera'!K23+'noor husain'!K23+'M ali super'!K23 -> 0 | L23: =+express!L23+'askari cash and carry'!L23+'Al-Makkah '!L23+sanwal!L23+'quality store'!L23+haider!L23+'six brother'!L23+'ali genera'!L23+'noor husain'!L23+'M ali super'!L23 -> 0 | M23: =I23-K23-L23 -> 0 | N23: =+express!N23+'askari cash and carry'!N23+'Al-Makkah '!N23+sanwal!N23+'quality store'!N23+haider!N23+'six brother'!N23+'ali genera'!N23+'noor husain'!N23+'M ali super'!N23 -> 0 | O23: =+express!O23+'askari cash and carry'!O23+'Al-Makkah '!O23+sanwal!O23+'quality store'!O23+haider!O23+'six brother'!O23+'ali genera'!O23+'noor husain'!O23+'M ali super'!O23 -> 0 | P23: =M23+N23+O23 -> 0 | T23: =+'M ali super'!A5 -> Customer Name : MA Super Store | U23: =+'M ali super'!P35 -> 7313.7027
A24: BCE | B24: =VLOOKUP($A24,'[1]Cust. Price List'!$D$6:$O$14,2,0) -> Meat Masala (ECO) | C24: =VLOOKUP(B24,'[1]Cust. Price List'!E14:P22,2,0) -> 60 | D24: =VLOOKUP(A24,'[1]Cust. Price List'!D14:M22,4,0) -> 40 | E24: =VLOOKUP(A24,'[1]Cust. Price List'!D14:M22,6,0) -> 50 | F24: =VLOOKUP(A24,'[1]Cust. Price List'!D14:M22,10,0) -> 39.23 | G24: =H24/40 -> 0 | H24: =+express!H24+'askari cash and carry'!H24+'Al-Makkah '!H24+sanwal!H24+'quality store'!H24+haider!H24+'six brother'!H24+'ali genera'!H24+'noor husain'!H24+'M ali super'!H24+'new kashmeer'!H24+'5 start'!H24 -> 0 | I24: =(G24*D24)*F24+H24*F24 -> 0 | J24: =+express!J24+'askari cash and carry'!J24+'Al-Makkah '!J24+sanwal!J24+'quality store'!J24+haider!J24+'six brother'!J24+'ali genera'!J24+'noor husain'!J24+'M ali super'!J24+'new kashmeer'!J24+'5 start'!J24 -> 0 | K24: =+express!K24+'askari cash and carry'!K24+'Al-Makkah '!K24+sanwal!K24+'quality store'!K24+haider!K24+'six brother'!K24+'ali genera'!K24+'noor husain'!K24+'M ali super'!K24 -> 0 | L24: =+express!L24+'askari cash and carry'!L24+'Al-Makkah '!L24+sanwal!L24+'quality store'!L24+haider!L24+'six brother'!L24+'ali genera'!L24+'noor husain'!L24+'M ali super'!L24 -> 0 | M24: =I24-K24-L24 -> 0 | N24: =+express!N24+'askari cash and carry'!N24+'Al-Makkah '!N24+sanwal!N24+'quality store'!N24+haider!N24+'six brother'!N24+'ali genera'!N24+'noor husain'!N24+'M ali super'!N24 -> 0 | O24: =+express!O24+'askari cash and carry'!O24+'Al-Makkah '!O24+sanwal!O24+'quality store'!O24+haider!O24+'six brother'!O24+'ali genera'!O24+'noor husain'!O24+'M ali super'!O24 -> 0 | P24: =M24+N24+O24 -> 0 | T24: =+'new kashmeer'!A5 -> Customer Name : New Kashmeer Bakery | U24: =+'new kashmeer'!P35 -> 5700.0052
A25: Total | G25: =SUM(G16:G24) -> 9.275 | H25: =SUM(H16:H24) -> 371 | I25: =SUM(I16:I24) -> 43544.74 | J25: =SUM(J16:J24) -> 28 | K25: =SUM(K16:K24) -> 53.54895 | L25: =SUM(L16:L24) -> 2070.3945 | M25: =SUM(M16:M24) -> 41420.797 | N25: =SUM(N16:N24) -> 5375.5101 | ... P25: =SUM(P16:P24) -> 47169.403 | T25: =+'5 start'!A5 -> Customer Name : Five Start GS | U25: =+'5 start'!P35 -> 5171.0276
T26: Total | U26: =SUM(U14:U25) -> 40949.365
B28: یکم جولائی 2024سے نئی ٹیکس ترمیم کے مطابق، ایف بی آر سیکشن 236 ایچ کے مطابق، فائلرز کے لیے ہر سیل انوائس پر 0.5% اور نان فائلرز کے لیے 2.5% ایڈوانس ود ہولڈنگ ٹیکس وصول کیا جائے گا۔ | N28: Gross Amount: | P28: =I25 -> 43544.74
N29: Regular Discount | P29: =L25 -> 2070.3945
N30: Trade Offre | P30: =K25 -> 53.54895
N31: After Dis. Amount | P31: =P28-P29-P30 -> 41420.797
N32: Total GST: | O32: =IF(B12="Registered",18%,22%) -> 0.22 | P32: =N25 -> 5375.5101
N33: Net Amount: | P33: =P31+P32 -> 46796.307
N34: Ad.Tax | O34: =IF(B11="Filer",0.5%,2.5%) -> 0.025 | P34: =O34*P33 -> 1169.9077
N35: Net Amount with Ad.Tax | P35: =P33+P34 -> 47966.214
B36: Delivered By

Sheet express
A2: Elite MARKETING
A3: 44A- Gulberg Lahore | K3: Invoice No # : | N3: 1 | XFC3: Filer | XFD3: 0.005
A4: STRN / NTN :3808207-1 | K4: Date/Day : | N4: =TODAY() -> 46177 | XFC4: Non-filer | XFD4: 0.025
A5: Customer Name : Express Store | K5: Order Date : | N5: =N4-1 -> 46176
A6: Address: Askari 5 | K6: Order Name : | N6: Salman Butt | XFC6: Registered | XFD6: 0.18
XFC7: Un-registered | XFD7: 0.22
XFD9: Yes
A10: NTN/CNIC Number: | B10: 3520123465409 | K10: Invoice Status : | N10: Serviced | XFD10: No
B11: Filer | C11: =IF($O34>2.49%,"No","Yes") -> Yes | K11: Order at Original Location : | N11: Yes
A12: STRN Number: | B12: Un-registered | C12: =IF($O32>21.99%,"No","Yes") -> No | K12: Reference Invoice : | XFD12: Monday/Tuesday
L13: 0.05 | XFD13: Tuesday / Wednesday
A14: Product Code/Description | C14: GM/ Pack | D14: CTN | E14: R.P Per | F14: T.P Per | G14: Sale QTY | I14: Gross Amount Excl. Taxes | J14: Trade Offer & Discount | M14: After Discount Amount | N14: GST | O14: Adv. Tax 236H | P14: Invoice | XFD14: Wednesday/Thursday
D15: SIZE | E15: Unit | F15: Unit | G15: CTN | H15: Pack | J15: FOC Qty | K15: Trade Offer | L15: Pass On | N15: =IF(B12="Registered",18%,22%) -> 0.22 | O15: =IF(B11="Filer",0.5%,2.5%) -> 0.005 | P15: Amount | XFD15: Thursday /Friday
A16: BCN | B16: =VLOOKUP($A16,'[1]Cust. Price List'!$D$6:$O$14,2,0) -> Meat Masala | C16: =VLOOKUP(A16,'[1]Cust. Price List'!D6:M14,3,0) -> 70 | D16: =VLOOKUP(A16,'[1]Cust. Price List'!D6:M14,4,0) -> 40 | E16: =VLOOKUP(A16,'[1]Cust. Price List'!D6:M14,6,0) -> 65 | F16: =VLOOKUP(A16,'[1]Cust. Price List'!D6:M14,10,0) -> 52.4625 | H16: 10 | I16: =(G16*D16)*F16+H16*F16 -> 524.625 | K16: =I16*$K$13 -> 0 | L16: =I16*8% -> 41.97 | M16: =I16-K16-L16 -> 482.655 | N16: =(M16*$N$15)+(J16*F16)*$N$15 -> 106.1841 | O16: =(N16+M16)*$O$15 -> 2.9441955 | P16: =M16+N16+O16 -> 591.7833 | XFD16: Friday / Saturday
A17: VTN | B17: =VLOOKUP($A17,'[1]Cust. Price List'!$D$6:$O$14,2,0) -> Lemon Tarka | C17: =VLOOKUP(B17,'[1]Cust. Price List'!E7:P15,2,0) -> 70 | D17: =VLOOKUP(A17,'[1]Cust. Price List'!D7:M15,4,0) -> 40 | E17: =VLOOKUP(A17,'[1]Cust. Price List'!D7:M15,6,0) -> 65 | F17: =VLOOKUP(A17,'[1]Cust. Price List'!D7:M15,10,0) -> 52.4625 | H17: 10 | I17: =(G17*D17)*F17+H17*F17 -> 524.625 | J17: 2 | K17: =I17*$K$13 -> 0 | L17: =I17*8% -> 41.97 | M17: =I17-K17-L17 -> 482.655 | N17: =(M17*$N$15)+(J17*F17)*$N$15 -> 129.2676 | O17: =(N17+M17)*$O$15 -> 3.059613 | P17: =M17+N17+O17 -> 614.98221 | XFD17: Saturday /Monday
A18: CCN | B18: =VLOOKUP($A18,'[1]Cust. Price List'!$D$6:$O$14,2,0) -> Chicken Chatkhara | C18: =VLOOKUP(B18,'[1]Cust. Price List'!E8:P16,2,0) -> 70 | D18: =VLOOKUP(A18,'[1]Cust. Price List'!D8:M16,4,0) -> 40 | E18: =VLOOKUP(A18,'[1]Cust. Price List'!D8:M16,6,0) -> 65 | F18: =VLOOKUP(A18,'[1]Cust. Price List'!D8:M16,10,0) -> 52.4625 | H18: 20 | I18: =(G18*D18)*F18+H18*F18 -> 1049.25 | K18: =I18*$K$13 -> 0 | L18: =I18*8% -> 83.94 | M18: =I18-K18-L18 -> 965.31 | N18: =(M18*$N$15)+(J18*F18)*$N$15 -> 212.3682 | O18: =(N18+M18)*$O$15 -> 5.888391 | P18: =M18+N18+O18 -> 1183.5666
A19: BCNJ | B19: =VLOOKUP($A19,'[1]Cust. Price List'!$D$6:$O$14,2,0) -> Meat Masala (Jumbo) | C19: =VLOOKUP(B19,'[1]Cust. Price List'!E9:P17,2,0) -> 120 | D19: =VLOOKUP(A19,'[1]Cust. Price List'!D9:M17,4,0) -> 40 | E19: =VLOOKUP(A19,'[1]Cust. Price List'!D9:M17,6,0) -> 90 | F19: =VLOOKUP(A19,'[1]Cust. Price List'!D9:M17,10,0) -> 72.64 | I19: =(G19*D19)*F19+H19*F19 -> 0 | K19: =I19*$K$13 -> 0 | L19: =I19*8% -> 0 | M19: =I19-K19-L19 -> 0 | N19: =(M19*$N$15)+(J19*F19)*$N$15 -> 0 | O19: =(N19+M19)*$O$15 -> 0 | P19: =M19+N19+O19 -> 0
A20: VTNJ | B20: =VLOOKUP($A20,'[1]Cust. Price List'!$D$6:$O$14,2,0) -> Lemon Tarka (Jumbo) | C20: =VLOOKUP(B20,'[1]Cust. Price List'!E10:P18,2,0) -> 120 | D20: =VLOOKUP(A20,'[1]Cust. Price List'!D10:M18,4,0) -> 40 | E20: =VLOOKUP(A20,'[1]Cust. Price List'!D10:M18,6,0) -> 90 | F20: =VLOOKUP(A20,'[1]Cust. Price List'!D10:M18,10,0) -> 72.64 | I20: =(G20*D20)*F20+H20*F20 -> 0 | K20: =I20*$K$13 -> 0 | L20: =I20*8% -> 0 | M20: =I20-K20-L20 -> 0 | N20: =(M20*$N$15)+(J20*F20)*$N$15 -> 0 | O20: =(N20+M20)*$O$15 -> 0 | P20: =M20+N20+O20 -> 0
A21: CCNJ | B21: =VLOOKUP($A21,'[1]Cust. Price List'!$D$6:$O$14,2,0) -> Chicken Chatkhara (Jumbo) | C21: =VLOOKUP(B21,'[1]Cust. Price List'!E11:P19,2,0) -> 120 | D21: =VLOOKUP(A21,'[1]Cust. Price List'!D11:M19,4,0) -> 40 | E21: =VLOOKUP(A21,'[1]Cust. Price List'!D11:M19,6,0) -> 90 | F21: =VLOOKUP(A21,'[1]Cust. Price List'!D11:M19,10,0) -> 72.64 | I21: =(G21*D21)*F21+H21*F21 -> 0 | K21: =I21*$K$13 -> 0 | L21: =I21*8% -> 0 | M21: =I21-K21-L21 -> 0 | N21: =(M21*$N$15)+(J21*F21)*$N$15 -> 0 | O21: =(N21+M21)*$O$15 -> 0 | P21: =M21+N21+O21 -> 0
A22: CCE | B22: =VLOOKUP($A22,'[1]Cust. Price List'!$D$6:$O$14,2,0) -> Chicken Chatkhara (ECO) | C22: =VLOOKUP(B22,'[1]Cust. Price List'!E12:P20,2,0) -> 60 | D22: =VLOOKUP(A22,'[1]Cust. Price List'!D12:M20,4,0) -> 40 | E22: =VLOOKUP(A22,'[1]Cust. Price List'!D12:M20,6,0) -> 50 | F22: =VLOOKUP(A22,'[1]Cust. Price List'!D12:M20,10,0) -> 39.23 | I22: =(G22*D22)*F22+H22*F22 -> 0 | K22: =I22*3.5% -> 0 | L22: =I22*5% -> 0 | M22: =I22-K22-L22 -> 0 | N22: =(M22*$N$15)+(J22*F22)*$N$15 -> 0 | O22: =(N22+M22)*$O$15 -> 0 | P22: =M22+N22+O22 -> 0
A23: VTE | B23: =VLOOKUP($A23,'[1]Cust. Price List'!$D$6:$O$14,2,0) -> Lemon Tarka (ECO) | C23: =VLOOKUP(B23,'[1]Cust. Price List'!E13:P21,2,0) -> 60 | D23: =VLOOKUP(A23,'[1]Cust. Price List'!D13:M21,4,0) -> 40 | E23: =VLOOKUP(A23,'[1]Cust. Price List'!D13:M21,6,0) -> 50 | F23: =VLOOKUP(A23,'[1]Cust. Price List'!D13:M21,10,0) -> 39.23 | I23: =(G23*D23)*F23+H23*F23 -> 0 | K23: =I23*3.5% -> 0 | L23: =I23*$L$13 -> 0 | M23: =I23-K23-L23 -> 0 | N23: =(M23*$N$15)+(J23*F23)*$N$15 -> 0 | O23: =(N23+M23)*$O$15 -> 0 | P23: =M23+N23+O23 -> 0
A24: BCE | B24: =VLOOKUP($A24,'[1]Cust. Price List'!$D$6:$O$14,2,0) -> Meat Masala (ECO) | C24: =VLOOKUP(B24,'[1]Cust. Price List'!E14:P22,2,0) -> 60 | D24: =VLOOKUP(A24,'[1]Cust. Price List'!D14:M22,4,0) -> 40 | E24: =VLOOKUP(A24,'[1]Cust. Price List'!D14:M22,6,0) -> 50 | F24: =VLOOKUP(A24,'[1]Cust. Price List'!D14:M22,10,0) -> 39.23 | I24: =(G24*D24)*F24+H24*F24 -> 0 | K24: =I24*3.5% -> 0 | L24: =I24*$L$13 -> 0 | M24: =I24-K24-L24 -> 0 | N24: =(M24*$N$15)+(J24*F24)*$N$15 -> 0 | O24: =(N24+M24)*$O$15 -> 0 | P24: =M24+N24+O24 -> 0
A25: Total | G25: =SUM(G16:G24) -> 0 | H25: =SUM(H16:H24) -> 40 | I25: =SUM(I16:I24) -> 2098.5 | K25: =SUM(K16:K24) -> 0 | L25: =SUM(L16:L24) -> 167.88 | M25: =SUM(M16:M24) -> 1930.62 | N25: =SUM(N16:N24) -> 447.8199 | O25: =SUM(O16:O24) -> 11.8922 | P25: =SUM(P16:P24) -> 2390.3321
B28: یکم جولائی 2024سے نئی ٹیکس ترمیم کے مطابق، ایف بی آر سیکشن 236 ایچ کے مطابق، فائلرز کے لیے ہر سیل انوائس پر 0.5% اور نان فائلرز کے لیے 2.5% ایڈوانس ود ہولڈنگ ٹیکس وصول کیا جائے گا۔ | N28: Gross Amount: | P28: =I25 -> 2098.5
N29: Regular Discount | P29: =L25 -> 167.88
N30: Trade Offre | P30: =K25 -> 0
N31: After Dis. Amount | P31: =P28-P29-P30 -> 1930.62
N32: Total GST: | O32: =IF(B12="Registered",18%,22%) -> 0.22 | P32: =N25 -> 447.8199
N33: Net Amount: | P33: =P31+P32 -> 2378.4399
N34: Ad.Tax | O34: =IF(B11="Filer",0.5%,2.5%) -> 0.005 | P34: =O34*P33 -> 11.8922
N35: Net Amount with Ad.Tax | P35: =P33+P34 -> 2390.3321
B36: Delivered By

Sheet askari cash and carry
A2: Elite MARKETING
A3: 44A- Gulberg Lahore | K3: Invoice No # : | N3: 2 | XFC3: Filer | XFD3: 0.005
A4: STRN / NTN :3808207-1 | K4: Date/Day : | N4: =TODAY() -> 46177 | XFC4: Non-filer | XFD4: 0.025
A5: Customer Name : Askari Cash & Carry | K5: Order Date : | N5: =N4-1 -> 46176
A6: Address: Askari 5 | K6: Order Name : | N6: Salman Butt | XFC6: Registered | XFD6: 0.18
XFC7: Un-registered | XFD7: 0.22
XFD9: Yes
A10: NTN/CNIC Number: | B10: 41197127 | K10: Invoice Status : | N10: Serviced | XFD10: No
B11: Filer | C11: =IF($O34>2.49%,"No","Yes") -> Yes | K11: Order at Original Location : | N11: Yes
A12: STRN Number: | B12: Un-registered | C12: =IF($O32>21.99%,"No","Yes") -> No | K12: Reference Invoice : | XFD12: Monday/Tuesday
L13: 0.05 | XFD13: Tuesday / Wednesday
A14: Product Code/Description | C14: GM/ Pack | D14: CTN | E14: R.P Per | F14: T.P Per | G14: Sale QTY | I14: Gross Amount Excl. Taxes | J14: Trade Offer & Discount | M14: After Discount Amount | N14: GST | O14: Adv. Tax 236H | P14: Invoice | XFD14: Wednesday/Thursday
D15: SIZE | E15: Unit | F15: Unit | G15: CTN | H15: Pack | J15: FOC Qty | K15: Trade Offer | L15: Pass On | N15: =IF(B12="Registered",18%,22%) -> 0.22 | O15: =IF(B11="Filer",0.5%,2.5%) -> 0.005 | P15: Amount | XFD15: Thursday /Friday
A16: BCN | B16: =VLOOKUP($A16,'[1]Cust. Price List'!$D$6:$O$14,2,0) -> Meat Masala | C16: =VLOOKUP(A16,'[1]Cust. Price List'!D6:M14,3,0) -> 70 | D16: =VLOOKUP(A16,'[1]Cust. Price List'!D6:M14,4,0) -> 40 | E16: =VLOOKUP(A16,'[1]Cust. Price List'!D6:M14,6,0) -> 65 | F16: =VLOOKUP(A16,'[1]Cust. Price List'!D6:M14,10,0) -> 52.4625 | I16: =(G16*D16)*F16+H16*F16 -> 0 | K16: =I16*$K$13 -> 0 | L16: =I16*8% -> 0 | M16: =I16-K16-L16 -> 0 | N16: =(M16*$N$15)+(J16*F16)*$N$15 -> 0 | O16: =(N16+M16)*$O$15 -> 0 | P16: =M16+N16+O16 -> 0 | XFD16: Friday / Saturday
A17: VTN | B17: =VLOOKUP($A17,'[1]Cust. Price List'!$D$6:$O$14,2,0) -> Lemon Tarka | C17: =VLOOKUP(B17,'[1]Cust. Price List'!E7:P15,2,0) -> 70 | D17: =VLOOKUP(A17,'[1]Cust. Price List'!D7:M15,4,0) -> 40 | E17: =VLOOKUP(A17,'[1]Cust. Price List'!D7:M15,6,0) -> 65 | F17: =VLOOKUP(A17,'[1]Cust. Price List'!D7:M15,10,0) -> 52.4625 | I17: =(G17*D17)*F17+H17*F17 -> 0 | K17: =I17*$K$13 -> 0 | L17: =I17*8% -> 0 | M17: =I17-K17-L17 -> 0 | N17: =(M17*$N$15)+(J17*F17)*$N$15 -> 0 | O17: =(N17+M17)*$O$15 -> 0 | P17: =M17+N17+O17 -> 0 | XFD17: Saturday /Monday
A18: CCN | B18: =VLOOKUP($A18,'[1]Cust. Price List'!$D$6:$O$14,2,0) -> Chicken Chatkhara | C18: =VLOOKUP(B18,'[1]Cust. Price List'!E8:P16,2,0) -> 70 | D18: =VLOOKUP(A18,'[1]Cust. Price List'!D8:M16,4,0) -> 40 | E18: =VLOOKUP(A18,'[1]Cust. Price List'!D8:M16,6,0) -> 65 | F18: =VLOOKUP(A18,'[1]Cust. Price List'!D8:M16,10,0) -> 52.4625 | I18: =(G18*D18)*F18+H18*F18 -> 0 | K18: =I18*$K$13 -> 0 | L18: =I18*8% -> 0 | M18: =I18-K18-L18 -> 0 | N18: =(M18*$N$15)+(J18*F18)*$N$15 -> 0 | O18: =(N18+M18)*$O$15 -> 0 | P18: =M18+N18+O18 -> 0
A19: BCNJ | B19: =VLOOKUP($A19,'[1]Cust. Price List'!$D$6:$O$14,2,0) -> Meat Masala (Jumbo) | C19: =VLOOKUP(B19,'[1]Cust. Price List'!E9:P17,2,0) -> 120 | D19: =VLOOKUP(A19,'[1]Cust. Price List'!D9:M17,4,0) -> 40 | E19: =VLOOKUP(A19,'[1]Cust. Price List'!D9:M17,6,0) -> 90 | F19: =VLOOKUP(A19,'[1]Cust. Price List'!D9:M17,10,0) -> 72.64 | H19: 10 | I19: =(G19*D19)*F19+H19*F19 -> 726.4 | K19: =I19*$K$13 -> 0 | L19: =I19*8% -> 58.112 | M19: =I19-K19-L19 -> 668.288 | N19: =(M19*$N$15)+(J19*F19)*$N$15 -> 147.02336 | O19: =(N19+M19)*$O$15 -> 4.0765568 | P19: =M19+N19+O19 -> 819.38792
A20: VTNJ | B20: =VLOOKUP($A20,'[1]Cust. Price List'!$D$6:$O$14,2,0) -> Lemon Tarka (Jumbo) | C20: =VLOOKUP(B20,'[1]Cust. Price List'!E10:P18,2,0) -> 120 | D20: =VLOOKUP(A20,'[1]Cust. Price List'!D10:M18,4,0) -> 40 | E20: =VLOOKUP(A20,'[1]Cust. Price List'!D10:M18,6,0) -> 90 | F20: =VLOOKUP(A20,'[1]Cust. Price List'!D10:M18,10,0) -> 72.64 | H20: 10 | I20: =(G20*D20)*F20+H20*F20 -> 726.4 | J20: 2 | K20: =I20*$K$13 -> 0 | L20: =I20*8% -> 58.112 | M20: =I20-K20-L20 -> 668.288 | N20: =(M20*$N$15)+(J20*F20)*$N$15 -> 178.98496 | O20: =(N20+M20)*$O$15 -> 4.2363648 | P20: =M20+N20+O20 -> 851.50932
A21: CCNJ | B21: =VLOOKUP($A21,'[1]Cust. Price List'!$D$6:$O$14,2,0) -> Chicken Chatkhara (Jumbo) | C21: =VLOOKUP(B21,'[1]Cust. Price List'!E11:P19,2,0) -> 120 | D21: =VLOOKUP(A21,'[1]Cust. Price List'!D11:M19,4,0) -> 40 | E21: =VLOOKUP(A21,'[1]Cust. Price List'!D11:M19,6,0) -> 90 | F21: =VLOOKUP(A21,'[1]Cust. Price List'!D11:M19,10,0) -> 72.64 | H21: 20 | I21: =(G21*D21)*F21+H21*F21 -> 1452.8 | K21: =I21*$K$13 -> 0 | L21: =I21*8% -> 116.224 | M21: =I21-K21-L21 -> 1336.576 | N21: =(M21*$N$15)+(J21*F21)*$N$15 -> 294.04672 | O21: =(N21+M21)*$O$15 -> 8.1531136 | P21: =M21+N21+O21 -> 1638.7758
A22: CCE | B22: =VLOOKUP($A22,'[1]Cust. Price List'!$D$6:$O$14,2,0) -> Chicken Chatkhara (ECO) | C22: =VLOOKUP(B22,'[1]Cust. Price List'!E12:P20,2,0) -> 60 | D22: =VLOOKUP(A22,'[1]Cust. Price List'!D12:M20,4,0) -> 40 | E22: =VLOOKUP(A22,'[1]Cust. Price List'!D12:M20,6,0) -> 50 | F22: =VLOOKUP(A22,'[1]Cust. Price List'!D12:M20,10,0) -> 39.23 | I22: =(G22*D22)*F22+H22*F22 -> 0 | K22: =I22*3.5% -> 0 | L22: =I22*5% -> 0 | M22: =I22-K22-L22 -> 0 | N22: =(M22*$N$15)+(J22*F22)*$N$15 -> 0 | O22: =(N22+M22)*$O$15 -> 0 | P22: =M22+N22+O22 -> 0
A23: VTE | B23: =VLOOKUP($A23,'[1]Cust. Price List'!$D$6:$O$14,2,0) -> Lemon Tarka (ECO) | C23: =VLOOKUP(B23,'[1]Cust. Price List'!E13:P21,2,0) -> 60 | D23: =VLOOKUP(A23,'[1]Cust. Price List'!D13:M21,4,0) -> 40 | E23: =VLOOKUP(A23,'[1]Cust. Price List'!D13:M21,6,0) -> 50 | F23: =VLOOKUP(A23,'[1]Cust. Price List'!D13:M21,10,0) -> 39.23 | I23: =(G23*D23)*F23+H23*F23 -> 0 | K23: =I23*3.5% -> 0 | L23: =I23*$L$13 -> 0 | M23: =I23-K23-L23 -> 0 | N23: =(M23*$N$15)+(J23*F23)*$N$15 -> 0 | O23: =(N23+M23)*$O$15 -> 0 | P23: =M23+N23+O23 -> 0
A24: BCE | B24: =VLOOKUP($A24,'[1]Cust. Price List'!$D$6:$O$14,2,0) -> Meat Masala (ECO) | C24: =VLOOKUP(B24,'[1]Cust. Price List'!E14:P22,2,0) -> 60 | D24: =VLOOKUP(A24,'[1]Cust. Price List'!D14:M22,4,0) -> 40 | E24: =VLOOKUP(A24,'[1]Cust. Price List'!D14:M22,6,0) -> 50 | F24: =VLOOKUP(A24,'[1]Cust. Price List'!D14:M22,10,0) -> 39.23 | I24: =(G24*D24)*F24+H24*F24 -> 0 | K24: =I24*3.5% -> 0 | L24: =I24*$L$13 -> 0 | M24: =I24-K24-L24 -> 0 | N24: =(M24*$N$15)+(J24*F24)*$N$15 -> 0 | O24: =(N24+M24)*$O$15 -> 0 | P24: =M24+N24+O24 -> 0
A25: Total | G25: =SUM(G16:G24) -> 0 | H25: =SUM(H16:H24) -> 40 | I25: =SUM(I16:I24) -> 2905.6 | K25: =SUM(K16:K24) -> 0 | L25: =SUM(L16:L24) -> 232.448 | M25: =SUM(M16:M24) -> 2673.152 | N25: =SUM(N16:N24) -> 620.05504 | O25: =SUM(O16:O24) -> 16.466035 | P25: =SUM(P16:P24) -> 3309.6731
B28: یکم جولائی 2024سے نئی ٹیکس ترمیم کے مطابق، ایف بی آر سیکشن 236 ایچ کے مطابق، فائلرز کے لیے ہر سیل انوائس پر 0.5% اور نان فائلرز کے لیے 2.5% ایڈوانس ود ہولڈنگ ٹیکس وصول کیا جائے گا۔ | N28: Gross Amount: | P28: =I25 -> 2905.6
N29: Regular Discount | P29: =L25 -> 232.448
N30: Trade Offre | P30: =K25 -> 0
N31: After Dis. Amount | P31: =P28-P29-P30 -> 2673.152
N32: Total GST: | O32: =IF(B12="Registered",18%,22%) -> 0.22 | P32: =N25 -> 620.05504
N33: Net Amount: | P33: =P31+P32 -> 3293.207
N34: Ad.Tax | O34: =IF(B11="Filer",0.5%,2.5%) -> 0.005 | P34: =O34*P33 -> 16.466035
N35: Net Amount with Ad.Tax | P35: =P33+P34 -> 3309.6731
B36: Delivered By

Sheet sanwal
A2: Elite MARKETING
A3: 44A- Gulberg Lahore | K3: Invoice No # : | N3: 4 | XFC3: Filer | XFD3: 0.005
A4: STRN / NTN :3808207-1 | K4: Date/Day : | N4: =TODAY() -> 46177 | XFC4: Non-filer | XFD4: 0.025
A5: Customer Name : Sanwal | K5: Order Date : | N5: =N4-1 -> 46176
A6: Address: Askari 5 | K6: Order Name : | N6: Salman Butt | XFC6: Registered | XFD6: 0.18
XFC7: Un-registered | XFD7: 0.22
XFD9: Yes
A10: NTN/CNIC Number: | B10: 3530232820806 | K10: Invoice Status : | N10: Serviced | XFD10: No
B11: Filer | C11: =IF($O34>2.49%,"No","Yes") -> Yes | K11: Order at Original Location : | N11: Yes
A12: STRN Number: | B12: Un-registered | C12: =IF($O32>21.99%,"No","Yes") -> No | K12: Reference Invoice : | XFD12: Monday/Tuesday
L13: 0.05 | XFD13: Tuesday / Wednesday
A14: Product Code/Description | C14: GM/ Pack | D14: CTN | E14: R.P Per | F14: T.P Per | G14: Sale QTY | I14: Gross Amount Excl. Taxes | J14: Trade Offer & Discount | M14: After Discount Amount | N14: GST | O14: Adv. Tax 236H | P14: Invoice | XFD14: Wednesday/Thursday
D15: SIZE | E15: Unit | F15: Unit | G15: CTN | H15: Pack | J15: FOC Qty | K15: Trade Offer | L15: Pass On | N15: =IF(B12="Registered",18%,22%) -> 0.22 | O15: =IF(B11="Filer",0.5%,2.5%) -> 0.005 | P15: Amount | XFD15: Thursday /Friday
A16: BCN | B16: =VLOOKUP($A16,'[1]Cust. Price List'!$D$6:$O$14,2,0) -> Meat Masala | C16: =VLOOKUP(A16,'[1]Cust. Price List'!D6:M14,3,0) -> 70 | D16: =VLOOKUP(A16,'[1]Cust. Price List'!D6:M14,4,0) -> 40 | E16: =VLOOKUP(A16,'[1]Cust. Price List'!D6:M14,6,0) -> 65 | F16: =VLOOKUP(A16,'[1]Cust. Price List'!D6:M14,10,0) -> 52.4625 | I16: =(G16*D16)*F16+H16*F16 -> 0 | K16: =I16*$K$13 -> 0 | L16: =I16*8% -> 0 | M16: =I16-K16-L16 -> 0 | N16: =(M16*$N$15)+(J16*F16)*$N$15 -> 0 | O16: =(N16+M16)*$O$15 -> 0 | P16: =M16+N16+O16 -> 0 | XFD16: Friday / Saturday
A17: VTN | B17: =VLOOKUP($A17,'[1]Cust. Price List'!$D$6:$O$14,2,0) -> Lemon Tarka | C17: =VLOOKUP(B17,'[1]Cust. Price List'!E7:P15,2,0) -> 70 | D17: =VLOOKUP(A17,'[1]Cust. Price List'!D7:M15,4,0) -> 40 | E17: =VLOOKUP(A17,'[1]Cust. Price List'!D7:M15,6,0) -> 65 | F17: =VLOOKUP(A17,'[1]Cust. Price List'!D7:M15,10,0) -> 52.4625 | I17: =(G17*D17)*F17+H17*F17 -> 0 | K17: =I17*$K$13 -> 0 | L17: =I17*8% -> 0 | M17: =I17-K17-L17 -> 0 | N17: =(M17*$N$15)+(J17*F17)*$N$15 -> 0 | O17: =(N17+M17)*$O$15 -> 0 | P17: =M17+N17+O17 -> 0 | XFD17: Saturday /Monday
A18: CCN | B18: =VLOOKUP($A18,'[1]Cust. Price List'!$D$6:$O$14,2,0) -> Chicken Chatkhara | C18: =VLOOKUP(B18,'[1]Cust. Price List'!E8:P16,2,0) -> 70 | D18: =VLOOKUP(A18,'[1]Cust. Price List'!D8:M16,4,0) -> 40 | E18: =VLOOKUP(A18,'[1]Cust. Price List'!D8:M16,6,0) -> 65 | F18: =VLOOKUP(A18,'[1]Cust. Price List'!D8:M16,10,0) -> 52.4625 | H18: 12 | I18: =(G18*D18)*F18+H18*F18 -> 629.55 | K18: =I18*$K$13 -> 0 | L18: =I18*8% -> 50.364 | M18: =I18-K18-L18 -> 579.186 | N18: =(M18*$N$15)+(J18*F18)*$N$15 -> 127.42092 | O18: =(N18+M18)*$O$15 -> 3.5330346 | P18: =M18+N18+O18 -> 710.13995
A19: BCNJ | B19: =VLOOKUP($A19,'[1]Cust. Price List'!$D$6:$O$14,2,0) -> Meat Masala (Jumbo) | C19: =VLOOKUP(B19,'[1]Cust. Price List'!E9:P17,2,0) -> 120 | D19: =VLOOKUP(A19,'[1]Cust. Price List'!D9:M17,4,0) -> 40 | E19: =VLOOKUP(A19,'[1]Cust. Price List'!D9:M17,6,0) -> 90 | F19: =VLOOKUP(A19,'[1]Cust. Price List'!D9:M17,10,0) -> 72.64 | I19: =(G19*D19)*F19+H19*F19 -> 0 | K19: =I19*$K$13 -> 0 | L19: =I19*8% -> 0 | M19: =I19-K19-L19 -> 0 | N19: =(M19*$N$15)+(J19*F19)*$N$15 -> 0 | O19: =(N19+M19)*$O$15 -> 0 | P19: =M19+N19+O19 -> 0
A20: VTNJ | B20: =VLOOKUP($A20,'[1]Cust. Price List'!$D$6:$O$14,2,0) -> Lemon Tarka (Jumbo) | C20: =VLOOKUP(B20,'[1]Cust. Price List'!E10:P18,2,0) -> 120 | D20: =VLOOKUP(A20,'[1]Cust. Price List'!D10:M18,4,0) -> 40 | E20: =VLOOKUP(A20,'[1]Cust. Price List'!D10:M18,6,0) -> 90 | F20: =VLOOKUP(A20,'[1]Cust. Price List'!D10:M18,10,0) -> 72.64 | I20: =(G20*D20)*F20+H20*F20 -> 0 | K20: =I20*$K$13 -> 0 | L20: =I20*8% -> 0 | M20: =I20-K20-L20 -> 0 | N20: =(M20*$N$15)+(J20*F20)*$N$15 -> 0 | O20: =(N20+M20)*$O$15 -> 0 | P20: =M20+N20+O20 -> 0
A21: CCNJ | B21: =VLOOKUP($A21,'[1]Cust. Price List'!$D$6:$O$14,2,0) -> Chicken Chatkhara (Jumbo) | C21: =VLOOKUP(B21,'[1]Cust. Price List'!E11:P19,2,0) -> 120 | D21: =VLOOKUP(A21,'[1]Cust. Price List'!D11:M19,4,0) -> 40 | E21: =VLOOKUP(A21,'[1]Cust. Price List'!D11:M19,6,0) -> 90 | F21: =VLOOKUP(A21,'[1]Cust. Price List'!D11:M19,10,0) -> 72.64 | I21: =(G21*D21)*F21+H21*F21 -> 0 | K21: =I21*$K$13 -> 0 | L21: =I21*8% -> 0 | M21: =I21-K21-L21 -> 0 | N21: =(M21*$N$15)+(J21*F21)*$N$15 -> 0 | O21: =(N21+M21)*$O$15 -> 0 | P21: =M21+N21+O21 -> 0
A22: CCE | B22: =VLOOKUP($A22,'[1]Cust. Price List'!$D$6:$O$14,2,0) -> Chicken Chatkhara (ECO) | C22: =VLOOKUP(B22,'[1]Cust. Price List'!E12:P20,2,0) -> 60 | D22: =VLOOKUP(A22,'[1]Cust. Price List'!D12:M20,4,0) -> 40 | E22: =VLOOKUP(A22,'[1]Cust. Price List'!D12:M20,6,0) -> 50 | F22: =VLOOKUP(A22,'[1]Cust. Price List'!D12:M20,10,0) -> 39.23 | H22: 12 | I22: =(G22*D22)*F22+H22*F22 -> 470.76 | K22: =I22*3.5% -> 16.4766 | L22: =I22*5% -> 23.538 | M22: =I22-K22-L22 -> 430.7454 | N22: =(M22*$N$15)+(J22*F22)*$N$15 -> 94.763988 | O22: =(N22+M22)*$O$15 -> 2.6275469 | P22: =M22+N22+O22 -> 528.13693
A23: VTE | B23: =VLOOKUP($A23,'[1]Cust. Price List'!$D$6:$O$14,2,0) -> Lemon Tarka (ECO) | C23: =VLOOKUP(B23,'[1]Cust. Price List'!E13:P21,2,0) -> 60 | D23: =VLOOKUP(A23,'[1]Cust. Price List'!D13:M21,4,0) -> 40 | E23: =VLOOKUP(A23,'[1]Cust. Price List'!D13:M21,6,0) -> 50 | F23: =VLOOKUP(A23,'[1]Cust. Price List'!D13:M21,10,0) -> 39.23 | I23: =(G23*D23)*F23+H23*F23 -> 0 | K23: =I23*3.5% -> 0 | L23: =I23*$L$13 -> 0 | M23: =I23-K23-L23 -> 0 | N23: =(M23*$N$15)+(J23*F23)*$N$15 -> 0 | O23: =(N23+M23)*$O$15 -> 0 | P23: =M23+N23+O23 -> 0
A24: BCE | B24: =VLOOKUP($A24,'[1]Cust. Price List'!$D$6:$O$14,2,0) -> Meat Masala (ECO) | C24: =VLOOKUP(B24,'[1]Cust. Price List'!E14:P22,2,0) -> 60 | D24: =VLOOKUP(A24,'[1]Cust. Price List'!D14:M22,4,0) -> 40 | E24: =VLOOKUP(A24,'[1]Cust. Price List'!D14:M22,6,0) -> 50 | F24: =VLOOKUP(A24,'[1]Cust. Price List'!D14:M22,10,0) -> 39.23 | I24: =(G24*D24)*F24+H24*F24 -> 0 | K24: =I24*3.5% -> 0 | L24: =I24*$L$13 -> 0 | M24: =I24-K24-L24 -> 0 | N24: =(M24*$N$15)+(J24*F24)*$N$15 -> 0 | O24: =(N24+M24)*$O$15 -> 0 | P24: =M24+N24+O24 -> 0
A25: Total | G25: =SUM(G16:G24) -> 0 | H25: =SUM(H16:H24) -> 24 | I25: =SUM(I16:I24) -> 1100.31 | K25: =SUM(K16:K24) -> 16.4766 | L25: =SUM(L16:L24) -> 73.902 | M25: =SUM(M16:M24) -> 1009.9314 | N25: =SUM(N16:N24) -> 222.18491 | O25: =SUM(O16:O24) -> 6.1605815 | P25: =SUM(P16:P24) -> 1238.2769
B28: یکم جولائی 2024سے نئی ٹیکس ترمیم کے مطابق، ایف بی آر سیکشن 236 ایچ کے مطابق، فائلرز کے لیے ہر سیل انوائس پر 0.5% اور نان فائلرز کے لیے 2.5% ایڈوانس ود ہولڈنگ ٹیکس وصول کیا جائے گا۔ | N28: Gross Amount: | P28: =I25 -> 1100.31
N29: Regular Discount | P29: =L25 -> 73.902
N30: Trade Offre | P30: =K25 -> 16.4766
N31: After Dis. Amount | P31: =P28-P29-P30 -> 1009.9314
N32: Total GST: | O32: =IF(B12="Registered",18%,22%) -> 0.22 | P32: =N25 -> 222.18491
N33: Net Amount: | P33: =P31+P32 -> 1232.1163
N34: Ad.Tax | O34: =IF(B11="Filer",0.5%,2.5%) -> 0.005 | P34: =O34*P33 -> 6.1605815
N35: Net Amount with Ad.Tax | P35: =P33+P34 -> 1238.2769
B36: Delivered By

Sheet Al-Makkah 
A2: Elite MARKETING
A3: 44A- Gulberg Lahore | K3: Invoice No # : | N3: 3 | XFC3: Filer | XFD3: 0.005
A4: STRN / NTN :3808207-1 | K4: Date/Day : | N4: =TODAY() -> 46177 | XFC4: Non-filer | XFD4: 0.025
A5: Customer Name : Al-Makkah Cash & Carry | K5: Order Date : | N5: =N4-1 -> 46176
A6: Address: Askari 5 | K6: Order Name : | N6: Salman Butt | XFC6: Registered | XFD6: 0.18
XFC7: Un-registered | XFD7: 0.22
XFD9: Yes
A10: NTN/CNIC Number: | B10: 21364524 | K10: Invoice Status : | N10: Serviced | XFD10: No
B11: Filer | C11: =IF($O34>2.49%,"No","Yes") -> Yes | K11: Order at Original Location : | N11: Yes
A12: STRN Number: | B12: Registered | C12: =IF($O32>21.99%,"No","Yes") -> Yes | K12: Reference Invoice : | XFD12: Monday/Tuesday
L13: 0.05 | XFD13: Tuesday / Wednesday
A14: Product Code/Description | C14: GM/ Pack | D14: CTN | E14: R.P Per | F14: T.P Per | G14: Sale QTY | I14: Gross Amount Excl. Taxes | J14: Trade Offer & Discount | M14: After Discount Amount | N14: GST | O14: Adv. Tax 236H | P14: Invoice | XFD14: Wednesday/Thursday
D15: SIZE | E15: Unit | F15: Unit | G15: CTN | H15: Pack | J15: FOC Qty | K15: Trade Offer | L15: Pass On | N15: =IF(B12="Registered",18%,22%) -> 0.18 | O15: =IF(B11="Filer",0.5%,2.5%) -> 0.005 | P15: Amount | XFD15: Thursday /Friday
A16: BCN | B16: =VLOOKUP($A16,'[1]Cust. Price List'!$D$6:$O$14,2,0) -> Meat Masala | C16: =VLOOKUP(A16,'[1]Cust. Price List'!D6:M14,3,0) -> 70 | D16: =VLOOKUP(A16,'[1]Cust. Price List'!D6:M14,4,0) -> 40 | E16: =VLOOKUP(A16,'[1]Cust. Price List'!D6:M14,6,0) -> 65 | F16: =VLOOKUP(A16,'[1]Cust. Price List'!D6:M14,10,0) -> 52.4625 | G16: 1 | I16: =(G16*D16)*F16+H16*F16 -> 2098.5 | J16: 2 | K16: =I16*$K$13 -> 0 | L16: =I16*8% -> 167.88 | M16: =I16-K16-L16 -> 1930.62 | N16: =(M16*$N$15)+(J16*F16)*$N$15 -> 366.3981 | O16: =(N16+M16)*$O$15 -> 11.48509 | P16: =M16+N16+O16 -> 2308.5032 | XFD16: Friday / Saturday
A17: VTN | B17: =VLOOKUP($A17,'[1]Cust. Price List'!$D$6:$O$14,2,0) -> Lemon Tarka | C17: =VLOOKUP(B17,'[1]Cust. Price List'!E7:P15,2,0) -> 70 | D17: =VLOOKUP(A17,'[1]Cust. Price List'!D7:M15,4,0) -> 40 | E17: =VLOOKUP(A17,'[1]Cust. Price List'!D7:M15,6,0) -> 65 | F17: =VLOOKUP(A17,'[1]Cust. Price List'!D7:M15,10,0) -> 52.4625 | G17: 1 | I17: =(G17*D17)*F17+H17*F17 -> 2098.5 | J17: 2 | K17: =I17*$K$13 -> 0 | L17: =I17*8% -> 167.88 | M17: =I17-K17-L17 -> 1930.62 | N17: =(M17*$N$15)+(J17*F17)*$N$15 -> 366.3981 | O17: =(N17+M17)*$O$15 -> 11.48509 | P17: =M17+N17+O17 -> 2308.5032 | XFD17: Saturday /Monday
A18: CCN | B18: =VLOOKUP($A18,'[1]Cust. Price List'!$D$6:$O$14,2,0) -> Chicken Chatkhara | C18: =VLOOKUP(B18,'[1]Cust. Price List'!E8:P16,2,0) -> 70 | D18: =VLOOKUP(A18,'[1]Cust. Price List'!D8:M16,4,0) -> 40 | E18: =VLOOKUP(A18,'[1]Cust. Price List'!D8:M16,6,0) -> 65 | F18: =VLOOKUP(A18,'[1]Cust. Price List'!D8:M16,10,0) -> 52.4625 | G18: 1 | I18: =(G18*D18)*F18+H18*F18 -> 2098.5 | J18: 2 | K18: =I18*$K$13 -> 0 | L18: =I18*8% -> 167.88 | M18: =I18-K18-L18 -> 1930.62 | N18: =(M18*$N$15)+(J18*F18)*$N$15 -> 366.3981 | O18: =(N18+M18)*$O$15 -> 11.48509 | P18: =M18+N18+O18 -> 2308.5032
A19: BCNJ | B19: =VLOOKUP($A19,'[1]Cust. Price List'!$D$6:$O$14,2,0) -> Meat Masala (Jumbo) | C19: =VLOOKUP(B19,'[1]Cust. Price List'!E9:P17,2,0) -> 120 | D19: =VLOOKUP(A19,'[1]Cust. Price List'!D9:M17,4,0) -> 40 | E19: =VLOOKUP(A19,'[1]Cust. Price List'!D9:M17,6,0) -> 90 | F19: =VLOOKUP(A19,'[1]Cust. Price List'!D9:M17,10,0) -> 72.64 | I19: =(G19*D19)*F19+H19*F19 -> 0 | K19: =I19*$K$13 -> 0 | L19: =I19*8% -> 0 | M19: =I19-K19-L19 -> 0 | N19: =(M19*$N$15)+(J19*F19)*$N$15 -> 0 | O19: =(N19+M19)*$O$15 -> 0 | P19: =M19+N19+O19 -> 0
A20: VTNJ | B20: =VLOOKUP($A20,'[1]Cust. Price List'!$D$6:$O$14,2,0) -> Lemon Tarka (Jumbo) | C20: =VLOOKUP(B20,'[1]Cust. Price List'!E10:P18,2,0) -> 120 | D20: =VLOOKUP(A20,'[1]Cust. Price List'!D10:M18,4,0) -> 40 | E20: =VLOOKUP(A20,'[1]Cust. Price List'!D10:M18,6,0) -> 90 | F20: =VLOOKUP(A20,'[1]Cust. Price List'!D10:M18,10,0) -> 72.64 | I20: =(G20*D20)*F20+H20*F20 -> 0 | K20: =I20*$K$13 -> 0 | L20: =I20*8% -> 0 | M20: =I20-K20-L20 -> 0 | N20: =(M20*$N$15)+(J20*F20)*$N$15 -> 0 | O20: =(N20+M20)*$O$15 -> 0 | P20: =M20+N20+O20 -> 0
A21: CCNJ | B21: =VLOOKUP($A21,'[1]Cust. Price List'!$D$6:$O$14,2,0) -> Chicken Chatkhara (Jumbo) | C21: =VLOOKUP(B21,'[1]Cust. Price List'!E11:P19,2,0) -> 120 | D21: =VLOOKUP(A21,'[1]Cust. Price List'!D11:M19,4,0) -> 40 | E21: =VLOOKUP(A21,'[1]Cust. Price List'!D11:M19,6,0) -> 90 | F21: =VLOOKUP(A21,'[1]Cust. Price List'!D11:M19,10,0) -> 72.64 | I21: =(G21*D21)*F21+H21*F21 -> 0 | K21: =I21*$K$13 -> 0 | L21: =I21*8% -> 0 | M21: =I21-K21-L21 -> 0 | N21: =(M21*$N$15)+(J21*F21)*$N$15 -> 0 | O21: =(N21+M21)*$O$15 -> 0 | P21: =M21+N21+O21 -> 0
A22: CCE | B22: =VLOOKUP($A22,'[1]Cust. Price List'!$D$6:$O$14,2,0) -> Chicken Chatkhara (ECO) | C22: =VLOOKUP(B22,'[1]Cust. Price List'!E12:P20,2,0) -> 60 | D22: =VLOOKUP(A22,'[1]Cust. Price List'!D12:M20,4,0) -> 40 | E22: =VLOOKUP(A22,'[1]Cust. Price List'!D12:M20,6,0) -> 50 | F22: =VLOOKUP(A22,'[1]Cust. Price List'!D12:M20,10,0) -> 39.23 | I22: =(G22*D22)*F22+H22*F22 -> 0 | K22: =I22*3.5% -> 0 | L22: =I22*5% -> 0 | M22: =I22-K22-L22 -> 0 | N22: =(M22*$N$15)+(J22*F22)*$N$15 -> 0 | O22: =(N22+M22)*$O$15 -> 0 | P22: =M22+N22+O22 -> 0
A23: VTE | B23: =VLOOKUP($A23,'[1]Cust. Price List'!$D$6:$O$14,2,0) -> Lemon Tarka (ECO) | C23: =VLOOKUP(B23,'[1]Cust. Price List'!E13:P21,2,0) -> 60 | D23: =VLOOKUP(A23,'[1]Cust. Price List'!D13:M21,4,0) -> 40 | E23: =VLOOKUP(A23,'[1]Cust. Price List'!D13:M21,6,0) -> 50 | F23: =VLOOKUP(A23,'[1]Cust. Price List'!D13:M21,10,0) -> 39.23 | I23: =(G23*D23)*F23+H23*F23 -> 0 | K23: =I23*3.5% -> 0 | L23: =I23*$L$13 -> 0 | M23: =I23-K23-L23 -> 0 | N23: =(M23*$N$15)+(J23*F23)*$N$15 -> 0 | O23: =(N23+M23)*$O$15 -> 0 | P23: =M23+N23+O23 -> 0
A24: BCE | B24: =VLOOKUP($A24,'[1]Cust. Price List'!$D$6:$O$14,2,0) -> Meat Masala (ECO) | C24: =VLOOKUP(B24,'[1]Cust. Price List'!E14:P22,2,0) -> 60 | D24: =VLOOKUP(A24,'[1]Cust. Price List'!D14:M22,4,0) -> 40 | E24: =VLOOKUP(A24,'[1]Cust. Price List'!D14:M22,6,0) -> 50 | F24: =VLOOKUP(A24,'[1]Cust. Price List'!D14:M22,10,0) -> 39.23 | I24: =(G24*D24)*F24+H24*F24 -> 0 | K24: =I24*3.5% -> 0 | L24: =I24*$L$13 -> 0 | M24: =I24-K24-L24 -> 0 | N24: =(M24*$N$15)+(J24*F24)*$N$15 -> 0 | O24: =(N24+M24)*$O$15 -> 0 | P24: =M24+N24+O24 -> 0
A25: Total | G25: =SUM(G16:G24) -> 3 | H25: =SUM(H16:H24) -> 0 | I25: =SUM(I16:I24) -> 6295.5 | K25: =SUM(K16:K24) -> 0 | L25: =SUM(L16:L24) -> 503.64 | M25: =SUM(M16:M24) -> 5791.86 | N25: =SUM(N16:N24) -> 1099.1943 | O25: =SUM(O16:O24) -> 34.455271 | P25: =SUM(P16:P24) -> 6925.5096
B28: یکم جولائی 2024سے نئی ٹیکس ترمیم کے مطابق، ایف بی آر سیکشن 236 ایچ کے مطابق، فائلرز کے لیے ہر سیل انوائس پر 0.5% اور نان فائلرز کے لیے 2.5% ایڈوانس ود ہولڈنگ ٹیکس وصول کیا جائے گا۔ | N28: Gross Amount: | P28: =I25 -> 6295.5
N29: Regular Discount | P29: =L25 -> 503.64
N30: Trade Offre | P30: =K25 -> 0
N31: After Dis. Amount | P31: =P28-P29-P30 -> 5791.86
N32: Total GST: | O32: =IF(B12="Registered",18%,22%) -> 0.18 | P32: =N25 -> 1099.1943
N33: Net Amount: | P33: =P31+P32 -> 6891.0543
N34: Ad.Tax | O34: =IF(B11="Filer",0.5%,2.5%) -> 0.005 | P34: =O34*P33 -> 34.455272
N35: Net Amount with Ad.Tax | P35: =P33+P34 -> 6925.5096
B36: Delivered By

Sheet quality store
A2: Elite MARKETING
A3: 44A- Gulberg Lahore | K3: Invoice No # : | N3: 5 | XFC3: Filer | XFD3: 0.005
A4: STRN / NTN :3808207-1 | K4: Date/Day : | N4: =TODAY() -> 46177 | XFC4: Non-filer | XFD4: 0.025
A5: Customer Name : Quality Store | K5: Order Date : | N5: =N4-1 -> 46176
A6: Address: Askari 5 | K6: Order Name : | N6: Salman Butt | XFC6: Registered | XFD6: 0.18
XFC7: Un-registered | XFD7: 0.22
XFD9: Yes
A10: NTN/CNIC Number: | K10: Invoice Status : | N10: Serviced | XFD10: No
B11: Non-filer | C11: =IF($O34>2.49%,"No","Yes") -> No | K11: Order at Original Location : | N11: Yes
A12: STRN Number: | B12: Un-registered | C12: =IF($O32>21.99%,"No","Yes") -> No | K12: Reference Invoice : | XFD12: Monday/Tuesday
L13: 0.05 | XFD13: Tuesday / Wednesday
A14: Product Code/Description | C14: GM/ Pack | D14: CTN | E14: R.P Per | F14: T.P Per | G14: Sale QTY | I14: Gross Amount Excl. Taxes | J14: Trade Offer & Discount | M14: After Discount Amount | N14: GST | O14: Adv. Tax 236H | P14: Invoice | XFD14: Wednesday/Thursday
D15: SIZE | E15: Unit | F15: Unit | G15: CTN | H15: Pack | J15: FOC Qty | K15: Trade Offer | L15: Pass On | N15: =IF(B12="Registered",18%,22%) -> 0.22 | O15: =IF(B11="Filer",0.5%,2.5%) -> 0.025 | P15: Amount | XFD15: Thursday /Friday
A16: BCN | B16: =VLOOKUP($A16,'[1]Cust. Price List'!$D$6:$O$14,2,0) -> Meat Masala | C16: =VLOOKUP(A16,'[1]Cust. Price List'!D6:M14,3,0) -> 70 | D16: =VLOOKUP(A16,'[1]Cust. Price List'!D6:M14,4,0) -> 40 | E16: =VLOOKUP(A16,'[1]Cust. Price List'!D6:M14,6,0) -> 65 | F16: =VLOOKUP(A16,'[1]Cust. Price List'!D6:M14,10,0) -> 52.4625 | H16: 10 | I16: =(G16*D16)*F16+H16*F16 -> 524.625 | J16: 1 | K16: =I16*$K$13 -> 0 | L16: =I16*8% -> 41.97 | M16: =I16-K16-L16 -> 482.655 | N16: =(M16*$N$15)+(J16*F16)*$N$15 -> 117.72585 | O16: =(N16+M16)*$O$15 -> 15.009521 | P16: =M16+N16+O16 -> 615.39037 | XFD16: Friday / Saturday
A17: VTN | B17: =VLOOKUP($A17,'[1]Cust. Price List'!$D$6:$O$14,2,0) -> Lemon Tarka | C17: =VLOOKUP(B17,'[1]Cust. Price List'!E7:P15,2,0) -> 70 | D17: =VLOOKUP(A17,'[1]Cust. Price List'!D7:M15,4,0) -> 40 | E17: =VLOOKUP(A17,'[1]Cust. Price List'!D7:M15,6,0) -> 65 | F17: =VLOOKUP(A17,'[1]Cust. Price List'!D7:M15,10,0) -> 52.4625 | I17: =(G17*D17)*F17+H17*F17 -> 0 | K17: =I17*$K$13 -> 0 | L17: =I17*8% -> 0 | M17: =I17-K17-L17 -> 0 | N17: =(M17*$N$15)+(J17*F17)*$N$15 -> 0 | O17: =(N17+M17)*$O$15 -> 0 | P17: =M17+N17+O17 -> 0 | XFD17: Saturday /Monday
A18: CCN | B18: =VLOOKUP($A18,'[1]Cust. Price List'!$D$6:$O$14,2,0) -> Chicken Chatkhara | C18: =VLOOKUP(B18,'[1]Cust. Price List'!E8:P16,2,0) -> 70 | D18: =VLOOKUP(A18,'[1]Cust. Price List'!D8:M16,4,0) -> 40 | E18: =VLOOKUP(A18,'[1]Cust. Price List'!D8:M16,6,0) -> 65 | F18: =VLOOKUP(A18,'[1]Cust. Price List'!D8:M16,10,0) -> 52.4625 | H18: 10 | I18: =(G18*D18)*F18+H18*F18 -> 524.625 | K18: =I18*$K$13 -> 0 | L18: =I18*8% -> 41.97 | M18: =I18-K18-L18 -> 482.655 | N18: =(M18*$N$15)+(J18*F18)*$N$15 -> 106.1841 | O18: =(N18+M18)*$O$15 -> 14.720977 | P18: =M18+N18+O18 -> 603.56008
A19: BCNJ | B19: =VLOOKUP($A19,'[1]Cust. Price List'!$D$6:$O$14,2,0) -> Meat Masala (Jumbo) | C19: =VLOOKUP(B19,'[1]Cust. Price List'!E9:P17,2,0) -> 120 | D19: =VLOOKUP(A19,'[1]Cust. Price List'!D9:M17,4,0) -> 40 | E19: =VLOOKUP(A19,'[1]Cust. Price List'!D9:M17,6,0) -> 90 | F19: =VLOOKUP(A19,'[1]Cust. Price List'!D9:M17,10,0) -> 72.64 | I19: =(G19*D19)*F19+H19*F19 -> 0 | K19: =I19*$K$13 -> 0 | L19: =I19*8% -> 0 | M19: =I19-K19-L19 -> 0 | N19: =(M19*$N$15)+(J19*F19)*$N$15 -> 0 | O19: =(N19+M19)*$O$15 -> 0 | P19: =M19+N19+O19 -> 0
A20: VTNJ | B20: =VLOOKUP($A20,'[1]Cust. Price List'!$D$6:$O$14,2,0) -> Lemon Tarka (Jumbo) | C20: =VLOOKUP(B20,'[1]Cust. Price List'!E10:P18,2,0) -> 120 | D20: =VLOOKUP(A20,'[1]Cust. Price List'!D10:M18,4,0) -> 40 | E20: =VLOOKUP(A20,'[1]Cust. Price List'!D10:M18,6,0) -> 90 | F20: =VLOOKUP(A20,'[1]Cust. Price List'!D10:M18,10,0) -> 72.64 | I20: =(G20*D20)*F20+H20*F20 -> 0 | K20: =I20*$K$13 -> 0 | L20: =I20*8% -> 0 | M20: =I20-K20-L20 -> 0 | N20: =(M20*$N$15)+(J20*F20)*$N$15 -> 0 | O20: =(N20+M20)*$O$15 -> 0 | P20: =M20+N20+O20 -> 0
A21: CCNJ | B21: =VLOOKUP($A21,'[1]Cust. Price List'!$D$6:$O$14,2,0) -> Chicken Chatkhara (Jumbo) | C21: =VLOOKUP(B21,'[1]Cust. Price List'!E11:P19,2,0) -> 120 | D21: =VLOOKUP(A21,'[1]Cust. Price List'!D11:M19,4,0) -> 40 | E21: =VLOOKUP(A21,'[1]Cust. Price List'!D11:M19,6,0) -> 90 | F21: =VLOOKUP(A21,'[1]Cust. Price List'!D11:M19,10,0) -> 72.64 | I21: =(G21*D21)*F21+H21*F21 -> 0 | K21: =I21*$K$13 -> 0 | L21: =I21*8% -> 0 | M21: =I21-K21-L21 -> 0 | N21: =(M21*$N$15)+(J21*F21)*$N$15 -> 0 | O21: =(N21+M21)*$O$15 -> 0 | P21: =M21+N21+O21 -> 0
A22: CCE | B22: =VLOOKUP($A22,'[1]Cust. Price List'!$D$6:$O$14,2,0) -> Chicken Chatkhara (ECO) | C22: =VLOOKUP(B22,'[1]Cust. Price List'!E12:P20,2,0) -> 60 | D22: =VLOOKUP(A22,'[1]Cust. Price List'!D12:M20,4,0) -> 40 | E22: =VLOOKUP(A22,'[1]Cust. Price List'!D12:M20,6,0) -> 50 | F22: =VLOOKUP(A22,'[1]Cust. Price List'!D12:M20,10,0) -> 39.23 | I22: =(G22*D22)*F22+H22*F22 -> 0 | K22: =I22*3.5% -> 0 | L22: =I22*5% -> 0 | M22: =I22-K22-L22 -> 0 | N22: =(M22*$N$15)+(J22*F22)*$N$15 -> 0 | O22: =(N22+M22)*$O$15 -> 0 | P22: =M22+N22+O22 -> 0
A23: VTE | B23: =VLOOKUP($A23,'[1]Cust. Price List'!$D$6:$O$14,2,0) -> Lemon Tarka (ECO) | C23: =VLOOKUP(B23,'[1]Cust. Price List'!E13:P21,2,0) -> 60 | D23: =VLOOKUP(A23,'[1]Cust. Price List'!D13:M21,4,0) -> 40 | E23: =VLOOKUP(A23,'[1]Cust. Price List'!D13:M21,6,0) -> 50 | F23: =VLOOKUP(A23,'[1]Cust. Price List'!D13:M21,10,0) -> 39.23 | I23: =(G23*D23)*F23+H23*F23 -> 0 | K23: =I23*3.5% -> 0 | L23: =I23*$L$13 -> 0 | M23: =I23-K23-L23 -> 0 | N23: =(M23*$N$15)+(J23*F23)*$N$15 -> 0 | O23: =(N23+M23)*$O$15 -> 0 | P23: =M23+N23+O23 -> 0
A24: BCE | B24: =VLOOKUP($A24,'[1]Cust. Price List'!$D$6:$O$14,2,0) -> Meat Masala (ECO) | C24: =VLOOKUP(B24,'[1]Cust. Price List'!E14:P22,2,0) -> 60 | D24: =VLOOKUP(A24,'[1]Cust. Price List'!D14:M22,4,0) -> 40 | E24: =VLOOKUP(A24,'[1]Cust. Price List'!D14:M22,6,0) -> 50 | F24: =VLOOKUP(A24,'[1]Cust. Price List'!D14:M22,10,0) -> 39.23 | I24: =(G24*D24)*F24+H24*F24 -> 0 | K24: =I24*3.5% -> 0 | L24: =I24*$L$13 -> 0 | M24: =I24-K24-L24 -> 0 | N24: =(M24*$N$15)+(J24*F24)*$N$15 -> 0 | O24: =(N24+M24)*$O$15 -> 0 | P24: =M24+N24+O24 -> 0
A25: Total | G25: =SUM(G16:G24) -> 0 | H25: =SUM(H16:H24) -> 20 | I25: =SUM(I16:I24) -> 1049.25 | K25: =SUM(K16:K24) -> 0 | L25: =SUM(L16:L24) -> 83.94 | M25: =SUM(M16:M24) -> 965.31 | N25: =SUM(N16:N24) -> 223.90995 | O25: =SUM(O16:O24) -> 29.730499 | P25: =SUM(P16:P24) -> 1218.9504
B28: یکم جولائی 2024سے نئی ٹیکس ترمیم کے مطابق، ایف بی آر سیکشن 236 ایچ کے مطابق، فائلرز کے لیے ہر سیل انوائس پر 0.5% اور نان فائلرز کے لیے 2.5% ایڈوانس ود ہولڈنگ ٹیکس وصول کیا جائے گا۔ | N28: Gross Amount: | P28: =I25 -> 1049.25
N29: Regular Discount | P29: =L25 -> 83.94
N30: Trade Offre | P30: =K25 -> 0
N31: After Dis. Amount | P31: =P28-P29-P30 -> 965.31
N32: Total GST: | O32: =IF(B12="Registered",18%,22%) -> 0.22 | P32: =N25 -> 223.90995
N33: Net Amount: | P33: =P31+P32 -> 1189.2199
