Workbook

Sheet Sheet2
B5: OB Name
A6: 1 | B6: Salman Butt
A7: 2 | B7: Qasim Khan
A8: 3 | B8: Mobeen Ahmad
A9: 4 | B9: Zahid Rafique
A10: 5 | B10: Zeeshan Meharban
A11: 6 | B11: Furqan
A12: 7 | B12: Rana Bilal Tso
A13: 8 | B13: Shakoor
A14: 9
A15: 10
A16: 11
A17: 12
A18: 13

Sheet Format
A2: Elite MARKETING
A3: 44A- Gulberg Lahore | K3: Invoice No # : | N3: 1 | XFC3: Filer | XFD3: 0.005
A4: STRN / NTN :3808207-1 | K4: Date/Day : | N4: =TODAY() -> 46178 | XFC4: Non-filer | XFD4: 0.025
A5: ZAHID | K5: Order Date : | N5: =N4-1 -> 46177
K6: Order Name : | N6: Salman Aslam | XFC6: Registered | XFD6: 0.18
XFC7: Un-registered | XFD7: 0.22
XFD9: Yes
K10: Invoice Status : | N10: Serviced | XFD10: No
K11: Order at Original Location : | N11: Yes
K12: Reference Invoice : | T12: Shop Bill Summary (Mobeen Ahmad) | XFD12: Monday/Tuesday
L13: 0.05 | XFD13: Tuesday / Wednesday
A14: Product Code/Description | C14: GM/ Pack | D14: CTN | E14: R.P Per | F14: T.P Per | G14: Sale QTY | I14: Gross Amount Excl. Taxes | J14: Trade Offer & Discount | M14: After Discount Amount | N14: GST | O14: Adv. Tax 236H | P14: Invoice | T14: =+shell!A5 -> Customer Name : Shell pump | U14: =+shell!P35 -> 6751.0744 | XFD14: Wednesday/Thursday
D15: SIZE | E15: Unit | F15: Unit | G15: CTN | H15: Pack | J15: FOC Qty | K15: Trade Offer | L15: Pass On | N15: =IF(B12="Registered",18%,22%) -> 0.22 | O15: =IF(B11="Filer",0.5%,2.5%) -> 0.025 | P15: Amount | T15: =+'2'!A5 -> Customer Name : Smart Mart | U15: =+'2'!P35 -> 10126.612 | XFD15: Thursday /Friday
A16: BCN | B16: =VLOOKUP($A16,'[1]Cust. Price List'!$D$6:$O$14,2,0) -> Meat Masala | C16: =VLOOKUP(A16,'[1]Cust. Price List'!D6:M14,3,0) -> 70 | D16: =VLOOKUP(A16,'[1]Cust. Price List'!D6:M14,4,0) -> 40 | E16: =VLOOKUP(A16,'[1]Cust. Price List'!D6:M14,6,0) -> 65 | F16: =VLOOKUP(A16,'[1]Cust. Price List'!D6:M14,10,0) -> 52.4625 | H16: =+shell!H16+'2'!H16+'4'!H16+'3'!H16+'5'!H16+'6'!H16+'7'!H16+'8'!H16+'9'!H16+'10'!H16+Bravo!H16+'786'!H16 -> 57 | I16: =(G16*D16)*F16+H16*F16 -> 2990.3625 | J16: =+shell!J16+'2'!J16+'4'!J16+'3'!J16+'5'!J16+'6'!J16+'7'!J16+'8'!J16+'9'!J16+'10'!J16+Bravo!J16+'786'!J16 -> 2 | K16: =+shell!K16+'2'!K16+'4'!K16+'3'!K16+'5'!K16+'6'!K16+'7'!K16+'8'!K16+'9'!K16+'10'!K16 -> 0 | L16: =+shell!L16+'2'!L16+'4'!L16+'3'!L16+'5'!L16+'6'!L16+'7'!L16+'8'!L16+'9'!L16+'10'!L16 -> 239.229 | M16: =I16-K16-L16 -> 2751.1335 | N16: =+shell!N16+'2'!N16+'4'!N16+'3'!N16+'5'!N16+'6'!N16+'7'!N16+'8'!N16+'9'!N16+'10'!N16 -> 587.62197 | O16: =+shell!O16+'2'!O16+'4'!O16+'3'!O16+'5'!O16+'6'!O16+'7'!O16+'8'!O16+'9'!O16+'10'!O16 -> 83.468887 | P16: =M16+N16+O16 -> 3422.2244 | T16: =+'4'!A5 -> Customer Name : Nazeer Store | U16: =+'4'!P35 -> 2219.1949 | XFD16: Friday / Saturday
A17: VTN | B17: =VLOOKUP($A17,'[1]Cust. Price List'!$D$6:$O$14,2,0) -> Lemon Tarka | C17: =VLOOKUP(B17,'[1]Cust. Price List'!E7:P15,2,0) -> 70 | D17: =VLOOKUP(A17,'[1]Cust. Price List'!D7:M15,4,0) -> 40 | E17: =VLOOKUP(A17,'[1]Cust. Price List'!D7:M15,6,0) -> 65 | F17: =VLOOKUP(A17,'[1]Cust. Price List'!D7:M15,10,0) -> 52.4625 | H17: =+shell!H17+'2'!H17+'4'!H17+'3'!H17+'5'!H17+'6'!H17+'7'!H17+'8'!H17+'9'!H17+'10'!H17+Bravo!H17+'786'!H17 -> 27 | I17: =(G17*D17)*F17+H17*F17 -> 1416.4875 | J17: =+shell!J17+'2'!J17+'4'!J17+'3'!J17+'5'!J17+'6'!J17+'7'!J17+'8'!J17+'9'!J17+'10'!J17+Bravo!J17+'786'!J17 -> 1 | K17: =+shell!K17+'2'!K17+'4'!K17+'3'!K17+'5'!K17+'6'!K17+'7'!K17+'8'!K17+'9'!K17+'10'!K17 -> 0 | L17: =+shell!L17+'2'!L17+'4'!L17+'3'!L17+'5'!L17+'6'!L17+'7'!L17+'8'!L17+'9'!L17+'10'!L17 -> 113.319 | M17: =I17-K17-L17 -> 1303.1685 | N17: =+shell!N17+'2'!N17+'4'!N17+'3'!N17+'5'!N17+'6'!N17+'7'!N17+'8'!N17+'9'!N17+'10'!N17 -> 298.23882 | O17: =+shell!O17+'2'!O17+'4'!O17+'3'!O17+'5'!O17+'6'!O17+'7'!O17+'8'!O17+'9'!O17+'10'!O17 -> 40.035183 | P17: =M17+N17+O17 -> 1641.4425 | T17: =+'3'!A5 -> Customer Name : Haneef Store | U17: =+'3'!P35 -> 1987.1913 | XFD17: Saturday /Monday
A18: CCN | B18: =VLOOKUP($A18,'[1]Cust. Price List'!$D$6:$O$14,2,0) -> Chicken Chatkhara | C18: =VLOOKUP(B18,'[1]Cust. Price List'!E8:P16,2,0) -> 70 | D18: =VLOOKUP(A18,'[1]Cust. Price List'!D8:M16,4,0) -> 40 | E18: =VLOOKUP(A18,'[1]Cust. Price List'!D8:M16,6,0) -> 65 | F18: =VLOOKUP(A18,'[1]Cust. Price List'!D8:M16,10,0) -> 52.4625 | H18: =+shell!H18+'2'!H18+'4'!H18+'3'!H18+'5'!H18+'6'!H18+'7'!H18+'8'!H18+'9'!H18+'10'!H18+Bravo!H18+'786'!H18 -> 0 | I18: =(G18*D18)*F18+H18*F18 -> 0 | J18: =+shell!J18+'2'!J18+'4'!J18+'3'!J18+'5'!J18+'6'!J18+'7'!J18+'8'!J18+'9'!J18+'10'!J18+Bravo!J18+'786'!J18 -> 0 | K18: =+shell!K18+'2'!K18+'4'!K18+'3'!K18+'5'!K18+'6'!K18+'7'!K18+'8'!K18+'9'!K18+'10'!K18 -> 0 | L18: =+shell!L18+'2'!L18+'4'!L18+'3'!L18+'5'!L18+'6'!L18+'7'!L18+'8'!L18+'9'!L18+'10'!L18 -> 0 | M18: =I18-K18-L18 -> 0 | N18: =+shell!N18+'2'!N18+'4'!N18+'3'!N18+'5'!N18+'6'!N18+'7'!N18+'8'!N18+'9'!N18+'10'!N18 -> 0 | O18: =+shell!O18+'2'!O18+'4'!O18+'3'!O18+'5'!O18+'6'!O18+'7'!O18+'8'!O18+'9'!O18+'10'!O18 -> 0 | P18: =M18+N18+O18 -> 0 | T18: =+'5'!A5 -> Customer Name : Tufail Store | U18: =+'5'!P35 -> 2437.9009
A19: BCNJ | B19: =VLOOKUP($A19,'[1]Cust. Price List'!$D$6:$O$14,2,0) -> Meat Masala (Jumbo) | C19: =VLOOKUP(B19,'[1]Cust. Price List'!E9:P17,2,0) -> 120 | D19: =VLOOKUP(A19,'[1]Cust. Price List'!D9:M17,4,0) -> 40 | E19: =VLOOKUP(A19,'[1]Cust. Price List'!D9:M17,6,0) -> 90 | F19: =VLOOKUP(A19,'[1]Cust. Price List'!D9:M17,10,0) -> 72.64 | H19: =+shell!H19+'2'!H19+'4'!H19+'3'!H19+'5'!H19+'6'!H19+'7'!H19+'8'!H19+'9'!H19+'10'!H19+Bravo!H19+'786'!H19 -> 52 | I19: =(G19*D19)*F19+H19*F19 -> 3777.28 | J19: =+shell!J19+'2'!J19+'4'!J19+'3'!J19+'5'!J19+'6'!J19+'7'!J19+'8'!J19+'9'!J19+'10'!J19+Bravo!J19+'786'!J19 -> 7 | K19: =+shell!K19+'2'!K19+'4'!K19+'3'!K19+'5'!K19+'6'!K19+'7'!K19+'8'!K19+'9'!K19+'10'!K19 -> 0 | L19: =+shell!L19+'2'!L19+'4'!L19+'3'!L19+'5'!L19+'6'!L19+'7'!L19+'8'!L19+'9'!L19+'10'!L19 -> 999.5264 | M19: =I19-K19-L19 -> 2777.7536 | N19: =+shell!N19+'2'!N19+'4'!N19+'3'!N19+'5'!N19+'6'!N19+'7'!N19+'8'!N19+'9'!N19+'10'!N19 -> 2415.1928 | O19: =+shell!O19+'2'!O19+'4'!O19+'3'!O19+'5'!O19+'6'!O19+'7'!O19+'8'!O19+'9'!O19+'10'!O19 -> 204.21864 | P19: =M19+N19+O19 -> 5397.1651 | T19: =+'6'!A5 -> Customer Name : Sadat Store | U19: =+'6'!P35 -> 538.64712
A20: VTNJ | B20: =VLOOKUP($A20,'[1]Cust. Price List'!$D$6:$O$14,2,0) -> Lemon Tarka (Jumbo) | C20: =VLOOKUP(B20,'[1]Cust. Price List'!E10:P18,2,0) -> 120 | D20: =VLOOKUP(A20,'[1]Cust. Price List'!D10:M18,4,0) -> 40 | E20: =VLOOKUP(A20,'[1]Cust. Price List'!D10:M18,6,0) -> 90 | F20: =VLOOKUP(A20,'[1]Cust. Price List'!D10:M18,10,0) -> 72.64 | H20: =+shell!H20+'2'!H20+'4'!H20+'3'!H20+'5'!H20+'6'!H20+'7'!H20+'8'!H20+'9'!H20+'10'!H20+Bravo!H20+'786'!H20 -> 50 | I20: =(G20*D20)*F20+H20*F20 -> 3632 | J20: =+shell!J20+'2'!J20+'4'!J20+'3'!J20+'5'!J20+'6'!J20+'7'!J20+'8'!J20+'9'!J20+'10'!J20+Bravo!J20+'786'!J20 -> 12 | K20: =+shell!K20+'2'!K20+'4'!K20+'3'!K20+'5'!K20+'6'!K20+'7'!K20+'8'!K20+'9'!K20+'10'!K20 -> 0 | L20: =+shell!L20+'2'!L20+'4'!L20+'3'!L20+'5'!L20+'6'!L20+'7'!L20+'8'!L20+'9'!L20+'10'!L20 -> 987.904 | M20: =I20-K20-L20 -> 2644.096 | N20: =+shell!N20+'2'!N20+'4'!N20+'3'!N20+'5'!N20+'6'!N20+'7'!N20+'8'!N20+'9'!N20+'10'!N20 -> 2465.6922 | O20: =+shell!O20+'2'!O20+'4'!O20+'3'!O20+'5'!O20+'6'!O20+'7'!O20+'8'!O20+'9'!O20+'10'!O20 -> 193.34734 | P20: =M20+N20+O20 -> 5303.1355 | T20: =+'7'!A5 -> Customer Name : Araf Store | U20: =+'7'!P35 -> 3309.6731
A21: CCNJ | B21: =VLOOKUP($A21,'[1]Cust. Price List'!$D$6:$O$14,2,0) -> Chicken Chatkhara (Jumbo) | C21: =VLOOKUP(B21,'[1]Cust. Price List'!E11:P19,2,0) -> 120 | D21: =VLOOKUP(A21,'[1]Cust. Price List'!D11:M19,4,0) -> 40 | E21: =VLOOKUP(A21,'[1]Cust. Price List'!D11:M19,6,0) -> 90 | F21: =VLOOKUP(A21,'[1]Cust. Price List'!D11:M19,10,0) -> 72.64 | H21: =+shell!H21+'2'!H21+'4'!H21+'3'!H21+'5'!H21+'6'!H21+'7'!H21+'8'!H21+'9'!H21+'10'!H21+Bravo!H21+'786'!H21 -> 42 | I21: =(G21*D21)*F21+H21*F21 -> 3050.88 | J21: =+shell!J21+'2'!J21+'4'!J21+'3'!J21+'5'!J21+'6'!J21+'7'!J21+'8'!J21+'9'!J21+'10'!J21+Bravo!J21+'786'!J21 -> 8 | K21: =+shell!K21+'2'!K21+'4'!K21+'3'!K21+'5'!K21+'6'!K21+'7'!K21+'8'!K21+'9'!K21+'10'!K21 -> 0 | L21: =+shell!L21+'2'!L21+'4'!L21+'3'!L21+'5'!L21+'6'!L21+'7'!L21+'8'!L21+'9'!L21+'10'!L21 -> 1173.8624 | M21: =I21-K21-L21 -> 1877.0176 | N21: =+shell!N21+'2'!N21+'4'!N21+'3'!N21+'5'!N21+'6'!N21+'7'!N21+'8'!N21+'9'!N21+'10'!N21 -> 2872.2437 | O21: =+shell!O21+'2'!O21+'4'!O21+'3'!O21+'5'!O21+'6'!O21+'7'!O21+'8'!O21+'9'!O21+'10'!O21 -> 257.6134 | P21: =M21+N21+O21 -> 5006.8747 | T21: =+'8'!A5 -> Customer Name : Nafees Store | U21: =+'8'!P35 -> 2022.0463
A22: CCE | B22: =VLOOKUP($A22,'[1]Cust. Price List'!$D$6:$O$14,2,0) -> Chicken Chatkhara (ECO) | C22: =VLOOKUP(B22,'[1]Cust. Price List'!E12:P20,2,0) -> 60 | D22: =VLOOKUP(A22,'[1]Cust. Price List'!D12:M20,4,0) -> 40 | E22: =VLOOKUP(A22,'[1]Cust. Price List'!D12:M20,6,0) -> 50 | F22: =VLOOKUP(A22,'[1]Cust. Price List'!D12:M20,10,0) -> 39.23 | H22: =+shell!H22+'2'!H22+'4'!H22+'3'!H22+'5'!H22+'6'!H22+'7'!H22+'8'!H22+'9'!H22+'10'!H22+Bravo!H22+'786'!H22 -> 48 | I22: =(G22*D22)*F22+H22*F22 -> 1883.04 | J22: =+shell!J22+'2'!J22+'4'!J22+'3'!J22+'5'!J22+'6'!J22+'7'!J22+'8'!J22+'9'!J22+'10'!J22+Bravo!J22+'786'!J22 -> 0 | K22: =+shell!K22+'2'!K22+'4'!K22+'3'!K22+'5'!K22+'6'!K22+'7'!K22+'8'!K22+'9'!K22+'10'!K22 -> 65.9064 | L22: =+shell!L22+'2'!L22+'4'!L22+'3'!L22+'5'!L22+'6'!L22+'7'!L22+'8'!L22+'9'!L22+'10'!L22 -> 94.152 | M22: =I22-K22-L22 -> 1722.9816 | N22: =+shell!N22+'2'!N22+'4'!N22+'3'!N22+'5'!N22+'6'!N22+'7'!N22+'8'!N22+'9'!N22+'10'!N22 -> 344.59632 | O22: =+shell!O22+'2'!O22+'4'!O22+'3'!O22+'5'!O22+'6'!O22+'7'!O22+'8'!O22+'9'!O22+'10'!O22 -> 51.689448 | P22: =M22+N22+O22 -> 2119.2674 | T22: =+'9'!A5 -> Customer Name : Rehman Store | U22: =+'9'!P35 -> 3375.5372
A23: VTE | B23: =VLOOKUP($A23,'[1]Cust. Price List'!$D$6:$O$14,2,0) -> Lemon Tarka (ECO) | C23: =VLOOKUP(B23,'[1]Cust. Price List'!E13:P21,2,0) -> 60 | D23: =VLOOKUP(A23,'[1]Cust. Price List'!D13:M21,4,0) -> 40 | E23: =VLOOKUP(A23,'[1]Cust. Price List'!D13:M21,6,0) -> 50 | F23: =VLOOKUP(A23,'[1]Cust. Price List'!D13:M21,10,0) -> 39.23 | H23: =+shell!H23+'2'!H23+'4'!H23+'3'!H23+'5'!H23+'6'!H23+'7'!H23+'8'!H23+'9'!H23+'10'!H23+Bravo!H23+'786'!H23 -> 0 | I23: =(G23*D23)*F23+H23*F23 -> 0 | J23: =+shell!J23+'2'!J23+'4'!J23+'3'!J23+'5'!J23+'6'!J23+'7'!J23+'8'!J23+'9'!J23+'10'!J23+Bravo!J23+'786'!J23 -> 0 | K23: =+shell!K23+'2'!K23+'4'!K23+'3'!K23+'5'!K23+'6'!K23+'7'!K23+'8'!K23+'9'!K23+'10'!K23 -> 0 | L23: =+shell!L23+'2'!L23+'4'!L23+'3'!L23+'5'!L23+'6'!L23+'7'!L23+'8'!L23+'9'!L23+'10'!L23 -> 0 | M23: =I23-K23-L23 -> 0 | N23: =+shell!N23+'2'!N23+'4'!N23+'3'!N23+'5'!N23+'6'!N23+'7'!N23+'8'!N23+'9'!N23+'10'!N23 -> 0 | O23: =+shell!O23+'2'!O23+'4'!O23+'3'!O23+'5'!O23+'6'!O23+'7'!O23+'8'!O23+'9'!O23+'10'!O23 -> 0 | P23: =M23+N23+O23 -> 0 | T23: =+'10'!A5 -> Customer Name : Tuqeer Store | U23: =+'10'!P35 -> 19178.233
A24: BCE | B24: =VLOOKUP($A24,'[1]Cust. Price List'!$D$6:$O$14,2,0) -> Meat Masala (ECO) | C24: =VLOOKUP(B24,'[1]Cust. Price List'!E14:P22,2,0) -> 60 | D24: =VLOOKUP(A24,'[1]Cust. Price List'!D14:M22,4,0) -> 40 | E24: =VLOOKUP(A24,'[1]Cust. Price List'!D14:M22,6,0) -> 50 | F24: =VLOOKUP(A24,'[1]Cust. Price List'!D14:M22,10,0) -> 39.23 | H24: =+shell!H24+'2'!H24+'4'!H24+'3'!H24+'5'!H24+'6'!H24+'7'!H24+'8'!H24+'9'!H24+'10'!H24+Bravo!H24+'786'!H24 -> 0 | I24: =(G24*D24)*F24+H24*F24 -> 0 | J24: =+shell!J24+'2'!J24+'4'!J24+'3'!J24+'5'!J24+'6'!J24+'7'!J24+'8'!J24+'9'!J24+'10'!J24+Bravo!J24+'786'!J24 -> 0 | K24: =+shell!K24+'2'!K24+'4'!K24+'3'!K24+'5'!K24+'6'!K24+'7'!K24+'8'!K24+'9'!K24+'10'!K24 -> 0 | L24: =+shell!L24+'2'!L24+'4'!L24+'3'!L24+'5'!L24+'6'!L24+'7'!L24+'8'!L24+'9'!L24+'10'!L24 -> 0 | M24: =I24-K24-L24 -> 0 | N24: =+shell!N24+'2'!N24+'4'!N24+'3'!N24+'5'!N24+'6'!N24+'7'!N24+'8'!N24+'9'!N24+'10'!N24 -> 0 | O24: =+shell!O24+'2'!O24+'4'!O24+'3'!O24+'5'!O24+'6'!O24+'7'!O24+'8'!O24+'9'!O24+'10'!O24 -> 0 | P24: =M24+N24+O24 -> 0 | T24: =+Bravo!A5 -> Customer Name : | U24: =+Bravo!P35 -> 0
A25: Total | G25: =SUM(G16:G24) -> 0 | H25: =SUM(H16:H24) -> 276 | I25: =SUM(I16:I24) -> 16750.05 | J25: =SUM(J16:J24) -> 30 | K25: =SUM(K16:K24) -> 65.9064 | L25: =SUM(L16:L24) -> 3607.9928 | M25: =SUM(M16:M24) -> 13076.151 | N25: =SUM(N16:N24) -> 8983.5858 | ... P25: =SUM(P16:P24) -> 22890.11 | T25: =+'786'!A5 -> Customer Name : | U25: =+'786'!P35 -> 0
T26: Total | U26: =SUM(U14:U25) -> 51946.11
B28: یکم جولائی 2024سے نئی ٹیکس ترمیم کے مطابق، ایف بی آر سیکشن 236 ایچ کے مطابق، فائلرز کے لیے ہر سیل انوائس پر 0.5% اور نان فائلرز کے لیے 2.5% ایڈوانس ود ہولڈنگ ٹیکس وصول کیا جائے گا۔ | N28: Gross Amount: | P28: =I25 -> 16750.05
N29: Regular Discount | P29: =L25 -> 3607.9928
N30: Trade Offre | P30: =K25 -> 65.9064
N31: After Dis. Amount | P31: =P28-P29-P30 -> 13076.151
N32: Total GST: | O32: =IF(B12="Registered",18%,22%) -> 0.22 | P32: =N25 -> 8983.5858
N33: Net Amount: | P33: =P31+P32 -> 22059.737
N34: Ad.Tax | O34: =IF(B11="Filer",0.5%,2.5%) -> 0.025 | P34: =O34*P33 -> 551.49342
N35: Net Amount with Ad.Tax | P35: =P33+P34 -> 22611.23
B36: Delivered By

Sheet Cust. Price List
V2: 0.18
A4: S# | B4: Code | D4: SKU | E4: SKUs Description | F4: Unit | H4: Retail Price | J4: TP Incl. | L4: TP Excl. | N4: Dist Margin | P4: Trade Offre | R4: Stale | T4: Ex-Fac | V4: S.Tax | X4: Dist. Price
B5: Bar | C5: SKU | F5: Gm | G5: CTN | H5: Ctn | I5: Pk | J5: Ctn | K5: Pk | L5: Ctn | M5: Pk | N5: 0.19 | O5: Amount | P5: 0.04 | Q5: Amount | R5: 0.005 | S5: Amount | T5: Ctn | U5: Pk | V5: Ctn | W5: Pk | X5: Ctn | Y5: Pk | AA5: Weight/ctn
A6: 1 | C6: BCN | D6: BCN | E6: Meat Masala | F6: 70 | G6: 40 | H6: =I6*G6 -> 2600 | I6: 65 | J6: =K6*G6 -> 2560.17 | K6: =M6*1.22 -> 64.00425 | L6: 2098.5 | M6: =L6/G6 -> 52.4625 | N6: 0.19 | O6: =N6*M6 -> 9.967875 | Q6: =P6*M6 -> 0 | S6: =R6*M6 -> 0 | T6: =U6*G6 -> 1699.785 | U6: =M6-O6-Q6-S6 -> 42.494625 | V6: =T6*$V$2 -> 305.9613 | W6: =U6*$V$2 -> 7.6490325 | X6: =T6+V6 -> 2005.7463 | Y6: =U6+W6 -> 50.143657 | AA6: =(F6*G6)/1000 -> 2.8
A7: =+A6+1 -> 2 | C7: VTN | D7: VTN | E7: Lemon Tarka | F7: 70 | G7: 40 | H7: =I7*G7 -> 2600 | I7: 65 | J7: =K7*G7 -> 2560.17 | K7: =M7*1.22 -> 64.00425 | L7: 2098.5 | M7: =L7/G7 -> 52.4625 | N7: =+N6 -> 0.19 | O7: =N7*M7 -> 9.967875 | Q7: =P7*M7 -> 0 | S7: =R7*M7 -> 0 | T7: =U7*G7 -> 1699.785 | U7: =M7-O7-Q7-S7 -> 42.494625 | V7: =T7*$V$2 -> 305.9613 | W7: =U7*$V$2 -> 7.6490325 | X7: =T7+V7 -> 2005.7463 | Y7: =U7+W7 -> 50.143657 | AA7: =(F7*G7)/1000 -> 2.8
A8: =+A7+1 -> 3 | C8: CCN | D8: CCN | E8: Chicken Chatkhara | F8: 70 | G8: 40 | H8: =I8*G8 -> 2600 | I8: 65 | J8: =K8*G8 -> 2560.17 | K8: =M8*1.22 -> 64.00425 | L8: 2098.5 | M8: =L8/G8 -> 52.4625 | N8: =+N7 -> 0.19 | O8: =N8*M8 -> 9.967875 | Q8: =P8*M8 -> 0 | S8: =R8*M8 -> 0 | T8: =U8*G8 -> 1699.785 | U8: =M8-O8-Q8-S8 -> 42.494625 | V8: =T8*$V$2 -> 305.9613 | W8: =U8*$V$2 -> 7.6490325 | X8: =T8+V8 -> 2005.7463 | Y8: =U8+W8 -> 50.143657 | AA8: =(F8*G8)/1000 -> 2.8
A9: =+A8+1 -> 4 | C9: BCNJ | D9: BCNJ | E9: Meat Masala (Jumbo) | F9: 120 | G9: 40 | H9: =I9*G9 -> 3600 | I9: 90 | J9: =K9*G9 -> 3544.832 | K9: =M9*1.22 -> 88.6208 | L9: 2905.6 | M9: =L9/G9 -> 72.64 | N9: =+N8 -> 0.19 | O9: =N9*M9 -> 13.8016 | Q9: =P9*M9 -> 0 | S9: =R9*M9 -> 0 | T9: =U9*G9 -> 2353.536 | U9: =M9-O9-Q9-S9 -> 58.8384 | V9: =T9*$V$2 -> 423.63648 | W9: =U9*$V$2 -> 10.590912 | X9: =T9+V9 -> 2777.1725 | Y9: =U9+W9 -> 69.429312 | AA9: =(F9*G9)/1000 -> 4.8
A10: =+A9+1 -> 5 | C10: VTNJ | D10: VTNJ | E10: Lemon Tarka (Jumbo) | F10: 120 | G10: 40 | H10: =I10*G10 -> 3600 | I10: 90 | J10: =K10*G10 -> 3544.832 | K10: =M10*1.22 -> 88.6208 | L10: 2905.6 | M10: =L10/G10 -> 72.64 | N10: =+N9 -> 0.19 | O10: =N10*M10 -> 13.8016 | Q10: =P10*M10 -> 0 | S10: =R10*M10 -> 0 | T10: =U10*G10 -> 2353.536 | U10: =M10-O10-Q10-S10 -> 58.8384 | V10: =T10*$V$2 -> 423.63648 | W10: =U10*$V$2 -> 10.590912 | X10: =T10+V10 -> 2777.1725 | Y10: =U10+W10 -> 69.429312 | AA10: =(F10*G10)/1000 -> 4.8
A11: =+A10+1 -> 6 | C11: CCNJ | D11: CCNJ | E11: Chicken Chatkhara (Jumbo) | F11: 120 | G11: 40 | H11: =I11*G11 -> 3600 | I11: 90 | J11: =K11*G11 -> 3544.832 | K11: =M11*1.22 -> 88.6208 | L11: 2905.6 | M11: =L11/G11 -> 72.64 | N11: =+N10 -> 0.19 | O11: =N11*M11 -> 13.8016 | Q11: =P11*M11 -> 0 | S11: =R11*M11 -> 0 | T11: =U11*G11 -> 2353.536 | U11: =M11-O11-Q11-S11 -> 58.8384 | V11: =T11*$V$2 -> 423.63648 | W11: =U11*$V$2 -> 10.590912 | X11: =T11+V11 -> 2777.1725 | Y11: =U11+W11 -> 69.429312 | AA11: =(F11*G11)/1000 -> 4.8
A12: =+A11+1 -> 7 | C12: CCE | D12: CCE | E12: Chicken Chatkhara (ECO) | F12: 60 | G12: 40 | H12: =I12*G12 -> 2000 | I12: 50 | J12: =K12*G12 -> 1914.424 | K12: =M12*1.22 -> 47.8606 | L12: 1569.2 | M12: =L12/G12 -> 39.23 | N12: =+N11 -> 0.19 | O12: =N12*M12 -> 7.4537 | Q12: =P12*M12 -> 0 | S12: =R12*M12 -> 0 | T12: =U12*G12 -> 1271.052 | U12: =M12-O12-Q12-S12 -> 31.7763 | V12: =T12*$V$2 -> 228.78936 | W12: =U12*$V$2 -> 5.719734 | X12: =T12+V12 -> 1499.8414 | Y12: =U12+W12 -> 37.496034 | AA12: =(F12*G12)/1000 -> 2.4
A13: =+A12+1 -> 8 | C13: VTE | D13: VTE | E13: Lemon Tarka (ECO) | F13: 60 | G13: 40 | H13: =I13*G13 -> 2000 | I13: 50 | J13: =K13*G13 -> 1914.424 | K13: =M13*1.22 -> 47.8606 | L13: 1569.2 | M13: =L13/G13 -> 39.23 | N13: =+N12 -> 0.19 | O13: =N13*M13 -> 7.4537 | Q13: =P13*M13 -> 0 | S13: =R13*M13 -> 0 | T13: =U13*G13 -> 1271.052 | U13: =M13-O13-Q13-S13 -> 31.7763 | V13: =T13*$V$2 -> 228.78936 | W13: =U13*$V$2 -> 5.719734 | X13: =T13+V13 -> 1499.8414 | Y13: =U13+W13 -> 37.496034 | AA13: =(F13*G13)/1000 -> 2.4
A14: =+A13+1 -> 9 | C14: BCE | D14: BCE | E14: Meat Masala (ECO) | F14: 60 | G14: 40 | H14: =I14*G14 -> 2000 | I14: 50 | J14: =K14*G14 -> 1914.424 | K14: =M14*1.22 -> 47.8606 | L14: 1569.2 | M14: =L14/G14 -> 39.23 | N14: =+N13 -> 0.19 | O14: =N14*M14 -> 7.4537 | Q14: =P14*M14 -> 0 | S14: =R14*M14 -> 0 | T14: =U14*G14 -> 1271.052 | U14: =M14-O14-Q14-S14 -> 31.7763 | V14: =T14*$V$2 -> 228.78936 | W14: =U14*$V$2 -> 5.719734 | X14: =T14+V14 -> 1499.8414 | Y14: =U14+W14 -> 37.496034 | AA14: =(F14*G14)/1000 -> 2.4
A15: =+A14+1 -> 10
A16: =+A15+1 -> 11
A17: =+A16+1 -> 12
A18: =+A17+1 -> 13
A19: =+A18+1 -> 14
A20: =+A19+1 -> 15
A22: =+A20+1 -> 16
A23: =+A22+1 -> 17
A24: =+A23+1 -> 18
A25: =+A24+1 -> 19
A26: =+A25+1 -> 20
A27: =+A26+1 -> 21
A28: =+A27+1 -> 22
A29: =+A28+1 -> 23
A30: =+A29+1 -> 24
A31: =+A30+1 -> 25
A32: =+A31+1 -> 26
A33: =+A32+1 -> 27
A34: =+A33+1 -> 28
A36: =+A34+1 -> 29
A37: =+A36+1 -> 30
A38: =+A37+1 -> 31
A39: =+A38+1 -> 32
A40: =+A39+1 -> 33
A41: =+A40+1 -> 34
A42: =+A41+1 -> 35
A43: =+A42+1 -> 36
A44: =+A43+1 -> 37
...

Sheet shell
A2: Elite MARKETING
A3: 44A- Gulberg Lahore | K3: Invoice No # : | N3: 1 | XFC3: Filer | XFD3: 0.005
A4: STRN / NTN :3808207-1 | K4: Date/Day : | N4: =TODAY() -> 46178 | XFC4: Non-filer | XFD4: 0.025
A5: Customer Name : Shell pump | K5: Order Date : | N5: =N4-1 -> 46177
A6: Address: Shimla pahari | K6: Order Name : | N6: Zahid Rafique | XFC6: Registered | XFD6: 0.18
XFC7: Un-registered | XFD7: 0.22
XFD9: Yes
A10: NTN/CNIC Number: | K10: Invoice Status : | N10: Serviced | XFD10: No
B11: Non-filer | C11: =IF($O34>2.49%,"No","Yes") -> No | K11: Order at Original Location : | N11: Yes
A12: STRN Number: | B12: Un-registered | C12: =IF($O32>21.99%,"No","Yes") -> No | K12: Reference Invoice : | XFD12: Monday/Tuesday
L13: 0.05 | XFD13: Tuesday / Wednesday
A14: Product Code/Description | C14: GM/ Pack | D14: CTN | E14: R.P Per | F14: T.P Per | G14: Sale QTY | I14: Gross Amount Excl. Taxes | J14: Trade Offer & Discount | M14: After Discount Amount | N14: GST | O14: Adv. Tax 236H | P14: Invoice | XFD14: Wednesday/Thursday
D15: SIZE | E15: Unit | F15: Unit | G15: CTN | H15: Pack | J15: FOC Qty | K15: Trade Offer | L15: Pass On | N15: =IF(B12="Registered",18%,22%) -> 0.22 | O15: =IF(B11="Filer",0.5%,2.5%) -> 0.025 | P15: Amount | XFD15: Thursday /Friday
A16: BCN | B16: =VLOOKUP($A16,'[1]Cust. Price List'!$D$6:$O$14,2,0) -> Meat Masala | C16: =VLOOKUP(A16,'[1]Cust. Price List'!D6:M14,3,0) -> 70 | D16: =VLOOKUP(A16,'[1]Cust. Price List'!D6:M14,4,0) -> 40 | E16: =VLOOKUP(A16,'[1]Cust. Price List'!D6:M14,6,0) -> 65 | F16: =VLOOKUP(A16,'[1]Cust. Price List'!D6:M14,10,0) -> 52.4625 | I16: =(G16*D16)*F16+H16*F16 -> 0 | K16: =I16*$K$13 -> 0 | L16: =I16*8% -> 0 | M16: =I16-K16-L16 -> 0 | N16: =(M16*$N$15)+(J16*F16)*$N$15 -> 0 | O16: =(N16+M16)*$O$15 -> 0 | P16: =M16+N16+O16 -> 0 | XFD16: Friday / Saturday
A17: VTN | B17: =VLOOKUP($A17,'[1]Cust. Price List'!$D$6:$O$14,2,0) -> Lemon Tarka | C17: =VLOOKUP(B17,'[1]Cust. Price List'!E7:P15,2,0) -> 70 | D17: =VLOOKUP(A17,'[1]Cust. Price List'!D7:M15,4,0) -> 40 | E17: =VLOOKUP(A17,'[1]Cust. Price List'!D7:M15,6,0) -> 65 | F17: =VLOOKUP(A17,'[1]Cust. Price List'!D7:M15,10,0) -> 52.4625 | I17: =(G17*D17)*F17+H17*F17 -> 0 | K17: =I17*$K$13 -> 0 | L17: =I17*8% -> 0 | M17: =I17-K17-L17 -> 0 | N17: =(M17*$N$15)+(J17*F17)*$N$15 -> 0 | O17: =(N17+M17)*$O$15 -> 0 | P17: =M17+N17+O17 -> 0 | XFD17: Saturday /Monday
A18: CCN | B18: =VLOOKUP($A18,'[1]Cust. Price List'!$D$6:$O$14,2,0) -> Chicken Chatkhara | C18: =VLOOKUP(B18,'[1]Cust. Price List'!E8:P16,2,0) -> 70 | D18: =VLOOKUP(A18,'[1]Cust. Price List'!D8:M16,4,0) -> 40 | E18: =VLOOKUP(A18,'[1]Cust. Price List'!D8:M16,6,0) -> 65 | F18: =VLOOKUP(A18,'[1]Cust. Price List'!D8:M16,10,0) -> 52.4625 | I18: =(G18*D18)*F18+H18*F18 -> 0 | K18: =I18*$K$13 -> 0 | L18: =I18*8% -> 0 | M18: =I18-K18-L18 -> 0 | N18: =(M18*$N$15)+(J18*F18)*$N$15 -> 0 | O18: =(N18+M18)*$O$15 -> 0 | P18: =M18+N18+O18 -> 0
A19: BCNJ | B19: =VLOOKUP($A19,'[1]Cust. Price List'!$D$6:$O$14,2,0) -> Meat Masala (Jumbo) | C19: =VLOOKUP(B19,'[1]Cust. Price List'!E9:P17,2,0) -> 120 | D19: =VLOOKUP(A19,'[1]Cust. Price List'!D9:M17,4,0) -> 40 | E19: =VLOOKUP(A19,'[1]Cust. Price List'!D9:M17,6,0) -> 90 | F19: =VLOOKUP(A19,'[1]Cust. Price List'!D9:M17,10,0) -> 72.64 | H19: 20 | I19: =(G19*D19)*F19+H19*F19 -> 1452.8 | J19: 1 | K19: =I19*$K$13 -> 0 | L19: =I19*8% -> 116.224 | M19: =I19-K19-L19 -> 1336.576 | N19: =(M19*$N$15)+(J19*F19)*$N$15 -> 310.02752 | O19: =(N19+M19)*$O$15 -> 41.165088 | P19: =M19+N19+O19 -> 1687.7686
A20: VTNJ | B20: =VLOOKUP($A20,'[1]Cust. Price List'!$D$6:$O$14,2,0) -> Lemon Tarka (Jumbo) | C20: =VLOOKUP(B20,'[1]Cust. Price List'!E10:P18,2,0) -> 120 | D20: =VLOOKUP(A20,'[1]Cust. Price List'!D10:M18,4,0) -> 40 | E20: =VLOOKUP(A20,'[1]Cust. Price List'!D10:M18,6,0) -> 90 | F20: =VLOOKUP(A20,'[1]Cust. Price List'!D10:M18,10,0) -> 72.64 | H20: 20 | I20: =(G20*D20)*F20+H20*F20 -> 1452.8 | J20: 1 | K20: =I20*$K$13 -> 0 | L20: =I20*8% -> 116.224 | M20: =I20-K20-L20 -> 1336.576 | N20: =(M20*$N$15)+(J20*F20)*$N$15 -> 310.02752 | O20: =(N20+M20)*$O$15 -> 41.165088 | P20: =M20+N20+O20 -> 1687.7686
A21: CCNJ | B21: =VLOOKUP($A21,'[1]Cust. Price List'!$D$6:$O$14,2,0) -> Chicken Chatkhara (Jumbo) | C21: =VLOOKUP(B21,'[1]Cust. Price List'!E11:P19,2,0) -> 120 | D21: =VLOOKUP(A21,'[1]Cust. Price List'!D11:M19,4,0) -> 40 | E21: =VLOOKUP(A21,'[1]Cust. Price List'!D11:M19,6,0) -> 90 | F21: =VLOOKUP(A21,'[1]Cust. Price List'!D11:M19,10,0) -> 72.64 | G21: 1 | I21: =(G21*D21)*F21+H21*F21 -> 2905.6 | J21: 2 | K21: =I21*$K$13 -> 0 | L21: =I21*8% -> 232.448 | M21: =I21-K21-L21 -> 2673.152 | N21: =(M21*$N$15)+(J21*F21)*$N$15 -> 620.05504 | O21: =(N21+M21)*$O$15 -> 82.330176 | P21: =M21+N21+O21 -> 3375.5372
A22: CCE | B22: =VLOOKUP($A22,'[1]Cust. Price List'!$D$6:$O$14,2,0) -> Chicken Chatkhara (ECO) | C22: =VLOOKUP(B22,'[1]Cust. Price List'!E12:P20,2,0) -> 60 | D22: =VLOOKUP(A22,'[1]Cust. Price List'!D12:M20,4,0) -> 40 | E22: =VLOOKUP(A22,'[1]Cust. Price List'!D12:M20,6,0) -> 50 | F22: =VLOOKUP(A22,'[1]Cust. Price List'!D12:M20,10,0) -> 39.23 | I22: =(G22*D22)*F22+H22*F22 -> 0 | K22: =I22*3.5% -> 0 | L22: =I22*5% -> 0 | M22: =I22-K22-L22 -> 0 | N22: =(M22*$N$15)+(J22*F22)*$N$15 -> 0 | O22: =(N22+M22)*$O$15 -> 0 | P22: =M22+N22+O22 -> 0
A23: VTE | B23: =VLOOKUP($A23,'[1]Cust. Price List'!$D$6:$O$14,2,0) -> Lemon Tarka (ECO) | C23: =VLOOKUP(B23,'[1]Cust. Price List'!E13:P21,2,0) -> 60 | D23: =VLOOKUP(A23,'[1]Cust. Price List'!D13:M21,4,0) -> 40 | E23: =VLOOKUP(A23,'[1]Cust. Price List'!D13:M21,6,0) -> 50 | F23: =VLOOKUP(A23,'[1]Cust. Price List'!D13:M21,10,0) -> 39.23 | I23: =(G23*D23)*F23+H23*F23 -> 0 | K23: =I23*3.5% -> 0 | L23: =I23*$L$13 -> 0 | M23: =I23-K23-L23 -> 0 | N23: =(M23*$N$15)+(J23*F23)*$N$15 -> 0 | O23: =(N23+M23)*$O$15 -> 0 | P23: =M23+N23+O23 -> 0
A24: BCE | B24: =VLOOKUP($A24,'[1]Cust. Price List'!$D$6:$O$14,2,0) -> Meat Masala (ECO) | C24: =VLOOKUP(B24,'[1]Cust. Price List'!E14:P22,2,0) -> 60 | D24: =VLOOKUP(A24,'[1]Cust. Price List'!D14:M22,4,0) -> 40 | E24: =VLOOKUP(A24,'[1]Cust. Price List'!D14:M22,6,0) -> 50 | F24: =VLOOKUP(A24,'[1]Cust. Price List'!D14:M22,10,0) -> 39.23 | I24: =(G24*D24)*F24+H24*F24 -> 0 | K24: =I24*3.5% -> 0 | L24: =I24*$L$13 -> 0 | M24: =I24-K24-L24 -> 0 | N24: =(M24*$N$15)+(J24*F24)*$N$15 -> 0 | O24: =(N24+M24)*$O$15 -> 0 | P24: =M24+N24+O24 -> 0
A25: Total | G25: =SUM(G16:G24) -> 1 | H25: =SUM(H16:H24) -> 40 | I25: =SUM(I16:I24) -> 5811.2 | K25: =SUM(K16:K24) -> 0 | L25: =SUM(L16:L24) -> 464.896 | M25: =SUM(M16:M24) -> 5346.304 | N25: =SUM(N16:N24) -> 1240.1101 | O25: =SUM(O16:O24) -> 164.66035 | P25: =SUM(P16:P24) -> 6751.0744
B28: یکم جولائی 2024سے نئی ٹیکس ترمیم کے مطابق، ایف بی آر سیکشن 236 ایچ کے مطابق، فائلرز کے لیے ہر سیل انوائس پر 0.5% اور نان فائلرز کے لیے 2.5% ایڈوانس ود ہولڈنگ ٹیکس وصول کیا جائے گا۔ | N28: Gross Amount: | P28: =I25 -> 5811.2
N29: Regular Discount | P29: =L25 -> 464.896
N30: Trade Offre | P30: =K25 -> 0
N31: After Dis. Amount | P31: =P28-P29-P30 -> 5346.304
N32: Total GST: | O32: =IF(B12="Registered",18%,22%) -> 0.22 | P32: =N25 -> 1240.1101
N33: Net Amount: | P33: =P31+P32 -> 6586.4141
N34: Ad.Tax | O34: =IF(B11="Filer",0.5%,2.5%) -> 0.025 | P34: =O34*P33 -> 164.66035
N35: Net Amount with Ad.Tax | P35: =P33+P34 -> 6751.0744
B36: Delivered By

Sheet 2
A2: Elite MARKETING
A3: 44A- Gulberg Lahore | K3: Invoice No # : | N3: 2 | XFC3: Filer | XFD3: 0.005
A4: STRN / NTN :3808207-1 | K4: Date/Day : | N4: =TODAY() -> 46178 | XFC4: Non-filer | XFD4: 0.025
A5: Customer Name : Smart Mart | K5: Order Date : | N5: =N4-1 -> 46177
A6: Address: Bibi pak daman | K6: Order Name : | N6: Zahid Rafique | XFC6: Registered | XFD6: 0.18
XFC7: Un-registered | XFD7: 0.22
XFD9: Yes
A10: NTN/CNIC Number: | K10: Invoice Status : | N10: Serviced | XFD10: No
B11: Non-filer | C11: =IF($O34>2.49%,"No","Yes") -> No | K11: Order at Original Location : | N11: Yes
A12: STRN Number: | B12: Un-registered | C12: =IF($O32>21.99%,"No","Yes") -> No | K12: Reference Invoice : | XFD12: Monday/Tuesday
L13: 0.05 | XFD13: Tuesday / Wednesday
A14: Product Code/Description | C14: GM/ Pack | D14: CTN | E14: R.P Per | F14: T.P Per | G14: Sale QTY | I14: Gross Amount Excl. Taxes | J14: Trade Offer & Discount | M14: After Discount Amount | N14: GST | O14: Adv. Tax 236H | P14: Invoice | XFD14: Wednesday/Thursday
D15: SIZE | E15: Unit | F15: Unit | G15: CTN | H15: Pack | J15: FOC Qty | K15: Trade Offer | L15: Pass On | N15: =IF(B12="Registered",18%,22%) -> 0.22 | O15: =IF(B11="Filer",0.5%,2.5%) -> 0.025 | P15: Amount | XFD15: Thursday /Friday
A16: BCN | B16: =VLOOKUP($A16,'[1]Cust. Price List'!$D$6:$O$14,2,0) -> Meat Masala | C16: =VLOOKUP(A16,'[1]Cust. Price List'!D6:M14,3,0) -> 70 | D16: =VLOOKUP(A16,'[1]Cust. Price List'!D6:M14,4,0) -> 40 | E16: =VLOOKUP(A16,'[1]Cust. Price List'!D6:M14,6,0) -> 65 | F16: =VLOOKUP(A16,'[1]Cust. Price List'!D6:M14,10,0) -> 52.4625 | I16: =(G16*D16)*F16+H16*F16 -> 0 | K16: =I16*$K$13 -> 0 | L16: =I16*8% -> 0 | M16: =I16-K16-L16 -> 0 | N16: =(M16*$N$15)+(J16*F16)*$N$15 -> 0 | O16: =(N16+M16)*$O$15 -> 0 | P16: =M16+N16+O16 -> 0 | XFD16: Friday / Saturday
A17: VTN | B17: =VLOOKUP($A17,'[1]Cust. Price List'!$D$6:$O$14,2,0) -> Lemon Tarka | C17: =VLOOKUP(B17,'[1]Cust. Price List'!E7:P15,2,0) -> 70 | D17: =VLOOKUP(A17,'[1]Cust. Price List'!D7:M15,4,0) -> 40 | E17: =VLOOKUP(A17,'[1]Cust. Price List'!D7:M15,6,0) -> 65 | F17: =VLOOKUP(A17,'[1]Cust. Price List'!D7:M15,10,0) -> 52.4625 | I17: =(G17*D17)*F17+H17*F17 -> 0 | K17: =I17*$K$13 -> 0 | L17: =I17*8% -> 0 | M17: =I17-K17-L17 -> 0 | N17: =(M17*$N$15)+(J17*F17)*$N$15 -> 0 | O17: =(N17+M17)*$O$15 -> 0 | P17: =M17+N17+O17 -> 0 | XFD17: Saturday /Monday
A18: CCN | B18: =VLOOKUP($A18,'[1]Cust. Price List'!$D$6:$O$14,2,0) -> Chicken Chatkhara | C18: =VLOOKUP(B18,'[1]Cust. Price List'!E8:P16,2,0) -> 70 | D18: =VLOOKUP(A18,'[1]Cust. Price List'!D8:M16,4,0) -> 40 | E18: =VLOOKUP(A18,'[1]Cust. Price List'!D8:M16,6,0) -> 65 | F18: =VLOOKUP(A18,'[1]Cust. Price List'!D8:M16,10,0) -> 52.4625 | I18: =(G18*D18)*F18+H18*F18 -> 0 | K18: =I18*$K$13 -> 0 | L18: =I18*8% -> 0 | M18: =I18-K18-L18 -> 0 | N18: =(M18*$N$15)+(J18*F18)*$N$15 -> 0 | O18: =(N18+M18)*$O$15 -> 0 | P18: =M18+N18+O18 -> 0
A19: BCNJ | B19: =VLOOKUP($A19,'[1]Cust. Price List'!$D$6:$O$14,2,0) -> Meat Masala (Jumbo) | C19: =VLOOKUP(B19,'[1]Cust. Price List'!E9:P17,2,0) -> 120 | D19: =VLOOKUP(A19,'[1]Cust. Price List'!D9:M17,4,0) -> 40 | E19: =VLOOKUP(A19,'[1]Cust. Price List'!D9:M17,6,0) -> 90 | F19: =VLOOKUP(A19,'[1]Cust. Price List'!D9:M17,10,0) -> 72.64 | G19: 1 | I19: =(G19*D19)*F19+H19*F19 -> 2905.6 | J19: 2 | K19: =I19*$K$13 -> 0 | L19: =I19*8% -> 232.448 | M19: =I19-K19-L19 -> 2673.152 | N19: =(M19*$N$15)+(J19*F19)*$N$15 -> 620.05504 | O19: =(N19+M19)*$O$15 -> 82.330176 | P19: =M19+N19+O19 -> 3375.5372
A20: VTNJ | B20: =VLOOKUP($A20,'[1]Cust. Price List'!$D$6:$O$14,2,0) -> Lemon Tarka (Jumbo) | C20: =VLOOKUP(B20,'[1]Cust. Price List'!E10:P18,2,0) -> 120 | D20: =VLOOKUP(A20,'[1]Cust. Price List'!D10:M18,4,0) -> 40 | E20: =VLOOKUP(A20,'[1]Cust. Price List'!D10:M18,6,0) -> 90 | F20: =VLOOKUP(A20,'[1]Cust. Price List'!D10:M18,10,0) -> 72.64 | G20: 1 | I20: =(G20*D20)*F20+H20*F20 -> 2905.6 | J20: 2 | K20: =I20*$K$13 -> 0 | L20: =I20*8% -> 232.448 | M20: =I20-K20-L20 -> 2673.152 | N20: =(M20*$N$15)+(J20*F20)*$N$15 -> 620.05504 | O20: =(N20+M20)*$O$15 -> 82.330176 | P20: =M20+N20+O20 -> 3375.5372
A21: CCNJ | B21: =VLOOKUP($A21,'[1]Cust. Price List'!$D$6:$O$14,2,0) -> Chicken Chatkhara (Jumbo) | C21: =VLOOKUP(B21,'[1]Cust. Price List'!E11:P19,2,0) -> 120 | D21: =VLOOKUP(A21,'[1]Cust. Price List'!D11:M19,4,0) -> 40 | E21: =VLOOKUP(A21,'[1]Cust. Price List'!D11:M19,6,0) -> 90 | F21: =VLOOKUP(A21,'[1]Cust. Price List'!D11:M19,10,0) -> 72.64 | G21: 1 | I21: =(G21*D21)*F21+H21*F21 -> 2905.6 | J21: 2 | K21: =I21*$K$13 -> 0 | L21: =I21*8% -> 232.448 | M21: =I21-K21-L21 -> 2673.152 | N21: =(M21*$N$15)+(J21*F21)*$N$15 -> 620.05504 | O21: =(N21+M21)*$O$15 -> 82.330176 | P21: =M21+N21+O21 -> 3375.5372
A22: CCE | B22: =VLOOKUP($A22,'[1]Cust. Price List'!$D$6:$O$14,2,0) -> Chicken Chatkhara (ECO) | C22: =VLOOKUP(B22,'[1]Cust. Price List'!E12:P20,2,0) -> 60 | D22: =VLOOKUP(A22,'[1]Cust. Price List'!D12:M20,4,0) -> 40 | E22: =VLOOKUP(A22,'[1]Cust. Price List'!D12:M20,6,0) -> 50 | F22: =VLOOKUP(A22,'[1]Cust. Price List'!D12:M20,10,0) -> 39.23 | I22: =(G22*D22)*F22+H22*F22 -> 0 | K22: =I22*3.5% -> 0 | L22: =I22*5% -> 0 | M22: =I22-K22-L22 -> 0 | N22: =(M22*$N$15)+(J22*F22)*$N$15 -> 0 | O22: =(N22+M22)*$O$15 -> 0 | P22: =M22+N22+O22 -> 0
A23: VTE | B23: =VLOOKUP($A23,'[1]Cust. Price List'!$D$6:$O$14,2,0) -> Lemon Tarka (ECO) | C23: =VLOOKUP(B23,'[1]Cust. Price List'!E13:P21,2,0) -> 60 | D23: =VLOOKUP(A23,'[1]Cust. Price List'!D13:M21,4,0) -> 40 | E23: =VLOOKUP(A23,'[1]Cust. Price List'!D13:M21,6,0) -> 50 | F23: =VLOOKUP(A23,'[1]Cust. Price List'!D13:M21,10,0) -> 39.23 | I23: =(G23*D23)*F23+H23*F23 -> 0 | K23: =I23*3.5% -> 0 | L23: =I23*$L$13 -> 0 | M23: =I23-K23-L23 -> 0 | N23: =(M23*$N$15)+(J23*F23)*$N$15 -> 0 | O23: =(N23+M23)*$O$15 -> 0 | P23: =M23+N23+O23 -> 0
A24: BCE | B24: =VLOOKUP($A24,'[1]Cust. Price List'!$D$6:$O$14,2,0) -> Meat Masala (ECO) | C24: =VLOOKUP(B24,'[1]Cust. Price List'!E14:P22,2,0) -> 60 | D24: =VLOOKUP(A24,'[1]Cust. Price List'!D14:M22,4,0) -> 40 | E24: =VLOOKUP(A24,'[1]Cust. Price List'!D14:M22,6,0) -> 50 | F24: =VLOOKUP(A24,'[1]Cust. Price List'!D14:M22,10,0) -> 39.23 | I24: =(G24*D24)*F24+H24*F24 -> 0 | K24: =I24*3.5% -> 0 | L24: =I24*$L$13 -> 0 | M24: =I24-K24-L24 -> 0 | N24: =(M24*$N$15)+(J24*F24)*$N$15 -> 0 | O24: =(N24+M24)*$O$15 -> 0 | P24: =M24+N24+O24 -> 0
A25: Total | G25: =SUM(G16:G24) -> 3 | H25: =SUM(H16:H24) -> 0 | I25: =SUM(I16:I24) -> 8716.8 | K25: =SUM(K16:K24) -> 0 | L25: =SUM(L16:L24) -> 697.344 | M25: =SUM(M16:M24) -> 8019.456 | N25: =SUM(N16:N24) -> 1860.1651 | O25: =SUM(O16:O24) -> 246.99053 | P25: =SUM(P16:P24) -> 10126.612
B28: یکم جولائی 2024سے نئی ٹیکس ترمیم کے مطابق، ایف بی آر سیکشن 236 ایچ کے مطابق، فائلرز کے لیے ہر سیل انوائس پر 0.5% اور نان فائلرز کے لیے 2.5% ایڈوانس ود ہولڈنگ ٹیکس وصول کیا جائے گا۔ | N28: Gross Amount: | P28: =I25 -> 8716.8
N29: Regular Discount | P29: =L25 -> 697.344
N30: Trade Offre | P30: =K25 -> 0
N31: After Dis. Amount | P31: =P28-P29-P30 -> 8019.456
N32: Total GST: | O32: =IF(B12="Registered",18%,22%) -> 0.22 | P32: =N25 -> 1860.1651
N33: Net Amount: | P33: =P31+P32 -> 9879.6211
N34: Ad.Tax | O34: =IF(B11="Filer",0.5%,2.5%) -> 0.025 | P34: =O34*P33 -> 246.99053
N35: Net Amount with Ad.Tax | P35: =P33+P34 -> 10126.612
B36: Delivered By

Sheet 3
A2: Elite MARKETING
A3: 44A- Gulberg Lahore | K3: Invoice No # : | N3: 4 | XFC3: Filer | XFD3: 0.005
A4: STRN / NTN :3808207-1 | K4: Date/Day : | N4: =TODAY() -> 46178 | XFC4: Non-filer | XFD4: 0.025
A5: Customer Name : Haneef Store | K5: Order Date : | N5: =N4-1 -> 46177
A6: Address: Bibi pak daman | K6: Order Name : | N6: Zahid Rafique | XFC6: Registered | XFD6: 0.18
XFC7: Un-registered | XFD7: 0.22
XFD9: Yes
A10: NTN/CNIC Number: | K10: Invoice Status : | N10: Serviced | XFD10: No
B11: Non-filer | C11: =IF($O34>2.49%,"No","Yes") -> No | K11: Order at Original Location : | N11: Yes
A12: STRN Number: | B12: Un-registered | C12: =IF($O32>21.99%,"No","Yes") -> No | K12: Reference Invoice : | XFD12: Monday/Tuesday
L13: 0.05 | XFD13: Tuesday / Wednesday
A14: Product Code/Description | C14: GM/ Pack | D14: CTN | E14: R.P Per | F14: T.P Per | G14: Sale QTY | I14: Gross Amount Excl. Taxes | J14: Trade Offer & Discount | M14: After Discount Amount | N14: GST | O14: Adv. Tax 236H | P14: Invoice | XFD14: Wednesday/Thursday
D15: SIZE | E15: Unit | F15: Unit | G15: CTN | H15: Pack | J15: FOC Qty | K15: Trade Offer | L15: Pass On | N15: =IF(B12="Registered",18%,22%) -> 0.22 | O15: =IF(B11="Filer",0.5%,2.5%) -> 0.025 | P15: Amount | XFD15: Thursday /Friday
A16: BCN | B16: =VLOOKUP($A16,'[1]Cust. Price List'!$D$6:$O$14,2,0) -> Meat Masala | C16: =VLOOKUP(A16,'[1]Cust. Price List'!D6:M14,3,0) -> 70 | D16: =VLOOKUP(A16,'[1]Cust. Price List'!D6:M14,4,0) -> 40 | E16: =VLOOKUP(A16,'[1]Cust. Price List'!D6:M14,6,0) -> 65 | F16: =VLOOKUP(A16,'[1]Cust. Price List'!D6:M14,10,0) -> 52.4625 | H16: 12 | I16: =(G16*D16)*F16+H16*F16 -> 629.55 | K16: =I16*$K$13 -> 0 | L16: =I16*8% -> 50.364 | M16: =I16-K16-L16 -> 579.186 | N16: =(M16*$N$15)+(J16*F16)*$N$15 -> 127.42092 | O16: =(N16+M16)*$O$15 -> 17.665173 | P16: =M16+N16+O16 -> 724.27209 | XFD16: Friday / Saturday
A17: VTN | B17: =VLOOKUP($A17,'[1]Cust. Price List'!$D$6:$O$14,2,0) -> Lemon Tarka | C17: =VLOOKUP(B17,'[1]Cust. Price List'!E7:P15,2,0) -> 70 | D17: =VLOOKUP(A17,'[1]Cust. Price List'!D7:M15,4,0) -> 40 | E17: =VLOOKUP(A17,'[1]Cust. Price List'!D7:M15,6,0) -> 65 | F17: =VLOOKUP(A17,'[1]Cust. Price List'!D7:M15,10,0) -> 52.4625 | H17: 12 | I17: =(G17*D17)*F17+H17*F17 -> 629.55 | K17: =I17*$K$13 -> 0 | L17: =I17*8% -> 50.364 | M17: =I17-K17-L17 -> 579.186 | N17: =(M17*$N$15)+(J17*F17)*$N$15 -> 127.42092 | O17: =(N17+M17)*$O$15 -> 17.665173 | P17: =M17+N17+O17 -> 724.27209 | XFD17: Saturday /Monday
A18: CCN | B18: =VLOOKUP($A18,'[1]Cust. Price List'!$D$6:$O$14,2,0) -> Chicken Chatkhara | C18: =VLOOKUP(B18,'[1]Cust. Price List'!E8:P16,2,0) -> 70 | D18: =VLOOKUP(A18,'[1]Cust. Price List'!D8:M16,4,0) -> 40 | E18: =VLOOKUP(A18,'[1]Cust. Price List'!D8:M16,6,0) -> 65 | F18: =VLOOKUP(A18,'[1]Cust. Price List'!D8:M16,10,0) -> 52.4625 | I18: =(G18*D18)*F18+H18*F18 -> 0 | K18: =I18*$K$13 -> 0 | L18: =I18*8% -> 0 | M18: =I18-K18-L18 -> 0 | N18: =(M18*$N$15)+(J18*F18)*$N$15 -> 0 | O18: =(N18+M18)*$O$15 -> 0 | P18: =M18+N18+O18 -> 0
A19: BCNJ | B19: =VLOOKUP($A19,'[1]Cust. Price List'!$D$6:$O$14,2,0) -> Meat Masala (Jumbo) | C19: =VLOOKUP(B19,'[1]Cust. Price List'!E9:P17,2,0) -> 120 | D19: =VLOOKUP(A19,'[1]Cust. Price List'!D9:M17,4,0) -> 40 | E19: =VLOOKUP(A19,'[1]Cust. Price List'!D9:M17,6,0) -> 90 | F19: =VLOOKUP(A19,'[1]Cust. Price List'!D9:M17,10,0) -> 72.64 | I19: =(G19*D19)*F19+H19*F19 -> 0 | K19: =I19*$K$13 -> 0 | L19: =I19*8% -> 0 | M19: =I19-K19-L19 -> 0 | N19: =(M19*$N$15)+(J19*F19)*$N$15 -> 0 | O19: =(N19+M19)*$O$15 -> 0 | P19: =M19+N19+O19 -> 0
A20: VTNJ | B20: =VLOOKUP($A20,'[1]Cust. Price List'!$D$6:$O$14,2,0) -> Lemon Tarka (Jumbo) | C20: =VLOOKUP(B20,'[1]Cust. Price List'!E10:P18,2,0) -> 120 | D20: =VLOOKUP(A20,'[1]Cust. Price List'!D10:M18,4,0) -> 40 | E20: =VLOOKUP(A20,'[1]Cust. Price List'!D10:M18,6,0) -> 90 | F20: =VLOOKUP(A20,'[1]Cust. Price List'!D10:M18,10,0) -> 72.64 | I20: =(G20*D20)*F20+H20*F20 -> 0 | K20: =I20*$K$13 -> 0 | L20: =I20*8% -> 0 | M20: =I20-K20-L20 -> 0 | N20: =(M20*$N$15)+(J20*F20)*$N$15 -> 0 | O20: =(N20+M20)*$O$15 -> 0 | P20: =M20+N20+O20 -> 0
A21: CCNJ | B21: =VLOOKUP($A21,'[1]Cust. Price List'!$D$6:$O$14,2,0) -> Chicken Chatkhara (Jumbo) | C21: =VLOOKUP(B21,'[1]Cust. Price List'!E11:P19,2,0) -> 120 | D21: =VLOOKUP(A21,'[1]Cust. Price List'!D11:M19,4,0) -> 40 | E21: =VLOOKUP(A21,'[1]Cust. Price List'!D11:M19,6,0) -> 90 | F21: =VLOOKUP(A21,'[1]Cust. Price List'!D11:M19,10,0) -> 72.64 | I21: =(G21*D21)*F21+H21*F21 -> 0 | K21: =I21*$K$13 -> 0 | L21: =I21*8% -> 0 | M21: =I21-K21-L21 -> 0 | N21: =(M21*$N$15)+(J21*F21)*$N$15 -> 0 | O21: =(N21+M21)*$O$15 -> 0 | P21: =M21+N21+O21 -> 0
A22: CCE | B22: =VLOOKUP($A22,'[1]Cust. Price List'!$D$6:$O$14,2,0) -> Chicken Chatkhara (ECO) | C22: =VLOOKUP(B22,'[1]Cust. Price List'!E12:P20,2,0) -> 60 | D22: =VLOOKUP(A22,'[1]Cust. Price List'!D12:M20,4,0) -> 40 | E22: =VLOOKUP(A22,'[1]Cust. Price List'!D12:M20,6,0) -> 50 | F22: =VLOOKUP(A22,'[1]Cust. Price List'!D12:M20,10,0) -> 39.23 | H22: 12 | I22: =(G22*D22)*F22+H22*F22 -> 470.76 | K22: =I22*3.5% -> 16.4766 | L22: =I22*5% -> 23.538 | M22: =I22-K22-L22 -> 430.7454 | N22: =(M22*$N$15)+(J22*F22)*$N$15 -> 94.763988 | O22: =(N22+M22)*$O$15 -> 13.137735 | P22: =M22+N22+O22 -> 538.64712
A23: VTE | B23: =VLOOKUP($A23,'[1]Cust. Price List'!$D$6:$O$14,2,0) -> Lemon Tarka (ECO) | C23: =VLOOKUP(B23,'[1]Cust. Price List'!E13:P21,2,0) -> 60 | D23: =VLOOKUP(A23,'[1]Cust. Price List'!D13:M21,4,0) -> 40 | E23: =VLOOKUP(A23,'[1]Cust. Price List'!D13:M21,6,0) -> 50 | F23: =VLOOKUP(A23,'[1]Cust. Price List'!D13:M21,10,0) -> 39.23 | I23: =(G23*D23)*F23+H23*F23 -> 0 | K23: =I23*3.5% -> 0 | L23: =I23*$L$13 -> 0 | M23: =I23-K23-L23 -> 0 | N23: =(M23*$N$15)+(J23*F23)*$N$15 -> 0 | O23: =(N23+M23)*$O$15 -> 0 | P23: =M23+N23+O23 -> 0
A24: BCE | B24: =VLOOKUP($A24,'[1]Cust. Price List'!$D$6:$O$14,2,0) -> Meat Masala (ECO) | C24: =VLOOKUP(B24,'[1]Cust. Price List'!E14:P22,2,0) -> 60 | D24: =VLOOKUP(A24,'[1]Cust. Price List'!D14:M22,4,0) -> 40 | E24: =VLOOKUP(A24,'[1]Cust. Price List'!D14:M22,6,0) -> 50 | F24: =VLOOKUP(A24,'[1]Cust. Price List'!D14:M22,10,0) -> 39.23 | I24: =(G24*D24)*F24+H24*F24 -> 0 | K24: =I24*3.5% -> 0 | L24: =I24*$L$13 -> 0 | M24: =I24-K24-L24 -> 0 | N24: =(M24*$N$15)+(J24*F24)*$N$15 -> 0 | O24: =(N24+M24)*$O$15 -> 0 | P24: =M24+N24+O24 -> 0
A25: Total | G25: =SUM(G16:G24) -> 0 | H25: =SUM(H16:H24) -> 36 | I25: =SUM(I16:I24) -> 1729.86 | K25: =SUM(K16:K24) -> 16.4766 | L25: =SUM(L16:L24) -> 124.266 | M25: =SUM(M16:M24) -> 1589.1174 | N25: =SUM(N16:N24) -> 349.60583 | O25: =SUM(O16:O24) -> 48.468081 | P25: =SUM(P16:P24) -> 1987.1913
B28: یکم جولائی 2024سے نئی ٹیکس ترمیم کے مطابق، ایف بی آر سیکشن 236 ایچ کے مطابق، فائلرز کے لیے ہر سیل انوائس پر 0.5% اور نان فائلرز کے لیے 2.5% ایڈوانس ود ہولڈنگ ٹیکس وصول کیا جائے گا۔ | N28: Gross Amount: | P28: =I25 -> 1729.86
N29: Regular Discount | P29: =L25 -> 124.266
N30: Trade Offre | P30: =K25 -> 16.4766
N31: After Dis. Amount | P31: =P28-P29-P30 -> 1589.1174
N32: Total GST: | O32: =IF(B12="Registered",18%,22%) -> 0.22 | P32: =N25 -> 349.60583
N33: Net Amount: | P33: =P31+P32 -> 1938.7232
N34: Ad.Tax | O34: =IF(B11="Filer",0.5%,2.5%) -> 0.025 | P34: =O34*P33 -> 48.468081
N35: Net Amount with Ad.Tax | P35: =P33+P34 -> 1987.1913
B36: Delivered By

Sheet 4
A2: Elite MARKETING
A3: 44A- Gulberg Lahore | K3: Invoice No # : | N3: 3 | XFC3: Filer | XFD3: 0.005
A4: STRN / NTN :3808207-1 | K4: Date/Day : | N4: =TODAY() -> 46178 | XFC4: Non-filer | XFD4: 0.025
A5: Customer Name : Nazeer Store | K5: Order Date : | N5: =N4-1 -> 46177
A6: Address: Bibi pak daman | K6: Order Name : | N6: Zahid Rafique | XFC6: Registered | XFD6: 0.18
XFC7: Un-registered | XFD7: 0.22
XFD9: Yes
A10: NTN/CNIC Number: | K10: Invoice Status : | N10: Serviced | XFD10: No
B11: Non-filer | C11: =IF($O34>2.49%,"No","Yes") -> No | K11: Order at Original Location : | N11: Yes
A12: STRN Number: | B12: Registered | C12: =IF($O32>21.99%,"No","Yes") -> Yes | K12: Reference Invoice : | XFD12: Monday/Tuesday
L13: 0.05 | XFD13: Tuesday / Wednesday
A14: Product Code/Description | C14: GM/ Pack | D14: CTN | E14: R.P Per | F14: T.P Per | G14: Sale QTY | I14: Gross Amount Excl. Taxes | J14: Trade Offer & Discount | M14: After Discount Amount | N14: GST | O14: Adv. Tax 236H | P14: Invoice | XFD14: Wednesday/Thursday
D15: SIZE | E15: Unit | F15: Unit | G15: CTN | H15: Pack | J15: FOC Qty | K15: Trade Offer | L15: Pass On | N15: =IF(B12="Registered",18%,22%) -> 0.18 | O15: =IF(B11="Filer",0.5%,2.5%) -> 0.025 | P15: Amount | XFD15: Thursday /Friday
A16: BCN | B16: =VLOOKUP($A16,'[1]Cust. Price List'!$D$6:$O$14,2,0) -> Meat Masala | C16: =VLOOKUP(A16,'[1]Cust. Price List'!D6:M14,3,0) -> 70 | D16: =VLOOKUP(A16,'[1]Cust. Price List'!D6:M14,4,0) -> 40 | E16: =VLOOKUP(A16,'[1]Cust. Price List'!D6:M14,6,0) -> 65 | F16: =VLOOKUP(A16,'[1]Cust. Price List'!D6:M14,10,0) -> 52.4625 | H16: 20 | I16: =(G16*D16)*F16+H16*F16 -> 1049.25 | J16: 1 | K16: =I16*$K$13 -> 0 | L16: =I16*8% -> 83.94 | M16: =I16-K16-L16 -> 965.31 | N16: =(M16*$N$15)+(J16*F16)*$N$15 -> 183.19905 | O16: =(N16+M16)*$O$15 -> 28.712726 | P16: =M16+N16+O16 -> 1177.2218 | XFD16: Friday / Saturday
A17: VTN | B17: =VLOOKUP($A17,'[1]Cust. Price List'!$D$6:$O$14,2,0) -> Lemon Tarka | C17: =VLOOKUP(B17,'[1]Cust. Price List'!E7:P15,2,0) -> 70 | D17: =VLOOKUP(A17,'[1]Cust. Price List'!D7:M15,4,0) -> 40 | E17: =VLOOKUP(A17,'[1]Cust. Price List'!D7:M15,6,0) -> 65 | F17: =VLOOKUP(A17,'[1]Cust. Price List'!D7:M15,10,0) -> 52.4625 | I17: =(G17*D17)*F17+H17*F17 -> 0 | K17: =I17*$K$13 -> 0 | L17: =I17*8% -> 0 | M17: =I17-K17-L17 -> 0 | N17: =(M17*$N$15)+(J17*F17)*$N$15 -> 0 | O17: =(N17+M17)*$O$15 -> 0 | P17: =M17+N17+O17 -> 0 | XFD17: Saturday /Monday
A18: CCN | B18: =VLOOKUP($A18,'[1]Cust. Price List'!$D$6:$O$14,2,0) -> Chicken Chatkhara | C18: =VLOOKUP(B18,'[1]Cust. Price List'!E8:P16,2,0) -> 70 | D18: =VLOOKUP(A18,'[1]Cust. Price List'!D8:M16,4,0) -> 40 | E18: =VLOOKUP(A18,'[1]Cust. Price List'!D8:M16,6,0) -> 65 | F18: =VLOOKUP(A18,'[1]Cust. Price List'!D8:M16,10,0) -> 52.4625 | I18: =(G18*D18)*F18+H18*F18 -> 0 | K18: =I18*$K$13 -> 0 | L18: =I18*8% -> 0 | M18: =I18-K18-L18 -> 0 | N18: =(M18*$N$15)+(J18*F18)*$N$15 -> 0 | O18: =(N18+M18)*$O$15 -> 0 | P18: =M18+N18+O18 -> 0
A19: BCNJ | B19: =VLOOKUP($A19,'[1]Cust. Price List'!$D$6:$O$14,2,0) -> Meat Masala (Jumbo) | C19: =VLOOKUP(B19,'[1]Cust. Price List'!E9:P17,2,0) -> 120 | D19: =VLOOKUP(A19,'[1]Cust. Price List'!D9:M17,4,0) -> 40 | E19: =VLOOKUP(A19,'[1]Cust. Price List'!D9:M17,6,0) -> 90 | F19: =VLOOKUP(A19,'[1]Cust. Price List'!D9:M17,10,0) -> 72.64 | I19: =(G19*D19)*F19+H19*F19 -> 0 | K19: =I19*$K$13 -> 0 | L19: =I19*8% -> 0 | M19: =I19-K19-L19 -> 0 | N19: =(M19*$N$15)+(J19*F19)*$N$15 -> 0 | O19: =(N19+M19)*$O$15 -> 0 | P19: =M19+N19+O19 -> 0
A20: VTNJ | B20: =VLOOKUP($A20,'[1]Cust. Price List'!$D$6:$O$14,2,0) -> Lemon Tarka (Jumbo) | C20: =VLOOKUP(B20,'[1]Cust. Price List'!E10:P18,2,0) -> 120 | D20: =VLOOKUP(A20,'[1]Cust. Price List'!D10:M18,4,0) -> 40 | E20: =VLOOKUP(A20,'[1]Cust. Price List'!D10:M18,6,0) -> 90 | F20: =VLOOKUP(A20,'[1]Cust. Price List'!D10:M18,10,0) -> 72.64 | I20: =(G20*D20)*F20+H20*F20 -> 0 | K20: =I20*$K$13 -> 0 | L20: =I20*8% -> 0 | M20: =I20-K20-L20 -> 0 | N20: =(M20*$N$15)+(J20*F20)*$N$15 -> 0 | O20: =(N20+M20)*$O$15 -> 0 | P20: =M20+N20+O20 -> 0
A21: CCNJ | B21: =VLOOKUP($A21,'[1]Cust. Price List'!$D$6:$O$14,2,0) -> Chicken Chatkhara (Jumbo) | C21: =VLOOKUP(B21,'[1]Cust. Price List'!E11:P19,2,0) -> 120 | D21: =VLOOKUP(A21,'[1]Cust. Price List'!D11:M19,4,0) -> 40 | E21: =VLOOKUP(A21,'[1]Cust. Price List'!D11:M19,6,0) -> 90 | F21: =VLOOKUP(A21,'[1]Cust. Price List'!D11:M19,10,0) -> 72.64 | I21: =(G21*D21)*F21+H21*F21 -> 0 | K21: =I21*$K$13 -> 0 | L21: =I21*8% -> 0 | M21: =I21-K21-L21 -> 0 | N21: =(M21*$N$15)+(J21*F21)*$N$15 -> 0 | O21: =(N21+M21)*$O$15 -> 0 | P21: =M21+N21+O21 -> 0
A22: CCE | B22: =VLOOKUP($A22,'[1]Cust. Price List'!$D$6:$O$14,2,0) -> Chicken Chatkhara (ECO) | C22: =VLOOKUP(B22,'[1]Cust. Price List'!E12:P20,2,0) -> 60 | D22: =VLOOKUP(A22,'[1]Cust. Price List'!D12:M20,4,0) -> 40 | E22: =VLOOKUP(A22,'[1]Cust. Price List'!D12:M20,6,0) -> 50 | F22: =VLOOKUP(A22,'[1]Cust. Price List'!D12:M20,10,0) -> 39.23 | H22: 24 | I22: =(G22*D22)*F22+H22*F22 -> 941.52 | K22: =I22*3.5% -> 32.9532 | L22: =I22*5% -> 47.076 | M22: =I22-K22-L22 -> 861.4908 | N22: =(M22*$N$15)+(J22*F22)*$N$15 -> 155.06834 | O22: =(N22+M22)*$O$15 -> 25.413979 | P22: =M22+N22+O22 -> 1041.9731
A23: VTE | B23: =VLOOKUP($A23,'[1]Cust. Price List'!$D$6:$O$14,2,0) -> Lemon Tarka (ECO) | C23: =VLOOKUP(B23,'[1]Cust. Price List'!E13:P21,2,0) -> 60 | D23: =VLOOKUP(A23,'[1]Cust. Price List'!D13:M21,4,0) -> 40 | E23: =VLOOKUP(A23,'[1]Cust. Price List'!D13:M21,6,0) -> 50 | F23: =VLOOKUP(A23,'[1]Cust. Price List'!D13:M21,10,0) -> 39.23 | I23: =(G23*D23)*F23+H23*F23 -> 0 | K23: =I23*3.5% -> 0 | L23: =I23*$L$13 -> 0 | M23: =I23-K23-L23 -> 0 | N23: =(M23*$N$15)+(J23*F23)*$N$15 -> 0 | O23: =(N23+M23)*$O$15 -> 0 | P23: =M23+N23+O23 -> 0
A24: BCE | B24: =VLOOKUP($A24,'[1]Cust. Price List'!$D$6:$O$14,2,0) -> Meat Masala (ECO) | C24: =VLOOKUP(B24,'[1]Cust. Price List'!E14:P22,2,0) -> 60 | D24: =VLOOKUP(A24,'[1]Cust. Price List'!D14:M22,4,0) -> 40 | E24: =VLOOKUP(A24,'[1]Cust. Price List'!D14:M22,6,0) -> 50 | F24: =VLOOKUP(A24,'[1]Cust. Price List'!D14:M22,10,0) -> 39.23 | I24: =(G24*D24)*F24+H24*F24 -> 0 | K24: =I24*3.5% -> 0 | L24: =I24*$L$13 -> 0 | M24: =I24-K24-L24 -> 0 | N24: =(M24*$N$15)+(J24*F24)*$N$15 -> 0 | O24: =(N24+M24)*$O$15 -> 0 | P24: =M24+N24+O24 -> 0
A25: Total | G25: =SUM(G16:G24) -> 0 | H25: =SUM(H16:H24) -> 44 | I25: =SUM(I16:I24) -> 1990.77 | K25: =SUM(K16:K24) -> 32.9532 | L25: =SUM(L16:L24) -> 131.016 | M25: =SUM(M16:M24) -> 1826.8008 | N25: =SUM(N16:N24) -> 338.26739 | O25: =SUM(O16:O24) -> 54.126705 | P25: =SUM(P16:P24) -> 2219.1949
B28: یکم جولائی 2024سے نئی ٹیکس ترمیم کے مطابق، ایف بی آر سیکشن 236 ایچ کے مطابق، فائلرز کے لیے ہر سیل انوائس پر 0.5% اور نان فائلرز کے لیے 2.5% ایڈوانس ود ہولڈنگ ٹیکس وصول کیا جائے گا۔ | N28: Gross Amount: | P28: =I25 -> 1990.77
N29: Regular Discount | P29: =L25 -> 131.016
N30: Trade Offre | P30: =K25 -> 32.9532
N31: After Dis. Amount | P31: =P28-P29-P30 -> 1826.8008
N32: Total GST: | O32: =IF(B12="Registered",18%,22%) -> 0.18 | P32: =N25 -> 338.26739
N33: Net Amount: | P33: =P31+P32 -> 2165.0682
N34: Ad.Tax | O34: =IF(B11="Filer",0.5%,2.5%) -> 0.025 | P34: =O34*P33 -> 54.126705
N35: Net Amount with Ad.Tax | P35: =P33+P34 -> 2219.1949
B36: Delivered By

Sheet 5
A2: Elite MARKETING
A3: 44A- Gulberg Lahore | K3: Invoice No # : | N3: 5 | XFC3: Filer | XFD3: 0.005
A4: STRN / NTN :3808207-1 | K4: Date/Day : | N4: =TODAY() -> 46178 | XFC4: Non-filer | XFD4: 0.025
A5: Customer Name : Tufail Store | K5: Order Date : | N5: =N4-1 -> 46177
A6: Address: Police line | K6: Order Name : | N6: Zahid Rafique | XFC6: Registered | XFD6: 0.18
XFC7: Un-registered | XFD7: 0.22
XFD9: Yes
A10: NTN/CNIC Number: | K10: Invoice Status : | N10: Serviced | XFD10: No
B11: Non-filer | C11: =IF($O34>2.49%,"No","Yes") -> No | K11: Order at Original Location : | N11: Yes
A12: STRN Number: | B12: Un-registered | C12: =IF($O32>21.99%,"No","Yes") -> No | K12: Reference Invoice : | XFD12: Monday/Tuesday
L13: 0.05 | XFD13: Tuesday / Wednesday
A14: Product Code/Description | C14: GM/ Pack | D14: CTN | E14: R.P Per | F14: T.P Per | G14: Sale QTY | I14: Gross Amount Excl. Taxes | J14: Trade Offer & Discount | M14: After Discount Amount | N14: GST | O14: Adv. Tax 236H | P14: Invoice | XFD14: Wednesday/Thursday
D15: SIZE | E15: Unit | F15: Unit | G15: CTN | H15: Pack | J15: FOC Qty | K15: Trade Offer | L15: Pass On | N15: =IF(B12="Registered",18%,22%) -> 0.22 | O15: =IF(B11="Filer",0.5%,2.5%) -> 0.025 | P15: Amount | XFD15: Thursday /Friday
A16: BCN | B16: =VLOOKUP($A16,'[1]Cust. Price List'!$D$6:$O$14,2,0) -> Meat Masala | C16: =VLOOKUP(A16,'[1]Cust. Price List'!D6:M14,3,0) -> 70 | D16: =VLOOKUP(A16,'[1]Cust. Price List'!D6:M14,4,0) -> 40 | E16: =VLOOKUP(A16,'[1]Cust. Price List'!D6:M14,6,0) -> 65 | F16: =VLOOKUP(A16,'[1]Cust. Price List'!D6:M14,10,0) -> 52.4625 | H16: 25 | I16: =(G16*D16)*F16+H16*F16 -> 1311.5625 | J16: 1 | K16: =I16*$K$13 -> 0 | L16: =I16*8% -> 104.925 | M16: =I16-K16-L16 -> 1206.6375 | N16: =(M16*$N$15)+(J16*F16)*$N$15 -> 277.002 | O16: =(N16+M16)*$O$15 -> 37.090988 | P16: =M16+N16+O16 -> 1520.7305 | XFD16: Friday / Saturday
A17: VTN | B17: =VLOOKUP($A17,'[1]Cust. Price List'!$D$6:$O$14,2,0) -> Lemon Tarka | C17: =VLOOKUP(B17,'[1]Cust. Price List'!E7:P15,2,0) -> 70 | D17: =VLOOKUP(A17,'[1]Cust. Price List'!D7:M15,4,0) -> 40 | E17: =VLOOKUP(A17,'[1]Cust. Price List'!D7:M15,6,0) -> 65 | F17: =VLOOKUP(A17,'[1]Cust. Price List'!D7:M15,10,0) -> 52.4625 | H17: 15 | I17: =(G17*D17)*F17+H17*F17 -> 786.9375 | J17: 1 | K17: =I17*$K$13 -> 0 | L17: =I17*8% -> 62.955 | M17: =I17-K17-L17 -> 723.9825 | N17: =(M17*$N$15)+(J17*F17)*$N$15 -> 170.8179 | O17: =(N17+M17)*$O$15 -> 22.37001 | P17: =M17+N17+O17 -> 917.17041 | XFD17: Saturday /Monday
A18: CCN | B18: =VLOOKUP($A18,'[1]Cust. Price List'!$D$6:$O$14,2,0) -> Chicken Chatkhara | C18: =VLOOKUP(B18,'[1]Cust. Price List'!E8:P16,2,0) -> 70 | D18: =VLOOKUP(A18,'[1]Cust. Price List'!D8:M16,4,0) -> 40 | E18: =VLOOKUP(A18,'[1]Cust. Price List'!D8:M16,6,0) -> 65 | F18: =VLOOKUP(A18,'[1]Cust. Price List'!D8:M16,10,0) -> 52.4625 | I18: =(G18*D18)*F18+H18*F18 -> 0 | K18: =I18*$K$13 -> 0 | L18: =I18*8% -> 0 | M18: =I18-K18-L18 -> 0 | N18: =(M18*$N$15)+(J18*F18)*$N$15 -> 0 | O18: =(N18+M18)*$O$15 -> 0 | P18: =M18+N18+O18 -> 0
A19: BCNJ | B19: =VLOOKUP($A19,'[1]Cust. Price List'!$D$6:$O$14,2,0) -> Meat Masala (Jumbo) | C19: =VLOOKUP(B19,'[1]Cust. Price List'!E9:P17,2,0) -> 120 | D19: =VLOOKUP(A19,'[1]Cust. Price List'!D9:M17,4,0) -> 40 | E19: =VLOOKUP(A19,'[1]Cust. Price List'!D9:M17,6,0) -> 90 | F19: =VLOOKUP(A19,'[1]Cust. Price List'!D9:M17,10,0) -> 72.64 | I19: =(G19*D19)*F19+H19*F19 -> 0 | K19: =I19*$K$13 -> 0 | L19: =I19*8% -> 0 | M19: =I19-K19-L19 -> 0 | N19: =(M19*$N$15)+(J19*F19)*$N$15 -> 0 | O19: =(N19+M19)*$O$15 -> 0 | P19: =M19+N19+O19 -> 0
A20: VTNJ | B20: =VLOOKUP($A20,'[1]Cust. Price List'!$D$6:$O$14,2,0) -> Lemon Tarka (Jumbo) | C20: =VLOOKUP(B20,'[1]Cust. Price List'!E10:P18,2,0) -> 120 | D20: =VLOOKUP(A20,'[1]Cust. Price List'!D10:M18,4,0) -> 40 | E20: =VLOOKUP(A20,'[1]Cust. Price List'!D10:M18,6,0) -> 90 | F20: =VLOOKUP(A20,'[1]Cust. Price List'!D10:M18,10,0) -> 72.64 | I20: =(G20*D20)*F20+H20*F20 -> 0 | K20: =I20*$K$13 -> 0 | L20: =I20*8% -> 0 | M20: =I20-K20-L20 -> 0 | N20: =(M20*$N$15)+(J20*F20)*$N$15 -> 0 | O20: =(N20+M20)*$O$15 -> 0 | P20: =M20+N20+O20 -> 0
A21: CCNJ | B21: =VLOOKUP($A21,'[1]Cust. Price List'!$D$6:$O$14,2,0) -> Chicken Chatkhara (Jumbo) | C21: =VLOOKUP(B21,'[1]Cust. Price List'!E11:P19,2,0) -> 120 | D21: =VLOOKUP(A21,'[1]Cust. Price List'!D11:M19,4,0) -> 40 | E21: =VLOOKUP(A21,'[1]Cust. Price List'!D11:M19,6,0) -> 90 | F21: =VLOOKUP(A21,'[1]Cust. Price List'!D11:M19,10,0) -> 72.64 | I21: =(G21*D21)*F21+H21*F21 -> 0 | K21: =I21*$K$13 -> 0 | L21: =I21*8% -> 0 | M21: =I21-K21-L21 -> 0 | N21: =(M21*$N$15)+(J21*F21)*$N$15 -> 0 | O21: =(N21+M21)*$O$15 -> 0 | P21: =M21+N21+O21 -> 0
A22: CCE | B22: =VLOOKUP($A22,'[1]Cust. Price List'!$D$6:$O$14,2,0) -> Chicken Chatkhara (ECO) | C22: =VLOOKUP(B22,'[1]Cust. Price List'!E12:P20,2,0) -> 60 | D22: =VLOOKUP(A22,'[1]Cust. Price List'!D12:M20,4,0) -> 40 | E22: =VLOOKUP(A22,'[1]Cust. Price List'!D12:M20,6,0) -> 50 | F22: =VLOOKUP(A22,'[1]Cust. Price List'!D12:M20,10,0) -> 39.23 | I22: =(G22*D22)*F22+H22*F22 -> 0 | K22: =I22*3.5% -> 0 | L22: =I22*5% -> 0 | M22: =I22-K22-L22 -> 0 | N22: =(M22*$N$15)+(J22*F22)*$N$15 -> 0 | O22: =(N22+M22)*$O$15 -> 0 | P22: =M22+N22+O22 -> 0
A23: VTE | B23: =VLOOKUP($A23,'[1]Cust. Price List'!$D$6:$O$14,2,0) -> Lemon Tarka (ECO) | C23: =VLOOKUP(B23,'[1]Cust. Price List'!E13:P21,2,0) -> 60 | D23: =VLOOKUP(A23,'[1]Cust. Price List'!D13:M21,4,0) -> 40 | E23: =VLOOKUP(A23,'[1]Cust. Price List'!D13:M21,6,0) -> 50 | F23: =VLOOKUP(A23,'[1]Cust. Price List'!D13:M21,10,0) -> 39.23 | I23: =(G23*D23)*F23+H23*F23 -> 0 | K23: =I23*3.5% -> 0 | L23: =I23*$L$13 -> 0 | M23: =I23-K23-L23 -> 0 | N23: =(M23*$N$15)+(J23*F23)*$N$15 -> 0 | O23: =(N23+M23)*$O$15 -> 0 | P23: =M23+N23+O23 -> 0
A24: BCE | B24: =VLOOKUP($A24,'[1]Cust. Price List'!$D$6:$O$14,2,0) -> Meat Masala (ECO) | C24: =VLOOKUP(B24,'[1]Cust. Price List'!E14:P22,2,0) -> 60 | D24: =VLOOKUP(A24,'[1]Cust. Price List'!D14:M22,4,0) -> 40 | E24: =VLOOKUP(A24,'[1]Cust. Price List'!D14:M22,6,0) -> 50 | F24: =VLOOKUP(A24,'[1]Cust. Price List'!D14:M22,10,0) -> 39.23 | I24: =(G24*D24)*F24+H24*F24 -> 0 | K24: =I24*3.5% -> 0 | L24: =I24*$L$13 -> 0 | M24: =I24-K24-L24 -> 0 | N24: =(M24*$N$15)+(J24*F24)*$N$15 -> 0 | O24: =(N24+M24)*$O$15 -> 0 | P24: =M24+N24+O24 -> 0
A25: Total | G25: =SUM(G16:G24) -> 0 | H25: =SUM(H16:H24) -> 40 | I25: =SUM(I16:I24) -> 2098.5 | K25: =SUM(K16:K24) -> 0 | L25: =SUM(L16:L24) -> 167.88 | M25: =SUM(M16:M24) -> 1930.62 | N25: =SUM(N16:N24) -> 447.8199 | O25: =SUM(O16:O24) -> 59.460998 | P25: =SUM(P16:P24) -> 2437.9009
B28: یکم جولائی 2024سے نئی ٹیکس ترمیم کے مطابق، ایف بی آر سیکشن 236 ایچ کے مطابق، فائلرز کے لیے ہر سیل انوائس پر 0.5% اور نان فائلرز کے لیے 2.5% ایڈوانس ود ہولڈنگ ٹیکس وصول کیا جائے گا۔ | N28: Gross Amount: | P28: =I25 -> 2098.5
N29: Regular Discount | P29: =L25 -> 167.88
N30: Trade Offre | P30: =K25 -> 0
N31: After Dis. Amount | P31: =P28-P29-P30 -> 1930.62
N32: Total GST: | O32: =IF(B12="Registered",18%,22%) -> 0.22 | P32: =N25 -> 447.8199
N33: Net Amount: | P33: =P31+P32 -> 2378.4399
N34: Ad.Tax | O34: =IF(B11="Filer",0.5%,2.5%) -> 0.025 | P34: =O34*P33 -> 59.460997
N35: Net Amount with Ad.Tax | P35: =P33+P34 -> 2437.9009
B36: Delivered By

Sheet 6
A2: Elite MARKETING
A3: 44A- Gulberg Lahore | K3: Invoice No # : | N3: 6 | XFC3: Filer | XFD3: 0.005
A4: STRN / NTN :3808207-1 | K4: Date/Day : | N4: =TODAY() -> 46178 | XFC4: Non-filer | XFD4: 0.025
A5: Customer Name : Sadat Store | K5: Order Date : | N5: =N4-1 -> 46177
A6: Address: Police Line | K6: Order Name : | N6: Zahid Rafique | XFC6: Registered | XFD6: 0.18
XFC7: Un-registered | XFD7: 0.22
XFD9: Yes
A10: NTN/CNIC Number: | K10: Invoice Status : | N10: Serviced | XFD10: No
B11: Non-filer | C11: =IF($O34>2.49%,"No","Yes") -> No | K11: Order at Original Location : | N11: Yes
A12: STRN Number: | B12: Un-registered | C12: =IF($O32>21.99%,"No","Yes") -> No | K12: Reference Invoice : | XFD12: Monday/Tuesday
L13: 0.05 | XFD13: Tuesday / Wednesday
A14: Product Code/Description | C14: GM/ Pack | D14: CTN | E14: R.P Per | F14: T.P Per | G14: Sale QTY | I14: Gross Amount Excl. Taxes | J14: Trade Offer & Discount | M14: After Discount Amount | N14: GST | O14: Adv. Tax 236H | P14: Invoice | XFD14: Wednesday/Thursday
D15: SIZE | E15: Unit | F15: Unit | G15: CTN | H15: Pack | J15: FOC Qty | K15: Trade Offer | L15: Pass On | N15: =IF(B12="Registered",18%,22%) -> 0.22 | O15: =IF(B11="Filer",0.5%,2.5%) -> 0.025 | P15: Amount | XFD15: Thursday /Friday
A16: BCN | B16: =VLOOKUP($A16,'[1]Cust. Price List'!$D$6:$O$14,2,0) -> Meat Masala | C16: =VLOOKUP(A16,'[1]Cust. Price List'!D6:M14,3,0) -> 70 | D16: =VLOOKUP(A16,'[1]Cust. Price List'!D6:M14,4,0) -> 40 | E16: =VLOOKUP(A16,'[1]Cust. Price List'!D6:M14,6,0) -> 65 | F16: =VLOOKUP(A16,'[1]Cust. Price List'!D6:M14,10,0) -> 52.4625 | I16: =(G16*D16)*F16+H16*F16 -> 0 | K16: =I16*$K$13 -> 0 | L16: =I16*8% -> 0 | M16: =I16-K16-L16 -> 0 | N16: =(M16*$N$15)+(J16*F16)*$N$15 -> 0 | O16: =(N16+M16)*$O$15 -> 0 | P16: =M16+N16+O16 -> 0 | XFD16: Friday / Saturday
A17: VTN | B17: =VLOOKUP($A17,'[1]Cust. Price List'!$D$6:$O$14,2,0) -> Lemon Tarka | C17: =VLOOKUP(B17,'[1]Cust. Price List'!E7:P15,2,0) -> 70 | D17: =VLOOKUP(A17,'[1]Cust. Price List'!D7:M15,4,0) -> 40 | E17: =VLOOKUP(A17,'[1]Cust. Price List'!D7:M15,6,0) -> 65 | F17: =VLOOKUP(A17,'[1]Cust. Price List'!D7:M15,10,0) -> 52.4625 | I17: =(G17*D17)*F17+H17*F17 -> 0 | K17: =I17*$K$13 -> 0 | L17: =I17*8% -> 0 | M17: =I17-K17-L17 -> 0 | N17: =(M17*$N$15)+(J17*F17)*$N$15 -> 0 | O17: =(N17+M17)*$O$15 -> 0 | P17: =M17+N17+O17 -> 0 | XFD17: Saturday /Monday
A18: CCN | B18: =VLOOKUP($A18,'[1]Cust. Price List'!$D$6:$O$14,2,0) -> Chicken Chatkhara | C18: =VLOOKUP(B18,'[1]Cust. Price List'!E8:P16,2,0) -> 70 | D18: =VLOOKUP(A18,'[1]Cust. Price List'!D8:M16,4,0) -> 40 | E18: =VLOOKUP(A18,'[1]Cust. Price List'!D8:M16,6,0) -> 65 | F18: =VLOOKUP(A18,'[1]Cust. Price List'!D8:M16,10,0) -> 52.4625 | I18: =(G18*D18)*F18+H18*F18 -> 0 | K18: =I18*$K$13 -> 0 | L18: =I18*8% -> 0 | M18: =I18-K18-L18 -> 0 | N18: =(M18*$N$15)+(J18*F18)*$N$15 -> 0 | O18: =(N18+M18)*$O$15 -> 0 | P18: =M18+N18+O18 -> 0
A19: BCNJ | B19: =VLOOKUP($A19,'[1]Cust. Price List'!$D$6:$O$14,2,0) -> Meat Masala (Jumbo) | C19: =VLOOKUP(B19,'[1]Cust. Price List'!E9:P17,2,0) -> 120 | D19: =VLOOKUP(A19,'[1]Cust. Price List'!D9:M17,4,0) -> 40 | E19: =VLOOKUP(A19,'[1]Cust. Price List'!D9:M17,6,0) -> 90 | F19: =VLOOKUP(A19,'[1]Cust. Price List'!D9:M17,10,0) -> 72.64 | I19: =(G19*D19)*F19+H19*F19 -> 0 | K19: =I19*$K$13 -> 0 | L19: =I19*8% -> 0 | M19: =I19-K19-L19 -> 0 | N19: =(M19*$N$15)+(J19*F19)*$N$15 -> 0 | O19: =(N19+M19)*$O$15 -> 0 | P19: =M19+N19+O19 -> 0
A20: VTNJ | B20: =VLOOKUP($A20,'[1]Cust. Price List'!$D$6:$O$14,2,0) -> Lemon Tarka (Jumbo) | C20: =VLOOKUP(B20,'[1]Cust. Price List'!E10:P18,2,0) -> 120 | D20: =VLOOKUP(A20,'[1]Cust. Price List'!D10:M18,4,0) -> 40 | E20: =VLOOKUP(A20,'[1]Cust. Price List'!D10:M18,6,0) -> 90 | F20: =VLOOKUP(A20,'[1]Cust. Price List'!D10:M18,10,0) -> 72.64 | I20: =(G20*D20)*F20+H20*F20 -> 0 | K20: =I20*$K$13 -> 0 | L20: =I20*8% -> 0 | M20: =I20-K20-L20 -> 0 | N20: =(M20*$N$15)+(J20*F20)*$N$15 -> 0 | O20: =(N20+M20)*$O$15 -> 0 | P20: =M20+N20+O20 -> 0
A21: CCNJ | B21: =VLOOKUP($A21,'[1]Cust. Price List'!$D$6:$O$14,2,0) -> Chicken Chatkhara (Jumbo) | C21: =VLOOKUP(B21,'[1]Cust. Price List'!E11:P19,2,0) -> 120 | D21: =VLOOKUP(A21,'[1]Cust. Price List'!D11:M19,4,0) -> 40 | E21: =VLOOKUP(A21,'[1]Cust. Price List'!D11:M19,6,0) -> 90 | F21: =VLOOKUP(A21,'[1]Cust. Price List'!D11:M19,10,0) -> 72.64 | I21: =(G21*D21)*F21+H21*F21 -> 0 | K21: =I21*$K$13 -> 0 | L21: =I21*8% -> 0 | M21: =I21-K21-L21 -> 0 | N21: =(M21*$N$15)+(J21*F21)*$N$15 -> 0 | O21: =(N21+M21)*$O$15 -> 0 | P21: =M21+N21+O21 -> 0
A22: CCE | B22: =VLOOKUP($A22,'[1]Cust. Price List'!$D$6:$O$14,2,0) -> Chicken Chatkhara (ECO) | C22: =VLOOKUP(B22,'[1]Cust. Price List'!E12:P20,2,0) -> 60 | D22: =VLOOKUP(A22,'[1]Cust. Price List'!D12:M20,4,0) -> 40 | E22: =VLOOKUP(A22,'[1]Cust. Price List'!D12:M20,6,0) -> 50 | F22: =VLOOKUP(A22,'[1]Cust. Price List'!D12:M20,10,0) -> 39.23 | H22: 12 | I22: =(G22*D22)*F22+H22*F22 -> 470.76 | K22: =I22*3.5% -> 16.4766 | L22: =I22*5% -> 23.538 | M22: =I22-K22-L22 -> 430.7454 | N22: =(M22*$N$15)+(J22*F22)*$N$15 -> 94.763988 | O22: =(N22+M22)*$O$15 -> 13.137735 | P22: =M22+N22+O22 -> 538.64712
