Workbook

Sheet STT Report
A1: Date | B1: Month | C1: Invoice Number | D1: Customer Code | E1: City | F1: Shop Type | G1: Shops Name | H1: Sales Person | I1: Address | K1: Indomie 70GM | O1: Indomie 120GM | S1: QTY | T1: FOC Indomie 70GM | X1: FOC Indomie 120GM | AB1: Rate 60GM | AC1: Rate 70GM | AD1: Rate 120GM | AE1: T.P Amount | AF1: Disc % | AG1: Disc Amt | AH1: 0.035 | AI1: Amount | AJ1: GST % | AK1: GST Amount | AL1: Net Amount | AM1: Cash Received | AN1: Oth Disc | AO1: Cash Receivable | AP1: Remarks
I2: Address | J2: Chicken 60gm | K2: Meat 70gr | L2: Lemon 70gr | M2: Chicken 70gr | N2: Total 70gr | O2: Meat 120g | P2: Lemon 120gr | Q2: Chicken 120gr | R2: Total 120gr | T2: Meat 70gr FOC | U2: Lemon 70gr FOC | V2: Chicken 70gr FOC | W2: Total 70gr FOC | X2: Meat 120g FOC | Y2: Lemon 120gr FOC | Z2: Chicken 120gr FOC | AA2: Total 120gr FOC | AH2: Trade offer (amount)
A3: 46204 | B3: July | C3: 123156 | D3: 5643 | E3: LHR | F3: LMT | G3: Gourmet Food | H3: Shakoor | I3: Awan Town | K3: 80 | L3: 80 | N3: =K3+L3+M3 -> 160 | O3: 80 | P3: 80 | Q3: 80 | R3: =SUM(O3:Q3) -> 240 | S3: =R3+N3+J3 -> 400 | U3: 79950 | AB3: 39.27 | AC3: 52.4625 | AD3: 72.64 | AE3: =(J3*AB3)+(N3*AC3)+(AD3*S3) -> 37450 | AF3: 0.08 | AG3: =AE3*AF3 -> 2996 | AH3: =(AB3*J3)*$AH$1 -> 0 | AI3: =AE3-AG3-AH3 -> 34454 | AJ3: 0.18 | AK3: =AI3*AJ3 -> 6201.72 | AL3: =AI3+AK3 -> 40655.72
A4: 46204 | B4: July | C4: 12313212 | D4: 5464 | E4: LHR | F4: LMT | G4: Gourmet Food | H4: Shakoor | I4: Canal view | K4: 80 | L4: 80 | N4: =K4+L4+M4 -> 160 | O4: 80 | P4: 80 | Q4: 80 | R4: =SUM(O4:Q4) -> 240 | S4: =R4+N4+J4 -> 400 | U4: =U3/40 -> 1998.75 | AB4: 39.27 | AC4: 52.4625 | AD4: 72.64 | AE4: =(J4*AB4)+(N4*AC4)+(AD4*S4) -> 37450 | AF4: 0.065 | AG4: =AE4*AF4 -> 2434.25 | AH4: =(AB4*J4)*$AH$1 -> 0 | AI4: =AE4-AG4 -> 35015.75 | AJ4: 0.18 | AK4: =AI4*AJ4 -> 6302.835 | AL4: =AI4+AK4 -> 41318.585
A5: 46204 | B5: July | C5: 156165 | D5: 1523 | E5: LHR | F5: LMT | G5: Gourmet Food | H5: Shakoor | I5: Liyaqat chowk | K5: 80 | L5: 80 | N5: =K5+L5+M5 -> 160 | O5: 80 | P5: 80 | Q5: 80 | R5: =SUM(O5:Q5) -> 240 | S5: =R5+N5+J5 -> 400 | AB5: 39.27 | AC5: 52.4625 | AD5: 72.64 | AE5: =(J5*AB5)+(N5*AC5)+(AD5*S5) -> 37450 | AF5: 0.065 | AG5: =AE5*AF5 -> 2434.25 | AH5: =(AB5*J5)*$AH$1 -> 0 | AI5: =AE5-AG5 -> 35015.75 | AJ5: 0.18 | AK5: =AI5*AJ5 -> 6302.835 | AL5: =AI5+AK5 -> 41318.585
A6: 46204 | B6: July | C6: 1561531 | D6: 5461 | E6: LHR | F6: LMT | G6: Gourmet Food | H6: Shakoor | I6: Gulshan Ravi | K6: 80 | L6: 80 | N6: =K6+L6+M6 -> 160 | O6: 40 | P6: 40 | Q6: 40 | R6: =SUM(O6:Q6) -> 120 | S6: =R6+N6+J6 -> 280 | AB6: 39.27 | AC6: 52.4625 | AD6: 72.64 | AE6: =(J6*AB6)+(N6*AC6)+(AD6*S6) -> 28733.2 | AF6: 0.065 | AG6: =AE6*AF6 -> 1867.658 | AH6: =(AB6*J6)*$AH$1 -> 0 | AI6: =AE6-AG6 -> 26865.542 | AJ6: 0.18 | AK6: =AI6*AJ6 -> 4835.7976 | AL6: =AI6+AK6 -> 31701.34
A7: 46204 | B7: July | C7: 1561561 | D7: 2316 | E7: LHR | F7: LMT | G7: Gourmet Food | H7: Shakoor | I7: Multan Road | K7: 40 | L7: 40 | N7: =K7+L7+M7 -> 80 | O7: 40 | P7: 40 | Q7: 40 | R7: =SUM(O7:Q7) -> 120 | S7: =R7+N7+J7 -> 200 | AB7: 39.27 | AC7: 52.4625 | AD7: 72.64 | AE7: =(J7*AB7)+(N7*AC7)+(AD7*S7) -> 18725 | AF7: 0.065 | AG7: =AE7*AF7 -> 1217.125 | AH7: =(AB7*J7)*$AH$1 -> 0 | AI7: =AE7-AG7 -> 17507.875 | AJ7: 0.18 | AK7: =AI7*AJ7 -> 3151.4175 | AL7: =AI7+AK7 -> 20659.292 | AM7: =SUM(#REF!) -> #REF! | AN7: =SUM(#REF!) -> #REF! | AO7: =SUM(#REF!) -> #REF!
A8: 46204 | B8: July | C8: 1561561 | D8: 2084.3 | E8: LHR | F8: LMT | G8: Gourmet Food | H8: Shakoor | I8: Nadeem Shaheed | K8: 40 | L8: 40 | N8: =K8+L8+M8 -> 80 | O8: 40 | P8: 80 | Q8: 80 | R8: =SUM(O8:Q8) -> 200 | S8: =R8+N8+J8 -> 280 | AB8: 39.27 | AC8: 52.4625 | AD8: 72.64 | AE8: =(J8*AB8)+(N8*AC8)+(AD8*S8) -> 24536.2 | AF8: 0.065 | AG8: =AE8*AF8 -> 1594.853 | AH8: =(AB8*J8)*$AH$1 -> 0 | AI8: =AE8-AG8 -> 22941.347 | AJ8: 0.18 | AK8: =AI8*AJ8 -> 4129.4425 | AL8: =AI8+AK8 -> 27070.789
A9: 46204 | B9: July | C9: 1561561 | D9: 1418.6 | E9: LHR | F9: LMT | G9: Gourmet Food | H9: Shakoor | I9: Poonch Road | K9: 80 | L9: 80 | N9: =K9+L9+M9 -> 160 | O9: 40 | P9: 40 | Q9: 40 | R9: =SUM(O9:Q9) -> 120 | S9: =R9+N9+J9 -> 280 | AB9: 39.27 | AC9: 52.4625 | AD9: 72.64 | AE9: =(J9*AB9)+(N9*AC9)+(AD9*S9) -> 28733.2 | AF9: 0.1 | AG9: =AE9*AF9 -> 2873.32 | AH9: =(AB9*J9)*$AH$1 -> 0 | AI9: =AE9-AG9 -> 25859.88 | AJ9: 0.18 | AK9: =AI9*AJ9 -> 4654.7784 | AL9: =AI9+AK9 -> 30514.658
A10: 46204 | B10: July | C10: 1561561 | D10: 752.9 | E10: LHR | F10: LMT | G10: Gourmet Food | H10: Shakoor | I10: Rehman pura | K10: 40 | L10: 40 | N10: =K10+L10+M10 -> 80 | O10: 40 | P10: 40 | Q10: 40 | R10: =SUM(O10:Q10) -> 120 | S10: =R10+N10+J10 -> 200 | AB10: 39.27 | AC10: 52.4625 | AD10: 72.64 | AE10: =(J10*AB10)+(N10*AC10)+(AD10*S10) -> 18725 | AF10: 0.065 | AG10: =AE10*AF10 -> 1217.125 | AH10: =(AB10*J10)*$AH$1 -> 0 | AI10: =AE10-AG10 -> 17507.875 | AJ10: 0.18 | AK10: =AI10*AJ10 -> 3151.4175 | AL10: =AI10+AK10 -> 20659.292
A11: 46204 | B11: July | C11: 435402.68 | D11: 87.2 | E11: LHR | F11: LMT | G11: Gourmet Food | H11: Shakoor | I11: Rewaz Garden | K11: 40 | L11: 40 | N11: =K11+L11+M11 -> 80 | O11: 40 | P11: 40 | Q11: 40 | R11: =SUM(O11:Q11) -> 120 | S11: =R11+N11+J11 -> 200 | AB11: 39.27 | AC11: 52.4625 | AD11: 72.64 | AE11: =(J11*AB11)+(N11*AC11)+(AD11*S11) -> 18725 | AF11: 0.065 | AG11: =AE11*AF11 -> 1217.125 | AH11: =(AB11*J11)*$AH$1 -> 0 | AI11: =AE11-AG11 -> 17507.875 | AJ11: 0.18 | AK11: =AI11*AJ11 -> 3151.4175 | AL11: =AI11+AK11 -> 20659.292
A12: 46204 | B12: July | C12: 34516.393 | D12: 578.5 | E12: LHR | F12: LMT | G12: Gourmet Food | H12: Shakoor | I12: Rustam Park | K12: 40 | L12: 40 | N12: =K12+L12+M12 -> 80 | O12: 40 | P12: 40 | Q12: 40 | R12: =SUM(O12:Q12) -> 120 | S12: =R12+N12+J12 -> 200 | AB12: 39.27 | AC12: 52.4625 | AD12: 72.64 | AE12: =(J12*AB12)+(N12*AC12)+(AD12*S12) -> 18725 | AF12: 0.065 | AG12: =AE12*AF12 -> 1217.125 | AH12: =(AB12*J12)*$AH$1 -> 0 | AI12: =AE12-AG12 -> 17507.875 | AJ12: 0.18 | AK12: =AI12*AJ12 -> 3151.4175 | AL12: =AI12+AK12 -> 20659.292
A13: 46204 | B13: July | C13: 504435.46 | D13: 1244.2 | E13: LHR | F13: LMT | G13: Gourmet Food | H13: Shakoor | I13: Samanaabd lhr | K13: 80 | L13: 80 | N13: =K13+L13+M13 -> 160 | O13: 40 | P13: 40 | Q13: 40 | R13: =SUM(O13:Q13) -> 120 | S13: =R13+N13+J13 -> 280 | AB13: 39.27 | AC13: 52.4625 | AD13: 72.64 | AE13: =(J13*AB13)+(N13*AC13)+(AD13*S13) -> 28733.2 | AF13: 0.065 | AG13: =AE13*AF13 -> 1867.658 | AH13: =(AB13*J13)*$AH$1 -> 0 | AI13: =AE13-AG13 -> 26865.542 | AJ13: 0.18 | AK13: =AI13*AJ13 -> 4835.7976 | AL13: =AI13+AK13 -> 31701.34
A14: 46204 | B14: July | C14: 974354.54 | D14: 1909.9 | E14: LHR | F14: LMT | G14: Gourmet Food | H14: Shakoor | I14: Wahdat Road | K14: 80 | L14: 80 | N14: =K14+L14+M14 -> 160 | O14: 40 | P14: 40 | Q14: 40 | R14: =SUM(O14:Q14) -> 120 | S14: =R14+N14+J14 -> 280 | AB14: 39.27 | AC14: 52.4625 | AD14: 72.64 | AE14: =(J14*AB14)+(N14*AC14)+(AD14*S14) -> 28733.2 | AF14: 0.065 | AG14: =AE14*AF14 -> 1867.658 | AH14: =(AB14*J14)*$AH$1 -> 0 | AI14: =AE14-AG14 -> 26865.542 | AJ14: 0.18 | AK14: =AI14*AJ14 -> 4835.7976 | AL14: =AI14+AK14 -> 31701.34
A15: 46204 | B15: July | C15: 1444273.6 | D15: 2575.6 | E15: LHR | F15: LMT | G15: Gourmet Food | H15: Shakoor | I15: Kareem Block | K15: 80 | L15: 80 | N15: =K15+L15+M15 -> 160 | O15: 40 | P15: 40 | Q15: 40 | R15: =SUM(O15:Q15) -> 120 | S15: =R15+N15+J15 -> 280 | AB15: 39.27 | AC15: 52.4625 | AD15: 72.64 | AE15: =(J15*AB15)+(N15*AC15)+(AD15*S15) -> 28733.2 | AF15: 0.065 | AG15: =AE15*AF15 -> 1867.658 | AH15: =(AB15*J15)*$AH$1 -> 0 | AI15: =AE15-AG15 -> 26865.542 | AJ15: 0.18 | AK15: =AI15*AJ15 -> 4835.7976 | AL15: =AI15+AK15 -> 31701.34
A16: 46204 | B16: July | C16: 1914192.7 | D16: 3241.3 | E16: LHR | F16: General Store | G16: Awan Store | H16: Furqan | I16: Lawrance Road | J16: 12 | N16: =K16+L16+M16 -> 0 | R16: =SUM(O16:Q16) -> 0 | S16: =R16+N16+J16 -> 12 | AB16: 39.27 | AC16: 52.4625 | AD16: 72.64 | AE16: =(J16*AB16)+(N16*AC16)+(AD16*S16) -> 1342.92 | AF16: 0.065 | AG16: =AE16*AF16 -> 87.2898 | AH16: =(AB16*J16)*$AH$1 -> 16.4934 | AI16: =AE16-AG16 -> 1255.6302 | AJ16: 0.18 | AK16: =AI16*AJ16 -> 226.01344 | AL16: =AI16+AK16 -> 1481.6436
A17: 46204 | B17: July | C17: 2384111.8 | D17: 3907 | E17: LHR | F17: General Store | G17: Ch General Store | H17: Furqan | I17: Lawrance Road | J17: 12 | N17: =K17+L17+M17 -> 0 | R17: =SUM(O17:Q17) -> 0 | S17: =R17+N17+J17 -> 12 | AB17: 39.27 | AC17: 52.4625 | AD17: 72.64 | AE17: =(J17*AB17)+(N17*AC17)+(AD17*S17) -> 1342.92 | AF17: 0.065 | AG17: =AE17*AF17 -> 87.2898 | AH17: =(AB17*J17)*$AH$1 -> 16.4934 | AI17: =AE17-AG17 -> 1255.6302 | AJ17: 0.18 | AK17: =AI17*AJ17 -> 226.01344 | AL17: =AI17+AK17 -> 1481.6436
A18: 46204 | B18: July | C18: 2854030.8 | D18: 4572.7 | E18: LHR | F18: General Store | G18: Shahid Bakery | H18: Furqan | I18: Lawrance Road | N18: =K18+L18+M18 -> 0 | O18: 15 | P18: 15 | Q18: 10 | R18: =SUM(O18:Q18) -> 40 | S18: =R18+N18+J18 -> 40 | AB18: 39.27 | AC18: 52.4625 | AD18: 72.64 | AE18: =(J18*AB18)+(N18*AC18)+(AD18*S18) -> 2905.6 | AF18: 0.065 | AG18: =AE18*AF18 -> 188.864 | AH18: =(AB18*J18)*$AH$1 -> 0 | AI18: =AE18-AG18 -> 2716.736 | AJ18: 0.18 | AK18: =AI18*AJ18 -> 489.01248 | AL18: =AI18+AK18 -> 3205.7485
A19: 46204 | B19: July | C19: 3323949.9 | D19: 5238.4 | E19: LHR | F19: General Store | G19: Khan Nimko | H19: Furqan | I19: Lawrance Road | N19: =K19+L19+M19 -> 0 | O19: 8 | P19: 4 | Q19: 8 | R19: =SUM(O19:Q19) -> 20 | S19: =R19+N19+J19 -> 20 | AB19: 39.27 | AC19: 52.4625 | AD19: 72.64 | AE19: =(J19*AB19)+(N19*AC19)+(AD19*S19) -> 1452.8 | AF19: 0.065 | AG19: =AE19*AF19 -> 94.432 | AH19: =(AB19*J19)*$AH$1 -> 0 | AI19: =AE19-AG19 -> 1358.368 | AJ19: 0.18 | AK19: =AI19*AJ19 -> 244.50624 | AL19: =AI19+AK19 -> 1602.8742
A20: 46204 | B20: July | C20: 3793869 | D20: 5904.1 | E20: LHR | F20: Mart | G20: Shell Petrol Mart | H20: Furqan | I20: Lawrance Road | K20: 40 | L20: 40 | N20: =K20+L20+M20 -> 80 | O20: 40 | P20: 40 | Q20: 40 | R20: =SUM(O20:Q20) -> 120 | S20: =R20+N20+J20 -> 200 | AB20: 39.27 | AC20: 52.4625 | AD20: 72.64 | AE20: =(J20*AB20)+(N20*AC20)+(AD20*S20) -> 18725 | AF20: 0.065 | AG20: =AE20*AF20 -> 1217.125 | AH20: =(AB20*J20)*$AH$1 -> 0 | AI20: =AE20-AG20 -> 17507.875 | AJ20: 0.18 | AK20: =AI20*AJ20 -> 3151.4175 | AL20: =AI20+AK20 -> 20659.292
A21: 46204 | B21: July | C21: 4263788 | D21: 6569.8 | E21: LHR | F21: General Store | G21: Lala G Super Store | H21: Salman | I21: Falcon Society | K21: 12 | L21: 12 | N21: =K21+L21+M21 -> 24 | R21: =SUM(O21:Q21) -> 0 | S21: =R21+N21+J21 -> 24 | AB21: 39.27 | AC21: 52.4625 | AD21: 72.64 | AE21: =(J21*AB21)+(N21*AC21)+(AD21*S21) -> 3002.46 | AF21: 0.065 | AG21: =AE21*AF21 -> 195.1599 | AH21: =(AB21*J21)*$AH$1 -> 0 | AI21: =AE21-AG21 -> 2807.3001 | AJ21: 0.18 | AK21: =AI21*AJ21 -> 505.31402 | AL21: =AI21+AK21 -> 3312.6141
A22: 46204 | B22: July | C22: 4733707.1 | D22: 7235.5 | E22: LHR | F22: General Store | G22: Ajwa Bakers | H22: Salman | I22: Falcon Society | N22: =K22+L22+M22 -> 0 | O22: 10 | P22: 15 | Q22: 15 | R22: =SUM(O22:Q22) -> 40 | S22: =R22+N22+J22 -> 40 | AB22: 39.27 | AC22: 52.4625 | AD22: 72.64 | AE22: =(J22*AB22)+(N22*AC22)+(AD22*S22) -> 2905.6 | AF22: 0.065 | AG22: =AE22*AF22 -> 188.864 | AH22: =(AB22*J22)*$AH$1 -> 0 | AI22: =AE22-AG22 -> 2716.736 | AJ22: 0.18 | AK22: =AI22*AJ22 -> 489.01248 | AL22: =AI22+AK22 -> 3205.7485
A23: 46204 | B23: July | C23: 5203626.2 | D23: 7901.2 | E23: LHR | F23: General Store | G23: New Way Store | H23: Salman | I23: Falcon Society | J23: 200 | N23: =K23+L23+M23 -> 0 | R23: =SUM(O23:Q23) -> 0 | S23: =R23+N23+J23 -> 200 | AB23: 39.27 | AC23: 52.4625 | AD23: 72.64 | AE23: =(J23*AB23)+(N23*AC23)+(AD23*S23) -> 22382 | AF23: 0.065 | AG23: =AE23*AF23 -> 1454.83 | AH23: =(AB23*J23)*$AH$1 -> 274.89 | AI23: =AE23-AG23 -> 20927.17 | AJ23: 0.18 | AK23: =AI23*AJ23 -> 3766.8906 | AL23: =AI23+AK23 -> 24694.061
A24: 46204 | B24: July | C24: 5673545.2 | D24: 8566.9 | E24: LHR | F24: General Store | G24: Sulshan bakery | H24: Umair | I24: Awan Market | J24: 40 | K24: 20 | L24: 20 | N24: =K24+L24+M24 -> 40 | R24: =SUM(O24:Q24) -> 0 | S24: =R24+N24+J24 -> 80 | AB24: 39.27 | AC24: 52.4625 | AD24: 72.64 | AE24: =(J24*AB24)+(N24*AC24)+(AD24*S24) -> 9480.5 | AF24: 0.065 | AG24: =AE24*AF24 -> 616.2325 | AH24: =(AB24*J24)*$AH$1 -> 54.978 | AI24: =AE24-AG24 -> 8864.2675 | AJ24: 0.18 | AK24: =AI24*AJ24 -> 1595.5681 | AL24: =AI24+AK24 -> 10459.836
A25: 46204 | B25: July | C25: 6143464.3 | D25: 9232.6 | E25: LHR | F25: General Store | G25: Ali Super GS | H25: Umair | I25: Awan Market | J25: 20 | N25: =K25+L25+M25 -> 0 | R25: =SUM(O25:Q25) -> 0 | S25: =R25+N25+J25 -> 20 | AB25: 39.27 | AC25: 52.4625 | AD25: 72.64 | AE25: =(J25*AB25)+(N25*AC25)+(AD25*S25) -> 2238.2 | AF25: 0.1 | AG25: =AE25*AF25 -> 223.82 | AH25: =(AB25*J25)*$AH$1 -> 27.489 | AI25: =AE25-AG25 -> 2014.38 | AJ25: 0.18 | AK25: =AI25*AJ25 -> 362.5884 | AL25: =AI25+AK25 -> 2376.9684
A26: 46204 | B26: July | C26: 6613383.4 | D26: 9898.3 | E26: LHR | F26: Mart | G26: Fareedia Bakery | H26: Umair | I26: Awan Market | J26: 12 | N26: =K26+L26+M26 -> 0 | O26: 20 | R26: =SUM(O26:Q26) -> 20 | S26: =R26+N26+J26 -> 32 | AB26: 39.27 | AC26: 52.4625 | AD26: 72.64 | AE26: =(J26*AB26)+(N26*AC26)+(AD26*S26) -> 2795.72 | AF26: 0.065 | AG26: =AE26*AF26 -> 181.7218 | AH26: =(AB26*J26)*$AH$1 -> 16.4934 | AI26: =AE26-AG26 -> 2613.9982 | AJ26: 0.18 | AK26: =AI26*AJ26 -> 470.51968 | AL26: =AI26+AK26 -> 3084.5179
A27: 46204 | B27: July | C27: 7083302.5 | D27: 10564 | E27: LHR | F27: General Store | G27: hanif Store | H27: Umair | I27: Awan Market | J27: 12 | N27: =K27+L27+M27 -> 0 | R27: =SUM(O27:Q27) -> 0 | S27: =R27+N27+J27 -> 12 | AB27: 39.27 | AC27: 52.4625 | AD27: 72.64 | AE27: =(J27*AB27)+(N27*AC27)+(AD27*S27) -> 1342.92 | AF27: 0.065 | AG27: =AE27*AF27 -> 87.2898 | AH27: =(AB27*J27)*$AH$1 -> 16.4934 | AI27: =AE27-AG27 -> 1255.6302 | AJ27: 0.18 | AK27: =AI27*AJ27 -> 226.01344 | AL27: =AI27+AK27 -> 1481.6436
A28: 46204 | B28: July | C28: 7553221.5 | D28: 11229.7 | E28: LHR | F28: General Store | G28: Khubaib Mart | H28: Umair | I28: Awan Market | N28: =K28+L28+M28 -> 0 | O28: 26 | P28: 26 | Q28: 28 | R28: =SUM(O28:Q28) -> 80 | S28: =R28+N28+J28 -> 80 | AB28: 39.27 | AC28: 52.4625 | AD28: 72.64 | AE28: =(J28*AB28)+(N28*AC28)+(AD28*S28) -> 5811.2 | AF28: 0.065 | AG28: =AE28*AF28 -> 377.728 | AH28: =(AB28*J28)*$AH$1 -> 0 | AI28: =AE28-AG28 -> 5433.472 | AJ28: 0.18 | AK28: =AI28*AJ28 -> 978.02496 | AL28: =AI28+AK28 -> 6411.497
A29: 46204 | B29: July | C29: 8023140.6 | D29: 11895.4 | E29: LHR | F29: General Store | G29: Chanda Mart | H29: Umair | I29: Awan Market | N29: =K29+L29+M29 -> 0 | P29: 20 | Q29: 20 | R29: =SUM(O29:Q29) -> 40 | S29: =R29+N29+J29 -> 40 | AB29: 39.27 | AC29: 52.4625 | AD29: 72.64 | AE29: =(J29*AB29)+(N29*AC29)+(AD29*S29) -> 2905.6 | AF29: 0.065 | AG29: =AE29*AF29 -> 188.864 | AH29: =(AB29*J29)*$AH$1 -> 0 | AI29: =AE29-AG29 -> 2716.736 | AJ29: 0.18 | AK29: =AI29*AJ29 -> 489.01248 | AL29: =AI29+AK29 -> 3205.7485
A30: 46204 | B30: July | C30: 8493059.7 | D30: 12561.1 | E30: LHR | F30: General Store | G30: DVA Store | H30: Umair | I30: Awan Market | J30: 40 | N30: =K30+L30+M30 -> 0 | R30: =SUM(O30:Q30) -> 0 | S30: =R30+N30+J30 -> 40 | AB30: 39.27 | AC30: 52.4625 | AD30: 72.64 | AE30: =(J30*AB30)+(N30*AC30)+(AD30*S30) -> 4476.4 | AF30: 0.065 | AG30: =AE30*AF30 -> 290.966 | AH30: =(AB30*J30)*$AH$1 -> 54.978 | AI30: =AE30-AG30 -> 4185.434 | AJ30: 0.18 | AK30: =AI30*AJ30 -> 753.37812 | AL30: =AI30+AK30 -> 4938.8121
A31: 46204 | B31: July | C31: 8962978.8 | D31: 13226.8 | E31: LHR | F31: General Store | G31: Palaece Sweet | H31: Umair | I31: Awan Market | J31: 40 | N31: =K31+L31+M31 -> 0 | R31: =SUM(O31:Q31) -> 0 | S31: =R31+N31+J31 -> 40 | AB31: 39.27 | AC31: 52.4625 | AD31: 72.64 | AE31: =(J31*AB31)+(N31*AC31)+(AD31*S31) -> 4476.4 | AF31: 0.065 | AG31: =AE31*AF31 -> 290.966 | AH31: =(AB31*J31)*$AH$1 -> 54.978 | AI31: =AE31-AG31 -> 4185.434 | AJ31: 0.18 | AK31: =AI31*AJ31 -> 753.37812 | AL31: =AI31+AK31 -> 4938.8121
A32: 46204 | B32: July | C32: 9432897.8 | D32: 13892.5 | E32: LHR | F32: Mart | G32: Ghosia Store | H32: Umair | I32: Awan Market | J32: 80 | N32: =K32+L32+M32 -> 0 | R32: =SUM(O32:Q32) -> 0 | S32: =R32+N32+J32 -> 80 | AB32: 39.27 | AC32: 52.4625 | AD32: 72.64 | AE32: =(J32*AB32)+(N32*AC32)+(AD32*S32) -> 8952.8 | AF32: 0.065 | AG32: =AE32*AF32 -> 581.932 | AH32: =(AB32*J32)*$AH$1 -> 109.956 | AI32: =AE32-AG32 -> 8370.868 | AJ32: 0.18 | AK32: =AI32*AJ32 -> 1506.7562 | AL32: =AI32+AK32 -> 9877.6242
A33: 46204 | B33: July | C33: 9902816.9 | D33: 14558.2 | E33: LHR | F33: General Store | G33: NM Mart | H33: Umair | I33: Awan Market | J33: 40 | K33: 20 | L33: 20 | N33: =K33+L33+M33 -> 40 | O33: 20 | P33: 20 | Q33: 20 | R33: =SUM(O33:Q33) -> 60 | S33: =R33+N33+J33 -> 140 | AB33: 39.27 | AC33: 52.4625 | AD33: 72.64 | AE33: =(J33*AB33)+(N33*AC33)+(AD33*S33) -> 13838.9 | AF33: 0.065 | AG33: =AE33*AF33 -> 899.5285 | AH33: =(AB33*J33)*$AH$1 -> 54.978 | AI33: =AE33-AG33 -> 12939.372 | AJ33: 0.18 | AK33: =AI33*AJ33 -> 2329.0869 | AL33: =AI33+AK33 -> 15268.458
A34: 46204 | B34: July | C34: 10372736 | D34: 15223.9 | E34: LHR | F34: General Store | G34: Qadri Store | H34: Zeshan | I34: Nishat | N34: =K34+L34+M34 -> 0 | Q34: 6 | R34: =SUM(O34:Q34) -> 6 | S34: =R34+N34+J34 -> 6 | AB34: 39.27 | AC34: 52.4625 | AD34: 72.64 | AE34: =(J34*AB34)+(N34*AC34)+(AD34*S34) -> 435.84 | AF34: 0.065 | AG34: =AE34*AF34 -> 28.3296 | AH34: =(AB34*J34)*$AH$1 -> 0 | AI34: =AE34-AG34 -> 407.5104 | AJ34: 0.18 | AK34: =AI34*AJ34 -> 73.351872 | AL34: =AI34+AK34 -> 480.86227
A35: 46204 | B35: July | C35: 10842655 | D35: 15889.6 | E35: LHR | F35: General Store | G35: Ahmad Store | H35: Zeshan | I35: Nishat | J35: 6 | N35: =K35+L35+M35 -> 0 | R35: =SUM(O35:Q35) -> 0 | S35: =R35+N35+J35 -> 6 | AB35: 39.27 | AC35: 52.4625 | AD35: 72.64 | AE35: =(J35*AB35)+(N35*AC35)+(AD35*S35) -> 671.46 | AF35: 0.065 | AG35: =AE35*AF35 -> 43.6449 | AH35: =(AB35*J35)*$AH$1 -> 8.2467 | AI35: =AE35-AG35 -> 627.8151 | AJ35: 0.18 | AK35: =AI35*AJ35 -> 113.00672 | AL35: =AI35+AK35 -> 740.82182
A36: 46204 | B36: July | C36: 11312574 | D36: 16555.3 | E36: LHR | F36: General Store | G36: Green Mart | H36: Zeshan | I36: Nishat | J36: 80 | N36: =K36+L36+M36 -> 0 | O36: 40 | P36: 40 | Q36: 80 | R36: =SUM(O36:Q36) -> 160 | S36: =R36+N36+J36 -> 240 | AB36: 39.27 | AC36: 52.4625 | AD36: 72.64 | AE36: =(J36*AB36)+(N36*AC36)+(AD36*S36) -> 20575.2 | AF36: 0.065 | AG36: =AE36*AF36 -> 1337.388 | AH36: =(AB36*J36)*$AH$1 -> 109.956 | AI36: =AE36-AG36 -> 19237.812 | AJ36: 0.18 | AK36: =AI36*AJ36 -> 3462.8062 | AL36: =AI36+AK36 -> 22700.618
A37: 46204 | B37: July | C37: 11782493 | D37: 17221 | E37: LHR | F37: General Store | G37: 786 Store | H37: Zeshan | I37: Nishat | N37: =K37+L37+M37 -> 0 | O37: 15 | P37: 15 | Q37: 10 | R37: =SUM(O37:Q37) -> 40 | S37: =R37+N37+J37 -> 40 | AB37: 39.27 | AC37: 52.4625 | AD37: 72.64 | AE37: =(J37*AB37)+(N37*AC37)+(AD37*S37) -> 2905.6 | AF37: 0.065 | AG37: =AE37*AF37 -> 188.864 | AH37: =(AB37*J37)*$AH$1 -> 0 | AI37: =AE37-AG37 -> 2716.736 | AJ37: 0.18 | AK37: =AI37*AJ37 -> 489.01248 | AL37: =AI37+AK37 -> 3205.7485
A38: 46204 | B38: July | C38: 12252412 | D38: 17886.7 | E38: LHR | F38: Mart | G38: Shreef Mart | H38: Zeshan | I38: Nishat | N38: =K38+L38+M38 -> 0 | O38: 10 | P38: 10 | Q38: 10 | R38: =SUM(O38:Q38) -> 30 | S38: =R38+N38+J38 -> 30 | AB38: 39.27 | AC38: 52.4625 | AD38: 72.64 | AE38: =(J38*AB38)+(N38*AC38)+(AD38*S38) -> 2179.2 | AF38: 0.065 | AG38: =AE38*AF38 -> 141.648 | AH38: =(AB38*J38)*$AH$1 -> 0 | AI38: =AE38-AG38 -> 2037.552 | AJ38: 0.18 | AK38: =AI38*AJ38 -> 366.75936 | AL38: =AI38+AK38 -> 2404.3114
A39: 46205 | B39: July | C39: 12722331 | D39: 18552.4 | E39: LHR | F39: LMT | G39: Native | H39: Asif Shb | I39: Origin Main | J39: 40 | K39: 20 | L39: 20 | N39: =K39+L39+M39 -> 40 | O39: 13 | P39: 13 | Q39: 14 | R39: =SUM(O39:Q39) -> 40 | S39: =R39+N39+J39 -> 120 | AB39: 39.27 | AC39: 52.4625 | AD39: 72.64 | AE39: =(J39*AB39)+(N39*AC39)+(AD39*S39) -> 12386.1 | AF39: 0.065 | AG39: =AE39*AF39 -> 805.0965 | AH39: =(AB39*J39)*$AH$1 -> 54.978 | AI39: =AE39-AG39 -> 11581.003 | AJ39: 0.18 | AK39: =AI39*AJ39 -> 2084.5806 | AL39: =AI39+AK39 -> 13665.584
A40: 46205 | B40: July | C40: 13192250 | D40: 19218.1 | E40: LHR | F40: General Store | G40: Bismillah GS | H40: Furqan | I40: Shadman Market | J40: 12 | N40: =K40+L40+M40 -> 0 | O40: 12 | P40: 0 | Q40: 12 | R40: =SUM(O40:Q40) -> 24 | S40: =R40+N40+J40 -> 36 | AB40: 39.27 | AC40: 52.4625 | AD40: 72.64 | AE40: =(J40*AB40)+(N40*AC40)+(AD40*S40) -> 3086.28 | AF40: 0.065 | AG40: =AE40*AF40 -> 200.6082 | AH40: =(AB40*J40)*$AH$1 -> 16.4934 | AI40: =AE40-AG40 -> 2885.6718 | AJ40: 0.18 | AK40: =AI40*AJ40 -> 519.42092 | AL40: =AI40+AK40 -> 3405.0927
...

Sheet Inventory
D4: STOCK REPORT
D5: Periode : 01 to 11July,2026
D6: SKU Name | E6: Opening Stock | F6: Stock In | G6: Stock Out | H6: Balance
D7: Indomie Chicken Chatkhara 120gm | E7: 273 | F7: 1047 | G7: ='STT Report'!Q864+'STT Report'!Z864 -> 913.5 | H7: =E7+F7-G7 -> 406.5
D8: Indomie Lemon Tarka 120gm | E8: 140 | F8: 203 | G8: ='STT Report'!P864+'STT Report'!Y864 -> 634.5 | H8: =E8+F8-G8 -> -291.5
D9: Indomie Meet Masala 120gm | E9: 178 | F9: 750 | G9: ='STT Report'!O864+'STT Report'!X864 -> 769.85 | H9: =E9+F9-G9 -> 158.15
D10: Sub Total | E10: =SUM(E7:E9) -> 591 | F10: =SUM(F7:F9) -> 2000 | G10: =SUM(G7:G9) -> 2317.85 | H10: =SUM(H7:H9) -> 273.15
D11: Indomie Chicken Chatkhara 60gm | E11: 1653 | G11: ='STT Report'!J864 -> 752.275 | H11: =(E11+F11)-G11 -> 900.725
H12: =(E12+F12)-G12 -> 0
H13: =(E13+F13)-G13 -> 0
D14: Sub Total | E14: =SUM(E11:E13) -> 1653 | F14: =SUM(F11:F13) -> 0 | G14: =SUM(G11:G13) -> 752.275 | H14: =SUM(H11:H13) -> 900.725
D15: Indomie Chicken Chatkhara 70gm | E15: 0 | G15: ='STT Report'!M864+'STT Report'!V864 -> 70 | H15: =E15+F15-G15 -> -70
D16: Indomie Lemon Tarka 70gm | E16: 267 | G16: ='STT Report'!L864+'STT Report'!U864 -> 401.675 | H16: =E16+F16-G16 -> -134.675
D17: Indomie Meet Masala 70gm | E17: 240 | G17: ='STT Report'!K864+'STT Report'!T864 -> 394.125 | H17: =E17+F17-G17 -> -154.125
D18: Sub Total | E18: =SUM(E15+E16+E17) -> 507 | F18: =SUM(F15:F17) -> 0 | G18: =SUM(G15:G17) -> 865.8 | H18: =SUM(H15:H17) -> -358.8
D19: Total | E19: =E10+E14+E18 -> 2751 | F19: =F10+F14+F18 -> 2000 | G19: =G10+G14+G18 -> 3935.925 | H19: =H10+H14+H18 -> 815.075
C23: SR NAME | D23: DISTRIBUTION NAME | E23: SR Target JUNE-2026 | F23: Totel CTN Order | G23: FOC 120g 20+1 | H23: FOC 70g10+1 | I23: Totel CTN 120g Sale | J23: Totel CTN 70g Sale | K23: Totel CTN 60g Sale | L23: Totel CTN Sale | M23: Achvid Target %
C24: Zeeshan Meharban | D24: ELITE MARKETING | E24: 500 | F24: =I24+J24+K24 -> 0 | G24: =I24/10 -> 0 | H24: =J24/10 -> 0 | L24: =I24+J24+G24+H24+K24 -> 0 | M24: =L24/E24 -> 0
C25: Salman Butt | D25: ELITE MARKETING | E25: 500 | F25: =I25+J25+K25 -> 0 | G25: =I25/10 -> 0 | H25: =J25/10 -> 0 | L25: =I25+J25+G25+H25+K25 -> 0 | M25: =L25/E25 -> 0
C26: Furqan Ali | D26: ELITE MARKETING | E26: 500 | F26: =I26+J26+K26 -> 0 | G26: =I26/10 -> 0 | H26: =J26/10 -> 0 | L26: =I26+J26+G26+H26+K26 -> 0 | M26: =L26/E26 -> 0
C27: Mobeen Ahmad | D27: ELITE MARKETING | E27: 500 | F27: =I27+J27+K27 -> 0 | G27: =I27/10 -> 0 | H27: =J27/10 -> 0 | L27: =I27+J27+G27+H27+K27 -> 0 | M27: =L27/E27 -> 0
C28: Umair Rehman | D28: ELITE MARKETING | E28: 500 | F28: =I28+J28+K28 -> 0 | G28: =I28/10 -> 0 | H28: =J28/10 -> 0 | L28: =I28+J28+G28+H28+K28 -> 0 | M28: =L28/E28 -> 0
C29: vacant | D29: ELITE MARKETING | E29: 500 | F29: =I29+J29+K29 -> 0 | G29: =I29/10 -> 0 | H29: =J29/10 -> 0 | L29: =I29+J29+G29+H29+K29 -> 0 | M29: =L29/E29 -> 0
C30: Shakoor (LMT) | D30: ELITE MARKETING | E30: 5000 | F30: =I30+J30+K30 -> 0 | G30: =I30/10 -> 0 | H30: =J30/10 -> 0 | L30: =I30+J30+G30+H30+K30 -> 0 | M30: =L30/E30 -> 0
C31: Total | E31: =SUM(E24:E30) -> 8000 | F31: =SUM(F24:F27) -> 0 | G31: =SUM(G24:G27) -> 0 | H31: =SUM(H24:H27) -> 0 | I31: =SUM(I24:I27) -> 0 | J31: =SUM(J24:J27) -> 0 | K31: =SUM(K24:K27) -> 0 | L31: =SUM(L24:L27) -> 0 | M31: =L31/E31 -> 0
