Workbook

Sheet Dist Price List
A2: DEMAND FOR SAMPLES
A3: SNACK FOOD SKU UPDATED LIST | J3: 1.1 | K3: 0.18 | L3: 1.18 | M3: 0.045 | N3: 0.12 | O3: Ex. Price | S3: 0.06 | U3: =K3 -> 0.18
A4: Sr.No | B4: SKUs | C4: Weight gms | E4: Price PKR | F4: Packets / Cartons | G4: Packets | H4: Cartons | J4: Trade Price | K4: GST | L4: Exclusive GST | M4: Adv. TO / Pack | N4: Dis. Margin | O4: Pack | P4: CTN
A5: 1 | B5: DAAL SEV | C5: 16 | D5: gm | E5: 20 | F5: 72 | G5: 100 | J5: =E5/$J$3 -> 18.181818 | K5: =L5*18% -> 2.7734977 | L5: =J5/$L$3 -> 15.40832 | M5: =L5-L5/1.045 -> 0.66351619 | N5: =L5-L5/1.12 -> 1.6508915 | O5: =J5-M5-N5 -> 15.867411 | P5: =O5*F5 -> 1142.4536 | Q5: =L5-M5-N5 -> 13.093913 | S5: =L5*S3 -> 0.92449923 | T5: =L5-S5 -> 14.483821 | U5: =T5+T5*U3 -> 17.090909
A6: 2 | B6: POTATO STICK (CHATPATA) | C6: 16 | D6: gm | E6: 20 | F6: 72 | G6: 100 | J6: =E6/$J$3 -> 18.181818 | K6: =L6*18% -> 2.7734977 | L6: =J6/$L$3 -> 15.40832 | M6: =L6-L6/1.06 -> 0.87216908 | N6: =J6*$N$3 -> 2.1818182 | O6: =J6-M6-N6 -> 15.127831 | P6: =O6*F6 -> 1089.2038 | U6: =U5*12 -> 205.09091
A7: 3 | B7: SPICY MIX NIMKO | C7: 16 | D7: gm | E7: 20 | F7: 72 | G7: 100 | J7: =E7/$J$3 -> 18.181818 | K7: =L7*18% -> 2.7734977 | L7: =J7/$L$3 -> 15.40832 | M7: =L7-L7/1.06 -> 0.87216908 | N7: =J7*$N$3 -> 2.1818182 | O7: =J7-M7-N7 -> 15.127831 | P7: =O7*F7 -> 1089.2038
A8: 4 | B8: NIMBOO DAAL | C8: 16 | D8: gm | E8: 20 | F8: 72 | G8: 100 | J8: =E8/$J$3 -> 18.181818 | K8: =L8*18% -> 2.7734977 | L8: =J8/$L$3 -> 15.40832 | M8: =L8-L8/1.06 -> 0.87216908 | N8: =J8*$N$3 -> 2.1818182 | O8: =J8-M8-N8 -> 15.127831 | P8: =O8*F8 -> 1089.2038
A9: 5 | B9: NIMKO MIX HOT & SPICY | C9: 16 | D9: gm | E9: 20 | F9: 72 | G9: 0 | J9: =E9/$J$3 -> 18.181818 | K9: =L9*18% -> 2.7734977 | L9: =J9/$L$3 -> 15.40832 | M9: =L9-L9/1.06 -> 0.87216908 | N9: =J9*$N$3 -> 2.1818182 | O9: =J9-M9-N9 -> 15.127831 | P9: =O9*F9 -> 1089.2038
A10: 6 | B10: NIMKO MIX LEMON & CHILLI | C10: 16 | D10: gm | E10: 20 | F10: 72 | G10: 0 | J10: =E10/$J$3 -> 18.181818 | K10: =L10*18% -> 2.7734977 | L10: =J10/$L$3 -> 15.40832 | M10: =L10-L10/1.06 -> 0.87216908 | N10: =J10*$N$3 -> 2.1818182 | O10: =J10-M10-N10 -> 15.127831 | P10: =O10*F10 -> 1089.2038
A11: 7 | B11: SLANTY (SALTED) | C11: 10 | D11: gm | E11: 20 | F11: 45 | G11: 0 | J11: =E11/$J$3 -> 18.181818 | K11: =L11*18% -> 2.7734977 | L11: =J11/$L$3 -> 15.40832 | M11: =L11-L11/1.06 -> 0.87216908 | N11: =J11*$N$3 -> 2.1818182 | O11: =J11-M11-N11 -> 15.127831 | P11: =O11*F11 -> 680.75239
A12: 8 | B12: SLANTY (VEGETABLE EU) | C12: 10 | D12: gm | E12: 20 | F12: 45 | G12: 0 | J12: =E12/$J$3 -> 18.181818 | K12: =L12*18% -> 2.7734977 | L12: =J12/$L$3 -> 15.40832 | M12: =L12-L12/1.06 -> 0.87216908 | N12: =J12*$N$3 -> 2.1818182 | O12: =J12-M12-N12 -> 15.127831 | P12: =O12*F12 -> 680.75239
A13: 9 | B13: SLANTY (KETCHUP) | C13: 10 | D13: gm | E13: 20 | F13: 45 | G13: Hold For Printing | J13: =E13/$J$3 -> 18.181818 | K13: =L13*18% -> 2.7734977 | L13: =J13/$L$3 -> 15.40832 | M13: =L13-L13/1.06 -> 0.87216908 | N13: =J13*$N$3 -> 2.1818182 | O13: =J13-M13-N13 -> 15.127831 | P13: =O13*F13 -> 680.75239
A15: 10 | B15: NIMBOO DAAL | C15: 24 | D15: gm | E15: 30 | F15: 45 | G15: 0 | J15: =E15/$J$3 -> 27.272727 | K15: =L15*18% -> 4.1602465 | L15: =J15/$L$3 -> 23.112481 | M15: =L15-L15/1.06 -> 1.3082536 | N15: =J15*$N$3 -> 3.2727273 | O15: =J15-M15-N15 -> 22.691746 | P15: =O15*F15 -> 1021.1286
A16: 11 | B16: DAAL MOUNG | C16: 18 | D16: gm | E16: 30 | F16: 72 | G16: 100 | J16: =E16/$J$3 -> 27.272727 | K16: =L16*18% -> 4.1602465 | L16: =J16/$L$3 -> 23.112481 | M16: =L16-L16/1.06 -> 1.3082536 | N16: =J16*$N$3 -> 3.2727273 | O16: =J16-M16-N16 -> 22.691746 | P16: =O16*F16 -> 1633.8057
A17: 12 | B17: NIMKO MIX HOT & SPICY | C17: 24 | D17: gm | E17: 30 | F17: 45 | G17: 100 | J17: =E17/$J$3 -> 27.272727 | K17: =L17*18% -> 4.1602465 | L17: =J17/$L$3 -> 23.112481 | M17: =L17-L17/1.06 -> 1.3082536 | N17: =J17*$N$3 -> 3.2727273 | O17: =J17-M17-N17 -> 22.691746 | P17: =O17*F17 -> 1021.1286
A18: 13 | B18: POTATO STICK (SALT & PEPPER) | C18: 24 | D18: gm | E18: 30 | F18: 45 | G18: 100 | J18: =E18/$J$3 -> 27.272727 | K18: =L18*18% -> 4.1602465 | L18: =J18/$L$3 -> 23.112481 | M18: =L18-L18/1.06 -> 1.3082536 | N18: =J18*$N$3 -> 3.2727273 | O18: =J18-M18-N18 -> 22.691746 | P18: =O18*F18 -> 1021.1286
A19: 14 | B19: SALTED PEANUT | C19: 16 | D19: gm | E19: 30 | F19: 85 | G19: 100 | J19: =E19/$J$3 -> 27.272727 | K19: =L19*18% -> 4.1602465 | L19: =J19/$L$3 -> 23.112481 | M19: =L19-L19/1.06 -> 1.3082536 | N19: =J19*$N$3 -> 3.2727273 | O19: =J19-M19-N19 -> 22.691746 | P19: =O19*F19 -> 1928.7984
A20: 15 | B20: PEANUT UNSALTED | C20: 16 | D20: gm | E20: 30 | F20: 85 | G20: 100 | J20: =E20/$J$3 -> 27.272727 | K20: =L20*18% -> 4.1602465 | L20: =J20/$L$3 -> 23.112481 | M20: =L20-L20/1.06 -> 1.3082536 | N20: =J20*$N$3 -> 3.2727273 | O20: =J20-M20-N20 -> 22.691746 | P20: =O20*F20 -> 1928.7984
A21: 16 | B21: NIMKO MIX LEMON & CHILLI | C21: 24 | D21: gm | E21: 30 | F21: 45 | G21: 0 | J21: =E21/$J$3 -> 27.272727 | K21: =L21*18% -> 4.1602465 | L21: =J21/$L$3 -> 23.112481 | M21: =L21-L21/1.06 -> 1.3082536 | N21: =J21*$N$3 -> 3.2727273 | O21: =J21-M21-N21 -> 22.691746 | P21: =O21*F21 -> 1021.1286
A22: 17 | B22: SPICY MIX NIMKO | C22: 24 | D22: gm | E22: 30 | F22: 45 | G22: 0 | J22: =E22/$J$3 -> 27.272727 | K22: =L22*18% -> 4.1602465 | L22: =J22/$L$3 -> 23.112481 | M22: =L22-L22/1.06 -> 1.3082536 | N22: =J22*$N$3 -> 3.2727273 | O22: =J22-M22-N22 -> 22.691746 | P22: =O22*F22 -> 1021.1286
A23: 18 | B23: DAAL SEV | C23: 24 | D23: gm | E23: 30 | F23: 45 | G23: 0 | J23: =E23/$J$3 -> 27.272727 | K23: =L23*18% -> 4.1602465 | L23: =J23/$L$3 -> 23.112481 | M23: =L23-L23/1.06 -> 1.3082536 | N23: =J23*$N$3 -> 3.2727273 | O23: =J23-M23-N23 -> 22.691746 | P23: =O23*F23 -> 1021.1286
A24: 19 | B24: SLANTY (SALTED) | C24: 15 | D24: gm | E24: 30 | F24: 30 | G24: 0 | J24: =E24/$J$3 -> 27.272727 | K24: =L24*18% -> 4.1602465 | L24: =J24/$L$3 -> 23.112481 | M24: =L24-L24/1.06 -> 1.3082536 | N24: =J24*$N$3 -> 3.2727273 | O24: =J24-M24-N24 -> 22.691746 | P24: =O24*F24 -> 680.75239
A25: 20 | B25: SLANTY (VEGETABLE EU) | C25: 15 | D25: gm | E25: 30 | F25: 30 | G25: 0 | J25: =E25/$J$3 -> 27.272727 | K25: =L25*18% -> 4.1602465 | L25: =J25/$L$3 -> 23.112481 | M25: =L25-L25/1.06 -> 1.3082536 | N25: =J25*$N$3 -> 3.2727273 | O25: =J25-M25-N25 -> 22.691746 | P25: =O25*F25 -> 680.75239
A26: 21 | B26: SLANTY (KETCHUP) | C26: 15 | D26: gm | E26: 30 | F26: 30 | G26: Hold For Printing | J26: =E26/$J$3 -> 27.272727 | K26: =L26*18% -> 4.1602465 | L26: =J26/$L$3 -> 23.112481 | M26: =L26-L26/1.06 -> 1.3082536 | N26: =J26*$N$3 -> 3.2727273 | O26: =J26-M26-N26 -> 22.691746 | P26: =O26*F26 -> 680.75239
A28: 22 | B28: NIMKO SALT & PEPPER | C28: 40 | D28: gm | E28: 50 | F28: 30 | G28: 100 | J28: =E28/$J$3 -> 45.454545 | K28: =L28*18% -> 6.9337442 | L28: =J28/$L$3 -> 38.520801 | M28: =L28-L28/1.06 -> 2.1804227 | N28: =J28*$N$3 -> 5.4545455 | O28: =J28-M28-N28 -> 37.819577 | P28: =O28*F28 -> 1134.5873
A29: 23 | B29: CHEWRA NIMKO | C29: 30 | D29: gm | E29: 50 | F29: 30 | G29: 100 | J29: =E29/$J$3 -> 45.454545 | K29: =L29*18% -> 6.9337442 | L29: =J29/$L$3 -> 38.520801 | M29: =L29-L29/1.06 -> 2.1804227 | N29: =J29*$N$3 -> 5.4545455 | O29: =J29-M29-N29 -> 37.819577 | P29: =O29*F29 -> 1134.5873
A30: 24 | B30: DAAL MOUNG | C30: 30 | D30: gm | E30: 50 | F30: 45 | G30: 0 | J30: =E30/$J$3 -> 45.454545 | K30: =L30*18% -> 6.9337442 | L30: =J30/$L$3 -> 38.520801 | M30: =L30-L30/1.06 -> 2.1804227 | N30: =J30*$N$3 -> 5.4545455 | O30: =J30-M30-N30 -> 37.819577 | P30: =O30*F30 -> 1701.881
A31: 25 | B31: SALTED PEANUT | C31: 25 | D31: gm | E31: 50 | F31: 45 | G31: 50 | J31: =E31/$J$3 -> 45.454545 | K31: =L31*18% -> 6.9337442 | L31: =J31/$L$3 -> 38.520801 | M31: =L31-L31/1.06 -> 2.1804227 | N31: =J31*$N$3 -> 5.4545455 | O31: =J31-M31-N31 -> 37.819577 | P31: =O31*F31 -> 1701.881
A32: 26 | B32: PEANUT UNSALTED | C32: 25 | D32: gm | E32: 50 | F32: 45 | G32: 50 | J32: =E32/$J$3 -> 45.454545 | K32: =L32*18% -> 6.9337442 | L32: =J32/$L$3 -> 38.520801 | M32: =L32-L32/1.06 -> 2.1804227 | N32: =J32*$N$3 -> 5.4545455 | O32: =J32-M32-N32 -> 37.819577 | P32: =O32*F32 -> 1701.881
A33: 27 | B33: KHAT MITHA | C33: 30 | D33: gm | E33: 50 | F33: 30 | G33: 100 | J33: =E33/$J$3 -> 45.454545 | K33: =L33*18% -> 6.9337442 | L33: =J33/$L$3 -> 38.520801 | M33: =L33-L33/1.06 -> 2.1804227 | N33: =J33*$N$3 -> 5.4545455 | O33: =J33-M33-N33 -> 37.819577 | P33: =O33*F33 -> 1134.5873
A34: 28 | B34: KARACHI NIMCO MIX | C34: 40 | D34: gm | E34: 50 | F34: 30 | G34: 0 | J34: =E34/$J$3 -> 45.454545 | K34: =L34*18% -> 6.9337442 | L34: =J34/$L$3 -> 38.520801 | M34: =L34-L34/1.06 -> 2.1804227 | N34: =J34*$N$3 -> 5.4545455 | O34: =J34-M34-N34 -> 37.819577 | P34: =O34*F34 -> 1134.5873
A35: 29 | B35: SLANTY (SALTED) | C35: 28 | D35: gm | E35: 50 | F35: 24 | G35: 0 | J35: =E35/$J$3 -> 45.454545 | K35: =L35*18% -> 6.9337442 | L35: =J35/$L$3 -> 38.520801 | M35: =L35-L35/1.06 -> 2.1804227 | N35: =J35*$N$3 -> 5.4545455 | O35: =J35-M35-N35 -> 37.819577 | P35: =O35*F35 -> 907.66985
A36: 30 | B36: SLANTY (VEGETABLE EU) | C36: 28 | D36: gm | E36: 50 | F36: 24 | G36: 0 | J36: =E36/$J$3 -> 45.454545 | K36: =L36*18% -> 6.9337442 | L36: =J36/$L$3 -> 38.520801 | M36: =L36-L36/1.06 -> 2.1804227 | N36: =J36*$N$3 -> 5.4545455 | O36: =J36-M36-N36 -> 37.819577 | P36: =O36*F36 -> 907.66985
A37: 31 | B37: SLANTY (KETCHUP) | C37: 28 | D37: gm | E37: 50 | G37: Hold For Printing | J37: =E37/$J$3 -> 45.454545 | K37: =L37*18% -> 6.9337442 | L37: =J37/$L$3 -> 38.520801 | M37: =L37-L37/1.06 -> 2.1804227 | N37: =J37*$N$3 -> 5.4545455 | O37: =J37-M37-N37 -> 37.819577 | P37: =O37*F37 -> 0
A39: 32 | B39: SALTED PEANUT | C39: 40 | D39: gm | E39: 80 | F39: 30 | G39: 50 | J39: =E39/$J$3 -> 72.727273 | K39: =L39*18% -> 11.093991 | L39: =J39/$L$3 -> 61.633282 | M39: =L39-L39/1.06 -> 3.4886763 | N39: =J39*$N$3 -> 8.7272727 | O39: =J39-M39-N39 -> 60.511324 | P39: =O39*F39 -> 1815.3397
A40: 33 | B40: PEANUT UNSALTED | C40: 40 | D40: gm | E40: 80 | F40: 30 | G40: 50 | J40: =E40/$J$3 -> 72.727273 | K40: =L40*18% -> 11.093991 | L40: =J40/$L$3 -> 61.633282 | M40: =L40-L40/1.06 -> 3.4886763 | N40: =J40*$N$3 -> 8.7272727 | O40: =J40-M40-N40 -> 60.511324 | P40: =O40*F40 -> 1815.3397
A42: 34 | B42: SHAHI MIX | C42: 80 | D42: gm | E42: 250 | F42: 40 | G42: 100 | J42: =E42/$J$3 -> 227.27273 | K42: =L42*18% -> 34.668721 | L42: =J42/$L$3 -> 192.60401 | M42: =L42-L42/1.06 -> 10.902114 | N42: =J42*$N$3 -> 27.272727 | O42: =J42-M42-N42 -> 189.09789 | P42: =O42*F42 -> 7563.9155
A43: 35 | B43: LAHORI MIX | C43: 80 | D43: gm | E43: 180 | F43: 40 | G43: 100 | J43: =E43/$J$3 -> 163.63636 | K43: =L43*18% -> 24.961479 | L43: =J43/$L$3 -> 138.67488 | M43: =L43-L43/1.06 -> 7.8495218 | N43: =J43*$N$3 -> 19.636364 | O43: =J43-M43-N43 -> 136.15048 | P43: =O43*F43 -> 5446.0191
A44: 36 | B44: NIMKO SALT & PEPPER | C44: 80 | D44: gm | E44: 120 | F44: 40 | G44: 50 | J44: =E44/$J$3 -> 109.09091 | K44: =L44*18% -> 16.640986 | L44: =J44/$L$3 -> 92.449923 | M44: =L44-L44/1.06 -> 5.2330145 | N44: =J44*$N$3 -> 13.090909 | O44: =J44-M44-N44 -> 90.766985 | P44: =O44*F44 -> 3630.6794
A46: 37 | B46: SHAHI MIX | C46: 180 | D46: gm | E46: 500 | F46: 27 | G46: 0 | J46: =E46/$J$3 -> 454.54545 | K46: =L46*18% -> 69.337442 | L46: =J46/$L$3 -> 385.20801 | M46: =L46-L46/1.06 -> 21.804227 | N46: =J46*$N$3 -> 54.545455 | O46: =J46-M46-N46 -> 378.19577 | P46: =O46*F46 -> 10211.286
...

Sheet Cust. Price List
V2: 0.18
A4: S# | B4: Code | D4: SKU | E4: SKUs Description | F4: Unit | H4: Retail Price | J4: TP Incl. | L4: TP Excl. | N4: Dist Margin | P4: Trade Offre | R4: Stale | T4: Ex-Fac | V4: S.Tax | X4: Dist. Price
B5: Bar | C5: SKU | F5: Gm | G5: CTN | H5: Ctn | I5: Pk | J5: Ctn | K5: Pk | L5: Ctn | M5: Pk | N5: 0.19 | O5: Amount | P5: 0.04 | Q5: Amount | R5: 0.005 | S5: Amount | T5: Ctn | U5: Pk | V5: Ctn | W5: Pk | X5: Ctn | Y5: Pk | AA5: Weight/ctn
A6: 1 | D6: CCN | E6: Chicken Chatkhara | F6: 70 | G6: 40 | H6: =I6*G6 -> 2600 | I6: 65 | J6: =K6*G6 -> 2560.17 | K6: =M6*1.22 -> 64.00425 | L6: 2098.5 | M6: =L6/G6 -> 52.4625 | N6: 0.11 | O6: =N6*M6 -> 5.770875 | Q6: =P6*M6 -> 0 | S6: =R6*M6 -> 0 | T6: =U6*G6 -> 1867.665 | U6: =M6-O6-Q6-S6 -> 46.691625 | V6: =T6*$V$2 -> 336.1797 | W6: =U6*$V$2 -> 8.4044925 | X6: =T6+V6 -> 2203.8447 | Y6: =U6+W6 -> 55.096118 | AA6: =(F6*G6)/1000 -> 2.8 | AB6: 2000 | AC6: =X6*AB6 -> 4407689.4
A7: =+A6+1 -> 2 | D7: VTN | E7: Lemon Tarka | F7: 70 | G7: 40 | H7: =I7*G7 -> 2600 | I7: 65 | J7: =K7*G7 -> 2560.17 | K7: =M7*1.22 -> 64.00425 | L7: 2098.5 | M7: =L7/G7 -> 52.4625 | N7: =+N6 -> 0.11 | O7: =N7*M7 -> 5.770875 | Q7: =P7*M7 -> 0 | S7: =R7*M7 -> 0 | T7: =U7*G7 -> 1867.665 | U7: =M7-O7-Q7-S7 -> 46.691625 | V7: =T7*$V$2 -> 336.1797 | W7: =U7*$V$2 -> 8.4044925 | X7: =T7+V7 -> 2203.8447 | Y7: =U7+W7 -> 55.096118 | AA7: =(F7*G7)/1000 -> 2.8
A8: =+A7+1 -> 3 | D8: BCN | E8: Meat Masala | F8: 70 | G8: 40 | H8: =I8*G8 -> 2600 | I8: 65 | J8: =K8*G8 -> 2560.17 | K8: =M8*1.22 -> 64.00425 | L8: 2098.5 | M8: =L8/G8 -> 52.4625 | N8: =+N7 -> 0.11 | O8: =N8*M8 -> 5.770875 | Q8: =P8*M8 -> 0 | S8: =R8*M8 -> 0 | T8: =U8*G8 -> 1867.665 | U8: =M8-O8-Q8-S8 -> 46.691625 | V8: =T8*$V$2 -> 336.1797 | W8: =U8*$V$2 -> 8.4044925 | X8: =T8+V8 -> 2203.8447 | Y8: =U8+W8 -> 55.096118 | AA8: =(F8*G8)/1000 -> 2.8
A9: =+A8+1 -> 4 | D9: CCNJ | E9: Chicken Chatkhara (Jumbo) | F9: 120 | G9: 40 | H9: =I9*G9 -> 3600 | I9: 90 | J9: =K9*G9 -> 3544.832 | K9: =M9*1.22 -> 88.6208 | L9: 2905.6 | M9: =L9/G9 -> 72.64 | N9: =+N8 -> 0.11 | O9: =N9*M9 -> 7.9904 | Q9: =P9*M9 -> 0 | S9: =R9*M9 -> 0 | T9: =U9*G9 -> 2585.984 | U9: =M9-O9-Q9-S9 -> 64.6496 | V9: =T9*$V$2 -> 465.47712 | W9: =U9*$V$2 -> 11.636928 | X9: =T9+V9 -> 3051.4611 | Y9: =U9+W9 -> 76.286528 | AA9: =(F9*G9)/1000 -> 4.8 | AB9: 1000 | AC9: =X9*AB9 -> 3051461.1
A10: =+A9+1 -> 5 | D10: VTNJ | E10: Lemon Tarka (Jumbo) | F10: 120 | G10: 40 | H10: =I10*G10 -> 3600 | I10: 90 | J10: =K10*G10 -> 3544.832 | K10: =M10*1.22 -> 88.6208 | L10: 2905.6 | M10: =L10/G10 -> 72.64 | N10: =+N9 -> 0.11 | O10: =N10*M10 -> 7.9904 | Q10: =P10*M10 -> 0 | S10: =R10*M10 -> 0 | T10: =U10*G10 -> 2585.984 | U10: =M10-O10-Q10-S10 -> 64.6496 | V10: =T10*$V$2 -> 465.47712 | W10: =U10*$V$2 -> 11.636928 | X10: =T10+V10 -> 3051.4611 | Y10: =U10+W10 -> 76.286528 | AA10: =(F10*G10)/1000 -> 4.8
A11: =+A10+1 -> 6 | D11: BCNJ | E11: Meat Masala (Jumbo) | F11: 120 | G11: 40 | H11: =I11*G11 -> 3600 | I11: 90 | J11: =K11*G11 -> 3544.832 | K11: =M11*1.22 -> 88.6208 | L11: 2905.6 | M11: =L11/G11 -> 72.64 | N11: =+N10 -> 0.11 | O11: =N11*M11 -> 7.9904 | Q11: =P11*M11 -> 0 | S11: =R11*M11 -> 0 | T11: =U11*G11 -> 2585.984 | U11: =M11-O11-Q11-S11 -> 64.6496 | V11: =T11*$V$2 -> 465.47712 | W11: =U11*$V$2 -> 11.636928 | X11: =T11+V11 -> 3051.4611 | Y11: =U11+W11 -> 76.286528 | AA11: =(F11*G11)/1000 -> 4.8
A12: =+A11+1 -> 7 | D12: CCE | E12: Chicken Chatkhara (ECO) | F12: 60 | G12: 40 | H12: =I12*G12 -> 2000 | I12: 50 | J12: =K12*G12 -> 1914.424 | K12: =M12*1.22 -> 47.8606 | L12: 1569.2 | M12: =L12/G12 -> 39.23 | N12: =+N11 -> 0.11 | O12: =N12*M12 -> 4.3153 | Q12: =P12*M12 -> 0 | S12: =R12*M12 -> 0 | T12: =U12*G12 -> 1396.588 | U12: =M12-O12-Q12-S12 -> 34.9147 | V12: =T12*$V$2 -> 251.38584 | W12: =U12*$V$2 -> 6.284646 | X12: =T12+V12 -> 1647.9738 | Y12: =U12+W12 -> 41.199346 | AA12: =(F12*G12)/1000 -> 2.4 | AB12: 2000 | AC12: =X12*AB12 -> 3295947.7
A13: =+A12+1 -> 8 | D13: VTE | E13: Lemon Tarka (ECO) | F13: 60 | G13: 40 | H13: =I13*G13 -> 2000 | I13: 50 | J13: =K13*G13 -> 1914.424 | K13: =M13*1.22 -> 47.8606 | L13: 1569.2 | M13: =L13/G13 -> 39.23 | N13: =+N12 -> 0.11 | O13: =N13*M13 -> 4.3153 | Q13: =P13*M13 -> 0 | S13: =R13*M13 -> 0 | T13: =U13*G13 -> 1396.588 | U13: =M13-O13-Q13-S13 -> 34.9147 | V13: =T13*$V$2 -> 251.38584 | W13: =U13*$V$2 -> 6.284646 | X13: =T13+V13 -> 1647.9738 | Y13: =U13+W13 -> 41.199346 | AA13: =(F13*G13)/1000 -> 2.4 | AC13: =SUM(AC6:AC12) -> 10755098
A14: =+A13+1 -> 9 | D14: BCE | E14: Meat Masala (ECO) | F14: 60 | G14: 40 | H14: =I14*G14 -> 2000 | I14: 50 | J14: =K14*G14 -> 1914.424 | K14: =M14*1.22 -> 47.8606 | L14: 1569.2 | M14: =L14/G14 -> 39.23 | N14: =+N13 -> 0.11 | O14: =N14*M14 -> 4.3153 | Q14: =P14*M14 -> 0 | S14: =R14*M14 -> 0 | T14: =U14*G14 -> 1396.588 | U14: =M14-O14-Q14-S14 -> 34.9147 | V14: =T14*$V$2 -> 251.38584 | W14: =U14*$V$2 -> 6.284646 | X14: =T14+V14 -> 1647.9738 | Y14: =U14+W14 -> 41.199346 | AA14: =(F14*G14)/1000 -> 2.4
A15: =+A14+1 -> 10
A16: =+A15+1 -> 11
A17: =+A16+1 -> 12
A18: =+A17+1 -> 13
A19: =+A18+1 -> 14
A20: =+A19+1 -> 15
A22: =+A20+1 -> 16
A23: =+A22+1 -> 17
A24: =+A23+1 -> 18
A25: =+A24+1 -> 19
A26: =+A25+1 -> 20
A27: =+A26+1 -> 21
A28: =+A27+1 -> 22
A29: =+A28+1 -> 23
A30: =+A29+1 -> 24
A31: =+A30+1 -> 25
A32: =+A31+1 -> 26
A33: =+A32+1 -> 27
A34: =+A33+1 -> 28
A36: =+A34+1 -> 29
A37: =+A36+1 -> 30
A38: =+A37+1 -> 31
A39: =+A38+1 -> 32
A40: =+A39+1 -> 33
A41: =+A40+1 -> 34
A42: =+A41+1 -> 35
A43: =+A42+1 -> 36
A44: =+A43+1 -> 37
...

Sheet Customer Invoice
A2: ABC
A3: 44A- Gulberg Lahore | K3: Invoice No # : | XEU3: Filer | XEV3: 0.005
A4: STRN / NTN : 12345-6789012-3/1234567-3 | K4: Date/Day : | N4: =TODAY()+1 -> 46320 | XEU4: Non-filer | XEV4: 0.025
A5: Customer Code : | K5: Order Date : | N5: =N4-1 -> 46319
A6: Customer Name : | K6: Order Name : | N6: Muhammad Hamza | XEU6: Registered | XEV6: 0.18
A7: CNIC #:12345-6789012-3 | K7: Route Name : | N7: Jallo-&-Taiz Ghar-&-Thu | XEU7: Un-registered | XEV7: 0.22
A8: Address: | K8: Section Name: | N8: Taiz Ghar
A9: Channel Type:Retail/LMT | K9: Visit & Delivery Day | N9: Monday/Tuesday | XEV9: Yes
A10: Sub-Channel:General/medical/LMT Store / | K10: Invoice Status : | N10: Serviced | XEV10: No
A11: NTN Status: | B11: Filer | C11: =IF($O34>2.49%,"No","Yes") -> Yes | K11: Order at Original Location : | N11: Yes
A12: STRN Status: | B12: Un-registered | C12: =IF($O32>21.99%,"No","Yes") -> Yes | K12: Reference Invoice : | XEV12: Monday/Tuesday
S13: Discount Slab | XEV13: Tuesday / Wednesday
A14: Product Code/Description | C14: GM/ Pack | D14: CTN | E14: Unit | G14: Sale QTY | I14: Gross Amount Excl. Taxes | J14: Trade Offer & Discount | M14: After Discount Amount | N14: GST 18% | O14: Adv. Tax 236H | P14: Invoice | XEV14: Wednesday/Thursday
D15: SIZE | E15: MRP | F15: T.P Per | G15: CTN | H15: Pack | J15: Pass On | K15: Trade Offer | L15: Add. | O15: =IF(B11="Filer",0.5%,2.5%) -> 0.005 | P15: Amount | S15: Pass On | T15: Trade Offer | U15: additional | XEV15: Thursday /Friday
A16: BCN | B16: =VLOOKUP($A16,'Cust. Price List'!$D$6:$O$14,2,0) -> Meat Masala | C16: =VLOOKUP(A16,'Cust. Price List'!D6:M14,3,0) -> 70 | D16: =VLOOKUP(A16,'Cust. Price List'!D6:M14,4,0) -> 40 | E16: =VLOOKUP(A16,'Cust. Price List'!D6:M14,6,0) -> 65 | F16: =VLOOKUP(A16,'Cust. Price List'!D6:M14,10,0) -> 52.4625 | G16: 1 | I16: =(G16*D16)*F16+H16*F16 -> 2098.5 | J16: =$I16*S16 -> 304.2825 | K16: =$I16*T16 -> 73.4475 | L16: =$I16*U16 -> 0 | M16: =I16-SUM(J16:L16) -> 1720.77 | N16: =(G16*D16+H16)*(E16-E16/1.18) -> 396.61017 | O16: =(N16+M16)*$O$15 -> 10.586901 | P16: =M16+N16+O16 -> 2127.9671 | S16: 0.145 | T16: 0.035 | XEV16: Friday / Saturday
A17: VTN | B17: =VLOOKUP($A17,'Cust. Price List'!$D$6:$O$14,2,0) -> Lemon Tarka | C17: =VLOOKUP(B17,'Cust. Price List'!E7:P15,2,0) -> 70 | D17: =VLOOKUP(A17,'Cust. Price List'!D7:M15,4,0) -> 40 | E17: =VLOOKUP(A17,'Cust. Price List'!D7:M15,6,0) -> 65 | F17: =VLOOKUP(A17,'Cust. Price List'!D7:M15,10,0) -> 52.4625 | G17: 1 | I17: =(G17*D17)*F17+H17*F17 -> 2098.5 | J17: =$I17*S17 -> 304.2825 | K17: =$I17*T17 -> 73.4475 | L17: =$I17*U17 -> 0 | M17: =I17-SUM(J17:L17) -> 1720.77 | N17: =(G17*D17+H17)*(E17-E17/1.18) -> 396.61017 | O17: =(N17+M17)*$O$15 -> 10.586901 | P17: =M17+N17+O17 -> 2127.9671 | S17: =+S16 -> 0.145 | T17: =+T16 -> 0.035 | XEV17: Saturday /Monday
A18: CCN | B18: =VLOOKUP($A18,'Cust. Price List'!$D$6:$O$14,2,0) -> Chicken Chatkhara | C18: =VLOOKUP(B18,'Cust. Price List'!E8:P16,2,0) -> #N/A | D18: =VLOOKUP(A18,'Cust. Price List'!D8:M16,4,0) -> #N/A | E18: =VLOOKUP(A18,'Cust. Price List'!D8:M16,6,0) -> #N/A | F18: =VLOOKUP(A18,'Cust. Price List'!D8:M16,10,0) -> #N/A | G18: 1 | I18: =(G18*D18)*F18+H18*F18 -> #N/A | J18: =$I18*S18 -> #N/A | K18: =$I18*T18 -> #N/A | L18: =$I18*U18 -> #N/A | M18: =I18-SUM(J18:L18) -> #N/A | N18: =(G18*D18+H18)*(E18-E18/1.18) -> #N/A | O18: =(N18+M18)*$O$15 -> #N/A | P18: =M18+N18+O18 -> #N/A | S18: =+S17 -> 0.145 | T18: =+T17 -> 0.035
A19: BCNJ | B19: =VLOOKUP($A19,'Cust. Price List'!$D$6:$O$14,2,0) -> Meat Masala (Jumbo) | C19: =VLOOKUP(B19,'Cust. Price List'!E9:P17,2,0) -> 120 | D19: =VLOOKUP(A19,'Cust. Price List'!D9:M17,4,0) -> 40 | E19: =VLOOKUP(A19,'Cust. Price List'!D9:M17,6,0) -> 90 | F19: =VLOOKUP(A19,'Cust. Price List'!D9:M17,10,0) -> 72.64 | G19: 1 | I19: =(G19*D19)*F19+H19*F19 -> 2905.6 | J19: =$I19*S19 -> 421.312 | K19: =$I19*T19 -> 101.696 | L19: =$I19*U19 -> 0 | M19: =I19-SUM(J19:L19) -> 2382.592 | N19: =(G19*D19+H19)*(E19-E19/1.18) -> 549.15254 | O19: =(N19+M19)*$O$15 -> 14.658723 | P19: =M19+N19+O19 -> 2946.4033 | S19: =+S18 -> 0.145 | T19: 0.035
A20: VTNJ | B20: =VLOOKUP($A20,'Cust. Price List'!$D$6:$O$14,2,0) -> Lemon Tarka (Jumbo) | C20: =VLOOKUP(B20,'Cust. Price List'!E10:P18,2,0) -> 120 | D20: =VLOOKUP(A20,'Cust. Price List'!D10:M18,4,0) -> 40 | E20: =VLOOKUP(A20,'Cust. Price List'!D10:M18,6,0) -> 90 | F20: =VLOOKUP(A20,'Cust. Price List'!D10:M18,10,0) -> 72.64 | G20: 1 | I20: =(G20*D20)*F20+H20*F20 -> 2905.6 | J20: =$I20*S20 -> 421.312 | K20: =$I20*T20 -> 101.696 | L20: =$I20*U20 -> 0 | M20: =I20-SUM(J20:L20) -> 2382.592 | N20: =(G20*D20+H20)*(E20-E20/1.18) -> 549.15254 | O20: =(N20+M20)*$O$15 -> 14.658723 | P20: =M20+N20+O20 -> 2946.4033 | S20: =+S19 -> 0.145 | T20: =+T19 -> 0.035
A21: CCNJ | B21: =VLOOKUP($A21,'Cust. Price List'!$D$6:$O$14,2,0) -> Chicken Chatkhara (Jumbo) | C21: =VLOOKUP(B21,'Cust. Price List'!E11:P19,2,0) -> #N/A | D21: =VLOOKUP(A21,'Cust. Price List'!D11:M19,4,0) -> #N/A | E21: =VLOOKUP(A21,'Cust. Price List'!D11:M19,6,0) -> #N/A | F21: =VLOOKUP(A21,'Cust. Price List'!D11:M19,10,0) -> #N/A | G21: 1 | I21: =(G21*D21)*F21+H21*F21 -> #N/A | J21: =$I21*S21 -> #N/A | K21: =$I21*T21 -> #N/A | L21: =$I21*U21 -> #N/A | M21: =I21-SUM(J21:L21) -> #N/A | N21: =(G21*D21+H21)*(E21-E21/1.18) -> #N/A | O21: =(N21+M21)*$O$15 -> #N/A | P21: =M21+N21+O21 -> #N/A | S21: =+S20 -> 0.145 | T21: =+T20 -> 0.035
A22: CCE | B22: =VLOOKUP($A22,'Cust. Price List'!$D$6:$O$14,2,0) -> Chicken Chatkhara (ECO) | C22: =VLOOKUP(B22,'Cust. Price List'!E12:P20,2,0) -> 60 | D22: =VLOOKUP(A22,'Cust. Price List'!D12:M20,4,0) -> 40 | E22: =VLOOKUP(A22,'Cust. Price List'!D12:M20,6,0) -> 50 | F22: =VLOOKUP(A22,'Cust. Price List'!D12:M20,10,0) -> 39.23 | G22: 1 | I22: =(G22*D22)*F22+H22*F22 -> 1569.2 | J22: =$I22*S22 -> 0 | K22: =$I22*T22 -> 54.922 | L22: =$I22*U22 -> 80.0292 | M22: =I22-SUM(J22:L22) -> 1434.2488 | N22: =(G22*D22+H22)*(E22-E22/1.18) -> 305.08475 | O22: =(N22+M22)*$O$15 -> 8.6966677 | P22: =M22+N22+O22 -> 1748.0302 | T22: 0.035 | U22: 0.051
A23: VTE | B23: =VLOOKUP($A23,'Cust. Price List'!$D$6:$O$14,2,0) -> Lemon Tarka (ECO) | C23: =VLOOKUP(B23,'Cust. Price List'!E13:P21,2,0) -> 60 | D23: =VLOOKUP(A23,'Cust. Price List'!D13:M21,4,0) -> 40 | E23: =VLOOKUP(A23,'Cust. Price List'!D13:M21,6,0) -> 50 | F23: =VLOOKUP(A23,'Cust. Price List'!D13:M21,10,0) -> 39.23 | I23: =(G23*D23)*F23+H23*F23 -> 0 | J23: =$I23*S23 -> 0 | K23: =$I23*T23 -> 0 | L23: =$I23*U23 -> 0 | M23: =I23-SUM(J23:L23) -> 0 | N23: =(G23*D23+H23)*(E23-E23/1.18) -> 0 | O23: =(N23+M23)*$O$15 -> 0 | P23: =M23+N23+O23 -> 0 | S23: =+S22 -> 0 | T23: =+T22 -> 0.035 | U23: =+U22 -> 0.051
A24: BCE | B24: =VLOOKUP($A24,'Cust. Price List'!$D$6:$O$14,2,0) -> Meat Masala (ECO) | C24: =VLOOKUP(B24,'Cust. Price List'!E14:P22,2,0) -> 60 | D24: =VLOOKUP(A24,'Cust. Price List'!D14:M22,4,0) -> 40 | E24: =VLOOKUP(A24,'Cust. Price List'!D14:M22,6,0) -> 50 | F24: =VLOOKUP(A24,'Cust. Price List'!D14:M22,10,0) -> 39.23 | I24: =(G24*D24)*F24+H24*F24 -> 0 | J24: =$I24*S24 -> 0 | K24: =$I24*T24 -> 0 | L24: =$I24*U24 -> 0 | M24: =I24-SUM(J24:L24) -> 0 | N24: =(G24*D24+H24)*(E24-E24/1.18) -> 0 | O24: =(N24+M24)*$O$15 -> 0 | P24: =M24+N24+O24 -> 0 | S24: =+S23 -> 0 | T24: =+T23 -> 0.035 | U24: =+U23 -> 0.051
C25: Total | G25: =SUM(G16:G24) -> 7 | H25: =SUM(H16:H24) -> 0 | I25: =SUM(I16:I24) -> #N/A | J25: =SUM(J16:J24) -> #N/A | K25: =SUM(K16:K24) -> #N/A | L25: =SUM(L16:L24) -> #N/A | M25: =SUM(M16:M24) -> #N/A | N25: =SUM(N16:N24) -> #N/A | ... P25: =SUM(P16:P24) -> #N/A
S27: =+F22*22% -> 8.6306
B28: یکم جولائی 2024سے نئی ٹیکس ترمیم کے مطابق، ایف بی آر سیکشن 236 ایچ کے مطابق، فائلرز کے لیے ہر سیل انوائس پر 0.5% اور نان فائلرز کے لیے 2.5% ایڈوانس ود ہولڈنگ ٹیکس وصول کیا جائے گا۔ | N28: Gross Amount: | P28: =I25 -> #N/A | S28: 7.63
N29: Regular Discount | P29: =+J25 -> #N/A
N30: Trade Offre | P30: =+K25+L25 -> #N/A
N31: After Dis. Amount | P31: =P28-P29-P30 -> #N/A
N32: Total GST: | O32: 0.18 | P32: =+N25 -> #N/A
N33: Net Amount: | P33: =P31+P32 -> #N/A
N34: Ad.Tax | O34: =IF(B11="Filer",0.5%,2.5%) -> 0.005 | P34: =O34*P33 -> #N/A
N35: Net Amount with Ad.Tax | P35: =+P33+P34 -> #N/A
B36: Delivered By

Sheet Customer Invoice (2)
A2: KK MART
A3: 44A- Gulberg Lahore | L3: Invoice No # :0001 | XEW3: Filer | XEX3: 0.005
A4: STRN / NTN : 12345-6789012-3/1234567-3 | L4: Date/Day : | P4: 46319 | XEW4: Non-filer | XEX4: 0.025
A5: Customer Code : | L5: Order Date : | P5: =P4-1 -> 46318
A6: Customer Name : | L6: Order Name : | P6: Shakoor Ahmad | XEW6: Registered | XEX6: 0.18
A7: NTN #: I978845-5 | L7: Route Name : | P7: Jallo-&-Taiz Ghar-&-Thu | XEW7: Un-registered | XEX7: 0.22
A8: Address:Gulberg Main Market Road | L8: Section Name: | P8: Taiz Ghar
A9: Channel Type:Retail/LMT | L9: Visit & Delivery Day | P9: Monday/Tuesday | XEX9: Yes
A10: Sub-Channel:General/medical/LMT Store / | L10: Invoice Status : | P10: Serviced | XEX10: No
A11: NTN Status: | B11: Filer | C11: =IF($Q34>2.49%,"No","Yes") -> Yes | L11: Order at Original Location : | P11: Yes
A12: STRN Status: | B12: Registered | C12: =IF($Q32>21.99%,"No","Yes") -> Yes | L12: Reference Invoice : | XEX12: Monday/Tuesday
U13: Discount Slab | XEX13: Tuesday / Wednesday
A14: Product Code/Description | C14: GM/ Pack | D14: CTN | E14: Unit | H14: Sale QTY | J14: Gross Amount Excl. Taxes | K14: Discount | P14: GST 18% | Q14: Adv. Tax 236H | R14: Invoice | XEX14: Wednesday/Thursday
D15: SIZE | E15: MRP | F15: T.P Exclu. GST | G15: MRP Exclu. GST | H15: CTN | I15: Pack | K15: Regular | L15: Additional(TO) | M15: Display | N15: Induction | O15: After Discount Amount | Q15: =IF(B11="Filer",0.5%,2.5%) -> 0.005 | R15: Amount | U15: Pass On | V15: Trade Offer | W15: additional | XEX15: Thursday /Friday
A16: CCN | B16: =VLOOKUP($A16,'Cust. Price List'!$D$6:$O$14,2,0) -> Chicken Chatkhara | C16: =VLOOKUP(A16,'Cust. Price List'!D6:M14,3,0) -> 70 | D16: =VLOOKUP(A16,'Cust. Price List'!D6:M14,4,0) -> 40 | E16: =VLOOKUP(A16,'Cust. Price List'!D6:M14,6,0) -> 65 | F16: =VLOOKUP(A16,'Cust. Price List'!D6:M14,10,0) -> 52.4625 | G16: =+E16/1.18 -> 55.084746 | I16: 144 | J16: =(H16*D16)*F16+I16*F16 -> 7554.6 | K16: =$J16*$C$36 -> 604.368 | L16: =$J16*$C$37 -> 264.411 | M16: =+J16*$C$38 -> 151.092 | N16: =$J16*$C$39 -> 151.092 | O16: =J16-SUM(K16:N16) -> 6383.637 | P16: =(H16*D16+I16)*(E16-E16/1.18) -> 1427.7966 | Q16: =(P16+O16)*$Q$15 -> 39.057168 | R16: =O16+P16+Q16 -> 7850.4908 | U16: 0.08 | V16: 0.035 | XEX16: Friday / Saturday
A17: VTN | B17: =VLOOKUP($A17,'Cust. Price List'!$D$6:$O$14,2,0) -> Lemon Tarka | C17: =VLOOKUP(A17,'Cust. Price List'!D7:M15,3,0) -> 70 | D17: =VLOOKUP(A17,'Cust. Price List'!D7:M15,4,0) -> 40 | E17: =VLOOKUP(A17,'Cust. Price List'!D7:M15,6,0) -> 65 | F17: =VLOOKUP(A17,'Cust. Price List'!D7:M15,10,0) -> 52.4625 | G17: =+E17/1.18 -> 55.084746 | I17: 288 | J17: =(H17*D17)*F17+I17*F17 -> 15109.2 | K17: =$J17*$C$36 -> 1208.736 | L17: =$J17*$C$37 -> 528.822 | M17: =+J17*$C$38 -> 302.184 | N17: =$J17*$C$39 -> 302.184 | O17: =J17-SUM(K17:N17) -> 12767.274 | P17: =(H17*D17+I17)*(E17-E17/1.18) -> 2855.5932 | Q17: =(P17+O17)*$Q$15 -> 78.114336 | R17: =O17+P17+Q17 -> 15700.982 | U17: =+U16 -> 0.08 | V17: =+V16 -> 0.035 | XEX17: Saturday /Monday
A18: BCN | B18: =VLOOKUP($A18,'Cust. Price List'!$D$6:$O$14,2,0) -> Meat Masala | C18: =VLOOKUP(A18,'Cust. Price List'!D8:M16,3,0) -> 70 | D18: =VLOOKUP(A18,'Cust. Price List'!D8:M16,4,0) -> 40 | E18: =VLOOKUP(A18,'Cust. Price List'!D8:M16,6,0) -> 65 | F18: =VLOOKUP(A18,'Cust. Price List'!D8:M16,10,0) -> 52.4625 | G18: =+E18/1.18 -> 55.084746 | I18: 288 | J18: =(H18*D18)*F18+I18*F18 -> 15109.2 | K18: =$J18*$C$36 -> 1208.736 | L18: =$J18*$C$37 -> 528.822 | M18: =+J18*$C$38 -> 302.184 | N18: =$J18*$C$39 -> 302.184 | O18: =J18-SUM(K18:N18) -> 12767.274 | P18: =(H18*D18+I18)*(E18-E18/1.18) -> 2855.5932 | Q18: =(P18+O18)*$Q$15 -> 78.114336 | R18: =O18+P18+Q18 -> 15700.982 | U18: =+U17 -> 0.08 | V18: =+V17 -> 0.035
A19: CCNJ | B19: =VLOOKUP($A19,'Cust. Price List'!$D$6:$O$14,2,0) -> Chicken Chatkhara (Jumbo) | C19: =VLOOKUP(A19,'Cust. Price List'!D9:M17,3,0) -> 120 | D19: =VLOOKUP(A19,'Cust. Price List'!D9:M17,4,0) -> 40 | E19: =VLOOKUP(A19,'Cust. Price List'!D9:M17,6,0) -> 90 | F19: =VLOOKUP(A19,'Cust. Price List'!D9:M17,10,0) -> 72.64 | G19: =+E19/1.18 -> 76.271186 | I19: 432 | J19: =(H19*D19)*F19+I19*F19 -> 31380.48 | K19: =$J19*$C$36 -> 2510.4384 | L19: =$J19*$C$37 -> 1098.3168 | M19: =+J19*$C$38 -> 627.6096 | N19: =$J19*$C$39 -> 627.6096 | O19: =J19-SUM(K19:N19) -> 26516.506 | P19: =(H19*D19+I19)*(E19-E19/1.18) -> 5930.8475 | Q19: =(P19+O19)*$Q$15 -> 162.23677 | R19: =O19+P19+Q19 -> 32609.59 | U19: =+U18 -> 0.08 | V19: 0.035
A20: VTNJ | B20: =VLOOKUP($A20,'Cust. Price List'!$D$6:$O$14,2,0) -> Lemon Tarka (Jumbo) | C20: =VLOOKUP(A20,'Cust. Price List'!D10:M18,3,0) -> 120 | D20: =VLOOKUP(A20,'Cust. Price List'!D10:M18,4,0) -> 40 | E20: =VLOOKUP(A20,'Cust. Price List'!D10:M18,6,0) -> 90 | F20: =VLOOKUP(A20,'Cust. Price List'!D10:M18,10,0) -> 72.64 | G20: =+E20/1.18 -> 76.271186 | I20: 288 | J20: =(H20*D20)*F20+I20*F20 -> 20920.32 | K20: =$J20*$C$36 -> 1673.6256 | L20: =$J20*$C$37 -> 732.2112 | M20: =+J20*$C$38 -> 418.4064 | N20: =$J20*$C$39 -> 418.4064 | O20: =J20-SUM(K20:N20) -> 17677.67 | P20: =(H20*D20+I20)*(E20-E20/1.18) -> 3953.8983 | Q20: =(P20+O20)*$Q$15 -> 108.15784 | R20: =O20+P20+Q20 -> 21739.727 | U20: =+U19 -> 0.08 | V20: =+V19 -> 0.035
A21: BCNJ | B21: =VLOOKUP($A21,'Cust. Price List'!$D$6:$O$14,2,0) -> Meat Masala (Jumbo) | C21: =VLOOKUP(A21,'Cust. Price List'!D11:M19,3,0) -> 120 | D21: =VLOOKUP(A21,'Cust. Price List'!D11:M19,4,0) -> 40 | E21: =VLOOKUP(A21,'Cust. Price List'!D11:M19,6,0) -> 90 | F21: =VLOOKUP(A21,'Cust. Price List'!D11:M19,10,0) -> 72.64 | G21: =+E21/1.18 -> 76.271186 | I21: 432 | J21: =(H21*D21)*F21+I21*F21 -> 31380.48 | K21: =$J21*$C$36 -> 2510.4384 | L21: =$J21*$C$37 -> 1098.3168 | M21: =+J21*$C$38 -> 627.6096 | N21: =$J21*$C$39 -> 627.6096 | O21: =J21-SUM(K21:N21) -> 26516.506 | P21: =(H21*D21+I21)*(E21-E21/1.18) -> 5930.8475 | Q21: =(P21+O21)*$Q$15 -> 162.23677 | R21: =O21+P21+Q21 -> 32609.59 | U21: =+U20 -> 0.08 | V21: =+V20 -> 0.035
A22: CCE | B22: =VLOOKUP($A22,'Cust. Price List'!$D$6:$O$14,2,0) -> Chicken Chatkhara (ECO) | C22: =VLOOKUP(A22,'Cust. Price List'!D12:M20,3,0) -> 60 | D22: =VLOOKUP(A22,'Cust. Price List'!D12:M20,4,0) -> 40 | E22: =VLOOKUP(A22,'Cust. Price List'!D12:M20,6,0) -> 50 | F22: =VLOOKUP(A22,'Cust. Price List'!D12:M20,10,0) -> 39.23 | G22: =+E22/1.18 -> 42.372881 | J22: =(H22*D22)*F22+I22*F22 -> 0 | K22: =$J22*$C$36 -> 0 | L22: =$J22*$C$37 -> 0 | M22: =+J22*$C$38 -> 0 | N22: =$J22*$C$39 -> 0 | O22: =J22-SUM(K22:N22) -> 0 | P22: =(H22*D22+I22)*(E22-E22/1.18) -> 0 | Q22: =(P22+O22)*$Q$15 -> 0 | R22: =O22+P22+Q22 -> 0 | U22: 0.05 | V22: 0.035 | W22: 0.051
A23: VTE | B23: =VLOOKUP($A23,'Cust. Price List'!$D$6:$O$14,2,0) -> Lemon Tarka (ECO) | C23: =VLOOKUP(B23,'Cust. Price List'!E13:P21,2,0) -> 60 | D23: =VLOOKUP(A23,'Cust. Price List'!D13:M21,4,0) -> 40 | E23: =VLOOKUP(A23,'Cust. Price List'!D13:M21,6,0) -> 50 | F23: =VLOOKUP(A23,'Cust. Price List'!D13:M21,10,0) -> 39.23 | J23: =(H23*D23)*F23+I23*F23 -> 0 | K23: =$J23*U23 -> 0 | L23: =$J23*V23 -> 0 | N23: =$J23*W23 -> 0 | O23: =J23-SUM(K23:N23) -> 0 | P23: =(H23*D23+I23)*(E23-E23/1.18) -> 0 | Q23: =(P23+O23)*$Q$15 -> 0 | R23: =O23+P23+Q23 -> 0 | U23: =+U22 -> 0.05 | V23: =+V22 -> 0.035 | W23: =+W22 -> 0.051
A24: BCE | B24: =VLOOKUP($A24,'Cust. Price List'!$D$6:$O$14,2,0) -> Meat Masala (ECO) | C24: =VLOOKUP(B24,'Cust. Price List'!E14:P22,2,0) -> 60 | D24: =VLOOKUP(A24,'Cust. Price List'!D14:M22,4,0) -> 40 | E24: =VLOOKUP(A24,'Cust. Price List'!D14:M22,6,0) -> 50 | F24: =VLOOKUP(A24,'Cust. Price List'!D14:M22,10,0) -> 39.23 | J24: =(H24*D24)*F24+I24*F24 -> 0 | K24: =$J24*U24 -> 0 | L24: =$J24*V24 -> 0 | N24: =$J24*W24 -> 0 | O24: =J24-SUM(K24:N24) -> 0 | P24: =(H24*D24+I24)*(E24-E24/1.18) -> 0 | Q24: =(P24+O24)*$Q$15 -> 0 | R24: =O24+P24+Q24 -> 0 | U24: =+U23 -> 0.05 | V24: =+V23 -> 0.035 | W24: =+W23 -> 0.051
C25: Total | H25: =SUM(H16:H24) -> 0 | I25: =SUM(I16:I24) -> 1872 | J25: =SUM(J16:J24) -> 121454.28 | K25: =SUM(K16:K24) -> 9716.3424 | L25: =SUM(L16:L24) -> 4250.8998 | M25: =SUM(M16:M24) -> 2429.0856 | N25: =SUM(N16:N24) -> 2429.0856 | O25: =SUM(O16:O24) -> 102628.87 | ... R25: =SUM(R16:R24) -> 126211.36
U27: =+F22*22% -> 8.6306
B28: یکم جولائی 2024سے نئی ٹیکس ترمیم کے مطابق، ایف بی آر سیکشن 236 ایچ کے مطابق، فائلرز کے لیے ہر سیل انوائس پر 0.5% اور نان فائلرز کے لیے 2.5% ایڈوانس ود ہولڈنگ ٹیکس وصول کیا جائے گا۔ | P28: Gross Amount: | R28: =J25 -> 121454.28 | U28: 7.63
P29: Regular Discount | R29: =+K25 -> 9716.3424
P30: Trade Offre | R30: =+L25+N25 -> 6679.9854
P31: After Dis. Amount | R31: =R28-R29-R30 -> 105057.95
P32: GST on MRP | Q32: 0.18 | R32: =+P25 -> 22954.576
P33: Net Amount: | R33: =R31+R32 -> 128012.53
P34: Ad.Tax | Q34: =IF(B11="Filer",0.5%,2.5%) -> 0.005 | R34: =Q34*R33 -> 640.06264
P35: Net Amount with Ad.Tax | R35: =+R33+R34 -> 128652.59
A36: 1 | B36: Regular Discount | C36: 0.08
A37: 2 | B37: Additional Discount | C37: 0.035
A38: 3 | B38: Discount in shape of display | C38: 0.02
A39: 4 | B39: Discount in shape of Induction | C39: 0.02
A40: Total | C40: =SUM(C36:C39) -> 0.155
