Workbook

Sheet Sheet2
B5: OB Name
A6: 1 | B6: Salman Butt
A7: 2 | B7: Qasim Khan
A8: 3 | B8: Mobeen Ahmad
A9: 4 | B9: Zahid Rafique
A10: 5 | B10: Zeeshan Meharban
A11: 6 | B11: Furqan
A12: 7 | B12: Rana Bilal Tso
A13: 8 | B13: Shakoor
A14: 9
A15: 10
A16: 11
A17: 12
A18: 13

Sheet Cust. Price List
V2: 0.18
A4: S# | B4: Code | D4: SKU | E4: SKUs Description | F4: Unit | H4: Retail Price | J4: TP Incl. | L4: TP Excl. | N4: Dist Margin | P4: Trade Offre | R4: Stale | T4: Ex-Fac | V4: S.Tax | X4: Dist. Price
B5: Bar | C5: SKU | F5: Gm | G5: CTN | H5: Ctn | I5: Pk | J5: Ctn | K5: Pk | L5: Ctn | M5: Pk | N5: 0.19 | O5: Amount | P5: 0.04 | Q5: Amount | R5: 0.005 | S5: Amount | T5: Ctn | U5: Pk | V5: Ctn | W5: Pk | X5: Ctn | Y5: Pk | AA5: Weight/ctn
A6: 1 | C6: BCN | D6: BCN | E6: Meat Masala | F6: 70 | G6: 40 | H6: =I6*G6 -> 2600 | I6: 65 | J6: =K6*G6 -> 2560.17 | K6: =M6*1.22 -> 64.00425 | L6: 2098.5 | M6: =L6/G6 -> 52.4625 | N6: 0.19 | O6: =N6*M6 -> 9.967875 | Q6: =P6*M6 -> 0 | S6: =R6*M6 -> 0 | T6: =U6*G6 -> 1699.785 | U6: =M6-O6-Q6-S6 -> 42.494625 | V6: =T6*$V$2 -> 305.9613 | W6: =U6*$V$2 -> 7.6490325 | X6: =T6+V6 -> 2005.7463 | Y6: =U6+W6 -> 50.143657 | AA6: =(F6*G6)/1000 -> 2.8
A7: =+A6+1 -> 2 | C7: VTN | D7: VTN | E7: Lemon Tarka | F7: 70 | G7: 40 | H7: =I7*G7 -> 2600 | I7: 65 | J7: =K7*G7 -> 2560.17 | K7: =M7*1.22 -> 64.00425 | L7: 2098.5 | M7: =L7/G7 -> 52.4625 | N7: =+N6 -> 0.19 | O7: =N7*M7 -> 9.967875 | Q7: =P7*M7 -> 0 | S7: =R7*M7 -> 0 | T7: =U7*G7 -> 1699.785 | U7: =M7-O7-Q7-S7 -> 42.494625 | V7: =T7*$V$2 -> 305.9613 | W7: =U7*$V$2 -> 7.6490325 | X7: =T7+V7 -> 2005.7463 | Y7: =U7+W7 -> 50.143657 | AA7: =(F7*G7)/1000 -> 2.8
A8: =+A7+1 -> 3 | C8: CCN | D8: CCN | E8: Chicken Chatkhara | F8: 70 | G8: 40 | H8: =I8*G8 -> 2600 | I8: 65 | J8: =K8*G8 -> 2560.17 | K8: =M8*1.22 -> 64.00425 | L8: 2098.5 | M8: =L8/G8 -> 52.4625 | N8: =+N7 -> 0.19 | O8: =N8*M8 -> 9.967875 | Q8: =P8*M8 -> 0 | S8: =R8*M8 -> 0 | T8: =U8*G8 -> 1699.785 | U8: =M8-O8-Q8-S8 -> 42.494625 | V8: =T8*$V$2 -> 305.9613 | W8: =U8*$V$2 -> 7.6490325 | X8: =T8+V8 -> 2005.7463 | Y8: =U8+W8 -> 50.143657 | AA8: =(F8*G8)/1000 -> 2.8
A9: =+A8+1 -> 4 | C9: BCNJ | D9: BCNJ | E9: Meat Masala (Jumbo) | F9: 120 | G9: 40 | H9: =I9*G9 -> 3600 | I9: 90 | J9: =K9*G9 -> 3544.832 | K9: =M9*1.22 -> 88.6208 | L9: 2905.6 | M9: =L9/G9 -> 72.64 | N9: =+N8 -> 0.19 | O9: =N9*M9 -> 13.8016 | Q9: =P9*M9 -> 0 | S9: =R9*M9 -> 0 | T9: =U9*G9 -> 2353.536 | U9: =M9-O9-Q9-S9 -> 58.8384 | V9: =T9*$V$2 -> 423.63648 | W9: =U9*$V$2 -> 10.590912 | X9: =T9+V9 -> 2777.1725 | Y9: =U9+W9 -> 69.429312 | AA9: =(F9*G9)/1000 -> 4.8
A10: =+A9+1 -> 5 | C10: VTNJ | D10: VTNJ | E10: Lemon Tarka (Jumbo) | F10: 120 | G10: 40 | H10: =I10*G10 -> 3600 | I10: 90 | J10: =K10*G10 -> 3544.832 | K10: =M10*1.22 -> 88.6208 | L10: 2905.6 | M10: =L10/G10 -> 72.64 | N10: =+N9 -> 0.19 | O10: =N10*M10 -> 13.8016 | Q10: =P10*M10 -> 0 | S10: =R10*M10 -> 0 | T10: =U10*G10 -> 2353.536 | U10: =M10-O10-Q10-S10 -> 58.8384 | V10: =T10*$V$2 -> 423.63648 | W10: =U10*$V$2 -> 10.590912 | X10: =T10+V10 -> 2777.1725 | Y10: =U10+W10 -> 69.429312 | AA10: =(F10*G10)/1000 -> 4.8
A11: =+A10+1 -> 6 | C11: CCNJ | D11: CCNJ | E11: Chicken Chatkhara (Jumbo) | F11: 120 | G11: 40 | H11: =I11*G11 -> 3600 | I11: 90 | J11: =K11*G11 -> 3544.832 | K11: =M11*1.22 -> 88.6208 | L11: 2905.6 | M11: =L11/G11 -> 72.64 | N11: =+N10 -> 0.19 | O11: =N11*M11 -> 13.8016 | Q11: =P11*M11 -> 0 | S11: =R11*M11 -> 0 | T11: =U11*G11 -> 2353.536 | U11: =M11-O11-Q11-S11 -> 58.8384 | V11: =T11*$V$2 -> 423.63648 | W11: =U11*$V$2 -> 10.590912 | X11: =T11+V11 -> 2777.1725 | Y11: =U11+W11 -> 69.429312 | AA11: =(F11*G11)/1000 -> 4.8
A12: =+A11+1 -> 7 | C12: CCE | D12: CCE | E12: Chicken Chatkhara (ECO) | F12: 60 | G12: 40 | H12: =I12*G12 -> 2000 | I12: 50 | J12: =K12*G12 -> 1914.424 | K12: =M12*1.22 -> 47.8606 | L12: 1569.2 | M12: =L12/G12 -> 39.23 | N12: =+N11 -> 0.19 | O12: =N12*M12 -> 7.4537 | Q12: =P12*M12 -> 0 | S12: =R12*M12 -> 0 | T12: =U12*G12 -> 1271.052 | U12: =M12-O12-Q12-S12 -> 31.7763 | V12: =T12*$V$2 -> 228.78936 | W12: =U12*$V$2 -> 5.719734 | X12: =T12+V12 -> 1499.8414 | Y12: =U12+W12 -> 37.496034 | AA12: =(F12*G12)/1000 -> 2.4
A13: =+A12+1 -> 8 | C13: VTE | D13: VTE | E13: Lemon Tarka (ECO) | F13: 60 | G13: 40 | H13: =I13*G13 -> 2000 | I13: 50 | J13: =K13*G13 -> 1914.424 | K13: =M13*1.22 -> 47.8606 | L13: 1569.2 | M13: =L13/G13 -> 39.23 | N13: =+N12 -> 0.19 | O13: =N13*M13 -> 7.4537 | Q13: =P13*M13 -> 0 | S13: =R13*M13 -> 0 | T13: =U13*G13 -> 1271.052 | U13: =M13-O13-Q13-S13 -> 31.7763 | V13: =T13*$V$2 -> 228.78936 | W13: =U13*$V$2 -> 5.719734 | X13: =T13+V13 -> 1499.8414 | Y13: =U13+W13 -> 37.496034 | AA13: =(F13*G13)/1000 -> 2.4
A14: =+A13+1 -> 9 | C14: BCE | D14: BCE | E14: Meat Masala (ECO) | F14: 60 | G14: 40 | H14: =I14*G14 -> 2000 | I14: 50 | J14: =K14*G14 -> 1914.424 | K14: =M14*1.22 -> 47.8606 | L14: 1569.2 | M14: =L14/G14 -> 39.23 | N14: =+N13 -> 0.19 | O14: =N14*M14 -> 7.4537 | Q14: =P14*M14 -> 0 | S14: =R14*M14 -> 0 | T14: =U14*G14 -> 1271.052 | U14: =M14-O14-Q14-S14 -> 31.7763 | V14: =T14*$V$2 -> 228.78936 | W14: =U14*$V$2 -> 5.719734 | X14: =T14+V14 -> 1499.8414 | Y14: =U14+W14 -> 37.496034 | AA14: =(F14*G14)/1000 -> 2.4
A15: =+A14+1 -> 10
A16: =+A15+1 -> 11
A17: =+A16+1 -> 12
A18: =+A17+1 -> 13
A19: =+A18+1 -> 14
A20: =+A19+1 -> 15
A22: =+A20+1 -> 16
A23: =+A22+1 -> 17
A24: =+A23+1 -> 18
A25: =+A24+1 -> 19
A26: =+A25+1 -> 20
A27: =+A26+1 -> 21
A28: =+A27+1 -> 22
A29: =+A28+1 -> 23
A30: =+A29+1 -> 24
A31: =+A30+1 -> 25
A32: =+A31+1 -> 26
A33: =+A32+1 -> 27
A34: =+A33+1 -> 28
A36: =+A34+1 -> 29
A37: =+A36+1 -> 30
A38: =+A37+1 -> 31
A39: =+A38+1 -> 32
A40: =+A39+1 -> 33
A41: =+A40+1 -> 34
A42: =+A41+1 -> 35
A43: =+A42+1 -> 36
A44: =+A43+1 -> 37
...

Sheet Format
A2: Elite MARKETING
A3: 44A- Gulberg Lahore | K3: Invoice No # : | N3: 1 | XFC3: Filer | XFD3: 0.005
A4: STRN / NTN :3808207-1 | K4: Date/Day : | N4: =TODAY() -> 46177 | XFC4: Non-filer | XFD4: 0.025
A5: Mubeen ahmad | K5: Order Date : | N5: =N4-1 -> 46176
K6: Order Name : | N6: Salman Aslam | XFC6: Registered | XFD6: 0.18
XFC7: Un-registered | XFD7: 0.22
XFD9: Yes
K10: Invoice Status : | N10: Serviced | XFD10: No
K11: Order at Original Location : | N11: Yes
K12: Reference Invoice : | T12: Shop Bill Summary (Mobeen Ahmad) | XFD12: Monday/Tuesday
L13: 0.05 | XFD13: Tuesday / Wednesday
A14: Product Code/Description | C14: GM/ Pack | D14: CTN | E14: R.P Per | F14: T.P Per | G14: Sale QTY | I14: Gross Amount Excl. Taxes | J14: Trade Offer & Discount | M14: After Discount Amount | N14: GST | O14: Adv. Tax 236H | P14: Invoice | T14: =+'faisal Store'!A5 -> Customer Name : Faisal Store | U14: =+'faisal Store'!P35 -> 5171.0276 | XFD14: Wednesday/Thursday
D15: SIZE | E15: Unit | F15: Unit | G15: CTN | H15: Pack | J15: FOC Qty | K15: Trade Offer | L15: Pass On | N15: =IF(B12="Registered",18%,22%) -> 0.22 | O15: =IF(B11="Filer",0.5%,2.5%) -> 0.025 | P15: Amount | T15: =+'fazal sweet'!A5 -> Customer Name : Fazal Sweet | U15: =+'fazal sweet'!P35 -> 1795.4904 | XFD15: Thursday /Friday
A16: BCN | B16: =VLOOKUP($A16,'[1]Cust. Price List'!$D$6:$O$14,2,0) -> Meat Masala | C16: =VLOOKUP(A16,'[1]Cust. Price List'!D6:M14,3,0) -> 70 | D16: =VLOOKUP(A16,'[1]Cust. Price List'!D6:M14,4,0) -> 40 | E16: =VLOOKUP(A16,'[1]Cust. Price List'!D6:M14,6,0) -> 65 | F16: =VLOOKUP(A16,'[1]Cust. Price List'!D6:M14,10,0) -> 52.4625 | H16: =+'faisal Store'!H16+'fazal sweet'!H16+'bhai bhai '!H16+tanver!H16+#REF!+food!H16+'shaheen '!H16+'bhai jan'!H16+Ghani!H16+Mehaj!H16+Bravo!H16+'786'!H16 -> #REF! | I16: =(G16*D16)*F16+H16*F16 -> #REF! | J16: =+'faisal Store'!J16+'fazal sweet'!J16+'bhai bhai '!J16+tanver!J16+#REF!+food!J16+'shaheen '!J16+'bhai jan'!J16+Ghani!J16+Mehaj!J16+Bravo!J16+'786'!J16 -> #REF! | K16: =+'faisal Store'!K16+'fazal sweet'!K16+'bhai bhai '!K16+tanver!K16+#REF!+food!K16+'shaheen '!K16+'bhai jan'!K16+Ghani!K16+Mehaj!K16 -> #REF! | L16: =+'faisal Store'!L16+'fazal sweet'!L16+'bhai bhai '!L16+tanver!L16+#REF!+food!L16+'shaheen '!L16+'bhai jan'!L16+Ghani!L16+Mehaj!L16 -> #REF! | M16: =I16-K16-L16 -> #REF! | N16: =+'faisal Store'!N16+'fazal sweet'!N16+'bhai bhai '!N16+tanver!N16+#REF!+food!N16+'shaheen '!N16+'bhai jan'!N16+Ghani!N16+Mehaj!N16 -> #REF! | O16: =+'faisal Store'!O16+'fazal sweet'!O16+'bhai bhai '!O16+tanver!O16+#REF!+food!O16+'shaheen '!O16+'bhai jan'!O16+Ghani!O16+Mehaj!O16 -> #REF! | P16: =M16+N16+O16 -> #REF! | T16: =+'bhai bhai '!A5 -> Customer Name : Bhai Bhai Medical Store | U16: =+'bhai bhai '!P35 -> 1474.8983 | XFD16: Friday / Saturday
A17: VTN | B17: =VLOOKUP($A17,'[1]Cust. Price List'!$D$6:$O$14,2,0) -> Lemon Tarka | C17: =VLOOKUP(B17,'[1]Cust. Price List'!E7:P15,2,0) -> 70 | D17: =VLOOKUP(A17,'[1]Cust. Price List'!D7:M15,4,0) -> 40 | E17: =VLOOKUP(A17,'[1]Cust. Price List'!D7:M15,6,0) -> 65 | F17: =VLOOKUP(A17,'[1]Cust. Price List'!D7:M15,10,0) -> 52.4625 | H17: =+'faisal Store'!H17+'fazal sweet'!H17+'bhai bhai '!H17+tanver!H17+#REF!+food!H17+'shaheen '!H17+'bhai jan'!H17+Ghani!H17+Mehaj!H17+Bravo!H17+'786'!H17 -> #REF! | I17: =(G17*D17)*F17+H17*F17 -> #REF! | J17: =+'faisal Store'!J17+'fazal sweet'!J17+'bhai bhai '!J17+tanver!J17+#REF!+food!J17+'shaheen '!J17+'bhai jan'!J17+Ghani!J17+Mehaj!J17+Bravo!J17+'786'!J17 -> #REF! | K17: =+'faisal Store'!K17+'fazal sweet'!K17+'bhai bhai '!K17+tanver!K17+#REF!+food!K17+'shaheen '!K17+'bhai jan'!K17+Ghani!K17+Mehaj!K17 -> #REF! | L17: =+'faisal Store'!L17+'fazal sweet'!L17+'bhai bhai '!L17+tanver!L17+#REF!+food!L17+'shaheen '!L17+'bhai jan'!L17+Ghani!L17+Mehaj!L17 -> #REF! | M17: =I17-K17-L17 -> #REF! | N17: =+'faisal Store'!N17+'fazal sweet'!N17+'bhai bhai '!N17+tanver!N17+#REF!+food!N17+'shaheen '!N17+'bhai jan'!N17+Ghani!N17+Mehaj!N17 -> #REF! | O17: =+'faisal Store'!O17+'fazal sweet'!O17+'bhai bhai '!O17+tanver!O17+#REF!+food!O17+'shaheen '!O17+'bhai jan'!O17+Ghani!O17+Mehaj!O17 -> #REF! | P17: =M17+N17+O17 -> #REF! | T17: =+tanver!A5 -> Customer Name : Tanveer Store | U17: =+tanver!P35 -> 3082.9602 | XFD17: Saturday /Monday
A18: CCN | B18: =VLOOKUP($A18,'[1]Cust. Price List'!$D$6:$O$14,2,0) -> Chicken Chatkhara | C18: =VLOOKUP(B18,'[1]Cust. Price List'!E8:P16,2,0) -> 70 | D18: =VLOOKUP(A18,'[1]Cust. Price List'!D8:M16,4,0) -> 40 | E18: =VLOOKUP(A18,'[1]Cust. Price List'!D8:M16,6,0) -> 65 | F18: =VLOOKUP(A18,'[1]Cust. Price List'!D8:M16,10,0) -> 52.4625 | H18: =+'faisal Store'!H18+'fazal sweet'!H18+'bhai bhai '!H18+tanver!H18+#REF!+food!H18+'shaheen '!H18+'bhai jan'!H18+Ghani!H18+Mehaj!H18+Bravo!H18+'786'!H18 -> #REF! | I18: =(G18*D18)*F18+H18*F18 -> #REF! | J18: =+'faisal Store'!J18+'fazal sweet'!J18+'bhai bhai '!J18+tanver!J18+#REF!+food!J18+'shaheen '!J18+'bhai jan'!J18+Ghani!J18+Mehaj!J18+Bravo!J18+'786'!J18 -> #REF! | K18: =+'faisal Store'!K18+'fazal sweet'!K18+'bhai bhai '!K18+tanver!K18+#REF!+food!K18+'shaheen '!K18+'bhai jan'!K18+Ghani!K18+Mehaj!K18 -> #REF! | L18: =+'faisal Store'!L18+'fazal sweet'!L18+'bhai bhai '!L18+tanver!L18+#REF!+food!L18+'shaheen '!L18+'bhai jan'!L18+Ghani!L18+Mehaj!L18 -> #REF! | M18: =I18-K18-L18 -> #REF! | N18: =+'faisal Store'!N18+'fazal sweet'!N18+'bhai bhai '!N18+tanver!N18+#REF!+food!N18+'shaheen '!N18+'bhai jan'!N18+Ghani!N18+Mehaj!N18 -> #REF! | O18: =+'faisal Store'!O18+'fazal sweet'!O18+'bhai bhai '!O18+tanver!O18+#REF!+food!O18+'shaheen '!O18+'bhai jan'!O18+Ghani!O18+Mehaj!O18 -> #REF! | P18: =M18+N18+O18 -> #REF! | T18: =+'[2]bhai bhai'!A6 -> #REF! | U18: =+#REF! -> #REF!
A19: BCNJ | B19: =VLOOKUP($A19,'[1]Cust. Price List'!$D$6:$O$14,2,0) -> Meat Masala (Jumbo) | C19: =VLOOKUP(B19,'[1]Cust. Price List'!E9:P17,2,0) -> 120 | D19: =VLOOKUP(A19,'[1]Cust. Price List'!D9:M17,4,0) -> 40 | E19: =VLOOKUP(A19,'[1]Cust. Price List'!D9:M17,6,0) -> 90 | F19: =VLOOKUP(A19,'[1]Cust. Price List'!D9:M17,10,0) -> 72.64 | H19: =+'faisal Store'!H19+'fazal sweet'!H19+'bhai bhai '!H19+tanver!H19+#REF!+food!H19+'shaheen '!H19+'bhai jan'!H19+Ghani!H19+Mehaj!H19+Bravo!H19+'786'!H19 -> #REF! | I19: =(G19*D19)*F19+H19*F19 -> #REF! | J19: =+'faisal Store'!J19+'fazal sweet'!J19+'bhai bhai '!J19+tanver!J19+#REF!+food!J19+'shaheen '!J19+'bhai jan'!J19+Ghani!J19+Mehaj!J19+Bravo!J19+'786'!J19 -> #REF! | K19: =+'faisal Store'!K19+'fazal sweet'!K19+'bhai bhai '!K19+tanver!K19+#REF!+food!K19+'shaheen '!K19+'bhai jan'!K19+Ghani!K19+Mehaj!K19 -> #REF! | L19: =+'faisal Store'!L19+'fazal sweet'!L19+'bhai bhai '!L19+tanver!L19+#REF!+food!L19+'shaheen '!L19+'bhai jan'!L19+Ghani!L19+Mehaj!L19 -> #REF! | M19: =I19-K19-L19 -> #REF! | N19: =+'faisal Store'!N19+'fazal sweet'!N19+'bhai bhai '!N19+tanver!N19+#REF!+food!N19+'shaheen '!N19+'bhai jan'!N19+Ghani!N19+Mehaj!N19 -> #REF! | O19: =+'faisal Store'!O19+'fazal sweet'!O19+'bhai bhai '!O19+tanver!O19+#REF!+food!O19+'shaheen '!O19+'bhai jan'!O19+Ghani!O19+Mehaj!O19 -> #REF! | P19: =M19+N19+O19 -> #REF! | T19: =+food!A5 -> Customer Name : Food Rite | U19: =+food!P35 -> 2308.5032
A20: VTNJ | B20: =VLOOKUP($A20,'[1]Cust. Price List'!$D$6:$O$14,2,0) -> Lemon Tarka (Jumbo) | C20: =VLOOKUP(B20,'[1]Cust. Price List'!E10:P18,2,0) -> 120 | D20: =VLOOKUP(A20,'[1]Cust. Price List'!D10:M18,4,0) -> 40 | E20: =VLOOKUP(A20,'[1]Cust. Price List'!D10:M18,6,0) -> 90 | F20: =VLOOKUP(A20,'[1]Cust. Price List'!D10:M18,10,0) -> 72.64 | H20: =+'faisal Store'!H20+'fazal sweet'!H20+'bhai bhai '!H20+tanver!H20+#REF!+food!H20+'shaheen '!H20+'bhai jan'!H20+Ghani!H20+Mehaj!H20+Bravo!H20+'786'!H20 -> #REF! | I20: =(G20*D20)*F20+H20*F20 -> #REF! | J20: =+'faisal Store'!J20+'fazal sweet'!J20+'bhai bhai '!J20+tanver!J20+#REF!+food!J20+'shaheen '!J20+'bhai jan'!J20+Ghani!J20+Mehaj!J20+Bravo!J20+'786'!J20 -> #REF! | K20: =+'faisal Store'!K20+'fazal sweet'!K20+'bhai bhai '!K20+tanver!K20+#REF!+food!K20+'shaheen '!K20+'bhai jan'!K20+Ghani!K20+Mehaj!K20 -> #REF! | L20: =+'faisal Store'!L20+'fazal sweet'!L20+'bhai bhai '!L20+tanver!L20+#REF!+food!L20+'shaheen '!L20+'bhai jan'!L20+Ghani!L20+Mehaj!L20 -> #REF! | M20: =I20-K20-L20 -> #REF! | N20: =+'faisal Store'!N20+'fazal sweet'!N20+'bhai bhai '!N20+tanver!N20+#REF!+food!N20+'shaheen '!N20+'bhai jan'!N20+Ghani!N20+Mehaj!N20 -> #REF! | O20: =+'faisal Store'!O20+'fazal sweet'!O20+'bhai bhai '!O20+tanver!O20+#REF!+food!O20+'shaheen '!O20+'bhai jan'!O20+Ghani!O20+Mehaj!O20 -> #REF! | P20: =M20+N20+O20 -> #REF! | T20: =+'shaheen '!A5 -> Customer Name :Shaheen Bakers | U20: =+'shaheen '!P35 -> 5070.1295
A21: CCNJ | B21: =VLOOKUP($A21,'[1]Cust. Price List'!$D$6:$O$14,2,0) -> Chicken Chatkhara (Jumbo) | C21: =VLOOKUP(B21,'[1]Cust. Price List'!E11:P19,2,0) -> 120 | D21: =VLOOKUP(A21,'[1]Cust. Price List'!D11:M19,4,0) -> 40 | E21: =VLOOKUP(A21,'[1]Cust. Price List'!D11:M19,6,0) -> 90 | F21: =VLOOKUP(A21,'[1]Cust. Price List'!D11:M19,10,0) -> 72.64 | H21: =+'faisal Store'!H21+'fazal sweet'!H21+'bhai bhai '!H21+tanver!H21+#REF!+food!H21+'shaheen '!H21+'bhai jan'!H21+Ghani!H21+Mehaj!H21+Bravo!H21+'786'!H21 -> #REF! | I21: =(G21*D21)*F21+H21*F21 -> #REF! | J21: =+'faisal Store'!J21+'fazal sweet'!J21+'bhai bhai '!J21+tanver!J21+#REF!+food!J21+'shaheen '!J21+'bhai jan'!J21+Ghani!J21+Mehaj!J21+Bravo!J21+'786'!J21 -> #REF! | K21: =+'faisal Store'!K21+'fazal sweet'!K21+'bhai bhai '!K21+tanver!K21+#REF!+food!K21+'shaheen '!K21+'bhai jan'!K21+Ghani!K21+Mehaj!K21 -> #REF! | L21: =+'faisal Store'!L21+'fazal sweet'!L21+'bhai bhai '!L21+tanver!L21+#REF!+food!L21+'shaheen '!L21+'bhai jan'!L21+Ghani!L21+Mehaj!L21 -> #REF! | M21: =I21-K21-L21 -> #REF! | N21: =+'faisal Store'!N21+'fazal sweet'!N21+'bhai bhai '!N21+tanver!N21+#REF!+food!N21+'shaheen '!N21+'bhai jan'!N21+Ghani!N21+Mehaj!N21 -> #REF! | O21: =+'faisal Store'!O21+'fazal sweet'!O21+'bhai bhai '!O21+tanver!O21+#REF!+food!O21+'shaheen '!O21+'bhai jan'!O21+Ghani!O21+Mehaj!O21 -> #REF! | P21: =M21+N21+O21 -> #REF! | T21: =+'bhai jan'!A5 -> Customer Name : Bhai Jan Store | U21: =+'bhai jan'!P35 -> 1795.4904
A22: CCE | B22: =VLOOKUP($A22,'[1]Cust. Price List'!$D$6:$O$14,2,0) -> Chicken Chatkhara (ECO) | C22: =VLOOKUP(B22,'[1]Cust. Price List'!E12:P20,2,0) -> 60 | D22: =VLOOKUP(A22,'[1]Cust. Price List'!D12:M20,4,0) -> 40 | E22: =VLOOKUP(A22,'[1]Cust. Price List'!D12:M20,6,0) -> 50 | F22: =VLOOKUP(A22,'[1]Cust. Price List'!D12:M20,10,0) -> 39.23 | H22: =+'faisal Store'!H22+'fazal sweet'!H22+'bhai bhai '!H22+tanver!H22+#REF!+food!H22+'shaheen '!H22+'bhai jan'!H22+Ghani!H22+Mehaj!H22+Bravo!H22+'786'!H22 -> #REF! | I22: =(G22*D22)*F22+H22*F22 -> #REF! | J22: =+'faisal Store'!J22+'fazal sweet'!J22+'bhai bhai '!J22+tanver!J22+#REF!+food!J22+'shaheen '!J22+'bhai jan'!J22+Ghani!J22+Mehaj!J22+Bravo!J22+'786'!J22 -> #REF! | K22: =+'faisal Store'!K22+'fazal sweet'!K22+'bhai bhai '!K22+tanver!K22+#REF!+food!K22+'shaheen '!K22+'bhai jan'!K22+Ghani!K22+Mehaj!K22 -> #REF! | L22: =+'faisal Store'!L22+'fazal sweet'!L22+'bhai bhai '!L22+tanver!L22+#REF!+food!L22+'shaheen '!L22+'bhai jan'!L22+Ghani!L22+Mehaj!L22 -> #REF! | M22: =I22-K22-L22 -> #REF! | N22: =+'faisal Store'!N22+'fazal sweet'!N22+'bhai bhai '!N22+tanver!N22+#REF!+food!N22+'shaheen '!N22+'bhai jan'!N22+Ghani!N22+Mehaj!N22 -> #REF! | O22: =+'faisal Store'!O22+'fazal sweet'!O22+'bhai bhai '!O22+tanver!O22+#REF!+food!O22+'shaheen '!O22+'bhai jan'!O22+Ghani!O22+Mehaj!O22 -> #REF! | P22: =M22+N22+O22 -> #REF! | T22: =+Ghani!A5 -> Customer Name : | U22: =+Ghani!P35 -> 0
A23: VTE | B23: =VLOOKUP($A23,'[1]Cust. Price List'!$D$6:$O$14,2,0) -> Lemon Tarka (ECO) | C23: =VLOOKUP(B23,'[1]Cust. Price List'!E13:P21,2,0) -> 60 | D23: =VLOOKUP(A23,'[1]Cust. Price List'!D13:M21,4,0) -> 40 | E23: =VLOOKUP(A23,'[1]Cust. Price List'!D13:M21,6,0) -> 50 | F23: =VLOOKUP(A23,'[1]Cust. Price List'!D13:M21,10,0) -> 39.23 | H23: =+'faisal Store'!H23+'fazal sweet'!H23+'bhai bhai '!H23+tanver!H23+#REF!+food!H23+'shaheen '!H23+'bhai jan'!H23+Ghani!H23+Mehaj!H23+Bravo!H23+'786'!H23 -> #REF! | I23: =(G23*D23)*F23+H23*F23 -> #REF! | J23: =+'faisal Store'!J23+'fazal sweet'!J23+'bhai bhai '!J23+tanver!J23+#REF!+food!J23+'shaheen '!J23+'bhai jan'!J23+Ghani!J23+Mehaj!J23+Bravo!J23+'786'!J23 -> #REF! | K23: =+'faisal Store'!K23+'fazal sweet'!K23+'bhai bhai '!K23+tanver!K23+#REF!+food!K23+'shaheen '!K23+'bhai jan'!K23+Ghani!K23+Mehaj!K23 -> #REF! | L23: =+'faisal Store'!L23+'fazal sweet'!L23+'bhai bhai '!L23+tanver!L23+#REF!+food!L23+'shaheen '!L23+'bhai jan'!L23+Ghani!L23+Mehaj!L23 -> #REF! | M23: =I23-K23-L23 -> #REF! | N23: =+'faisal Store'!N23+'fazal sweet'!N23+'bhai bhai '!N23+tanver!N23+#REF!+food!N23+'shaheen '!N23+'bhai jan'!N23+Ghani!N23+Mehaj!N23 -> #REF! | O23: =+'faisal Store'!O23+'fazal sweet'!O23+'bhai bhai '!O23+tanver!O23+#REF!+food!O23+'shaheen '!O23+'bhai jan'!O23+Ghani!O23+Mehaj!O23 -> #REF! | P23: =M23+N23+O23 -> #REF! | T23: =+Mehaj!A5 -> Customer Name : | U23: =+Mehaj!P35 -> 0
A24: BCE | B24: =VLOOKUP($A24,'[1]Cust. Price List'!$D$6:$O$14,2,0) -> Meat Masala (ECO) | C24: =VLOOKUP(B24,'[1]Cust. Price List'!E14:P22,2,0) -> 60 | D24: =VLOOKUP(A24,'[1]Cust. Price List'!D14:M22,4,0) -> 40 | E24: =VLOOKUP(A24,'[1]Cust. Price List'!D14:M22,6,0) -> 50 | F24: =VLOOKUP(A24,'[1]Cust. Price List'!D14:M22,10,0) -> 39.23 | H24: =+'faisal Store'!H24+'fazal sweet'!H24+'bhai bhai '!H24+tanver!H24+#REF!+food!H24+'shaheen '!H24+'bhai jan'!H24+Ghani!H24+Mehaj!H24+Bravo!H24+'786'!H24 -> #REF! | I24: =(G24*D24)*F24+H24*F24 -> #REF! | J24: =+'faisal Store'!J24+'fazal sweet'!J24+'bhai bhai '!J24+tanver!J24+#REF!+food!J24+'shaheen '!J24+'bhai jan'!J24+Ghani!J24+Mehaj!J24+Bravo!J24+'786'!J24 -> #REF! | K24: =+'faisal Store'!K24+'fazal sweet'!K24+'bhai bhai '!K24+tanver!K24+#REF!+food!K24+'shaheen '!K24+'bhai jan'!K24+Ghani!K24+Mehaj!K24 -> #REF! | L24: =+'faisal Store'!L24+'fazal sweet'!L24+'bhai bhai '!L24+tanver!L24+#REF!+food!L24+'shaheen '!L24+'bhai jan'!L24+Ghani!L24+Mehaj!L24 -> #REF! | M24: =I24-K24-L24 -> #REF! | N24: =+'faisal Store'!N24+'fazal sweet'!N24+'bhai bhai '!N24+tanver!N24+#REF!+food!N24+'shaheen '!N24+'bhai jan'!N24+Ghani!N24+Mehaj!N24 -> #REF! | O24: =+'faisal Store'!O24+'fazal sweet'!O24+'bhai bhai '!O24+tanver!O24+#REF!+food!O24+'shaheen '!O24+'bhai jan'!O24+Ghani!O24+Mehaj!O24 -> #REF! | P24: =M24+N24+O24 -> #REF! | T24: =+Bravo!A5 -> Customer Name : | U24: =+Bravo!P35 -> 0
A25: Total | G25: =SUM(G16:G24) -> 0 | H25: =SUM(H16:H24) -> #REF! | I25: =SUM(I16:I24) -> #REF! | J25: =SUM(J16:J24) -> #REF! | K25: =SUM(K16:K24) -> #REF! | L25: =SUM(L16:L24) -> #REF! | M25: =SUM(M16:M24) -> #REF! | N25: =SUM(N16:N24) -> #REF! | ... P25: =SUM(P16:P24) -> #REF! | T25: =+'786'!A5 -> Customer Name : | U25: =+'786'!P35 -> 0
T26: Total | U26: =SUM(U14:U25) -> #REF!
B28: یکم جولائی 2024سے نئی ٹیکس ترمیم کے مطابق، ایف بی آر سیکشن 236 ایچ کے مطابق، فائلرز کے لیے ہر سیل انوائس پر 0.5% اور نان فائلرز کے لیے 2.5% ایڈوانس ود ہولڈنگ ٹیکس وصول کیا جائے گا۔ | N28: Gross Amount: | P28: =I25 -> #REF!
N29: Regular Discount | P29: =L25 -> #REF!
N30: Trade Offre | P30: =K25 -> #REF!
N31: After Dis. Amount | P31: =P28-P29-P30 -> #REF!
N32: Total GST: | O32: =IF(B12="Registered",18%,22%) -> 0.22 | P32: =N25 -> #REF!
N33: Net Amount: | P33: =P31+P32 -> #REF!
N34: Ad.Tax | O34: =IF(B11="Filer",0.5%,2.5%) -> 0.025 | P34: =O34*P33 -> #REF!
N35: Net Amount with Ad.Tax | P35: =P33+P34 -> #REF!
B36: Delivered By

Sheet faisal Store
A2: Elite MARKETING
A3: 44A- Gulberg Lahore | K3: Invoice No # : | N3: 1 | XFC3: Filer | XFD3: 0.005
A4: STRN / NTN :3808207-1 | K4: Date/Day : | N4: =TODAY() -> 46177 | XFC4: Non-filer | XFD4: 0.025
A5: Customer Name : Faisal Store | K5: Order Date : | N5: =N4-1 -> 46176
A6: Address: Sharampura chowk | K6: Order Name : | N6: Mobeen Ahmad | XFC6: Registered | XFD6: 0.18
XFC7: Un-registered | XFD7: 0.22
XFD9: Yes
A10: NTN/CNIC Number: | K10: Invoice Status : | N10: Serviced | XFD10: No
B11: Non-filer | C11: =IF($O34>2.49%,"No","Yes") -> No | K11: Order at Original Location : | N11: Yes
A12: STRN Number: | B12: Un-registered | C12: =IF($O32>21.99%,"No","Yes") -> No | K12: Reference Invoice : | XFD12: Monday/Tuesday
L13: 0.05 | XFD13: Tuesday / Wednesday
A14: Product Code/Description | C14: GM/ Pack | D14: CTN | E14: R.P Per | F14: T.P Per | G14: Sale QTY | I14: Gross Amount Excl. Taxes | J14: Trade Offer & Discount | M14: After Discount Amount | N14: GST | O14: Adv. Tax 236H | P14: Invoice | XFD14: Wednesday/Thursday
D15: SIZE | E15: Unit | F15: Unit | G15: CTN | H15: Pack | J15: FOC Qty | K15: Trade Offer | L15: Pass On | N15: =IF(B12="Registered",18%,22%) -> 0.22 | O15: =IF(B11="Filer",0.5%,2.5%) -> 0.025 | P15: Amount | XFD15: Thursday /Friday
A16: BCN | B16: =VLOOKUP($A16,'[1]Cust. Price List'!$D$6:$O$14,2,0) -> Meat Masala | C16: =VLOOKUP(A16,'[1]Cust. Price List'!D6:M14,3,0) -> 70 | D16: =VLOOKUP(A16,'[1]Cust. Price List'!D6:M14,4,0) -> 40 | E16: =VLOOKUP(A16,'[1]Cust. Price List'!D6:M14,6,0) -> 65 | F16: =VLOOKUP(A16,'[1]Cust. Price List'!D6:M14,10,0) -> 52.4625 | I16: =(G16*D16)*F16+H16*F16 -> 0 | K16: =I16*$K$13 -> 0 | L16: =I16*8% -> 0 | M16: =I16-K16-L16 -> 0 | N16: =(M16*$N$15)+(J16*F16)*$N$15 -> 0 | O16: =(N16+M16)*$O$15 -> 0 | P16: =M16+N16+O16 -> 0 | XFD16: Friday / Saturday
A17: VTN | B17: =VLOOKUP($A17,'[1]Cust. Price List'!$D$6:$O$14,2,0) -> Lemon Tarka | C17: =VLOOKUP(B17,'[1]Cust. Price List'!E7:P15,2,0) -> 70 | D17: =VLOOKUP(A17,'[1]Cust. Price List'!D7:M15,4,0) -> 40 | E17: =VLOOKUP(A17,'[1]Cust. Price List'!D7:M15,6,0) -> 65 | F17: =VLOOKUP(A17,'[1]Cust. Price List'!D7:M15,10,0) -> 52.4625 | I17: =(G17*D17)*F17+H17*F17 -> 0 | K17: =I17*$K$13 -> 0 | L17: =I17*8% -> 0 | M17: =I17-K17-L17 -> 0 | N17: =(M17*$N$15)+(J17*F17)*$N$15 -> 0 | O17: =(N17+M17)*$O$15 -> 0 | P17: =M17+N17+O17 -> 0 | XFD17: Saturday /Monday
A18: CCN | B18: =VLOOKUP($A18,'[1]Cust. Price List'!$D$6:$O$14,2,0) -> Chicken Chatkhara | C18: =VLOOKUP(B18,'[1]Cust. Price List'!E8:P16,2,0) -> 70 | D18: =VLOOKUP(A18,'[1]Cust. Price List'!D8:M16,4,0) -> 40 | E18: =VLOOKUP(A18,'[1]Cust. Price List'!D8:M16,6,0) -> 65 | F18: =VLOOKUP(A18,'[1]Cust. Price List'!D8:M16,10,0) -> 52.4625 | I18: =(G18*D18)*F18+H18*F18 -> 0 | K18: =I18*$K$13 -> 0 | L18: =I18*8% -> 0 | M18: =I18-K18-L18 -> 0 | N18: =(M18*$N$15)+(J18*F18)*$N$15 -> 0 | O18: =(N18+M18)*$O$15 -> 0 | P18: =M18+N18+O18 -> 0
A19: BCNJ | B19: =VLOOKUP($A19,'[1]Cust. Price List'!$D$6:$O$14,2,0) -> Meat Masala (Jumbo) | C19: =VLOOKUP(B19,'[1]Cust. Price List'!E9:P17,2,0) -> 120 | D19: =VLOOKUP(A19,'[1]Cust. Price List'!D9:M17,4,0) -> 40 | E19: =VLOOKUP(A19,'[1]Cust. Price List'!D9:M17,6,0) -> 90 | F19: =VLOOKUP(A19,'[1]Cust. Price List'!D9:M17,10,0) -> 72.64 | H19: 20 | I19: =(G19*D19)*F19+H19*F19 -> 1452.8 | J19: 1 | K19: =I19*$K$13 -> 0 | L19: =I19*8% -> 116.224 | M19: =I19-K19-L19 -> 1336.576 | N19: =(M19*$N$15)+(J19*F19)*$N$15 -> 310.02752 | O19: =(N19+M19)*$O$15 -> 41.165088 | P19: =M19+N19+O19 -> 1687.7686
A20: VTNJ | B20: =VLOOKUP($A20,'[1]Cust. Price List'!$D$6:$O$14,2,0) -> Lemon Tarka (Jumbo) | C20: =VLOOKUP(B20,'[1]Cust. Price List'!E10:P18,2,0) -> 120 | D20: =VLOOKUP(A20,'[1]Cust. Price List'!D10:M18,4,0) -> 40 | E20: =VLOOKUP(A20,'[1]Cust. Price List'!D10:M18,6,0) -> 90 | F20: =VLOOKUP(A20,'[1]Cust. Price List'!D10:M18,10,0) -> 72.64 | I20: =(G20*D20)*F20+H20*F20 -> 0 | K20: =I20*$K$13 -> 0 | L20: =I20*8% -> 0 | M20: =I20-K20-L20 -> 0 | N20: =(M20*$N$15)+(J20*F20)*$N$15 -> 0 | O20: =(N20+M20)*$O$15 -> 0 | P20: =M20+N20+O20 -> 0
A21: CCNJ | B21: =VLOOKUP($A21,'[1]Cust. Price List'!$D$6:$O$14,2,0) -> Chicken Chatkhara (Jumbo) | C21: =VLOOKUP(B21,'[1]Cust. Price List'!E11:P19,2,0) -> 120 | D21: =VLOOKUP(A21,'[1]Cust. Price List'!D11:M19,4,0) -> 40 | E21: =VLOOKUP(A21,'[1]Cust. Price List'!D11:M19,6,0) -> 90 | F21: =VLOOKUP(A21,'[1]Cust. Price List'!D11:M19,10,0) -> 72.64 | H21: 20 | I21: =(G21*D21)*F21+H21*F21 -> 1452.8 | J21: 1 | K21: =I21*$K$13 -> 0 | L21: =I21*8% -> 116.224 | M21: =I21-K21-L21 -> 1336.576 | N21: =(M21*$N$15)+(J21*F21)*$N$15 -> 310.02752 | O21: =(N21+M21)*$O$15 -> 41.165088 | P21: =M21+N21+O21 -> 1687.7686
A22: CCE | B22: =VLOOKUP($A22,'[1]Cust. Price List'!$D$6:$O$14,2,0) -> Chicken Chatkhara (ECO) | C22: =VLOOKUP(B22,'[1]Cust. Price List'!E12:P20,2,0) -> 60 | D22: =VLOOKUP(A22,'[1]Cust. Price List'!D12:M20,4,0) -> 40 | E22: =VLOOKUP(A22,'[1]Cust. Price List'!D12:M20,6,0) -> 50 | F22: =VLOOKUP(A22,'[1]Cust. Price List'!D12:M20,10,0) -> 39.23 | G22: 1 | I22: =(G22*D22)*F22+H22*F22 -> 1569.2 | K22: =I22*3.5% -> 54.922 | L22: =I22*5% -> 78.46 | M22: =I22-K22-L22 -> 1435.818 | N22: =(M22*$N$15)+(J22*F22)*$N$15 -> 315.87996 | O22: =(N22+M22)*$O$15 -> 43.792449 | P22: =M22+N22+O22 -> 1795.4904
A23: VTE | B23: =VLOOKUP($A23,'[1]Cust. Price List'!$D$6:$O$14,2,0) -> Lemon Tarka (ECO) | C23: =VLOOKUP(B23,'[1]Cust. Price List'!E13:P21,2,0) -> 60 | D23: =VLOOKUP(A23,'[1]Cust. Price List'!D13:M21,4,0) -> 40 | E23: =VLOOKUP(A23,'[1]Cust. Price List'!D13:M21,6,0) -> 50 | F23: =VLOOKUP(A23,'[1]Cust. Price List'!D13:M21,10,0) -> 39.23 | I23: =(G23*D23)*F23+H23*F23 -> 0 | K23: =I23*3.5% -> 0 | L23: =I23*$L$13 -> 0 | M23: =I23-K23-L23 -> 0 | N23: =(M23*$N$15)+(J23*F23)*$N$15 -> 0 | O23: =(N23+M23)*$O$15 -> 0 | P23: =M23+N23+O23 -> 0
A24: BCE | B24: =VLOOKUP($A24,'[1]Cust. Price List'!$D$6:$O$14,2,0) -> Meat Masala (ECO) | C24: =VLOOKUP(B24,'[1]Cust. Price List'!E14:P22,2,0) -> 60 | D24: =VLOOKUP(A24,'[1]Cust. Price List'!D14:M22,4,0) -> 40 | E24: =VLOOKUP(A24,'[1]Cust. Price List'!D14:M22,6,0) -> 50 | F24: =VLOOKUP(A24,'[1]Cust. Price List'!D14:M22,10,0) -> 39.23 | I24: =(G24*D24)*F24+H24*F24 -> 0 | K24: =I24*3.5% -> 0 | L24: =I24*$L$13 -> 0 | M24: =I24-K24-L24 -> 0 | N24: =(M24*$N$15)+(J24*F24)*$N$15 -> 0 | O24: =(N24+M24)*$O$15 -> 0 | P24: =M24+N24+O24 -> 0
A25: Total | G25: =SUM(G16:G24) -> 1 | H25: =SUM(H16:H24) -> 40 | I25: =SUM(I16:I24) -> 4474.8 | K25: =SUM(K16:K24) -> 54.922 | L25: =SUM(L16:L24) -> 310.908 | M25: =SUM(M16:M24) -> 4108.97 | N25: =SUM(N16:N24) -> 935.935 | O25: =SUM(O16:O24) -> 126.12263 | P25: =SUM(P16:P24) -> 5171.0276
B28: یکم جولائی 2024سے نئی ٹیکس ترمیم کے مطابق، ایف بی آر سیکشن 236 ایچ کے مطابق، فائلرز کے لیے ہر سیل انوائس پر 0.5% اور نان فائلرز کے لیے 2.5% ایڈوانس ود ہولڈنگ ٹیکس وصول کیا جائے گا۔ | N28: Gross Amount: | P28: =I25 -> 4474.8
N29: Regular Discount | P29: =L25 -> 310.908
N30: Trade Offre | P30: =K25 -> 54.922
N31: After Dis. Amount | P31: =P28-P29-P30 -> 4108.97
N32: Total GST: | O32: =IF(B12="Registered",18%,22%) -> 0.22 | P32: =N25 -> 935.935
N33: Net Amount: | P33: =P31+P32 -> 5044.905
N34: Ad.Tax | O34: =IF(B11="Filer",0.5%,2.5%) -> 0.025 | P34: =O34*P33 -> 126.12263
N35: Net Amount with Ad.Tax | P35: =P33+P34 -> 5171.0276
B36: Delivered By

Sheet fazal sweet
A2: Elite MARKETING
A3: 44A- Gulberg Lahore | K3: Invoice No # : | N3: 2 | XFC3: Filer | XFD3: 0.005
A4: STRN / NTN :3808207-1 | K4: Date/Day : | N4: =TODAY() -> 46177 | XFC4: Non-filer | XFD4: 0.025
A5: Customer Name : Fazal Sweet | K5: Order Date : | N5: =N4-1 -> 46176
A6: Address: Dharampura Chowk | K6: Order Name : | N6: Mobeen Ahmad | XFC6: Registered | XFD6: 0.18
XFC7: Un-registered | XFD7: 0.22
XFD9: Yes
A10: NTN/CNIC Number: | K10: Invoice Status : | N10: Serviced | XFD10: No
B11: Non-filer | C11: =IF($O34>2.49%,"No","Yes") -> No | K11: Order at Original Location : | N11: Yes
A12: STRN Number: | B12: Un-registered | C12: =IF($O32>21.99%,"No","Yes") -> No | K12: Reference Invoice : | XFD12: Monday/Tuesday
L13: 0.05 | XFD13: Tuesday / Wednesday
A14: Product Code/Description | C14: GM/ Pack | D14: CTN | E14: R.P Per | F14: T.P Per | G14: Sale QTY | I14: Gross Amount Excl. Taxes | J14: Trade Offer & Discount | M14: After Discount Amount | N14: GST | O14: Adv. Tax 236H | P14: Invoice | XFD14: Wednesday/Thursday
D15: SIZE | E15: Unit | F15: Unit | G15: CTN | H15: Pack | J15: FOC Qty | K15: Trade Offer | L15: Pass On | N15: =IF(B12="Registered",18%,22%) -> 0.22 | O15: =IF(B11="Filer",0.5%,2.5%) -> 0.025 | P15: Amount | XFD15: Thursday /Friday
A16: BCN | B16: =VLOOKUP($A16,'[1]Cust. Price List'!$D$6:$O$14,2,0) -> Meat Masala | C16: =VLOOKUP(A16,'[1]Cust. Price List'!D6:M14,3,0) -> 70 | D16: =VLOOKUP(A16,'[1]Cust. Price List'!D6:M14,4,0) -> 40 | E16: =VLOOKUP(A16,'[1]Cust. Price List'!D6:M14,6,0) -> 65 | F16: =VLOOKUP(A16,'[1]Cust. Price List'!D6:M14,10,0) -> 52.4625 | I16: =(G16*D16)*F16+H16*F16 -> 0 | K16: =I16*$K$13 -> 0 | L16: =I16*8% -> 0 | M16: =I16-K16-L16 -> 0 | N16: =(M16*$N$15)+(J16*F16)*$N$15 -> 0 | O16: =(N16+M16)*$O$15 -> 0 | P16: =M16+N16+O16 -> 0 | XFD16: Friday / Saturday
A17: VTN | B17: =VLOOKUP($A17,'[1]Cust. Price List'!$D$6:$O$14,2,0) -> Lemon Tarka | C17: =VLOOKUP(B17,'[1]Cust. Price List'!E7:P15,2,0) -> 70 | D17: =VLOOKUP(A17,'[1]Cust. Price List'!D7:M15,4,0) -> 40 | E17: =VLOOKUP(A17,'[1]Cust. Price List'!D7:M15,6,0) -> 65 | F17: =VLOOKUP(A17,'[1]Cust. Price List'!D7:M15,10,0) -> 52.4625 | I17: =(G17*D17)*F17+H17*F17 -> 0 | K17: =I17*$K$13 -> 0 | L17: =I17*8% -> 0 | M17: =I17-K17-L17 -> 0 | N17: =(M17*$N$15)+(J17*F17)*$N$15 -> 0 | O17: =(N17+M17)*$O$15 -> 0 | P17: =M17+N17+O17 -> 0 | XFD17: Saturday /Monday
A18: CCN | B18: =VLOOKUP($A18,'[1]Cust. Price List'!$D$6:$O$14,2,0) -> Chicken Chatkhara | C18: =VLOOKUP(B18,'[1]Cust. Price List'!E8:P16,2,0) -> 70 | D18: =VLOOKUP(A18,'[1]Cust. Price List'!D8:M16,4,0) -> 40 | E18: =VLOOKUP(A18,'[1]Cust. Price List'!D8:M16,6,0) -> 65 | F18: =VLOOKUP(A18,'[1]Cust. Price List'!D8:M16,10,0) -> 52.4625 | I18: =(G18*D18)*F18+H18*F18 -> 0 | K18: =I18*$K$13 -> 0 | L18: =I18*8% -> 0 | M18: =I18-K18-L18 -> 0 | N18: =(M18*$N$15)+(J18*F18)*$N$15 -> 0 | O18: =(N18+M18)*$O$15 -> 0 | P18: =M18+N18+O18 -> 0
A19: BCNJ | B19: =VLOOKUP($A19,'[1]Cust. Price List'!$D$6:$O$14,2,0) -> Meat Masala (Jumbo) | C19: =VLOOKUP(B19,'[1]Cust. Price List'!E9:P17,2,0) -> 120 | D19: =VLOOKUP(A19,'[1]Cust. Price List'!D9:M17,4,0) -> 40 | E19: =VLOOKUP(A19,'[1]Cust. Price List'!D9:M17,6,0) -> 90 | F19: =VLOOKUP(A19,'[1]Cust. Price List'!D9:M17,10,0) -> 72.64 | I19: =(G19*D19)*F19+H19*F19 -> 0 | K19: =I19*$K$13 -> 0 | L19: =I19*8% -> 0 | M19: =I19-K19-L19 -> 0 | N19: =(M19*$N$15)+(J19*F19)*$N$15 -> 0 | O19: =(N19+M19)*$O$15 -> 0 | P19: =M19+N19+O19 -> 0
A20: VTNJ | B20: =VLOOKUP($A20,'[1]Cust. Price List'!$D$6:$O$14,2,0) -> Lemon Tarka (Jumbo) | C20: =VLOOKUP(B20,'[1]Cust. Price List'!E10:P18,2,0) -> 120 | D20: =VLOOKUP(A20,'[1]Cust. Price List'!D10:M18,4,0) -> 40 | E20: =VLOOKUP(A20,'[1]Cust. Price List'!D10:M18,6,0) -> 90 | F20: =VLOOKUP(A20,'[1]Cust. Price List'!D10:M18,10,0) -> 72.64 | I20: =(G20*D20)*F20+H20*F20 -> 0 | K20: =I20*$K$13 -> 0 | L20: =I20*8% -> 0 | M20: =I20-K20-L20 -> 0 | N20: =(M20*$N$15)+(J20*F20)*$N$15 -> 0 | O20: =(N20+M20)*$O$15 -> 0 | P20: =M20+N20+O20 -> 0
A21: CCNJ | B21: =VLOOKUP($A21,'[1]Cust. Price List'!$D$6:$O$14,2,0) -> Chicken Chatkhara (Jumbo) | C21: =VLOOKUP(B21,'[1]Cust. Price List'!E11:P19,2,0) -> 120 | D21: =VLOOKUP(A21,'[1]Cust. Price List'!D11:M19,4,0) -> 40 | E21: =VLOOKUP(A21,'[1]Cust. Price List'!D11:M19,6,0) -> 90 | F21: =VLOOKUP(A21,'[1]Cust. Price List'!D11:M19,10,0) -> 72.64 | I21: =(G21*D21)*F21+H21*F21 -> 0 | K21: =I21*$K$13 -> 0 | L21: =I21*8% -> 0 | M21: =I21-K21-L21 -> 0 | N21: =(M21*$N$15)+(J21*F21)*$N$15 -> 0 | O21: =(N21+M21)*$O$15 -> 0 | P21: =M21+N21+O21 -> 0
A22: CCE | B22: =VLOOKUP($A22,'[1]Cust. Price List'!$D$6:$O$14,2,0) -> Chicken Chatkhara (ECO) | C22: =VLOOKUP(B22,'[1]Cust. Price List'!E12:P20,2,0) -> 60 | D22: =VLOOKUP(A22,'[1]Cust. Price List'!D12:M20,4,0) -> 40 | E22: =VLOOKUP(A22,'[1]Cust. Price List'!D12:M20,6,0) -> 50 | F22: =VLOOKUP(A22,'[1]Cust. Price List'!D12:M20,10,0) -> 39.23 | G22: 1 | I22: =(G22*D22)*F22+H22*F22 -> 1569.2 | K22: =I22*3.5% -> 54.922 | L22: =I22*5% -> 78.46 | M22: =I22-K22-L22 -> 1435.818 | N22: =(M22*$N$15)+(J22*F22)*$N$15 -> 315.87996 | O22: =(N22+M22)*$O$15 -> 43.792449 | P22: =M22+N22+O22 -> 1795.4904
A23: VTE | B23: =VLOOKUP($A23,'[1]Cust. Price List'!$D$6:$O$14,2,0) -> Lemon Tarka (ECO) | C23: =VLOOKUP(B23,'[1]Cust. Price List'!E13:P21,2,0) -> 60 | D23: =VLOOKUP(A23,'[1]Cust. Price List'!D13:M21,4,0) -> 40 | E23: =VLOOKUP(A23,'[1]Cust. Price List'!D13:M21,6,0) -> 50 | F23: =VLOOKUP(A23,'[1]Cust. Price List'!D13:M21,10,0) -> 39.23 | I23: =(G23*D23)*F23+H23*F23 -> 0 | K23: =I23*3.5% -> 0 | L23: =I23*$L$13 -> 0 | M23: =I23-K23-L23 -> 0 | N23: =(M23*$N$15)+(J23*F23)*$N$15 -> 0 | O23: =(N23+M23)*$O$15 -> 0 | P23: =M23+N23+O23 -> 0
A24: BCE | B24: =VLOOKUP($A24,'[1]Cust. Price List'!$D$6:$O$14,2,0) -> Meat Masala (ECO) | C24: =VLOOKUP(B24,'[1]Cust. Price List'!E14:P22,2,0) -> 60 | D24: =VLOOKUP(A24,'[1]Cust. Price List'!D14:M22,4,0) -> 40 | E24: =VLOOKUP(A24,'[1]Cust. Price List'!D14:M22,6,0) -> 50 | F24: =VLOOKUP(A24,'[1]Cust. Price List'!D14:M22,10,0) -> 39.23 | I24: =(G24*D24)*F24+H24*F24 -> 0 | K24: =I24*3.5% -> 0 | L24: =I24*$L$13 -> 0 | M24: =I24-K24-L24 -> 0 | N24: =(M24*$N$15)+(J24*F24)*$N$15 -> 0 | O24: =(N24+M24)*$O$15 -> 0 | P24: =M24+N24+O24 -> 0
A25: Total | G25: =SUM(G16:G24) -> 1 | H25: =SUM(H16:H24) -> 0 | I25: =SUM(I16:I24) -> 1569.2 | K25: =SUM(K16:K24) -> 54.922 | L25: =SUM(L16:L24) -> 78.46 | M25: =SUM(M16:M24) -> 1435.818 | N25: =SUM(N16:N24) -> 315.87996 | O25: =SUM(O16:O24) -> 43.792449 | P25: =SUM(P16:P24) -> 1795.4904
B28: یکم جولائی 2024سے نئی ٹیکس ترمیم کے مطابق، ایف بی آر سیکشن 236 ایچ کے مطابق، فائلرز کے لیے ہر سیل انوائس پر 0.5% اور نان فائلرز کے لیے 2.5% ایڈوانس ود ہولڈنگ ٹیکس وصول کیا جائے گا۔ | N28: Gross Amount: | P28: =I25 -> 1569.2
N29: Regular Discount | P29: =L25 -> 78.46
N30: Trade Offre | P30: =K25 -> 54.922
N31: After Dis. Amount | P31: =P28-P29-P30 -> 1435.818
N32: Total GST: | O32: =IF(B12="Registered",18%,22%) -> 0.22 | P32: =N25 -> 315.87996
N33: Net Amount: | P33: =P31+P32 -> 1751.698
N34: Ad.Tax | O34: =IF(B11="Filer",0.5%,2.5%) -> 0.025 | P34: =O34*P33 -> 43.792449
N35: Net Amount with Ad.Tax | P35: =P33+P34 -> 1795.4904
B36: Delivered By

Sheet tanver
A2: Elite MARKETING
A3: 44A- Gulberg Lahore | K3: Invoice No # : | N3: 4 | XFC3: Filer | XFD3: 0.005
A4: STRN / NTN :3808207-1 | K4: Date/Day : | N4: =TODAY() -> 46177 | XFC4: Non-filer | XFD4: 0.025
A5: Customer Name : Tanveer Store | K5: Order Date : | N5: =N4-1 -> 46176
A6: Address: Lala Book Depot Dharampura Chowk | K6: Order Name : | N6: Mobeen Ahmad | XFC6: Registered | XFD6: 0.18
XFC7: Un-registered | XFD7: 0.22
XFD9: Yes
A10: NTN/CNIC Number: | K10: Invoice Status : | N10: Serviced | XFD10: No
B11: Non-filer | C11: =IF($O34>2.49%,"No","Yes") -> No | K11: Order at Original Location : | N11: Yes
A12: STRN Number: | B12: Un-registered | C12: =IF($O32>21.99%,"No","Yes") -> No | K12: Reference Invoice : | XFD12: Monday/Tuesday
L13: 0.05 | XFD13: Tuesday / Wednesday
A14: Product Code/Description | C14: GM/ Pack | D14: CTN | E14: R.P Per | F14: T.P Per | G14: Sale QTY | I14: Gross Amount Excl. Taxes | J14: Trade Offer & Discount | M14: After Discount Amount | N14: GST | O14: Adv. Tax 236H | P14: Invoice | XFD14: Wednesday/Thursday
D15: SIZE | E15: Unit | F15: Unit | G15: CTN | H15: Pack | J15: FOC Qty | K15: Trade Offer | L15: Pass On | N15: =IF(B12="Registered",18%,22%) -> 0.22 | O15: =IF(B11="Filer",0.5%,2.5%) -> 0.025 | P15: Amount | XFD15: Thursday /Friday
A16: BCN | B16: =VLOOKUP($A16,'[1]Cust. Price List'!$D$6:$O$14,2,0) -> Meat Masala | C16: =VLOOKUP(A16,'[1]Cust. Price List'!D6:M14,3,0) -> 70 | D16: =VLOOKUP(A16,'[1]Cust. Price List'!D6:M14,4,0) -> 40 | E16: =VLOOKUP(A16,'[1]Cust. Price List'!D6:M14,6,0) -> 65 | F16: =VLOOKUP(A16,'[1]Cust. Price List'!D6:M14,10,0) -> 52.4625 | I16: =(G16*D16)*F16+H16*F16 -> 0 | K16: =I16*$K$13 -> 0 | L16: =I16*8% -> 0 | M16: =I16-K16-L16 -> 0 | N16: =(M16*$N$15)+(J16*F16)*$N$15 -> 0 | O16: =(N16+M16)*$O$15 -> 0 | P16: =M16+N16+O16 -> 0 | XFD16: Friday / Saturday
A17: VTN | B17: =VLOOKUP($A17,'[1]Cust. Price List'!$D$6:$O$14,2,0) -> Lemon Tarka | C17: =VLOOKUP(B17,'[1]Cust. Price List'!E7:P15,2,0) -> 70 | D17: =VLOOKUP(A17,'[1]Cust. Price List'!D7:M15,4,0) -> 40 | E17: =VLOOKUP(A17,'[1]Cust. Price List'!D7:M15,6,0) -> 65 | F17: =VLOOKUP(A17,'[1]Cust. Price List'!D7:M15,10,0) -> 52.4625 | I17: =(G17*D17)*F17+H17*F17 -> 0 | K17: =I17*$K$13 -> 0 | L17: =I17*8% -> 0 | M17: =I17-K17-L17 -> 0 | N17: =(M17*$N$15)+(J17*F17)*$N$15 -> 0 | O17: =(N17+M17)*$O$15 -> 0 | P17: =M17+N17+O17 -> 0 | XFD17: Saturday /Monday
A18: CCN | B18: =VLOOKUP($A18,'[1]Cust. Price List'!$D$6:$O$14,2,0) -> Chicken Chatkhara | C18: =VLOOKUP(B18,'[1]Cust. Price List'!E8:P16,2,0) -> 70 | D18: =VLOOKUP(A18,'[1]Cust. Price List'!D8:M16,4,0) -> 40 | E18: =VLOOKUP(A18,'[1]Cust. Price List'!D8:M16,6,0) -> 65 | F18: =VLOOKUP(A18,'[1]Cust. Price List'!D8:M16,10,0) -> 52.4625 | I18: =(G18*D18)*F18+H18*F18 -> 0 | K18: =I18*$K$13 -> 0 | L18: =I18*8% -> 0 | M18: =I18-K18-L18 -> 0 | N18: =(M18*$N$15)+(J18*F18)*$N$15 -> 0 | O18: =(N18+M18)*$O$15 -> 0 | P18: =M18+N18+O18 -> 0
A19: BCNJ | B19: =VLOOKUP($A19,'[1]Cust. Price List'!$D$6:$O$14,2,0) -> Meat Masala (Jumbo) | C19: =VLOOKUP(B19,'[1]Cust. Price List'!E9:P17,2,0) -> 120 | D19: =VLOOKUP(A19,'[1]Cust. Price List'!D9:M17,4,0) -> 40 | E19: =VLOOKUP(A19,'[1]Cust. Price List'!D9:M17,6,0) -> 90 | F19: =VLOOKUP(A19,'[1]Cust. Price List'!D9:M17,10,0) -> 72.64 | H19: 12 | I19: =(G19*D19)*F19+H19*F19 -> 871.68 | K19: =I19*$K$13 -> 0 | L19: =I19*8% -> 69.7344 | M19: =I19-K19-L19 -> 801.9456 | N19: =(M19*$N$15)+(J19*F19)*$N$15 -> 176.42803 | O19: =(N19+M19)*$O$15 -> 24.459341 | P19: =M19+N19+O19 -> 1002.833
A20: VTNJ | B20: =VLOOKUP($A20,'[1]Cust. Price List'!$D$6:$O$14,2,0) -> Lemon Tarka (Jumbo) | C20: =VLOOKUP(B20,'[1]Cust. Price List'!E10:P18,2,0) -> 120 | D20: =VLOOKUP(A20,'[1]Cust. Price List'!D10:M18,4,0) -> 40 | E20: =VLOOKUP(A20,'[1]Cust. Price List'!D10:M18,6,0) -> 90 | F20: =VLOOKUP(A20,'[1]Cust. Price List'!D10:M18,10,0) -> 72.64 | I20: =(G20*D20)*F20+H20*F20 -> 0 | K20: =I20*$K$13 -> 0 | L20: =I20*8% -> 0 | M20: =I20-K20-L20 -> 0 | N20: =(M20*$N$15)+(J20*F20)*$N$15 -> 0 | O20: =(N20+M20)*$O$15 -> 0 | P20: =M20+N20+O20 -> 0
A21: CCNJ | B21: =VLOOKUP($A21,'[1]Cust. Price List'!$D$6:$O$14,2,0) -> Chicken Chatkhara (Jumbo) | C21: =VLOOKUP(B21,'[1]Cust. Price List'!E11:P19,2,0) -> 120 | D21: =VLOOKUP(A21,'[1]Cust. Price List'!D11:M19,4,0) -> 40 | E21: =VLOOKUP(A21,'[1]Cust. Price List'!D11:M19,6,0) -> 90 | F21: =VLOOKUP(A21,'[1]Cust. Price List'!D11:M19,10,0) -> 72.64 | H21: 12 | I21: =(G21*D21)*F21+H21*F21 -> 871.68 | K21: =I21*$K$13 -> 0 | L21: =I21*8% -> 69.7344 | M21: =I21-K21-L21 -> 801.9456 | N21: =(M21*$N$15)+(J21*F21)*$N$15 -> 176.42803 | O21: =(N21+M21)*$O$15 -> 24.459341 | P21: =M21+N21+O21 -> 1002.833
A22: CCE | B22: =VLOOKUP($A22,'[1]Cust. Price List'!$D$6:$O$14,2,0) -> Chicken Chatkhara (ECO) | C22: =VLOOKUP(B22,'[1]Cust. Price List'!E12:P20,2,0) -> 60 | D22: =VLOOKUP(A22,'[1]Cust. Price List'!D12:M20,4,0) -> 40 | E22: =VLOOKUP(A22,'[1]Cust. Price List'!D12:M20,6,0) -> 50 | F22: =VLOOKUP(A22,'[1]Cust. Price List'!D12:M20,10,0) -> 39.23 | H22: 24 | I22: =(G22*D22)*F22+H22*F22 -> 941.52 | K22: =I22*3.5% -> 32.9532 | L22: =I22*5% -> 47.076 | M22: =I22-K22-L22 -> 861.4908 | N22: =(M22*$N$15)+(J22*F22)*$N$15 -> 189.52798 | O22: =(N22+M22)*$O$15 -> 26.275469 | P22: =M22+N22+O22 -> 1077.2942
A23: VTE | B23: =VLOOKUP($A23,'[1]Cust. Price List'!$D$6:$O$14,2,0) -> Lemon Tarka (ECO) | C23: =VLOOKUP(B23,'[1]Cust. Price List'!E13:P21,2,0) -> 60 | D23: =VLOOKUP(A23,'[1]Cust. Price List'!D13:M21,4,0) -> 40 | E23: =VLOOKUP(A23,'[1]Cust. Price List'!D13:M21,6,0) -> 50 | F23: =VLOOKUP(A23,'[1]Cust. Price List'!D13:M21,10,0) -> 39.23 | I23: =(G23*D23)*F23+H23*F23 -> 0 | K23: =I23*3.5% -> 0 | L23: =I23*$L$13 -> 0 | M23: =I23-K23-L23 -> 0 | N23: =(M23*$N$15)+(J23*F23)*$N$15 -> 0 | O23: =(N23+M23)*$O$15 -> 0 | P23: =M23+N23+O23 -> 0
A24: BCE | B24: =VLOOKUP($A24,'[1]Cust. Price List'!$D$6:$O$14,2,0) -> Meat Masala (ECO) | C24: =VLOOKUP(B24,'[1]Cust. Price List'!E14:P22,2,0) -> 60 | D24: =VLOOKUP(A24,'[1]Cust. Price List'!D14:M22,4,0) -> 40 | E24: =VLOOKUP(A24,'[1]Cust. Price List'!D14:M22,6,0) -> 50 | F24: =VLOOKUP(A24,'[1]Cust. Price List'!D14:M22,10,0) -> 39.23 | I24: =(G24*D24)*F24+H24*F24 -> 0 | K24: =I24*3.5% -> 0 | L24: =I24*$L$13 -> 0 | M24: =I24-K24-L24 -> 0 | N24: =(M24*$N$15)+(J24*F24)*$N$15 -> 0 | O24: =(N24+M24)*$O$15 -> 0 | P24: =M24+N24+O24 -> 0
A25: Total | G25: =SUM(G16:G24) -> 0 | H25: =SUM(H16:H24) -> 48 | I25: =SUM(I16:I24) -> 2684.88 | K25: =SUM(K16:K24) -> 32.9532 | L25: =SUM(L16:L24) -> 186.5448 | M25: =SUM(M16:M24) -> 2465.382 | N25: =SUM(N16:N24) -> 542.38404 | O25: =SUM(O16:O24) -> 75.194151 | P25: =SUM(P16:P24) -> 3082.9602
B28: یکم جولائی 2024سے نئی ٹیکس ترمیم کے مطابق، ایف بی آر سیکشن 236 ایچ کے مطابق، فائلرز کے لیے ہر سیل انوائس پر 0.5% اور نان فائلرز کے لیے 2.5% ایڈوانس ود ہولڈنگ ٹیکس وصول کیا جائے گا۔ | N28: Gross Amount: | P28: =I25 -> 2684.88
N29: Regular Discount | P29: =L25 -> 186.5448
N30: Trade Offre | P30: =K25 -> 32.9532
N31: After Dis. Amount | P31: =P28-P29-P30 -> 2465.382
N32: Total GST: | O32: =IF(B12="Registered",18%,22%) -> 0.22 | P32: =N25 -> 542.38404
N33: Net Amount: | P33: =P31+P32 -> 3007.766
N34: Ad.Tax | O34: =IF(B11="Filer",0.5%,2.5%) -> 0.025 | P34: =O34*P33 -> 75.194151
N35: Net Amount with Ad.Tax | P35: =P33+P34 -> 3082.9602
B36: Delivered By

Sheet bhai bhai 
A2: Elite MARKETING
A3: 44A- Gulberg Lahore | K3: Invoice No # : | N3: 3 | XFC3: Filer | XFD3: 0.005
A4: STRN / NTN :3808207-1 | K4: Date/Day : | N4: =TODAY() -> 46177 | XFC4: Non-filer | XFD4: 0.025
A5: Customer Name : Bhai Bhai Medical Store | K5: Order Date : | N5: =N4-1 -> 46176
A6: Address: Dharampura Chowk | K6: Order Name : | N6: Mobeen Ahmad | XFC6: Registered | XFD6: 0.18
XFC7: Un-registered | XFD7: 0.22
XFD9: Yes
A10: NTN/CNIC Number: | B10: 0159676-4 | K10: Invoice Status : | N10: Serviced | XFD10: No
B11: Filer | C11: =IF($O34>2.49%,"No","Yes") -> Yes | K11: Order at Original Location : | N11: Yes
A12: STRN Number: | B12: Un-registered | C12: =IF($O32>21.99%,"No","Yes") -> No | K12: Reference Invoice : | XFD12: Monday/Tuesday
L13: 0.05 | XFD13: Tuesday / Wednesday
A14: Product Code/Description | C14: GM/ Pack | D14: CTN | E14: R.P Per | F14: T.P Per | G14: Sale QTY | I14: Gross Amount Excl. Taxes | J14: Trade Offer & Discount | M14: After Discount Amount | N14: GST | O14: Adv. Tax 236H | P14: Invoice | XFD14: Wednesday/Thursday
D15: SIZE | E15: Unit | F15: Unit | G15: CTN | H15: Pack | J15: FOC Qty | K15: Trade Offer | L15: Pass On | N15: =IF(B12="Registered",18%,22%) -> 0.22 | O15: =IF(B11="Filer",0.5%,2.5%) -> 0.005 | P15: Amount | XFD15: Thursday /Friday
A16: BCN | B16: =VLOOKUP($A16,'[1]Cust. Price List'!$D$6:$O$14,2,0) -> Meat Masala | C16: =VLOOKUP(A16,'[1]Cust. Price List'!D6:M14,3,0) -> 70 | D16: =VLOOKUP(A16,'[1]Cust. Price List'!D6:M14,4,0) -> 40 | E16: =VLOOKUP(A16,'[1]Cust. Price List'!D6:M14,6,0) -> 65 | F16: =VLOOKUP(A16,'[1]Cust. Price List'!D6:M14,10,0) -> 52.4625 | I16: =(G16*D16)*F16+H16*F16 -> 0 | K16: =I16*$K$13 -> 0 | L16: =I16*8% -> 0 | M16: =I16-K16-L16 -> 0 | N16: =(M16*$N$15)+(J16*F16)*$N$15 -> 0 | O16: =(N16+M16)*$O$15 -> 0 | P16: =M16+N16+O16 -> 0 | XFD16: Friday / Saturday
A17: VTN | B17: =VLOOKUP($A17,'[1]Cust. Price List'!$D$6:$O$14,2,0) -> Lemon Tarka | C17: =VLOOKUP(B17,'[1]Cust. Price List'!E7:P15,2,0) -> 70 | D17: =VLOOKUP(A17,'[1]Cust. Price List'!D7:M15,4,0) -> 40 | E17: =VLOOKUP(A17,'[1]Cust. Price List'!D7:M15,6,0) -> 65 | F17: =VLOOKUP(A17,'[1]Cust. Price List'!D7:M15,10,0) -> 52.4625 | I17: =(G17*D17)*F17+H17*F17 -> 0 | K17: =I17*$K$13 -> 0 | L17: =I17*8% -> 0 | M17: =I17-K17-L17 -> 0 | N17: =(M17*$N$15)+(J17*F17)*$N$15 -> 0 | O17: =(N17+M17)*$O$15 -> 0 | P17: =M17+N17+O17 -> 0 | XFD17: Saturday /Monday
A18: CCN | B18: =VLOOKUP($A18,'[1]Cust. Price List'!$D$6:$O$14,2,0) -> Chicken Chatkhara | C18: =VLOOKUP(B18,'[1]Cust. Price List'!E8:P16,2,0) -> 70 | D18: =VLOOKUP(A18,'[1]Cust. Price List'!D8:M16,4,0) -> 40 | E18: =VLOOKUP(A18,'[1]Cust. Price List'!D8:M16,6,0) -> 65 | F18: =VLOOKUP(A18,'[1]Cust. Price List'!D8:M16,10,0) -> 52.4625 | I18: =(G18*D18)*F18+H18*F18 -> 0 | K18: =I18*$K$13 -> 0 | L18: =I18*8% -> 0 | M18: =I18-K18-L18 -> 0 | N18: =(M18*$N$15)+(J18*F18)*$N$15 -> 0 | O18: =(N18+M18)*$O$15 -> 0 | P18: =M18+N18+O18 -> 0
A19: BCNJ | B19: =VLOOKUP($A19,'[1]Cust. Price List'!$D$6:$O$14,2,0) -> Meat Masala (Jumbo) | C19: =VLOOKUP(B19,'[1]Cust. Price List'!E9:P17,2,0) -> 120 | D19: =VLOOKUP(A19,'[1]Cust. Price List'!D9:M17,4,0) -> 40 | E19: =VLOOKUP(A19,'[1]Cust. Price List'!D9:M17,6,0) -> 90 | F19: =VLOOKUP(A19,'[1]Cust. Price List'!D9:M17,10,0) -> 72.64 | H19: 6 | I19: =(G19*D19)*F19+H19*F19 -> 435.84 | K19: =I19*$K$13 -> 0 | L19: =I19*8% -> 34.8672 | M19: =I19-K19-L19 -> 400.9728 | N19: =(M19*$N$15)+(J19*F19)*$N$15 -> 88.214016 | O19: =(N19+M19)*$O$15 -> 2.4459341 | P19: =M19+N19+O19 -> 491.63275
A20: VTNJ | B20: =VLOOKUP($A20,'[1]Cust. Price List'!$D$6:$O$14,2,0) -> Lemon Tarka (Jumbo) | C20: =VLOOKUP(B20,'[1]Cust. Price List'!E10:P18,2,0) -> 120 | D20: =VLOOKUP(A20,'[1]Cust. Price List'!D10:M18,4,0) -> 40 | E20: =VLOOKUP(A20,'[1]Cust. Price List'!D10:M18,6,0) -> 90 | F20: =VLOOKUP(A20,'[1]Cust. Price List'!D10:M18,10,0) -> 72.64 | H20: 6 | I20: =(G20*D20)*F20+H20*F20 -> 435.84 | K20: =I20*$K$13 -> 0 | L20: =I20*8% -> 34.8672 | M20: =I20-K20-L20 -> 400.9728 | N20: =(M20*$N$15)+(J20*F20)*$N$15 -> 88.214016 | O20: =(N20+M20)*$O$15 -> 2.4459341 | P20: =M20+N20+O20 -> 491.63275
A21: CCNJ | B21: =VLOOKUP($A21,'[1]Cust. Price List'!$D$6:$O$14,2,0) -> Chicken Chatkhara (Jumbo) | C21: =VLOOKUP(B21,'[1]Cust. Price List'!E11:P19,2,0) -> 120 | D21: =VLOOKUP(A21,'[1]Cust. Price List'!D11:M19,4,0) -> 40 | E21: =VLOOKUP(A21,'[1]Cust. Price List'!D11:M19,6,0) -> 90 | F21: =VLOOKUP(A21,'[1]Cust. Price List'!D11:M19,10,0) -> 72.64 | H21: 6 | I21: =(G21*D21)*F21+H21*F21 -> 435.84 | K21: =I21*$K$13 -> 0 | L21: =I21*8% -> 34.8672 | M21: =I21-K21-L21 -> 400.9728 | N21: =(M21*$N$15)+(J21*F21)*$N$15 -> 88.214016 | O21: =(N21+M21)*$O$15 -> 2.4459341 | P21: =M21+N21+O21 -> 491.63275
A22: CCE | B22: =VLOOKUP($A22,'[1]Cust. Price List'!$D$6:$O$14,2,0) -> Chicken Chatkhara (ECO) | C22: =VLOOKUP(B22,'[1]Cust. Price List'!E12:P20,2,0) -> 60 | D22: =VLOOKUP(A22,'[1]Cust. Price List'!D12:M20,4,0) -> 40 | E22: =VLOOKUP(A22,'[1]Cust. Price List'!D12:M20,6,0) -> 50 | F22: =VLOOKUP(A22,'[1]Cust. Price List'!D12:M20,10,0) -> 39.23 | I22: =(G22*D22)*F22+H22*F22 -> 0 | K22: =I22*3.5% -> 0 | L22: =I22*5% -> 0 | M22: =I22-K22-L22 -> 0 | N22: =(M22*$N$15)+(J22*F22)*$N$15 -> 0 | O22: =(N22+M22)*$O$15 -> 0 | P22: =M22+N22+O22 -> 0
A23: VTE | B23: =VLOOKUP($A23,'[1]Cust. Price List'!$D$6:$O$14,2,0) -> Lemon Tarka (ECO) | C23: =VLOOKUP(B23,'[1]Cust. Price List'!E13:P21,2,0) -> 60 | D23: =VLOOKUP(A23,'[1]Cust. Price List'!D13:M21,4,0) -> 40 | E23: =VLOOKUP(A23,'[1]Cust. Price List'!D13:M21,6,0) -> 50 | F23: =VLOOKUP(A23,'[1]Cust. Price List'!D13:M21,10,0) -> 39.23 | I23: =(G23*D23)*F23+H23*F23 -> 0 | K23: =I23*3.5% -> 0 | L23: =I23*$L$13 -> 0 | M23: =I23-K23-L23 -> 0 | N23: =(M23*$N$15)+(J23*F23)*$N$15 -> 0 | O23: =(N23+M23)*$O$15 -> 0 | P23: =M23+N23+O23 -> 0
A24: BCE | B24: =VLOOKUP($A24,'[1]Cust. Price List'!$D$6:$O$14,2,0) -> Meat Masala (ECO) | C24: =VLOOKUP(B24,'[1]Cust. Price List'!E14:P22,2,0) -> 60 | D24: =VLOOKUP(A24,'[1]Cust. Price List'!D14:M22,4,0) -> 40 | E24: =VLOOKUP(A24,'[1]Cust. Price List'!D14:M22,6,0) -> 50 | F24: =VLOOKUP(A24,'[1]Cust. Price List'!D14:M22,10,0) -> 39.23 | I24: =(G24*D24)*F24+H24*F24 -> 0 | K24: =I24*3.5% -> 0 | L24: =I24*$L$13 -> 0 | M24: =I24-K24-L24 -> 0 | N24: =(M24*$N$15)+(J24*F24)*$N$15 -> 0 | O24: =(N24+M24)*$O$15 -> 0 | P24: =M24+N24+O24 -> 0
A25: Total | G25: =SUM(G16:G24) -> 0 | H25: =SUM(H16:H24) -> 18 | I25: =SUM(I16:I24) -> 1307.52 | K25: =SUM(K16:K24) -> 0 | L25: =SUM(L16:L24) -> 104.6016 | M25: =SUM(M16:M24) -> 1202.9184 | N25: =SUM(N16:N24) -> 264.64205 | O25: =SUM(O16:O24) -> 7.3378022 | P25: =SUM(P16:P24) -> 1474.8983
B28: یکم جولائی 2024سے نئی ٹیکس ترمیم کے مطابق، ایف بی آر سیکشن 236 ایچ کے مطابق، فائلرز کے لیے ہر سیل انوائس پر 0.5% اور نان فائلرز کے لیے 2.5% ایڈوانس ود ہولڈنگ ٹیکس وصول کیا جائے گا۔ | N28: Gross Amount: | P28: =I25 -> 1307.52
N29: Regular Discount | P29: =L25 -> 104.6016
N30: Trade Offre | P30: =K25 -> 0
N31: After Dis. Amount | P31: =P28-P29-P30 -> 1202.9184
N32: Total GST: | O32: =IF(B12="Registered",18%,22%) -> 0.22 | P32: =N25 -> 264.64205
N33: Net Amount: | P33: =P31+P32 -> 1467.5604
N34: Ad.Tax | O34: =IF(B11="Filer",0.5%,2.5%) -> 0.005 | P34: =O34*P33 -> 7.3378022
N35: Net Amount with Ad.Tax | P35: =P33+P34 -> 1474.8983
B36: Delivered By

Sheet food
A2: Elite MARKETING
A3: 44A- Gulberg Lahore | K3: Invoice No # : | N3: 6 | XFC3: Filer | XFD3: 0.005
A4: STRN / NTN :3808207-1 | K4: Date/Day : | N4: =TODAY() -> 46177 | XFC4: Non-filer | XFD4: 0.025
A5: Customer Name : Food Rite | K5: Order Date : | N5: =N4-1 -> 46176
A6: Address: Iqbal Road | K6: Order Name : | N6: Mobeen Ahmad | XFC6: Registered | XFD6: 0.18
XFC7: Un-registered | XFD7: 0.22
XFD9: Yes
A10: NTN/CNIC Number: | B10: 4031762-5 | K10: Invoice Status : | N10: Serviced | XFD10: No
B11: Filer | C11: =IF($O34>2.49%,"No","Yes") -> Yes | K11: Order at Original Location : | N11: Yes
A12: STRN Number: | B12: Registered | C12: =IF($O32>21.99%,"No","Yes") -> Yes | K12: Reference Invoice : | XFD12: Monday/Tuesday
B13: 3520168333533 | L13: 0.05 | XFD13: Tuesday / Wednesday
A14: Product Code/Description | C14: GM/ Pack | D14: CTN | E14: R.P Per | F14: T.P Per | G14: Sale QTY | I14: Gross Amount Excl. Taxes | J14: Trade Offer & Discount | M14: After Discount Amount | N14: GST | O14: Adv. Tax 236H | P14: Invoice | XFD14: Wednesday/Thursday
D15: SIZE | E15: Unit | F15: Unit | G15: CTN | H15: Pack | J15: FOC Qty | K15: Trade Offer | L15: Pass On | N15: =IF(B12="Registered",18%,22%) -> 0.18 | O15: =IF(B11="Filer",0.5%,2.5%) -> 0.005 | P15: Amount | XFD15: Thursday /Friday
A16: BCN | B16: =VLOOKUP($A16,'[1]Cust. Price List'!$D$6:$O$14,2,0) -> Meat Masala | C16: =VLOOKUP(A16,'[1]Cust. Price List'!D6:M14,3,0) -> 70 | D16: =VLOOKUP(A16,'[1]Cust. Price List'!D6:M14,4,0) -> 40 | E16: =VLOOKUP(A16,'[1]Cust. Price List'!D6:M14,6,0) -> 65 | F16: =VLOOKUP(A16,'[1]Cust. Price List'!D6:M14,10,0) -> 52.4625 | I16: =(G16*D16)*F16+H16*F16 -> 0 | K16: =I16*$K$13 -> 0 | L16: =I16*8% -> 0 | M16: =I16-K16-L16 -> 0 | N16: =(M16*$N$15)+(J16*F16)*$N$15 -> 0 | O16: =(N16+M16)*$O$15 -> 0 | P16: =M16+N16+O16 -> 0 | XFD16: Friday / Saturday
A17: VTN | B17: =VLOOKUP($A17,'[1]Cust. Price List'!$D$6:$O$14,2,0) -> Lemon Tarka | C17: =VLOOKUP(B17,'[1]Cust. Price List'!E7:P15,2,0) -> 70 | D17: =VLOOKUP(A17,'[1]Cust. Price List'!D7:M15,4,0) -> 40 | E17: =VLOOKUP(A17,'[1]Cust. Price List'!D7:M15,6,0) -> 65 | F17: =VLOOKUP(A17,'[1]Cust. Price List'!D7:M15,10,0) -> 52.4625 | H17: 16 | I17: =(G17*D17)*F17+H17*F17 -> 839.4 | J17: 1 | K17: =I17*$K$13 -> 0 | L17: =I17*8% -> 67.152 | M17: =I17-K17-L17 -> 772.248 | N17: =(M17*$N$15)+(J17*F17)*$N$15 -> 148.44789 | O17: =(N17+M17)*$O$15 -> 4.6034795 | P17: =M17+N17+O17 -> 925.29937 | XFD17: Saturday /Monday
A18: CCN | B18: =VLOOKUP($A18,'[1]Cust. Price List'!$D$6:$O$14,2,0) -> Chicken Chatkhara | C18: =VLOOKUP(B18,'[1]Cust. Price List'!E8:P16,2,0) -> 70 | D18: =VLOOKUP(A18,'[1]Cust. Price List'!D8:M16,4,0) -> 40 | E18: =VLOOKUP(A18,'[1]Cust. Price List'!D8:M16,6,0) -> 65 | F18: =VLOOKUP(A18,'[1]Cust. Price List'!D8:M16,10,0) -> 52.4625 | H18: 24 | I18: =(G18*D18)*F18+H18*F18 -> 1259.1 | J18: 1 | K18: =I18*$K$13 -> 0 | L18: =I18*8% -> 100.728 | M18: =I18-K18-L18 -> 1158.372 | N18: =(M18*$N$15)+(J18*F18)*$N$15 -> 217.95021 | O18: =(N18+M18)*$O$15 -> 6.881611 | P18: =M18+N18+O18 -> 1383.2038
A19: BCNJ | B19: =VLOOKUP($A19,'[1]Cust. Price List'!$D$6:$O$14,2,0) -> Meat Masala (Jumbo) | C19: =VLOOKUP(B19,'[1]Cust. Price List'!E9:P17,2,0) -> 120 | D19: =VLOOKUP(A19,'[1]Cust. Price List'!D9:M17,4,0) -> 40 | E19: =VLOOKUP(A19,'[1]Cust. Price List'!D9:M17,6,0) -> 90 | F19: =VLOOKUP(A19,'[1]Cust. Price List'!D9:M17,10,0) -> 72.64 | I19: =(G19*D19)*F19+H19*F19 -> 0 | K19: =I19*$K$13 -> 0 | L19: =I19*8% -> 0 | M19: =I19-K19-L19 -> 0 | N19: =(M19*$N$15)+(J19*F19)*$N$15 -> 0 | O19: =(N19+M19)*$O$15 -> 0 | P19: =M19+N19+O19 -> 0
A20: VTNJ | B20: =VLOOKUP($A20,'[1]Cust. Price List'!$D$6:$O$14,2,0) -> Lemon Tarka (Jumbo) | C20: =VLOOKUP(B20,'[1]Cust. Price List'!E10:P18,2,0) -> 120 | D20: =VLOOKUP(A20,'[1]Cust. Price List'!D10:M18,4,0) -> 40 | E20: =VLOOKUP(A20,'[1]Cust. Price List'!D10:M18,6,0) -> 90 | F20: =VLOOKUP(A20,'[1]Cust. Price List'!D10:M18,10,0) -> 72.64 | I20: =(G20*D20)*F20+H20*F20 -> 0 | K20: =I20*$K$13 -> 0 | L20: =I20*8% -> 0 | M20: =I20-K20-L20 -> 0 | N20: =(M20*$N$15)+(J20*F20)*$N$15 -> 0 | O20: =(N20+M20)*$O$15 -> 0 | P20: =M20+N20+O20 -> 0
A21: CCNJ | B21: =VLOOKUP($A21,'[1]Cust. Price List'!$D$6:$O$14,2,0) -> Chicken Chatkhara (Jumbo) | C21: =VLOOKUP(B21,'[1]Cust. Price List'!E11:P19,2,0) -> 120 | D21: =VLOOKUP(A21,'[1]Cust. Price List'!D11:M19,4,0) -> 40 | E21: =VLOOKUP(A21,'[1]Cust. Price List'!D11:M19,6,0) -> 90 | F21: =VLOOKUP(A21,'[1]Cust. Price List'!D11:M19,10,0) -> 72.64 | I21: =(G21*D21)*F21+H21*F21 -> 0 | K21: =I21*$K$13 -> 0 | L21: =I21*8% -> 0 | M21: =I21-K21-L21 -> 0 | N21: =(M21*$N$15)+(J21*F21)*$N$15 -> 0 | O21: =(N21+M21)*$O$15 -> 0 | P21: =M21+N21+O21 -> 0
A22: CCE | B22: =VLOOKUP($A22,'[1]Cust. Price List'!$D$6:$O$14,2,0) -> Chicken Chatkhara (ECO) | C22: =VLOOKUP(B22,'[1]Cust. Price List'!E12:P20,2,0) -> 60 | D22: =VLOOKUP(A22,'[1]Cust. Price List'!D12:M20,4,0) -> 40 | E22: =VLOOKUP(A22,'[1]Cust. Price List'!D12:M20,6,0) -> 50 | F22: =VLOOKUP(A22,'[1]Cust. Price List'!D12:M20,10,0) -> 39.23 | I22: =(G22*D22)*F22+H22*F22 -> 0 | K22: =I22*3.5% -> 0 | L22: =I22*5% -> 0 | M22: =I22-K22-L22 -> 0 | N22: =(M22*$N$15)+(J22*F22)*$N$15 -> 0 | O22: =(N22+M22)*$O$15 -> 0 | P22: =M22+N22+O22 -> 0
A23: VTE | B23: =VLOOKUP($A23,'[1]Cust. Price List'!$D$6:$O$14,2,0) -> Lemon Tarka (ECO) | C23: =VLOOKUP(B23,'[1]Cust. Price List'!E13:P21,2,0) -> 60 | D23: =VLOOKUP(A23,'[1]Cust. Price List'!D13:M21,4,0) -> 40 | E23: =VLOOKUP(A23,'[1]Cust. Price List'!D13:M21,6,0) -> 50 | F23: =VLOOKUP(A23,'[1]Cust. Price List'!D13:M21,10,0) -> 39.23 | I23: =(G23*D23)*F23+H23*F23 -> 0 | K23: =I23*3.5% -> 0 | L23: =I23*$L$13 -> 0 | M23: =I23-K23-L23 -> 0 | N23: =(M23*$N$15)+(J23*F23)*$N$15 -> 0 | O23: =(N23+M23)*$O$15 -> 0 | P23: =M23+N23+O23 -> 0
A24: BCE | B24: =VLOOKUP($A24,'[1]Cust. Price List'!$D$6:$O$14,2,0) -> Meat Masala (ECO) | C24: =VLOOKUP(B24,'[1]Cust. Price List'!E14:P22,2,0) -> 60 | D24: =VLOOKUP(A24,'[1]Cust. Price List'!D14:M22,4,0) -> 40 | E24: =VLOOKUP(A24,'[1]Cust. Price List'!D14:M22,6,0) -> 50 | F24: =VLOOKUP(A24,'[1]Cust. Price List'!D14:M22,10,0) -> 39.23 | I24: =(G24*D24)*F24+H24*F24 -> 0 | K24: =I24*3.5% -> 0 | L24: =I24*$L$13 -> 0 | M24: =I24-K24-L24 -> 0 | N24: =(M24*$N$15)+(J24*F24)*$N$15 -> 0 | O24: =(N24+M24)*$O$15 -> 0 | P24: =M24+N24+O24 -> 0
A25: Total | G25: =SUM(G16:G24) -> 0 | H25: =SUM(H16:H24) -> 40 | I25: =SUM(I16:I24) -> 2098.5 | K25: =SUM(K16:K24) -> 0 | L25: =SUM(L16:L24) -> 167.88 | M25: =SUM(M16:M24) -> 1930.62 | N25: =SUM(N16:N24) -> 366.3981 | O25: =SUM(O16:O24) -> 11.48509 | P25: =SUM(P16:P24) -> 2308.5032
B28: یکم جولائی 2024سے نئی ٹیکس ترمیم کے مطابق، ایف بی آر سیکشن 236 ایچ کے مطابق، فائلرز کے لیے ہر سیل انوائس پر 0.5% اور نان فائلرز کے لیے 2.5% ایڈوانس ود ہولڈنگ ٹیکس وصول کیا جائے گا۔ | N28: Gross Amount: | P28: =I25 -> 2098.5
N29: Regular Discount | P29: =L25 -> 167.88
N30: Trade Offre | P30: =K25 -> 0
N31: After Dis. Amount | P31: =P28-P29-P30 -> 1930.62
N32: Total GST: | O32: =IF(B12="Registered",18%,22%) -> 0.18 | P32: =N25 -> 366.3981
N33: Net Amount: | P33: =P31+P32 -> 2297.0181
N34: Ad.Tax | O34: =IF(B11="Filer",0.5%,2.5%) -> 0.005 | P34: =O34*P33 -> 11.48509
N35: Net Amount with Ad.Tax | P35: =P33+P34 -> 2308.5032
B36: Delivered By

Sheet shaheen 
A2: Elite MARKETING
A3: 44A- Gulberg Lahore | K3: Invoice No # : | N3: 7 | XFC3: Filer | XFD3: 0.005
A4: STRN / NTN :3808207-1 | K4: Date/Day : | N4: =TODAY() -> 46177 | XFC4: Non-filer | XFD4: 0.025
A5: Customer Name :Shaheen Bakers | K5: Order Date : | N5: =N4-1 -> 46176
A6: Address: Sadar Bazar | K6: Order Name : | N6: Mobeen Ahmad | XFC6: Registered | XFD6: 0.18
XFC7: Un-registered | XFD7: 0.22
XFD9: Yes
A10: NTN/CNIC Number: | K10: Invoice Status : | N10: Serviced | XFD10: No
B11: Filer | C11: =IF($O34>2.49%,"No","Yes") -> Yes | K11: Order at Original Location : | N11: Yes
A12: STRN Number: | B12: Un-registered | C12: =IF($O32>21.99%,"No","Yes") -> No | K12: Reference Invoice : | XFD12: Monday/Tuesday
L13: 0.05 | XFD13: Tuesday / Wednesday
A14: Product Code/Description | C14: GM/ Pack | D14: CTN | E14: R.P Per | F14: T.P Per | G14: Sale QTY | I14: Gross Amount Excl. Taxes | J14: Trade Offer & Discount | M14: After Discount Amount | N14: GST | O14: Adv. Tax 236H | P14: Invoice | XFD14: Wednesday/Thursday
D15: SIZE | E15: Unit | F15: Unit | G15: CTN | H15: Pack | J15: FOC Qty | K15: Trade Offer | L15: Pass On | N15: =IF(B12="Registered",18%,22%) -> 0.22 | O15: =IF(B11="Filer",0.5%,2.5%) -> 0.005 | P15: Amount | XFD15: Thursday /Friday
A16: BCN | B16: =VLOOKUP($A16,'[1]Cust. Price List'!$D$6:$O$14,2,0) -> Meat Masala | C16: =VLOOKUP(A16,'[1]Cust. Price List'!D6:M14,3,0) -> 70 | D16: =VLOOKUP(A16,'[1]Cust. Price List'!D6:M14,4,0) -> 40 | E16: =VLOOKUP(A16,'[1]Cust. Price List'!D6:M14,6,0) -> 65 | F16: =VLOOKUP(A16,'[1]Cust. Price List'!D6:M14,10,0) -> 52.4625 | I16: =(G16*D16)*F16+H16*F16 -> 0 | K16: =I16*$K$13 -> 0 | L16: =I16*8% -> 0 | M16: =I16-K16-L16 -> 0 | N16: =(M16*$N$15)+(J16*F16)*$N$15 -> 0 | O16: =(N16+M16)*$O$15 -> 0 | P16: =M16+N16+O16 -> 0 | XFD16: Friday / Saturday
A17: VTN | B17: =VLOOKUP($A17,'[1]Cust. Price List'!$D$6:$O$14,2,0) -> Lemon Tarka | C17: =VLOOKUP(B17,'[1]Cust. Price List'!E7:P15,2,0) -> 70 | D17: =VLOOKUP(A17,'[1]Cust. Price List'!D7:M15,4,0) -> 40 | E17: =VLOOKUP(A17,'[1]Cust. Price List'!D7:M15,6,0) -> 65 | F17: =VLOOKUP(A17,'[1]Cust. Price List'!D7:M15,10,0) -> 52.4625 | I17: =(G17*D17)*F17+H17*F17 -> 0 | K17: =I17*$K$13 -> 0 | L17: =I17*8% -> 0 | M17: =I17-K17-L17 -> 0 | N17: =(M17*$N$15)+(J17*F17)*$N$15 -> 0 | O17: =(N17+M17)*$O$15 -> 0 | P17: =M17+N17+O17 -> 0 | XFD17: Saturday /Monday
