Workbook

Sheet Sheet2
B5: OB Name
A6: 1 | B6: Salman Butt
A7: 2 | B7: Qasim Khan
A8: 3 | B8: Mobeen Ahmad
A9: 4 | B9: Zahid Rafique
A10: 5 | B10: Zeeshan Meharban
A11: 6 | B11: Furqan
A12: 7 | B12: Rana Bilal Tso
A13: 8 | B13: Shakoor
A14: 9
A15: 10
A16: 11
A17: 12
A18: 13

Sheet Cust. Price List
V2: 0.18
A4: S# | B4: Code | D4: SKU | E4: SKUs Description | F4: Unit | H4: Retail Price | J4: TP Incl. | L4: TP Excl. | N4: Dist Margin | P4: Trade Offre | R4: Stale | T4: Ex-Fac | V4: S.Tax | X4: Dist. Price
B5: Bar | C5: SKU | F5: Gm | G5: CTN | H5: Ctn | I5: Pk | J5: Ctn | K5: Pk | L5: Ctn | M5: Pk | N5: 0.19 | O5: Amount | P5: 0.04 | Q5: Amount | R5: 0.005 | S5: Amount | T5: Ctn | U5: Pk | V5: Ctn | W5: Pk | X5: Ctn | Y5: Pk | AA5: Weight/ctn
A6: 1 | C6: BCN | D6: BCN | E6: Meat Masala | F6: 70 | G6: 40 | H6: =I6*G6 -> 2600 | I6: 65 | J6: =K6*G6 -> 2560.17 | K6: =M6*1.22 -> 64.00425 | L6: 2098.5 | M6: =L6/G6 -> 52.4625 | N6: 0.19 | O6: =N6*M6 -> 9.967875 | Q6: =P6*M6 -> 0 | S6: =R6*M6 -> 0 | T6: =U6*G6 -> 1699.785 | U6: =M6-O6-Q6-S6 -> 42.494625 | V6: =T6*$V$2 -> 305.9613 | W6: =U6*$V$2 -> 7.6490325 | X6: =T6+V6 -> 2005.7463 | Y6: =U6+W6 -> 50.143657 | AA6: =(F6*G6)/1000 -> 2.8
A7: =+A6+1 -> 2 | C7: VTN | D7: VTN | E7: Lemon Tarka | F7: 70 | G7: 40 | H7: =I7*G7 -> 2600 | I7: 65 | J7: =K7*G7 -> 2560.17 | K7: =M7*1.22 -> 64.00425 | L7: 2098.5 | M7: =L7/G7 -> 52.4625 | N7: =+N6 -> 0.19 | O7: =N7*M7 -> 9.967875 | Q7: =P7*M7 -> 0 | S7: =R7*M7 -> 0 | T7: =U7*G7 -> 1699.785 | U7: =M7-O7-Q7-S7 -> 42.494625 | V7: =T7*$V$2 -> 305.9613 | W7: =U7*$V$2 -> 7.6490325 | X7: =T7+V7 -> 2005.7463 | Y7: =U7+W7 -> 50.143657 | AA7: =(F7*G7)/1000 -> 2.8
A8: =+A7+1 -> 3 | C8: CCN | D8: CCN | E8: Chicken Chatkhara | F8: 70 | G8: 40 | H8: =I8*G8 -> 2600 | I8: 65 | J8: =K8*G8 -> 2560.17 | K8: =M8*1.22 -> 64.00425 | L8: 2098.5 | M8: =L8/G8 -> 52.4625 | N8: =+N7 -> 0.19 | O8: =N8*M8 -> 9.967875 | Q8: =P8*M8 -> 0 | S8: =R8*M8 -> 0 | T8: =U8*G8 -> 1699.785 | U8: =M8-O8-Q8-S8 -> 42.494625 | V8: =T8*$V$2 -> 305.9613 | W8: =U8*$V$2 -> 7.6490325 | X8: =T8+V8 -> 2005.7463 | Y8: =U8+W8 -> 50.143657 | AA8: =(F8*G8)/1000 -> 2.8
A9: =+A8+1 -> 4 | C9: BCNJ | D9: BCNJ | E9: Meat Masala (Jumbo) | F9: 120 | G9: 40 | H9: =I9*G9 -> 3600 | I9: 90 | J9: =K9*G9 -> 3544.832 | K9: =M9*1.22 -> 88.6208 | L9: 2905.6 | M9: =L9/G9 -> 72.64 | N9: =+N8 -> 0.19 | O9: =N9*M9 -> 13.8016 | Q9: =P9*M9 -> 0 | S9: =R9*M9 -> 0 | T9: =U9*G9 -> 2353.536 | U9: =M9-O9-Q9-S9 -> 58.8384 | V9: =T9*$V$2 -> 423.63648 | W9: =U9*$V$2 -> 10.590912 | X9: =T9+V9 -> 2777.1725 | Y9: =U9+W9 -> 69.429312 | AA9: =(F9*G9)/1000 -> 4.8
A10: =+A9+1 -> 5 | C10: VTNJ | D10: VTNJ | E10: Lemon Tarka (Jumbo) | F10: 120 | G10: 40 | H10: =I10*G10 -> 3600 | I10: 90 | J10: =K10*G10 -> 3544.832 | K10: =M10*1.22 -> 88.6208 | L10: 2905.6 | M10: =L10/G10 -> 72.64 | N10: =+N9 -> 0.19 | O10: =N10*M10 -> 13.8016 | Q10: =P10*M10 -> 0 | S10: =R10*M10 -> 0 | T10: =U10*G10 -> 2353.536 | U10: =M10-O10-Q10-S10 -> 58.8384 | V10: =T10*$V$2 -> 423.63648 | W10: =U10*$V$2 -> 10.590912 | X10: =T10+V10 -> 2777.1725 | Y10: =U10+W10 -> 69.429312 | AA10: =(F10*G10)/1000 -> 4.8
A11: =+A10+1 -> 6 | C11: CCNJ | D11: CCNJ | E11: Chicken Chatkhara (Jumbo) | F11: 120 | G11: 40 | H11: =I11*G11 -> 3600 | I11: 90 | J11: =K11*G11 -> 3544.832 | K11: =M11*1.22 -> 88.6208 | L11: 2905.6 | M11: =L11/G11 -> 72.64 | N11: =+N10 -> 0.19 | O11: =N11*M11 -> 13.8016 | Q11: =P11*M11 -> 0 | S11: =R11*M11 -> 0 | T11: =U11*G11 -> 2353.536 | U11: =M11-O11-Q11-S11 -> 58.8384 | V11: =T11*$V$2 -> 423.63648 | W11: =U11*$V$2 -> 10.590912 | X11: =T11+V11 -> 2777.1725 | Y11: =U11+W11 -> 69.429312 | AA11: =(F11*G11)/1000 -> 4.8
A12: =+A11+1 -> 7 | C12: CCE | D12: CCE | E12: Chicken Chatkhara (ECO) | F12: 60 | G12: 40 | H12: =I12*G12 -> 2000 | I12: 50 | J12: =K12*G12 -> 1914.424 | K12: =M12*1.22 -> 47.8606 | L12: 1569.2 | M12: =L12/G12 -> 39.23 | N12: =+N11 -> 0.19 | O12: =N12*M12 -> 7.4537 | Q12: =P12*M12 -> 0 | S12: =R12*M12 -> 0 | T12: =U12*G12 -> 1271.052 | U12: =M12-O12-Q12-S12 -> 31.7763 | V12: =T12*$V$2 -> 228.78936 | W12: =U12*$V$2 -> 5.719734 | X12: =T12+V12 -> 1499.8414 | Y12: =U12+W12 -> 37.496034 | AA12: =(F12*G12)/1000 -> 2.4
A13: =+A12+1 -> 8 | C13: VTE | D13: VTE | E13: Lemon Tarka (ECO) | F13: 60 | G13: 40 | H13: =I13*G13 -> 2000 | I13: 50 | J13: =K13*G13 -> 1914.424 | K13: =M13*1.22 -> 47.8606 | L13: 1569.2 | M13: =L13/G13 -> 39.23 | N13: =+N12 -> 0.19 | O13: =N13*M13 -> 7.4537 | Q13: =P13*M13 -> 0 | S13: =R13*M13 -> 0 | T13: =U13*G13 -> 1271.052 | U13: =M13-O13-Q13-S13 -> 31.7763 | V13: =T13*$V$2 -> 228.78936 | W13: =U13*$V$2 -> 5.719734 | X13: =T13+V13 -> 1499.8414 | Y13: =U13+W13 -> 37.496034 | AA13: =(F13*G13)/1000 -> 2.4
A14: =+A13+1 -> 9 | C14: BCE | D14: BCE | E14: Meat Masala (ECO) | F14: 60 | G14: 40 | H14: =I14*G14 -> 2000 | I14: 50 | J14: =K14*G14 -> 1914.424 | K14: =M14*1.22 -> 47.8606 | L14: 1569.2 | M14: =L14/G14 -> 39.23 | N14: =+N13 -> 0.19 | O14: =N14*M14 -> 7.4537 | Q14: =P14*M14 -> 0 | S14: =R14*M14 -> 0 | T14: =U14*G14 -> 1271.052 | U14: =M14-O14-Q14-S14 -> 31.7763 | V14: =T14*$V$2 -> 228.78936 | W14: =U14*$V$2 -> 5.719734 | X14: =T14+V14 -> 1499.8414 | Y14: =U14+W14 -> 37.496034 | AA14: =(F14*G14)/1000 -> 2.4
A15: =+A14+1 -> 10
A16: =+A15+1 -> 11
A17: =+A16+1 -> 12
A18: =+A17+1 -> 13
A19: =+A18+1 -> 14
A20: =+A19+1 -> 15
A22: =+A20+1 -> 16
A23: =+A22+1 -> 17
A24: =+A23+1 -> 18
A25: =+A24+1 -> 19
A26: =+A25+1 -> 20
A27: =+A26+1 -> 21
A28: =+A27+1 -> 22
A29: =+A28+1 -> 23
A30: =+A29+1 -> 24
A31: =+A30+1 -> 25
A32: =+A31+1 -> 26
A33: =+A32+1 -> 27
A34: =+A33+1 -> 28
A36: =+A34+1 -> 29
A37: =+A36+1 -> 30
A38: =+A37+1 -> 31
A39: =+A38+1 -> 32
A40: =+A39+1 -> 33
A41: =+A40+1 -> 34
A42: =+A41+1 -> 35
A43: =+A42+1 -> 36
A44: =+A43+1 -> 37
...

Sheet Format
A2: Elite MARKETING
A3: 44A- Gulberg Lahore | K3: Invoice No # : | N3: 1 | XFC3: Filer | XFD3: 0.005
A4: STRN / NTN :3808207-1 | K4: Date/Day : | N4: =TODAY() -> 46188 | XFC4: Non-filer | XFD4: 0.025
A5: Shakoor | K5: Order Date : | N5: =N4-1 -> 46187
K6: Order Name : | N6: Salman Aslam | XFC6: Registered | XFD6: 0.18
XFC7: Un-registered | XFD7: 0.22
XFD9: Yes
K10: Invoice Status : | N10: Serviced | XFD10: No
K11: Order at Original Location : | N11: Yes
K12: Reference Invoice : | T12: Shop Bill Summary (Mobeen Ahmad) | XFD12: Monday/Tuesday
L13: 0.05 | XFD13: Tuesday / Wednesday
A14: Product Code/Description | C14: GM/ Pack | D14: CTN | E14: R.P Per | F14: T.P Per | G14: Sale QTY | I14: Gross Amount Excl. Taxes | J14: Trade Offer & Discount | M14: After Discount Amount | N14: GST | O14: Adv. Tax 236H | P14: Invoice | T14: =+Clinix!A5 -> Customer Name : Clinix Central Warehouse | U14: =+Clinix!P35 -> 121290.65 | XFD14: Wednesday/Thursday
D15: SIZE | E15: Unit | F15: Unit | G15: CTN | H15: Pack | J15: FOC Qty | K15: Trade Offer | L15: Pass On | N15: =IF(B12="Registered",18%,22%) -> 0.22 | O15: =IF(B11="Filer",0.5%,2.5%) -> 0.025 | P15: Amount | T15: =+'al-fatah'!A5 -> Customer Name : Al-Fatah Shoping Mall | U15: =+'al-fatah'!P35 -> 419118.83 | XFD15: Thursday /Friday
A16: BCN | B16: =VLOOKUP($A16,'[1]Cust. Price List'!$D$6:$O$14,2,0) -> Meat Masala | C16: =VLOOKUP(A16,'[1]Cust. Price List'!D6:M14,3,0) -> 70 | D16: =VLOOKUP(A16,'[1]Cust. Price List'!D6:M14,4,0) -> 40 | E16: =VLOOKUP(A16,'[1]Cust. Price List'!D6:M14,6,0) -> 65 | F16: =VLOOKUP(A16,'[1]Cust. Price List'!D6:M14,10,0) -> 52.4625 | H16: =+Clinix!H16+'al-fatah'!H16+khan!H16+top!H16+mrwa!H16+saad!H16+cant!H16+HRMN!H16+Ghani!H16+Mehaj!H16+Bravo!H16+'786'!H16 -> 840 | I16: =(G16*D16)*F16+H16*F16 -> 44068.5 | J16: =+Clinix!J16+'al-fatah'!J16+khan!J16+top!J16+mrwa!J16+saad!J16+cant!J16+HRMN!J16+Ghani!J16+Mehaj!J16+Bravo!J16+'786'!J16 -> 0 | K16: =+Clinix!K16+'al-fatah'!K16+khan!K16+top!K16+mrwa!K16+saad!K16+cant!K16+HRMN!K16+Ghani!K16+Mehaj!K16 -> 0 | L16: =+Clinix!L16+'al-fatah'!L16+khan!L16+top!L16+mrwa!L16+saad!L16+cant!L16+HRMN!L16+Ghani!L16+Mehaj!L16 -> 7176.87 | M16: =I16-K16-L16 -> 36891.63 | N16: =+Clinix!N16+'al-fatah'!N16+khan!N16+top!N16+mrwa!N16+saad!N16+cant!N16+HRMN!N16+Ghani!N16+Mehaj!N16 -> 6640.4934 | O16: =+Clinix!O16+'al-fatah'!O16+khan!O16+top!O16+mrwa!O16+saad!O16+cant!O16+HRMN!O16+Ghani!O16+Mehaj!O16 -> 217.66062 | P16: =M16+N16+O16 -> 43749.784 | T16: =+khan!A5 -> Customer Name : Khan Store | U16: =+khan!P35 -> 0 | XFD16: Friday / Saturday
A17: VTN | B17: =VLOOKUP($A17,'[1]Cust. Price List'!$D$6:$O$14,2,0) -> Lemon Tarka | C17: =VLOOKUP(B17,'[1]Cust. Price List'!E7:P15,2,0) -> 70 | D17: =VLOOKUP(A17,'[1]Cust. Price List'!D7:M15,4,0) -> 40 | E17: =VLOOKUP(A17,'[1]Cust. Price List'!D7:M15,6,0) -> 65 | F17: =VLOOKUP(A17,'[1]Cust. Price List'!D7:M15,10,0) -> 52.4625 | H17: =+Clinix!H17+'al-fatah'!H17+khan!H17+top!H17+mrwa!H17+saad!H17+cant!H17+HRMN!H17+Ghani!H17+Mehaj!H17+Bravo!H17+'786'!H17 -> 840 | I17: =(G17*D17)*F17+H17*F17 -> 44068.5 | J17: =+Clinix!J17+'al-fatah'!J17+khan!J17+top!J17+mrwa!J17+saad!J17+cant!J17+HRMN!J17+Ghani!J17+Mehaj!J17+Bravo!J17+'786'!J17 -> 0 | K17: =+Clinix!K17+'al-fatah'!K17+khan!K17+top!K17+mrwa!K17+saad!K17+cant!K17+HRMN!K17+Ghani!K17+Mehaj!K17 -> 0 | L17: =+Clinix!L17+'al-fatah'!L17+khan!L17+top!L17+mrwa!L17+saad!L17+cant!L17+HRMN!L17+Ghani!L17+Mehaj!L17 -> 7176.87 | M17: =I17-K17-L17 -> 36891.63 | N17: =+Clinix!N17+'al-fatah'!N17+khan!N17+top!N17+mrwa!N17+saad!N17+cant!N17+HRMN!N17+Ghani!N17+Mehaj!N17 -> 6640.4934 | O17: =+Clinix!O17+'al-fatah'!O17+khan!O17+top!O17+mrwa!O17+saad!O17+cant!O17+HRMN!O17+Ghani!O17+Mehaj!O17 -> 217.66062 | P17: =M17+N17+O17 -> 43749.784 | T17: =+top!A5 -> Customer Name : Top Bakers | U17: =+top!P35 -> 0 | XFD17: Saturday /Monday
A18: CCN | B18: =VLOOKUP($A18,'[1]Cust. Price List'!$D$6:$O$14,2,0) -> Chicken Chatkhara | C18: =VLOOKUP(B18,'[1]Cust. Price List'!E8:P16,2,0) -> 70 | D18: =VLOOKUP(A18,'[1]Cust. Price List'!D8:M16,4,0) -> 40 | E18: =VLOOKUP(A18,'[1]Cust. Price List'!D8:M16,6,0) -> 65 | F18: =VLOOKUP(A18,'[1]Cust. Price List'!D8:M16,10,0) -> 52.4625 | H18: =+Clinix!H18+'al-fatah'!H18+khan!H18+top!H18+mrwa!H18+saad!H18+cant!H18+HRMN!H18+Ghani!H18+Mehaj!H18+Bravo!H18+'786'!H18 -> 1440 | I18: =(G18*D18)*F18+H18*F18 -> 75546 | J18: =+Clinix!J18+'al-fatah'!J18+khan!J18+top!J18+mrwa!J18+saad!J18+cant!J18+HRMN!J18+Ghani!J18+Mehaj!J18+Bravo!J18+'786'!J18 -> 0 | K18: =+Clinix!K18+'al-fatah'!K18+khan!K18+top!K18+mrwa!K18+saad!K18+cant!K18+HRMN!K18+Ghani!K18+Mehaj!K18 -> 0 | L18: =+Clinix!L18+'al-fatah'!L18+khan!L18+top!L18+mrwa!L18+saad!L18+cant!L18+HRMN!L18+Ghani!L18+Mehaj!L18 -> 12842.82 | M18: =I18-K18-L18 -> 62703.18 | N18: =+Clinix!N18+'al-fatah'!N18+khan!N18+top!N18+mrwa!N18+saad!N18+cant!N18+HRMN!N18+Ghani!N18+Mehaj!N18 -> 11286.572 | O18: =+Clinix!O18+'al-fatah'!O18+khan!O18+top!O18+mrwa!O18+saad!O18+cant!O18+HRMN!O18+Ghani!O18+Mehaj!O18 -> 369.94876 | P18: =M18+N18+O18 -> 74359.701 | T18: =+mrwa!A5 -> Customer Name : Marwa Mart | U18: =+mrwa!P35 -> 0
A19: BCNJ | B19: =VLOOKUP($A19,'[1]Cust. Price List'!$D$6:$O$14,2,0) -> Meat Masala (Jumbo) | C19: =VLOOKUP(B19,'[1]Cust. Price List'!E9:P17,2,0) -> 120 | D19: =VLOOKUP(A19,'[1]Cust. Price List'!D9:M17,4,0) -> 40 | E19: =VLOOKUP(A19,'[1]Cust. Price List'!D9:M17,6,0) -> 90 | F19: =VLOOKUP(A19,'[1]Cust. Price List'!D9:M17,10,0) -> 72.64 | H19: =+Clinix!H19+'al-fatah'!H19+khan!H19+top!H19+mrwa!H19+saad!H19+cant!H19+HRMN!H19+Ghani!H19+Mehaj!H19+Bravo!H19+'786'!H19 -> 2040 | I19: =(G19*D19)*F19+H19*F19 -> 148185.6 | J19: =+Clinix!J19+'al-fatah'!J19+khan!J19+top!J19+mrwa!J19+saad!J19+cant!J19+HRMN!J19+Ghani!J19+Mehaj!J19+Bravo!J19+'786'!J19 -> 0 | K19: =+Clinix!K19+'al-fatah'!K19+khan!K19+top!K19+mrwa!K19+saad!K19+cant!K19+HRMN!K19+Ghani!K19+Mehaj!K19 -> 0 | L19: =+Clinix!L19+'al-fatah'!L19+khan!L19+top!L19+mrwa!L19+saad!L19+cant!L19+HRMN!L19+Ghani!L19+Mehaj!L19 -> 25627.392 | M19: =I19-K19-L19 -> 122558.21 | N19: =+Clinix!N19+'al-fatah'!N19+khan!N19+top!N19+mrwa!N19+saad!N19+cant!N19+HRMN!N19+Ghani!N19+Mehaj!N19 -> 22060.477 | O19: =+Clinix!O19+'al-fatah'!O19+khan!O19+top!O19+mrwa!O19+saad!O19+cant!O19+HRMN!O19+Ghani!O19+Mehaj!O19 -> 723.09343 | P19: =M19+N19+O19 -> 145341.78 | T19: =+saad!A5 -> Customer Name : Saad Mart | U19: =+saad!P35 -> 0
A20: VTNJ | B20: =VLOOKUP($A20,'[1]Cust. Price List'!$D$6:$O$14,2,0) -> Lemon Tarka (Jumbo) | C20: =VLOOKUP(B20,'[1]Cust. Price List'!E10:P18,2,0) -> 120 | D20: =VLOOKUP(A20,'[1]Cust. Price List'!D10:M18,4,0) -> 40 | E20: =VLOOKUP(A20,'[1]Cust. Price List'!D10:M18,6,0) -> 90 | F20: =VLOOKUP(A20,'[1]Cust. Price List'!D10:M18,10,0) -> 72.64 | H20: =+Clinix!H20+'al-fatah'!H20+khan!H20+top!H20+mrwa!H20+saad!H20+cant!H20+HRMN!H20+Ghani!H20+Mehaj!H20+Bravo!H20+'786'!H20 -> 1440 | I20: =(G20*D20)*F20+H20*F20 -> 104601.6 | J20: =+Clinix!J20+'al-fatah'!J20+khan!J20+top!J20+mrwa!J20+saad!J20+cant!J20+HRMN!J20+Ghani!J20+Mehaj!J20+Bravo!J20+'786'!J20 -> 0 | K20: =+Clinix!K20+'al-fatah'!K20+khan!K20+top!K20+mrwa!K20+saad!K20+cant!K20+HRMN!K20+Ghani!K20+Mehaj!K20 -> 0 | L20: =+Clinix!L20+'al-fatah'!L20+khan!L20+top!L20+mrwa!L20+saad!L20+cant!L20+HRMN!L20+Ghani!L20+Mehaj!L20 -> 17782.272 | M20: =I20-K20-L20 -> 86819.328 | N20: =+Clinix!N20+'al-fatah'!N20+khan!N20+top!N20+mrwa!N20+saad!N20+cant!N20+HRMN!N20+Ghani!N20+Mehaj!N20 -> 15627.479 | O20: =+Clinix!O20+'al-fatah'!O20+khan!O20+top!O20+mrwa!O20+saad!O20+cant!O20+HRMN!O20+Ghani!O20+Mehaj!O20 -> 512.23404 | P20: =M20+N20+O20 -> 102959.04 | T20: =+cant!A5 -> Customer Name : | U20: =+cant!P35 -> 0
A21: CCNJ | B21: =VLOOKUP($A21,'[1]Cust. Price List'!$D$6:$O$14,2,0) -> Chicken Chatkhara (Jumbo) | C21: =VLOOKUP(B21,'[1]Cust. Price List'!E11:P19,2,0) -> 120 | D21: =VLOOKUP(A21,'[1]Cust. Price List'!D11:M19,4,0) -> 40 | E21: =VLOOKUP(A21,'[1]Cust. Price List'!D11:M19,6,0) -> 90 | F21: =VLOOKUP(A21,'[1]Cust. Price List'!D11:M19,10,0) -> 72.64 | H21: =+Clinix!H21+'al-fatah'!H21+khan!H21+top!H21+mrwa!H21+saad!H21+cant!H21+HRMN!H21+Ghani!H21+Mehaj!H21+Bravo!H21+'786'!H21 -> 1800 | I21: =(G21*D21)*F21+H21*F21 -> 130752 | J21: =+Clinix!J21+'al-fatah'!J21+khan!J21+top!J21+mrwa!J21+saad!J21+cant!J21+HRMN!J21+Ghani!J21+Mehaj!J21+Bravo!J21+'786'!J21 -> 0 | K21: =+Clinix!K21+'al-fatah'!K21+khan!K21+top!K21+mrwa!K21+saad!K21+cant!K21+HRMN!K21+Ghani!K21+Mehaj!K21 -> 0 | L21: =+Clinix!L21+'al-fatah'!L21+khan!L21+top!L21+mrwa!L21+saad!L21+cant!L21+HRMN!L21+Ghani!L21+Mehaj!L21 -> 20920.32 | M21: =I21-K21-L21 -> 109831.68 | N21: =+Clinix!N21+'al-fatah'!N21+khan!N21+top!N21+mrwa!N21+saad!N21+cant!N21+HRMN!N21+Ghani!N21+Mehaj!N21 -> 19769.702 | O21: =+Clinix!O21+'al-fatah'!O21+khan!O21+top!O21+mrwa!O21+saad!O21+cant!O21+HRMN!O21+Ghani!O21+Mehaj!O21 -> 648.00691 | P21: =M21+N21+O21 -> 130249.39 | T21: =+HRMN!A5 -> Customer Name : | U21: =+HRMN!P35 -> 0
A22: CCE | B22: =VLOOKUP($A22,'[1]Cust. Price List'!$D$6:$O$14,2,0) -> Chicken Chatkhara (ECO) | C22: =VLOOKUP(B22,'[1]Cust. Price List'!E12:P20,2,0) -> 60 | D22: =VLOOKUP(A22,'[1]Cust. Price List'!D12:M20,4,0) -> 40 | E22: =VLOOKUP(A22,'[1]Cust. Price List'!D12:M20,6,0) -> 50 | F22: =VLOOKUP(A22,'[1]Cust. Price List'!D12:M20,10,0) -> 39.23 | H22: =+Clinix!H22+'al-fatah'!H22+khan!H22+top!H22+mrwa!H22+saad!H22+cant!H22+HRMN!H22+Ghani!H22+Mehaj!H22+Bravo!H22+'786'!H22 -> 0 | I22: =(G22*D22)*F22+H22*F22 -> 0 | J22: =+Clinix!J22+'al-fatah'!J22+khan!J22+top!J22+mrwa!J22+saad!J22+cant!J22+HRMN!J22+Ghani!J22+Mehaj!J22+Bravo!J22+'786'!J22 -> 0 | K22: =+Clinix!K22+'al-fatah'!K22+khan!K22+top!K22+mrwa!K22+saad!K22+cant!K22+HRMN!K22+Ghani!K22+Mehaj!K22 -> 0 | L22: =+Clinix!L22+'al-fatah'!L22+khan!L22+top!L22+mrwa!L22+saad!L22+cant!L22+HRMN!L22+Ghani!L22+Mehaj!L22 -> 0 | M22: =I22-K22-L22 -> 0 | N22: =+Clinix!N22+'al-fatah'!N22+khan!N22+top!N22+mrwa!N22+saad!N22+cant!N22+HRMN!N22+Ghani!N22+Mehaj!N22 -> 0 | O22: =+Clinix!O22+'al-fatah'!O22+khan!O22+top!O22+mrwa!O22+saad!O22+cant!O22+HRMN!O22+Ghani!O22+Mehaj!O22 -> 0 | P22: =M22+N22+O22 -> 0 | T22: =+Ghani!A5 -> Customer Name : | U22: =+Ghani!P35 -> 0
A23: VTE | B23: =VLOOKUP($A23,'[1]Cust. Price List'!$D$6:$O$14,2,0) -> Lemon Tarka (ECO) | C23: =VLOOKUP(B23,'[1]Cust. Price List'!E13:P21,2,0) -> 60 | D23: =VLOOKUP(A23,'[1]Cust. Price List'!D13:M21,4,0) -> 40 | E23: =VLOOKUP(A23,'[1]Cust. Price List'!D13:M21,6,0) -> 50 | F23: =VLOOKUP(A23,'[1]Cust. Price List'!D13:M21,10,0) -> 39.23 | H23: =+Clinix!H23+'al-fatah'!H23+khan!H23+top!H23+mrwa!H23+saad!H23+cant!H23+HRMN!H23+Ghani!H23+Mehaj!H23+Bravo!H23+'786'!H23 -> 0 | I23: =(G23*D23)*F23+H23*F23 -> 0 | J23: =+Clinix!J23+'al-fatah'!J23+khan!J23+top!J23+mrwa!J23+saad!J23+cant!J23+HRMN!J23+Ghani!J23+Mehaj!J23+Bravo!J23+'786'!J23 -> 0 | K23: =+Clinix!K23+'al-fatah'!K23+khan!K23+top!K23+mrwa!K23+saad!K23+cant!K23+HRMN!K23+Ghani!K23+Mehaj!K23 -> 0 | L23: =+Clinix!L23+'al-fatah'!L23+khan!L23+top!L23+mrwa!L23+saad!L23+cant!L23+HRMN!L23+Ghani!L23+Mehaj!L23 -> 0 | M23: =I23-K23-L23 -> 0 | N23: =+Clinix!N23+'al-fatah'!N23+khan!N23+top!N23+mrwa!N23+saad!N23+cant!N23+HRMN!N23+Ghani!N23+Mehaj!N23 -> 0 | O23: =+Clinix!O23+'al-fatah'!O23+khan!O23+top!O23+mrwa!O23+saad!O23+cant!O23+HRMN!O23+Ghani!O23+Mehaj!O23 -> 0 | P23: =M23+N23+O23 -> 0 | T23: =+Mehaj!A5 -> Customer Name : | U23: =+Mehaj!P35 -> 0
A24: BCE | B24: =VLOOKUP($A24,'[1]Cust. Price List'!$D$6:$O$14,2,0) -> Meat Masala (ECO) | C24: =VLOOKUP(B24,'[1]Cust. Price List'!E14:P22,2,0) -> 60 | D24: =VLOOKUP(A24,'[1]Cust. Price List'!D14:M22,4,0) -> 40 | E24: =VLOOKUP(A24,'[1]Cust. Price List'!D14:M22,6,0) -> 50 | F24: =VLOOKUP(A24,'[1]Cust. Price List'!D14:M22,10,0) -> 39.23 | H24: =+Clinix!H24+'al-fatah'!H24+khan!H24+top!H24+mrwa!H24+saad!H24+cant!H24+HRMN!H24+Ghani!H24+Mehaj!H24+Bravo!H24+'786'!H24 -> 0 | I24: =(G24*D24)*F24+H24*F24 -> 0 | J24: =+Clinix!J24+'al-fatah'!J24+khan!J24+top!J24+mrwa!J24+saad!J24+cant!J24+HRMN!J24+Ghani!J24+Mehaj!J24+Bravo!J24+'786'!J24 -> 0 | K24: =+Clinix!K24+'al-fatah'!K24+khan!K24+top!K24+mrwa!K24+saad!K24+cant!K24+HRMN!K24+Ghani!K24+Mehaj!K24 -> 0 | L24: =+Clinix!L24+'al-fatah'!L24+khan!L24+top!L24+mrwa!L24+saad!L24+cant!L24+HRMN!L24+Ghani!L24+Mehaj!L24 -> 0 | M24: =I24-K24-L24 -> 0 | N24: =+Clinix!N24+'al-fatah'!N24+khan!N24+top!N24+mrwa!N24+saad!N24+cant!N24+HRMN!N24+Ghani!N24+Mehaj!N24 -> 0 | O24: =+Clinix!O24+'al-fatah'!O24+khan!O24+top!O24+mrwa!O24+saad!O24+cant!O24+HRMN!O24+Ghani!O24+Mehaj!O24 -> 0 | P24: =M24+N24+O24 -> 0 | T24: =+Bravo!A5 -> Customer Name : | U24: =+Bravo!P35 -> 0
A25: Total | G25: =SUM(G16:G24) -> 0 | H25: =SUM(H16:H24) -> 8400 | I25: =SUM(I16:I24) -> 547222.2 | J25: =SUM(J16:J24) -> 0 | K25: =SUM(K16:K24) -> 0 | L25: =SUM(L16:L24) -> 91526.544 | M25: =SUM(M16:M24) -> 455695.66 | N25: =SUM(N16:N24) -> 82025.218 | ... P25: =SUM(P16:P24) -> 540409.48 | T25: =+'786'!A5 -> Customer Name : | U25: =+'786'!P35 -> 0
T26: Total | U26: =SUM(U14:U25) -> 540409.48
B28: یکم جولائی 2024سے نئی ٹیکس ترمیم کے مطابق، ایف بی آر سیکشن 236 ایچ کے مطابق، فائلرز کے لیے ہر سیل انوائس پر 0.5% اور نان فائلرز کے لیے 2.5% ایڈوانس ود ہولڈنگ ٹیکس وصول کیا جائے گا۔ | N28: Gross Amount: | P28: =I25 -> 547222.2
N29: Regular Discount | P29: =L25 -> 91526.544
N30: Trade Offre | P30: =K25 -> 0
N31: After Dis. Amount | P31: =P28-P29-P30 -> 455695.66
N32: Total GST: | O32: =IF(B12="Registered",18%,22%) -> 0.22 | P32: =N25 -> 82025.218
N33: Net Amount: | P33: =P31+P32 -> 537720.87
N34: Ad.Tax | O34: =IF(B11="Filer",0.5%,2.5%) -> 0.025 | P34: =O34*P33 -> 13443.022
N35: Net Amount with Ad.Tax | P35: =P33+P34 -> 551163.9
B36: Delivered By

Sheet Clinix
A2: Elite MARKETING
A3: 44A- Gulberg Lahore | K3: Invoice No # : | N3: 1 | XFC3: Filer | XFD3: 0.005
A4: STRN / NTN :3808207-1 | K4: Date/Day : | N4: =TODAY() -> 46188 | XFC4: Non-filer | XFD4: 0.025
A5: Customer Name : Clinix Central Warehouse | K5: Order Date : | N5: =N4-1 -> 46187
A6: Address: S-94-R 153,E, Main Multan Road Lahore | K6: Order Name : | N6: Shakoor | XFC6: Registered | XFD6: 0.18
XFC7: Un-registered | XFD7: 0.22
XFD9: Yes
A10: NTN/CNIC Number: | B10: 0150979-9 | K10: Invoice Status : | N10: Serviced | XFD10: No
B11: Filer | C11: =IF($O34>2.49%,"No","Yes") -> Yes | K11: Order at Original Location : | N11: Yes
A12: STRN Number: | B12: Registered | C12: =IF($O32>21.99%,"No","Yes") -> Yes | K12: Reference Invoice : | XFD12: Monday/Tuesday
B13: 3520247902365 | L13: 0.05 | XFD13: Tuesday / Wednesday
A14: Product Code/Description | C14: GM/ Pack | D14: CTN | E14: R.P Per | F14: T.P Per | G14: Sale QTY | I14: Gross Amount Excl. Taxes | J14: Trade Offer & Discount | M14: After Discount Amount | N14: GST | O14: Adv. Tax 236H | P14: Invoice | XFD14: Wednesday/Thursday
D15: SIZE | E15: Unit | F15: Unit | G15: CTN | H15: Pack | J15: FOC Qty | K15: Trade Offer | L15: Pass On | N15: =IF(B12="Registered",18%,22%) -> 0.18 | O15: =IF(B11="Filer",0.5%,2.5%) -> 0.005 | P15: Amount | XFD15: Thursday /Friday
A16: BCN | B16: =VLOOKUP($A16,'[1]Cust. Price List'!$D$6:$O$14,2,0) -> Meat Masala | C16: =VLOOKUP(A16,'[1]Cust. Price List'!D6:M14,3,0) -> 70 | D16: =VLOOKUP(A16,'[1]Cust. Price List'!D6:M14,4,0) -> 40 | E16: =VLOOKUP(A16,'[1]Cust. Price List'!D6:M14,6,0) -> 65 | F16: =VLOOKUP(A16,'[1]Cust. Price List'!D6:M14,10,0) -> 52.4625 | H16: 240 | I16: =(G16*D16)*F16+H16*F16 -> 12591 | K16: =I16*$K$13 -> 0 | L16: =I16*12% -> 1510.92 | M16: =I16-K16-L16 -> 11080.08 | N16: =(M16*$N$15)+(J16*F16)*$N$15 -> 1994.4144 | O16: =(N16+M16)*$O$15 -> 65.372472 | P16: =M16+N16+O16 -> 13139.867 | XFD16: Friday / Saturday
A17: VTN | B17: =VLOOKUP($A17,'[1]Cust. Price List'!$D$6:$O$14,2,0) -> Lemon Tarka | C17: =VLOOKUP(B17,'[1]Cust. Price List'!E7:P15,2,0) -> 70 | D17: =VLOOKUP(A17,'[1]Cust. Price List'!D7:M15,4,0) -> 40 | E17: =VLOOKUP(A17,'[1]Cust. Price List'!D7:M15,6,0) -> 65 | F17: =VLOOKUP(A17,'[1]Cust. Price List'!D7:M15,10,0) -> 52.4625 | H17: 240 | I17: =(G17*D17)*F17+H17*F17 -> 12591 | K17: =I17*$K$13 -> 0 | L17: =I17*12% -> 1510.92 | M17: =I17-K17-L17 -> 11080.08 | N17: =(M17*$N$15)+(J17*F17)*$N$15 -> 1994.4144 | O17: =(N17+M17)*$O$15 -> 65.372472 | P17: =M17+N17+O17 -> 13139.867 | XFD17: Saturday /Monday
A18: CCN | B18: =VLOOKUP($A18,'[1]Cust. Price List'!$D$6:$O$14,2,0) -> Chicken Chatkhara | C18: =VLOOKUP(B18,'[1]Cust. Price List'!E8:P16,2,0) -> 70 | D18: =VLOOKUP(A18,'[1]Cust. Price List'!D8:M16,4,0) -> 40 | E18: =VLOOKUP(A18,'[1]Cust. Price List'!D8:M16,6,0) -> 65 | F18: =VLOOKUP(A18,'[1]Cust. Price List'!D8:M16,10,0) -> 52.4625 | H18: 240 | I18: =(G18*D18)*F18+H18*F18 -> 12591 | K18: =I18*$K$13 -> 0 | L18: =I18*12% -> 1510.92 | M18: =I18-K18-L18 -> 11080.08 | N18: =(M18*$N$15)+(J18*F18)*$N$15 -> 1994.4144 | O18: =(N18+M18)*$O$15 -> 65.372472 | P18: =M18+N18+O18 -> 13139.867
A19: BCNJ | B19: =VLOOKUP($A19,'[1]Cust. Price List'!$D$6:$O$14,2,0) -> Meat Masala (Jumbo) | C19: =VLOOKUP(B19,'[1]Cust. Price List'!E9:P17,2,0) -> 120 | D19: =VLOOKUP(A19,'[1]Cust. Price List'!D9:M17,4,0) -> 40 | E19: =VLOOKUP(A19,'[1]Cust. Price List'!D9:M17,6,0) -> 90 | F19: =VLOOKUP(A19,'[1]Cust. Price List'!D9:M17,10,0) -> 72.64 | H19: 240 | I19: =(G19*D19)*F19+H19*F19 -> 17433.6 | K19: =I19*$K$13 -> 0 | L19: =I19*12% -> 2092.032 | M19: =I19-K19-L19 -> 15341.568 | N19: =(M19*$N$15)+(J19*F19)*$N$15 -> 2761.4822 | O19: =(N19+M19)*$O$15 -> 90.515251 | P19: =M19+N19+O19 -> 18193.565
A20: VTNJ | B20: =VLOOKUP($A20,'[1]Cust. Price List'!$D$6:$O$14,2,0) -> Lemon Tarka (Jumbo) | C20: =VLOOKUP(B20,'[1]Cust. Price List'!E10:P18,2,0) -> 120 | D20: =VLOOKUP(A20,'[1]Cust. Price List'!D10:M18,4,0) -> 40 | E20: =VLOOKUP(A20,'[1]Cust. Price List'!D10:M18,6,0) -> 90 | F20: =VLOOKUP(A20,'[1]Cust. Price List'!D10:M18,10,0) -> 72.64 | H20: 240 | I20: =(G20*D20)*F20+H20*F20 -> 17433.6 | K20: =I20*$K$13 -> 0 | L20: =I20*12% -> 2092.032 | M20: =I20-K20-L20 -> 15341.568 | N20: =(M20*$N$15)+(J20*F20)*$N$15 -> 2761.4822 | O20: =(N20+M20)*$O$15 -> 90.515251 | P20: =M20+N20+O20 -> 18193.565
A21: CCNJ | B21: =VLOOKUP($A21,'[1]Cust. Price List'!$D$6:$O$14,2,0) -> Chicken Chatkhara (Jumbo) | C21: =VLOOKUP(B21,'[1]Cust. Price List'!E11:P19,2,0) -> 120 | D21: =VLOOKUP(A21,'[1]Cust. Price List'!D11:M19,4,0) -> 40 | E21: =VLOOKUP(A21,'[1]Cust. Price List'!D11:M19,6,0) -> 90 | F21: =VLOOKUP(A21,'[1]Cust. Price List'!D11:M19,10,0) -> 72.64 | H21: 600 | I21: =(G21*D21)*F21+H21*F21 -> 43584 | K21: =I21*$K$13 -> 0 | L21: =I21*12% -> 5230.08 | M21: =I21-K21-L21 -> 38353.92 | N21: =(M21*$N$15)+(J21*F21)*$N$15 -> 6903.7056 | O21: =(N21+M21)*$O$15 -> 226.28813 | P21: =M21+N21+O21 -> 45483.914
A22: CCE | B22: =VLOOKUP($A22,'[1]Cust. Price List'!$D$6:$O$14,2,0) -> Chicken Chatkhara (ECO) | C22: =VLOOKUP(B22,'[1]Cust. Price List'!E12:P20,2,0) -> 60 | D22: =VLOOKUP(A22,'[1]Cust. Price List'!D12:M20,4,0) -> 40 | E22: =VLOOKUP(A22,'[1]Cust. Price List'!D12:M20,6,0) -> 50 | F22: =VLOOKUP(A22,'[1]Cust. Price List'!D12:M20,10,0) -> 39.23 | I22: =(G22*D22)*F22+H22*F22 -> 0 | K22: =I22*3.5% -> 0 | L22: =I22*12% -> 0 | M22: =I22-K22-L22 -> 0 | N22: =(M22*$N$15)+(J22*F22)*$N$15 -> 0 | O22: =(N22+M22)*$O$15 -> 0 | P22: =M22+N22+O22 -> 0 | Q22: =H25/40 -> 45
A23: VTE | B23: =VLOOKUP($A23,'[1]Cust. Price List'!$D$6:$O$14,2,0) -> Lemon Tarka (ECO) | C23: =VLOOKUP(B23,'[1]Cust. Price List'!E13:P21,2,0) -> 60 | D23: =VLOOKUP(A23,'[1]Cust. Price List'!D13:M21,4,0) -> 40 | E23: =VLOOKUP(A23,'[1]Cust. Price List'!D13:M21,6,0) -> 50 | F23: =VLOOKUP(A23,'[1]Cust. Price List'!D13:M21,10,0) -> 39.23 | I23: =(G23*D23)*F23+H23*F23 -> 0 | K23: =I23*3.5% -> 0 | L23: =I23*$L$13 -> 0 | M23: =I23-K23-L23 -> 0 | N23: =(M23*$N$15)+(J23*F23)*$N$15 -> 0 | O23: =(N23+M23)*$O$15 -> 0 | P23: =M23+N23+O23 -> 0
A24: BCE | B24: =VLOOKUP($A24,'[1]Cust. Price List'!$D$6:$O$14,2,0) -> Meat Masala (ECO) | C24: =VLOOKUP(B24,'[1]Cust. Price List'!E14:P22,2,0) -> 60 | D24: =VLOOKUP(A24,'[1]Cust. Price List'!D14:M22,4,0) -> 40 | E24: =VLOOKUP(A24,'[1]Cust. Price List'!D14:M22,6,0) -> 50 | F24: =VLOOKUP(A24,'[1]Cust. Price List'!D14:M22,10,0) -> 39.23 | I24: =(G24*D24)*F24+H24*F24 -> 0 | K24: =I24*3.5% -> 0 | L24: =I24*$L$13 -> 0 | M24: =I24-K24-L24 -> 0 | N24: =(M24*$N$15)+(J24*F24)*$N$15 -> 0 | O24: =(N24+M24)*$O$15 -> 0 | P24: =M24+N24+O24 -> 0
A25: Total | G25: =SUM(G16:G24) -> 0 | H25: =SUM(H16:H24) -> 1800 | I25: =SUM(I16:I24) -> 116224.2 | K25: =SUM(K16:K24) -> 0 | L25: =SUM(L16:L24) -> 13946.904 | M25: =SUM(M16:M24) -> 102277.3 | N25: =SUM(N16:N24) -> 18409.913 | O25: =SUM(O16:O24) -> 603.43605 | P25: =SUM(P16:P24) -> 121290.65
B28: یکم جولائی 2024سے نئی ٹیکس ترمیم کے مطابق، ایف بی آر سیکشن 236 ایچ کے مطابق، فائلرز کے لیے ہر سیل انوائس پر 0.5% اور نان فائلرز کے لیے 2.5% ایڈوانس ود ہولڈنگ ٹیکس وصول کیا جائے گا۔ | N28: Gross Amount: | P28: =I25 -> 116224.2
N29: Regular Discount | P29: =L25 -> 13946.904
N30: Trade Offre | P30: =K25 -> 0
N31: After Dis. Amount | P31: =P28-P29-P30 -> 102277.3
N32: Total GST: | O32: =IF(B12="Registered",18%,22%) -> 0.18 | P32: =N25 -> 18409.913
N33: Net Amount: | P33: =P31+P32 -> 120687.21
N34: Ad.Tax | O34: =IF(B11="Filer",0.5%,2.5%) -> 0.005 | P34: =O34*P33 -> 603.43605
N35: Net Amount with Ad.Tax | P35: =P33+P34 -> 121290.65
B36: Delivered By

Sheet al-fatah
A2: Elite MARKETING
A3: 44A- Gulberg Lahore | K3: Invoice No # : | N3: 2 | XFC3: Filer | XFD3: 0.005
A4: STRN / NTN :3808207-1 | K4: Date/Day : | N4: =TODAY() -> 46188 | XFC4: Non-filer | XFD4: 0.025
A5: Customer Name : Al-Fatah Shoping Mall | K5: Order Date : | N5: =N4-1 -> 46187
A6: Address: Attari Darbaar | K6: Order Name : | N6: Shakoor | XFC6: Registered | XFD6: 0.18
XFC7: Un-registered | XFD7: 0.22
XFD9: Yes
A10: NTN/CNIC Number: | B10: 4269497-3 | K10: Invoice Status : | N10: Serviced | XFD10: No
B11: Filer | C11: =IF($O34>2.49%,"No","Yes") -> Yes | K11: Order at Original Location : | N11: Yes
A12: STRN Number: | B12: Registered | C12: =IF($O32>21.99%,"No","Yes") -> Yes | K12: Reference Invoice : | XFD12: Monday/Tuesday
B13: 300426949714 | L13: 0.05 | XFD13: Tuesday / Wednesday
A14: Product Code/Description | C14: GM/ Pack | D14: CTN | E14: R.P Per | F14: T.P Per | G14: Sale QTY | I14: Gross Amount Excl. Taxes | J14: Trade Offer & Discount | M14: After Discount Amount | N14: GST | O14: Adv. Tax 236H | P14: Invoice | XFD14: Wednesday/Thursday
D15: SIZE | E15: Unit | F15: Unit | G15: CTN | H15: Pack | J15: FOC Qty | K15: Trade Offer | L15: Pass On | N15: =IF(B12="Registered",18%,22%) -> 0.18 | O15: =IF(B11="Filer",0.5%,2.5%) -> 0.005 | P15: Amount | XFD15: Thursday /Friday
A16: BCN | B16: =VLOOKUP($A16,'[1]Cust. Price List'!$D$6:$O$14,2,0) -> Meat Masala | C16: =VLOOKUP(A16,'[1]Cust. Price List'!D6:M14,3,0) -> 70 | D16: =VLOOKUP(A16,'[1]Cust. Price List'!D6:M14,4,0) -> 40 | E16: =VLOOKUP(A16,'[1]Cust. Price List'!D6:M14,6,0) -> 65 | F16: =VLOOKUP(A16,'[1]Cust. Price List'!D6:M14,10,0) -> 52.4625 | H16: 600 | I16: =(G16*D16)*F16+H16*F16 -> 31477.5 | K16: =I16*$K$13 -> 0 | L16: =I16*18% -> 5665.95 | M16: =I16-K16-L16 -> 25811.55 | N16: =(M16*$N$15)+(J16*F16)*$N$15 -> 4646.079 | O16: =(N16+M16)*$O$15 -> 152.28815 | P16: =M16+N16+O16 -> 30609.917 | XFD16: Friday / Saturday
A17: VTN | B17: =VLOOKUP($A17,'[1]Cust. Price List'!$D$6:$O$14,2,0) -> Lemon Tarka | C17: =VLOOKUP(B17,'[1]Cust. Price List'!E7:P15,2,0) -> 70 | D17: =VLOOKUP(A17,'[1]Cust. Price List'!D7:M15,4,0) -> 40 | E17: =VLOOKUP(A17,'[1]Cust. Price List'!D7:M15,6,0) -> 65 | F17: =VLOOKUP(A17,'[1]Cust. Price List'!D7:M15,10,0) -> 52.4625 | H17: 600 | I17: =(G17*D17)*F17+H17*F17 -> 31477.5 | K17: =I17*$K$13 -> 0 | L17: =I17*18% -> 5665.95 | M17: =I17-K17-L17 -> 25811.55 | N17: =(M17*$N$15)+(J17*F17)*$N$15 -> 4646.079 | O17: =(N17+M17)*$O$15 -> 152.28815 | P17: =M17+N17+O17 -> 30609.917 | XFD17: Saturday /Monday
A18: CCN | B18: =VLOOKUP($A18,'[1]Cust. Price List'!$D$6:$O$14,2,0) -> Chicken Chatkhara | C18: =VLOOKUP(B18,'[1]Cust. Price List'!E8:P16,2,0) -> 70 | D18: =VLOOKUP(A18,'[1]Cust. Price List'!D8:M16,4,0) -> 40 | E18: =VLOOKUP(A18,'[1]Cust. Price List'!D8:M16,6,0) -> 65 | F18: =VLOOKUP(A18,'[1]Cust. Price List'!D8:M16,10,0) -> 52.4625 | H18: 1200 | I18: =(G18*D18)*F18+H18*F18 -> 62955 | K18: =I18*$K$13 -> 0 | L18: =I18*18% -> 11331.9 | M18: =I18-K18-L18 -> 51623.1 | N18: =(M18*$N$15)+(J18*F18)*$N$15 -> 9292.158 | O18: =(N18+M18)*$O$15 -> 304.57629 | P18: =M18+N18+O18 -> 61219.834 | R18: =H25/40 -> 165
A19: BCNJ | B19: =VLOOKUP($A19,'[1]Cust. Price List'!$D$6:$O$14,2,0) -> Meat Masala (Jumbo) | C19: =VLOOKUP(B19,'[1]Cust. Price List'!E9:P17,2,0) -> 120 | D19: =VLOOKUP(A19,'[1]Cust. Price List'!D9:M17,4,0) -> 40 | E19: =VLOOKUP(A19,'[1]Cust. Price List'!D9:M17,6,0) -> 90 | F19: =VLOOKUP(A19,'[1]Cust. Price List'!D9:M17,10,0) -> 72.64 | H19: 1800 | I19: =(G19*D19)*F19+H19*F19 -> 130752 | K19: =I19*$K$13 -> 0 | L19: =I19*18% -> 23535.36 | M19: =I19-K19-L19 -> 107216.64 | N19: =(M19*$N$15)+(J19*F19)*$N$15 -> 19298.995 | O19: =(N19+M19)*$O$15 -> 632.57818 | P19: =M19+N19+O19 -> 127148.21
A20: VTNJ | B20: =VLOOKUP($A20,'[1]Cust. Price List'!$D$6:$O$14,2,0) -> Lemon Tarka (Jumbo) | C20: =VLOOKUP(B20,'[1]Cust. Price List'!E10:P18,2,0) -> 120 | D20: =VLOOKUP(A20,'[1]Cust. Price List'!D10:M18,4,0) -> 40 | E20: =VLOOKUP(A20,'[1]Cust. Price List'!D10:M18,6,0) -> 90 | F20: =VLOOKUP(A20,'[1]Cust. Price List'!D10:M18,10,0) -> 72.64 | H20: 1200 | I20: =(G20*D20)*F20+H20*F20 -> 87168 | K20: =I20*$K$13 -> 0 | L20: =I20*18% -> 15690.24 | M20: =I20-K20-L20 -> 71477.76 | N20: =(M20*$N$15)+(J20*F20)*$N$15 -> 12865.997 | O20: =(N20+M20)*$O$15 -> 421.71878 | P20: =M20+N20+O20 -> 84765.476
A21: CCNJ | B21: =VLOOKUP($A21,'[1]Cust. Price List'!$D$6:$O$14,2,0) -> Chicken Chatkhara (Jumbo) | C21: =VLOOKUP(B21,'[1]Cust. Price List'!E11:P19,2,0) -> 120 | D21: =VLOOKUP(A21,'[1]Cust. Price List'!D11:M19,4,0) -> 40 | E21: =VLOOKUP(A21,'[1]Cust. Price List'!D11:M19,6,0) -> 90 | F21: =VLOOKUP(A21,'[1]Cust. Price List'!D11:M19,10,0) -> 72.64 | H21: 1200 | I21: =(G21*D21)*F21+H21*F21 -> 87168 | K21: =I21*$K$13 -> 0 | L21: =I21*18% -> 15690.24 | M21: =I21-K21-L21 -> 71477.76 | N21: =(M21*$N$15)+(J21*F21)*$N$15 -> 12865.997 | O21: =(N21+M21)*$O$15 -> 421.71878 | P21: =M21+N21+O21 -> 84765.476
A22: CCE | B22: =VLOOKUP($A22,'[1]Cust. Price List'!$D$6:$O$14,2,0) -> Chicken Chatkhara (ECO) | C22: =VLOOKUP(B22,'[1]Cust. Price List'!E12:P20,2,0) -> 60 | D22: =VLOOKUP(A22,'[1]Cust. Price List'!D12:M20,4,0) -> 40 | E22: =VLOOKUP(A22,'[1]Cust. Price List'!D12:M20,6,0) -> 50 | F22: =VLOOKUP(A22,'[1]Cust. Price List'!D12:M20,10,0) -> 39.23 | I22: =(G22*D22)*F22+H22*F22 -> 0 | K22: =I22*3.5% -> 0 | L22: =I22*18% -> 0 | M22: =I22-K22-L22 -> 0 | N22: =(M22*$N$15)+(J22*F22)*$N$15 -> 0 | O22: =(N22+M22)*$O$15 -> 0 | P22: =M22+N22+O22 -> 0
A23: VTE | B23: =VLOOKUP($A23,'[1]Cust. Price List'!$D$6:$O$14,2,0) -> Lemon Tarka (ECO) | C23: =VLOOKUP(B23,'[1]Cust. Price List'!E13:P21,2,0) -> 60 | D23: =VLOOKUP(A23,'[1]Cust. Price List'!D13:M21,4,0) -> 40 | E23: =VLOOKUP(A23,'[1]Cust. Price List'!D13:M21,6,0) -> 50 | F23: =VLOOKUP(A23,'[1]Cust. Price List'!D13:M21,10,0) -> 39.23 | I23: =(G23*D23)*F23+H23*F23 -> 0 | K23: =I23*3.5% -> 0 | L23: =I23*18% -> 0 | M23: =I23-K23-L23 -> 0 | N23: =(M23*$N$15)+(J23*F23)*$N$15 -> 0 | O23: =(N23+M23)*$O$15 -> 0 | P23: =M23+N23+O23 -> 0
A24: BCE | B24: =VLOOKUP($A24,'[1]Cust. Price List'!$D$6:$O$14,2,0) -> Meat Masala (ECO) | C24: =VLOOKUP(B24,'[1]Cust. Price List'!E14:P22,2,0) -> 60 | D24: =VLOOKUP(A24,'[1]Cust. Price List'!D14:M22,4,0) -> 40 | E24: =VLOOKUP(A24,'[1]Cust. Price List'!D14:M22,6,0) -> 50 | F24: =VLOOKUP(A24,'[1]Cust. Price List'!D14:M22,10,0) -> 39.23 | I24: =(G24*D24)*F24+H24*F24 -> 0 | K24: =I24*3.5% -> 0 | L24: =I24*18% -> 0 | M24: =I24-K24-L24 -> 0 | N24: =(M24*$N$15)+(J24*F24)*$N$15 -> 0 | O24: =(N24+M24)*$O$15 -> 0 | P24: =M24+N24+O24 -> 0
A25: Total | G25: =SUM(G16:G24) -> 0 | H25: =SUM(H16:H24) -> 6600 | I25: =SUM(I16:I24) -> 430998 | K25: =SUM(K16:K24) -> 0 | L25: =SUM(L16:L24) -> 77579.64 | M25: =SUM(M16:M24) -> 353418.36 | N25: =SUM(N16:N24) -> 63615.305 | O25: =SUM(O16:O24) -> 2085.1683 | P25: =SUM(P16:P24) -> 419118.83
B28: یکم جولائی 2024سے نئی ٹیکس ترمیم کے مطابق، ایف بی آر سیکشن 236 ایچ کے مطابق، فائلرز کے لیے ہر سیل انوائس پر 0.5% اور نان فائلرز کے لیے 2.5% ایڈوانس ود ہولڈنگ ٹیکس وصول کیا جائے گا۔ | N28: Gross Amount: | P28: =I25 -> 430998
N29: Regular Discount | P29: =L25 -> 77579.64
N30: Trade Offre | P30: =K25 -> 0
N31: After Dis. Amount | P31: =P28-P29-P30 -> 353418.36
N32: Total GST: | O32: =IF(B12="Registered",18%,22%) -> 0.18 | P32: =N25 -> 63615.305
N33: Net Amount: | P33: =P31+P32 -> 417033.66
N34: Ad.Tax | O34: =IF(B11="Filer",0.5%,2.5%) -> 0.005 | P34: =O34*P33 -> 2085.1683
N35: Net Amount with Ad.Tax | P35: =P33+P34 -> 419118.83
B36: Delivered By

Sheet top
A2: Elite MARKETING
A3: 44A- Gulberg Lahore | K3: Invoice No # : | N3: 4 | XFC3: Filer | XFD3: 0.005
A4: STRN / NTN :3808207-1 | K4: Date/Day : | N4: =TODAY() -> 46188 | XFC4: Non-filer | XFD4: 0.025
A5: Customer Name : Top Bakers | K5: Order Date : | N5: =N4-1 -> 46187
A6: Address: Tajbagh | K6: Order Name : | N6: Mobeen Ahmad | XFC6: Registered | XFD6: 0.18
XFC7: Un-registered | XFD7: 0.22
XFD9: Yes
A10: NTN/CNIC Number: | K10: Invoice Status : | N10: Serviced | XFD10: No
B11: Non-filer | C11: =IF($O34>2.49%,"No","Yes") -> No | K11: Order at Original Location : | N11: Yes
A12: STRN Number: | B12: Un-registered | C12: =IF($O32>21.99%,"No","Yes") -> No | K12: Reference Invoice : | XFD12: Monday/Tuesday
L13: 0.05 | XFD13: Tuesday / Wednesday
A14: Product Code/Description | C14: GM/ Pack | D14: CTN | E14: R.P Per | F14: T.P Per | G14: Sale QTY | I14: Gross Amount Excl. Taxes | J14: Trade Offer & Discount | M14: After Discount Amount | N14: GST | O14: Adv. Tax 236H | P14: Invoice | XFD14: Wednesday/Thursday
D15: SIZE | E15: Unit | F15: Unit | G15: CTN | H15: Pack | J15: FOC Qty | K15: Trade Offer | L15: Pass On | N15: =IF(B12="Registered",18%,22%) -> 0.22 | O15: =IF(B11="Filer",0.5%,2.5%) -> 0.025 | P15: Amount | XFD15: Thursday /Friday
A16: BCN | B16: =VLOOKUP($A16,'[1]Cust. Price List'!$D$6:$O$14,2,0) -> Meat Masala | C16: =VLOOKUP(A16,'[1]Cust. Price List'!D6:M14,3,0) -> 70 | D16: =VLOOKUP(A16,'[1]Cust. Price List'!D6:M14,4,0) -> 40 | E16: =VLOOKUP(A16,'[1]Cust. Price List'!D6:M14,6,0) -> 65 | F16: =VLOOKUP(A16,'[1]Cust. Price List'!D6:M14,10,0) -> 52.4625 | I16: =(G16*D16)*F16+H16*F16 -> 0 | K16: =I16*$K$13 -> 0 | L16: =I16*8% -> 0 | M16: =I16-K16-L16 -> 0 | N16: =(M16*$N$15)+(J16*F16)*$N$15 -> 0 | O16: =(N16+M16)*$O$15 -> 0 | P16: =M16+N16+O16 -> 0 | XFD16: Friday / Saturday
A17: VTN | B17: =VLOOKUP($A17,'[1]Cust. Price List'!$D$6:$O$14,2,0) -> Lemon Tarka | C17: =VLOOKUP(B17,'[1]Cust. Price List'!E7:P15,2,0) -> 70 | D17: =VLOOKUP(A17,'[1]Cust. Price List'!D7:M15,4,0) -> 40 | E17: =VLOOKUP(A17,'[1]Cust. Price List'!D7:M15,6,0) -> 65 | F17: =VLOOKUP(A17,'[1]Cust. Price List'!D7:M15,10,0) -> 52.4625 | I17: =(G17*D17)*F17+H17*F17 -> 0 | K17: =I17*$K$13 -> 0 | L17: =I17*8% -> 0 | M17: =I17-K17-L17 -> 0 | N17: =(M17*$N$15)+(J17*F17)*$N$15 -> 0 | O17: =(N17+M17)*$O$15 -> 0 | P17: =M17+N17+O17 -> 0 | XFD17: Saturday /Monday
A18: CCN | B18: =VLOOKUP($A18,'[1]Cust. Price List'!$D$6:$O$14,2,0) -> Chicken Chatkhara | C18: =VLOOKUP(B18,'[1]Cust. Price List'!E8:P16,2,0) -> 70 | D18: =VLOOKUP(A18,'[1]Cust. Price List'!D8:M16,4,0) -> 40 | E18: =VLOOKUP(A18,'[1]Cust. Price List'!D8:M16,6,0) -> 65 | F18: =VLOOKUP(A18,'[1]Cust. Price List'!D8:M16,10,0) -> 52.4625 | I18: =(G18*D18)*F18+H18*F18 -> 0 | K18: =I18*$K$13 -> 0 | L18: =I18*8% -> 0 | M18: =I18-K18-L18 -> 0 | N18: =(M18*$N$15)+(J18*F18)*$N$15 -> 0 | O18: =(N18+M18)*$O$15 -> 0 | P18: =M18+N18+O18 -> 0
A19: BCNJ | B19: =VLOOKUP($A19,'[1]Cust. Price List'!$D$6:$O$14,2,0) -> Meat Masala (Jumbo) | C19: =VLOOKUP(B19,'[1]Cust. Price List'!E9:P17,2,0) -> 120 | D19: =VLOOKUP(A19,'[1]Cust. Price List'!D9:M17,4,0) -> 40 | E19: =VLOOKUP(A19,'[1]Cust. Price List'!D9:M17,6,0) -> 90 | F19: =VLOOKUP(A19,'[1]Cust. Price List'!D9:M17,10,0) -> 72.64 | I19: =(G19*D19)*F19+H19*F19 -> 0 | K19: =I19*$K$13 -> 0 | L19: =I19*8% -> 0 | M19: =I19-K19-L19 -> 0 | N19: =(M19*$N$15)+(J19*F19)*$N$15 -> 0 | O19: =(N19+M19)*$O$15 -> 0 | P19: =M19+N19+O19 -> 0
A20: VTNJ | B20: =VLOOKUP($A20,'[1]Cust. Price List'!$D$6:$O$14,2,0) -> Lemon Tarka (Jumbo) | C20: =VLOOKUP(B20,'[1]Cust. Price List'!E10:P18,2,0) -> 120 | D20: =VLOOKUP(A20,'[1]Cust. Price List'!D10:M18,4,0) -> 40 | E20: =VLOOKUP(A20,'[1]Cust. Price List'!D10:M18,6,0) -> 90 | F20: =VLOOKUP(A20,'[1]Cust. Price List'!D10:M18,10,0) -> 72.64 | I20: =(G20*D20)*F20+H20*F20 -> 0 | K20: =I20*$K$13 -> 0 | L20: =I20*8% -> 0 | M20: =I20-K20-L20 -> 0 | N20: =(M20*$N$15)+(J20*F20)*$N$15 -> 0 | O20: =(N20+M20)*$O$15 -> 0 | P20: =M20+N20+O20 -> 0
A21: CCNJ | B21: =VLOOKUP($A21,'[1]Cust. Price List'!$D$6:$O$14,2,0) -> Chicken Chatkhara (Jumbo) | C21: =VLOOKUP(B21,'[1]Cust. Price List'!E11:P19,2,0) -> 120 | D21: =VLOOKUP(A21,'[1]Cust. Price List'!D11:M19,4,0) -> 40 | E21: =VLOOKUP(A21,'[1]Cust. Price List'!D11:M19,6,0) -> 90 | F21: =VLOOKUP(A21,'[1]Cust. Price List'!D11:M19,10,0) -> 72.64 | I21: =(G21*D21)*F21+H21*F21 -> 0 | K21: =I21*$K$13 -> 0 | L21: =I21*8% -> 0 | M21: =I21-K21-L21 -> 0 | N21: =(M21*$N$15)+(J21*F21)*$N$15 -> 0 | O21: =(N21+M21)*$O$15 -> 0 | P21: =M21+N21+O21 -> 0
A22: CCE | B22: =VLOOKUP($A22,'[1]Cust. Price List'!$D$6:$O$14,2,0) -> Chicken Chatkhara (ECO) | C22: =VLOOKUP(B22,'[1]Cust. Price List'!E12:P20,2,0) -> 60 | D22: =VLOOKUP(A22,'[1]Cust. Price List'!D12:M20,4,0) -> 40 | E22: =VLOOKUP(A22,'[1]Cust. Price List'!D12:M20,6,0) -> 50 | F22: =VLOOKUP(A22,'[1]Cust. Price List'!D12:M20,10,0) -> 39.23 | I22: =(G22*D22)*F22+H22*F22 -> 0 | K22: =I22*3.5% -> 0 | L22: =I22*5% -> 0 | M22: =I22-K22-L22 -> 0 | N22: =(M22*$N$15)+(J22*F22)*$N$15 -> 0 | O22: =(N22+M22)*$O$15 -> 0 | P22: =M22+N22+O22 -> 0
A23: VTE | B23: =VLOOKUP($A23,'[1]Cust. Price List'!$D$6:$O$14,2,0) -> Lemon Tarka (ECO) | C23: =VLOOKUP(B23,'[1]Cust. Price List'!E13:P21,2,0) -> 60 | D23: =VLOOKUP(A23,'[1]Cust. Price List'!D13:M21,4,0) -> 40 | E23: =VLOOKUP(A23,'[1]Cust. Price List'!D13:M21,6,0) -> 50 | F23: =VLOOKUP(A23,'[1]Cust. Price List'!D13:M21,10,0) -> 39.23 | I23: =(G23*D23)*F23+H23*F23 -> 0 | K23: =I23*3.5% -> 0 | L23: =I23*$L$13 -> 0 | M23: =I23-K23-L23 -> 0 | N23: =(M23*$N$15)+(J23*F23)*$N$15 -> 0 | O23: =(N23+M23)*$O$15 -> 0 | P23: =M23+N23+O23 -> 0
A24: BCE | B24: =VLOOKUP($A24,'[1]Cust. Price List'!$D$6:$O$14,2,0) -> Meat Masala (ECO) | C24: =VLOOKUP(B24,'[1]Cust. Price List'!E14:P22,2,0) -> 60 | D24: =VLOOKUP(A24,'[1]Cust. Price List'!D14:M22,4,0) -> 40 | E24: =VLOOKUP(A24,'[1]Cust. Price List'!D14:M22,6,0) -> 50 | F24: =VLOOKUP(A24,'[1]Cust. Price List'!D14:M22,10,0) -> 39.23 | I24: =(G24*D24)*F24+H24*F24 -> 0 | K24: =I24*3.5% -> 0 | L24: =I24*$L$13 -> 0 | M24: =I24-K24-L24 -> 0 | N24: =(M24*$N$15)+(J24*F24)*$N$15 -> 0 | O24: =(N24+M24)*$O$15 -> 0 | P24: =M24+N24+O24 -> 0
A25: Total | G25: =SUM(G16:G24) -> 0 | H25: =SUM(H16:H24) -> 0 | I25: =SUM(I16:I24) -> 0 | K25: =SUM(K16:K24) -> 0 | L25: =SUM(L16:L24) -> 0 | M25: =SUM(M16:M24) -> 0 | N25: =SUM(N16:N24) -> 0 | O25: =SUM(O16:O24) -> 0 | P25: =SUM(P16:P24) -> 0
B28: یکم جولائی 2024سے نئی ٹیکس ترمیم کے مطابق، ایف بی آر سیکشن 236 ایچ کے مطابق، فائلرز کے لیے ہر سیل انوائس پر 0.5% اور نان فائلرز کے لیے 2.5% ایڈوانس ود ہولڈنگ ٹیکس وصول کیا جائے گا۔ | N28: Gross Amount: | P28: =I25 -> 0
N29: Regular Discount | P29: =L25 -> 0
N30: Trade Offre | P30: =K25 -> 0
N31: After Dis. Amount | P31: =P28-P29-P30 -> 0
N32: Total GST: | O32: =IF(B12="Registered",18%,22%) -> 0.22 | P32: =N25 -> 0
N33: Net Amount: | P33: =P31+P32 -> 0
N34: Ad.Tax | O34: =IF(B11="Filer",0.5%,2.5%) -> 0.025 | P34: =O34*P33 -> 0
N35: Net Amount with Ad.Tax | P35: =P33+P34 -> 0
B36: Delivered By

Sheet khan
A2: Elite MARKETING
A3: 44A- Gulberg Lahore | K3: Invoice No # : | N3: 3 | XFC3: Filer | XFD3: 0.005
A4: STRN / NTN :3808207-1 | K4: Date/Day : | N4: =TODAY() -> 46188 | XFC4: Non-filer | XFD4: 0.025
A5: Customer Name : Khan Store | K5: Order Date : | N5: =N4-1 -> 46187
A6: Address: Tajbagh | K6: Order Name : | N6: Mobeen Ahmad | XFC6: Registered | XFD6: 0.18
XFC7: Un-registered | XFD7: 0.22
XFD9: Yes
A10: NTN/CNIC Number: | B10: 368496-8 | K10: Invoice Status : | N10: Serviced | XFD10: No
B11: Filer | C11: =IF($O34>2.49%,"No","Yes") -> Yes | K11: Order at Original Location : | N11: Yes
A12: STRN Number: | B12: Registered | C12: =IF($O32>21.99%,"No","Yes") -> Yes | K12: Reference Invoice : | XFD12: Monday/Tuesday
L13: 0.05 | XFD13: Tuesday / Wednesday
A14: Product Code/Description | C14: GM/ Pack | D14: CTN | E14: R.P Per | F14: T.P Per | G14: Sale QTY | I14: Gross Amount Excl. Taxes | J14: Trade Offer & Discount | M14: After Discount Amount | N14: GST | O14: Adv. Tax 236H | P14: Invoice | XFD14: Wednesday/Thursday
D15: SIZE | E15: Unit | F15: Unit | G15: CTN | H15: Pack | J15: FOC Qty | K15: Trade Offer | L15: Pass On | N15: =IF(B12="Registered",18%,22%) -> 0.18 | O15: =IF(B11="Filer",0.5%,2.5%) -> 0.005 | P15: Amount | XFD15: Thursday /Friday
A16: BCN | B16: =VLOOKUP($A16,'[1]Cust. Price List'!$D$6:$O$14,2,0) -> Meat Masala | C16: =VLOOKUP(A16,'[1]Cust. Price List'!D6:M14,3,0) -> 70 | D16: =VLOOKUP(A16,'[1]Cust. Price List'!D6:M14,4,0) -> 40 | E16: =VLOOKUP(A16,'[1]Cust. Price List'!D6:M14,6,0) -> 65 | F16: =VLOOKUP(A16,'[1]Cust. Price List'!D6:M14,10,0) -> 52.4625 | I16: =(G16*D16)*F16+H16*F16 -> 0 | K16: =I16*$K$13 -> 0 | L16: =I16*8% -> 0 | M16: =I16-K16-L16 -> 0 | N16: =(M16*$N$15)+(J16*F16)*$N$15 -> 0 | O16: =(N16+M16)*$O$15 -> 0 | P16: =M16+N16+O16 -> 0 | XFD16: Friday / Saturday
A17: VTN | B17: =VLOOKUP($A17,'[1]Cust. Price List'!$D$6:$O$14,2,0) -> Lemon Tarka | C17: =VLOOKUP(B17,'[1]Cust. Price List'!E7:P15,2,0) -> 70 | D17: =VLOOKUP(A17,'[1]Cust. Price List'!D7:M15,4,0) -> 40 | E17: =VLOOKUP(A17,'[1]Cust. Price List'!D7:M15,6,0) -> 65 | F17: =VLOOKUP(A17,'[1]Cust. Price List'!D7:M15,10,0) -> 52.4625 | I17: =(G17*D17)*F17+H17*F17 -> 0 | K17: =I17*$K$13 -> 0 | L17: =I17*8% -> 0 | M17: =I17-K17-L17 -> 0 | N17: =(M17*$N$15)+(J17*F17)*$N$15 -> 0 | O17: =(N17+M17)*$O$15 -> 0 | P17: =M17+N17+O17 -> 0 | XFD17: Saturday /Monday
A18: CCN | B18: =VLOOKUP($A18,'[1]Cust. Price List'!$D$6:$O$14,2,0) -> Chicken Chatkhara | C18: =VLOOKUP(B18,'[1]Cust. Price List'!E8:P16,2,0) -> 70 | D18: =VLOOKUP(A18,'[1]Cust. Price List'!D8:M16,4,0) -> 40 | E18: =VLOOKUP(A18,'[1]Cust. Price List'!D8:M16,6,0) -> 65 | F18: =VLOOKUP(A18,'[1]Cust. Price List'!D8:M16,10,0) -> 52.4625 | I18: =(G18*D18)*F18+H18*F18 -> 0 | K18: =I18*$K$13 -> 0 | L18: =I18*8% -> 0 | M18: =I18-K18-L18 -> 0 | N18: =(M18*$N$15)+(J18*F18)*$N$15 -> 0 | O18: =(N18+M18)*$O$15 -> 0 | P18: =M18+N18+O18 -> 0
A19: BCNJ | B19: =VLOOKUP($A19,'[1]Cust. Price List'!$D$6:$O$14,2,0) -> Meat Masala (Jumbo) | C19: =VLOOKUP(B19,'[1]Cust. Price List'!E9:P17,2,0) -> 120 | D19: =VLOOKUP(A19,'[1]Cust. Price List'!D9:M17,4,0) -> 40 | E19: =VLOOKUP(A19,'[1]Cust. Price List'!D9:M17,6,0) -> 90 | F19: =VLOOKUP(A19,'[1]Cust. Price List'!D9:M17,10,0) -> 72.64 | I19: =(G19*D19)*F19+H19*F19 -> 0 | K19: =I19*$K$13 -> 0 | L19: =I19*8% -> 0 | M19: =I19-K19-L19 -> 0 | N19: =(M19*$N$15)+(J19*F19)*$N$15 -> 0 | O19: =(N19+M19)*$O$15 -> 0 | P19: =M19+N19+O19 -> 0
A20: VTNJ | B20: =VLOOKUP($A20,'[1]Cust. Price List'!$D$6:$O$14,2,0) -> Lemon Tarka (Jumbo) | C20: =VLOOKUP(B20,'[1]Cust. Price List'!E10:P18,2,0) -> 120 | D20: =VLOOKUP(A20,'[1]Cust. Price List'!D10:M18,4,0) -> 40 | E20: =VLOOKUP(A20,'[1]Cust. Price List'!D10:M18,6,0) -> 90 | F20: =VLOOKUP(A20,'[1]Cust. Price List'!D10:M18,10,0) -> 72.64 | I20: =(G20*D20)*F20+H20*F20 -> 0 | K20: =I20*$K$13 -> 0 | L20: =I20*8% -> 0 | M20: =I20-K20-L20 -> 0 | N20: =(M20*$N$15)+(J20*F20)*$N$15 -> 0 | O20: =(N20+M20)*$O$15 -> 0 | P20: =M20+N20+O20 -> 0
A21: CCNJ | B21: =VLOOKUP($A21,'[1]Cust. Price List'!$D$6:$O$14,2,0) -> Chicken Chatkhara (Jumbo) | C21: =VLOOKUP(B21,'[1]Cust. Price List'!E11:P19,2,0) -> 120 | D21: =VLOOKUP(A21,'[1]Cust. Price List'!D11:M19,4,0) -> 40 | E21: =VLOOKUP(A21,'[1]Cust. Price List'!D11:M19,6,0) -> 90 | F21: =VLOOKUP(A21,'[1]Cust. Price List'!D11:M19,10,0) -> 72.64 | I21: =(G21*D21)*F21+H21*F21 -> 0 | K21: =I21*$K$13 -> 0 | L21: =I21*8% -> 0 | M21: =I21-K21-L21 -> 0 | N21: =(M21*$N$15)+(J21*F21)*$N$15 -> 0 | O21: =(N21+M21)*$O$15 -> 0 | P21: =M21+N21+O21 -> 0
A22: CCE | B22: =VLOOKUP($A22,'[1]Cust. Price List'!$D$6:$O$14,2,0) -> Chicken Chatkhara (ECO) | C22: =VLOOKUP(B22,'[1]Cust. Price List'!E12:P20,2,0) -> 60 | D22: =VLOOKUP(A22,'[1]Cust. Price List'!D12:M20,4,0) -> 40 | E22: =VLOOKUP(A22,'[1]Cust. Price List'!D12:M20,6,0) -> 50 | F22: =VLOOKUP(A22,'[1]Cust. Price List'!D12:M20,10,0) -> 39.23 | I22: =(G22*D22)*F22+H22*F22 -> 0 | K22: =I22*3.5% -> 0 | L22: =I22*5% -> 0 | M22: =I22-K22-L22 -> 0 | N22: =(M22*$N$15)+(J22*F22)*$N$15 -> 0 | O22: =(N22+M22)*$O$15 -> 0 | P22: =M22+N22+O22 -> 0
A23: VTE | B23: =VLOOKUP($A23,'[1]Cust. Price List'!$D$6:$O$14,2,0) -> Lemon Tarka (ECO) | C23: =VLOOKUP(B23,'[1]Cust. Price List'!E13:P21,2,0) -> 60 | D23: =VLOOKUP(A23,'[1]Cust. Price List'!D13:M21,4,0) -> 40 | E23: =VLOOKUP(A23,'[1]Cust. Price List'!D13:M21,6,0) -> 50 | F23: =VLOOKUP(A23,'[1]Cust. Price List'!D13:M21,10,0) -> 39.23 | I23: =(G23*D23)*F23+H23*F23 -> 0 | K23: =I23*3.5% -> 0 | L23: =I23*$L$13 -> 0 | M23: =I23-K23-L23 -> 0 | N23: =(M23*$N$15)+(J23*F23)*$N$15 -> 0 | O23: =(N23+M23)*$O$15 -> 0 | P23: =M23+N23+O23 -> 0
A24: BCE | B24: =VLOOKUP($A24,'[1]Cust. Price List'!$D$6:$O$14,2,0) -> Meat Masala (ECO) | C24: =VLOOKUP(B24,'[1]Cust. Price List'!E14:P22,2,0) -> 60 | D24: =VLOOKUP(A24,'[1]Cust. Price List'!D14:M22,4,0) -> 40 | E24: =VLOOKUP(A24,'[1]Cust. Price List'!D14:M22,6,0) -> 50 | F24: =VLOOKUP(A24,'[1]Cust. Price List'!D14:M22,10,0) -> 39.23 | I24: =(G24*D24)*F24+H24*F24 -> 0 | K24: =I24*3.5% -> 0 | L24: =I24*$L$13 -> 0 | M24: =I24-K24-L24 -> 0 | N24: =(M24*$N$15)+(J24*F24)*$N$15 -> 0 | O24: =(N24+M24)*$O$15 -> 0 | P24: =M24+N24+O24 -> 0
A25: Total | G25: =SUM(G16:G24) -> 0 | H25: =SUM(H16:H24) -> 0 | I25: =SUM(I16:I24) -> 0 | K25: =SUM(K16:K24) -> 0 | L25: =SUM(L16:L24) -> 0 | M25: =SUM(M16:M24) -> 0 | N25: =SUM(N16:N24) -> 0 | O25: =SUM(O16:O24) -> 0 | P25: =SUM(P16:P24) -> 0
B28: یکم جولائی 2024سے نئی ٹیکس ترمیم کے مطابق، ایف بی آر سیکشن 236 ایچ کے مطابق، فائلرز کے لیے ہر سیل انوائس پر 0.5% اور نان فائلرز کے لیے 2.5% ایڈوانس ود ہولڈنگ ٹیکس وصول کیا جائے گا۔ | N28: Gross Amount: | P28: =I25 -> 0
N29: Regular Discount | P29: =L25 -> 0
N30: Trade Offre | P30: =K25 -> 0
N31: After Dis. Amount | P31: =P28-P29-P30 -> 0
N32: Total GST: | O32: =IF(B12="Registered",18%,22%) -> 0.18 | P32: =N25 -> 0
N33: Net Amount: | P33: =P31+P32 -> 0
N34: Ad.Tax | O34: =IF(B11="Filer",0.5%,2.5%) -> 0.005 | P34: =O34*P33 -> 0
N35: Net Amount with Ad.Tax | P35: =P33+P34 -> 0
B36: Delivered By

Sheet mrwa
A2: Elite MARKETING
A3: 44A- Gulberg Lahore | K3: Invoice No # : | N3: 5 | XFC3: Filer | XFD3: 0.005
A4: STRN / NTN :3808207-1 | K4: Date/Day : | N4: =TODAY() -> 46188 | XFC4: Non-filer | XFD4: 0.025
A5: Customer Name : Marwa Mart | K5: Order Date : | N5: =N4-1 -> 46187
A6: Address: Tajbagh | K6: Order Name : | N6: Mobeen Ahmad | XFC6: Registered | XFD6: 0.18
XFC7: Un-registered | XFD7: 0.22
XFD9: Yes
A10: NTN/CNIC Number: | B10: 7919618-5 | K10: Invoice Status : | N10: Serviced | XFD10: No
B11: Filer | C11: =IF($O34>2.49%,"No","Yes") -> Yes | K11: Order at Original Location : | N11: Yes
A12: STRN Number: | B12: Un-registered | C12: =IF($O32>21.99%,"No","Yes") -> No | K12: Reference Invoice : | XFD12: Monday/Tuesday
L13: 0.05 | XFD13: Tuesday / Wednesday
A14: Product Code/Description | C14: GM/ Pack | D14: CTN | E14: R.P Per | F14: T.P Per | G14: Sale QTY | I14: Gross Amount Excl. Taxes | J14: Trade Offer & Discount | M14: After Discount Amount | N14: GST | O14: Adv. Tax 236H | P14: Invoice | XFD14: Wednesday/Thursday
D15: SIZE | E15: Unit | F15: Unit | G15: CTN | H15: Pack | J15: FOC Qty | K15: Trade Offer | L15: Pass On | N15: =IF(B12="Registered",18%,22%) -> 0.22 | O15: =IF(B11="Filer",0.5%,2.5%) -> 0.005 | P15: Amount | XFD15: Thursday /Friday
A16: BCN | B16: =VLOOKUP($A16,'[1]Cust. Price List'!$D$6:$O$14,2,0) -> Meat Masala | C16: =VLOOKUP(A16,'[1]Cust. Price List'!D6:M14,3,0) -> 70 | D16: =VLOOKUP(A16,'[1]Cust. Price List'!D6:M14,4,0) -> 40 | E16: =VLOOKUP(A16,'[1]Cust. Price List'!D6:M14,6,0) -> 65 | F16: =VLOOKUP(A16,'[1]Cust. Price List'!D6:M14,10,0) -> 52.4625 | I16: =(G16*D16)*F16+H16*F16 -> 0 | K16: =I16*$K$13 -> 0 | L16: =I16*8% -> 0 | M16: =I16-K16-L16 -> 0 | N16: =(M16*$N$15)+(J16*F16)*$N$15 -> 0 | O16: =(N16+M16)*$O$15 -> 0 | P16: =M16+N16+O16 -> 0 | XFD16: Friday / Saturday
A17: VTN | B17: =VLOOKUP($A17,'[1]Cust. Price List'!$D$6:$O$14,2,0) -> Lemon Tarka | C17: =VLOOKUP(B17,'[1]Cust. Price List'!E7:P15,2,0) -> 70 | D17: =VLOOKUP(A17,'[1]Cust. Price List'!D7:M15,4,0) -> 40 | E17: =VLOOKUP(A17,'[1]Cust. Price List'!D7:M15,6,0) -> 65 | F17: =VLOOKUP(A17,'[1]Cust. Price List'!D7:M15,10,0) -> 52.4625 | I17: =(G17*D17)*F17+H17*F17 -> 0 | K17: =I17*$K$13 -> 0 | L17: =I17*8% -> 0 | M17: =I17-K17-L17 -> 0 | N17: =(M17*$N$15)+(J17*F17)*$N$15 -> 0 | O17: =(N17+M17)*$O$15 -> 0 | P17: =M17+N17+O17 -> 0 | XFD17: Saturday /Monday
A18: CCN | B18: =VLOOKUP($A18,'[1]Cust. Price List'!$D$6:$O$14,2,0) -> Chicken Chatkhara | C18: =VLOOKUP(B18,'[1]Cust. Price List'!E8:P16,2,0) -> 70 | D18: =VLOOKUP(A18,'[1]Cust. Price List'!D8:M16,4,0) -> 40 | E18: =VLOOKUP(A18,'[1]Cust. Price List'!D8:M16,6,0) -> 65 | F18: =VLOOKUP(A18,'[1]Cust. Price List'!D8:M16,10,0) -> 52.4625 | I18: =(G18*D18)*F18+H18*F18 -> 0 | K18: =I18*$K$13 -> 0 | L18: =I18*8% -> 0 | M18: =I18-K18-L18 -> 0 | N18: =(M18*$N$15)+(J18*F18)*$N$15 -> 0 | O18: =(N18+M18)*$O$15 -> 0 | P18: =M18+N18+O18 -> 0
A19: BCNJ | B19: =VLOOKUP($A19,'[1]Cust. Price List'!$D$6:$O$14,2,0) -> Meat Masala (Jumbo) | C19: =VLOOKUP(B19,'[1]Cust. Price List'!E9:P17,2,0) -> 120 | D19: =VLOOKUP(A19,'[1]Cust. Price List'!D9:M17,4,0) -> 40 | E19: =VLOOKUP(A19,'[1]Cust. Price List'!D9:M17,6,0) -> 90 | F19: =VLOOKUP(A19,'[1]Cust. Price List'!D9:M17,10,0) -> 72.64 | I19: =(G19*D19)*F19+H19*F19 -> 0 | K19: =I19*$K$13 -> 0 | L19: =I19*8% -> 0 | M19: =I19-K19-L19 -> 0 | N19: =(M19*$N$15)+(J19*F19)*$N$15 -> 0 | O19: =(N19+M19)*$O$15 -> 0 | P19: =M19+N19+O19 -> 0
A20: VTNJ | B20: =VLOOKUP($A20,'[1]Cust. Price List'!$D$6:$O$14,2,0) -> Lemon Tarka (Jumbo) | C20: =VLOOKUP(B20,'[1]Cust. Price List'!E10:P18,2,0) -> 120 | D20: =VLOOKUP(A20,'[1]Cust. Price List'!D10:M18,4,0) -> 40 | E20: =VLOOKUP(A20,'[1]Cust. Price List'!D10:M18,6,0) -> 90 | F20: =VLOOKUP(A20,'[1]Cust. Price List'!D10:M18,10,0) -> 72.64 | I20: =(G20*D20)*F20+H20*F20 -> 0 | K20: =I20*$K$13 -> 0 | L20: =I20*8% -> 0 | M20: =I20-K20-L20 -> 0 | N20: =(M20*$N$15)+(J20*F20)*$N$15 -> 0 | O20: =(N20+M20)*$O$15 -> 0 | P20: =M20+N20+O20 -> 0
A21: CCNJ | B21: =VLOOKUP($A21,'[1]Cust. Price List'!$D$6:$O$14,2,0) -> Chicken Chatkhara (Jumbo) | C21: =VLOOKUP(B21,'[1]Cust. Price List'!E11:P19,2,0) -> 120 | D21: =VLOOKUP(A21,'[1]Cust. Price List'!D11:M19,4,0) -> 40 | E21: =VLOOKUP(A21,'[1]Cust. Price List'!D11:M19,6,0) -> 90 | F21: =VLOOKUP(A21,'[1]Cust. Price List'!D11:M19,10,0) -> 72.64 | I21: =(G21*D21)*F21+H21*F21 -> 0 | K21: =I21*$K$13 -> 0 | L21: =I21*8% -> 0 | M21: =I21-K21-L21 -> 0 | N21: =(M21*$N$15)+(J21*F21)*$N$15 -> 0 | O21: =(N21+M21)*$O$15 -> 0 | P21: =M21+N21+O21 -> 0
A22: CCE | B22: =VLOOKUP($A22,'[1]Cust. Price List'!$D$6:$O$14,2,0) -> Chicken Chatkhara (ECO) | C22: =VLOOKUP(B22,'[1]Cust. Price List'!E12:P20,2,0) -> 60 | D22: =VLOOKUP(A22,'[1]Cust. Price List'!D12:M20,4,0) -> 40 | E22: =VLOOKUP(A22,'[1]Cust. Price List'!D12:M20,6,0) -> 50 | F22: =VLOOKUP(A22,'[1]Cust. Price List'!D12:M20,10,0) -> 39.23 | I22: =(G22*D22)*F22+H22*F22 -> 0 | K22: =I22*3.5% -> 0 | L22: =I22*5% -> 0 | M22: =I22-K22-L22 -> 0 | N22: =(M22*$N$15)+(J22*F22)*$N$15 -> 0 | O22: =(N22+M22)*$O$15 -> 0 | P22: =M22+N22+O22 -> 0
A23: VTE | B23: =VLOOKUP($A23,'[1]Cust. Price List'!$D$6:$O$14,2,0) -> Lemon Tarka (ECO) | C23: =VLOOKUP(B23,'[1]Cust. Price List'!E13:P21,2,0) -> 60 | D23: =VLOOKUP(A23,'[1]Cust. Price List'!D13:M21,4,0) -> 40 | E23: =VLOOKUP(A23,'[1]Cust. Price List'!D13:M21,6,0) -> 50 | F23: =VLOOKUP(A23,'[1]Cust. Price List'!D13:M21,10,0) -> 39.23 | I23: =(G23*D23)*F23+H23*F23 -> 0 | K23: =I23*3.5% -> 0 | L23: =I23*$L$13 -> 0 | M23: =I23-K23-L23 -> 0 | N23: =(M23*$N$15)+(J23*F23)*$N$15 -> 0 | O23: =(N23+M23)*$O$15 -> 0 | P23: =M23+N23+O23 -> 0
A24: BCE | B24: =VLOOKUP($A24,'[1]Cust. Price List'!$D$6:$O$14,2,0) -> Meat Masala (ECO) | C24: =VLOOKUP(B24,'[1]Cust. Price List'!E14:P22,2,0) -> 60 | D24: =VLOOKUP(A24,'[1]Cust. Price List'!D14:M22,4,0) -> 40 | E24: =VLOOKUP(A24,'[1]Cust. Price List'!D14:M22,6,0) -> 50 | F24: =VLOOKUP(A24,'[1]Cust. Price List'!D14:M22,10,0) -> 39.23 | I24: =(G24*D24)*F24+H24*F24 -> 0 | K24: =I24*3.5% -> 0 | L24: =I24*$L$13 -> 0 | M24: =I24-K24-L24 -> 0 | N24: =(M24*$N$15)+(J24*F24)*$N$15 -> 0 | O24: =(N24+M24)*$O$15 -> 0 | P24: =M24+N24+O24 -> 0
A25: Total | G25: =SUM(G16:G24) -> 0 | H25: =SUM(H16:H24) -> 0 | I25: =SUM(I16:I24) -> 0 | K25: =SUM(K16:K24) -> 0 | L25: =SUM(L16:L24) -> 0 | M25: =SUM(M16:M24) -> 0 | N25: =SUM(N16:N24) -> 0 | O25: =SUM(O16:O24) -> 0 | P25: =SUM(P16:P24) -> 0
B28: یکم جولائی 2024سے نئی ٹیکس ترمیم کے مطابق، ایف بی آر سیکشن 236 ایچ کے مطابق، فائلرز کے لیے ہر سیل انوائس پر 0.5% اور نان فائلرز کے لیے 2.5% ایڈوانس ود ہولڈنگ ٹیکس وصول کیا جائے گا۔ | N28: Gross Amount: | P28: =I25 -> 0
N29: Regular Discount | P29: =L25 -> 0
N30: Trade Offre | P30: =K25 -> 0
N31: After Dis. Amount | P31: =P28-P29-P30 -> 0
N32: Total GST: | O32: =IF(B12="Registered",18%,22%) -> 0.22 | P32: =N25 -> 0
N33: Net Amount: | P33: =P31+P32 -> 0
N34: Ad.Tax | O34: =IF(B11="Filer",0.5%,2.5%) -> 0.005 | P34: =O34*P33 -> 0
N35: Net Amount with Ad.Tax | P35: =P33+P34 -> 0
B36: Delivered By

Sheet saad
A2: Elite MARKETING
A3: 44A- Gulberg Lahore | K3: Invoice No # : | N3: 6 | XFC3: Filer | XFD3: 0.005
A4: STRN / NTN :3808207-1 | K4: Date/Day : | N4: =TODAY() -> 46188 | XFC4: Non-filer | XFD4: 0.025
A5: Customer Name : Saad Mart | K5: Order Date : | N5: =N4-1 -> 46187
A6: Address: Tajbagh | K6: Order Name : | N6: Mobeen Ahmad | XFC6: Registered | XFD6: 0.18
XFC7: Un-registered | XFD7: 0.22
XFD9: Yes
A10: NTN/CNIC Number: | B10: 200379-3 | K10: Invoice Status : | N10: Serviced | XFD10: No
B11: Filer | C11: =IF($O34>2.49%,"No","Yes") -> Yes | K11: Order at Original Location : | N11: Yes
A12: STRN Number: | B12: Un-registered | C12: =IF($O32>21.99%,"No","Yes") -> No | K12: Reference Invoice : | XFD12: Monday/Tuesday
L13: 0.05 | XFD13: Tuesday / Wednesday
A14: Product Code/Description | C14: GM/ Pack | D14: CTN | E14: R.P Per | F14: T.P Per | G14: Sale QTY | I14: Gross Amount Excl. Taxes | J14: Trade Offer & Discount | M14: After Discount Amount | N14: GST | O14: Adv. Tax 236H | P14: Invoice | XFD14: Wednesday/Thursday
D15: SIZE | E15: Unit | F15: Unit | G15: CTN | H15: Pack | J15: FOC Qty | K15: Trade Offer | L15: Pass On | N15: =IF(B12="Registered",18%,22%) -> 0.22 | O15: =IF(B11="Filer",0.5%,2.5%) -> 0.005 | P15: Amount | XFD15: Thursday /Friday
A16: BCN | B16: =VLOOKUP($A16,'[1]Cust. Price List'!$D$6:$O$14,2,0) -> Meat Masala | C16: =VLOOKUP(A16,'[1]Cust. Price List'!D6:M14,3,0) -> 70 | D16: =VLOOKUP(A16,'[1]Cust. Price List'!D6:M14,4,0) -> 40 | E16: =VLOOKUP(A16,'[1]Cust. Price List'!D6:M14,6,0) -> 65 | F16: =VLOOKUP(A16,'[1]Cust. Price List'!D6:M14,10,0) -> 52.4625 | I16: =(G16*D16)*F16+H16*F16 -> 0 | K16: =I16*$K$13 -> 0 | L16: =I16*8% -> 0 | M16: =I16-K16-L16 -> 0 | N16: =(M16*$N$15)+(J16*F16)*$N$15 -> 0 | O16: =(N16+M16)*$O$15 -> 0 | P16: =M16+N16+O16 -> 0 | XFD16: Friday / Saturday
A17: VTN | B17: =VLOOKUP($A17,'[1]Cust. Price List'!$D$6:$O$14,2,0) -> Lemon Tarka | C17: =VLOOKUP(B17,'[1]Cust. Price List'!E7:P15,2,0) -> 70 | D17: =VLOOKUP(A17,'[1]Cust. Price List'!D7:M15,4,0) -> 40 | E17: =VLOOKUP(A17,'[1]Cust. Price List'!D7:M15,6,0) -> 65 | F17: =VLOOKUP(A17,'[1]Cust. Price List'!D7:M15,10,0) -> 52.4625 | I17: =(G17*D17)*F17+H17*F17 -> 0 | K17: =I17*$K$13 -> 0 | L17: =I17*8% -> 0 | M17: =I17-K17-L17 -> 0 | N17: =(M17*$N$15)+(J17*F17)*$N$15 -> 0 | O17: =(N17+M17)*$O$15 -> 0 | P17: =M17+N17+O17 -> 0 | XFD17: Saturday /Monday
A18: CCN | B18: =VLOOKUP($A18,'[1]Cust. Price List'!$D$6:$O$14,2,0) -> Chicken Chatkhara | C18: =VLOOKUP(B18,'[1]Cust. Price List'!E8:P16,2,0) -> 70 | D18: =VLOOKUP(A18,'[1]Cust. Price List'!D8:M16,4,0) -> 40 | E18: =VLOOKUP(A18,'[1]Cust. Price List'!D8:M16,6,0) -> 65 | F18: =VLOOKUP(A18,'[1]Cust. Price List'!D8:M16,10,0) -> 52.4625 | I18: =(G18*D18)*F18+H18*F18 -> 0 | K18: =I18*$K$13 -> 0 | L18: =I18*8% -> 0 | M18: =I18-K18-L18 -> 0 | N18: =(M18*$N$15)+(J18*F18)*$N$15 -> 0 | O18: =(N18+M18)*$O$15 -> 0 | P18: =M18+N18+O18 -> 0
A19: BCNJ | B19: =VLOOKUP($A19,'[1]Cust. Price List'!$D$6:$O$14,2,0) -> Meat Masala (Jumbo) | C19: =VLOOKUP(B19,'[1]Cust. Price List'!E9:P17,2,0) -> 120 | D19: =VLOOKUP(A19,'[1]Cust. Price List'!D9:M17,4,0) -> 40 | E19: =VLOOKUP(A19,'[1]Cust. Price List'!D9:M17,6,0) -> 90 | F19: =VLOOKUP(A19,'[1]Cust. Price List'!D9:M17,10,0) -> 72.64 | I19: =(G19*D19)*F19+H19*F19 -> 0 | K19: =I19*$K$13 -> 0 | L19: =I19*8% -> 0 | M19: =I19-K19-L19 -> 0 | N19: =(M19*$N$15)+(J19*F19)*$N$15 -> 0 | O19: =(N19+M19)*$O$15 -> 0 | P19: =M19+N19+O19 -> 0
A20: VTNJ | B20: =VLOOKUP($A20,'[1]Cust. Price List'!$D$6:$O$14,2,0) -> Lemon Tarka (Jumbo) | C20: =VLOOKUP(B20,'[1]Cust. Price List'!E10:P18,2,0) -> 120 | D20: =VLOOKUP(A20,'[1]Cust. Price List'!D10:M18,4,0) -> 40 | E20: =VLOOKUP(A20,'[1]Cust. Price List'!D10:M18,6,0) -> 90 | F20: =VLOOKUP(A20,'[1]Cust. Price List'!D10:M18,10,0) -> 72.64 | I20: =(G20*D20)*F20+H20*F20 -> 0 | K20: =I20*$K$13 -> 0 | L20: =I20*8% -> 0 | M20: =I20-K20-L20 -> 0 | N20: =(M20*$N$15)+(J20*F20)*$N$15 -> 0 | O20: =(N20+M20)*$O$15 -> 0 | P20: =M20+N20+O20 -> 0
A21: CCNJ | B21: =VLOOKUP($A21,'[1]Cust. Price List'!$D$6:$O$14,2,0) -> Chicken Chatkhara (Jumbo) | C21: =VLOOKUP(B21,'[1]Cust. Price List'!E11:P19,2,0) -> 120 | D21: =VLOOKUP(A21,'[1]Cust. Price List'!D11:M19,4,0) -> 40 | E21: =VLOOKUP(A21,'[1]Cust. Price List'!D11:M19,6,0) -> 90 | F21: =VLOOKUP(A21,'[1]Cust. Price List'!D11:M19,10,0) -> 72.64 | I21: =(G21*D21)*F21+H21*F21 -> 0 | K21: =I21*$K$13 -> 0 | L21: =I21*8% -> 0 | M21: =I21-K21-L21 -> 0 | N21: =(M21*$N$15)+(J21*F21)*$N$15 -> 0 | O21: =(N21+M21)*$O$15 -> 0 | P21: =M21+N21+O21 -> 0
