Workbook

Sheet Price
V2: 0.18
A4: S# | B4: Code | D4: SKU | E4: SKUs Description | F4: Unit | H4: Retail Price | J4: TP Incl. | L4: TP Excl. | N4: Dist Margin | P4: Trade Offre | R4: Stale | T4: Ex-Fac | V4: S.Tax | X4: Dist. Price
B5: Bar | C5: SKU | F5: Gm | G5: CTN | H5: Ctn | I5: Pk | J5: Ctn | K5: Pk | L5: Ctn | M5: Pk | N5: 0.19 | O5: Amount | P5: 0.04 | Q5: Amount | R5: 0.005 | S5: Amount | T5: Ctn | U5: Pk | V5: Ctn | W5: Pk | X5: Ctn | Y5: Pk | AA5: Weight/ctn
A6: 1 | C6: BCN | D6: BCN | E6: Meat Masala | F6: 70 | G6: 40 | H6: =I6*G6 -> 2600 | I6: 65 | J6: =K6*G6 -> 2560.17 | K6: =M6*1.22 -> 64.00425 | L6: 2098.5 | M6: =L6/G6 -> 52.4625 | N6: 0.19 | O6: =N6*M6 -> 9.967875 | Q6: =P6*M6 -> 0 | S6: =R6*M6 -> 0 | T6: =U6*G6 -> 1699.785 | U6: =M6-O6-Q6-S6 -> 42.494625 | V6: =T6*$V$2 -> 305.9613 | W6: =U6*$V$2 -> 7.6490325 | X6: =T6+V6 -> 2005.7463 | Y6: =U6+W6 -> 50.143657 | AA6: =(F6*G6)/1000 -> 2.8 | AB6: 2000 | AC6: =X6*AB6 -> 4011492.6
A7: =+A6+1 -> 2 | C7: VTN | D7: VTN | E7: Lemon Tarka | F7: 70 | G7: 40 | H7: =I7*G7 -> 2600 | I7: 65 | J7: =K7*G7 -> 2560.17 | K7: =M7*1.22 -> 64.00425 | L7: 2098.5 | M7: =L7/G7 -> 52.4625 | N7: =+N6 -> 0.19 | O7: =N7*M7 -> 9.967875 | Q7: =P7*M7 -> 0 | S7: =R7*M7 -> 0 | T7: =U7*G7 -> 1699.785 | U7: =M7-O7-Q7-S7 -> 42.494625 | V7: =T7*$V$2 -> 305.9613 | W7: =U7*$V$2 -> 7.6490325 | X7: =T7+V7 -> 2005.7463 | Y7: =U7+W7 -> 50.143657 | AA7: =(F7*G7)/1000 -> 2.8
A8: =+A7+1 -> 3 | C8: CCN | D8: CCN | E8: Chicken Chatkhara | F8: 70 | G8: 40 | H8: =I8*G8 -> 2600 | I8: 65 | J8: =K8*G8 -> 2560.17 | K8: =M8*1.22 -> 64.00425 | L8: 2098.5 | M8: =L8/G8 -> 52.4625 | N8: =+N7 -> 0.19 | O8: =N8*M8 -> 9.967875 | Q8: =P8*M8 -> 0 | S8: =R8*M8 -> 0 | T8: =U8*G8 -> 1699.785 | U8: =M8-O8-Q8-S8 -> 42.494625 | V8: =T8*$V$2 -> 305.9613 | W8: =U8*$V$2 -> 7.6490325 | X8: =T8+V8 -> 2005.7463 | Y8: =U8+W8 -> 50.143657 | AA8: =(F8*G8)/1000 -> 2.8
A9: =+A8+1 -> 4 | C9: BCNJ | D9: BCNJ | E9: Meat Masala (Jumbo) | F9: 120 | G9: 40 | H9: =I9*G9 -> 3600 | I9: 90 | J9: =K9*G9 -> 3544.832 | K9: =M9*1.22 -> 88.6208 | L9: 2905.6 | M9: =L9/G9 -> 72.64 | N9: =+N8 -> 0.19 | O9: =N9*M9 -> 13.8016 | Q9: =P9*M9 -> 0 | S9: =R9*M9 -> 0 | T9: =U9*G9 -> 2353.536 | U9: =M9-O9-Q9-S9 -> 58.8384 | V9: =T9*$V$2 -> 423.63648 | W9: =U9*$V$2 -> 10.590912 | X9: =T9+V9 -> 2777.1725 | Y9: =U9+W9 -> 69.429312 | AA9: =(F9*G9)/1000 -> 4.8 | AB9: 1000 | AC9: =X9*AB9 -> 2777172.5
A10: =+A9+1 -> 5 | C10: VTNJ | D10: VTNJ | E10: Lemon Tarka (Jumbo) | F10: 120 | G10: 40 | H10: =I10*G10 -> 3600 | I10: 90 | J10: =K10*G10 -> 3544.832 | K10: =M10*1.22 -> 88.6208 | L10: 2905.6 | M10: =L10/G10 -> 72.64 | N10: =+N9 -> 0.19 | O10: =N10*M10 -> 13.8016 | Q10: =P10*M10 -> 0 | S10: =R10*M10 -> 0 | T10: =U10*G10 -> 2353.536 | U10: =M10-O10-Q10-S10 -> 58.8384 | V10: =T10*$V$2 -> 423.63648 | W10: =U10*$V$2 -> 10.590912 | X10: =T10+V10 -> 2777.1725 | Y10: =U10+W10 -> 69.429312 | AA10: =(F10*G10)/1000 -> 4.8
A11: =+A10+1 -> 6 | C11: CCNJ | D11: CCNJ | E11: Chicken Chatkhara (Jumbo) | F11: 120 | G11: 40 | H11: =I11*G11 -> 3600 | I11: 90 | J11: =K11*G11 -> 3544.832 | K11: =M11*1.22 -> 88.6208 | L11: 2905.6 | M11: =L11/G11 -> 72.64 | N11: =+N10 -> 0.19 | O11: =N11*M11 -> 13.8016 | Q11: =P11*M11 -> 0 | S11: =R11*M11 -> 0 | T11: =U11*G11 -> 2353.536 | U11: =M11-O11-Q11-S11 -> 58.8384 | V11: =T11*$V$2 -> 423.63648 | W11: =U11*$V$2 -> 10.590912 | X11: =T11+V11 -> 2777.1725 | Y11: =U11+W11 -> 69.429312 | AA11: =(F11*G11)/1000 -> 4.8
A12: =+A11+1 -> 7 | C12: CCE | D12: CCE | E12: Chicken Chatkhara (ECO) | F12: 60 | G12: 40 | H12: =I12*G12 -> 2000 | I12: 50 | J12: =K12*G12 -> 1914.424 | K12: =M12*1.22 -> 47.8606 | L12: 1569.2 | M12: =L12/G12 -> 39.23 | N12: =+N11 -> 0.19 | O12: =N12*M12 -> 7.4537 | Q12: =P12*M12 -> 0 | S12: =R12*M12 -> 0 | T12: =U12*G12 -> 1271.052 | U12: =M12-O12-Q12-S12 -> 31.7763 | V12: =T12*$V$2 -> 228.78936 | W12: =U12*$V$2 -> 5.719734 | X12: =T12+V12 -> 1499.8414 | Y12: =U12+W12 -> 37.496034 | AA12: =(F12*G12)/1000 -> 2.4 | AB12: 2000 | AC12: =X12*AB12 -> 2999682.7
A13: =+A12+1 -> 8 | C13: VTE | D13: VTE | E13: Lemon Tarka (ECO) | F13: 60 | G13: 40 | H13: =I13*G13 -> 2000 | I13: 50 | J13: =K13*G13 -> 1914.424 | K13: =M13*1.22 -> 47.8606 | L13: 1569.2 | M13: =L13/G13 -> 39.23 | N13: =+N12 -> 0.19 | O13: =N13*M13 -> 7.4537 | Q13: =P13*M13 -> 0 | S13: =R13*M13 -> 0 | T13: =U13*G13 -> 1271.052 | U13: =M13-O13-Q13-S13 -> 31.7763 | V13: =T13*$V$2 -> 228.78936 | W13: =U13*$V$2 -> 5.719734 | X13: =T13+V13 -> 1499.8414 | Y13: =U13+W13 -> 37.496034 | AA13: =(F13*G13)/1000 -> 2.4 | AC13: =SUM(AC6:AC12) -> 9788347.8
A14: =+A13+1 -> 9 | C14: BCE | D14: BCE | E14: Meat Masala (ECO) | F14: 60 | G14: 40 | H14: =I14*G14 -> 2000 | I14: 50 | J14: =K14*G14 -> 1914.424 | K14: =M14*1.22 -> 47.8606 | L14: 1569.2 | M14: =L14/G14 -> 39.23 | N14: =+N13 -> 0.19 | O14: =N14*M14 -> 7.4537 | Q14: =P14*M14 -> 0 | S14: =R14*M14 -> 0 | T14: =U14*G14 -> 1271.052 | U14: =M14-O14-Q14-S14 -> 31.7763 | V14: =T14*$V$2 -> 228.78936 | W14: =U14*$V$2 -> 5.719734 | X14: =T14+V14 -> 1499.8414 | Y14: =U14+W14 -> 37.496034 | AA14: =(F14*G14)/1000 -> 2.4

Sheet TGT
A2: 46174 | C2: City:Lahore | D2: Total Days | F2: Days Gone | G2: Bal Days | H2: Re-Day
A3: Distribution Name: | E3: 26 | F3: 1 | G3: =F3/E3 -> 0.038461538 | H3: =E3-F3 -> 25
A4: Sr# | B4: ID | C4: Booker Name | D4: Unit | F4: Trade Price | G4: Secondary Sales Update
D5: Gm | E5: CTN | F5: Excl. GST | G5: Target | H5: Ach. | I5: % | J5: Balance | K5: ADS | L5: RPD
A6: 1 | D6: 70 | E6: 40 | F6: =[1]Price!M6 -> 52.4625 | G6: 500 | H6: =Ttl!L6 -> 66.275 | I6: =H6/G6 -> 0.13255 | J6: =G6-H6 -> 433.725 | K6: =H6/$F$3 -> 66.275 | L6: =J6/$H$3 -> 17.349
A7: 2 | D7: 70 | E7: 40 | F7: =[1]Price!M7 -> 52.4625 | G7: 500 | H7: =Ttl!L7 -> 0 | I7: =H7/G7 -> 0 | J7: =G7-H7 -> 500 | K7: =H7/$F$3 -> 0 | L7: =J7/$H$3 -> 20
A8: 3 | D8: 70 | E8: 40 | F8: =[1]Price!M8 -> 52.4625 | G8: 500 | H8: =Ttl!L8 -> 217.7 | I8: =H8/G8 -> 0.4354 | J8: =G8-H8 -> 282.3 | K8: =H8/$F$3 -> 217.7 | L8: =J8/$H$3 -> 11.292
A9: 4 | D9: 120 | E9: 40 | F9: =[1]Price!M9 -> 72.64 | G9: 500 | H9: =Ttl!L9 -> 70.6 | I9: =H9/G9 -> 0.1412 | J9: =G9-H9 -> 429.4 | K9: =H9/$F$3 -> 70.6 | L9: =J9/$H$3 -> 17.176
A10: 5 | D10: 120 | E10: 40 | F10: =[1]Price!M10 -> 72.64 | G10: 500 | H10: =Ttl!L10 -> 131.8 | I10: =H10/G10 -> 0.2636 | J10: =G10-H10 -> 368.2 | K10: =H10/$F$3 -> 131.8 | L10: =J10/$H$3 -> 14.728
A11: 6 | D11: 120 | E11: 40 | F11: =[1]Price!M11 -> 72.64 | G11: 500 | H11: =Ttl!L11 -> 100.5 | I11: =H11/G11 -> 0.201 | J11: =G11-H11 -> 399.5 | K11: =H11/$F$3 -> 100.5 | L11: =J11/$H$3 -> 15.98
A12: 7 | D12: 60 | E12: 40 | F12: =[1]Price!M12 -> 39.23 | G12: 6000 | H12: =Ttl!L14 -> 1724.15 | I12: =H12/G12 -> 0.28735833 | J12: =G12-H12 -> 4275.85 | K12: =H12/$F$3 -> 1724.15 | L12: =J12/$H$3 -> 171.034
A13: 8 | D13: 60 | E13: 40 | F13: =[1]Price!M13 -> 39.23 | G13: 500 | H13: =Ttl!L15 -> 400 | I13: =H13/G13 -> 0.8 | J13: =G13-H13 -> 100 | K13: =H13/$F$3 -> 400 | L13: =J13/$H$3 -> 4
A14: 9 | D14: 60 | E14: 40 | F14: =[1]Price!M14 -> 39.23 | G14: 500 | H14: =Ttl!L16 -> 90 | I14: =H14/G14 -> 0.18 | J14: =G14-H14 -> 410 | K14: =H14/$F$3 -> 90 | L14: =J14/$H$3 -> 16.4
A15: 10 | H15: =Ttl!L17 -> 100 | I15: =H15/G15 -> #DIV/0! | J15: =G15-H15 -> -100 | K15: =H15/$F$3 -> 100 | L15: =J15/$H$3 -> -4
A16: Total | G16: =SUM(G6:G15) -> 10000 | H16: =SUM(H6:H15) -> 2901.025 | I16: =H16/G16 -> 0.2901025 | J16: =SUM(J6:J15) -> 7098.975 | K16: =SUM(K6:K15) -> 2901.025 | L16: =SUM(L6:L15) -> 283.959
A19: Sr# | B19: ID | C19: Booker Name | F19: Trade Price | G19: Unique Productivity
D20: Gm | E20: CTN | F20: Excl. GST | G20: P-Shop | H20: Shops | I20: % | J20: Balance | K20: ADS
A21: 1 | D21: 70 | E21: 40 | F21: =F6 -> 52.4625 | G21: =Ttl!Z6 -> 0 | H21: =Ttl!AA6 -> 0 | I21: =H21/G21 -> #DIV/0! | J21: =G21-H21 -> 0 | K21: =H21/$F$3 -> 0
A22: 2 | D22: 70 | E22: 40 | F22: =F7 -> 52.4625 | G22: =Ttl!Z7 -> 0 | H22: =Ttl!AA7 -> 0 | I22: =H22/G22 -> #DIV/0! | J22: =G22-H22 -> 0 | K22: =H22/$F$3 -> 0
A23: 3 | D23: 70 | E23: 40 | F23: =F8 -> 52.4625 | G23: =Ttl!Z8 -> 0 | H23: =Ttl!AA8 -> 0 | I23: =H23/G23 -> #DIV/0! | J23: =G23-H23 -> 0 | K23: =H23/$F$3 -> 0
A24: 4 | D24: 120 | E24: 40 | F24: =F9 -> 72.64 | G24: =Ttl!Z9 -> 0 | H24: =Ttl!AA9 -> 0 | I24: =H24/G24 -> #DIV/0! | J24: =G24-H24 -> 0 | K24: =H24/$F$3 -> 0
A25: 5 | D25: 120 | E25: 40 | F25: =F10 -> 72.64 | G25: =Ttl!Z10 -> 0 | H25: =Ttl!AA10 -> 0 | I25: =H25/G25 -> #DIV/0! | J25: =G25-H25 -> 0 | K25: =H25/$F$3 -> 0
A26: 6 | D26: 120 | E26: 40 | F26: =F11 -> 72.64 | G26: =Ttl!Z11 -> 0 | H26: =Ttl!AA11 -> 0 | I26: =H26/G26 -> #DIV/0! | J26: =G26-H26 -> 0 | K26: =H26/$F$3 -> 0
A27: 7 | D27: 60 | E27: 40 | F27: =F12 -> 39.23 | G27: =Ttl!Z14 -> 0 | H27: =Ttl!AA14 -> 0 | I27: =H27/G27 -> #DIV/0! | J27: =G27-H27 -> 0 | K27: =H27/$F$3 -> 0
A28: 8 | D28: 60 | E28: 40 | F28: =F13 -> 39.23 | G28: =Ttl!Z15 -> 0 | H28: =Ttl!AA15 -> 0 | I28: =H28/G28 -> #DIV/0! | J28: =G28-H28 -> 0 | K28: =H28/$F$3 -> 0
A29: 9 | D29: 60 | E29: 40 | F29: =F14 -> 39.23 | G29: =Ttl!Z16 -> 0 | H29: =Ttl!AA16 -> 0 | I29: =H29/G29 -> #DIV/0! | J29: =G29-H29 -> 0 | K29: =H29/$F$3 -> 0
A30: 10 | G30: =Ttl!Z17 -> 0 | H30: =Ttl!AA17 -> 0 | I30: =H30/G30 -> #DIV/0! | J30: =G30-H30 -> 0 | K30: =H30/$F$3 -> 0
A31: Total | G31: =SUM(G21:G30) -> 0 | H31: =SUM(H21:H30) -> 0 | I31: =SUM(I21:I30) -> #DIV/0! | J31: =SUM(J21:J30) -> 0 | K31: =SUM(K21:K30) -> 0 | L31: =SUM(L21:L30) -> 0

Sheet Ttl
A2: 46193
A3: ID | B3: Gm | C3: 60 | D3: 60 | E3: 60 | F3: 70 | G3: 70 | H3: 70 | I3: 120 | J3: 120 | K3: 120 | L3: Total | O3: FOC | Q3: 0.05 | R3: 0.08 | S3: 0.08 | U3: 0.035 | Y3: Route Name | Z3: KPI's
B4: TP Excl. GST | C4: 39.23 | D4: 39.23 | E4: 39.23 | F4: 52.4625 | G4: 52.4625 | H4: 52.4625 | I4: 72.64 | J4: 72.64 | K4: 72.64 | Q4: Discount | U4: Trader offer | Z4: Unique | AC4: Drop Size | AD4: SKU/Call | AF4: Sales | AJ4: Contribution
B5: Booker Name | C5: CHk | D5: LEM | E5: Meat | F5: Meat | G5: LEM | H5: CHK | I5: Meat | J5: LEM | K5: CHK | L5: CTN | M5: Amount | N5: Volume | O5: 70 | P5: 120 | Q5: 60 | R5: 70 | S5: 120 | T5: Total | U5: 60 | V5: 70 | W5: 120 | X5: Total | Z5: Plan Shop | AA5: Productivity | AB5: % | AF5: 60 | AG5: 70 | AH5: 120 | AJ5: 60 | AK5: 70 | AL5: 120
A6: 1 | B6: Zahid Rafique | C6: ='1'!C6+'2'!C6+'3'!C6+'4'!C6+'5'!C6+'6'!C6+'7'!C6+'8'!C6+'9'!C6+'10'!C6+'11'!C6+'12'!C6+'13'!C6+'14'!C6+'15'!C6+'16'!C6+'17'!C6+'18'!C6+'19'!C6+'20'!C6+'21'!C6+'22'!C6+'23'!C6+'24'!C6+'25'!C6+'26'!C6+'27'!C6+'28'!C6+'29'!C6+'30'!C6+'31'!C6 -> 526 | D6: ='1'!D6+'2'!D6+'3'!D6+'4'!D6+'5'!D6+'6'!D6+'7'!D6+'8'!D6+'9'!D6+'10'!D6+'11'!D6+'12'!D6+'13'!D6+'14'!D6+'15'!D6+'16'!D6+'17'!D6+'18'!D6+'19'!D6+'20'!D6+'21'!D6+'22'!D6+'23'!D6+'24'!D6+'25'!D6+'26'!D6+'27'!D6+'28'!D6+'29'!D6+'30'!D6+'31'!D6 -> 0 | E6: ='1'!E6+'2'!E6+'3'!E6+'4'!E6+'5'!E6+'6'!E6+'7'!E6+'8'!E6+'9'!E6+'10'!E6+'11'!E6+'12'!E6+'13'!E6+'14'!E6+'15'!E6+'16'!E6+'17'!E6+'18'!E6+'19'!E6+'20'!E6+'21'!E6+'22'!E6+'23'!E6+'24'!E6+'25'!E6+'26'!E6+'27'!E6+'28'!E6+'29'!E6+'30'!E6+'31'!E6 -> 0 | F6: ='1'!F6+'2'!F6+'3'!F6+'4'!F6+'5'!F6+'6'!F6+'7'!F6+'8'!F6+'9'!F6+'10'!F6+'11'!F6+'12'!F6+'13'!F6+'14'!F6+'15'!F6+'16'!F6+'17'!F6+'18'!F6+'19'!F6+'20'!F6+'21'!F6+'22'!F6+'23'!F6+'24'!F6+'25'!F6+'26'!F6+'27'!F6+'28'!F6+'29'!F6+'30'!F6+'31'!F6 -> 319 | G6: ='1'!G6+'2'!G6+'3'!G6+'4'!G6+'5'!G6+'6'!G6+'7'!G6+'8'!G6+'9'!G6+'10'!G6+'11'!G6+'12'!G6+'13'!G6+'14'!G6+'15'!G6+'16'!G6+'17'!G6+'18'!G6+'19'!G6+'20'!G6+'21'!G6+'22'!G6+'23'!G6+'24'!G6+'25'!G6+'26'!G6+'27'!G6+'28'!G6+'29'!G6+'30'!G6+'31'!G6 -> 262 | H6: ='1'!H6+'2'!H6+'3'!H6+'4'!H6+'5'!H6+'6'!H6+'7'!H6+'8'!H6+'9'!H6+'10'!H6+'11'!H6+'12'!H6+'13'!H6+'14'!H6+'15'!H6+'16'!H6+'17'!H6+'18'!H6+'19'!H6+'20'!H6+'21'!H6+'22'!H6+'23'!H6+'24'!H6+'25'!H6+'26'!H6+'27'!H6+'28'!H6+'29'!H6+'30'!H6+'31'!H6 -> 310 | I6: ='1'!I6+'2'!I6+'3'!I6+'4'!I6+'5'!I6+'6'!I6+'7'!I6+'8'!I6+'9'!I6+'10'!I6+'11'!I6+'12'!I6+'13'!I6+'14'!I6+'15'!I6+'16'!I6+'17'!I6+'18'!I6+'19'!I6+'20'!I6+'21'!I6+'22'!I6+'23'!I6+'24'!I6+'25'!I6+'26'!I6+'27'!I6+'28'!I6+'29'!I6+'30'!I6+'31'!I6 -> 457 | J6: ='1'!J6+'2'!J6+'3'!J6+'4'!J6+'5'!J6+'6'!J6+'7'!J6+'8'!J6+'9'!J6+'10'!J6+'11'!J6+'12'!J6+'13'!J6+'14'!J6+'15'!J6+'16'!J6+'17'!J6+'18'!J6+'19'!J6+'20'!J6+'21'!J6+'22'!J6+'23'!J6+'24'!J6+'25'!J6+'26'!J6+'27'!J6+'28'!J6+'29'!J6+'30'!J6+'31'!J6 -> 383 | K6: ='1'!K6+'2'!K6+'3'!K6+'4'!K6+'5'!K6+'6'!K6+'7'!K6+'8'!K6+'9'!K6+'10'!K6+'11'!K6+'12'!K6+'13'!K6+'14'!K6+'15'!K6+'16'!K6+'17'!K6+'18'!K6+'19'!K6+'20'!K6+'21'!K6+'22'!K6+'23'!K6+'24'!K6+'25'!K6+'26'!K6+'27'!K6+'28'!K6+'29'!K6+'30'!K6+'31'!K6 -> 394 | L6: =SUM(C6:K6)/40 -> 66.275 | M6: =SUMPRODUCT($C$4:$K$4,$C6:$K6) -> 157016.83 | N6: =SUMPRODUCT($C$3:$K$3,$C6:$K6)/1000 -> 242.01 | Q6: =SUMPRODUCT($C$4:$E$4,$C$6:$E$6)*$Q$3 -> 1031.749 | R6: =SUMPRODUCT($F$4:$H$4,$F$6:$H$6)*$R$3 -> 3739.527 | S6: =SUMPRODUCT($I$4:$K$4,$I$6:$K$6)*$S$3 -> 7171.0208 | T6: =SUM(Q6:S6) -> 11942.297 | U6: =SUM(C6:E6)*$U$3 -> 18.41 | V6: =SUM(F6:H6)*$V$3 -> 0 | W6: =SUM(I6:K6)*$W$3 -> 0 | X6: =SUM(U6:W6) -> 18.41 | AB6: =AA6/Z6 -> #DIV/0! | AC6: =M6/AA6 -> #DIV/0! | AF6: =SUM(C6:E6)/40 -> 13.15 | AG6: =SUM(F6:H6)/40 -> 22.275 | AH6: =SUM(E6:G6)/40 -> 14.525 | AJ6: =AF6/SUM(AF6:AH6) -> 0.26326326 | AK6: =AG6/SUM(AF6:AH6) -> 0.44594595 | AL6: =AH6/SUM(AF6:AH6) -> 0.29079079
A7: 2 | B7: salman | C7: ='1'!C7+'2'!C7+'3'!C7+'4'!C7+'5'!C7+'6'!C7+'7'!C7+'8'!C7+'9'!C7+'10'!C7+'11'!C7+'12'!C7+'13'!C7+'14'!C7+'15'!C7+'16'!C7+'17'!C7+'18'!C7+'19'!C7+'20'!C7+'21'!C7+'22'!C7+'23'!C7+'24'!C7+'25'!C7+'26'!C7+'27'!C7+'28'!C7+'29'!C7+'30'!C7+'31'!C7 -> 0 | D7: ='1'!D7+'2'!D7+'3'!D7+'4'!D7+'5'!D7+'6'!D7+'7'!D7+'8'!D7+'9'!D7+'10'!D7+'11'!D7+'12'!D7+'13'!D7+'14'!D7+'15'!D7+'16'!D7+'17'!D7+'18'!D7+'19'!D7+'20'!D7+'21'!D7+'22'!D7+'23'!D7+'24'!D7+'25'!D7+'26'!D7+'27'!D7+'28'!D7+'29'!D7+'30'!D7+'31'!D7 -> 0 | E7: ='1'!E7+'2'!E7+'3'!E7+'4'!E7+'5'!E7+'6'!E7+'7'!E7+'8'!E7+'9'!E7+'10'!E7+'11'!E7+'12'!E7+'13'!E7+'14'!E7+'15'!E7+'16'!E7+'17'!E7+'18'!E7+'19'!E7+'20'!E7+'21'!E7+'22'!E7+'23'!E7+'24'!E7+'25'!E7+'26'!E7+'27'!E7+'28'!E7+'29'!E7+'30'!E7+'31'!E7 -> 0 | F7: ='1'!F7+'2'!F7+'3'!F7+'4'!F7+'5'!F7+'6'!F7+'7'!F7+'8'!F7+'9'!F7+'10'!F7+'11'!F7+'12'!F7+'13'!F7+'14'!F7+'15'!F7+'16'!F7+'17'!F7+'18'!F7+'19'!F7+'20'!F7+'21'!F7+'22'!F7+'23'!F7+'24'!F7+'25'!F7+'26'!F7+'27'!F7+'28'!F7+'29'!F7+'30'!F7+'31'!F7 -> 0 | G7: ='1'!G7+'2'!G7+'3'!G7+'4'!G7+'5'!G7+'6'!G7+'7'!G7+'8'!G7+'9'!G7+'10'!G7+'11'!G7+'12'!G7+'13'!G7+'14'!G7+'15'!G7+'16'!G7+'17'!G7+'18'!G7+'19'!G7+'20'!G7+'21'!G7+'22'!G7+'23'!G7+'24'!G7+'25'!G7+'26'!G7+'27'!G7+'28'!G7+'29'!G7+'30'!G7+'31'!G7 -> 0 | H7: ='1'!H7+'2'!H7+'3'!H7+'4'!H7+'5'!H7+'6'!H7+'7'!H7+'8'!H7+'9'!H7+'10'!H7+'11'!H7+'12'!H7+'13'!H7+'14'!H7+'15'!H7+'16'!H7+'17'!H7+'18'!H7+'19'!H7+'20'!H7+'21'!H7+'22'!H7+'23'!H7+'24'!H7+'25'!H7+'26'!H7+'27'!H7+'28'!H7+'29'!H7+'30'!H7+'31'!H7 -> 0 | I7: ='1'!I7+'2'!I7+'3'!I7+'4'!I7+'5'!I7+'6'!I7+'7'!I7+'8'!I7+'9'!I7+'10'!I7+'11'!I7+'12'!I7+'13'!I7+'14'!I7+'15'!I7+'16'!I7+'17'!I7+'18'!I7+'19'!I7+'20'!I7+'21'!I7+'22'!I7+'23'!I7+'24'!I7+'25'!I7+'26'!I7+'27'!I7+'28'!I7+'29'!I7+'30'!I7+'31'!I7 -> 0 | J7: ='1'!J7+'2'!J7+'3'!J7+'4'!J7+'5'!J7+'6'!J7+'7'!J7+'8'!J7+'9'!J7+'10'!J7+'11'!J7+'12'!J7+'13'!J7+'14'!J7+'15'!J7+'16'!J7+'17'!J7+'18'!J7+'19'!J7+'20'!J7+'21'!J7+'22'!J7+'23'!J7+'24'!J7+'25'!J7+'26'!J7+'27'!J7+'28'!J7+'29'!J7+'30'!J7+'31'!J7 -> 0 | K7: ='1'!K7+'2'!K7+'3'!K7+'4'!K7+'5'!K7+'6'!K7+'7'!K7+'8'!K7+'9'!K7+'10'!K7+'11'!K7+'12'!K7+'13'!K7+'14'!K7+'15'!K7+'16'!K7+'17'!K7+'18'!K7+'19'!K7+'20'!K7+'21'!K7+'22'!K7+'23'!K7+'24'!K7+'25'!K7+'26'!K7+'27'!K7+'28'!K7+'29'!K7+'30'!K7+'31'!K7 -> 0 | L7: =SUM(C7:K7)/40 -> 0 | M7: =SUMPRODUCT($C$4:$K$4,$C7:$K7) -> 0 | N7: =SUMPRODUCT($C$3:$K$3,$C7:$K7)/1000 -> 0 | Q7: =SUMPRODUCT($C$4:$E$4,$C$6:$E$6)*$Q$3 -> 1031.749 | R7: =SUMPRODUCT($F$4:$H$4,$F$6:$H$6)*$R$3 -> 3739.527 | S7: =SUMPRODUCT($I$4:$K$4,$I$6:$K$6)*$S$3 -> 7171.0208 | T7: =SUM(Q7:S7) -> 11942.297 | U7: =SUM(C7:E7)*$U$3 -> 0 | V7: =SUM(F7:H7)*$V$3 -> 0 | W7: =SUM(I7:K7)*$W$3 -> 0 | X7: =SUM(U7:W7) -> 0 | AB7: =AA7/Z7 -> #DIV/0! | AC7: =M7/AA7 -> #DIV/0! | AF7: =SUM(C7:E7)/40 -> 0 | AG7: =SUM(F7:H7)/40 -> 0 | AH7: =SUM(E7:G7)/40 -> 0 | AJ7: =AF7/SUM(AF7:AH7) -> #DIV/0! | AK7: =AG7/SUM(AF7:AH7) -> #DIV/0! | AL7: =AH7/SUM(AF7:AH7) -> #DIV/0!
A8: 3 | B8: zeeshan | C8: ='1'!C8+'2'!C8+'3'!C8+'4'!C8+'5'!C8+'6'!C8+'7'!C8+'8'!C8+'9'!C8+'10'!C8+'11'!C8+'12'!C8+'13'!C8+'14'!C8+'15'!C8+'16'!C8+'17'!C8+'18'!C8+'19'!C8+'20'!C8+'21'!C8+'22'!C8+'23'!C8+'24'!C8+'25'!C8+'26'!C8+'27'!C8+'28'!C8+'29'!C8+'30'!C8+'31'!C8 -> 1136 | D8: ='1'!D8+'2'!D8+'3'!D8+'4'!D8+'5'!D8+'6'!D8+'7'!D8+'8'!D8+'9'!D8+'10'!D8+'11'!D8+'12'!D8+'13'!D8+'14'!D8+'15'!D8+'16'!D8+'17'!D8+'18'!D8+'19'!D8+'20'!D8+'21'!D8+'22'!D8+'23'!D8+'24'!D8+'25'!D8+'26'!D8+'27'!D8+'28'!D8+'29'!D8+'30'!D8+'31'!D8 -> 0 | E8: ='1'!E8+'2'!E8+'3'!E8+'4'!E8+'5'!E8+'6'!E8+'7'!E8+'8'!E8+'9'!E8+'10'!E8+'11'!E8+'12'!E8+'13'!E8+'14'!E8+'15'!E8+'16'!E8+'17'!E8+'18'!E8+'19'!E8+'20'!E8+'21'!E8+'22'!E8+'23'!E8+'24'!E8+'25'!E8+'26'!E8+'27'!E8+'28'!E8+'29'!E8+'30'!E8+'31'!E8 -> 0 | F8: ='1'!F8+'2'!F8+'3'!F8+'4'!F8+'5'!F8+'6'!F8+'7'!F8+'8'!F8+'9'!F8+'10'!F8+'11'!F8+'12'!F8+'13'!F8+'14'!F8+'15'!F8+'16'!F8+'17'!F8+'18'!F8+'19'!F8+'20'!F8+'21'!F8+'22'!F8+'23'!F8+'24'!F8+'25'!F8+'26'!F8+'27'!F8+'28'!F8+'29'!F8+'30'!F8+'31'!F8 -> 675 | G8: ='1'!G8+'2'!G8+'3'!G8+'4'!G8+'5'!G8+'6'!G8+'7'!G8+'8'!G8+'9'!G8+'10'!G8+'11'!G8+'12'!G8+'13'!G8+'14'!G8+'15'!G8+'16'!G8+'17'!G8+'18'!G8+'19'!G8+'20'!G8+'21'!G8+'22'!G8+'23'!G8+'24'!G8+'25'!G8+'26'!G8+'27'!G8+'28'!G8+'29'!G8+'30'!G8+'31'!G8 -> 801 | H8: ='1'!H8+'2'!H8+'3'!H8+'4'!H8+'5'!H8+'6'!H8+'7'!H8+'8'!H8+'9'!H8+'10'!H8+'11'!H8+'12'!H8+'13'!H8+'14'!H8+'15'!H8+'16'!H8+'17'!H8+'18'!H8+'19'!H8+'20'!H8+'21'!H8+'22'!H8+'23'!H8+'24'!H8+'25'!H8+'26'!H8+'27'!H8+'28'!H8+'29'!H8+'30'!H8+'31'!H8 -> 497 | I8: ='1'!I8+'2'!I8+'3'!I8+'4'!I8+'5'!I8+'6'!I8+'7'!I8+'8'!I8+'9'!I8+'10'!I8+'11'!I8+'12'!I8+'13'!I8+'14'!I8+'15'!I8+'16'!I8+'17'!I8+'18'!I8+'19'!I8+'20'!I8+'21'!I8+'22'!I8+'23'!I8+'24'!I8+'25'!I8+'26'!I8+'27'!I8+'28'!I8+'29'!I8+'30'!I8+'31'!I8 -> 2027 | J8: ='1'!J8+'2'!J8+'3'!J8+'4'!J8+'5'!J8+'6'!J8+'7'!J8+'8'!J8+'9'!J8+'10'!J8+'11'!J8+'12'!J8+'13'!J8+'14'!J8+'15'!J8+'16'!J8+'17'!J8+'18'!J8+'19'!J8+'20'!J8+'21'!J8+'22'!J8+'23'!J8+'24'!J8+'25'!J8+'26'!J8+'27'!J8+'28'!J8+'29'!J8+'30'!J8+'31'!J8 -> 1468 | K8: ='1'!K8+'2'!K8+'3'!K8+'4'!K8+'5'!K8+'6'!K8+'7'!K8+'8'!K8+'9'!K8+'10'!K8+'11'!K8+'12'!K8+'13'!K8+'14'!K8+'15'!K8+'16'!K8+'17'!K8+'18'!K8+'19'!K8+'20'!K8+'21'!K8+'22'!K8+'23'!K8+'24'!K8+'25'!K8+'26'!K8+'27'!K8+'28'!K8+'29'!K8+'30'!K8+'31'!K8 -> 2104 | L8: =SUM(C8:K8)/40 -> 217.7 | M8: =SUMPRODUCT($C$4:$K$4,$C8:$K8) -> 554785.15 | N8: =SUMPRODUCT($C$3:$K$3,$C8:$K8)/1000 -> 878.15 | Q8: =SUMPRODUCT($C$4:$E$4,$C$6:$E$6)*$Q$3 -> 1031.749 | R8: =SUMPRODUCT($F$4:$H$4,$F$6:$H$6)*$R$3 -> 3739.527 | S8: =SUMPRODUCT($I$4:$K$4,$I$6:$K$6)*$S$3 -> 7171.0208 | T8: =SUM(Q8:S8) -> 11942.297 | U8: =SUM(C8:E8)*$U$3 -> 39.76 | V8: =SUM(F8:H8)*$V$3 -> 0 | W8: =SUM(I8:K8)*$W$3 -> 0 | X8: =SUM(U8:W8) -> 39.76 | AB8: =AA8/Z8 -> #DIV/0! | AC8: =M8/AA8 -> #DIV/0! | AF8: =SUM(C8:E8)/40 -> 28.4 | AG8: =SUM(F8:H8)/40 -> 49.325 | AH8: =SUM(E8:G8)/40 -> 36.9 | AJ8: =AF8/SUM(AF8:AH8) -> 0.24776445 | AK8: =AG8/SUM(AF8:AH8) -> 0.43031625 | AL8: =AH8/SUM(AF8:AH8) -> 0.3219193
A9: 4 | B9: Furqan Ali | C9: ='1'!C9+'2'!C9+'3'!C9+'4'!C9+'5'!C9+'6'!C9+'7'!C9+'8'!C9+'9'!C9+'10'!C9+'11'!C9+'12'!C9+'13'!C9+'14'!C9+'15'!C9+'16'!C9+'17'!C9+'18'!C9+'19'!C9+'20'!C9+'21'!C9+'22'!C9+'23'!C9+'24'!C9+'25'!C9+'26'!C9+'27'!C9+'28'!C9+'29'!C9+'30'!C9+'31'!C9 -> 294 | D9: ='1'!D9+'2'!D9+'3'!D9+'4'!D9+'5'!D9+'6'!D9+'7'!D9+'8'!D9+'9'!D9+'10'!D9+'11'!D9+'12'!D9+'13'!D9+'14'!D9+'15'!D9+'16'!D9+'17'!D9+'18'!D9+'19'!D9+'20'!D9+'21'!D9+'22'!D9+'23'!D9+'24'!D9+'25'!D9+'26'!D9+'27'!D9+'28'!D9+'29'!D9+'30'!D9+'31'!D9 -> 0 | E9: ='1'!E9+'2'!E9+'3'!E9+'4'!E9+'5'!E9+'6'!E9+'7'!E9+'8'!E9+'9'!E9+'10'!E9+'11'!E9+'12'!E9+'13'!E9+'14'!E9+'15'!E9+'16'!E9+'17'!E9+'18'!E9+'19'!E9+'20'!E9+'21'!E9+'22'!E9+'23'!E9+'24'!E9+'25'!E9+'26'!E9+'27'!E9+'28'!E9+'29'!E9+'30'!E9+'31'!E9 -> 0 | F9: ='1'!F9+'2'!F9+'3'!F9+'4'!F9+'5'!F9+'6'!F9+'7'!F9+'8'!F9+'9'!F9+'10'!F9+'11'!F9+'12'!F9+'13'!F9+'14'!F9+'15'!F9+'16'!F9+'17'!F9+'18'!F9+'19'!F9+'20'!F9+'21'!F9+'22'!F9+'23'!F9+'24'!F9+'25'!F9+'26'!F9+'27'!F9+'28'!F9+'29'!F9+'30'!F9+'31'!F9 -> 318 | G9: ='1'!G9+'2'!G9+'3'!G9+'4'!G9+'5'!G9+'6'!G9+'7'!G9+'8'!G9+'9'!G9+'10'!G9+'11'!G9+'12'!G9+'13'!G9+'14'!G9+'15'!G9+'16'!G9+'17'!G9+'18'!G9+'19'!G9+'20'!G9+'21'!G9+'22'!G9+'23'!G9+'24'!G9+'25'!G9+'26'!G9+'27'!G9+'28'!G9+'29'!G9+'30'!G9+'31'!G9 -> 282 | H9: ='1'!H9+'2'!H9+'3'!H9+'4'!H9+'5'!H9+'6'!H9+'7'!H9+'8'!H9+'9'!H9+'10'!H9+'11'!H9+'12'!H9+'13'!H9+'14'!H9+'15'!H9+'16'!H9+'17'!H9+'18'!H9+'19'!H9+'20'!H9+'21'!H9+'22'!H9+'23'!H9+'24'!H9+'25'!H9+'26'!H9+'27'!H9+'28'!H9+'29'!H9+'30'!H9+'31'!H9 -> 182 | I9: ='1'!I9+'2'!I9+'3'!I9+'4'!I9+'5'!I9+'6'!I9+'7'!I9+'8'!I9+'9'!I9+'10'!I9+'11'!I9+'12'!I9+'13'!I9+'14'!I9+'15'!I9+'16'!I9+'17'!I9+'18'!I9+'19'!I9+'20'!I9+'21'!I9+'22'!I9+'23'!I9+'24'!I9+'25'!I9+'26'!I9+'27'!I9+'28'!I9+'29'!I9+'30'!I9+'31'!I9 -> 681 | J9: ='1'!J9+'2'!J9+'3'!J9+'4'!J9+'5'!J9+'6'!J9+'7'!J9+'8'!J9+'9'!J9+'10'!J9+'11'!J9+'12'!J9+'13'!J9+'14'!J9+'15'!J9+'16'!J9+'17'!J9+'18'!J9+'19'!J9+'20'!J9+'21'!J9+'22'!J9+'23'!J9+'24'!J9+'25'!J9+'26'!J9+'27'!J9+'28'!J9+'29'!J9+'30'!J9+'31'!J9 -> 472 | K9: ='1'!K9+'2'!K9+'3'!K9+'4'!K9+'5'!K9+'6'!K9+'7'!K9+'8'!K9+'9'!K9+'10'!K9+'11'!K9+'12'!K9+'13'!K9+'14'!K9+'15'!K9+'16'!K9+'17'!K9+'18'!K9+'19'!K9+'20'!K9+'21'!K9+'22'!K9+'23'!K9+'24'!K9+'25'!K9+'26'!K9+'27'!K9+'28'!K9+'29'!K9+'30'!K9+'31'!K9 -> 595 | L9: =SUM(C9:K9)/40 -> 70.6 | M9: =SUMPRODUCT($C$4:$K$4,$C9:$K9) -> 179534.02 | N9: =SUMPRODUCT($C$3:$K$3,$C9:$K9)/1000 -> 282.14 | Q9: =SUMPRODUCT($C$4:$E$4,$C$6:$E$6)*$Q$3 -> 1031.749 | R9: =SUMPRODUCT($F$4:$H$4,$F$6:$H$6)*$R$3 -> 3739.527 | S9: =SUMPRODUCT($I$4:$K$4,$I$6:$K$6)*$S$3 -> 7171.0208 | T9: =SUM(Q9:S9) -> 11942.297 | U9: =SUM(C9:E9)*$U$3 -> 10.29 | V9: =SUM(F9:H9)*$V$3 -> 0 | W9: =SUM(I9:K9)*$W$3 -> 0 | X9: =SUM(U9:W9) -> 10.29 | AB9: =AA9/Z9 -> #DIV/0! | AC9: =M9/AA9 -> #DIV/0! | AF9: =SUM(C9:E9)/40 -> 7.35 | AG9: =SUM(F9:H9)/40 -> 19.55 | AH9: =SUM(E9:G9)/40 -> 15 | AJ9: =AF9/SUM(AF9:AH9) -> 0.17541766 | AK9: =AG9/SUM(AF9:AH9) -> 0.46658711 | AL9: =AH9/SUM(AF9:AH9) -> 0.35799523
A10: 5 | B10: Salman Butt | C10: ='1'!C10+'2'!C10+'3'!C10+'4'!C10+'5'!C10+'6'!C10+'7'!C10+'8'!C10+'9'!C10+'10'!C10+'11'!C10+'12'!C10+'13'!C10+'14'!C10+'15'!C10+'16'!C10+'17'!C10+'18'!C10+'19'!C10+'20'!C10+'21'!C10+'22'!C10+'23'!C10+'24'!C10+'25'!C10+'26'!C10+'27'!C10+'28'!C10+'29'!C10+'30'!C10+'31'!C10 -> 934 | D10: ='1'!D10+'2'!D10+'3'!D10+'4'!D10+'5'!D10+'6'!D10+'7'!D10+'8'!D10+'9'!D10+'10'!D10+'11'!D10+'12'!D10+'13'!D10+'14'!D10+'15'!D10+'16'!D10+'17'!D10+'18'!D10+'19'!D10+'20'!D10+'21'!D10+'22'!D10+'23'!D10+'24'!D10+'25'!D10+'26'!D10+'27'!D10+'28'!D10+'29'!D10+'30'!D10+'31'!D10 -> 0 | E10: ='1'!E10+'2'!E10+'3'!E10+'4'!E10+'5'!E10+'6'!E10+'7'!E10+'8'!E10+'9'!E10+'10'!E10+'11'!E10+'12'!E10+'13'!E10+'14'!E10+'15'!E10+'16'!E10+'17'!E10+'18'!E10+'19'!E10+'20'!E10+'21'!E10+'22'!E10+'23'!E10+'24'!E10+'25'!E10+'26'!E10+'27'!E10+'28'!E10+'29'!E10+'30'!E10+'31'!E10 -> 0 | F10: ='1'!F10+'2'!F10+'3'!F10+'4'!F10+'5'!F10+'6'!F10+'7'!F10+'8'!F10+'9'!F10+'10'!F10+'11'!F10+'12'!F10+'13'!F10+'14'!F10+'15'!F10+'16'!F10+'17'!F10+'18'!F10+'19'!F10+'20'!F10+'21'!F10+'22'!F10+'23'!F10+'24'!F10+'25'!F10+'26'!F10+'27'!F10+'28'!F10+'29'!F10+'30'!F10+'31'!F10 -> 686 | G10: ='1'!G10+'2'!G10+'3'!G10+'4'!G10+'5'!G10+'6'!G10+'7'!G10+'8'!G10+'9'!G10+'10'!G10+'11'!G10+'12'!G10+'13'!G10+'14'!G10+'15'!G10+'16'!G10+'17'!G10+'18'!G10+'19'!G10+'20'!G10+'21'!G10+'22'!G10+'23'!G10+'24'!G10+'25'!G10+'26'!G10+'27'!G10+'28'!G10+'29'!G10+'30'!G10+'31'!G10 -> 609 | H10: ='1'!H10+'2'!H10+'3'!H10+'4'!H10+'5'!H10+'6'!H10+'7'!H10+'8'!H10+'9'!H10+'10'!H10+'11'!H10+'12'!H10+'13'!H10+'14'!H10+'15'!H10+'16'!H10+'17'!H10+'18'!H10+'19'!H10+'20'!H10+'21'!H10+'22'!H10+'23'!H10+'24'!H10+'25'!H10+'26'!H10+'27'!H10+'28'!H10+'29'!H10+'30'!H10+'31'!H10 -> 572 | I10: ='1'!I10+'2'!I10+'3'!I10+'4'!I10+'5'!I10+'6'!I10+'7'!I10+'8'!I10+'9'!I10+'10'!I10+'11'!I10+'12'!I10+'13'!I10+'14'!I10+'15'!I10+'16'!I10+'17'!I10+'18'!I10+'19'!I10+'20'!I10+'21'!I10+'22'!I10+'23'!I10+'24'!I10+'25'!I10+'26'!I10+'27'!I10+'28'!I10+'29'!I10+'30'!I10+'31'!I10 -> 851 | J10: ='1'!J10+'2'!J10+'3'!J10+'4'!J10+'5'!J10+'6'!J10+'7'!J10+'8'!J10+'9'!J10+'10'!J10+'11'!J10+'12'!J10+'13'!J10+'14'!J10+'15'!J10+'16'!J10+'17'!J10+'18'!J10+'19'!J10+'20'!J10+'21'!J10+'22'!J10+'23'!J10+'24'!J10+'25'!J10+'26'!J10+'27'!J10+'28'!J10+'29'!J10+'30'!J10+'31'!J10 -> 764 | K10: ='1'!K10+'2'!K10+'3'!K10+'4'!K10+'5'!K10+'6'!K10+'7'!K10+'8'!K10+'9'!K10+'10'!K10+'11'!K10+'12'!K10+'13'!K10+'14'!K10+'15'!K10+'16'!K10+'17'!K10+'18'!K10+'19'!K10+'20'!K10+'21'!K10+'22'!K10+'23'!K10+'24'!K10+'25'!K10+'26'!K10+'27'!K10+'28'!K10+'29'!K10+'30'!K10+'31'!K10 -> 856 | L10: =SUM(C10:K10)/40 -> 131.8 | M10: =SUMPRODUCT($C$4:$K$4,$C10:$K10) -> 314081.75 | N10: =SUMPRODUCT($C$3:$K$3,$C10:$K10)/1000 -> 483.25 | Q10: =SUMPRODUCT($C$4:$E$4,$C$6:$E$6)*$Q$3 -> 1031.749 | R10: =SUMPRODUCT($F$4:$H$4,$F$6:$H$6)*$R$3 -> 3739.527 | S10: =SUMPRODUCT($I$4:$K$4,$I$6:$K$6)*$S$3 -> 7171.0208 | T10: =SUM(Q10:S10) -> 11942.297 | U10: =SUM(C10:E10)*$U$3 -> 32.69 | V10: =SUM(F10:H10)*$V$3 -> 0 | W10: =SUM(I10:K10)*$W$3 -> 0 | X10: =SUM(U10:W10) -> 32.69 | AB10: =AA10/Z10 -> #DIV/0! | AC10: =M10/AA10 -> #DIV/0! | AF10: =SUM(C10:E10)/40 -> 23.35 | AG10: =SUM(F10:H10)/40 -> 46.675 | AH10: =SUM(E10:G10)/40 -> 32.375 | AJ10: =AF10/SUM(AF10:AH10) -> 0.22802734 | AK10: =AG10/SUM(AF10:AH10) -> 0.45581055 | AL10: =AH10/SUM(AF10:AH10) -> 0.31616211
A11: 6 | B11: Mobeen | C11: ='1'!C11+'2'!C11+'3'!C11+'4'!C11+'5'!C11+'6'!C11+'7'!C11+'8'!C11+'9'!C11+'10'!C11+'11'!C11+'12'!C11+'13'!C11+'14'!C11+'15'!C11+'16'!C11+'17'!C11+'18'!C11+'19'!C11+'20'!C11+'21'!C11+'22'!C11+'23'!C11+'24'!C11+'25'!C11+'26'!C11+'27'!C11+'28'!C11+'29'!C11+'30'!C11+'31'!C11 -> 473 | D11: ='1'!D11+'2'!D11+'3'!D11+'4'!D11+'5'!D11+'6'!D11+'7'!D11+'8'!D11+'9'!D11+'10'!D11+'11'!D11+'12'!D11+'13'!D11+'14'!D11+'15'!D11+'16'!D11+'17'!D11+'18'!D11+'19'!D11+'20'!D11+'21'!D11+'22'!D11+'23'!D11+'24'!D11+'25'!D11+'26'!D11+'27'!D11+'28'!D11+'29'!D11+'30'!D11+'31'!D11 -> 0 | E11: ='1'!E11+'2'!E11+'3'!E11+'4'!E11+'5'!E11+'6'!E11+'7'!E11+'8'!E11+'9'!E11+'10'!E11+'11'!E11+'12'!E11+'13'!E11+'14'!E11+'15'!E11+'16'!E11+'17'!E11+'18'!E11+'19'!E11+'20'!E11+'21'!E11+'22'!E11+'23'!E11+'24'!E11+'25'!E11+'26'!E11+'27'!E11+'28'!E11+'29'!E11+'30'!E11+'31'!E11 -> 0 | F11: ='1'!F11+'2'!F11+'3'!F11+'4'!F11+'5'!F11+'6'!F11+'7'!F11+'8'!F11+'9'!F11+'10'!F11+'11'!F11+'12'!F11+'13'!F11+'14'!F11+'15'!F11+'16'!F11+'17'!F11+'18'!F11+'19'!F11+'20'!F11+'21'!F11+'22'!F11+'23'!F11+'24'!F11+'25'!F11+'26'!F11+'27'!F11+'28'!F11+'29'!F11+'30'!F11+'31'!F11 -> 350 | G11: ='1'!G11+'2'!G11+'3'!G11+'4'!G11+'5'!G11+'6'!G11+'7'!G11+'8'!G11+'9'!G11+'10'!G11+'11'!G11+'12'!G11+'13'!G11+'14'!G11+'15'!G11+'16'!G11+'17'!G11+'18'!G11+'19'!G11+'20'!G11+'21'!G11+'22'!G11+'23'!G11+'24'!G11+'25'!G11+'26'!G11+'27'!G11+'28'!G11+'29'!G11+'30'!G11+'31'!G11 -> 388 | H11: ='1'!H11+'2'!H11+'3'!H11+'4'!H11+'5'!H11+'6'!H11+'7'!H11+'8'!H11+'9'!H11+'10'!H11+'11'!H11+'12'!H11+'13'!H11+'14'!H11+'15'!H11+'16'!H11+'17'!H11+'18'!H11+'19'!H11+'20'!H11+'21'!H11+'22'!H11+'23'!H11+'24'!H11+'25'!H11+'26'!H11+'27'!H11+'28'!H11+'29'!H11+'30'!H11+'31'!H11 -> 448 | I11: ='1'!I11+'2'!I11+'3'!I11+'4'!I11+'5'!I11+'6'!I11+'7'!I11+'8'!I11+'9'!I11+'10'!I11+'11'!I11+'12'!I11+'13'!I11+'14'!I11+'15'!I11+'16'!I11+'17'!I11+'18'!I11+'19'!I11+'20'!I11+'21'!I11+'22'!I11+'23'!I11+'24'!I11+'25'!I11+'26'!I11+'27'!I11+'28'!I11+'29'!I11+'30'!I11+'31'!I11 -> 728 | J11: ='1'!J11+'2'!J11+'3'!J11+'4'!J11+'5'!J11+'6'!J11+'7'!J11+'8'!J11+'9'!J11+'10'!J11+'11'!J11+'12'!J11+'13'!J11+'14'!J11+'15'!J11+'16'!J11+'17'!J11+'18'!J11+'19'!J11+'20'!J11+'21'!J11+'22'!J11+'23'!J11+'24'!J11+'25'!J11+'26'!J11+'27'!J11+'28'!J11+'29'!J11+'30'!J11+'31'!J11 -> 708 | K11: ='1'!K11+'2'!K11+'3'!K11+'4'!K11+'5'!K11+'6'!K11+'7'!K11+'8'!K11+'9'!K11+'10'!K11+'11'!K11+'12'!K11+'13'!K11+'14'!K11+'15'!K11+'16'!K11+'17'!K11+'18'!K11+'19'!K11+'20'!K11+'21'!K11+'22'!K11+'23'!K11+'24'!K11+'25'!K11+'26'!K11+'27'!K11+'28'!K11+'29'!K11+'30'!K11+'31'!K11 -> 925 | L11: =SUM(C11:K11)/40 -> 100.5 | M11: =SUMPRODUCT($C$4:$K$4,$C11:$K11) -> 252279.35 | N11: =SUMPRODUCT($C$3:$K$3,$C11:$K11)/1000 -> 394.72 | Q11: =SUMPRODUCT($C$4:$E$4,$C$6:$E$6)*$Q$3 -> 1031.749 | R11: =SUMPRODUCT($F$4:$H$4,$F$6:$H$6)*$R$3 -> 3739.527 | S11: =SUMPRODUCT($I$4:$K$4,$I$6:$K$6)*$S$3 -> 7171.0208 | T11: =SUM(Q11:S11) -> 11942.297 | U11: =SUM(C11:E11)*$U$3 -> 16.555 | V11: =SUM(F11:H11)*$V$3 -> 0 | W11: =SUM(I11:K11)*$W$3 -> 0 | X11: =SUM(U11:W11) -> 16.555 | AB11: =AA11/Z11 -> #DIV/0! | AC11: =M11/AA11 -> #DIV/0! | AF11: =SUM(C11:E11)/40 -> 11.825 | AG11: =SUM(F11:H11)/40 -> 29.65 | AH11: =SUM(E11:G11)/40 -> 18.45 | AJ11: =AF11/SUM(AF11:AH11) -> 0.19733 | AK11: =AG11/SUM(AF11:AH11) -> 0.49478515 | AL11: =AH11/SUM(AF11:AH11) -> 0.30788486
A12: 7 | B12: Umair Rehman | C12: ='1'!C12+'2'!C12+'3'!C12+'4'!C12+'5'!C12+'6'!C12+'7'!C12+'8'!C12+'9'!C12+'10'!C12+'11'!C12+'12'!C12+'13'!C12+'14'!C12+'15'!C12+'16'!C12+'17'!C12+'18'!C12+'19'!C12+'20'!C12+'21'!C12+'22'!C12+'23'!C12+'24'!C12+'25'!C12+'26'!C12+'27'!C12+'28'!C12+'29'!C12+'30'!C12+'31'!C12 -> 212 | D12: ='1'!D12+'2'!D12+'3'!D12+'4'!D12+'5'!D12+'6'!D12+'7'!D12+'8'!D12+'9'!D12+'10'!D12+'11'!D12+'12'!D12+'13'!D12+'14'!D12+'15'!D12+'16'!D12+'17'!D12+'18'!D12+'19'!D12+'20'!D12+'21'!D12+'22'!D12+'23'!D12+'24'!D12+'25'!D12+'26'!D12+'27'!D12+'28'!D12+'29'!D12+'30'!D12+'31'!D12 -> 0 | E12: ='1'!E12+'2'!E12+'3'!E12+'4'!E12+'5'!E12+'6'!E12+'7'!E12+'8'!E12+'9'!E12+'10'!E12+'11'!E12+'12'!E12+'13'!E12+'14'!E12+'15'!E12+'16'!E12+'17'!E12+'18'!E12+'19'!E12+'20'!E12+'21'!E12+'22'!E12+'23'!E12+'24'!E12+'25'!E12+'26'!E12+'27'!E12+'28'!E12+'29'!E12+'30'!E12+'31'!E12 -> 0 | F12: ='1'!F12+'2'!F12+'3'!F12+'4'!F12+'5'!F12+'6'!F12+'7'!F12+'8'!F12+'9'!F12+'10'!F12+'11'!F12+'12'!F12+'13'!F12+'14'!F12+'15'!F12+'16'!F12+'17'!F12+'18'!F12+'19'!F12+'20'!F12+'21'!F12+'22'!F12+'23'!F12+'24'!F12+'25'!F12+'26'!F12+'27'!F12+'28'!F12+'29'!F12+'30'!F12+'31'!F12 -> 32 | G12: ='1'!G12+'2'!G12+'3'!G12+'4'!G12+'5'!G12+'6'!G12+'7'!G12+'8'!G12+'9'!G12+'10'!G12+'11'!G12+'12'!G12+'13'!G12+'14'!G12+'15'!G12+'16'!G12+'17'!G12+'18'!G12+'19'!G12+'20'!G12+'21'!G12+'22'!G12+'23'!G12+'24'!G12+'25'!G12+'26'!G12+'27'!G12+'28'!G12+'29'!G12+'30'!G12+'31'!G12 -> 32 | H12: ='1'!H12+'2'!H12+'3'!H12+'4'!H12+'5'!H12+'6'!H12+'7'!H12+'8'!H12+'9'!H12+'10'!H12+'11'!H12+'12'!H12+'13'!H12+'14'!H12+'15'!H12+'16'!H12+'17'!H12+'18'!H12+'19'!H12+'20'!H12+'21'!H12+'22'!H12+'23'!H12+'24'!H12+'25'!H12+'26'!H12+'27'!H12+'28'!H12+'29'!H12+'30'!H12+'31'!H12 -> 12 | I12: ='1'!I12+'2'!I12+'3'!I12+'4'!I12+'5'!I12+'6'!I12+'7'!I12+'8'!I12+'9'!I12+'10'!I12+'11'!I12+'12'!I12+'13'!I12+'14'!I12+'15'!I12+'16'!I12+'17'!I12+'18'!I12+'19'!I12+'20'!I12+'21'!I12+'22'!I12+'23'!I12+'24'!I12+'25'!I12+'26'!I12+'27'!I12+'28'!I12+'29'!I12+'30'!I12+'31'!I12 -> 66 | J12: ='1'!J12+'2'!J12+'3'!J12+'4'!J12+'5'!J12+'6'!J12+'7'!J12+'8'!J12+'9'!J12+'10'!J12+'11'!J12+'12'!J12+'13'!J12+'14'!J12+'15'!J12+'16'!J12+'17'!J12+'18'!J12+'19'!J12+'20'!J12+'21'!J12+'22'!J12+'23'!J12+'24'!J12+'25'!J12+'26'!J12+'27'!J12+'28'!J12+'29'!J12+'30'!J12+'31'!J12 -> 36 | K12: ='1'!K12+'2'!K12+'3'!K12+'4'!K12+'5'!K12+'6'!K12+'7'!K12+'8'!K12+'9'!K12+'10'!K12+'11'!K12+'12'!K12+'13'!K12+'14'!K12+'15'!K12+'16'!K12+'17'!K12+'18'!K12+'19'!K12+'20'!K12+'21'!K12+'22'!K12+'23'!K12+'24'!K12+'25'!K12+'26'!K12+'27'!K12+'28'!K12+'29'!K12+'30'!K12+'31'!K12 -> 37 | L12: =SUM(C12:K12)/40 -> 10.675 | M12: =SUMPRODUCT($C$4:$K$4,$C12:$K12) -> 22400.87 | N12: =SUMPRODUCT($C$3:$K$3,$C12:$K12)/1000 -> 34.72 | Q12: =SUMPRODUCT($C$4:$E$4,$C$6:$E$6)*$Q$3 -> 1031.749 | R12: =SUMPRODUCT($F$4:$H$4,$F$6:$H$6)*$R$3 -> 3739.527 | S12: =SUMPRODUCT($I$4:$K$4,$I$6:$K$6)*$S$3 -> 7171.0208 | T12: =SUM(Q12:S12) -> 11942.297 | U12: =SUM(C12:E12)*$U$3 -> 7.42 | V12: =SUM(F12:H12)*$V$3 -> 0 | W12: =SUM(I12:K12)*$W$3 -> 0 | X12: =SUM(U12:W12) -> 7.42 | AB12: =AA12/Z12 -> #DIV/0! | AC12: =M12/AA12 -> #DIV/0!
A13: 8 | B13: Umer Nawaz | C13: ='1'!C13+'2'!C13+'3'!C13+'4'!C13+'5'!C13+'6'!C13+'7'!C13+'8'!C13+'9'!C13+'10'!C13+'11'!C13+'12'!C13+'13'!C13+'14'!C13+'15'!C13+'16'!C13+'17'!C13+'18'!C13+'19'!C13+'20'!C13+'21'!C13+'22'!C13+'23'!C13+'24'!C13+'25'!C13+'26'!C13+'27'!C13+'28'!C13+'29'!C13+'30'!C13+'31'!C13 -> 0 | D13: ='1'!D13+'2'!D13+'3'!D13+'4'!D13+'5'!D13+'6'!D13+'7'!D13+'8'!D13+'9'!D13+'10'!D13+'11'!D13+'12'!D13+'13'!D13+'14'!D13+'15'!D13+'16'!D13+'17'!D13+'18'!D13+'19'!D13+'20'!D13+'21'!D13+'22'!D13+'23'!D13+'24'!D13+'25'!D13+'26'!D13+'27'!D13+'28'!D13+'29'!D13+'30'!D13+'31'!D13 -> 0 | E13: ='1'!E13+'2'!E13+'3'!E13+'4'!E13+'5'!E13+'6'!E13+'7'!E13+'8'!E13+'9'!E13+'10'!E13+'11'!E13+'12'!E13+'13'!E13+'14'!E13+'15'!E13+'16'!E13+'17'!E13+'18'!E13+'19'!E13+'20'!E13+'21'!E13+'22'!E13+'23'!E13+'24'!E13+'25'!E13+'26'!E13+'27'!E13+'28'!E13+'29'!E13+'30'!E13+'31'!E13 -> 0 | F13: ='1'!F13+'2'!F13+'3'!F13+'4'!F13+'5'!F13+'6'!F13+'7'!F13+'8'!F13+'9'!F13+'10'!F13+'11'!F13+'12'!F13+'13'!F13+'14'!F13+'15'!F13+'16'!F13+'17'!F13+'18'!F13+'19'!F13+'20'!F13+'21'!F13+'22'!F13+'23'!F13+'24'!F13+'25'!F13+'26'!F13+'27'!F13+'28'!F13+'29'!F13+'30'!F13+'31'!F13 -> 0 | G13: ='1'!G13+'2'!G13+'3'!G13+'4'!G13+'5'!G13+'6'!G13+'7'!G13+'8'!G13+'9'!G13+'10'!G13+'11'!G13+'12'!G13+'13'!G13+'14'!G13+'15'!G13+'16'!G13+'17'!G13+'18'!G13+'19'!G13+'20'!G13+'21'!G13+'22'!G13+'23'!G13+'24'!G13+'25'!G13+'26'!G13+'27'!G13+'28'!G13+'29'!G13+'30'!G13+'31'!G13 -> 0 | H13: ='1'!H13+'2'!H13+'3'!H13+'4'!H13+'5'!H13+'6'!H13+'7'!H13+'8'!H13+'9'!H13+'10'!H13+'11'!H13+'12'!H13+'13'!H13+'14'!H13+'15'!H13+'16'!H13+'17'!H13+'18'!H13+'19'!H13+'20'!H13+'21'!H13+'22'!H13+'23'!H13+'24'!H13+'25'!H13+'26'!H13+'27'!H13+'28'!H13+'29'!H13+'30'!H13+'31'!H13 -> 0 | I13: ='1'!I13+'2'!I13+'3'!I13+'4'!I13+'5'!I13+'6'!I13+'7'!I13+'8'!I13+'9'!I13+'10'!I13+'11'!I13+'12'!I13+'13'!I13+'14'!I13+'15'!I13+'16'!I13+'17'!I13+'18'!I13+'19'!I13+'20'!I13+'21'!I13+'22'!I13+'23'!I13+'24'!I13+'25'!I13+'26'!I13+'27'!I13+'28'!I13+'29'!I13+'30'!I13+'31'!I13 -> 0 | J13: ='1'!J13+'2'!J13+'3'!J13+'4'!J13+'5'!J13+'6'!J13+'7'!J13+'8'!J13+'9'!J13+'10'!J13+'11'!J13+'12'!J13+'13'!J13+'14'!J13+'15'!J13+'16'!J13+'17'!J13+'18'!J13+'19'!J13+'20'!J13+'21'!J13+'22'!J13+'23'!J13+'24'!J13+'25'!J13+'26'!J13+'27'!J13+'28'!J13+'29'!J13+'30'!J13+'31'!J13 -> 0 | K13: ='1'!K13+'2'!K13+'3'!K13+'4'!K13+'5'!K13+'6'!K13+'7'!K13+'8'!K13+'9'!K13+'10'!K13+'11'!K13+'12'!K13+'13'!K13+'14'!K13+'15'!K13+'16'!K13+'17'!K13+'18'!K13+'19'!K13+'20'!K13+'21'!K13+'22'!K13+'23'!K13+'24'!K13+'25'!K13+'26'!K13+'27'!K13+'28'!K13+'29'!K13+'30'!K13+'31'!K13 -> 0 | L13: =SUM(C13:K13)/40 -> 0 | M13: =SUMPRODUCT($C$4:$K$4,$C13:$K13) -> 0 | N13: =SUMPRODUCT($C$3:$K$3,$C13:$K13)/1000 -> 0 | Q13: =SUMPRODUCT($C$4:$E$4,$C$6:$E$6)*$Q$3 -> 1031.749 | R13: =SUMPRODUCT($F$4:$H$4,$F$6:$H$6)*$R$3 -> 3739.527 | S13: =SUMPRODUCT($I$4:$K$4,$I$6:$K$6)*$S$3 -> 7171.0208 | T13: =SUM(Q13:S13) -> 11942.297 | U13: =SUM(C13:E13)*$U$3 -> 0 | V13: =SUM(F13:H13)*$V$3 -> 0 | W13: =SUM(I13:K13)*$W$3 -> 0 | X13: =SUM(U13:W13) -> 0 | AB13: =AA13/Z13 -> #DIV/0! | AC13: =M13/AA13 -> #DIV/0!
A14: 9 | B14: Shakoor (LMT) | C14: ='1'!C14+'2'!C14+'3'!C14+'4'!C14+'5'!C14+'6'!C14+'7'!C14+'8'!C14+'9'!C14+'10'!C14+'11'!C14+'12'!C14+'13'!C14+'14'!C14+'15'!C14+'16'!C14+'17'!C14+'18'!C14+'19'!C14+'20'!C14+'21'!C14+'22'!C14+'23'!C14+'24'!C14+'25'!C14+'26'!C14+'27'!C14+'28'!C14+'29'!C14+'30'!C14+'31'!C14 -> 1360 | D14: ='1'!D14+'2'!D14+'3'!D14+'4'!D14+'5'!D14+'6'!D14+'7'!D14+'8'!D14+'9'!D14+'10'!D14+'11'!D14+'12'!D14+'13'!D14+'14'!D14+'15'!D14+'16'!D14+'17'!D14+'18'!D14+'19'!D14+'20'!D14+'21'!D14+'22'!D14+'23'!D14+'24'!D14+'25'!D14+'26'!D14+'27'!D14+'28'!D14+'29'!D14+'30'!D14+'31'!D14 -> 0 | E14: ='1'!E14+'2'!E14+'3'!E14+'4'!E14+'5'!E14+'6'!E14+'7'!E14+'8'!E14+'9'!E14+'10'!E14+'11'!E14+'12'!E14+'13'!E14+'14'!E14+'15'!E14+'16'!E14+'17'!E14+'18'!E14+'19'!E14+'20'!E14+'21'!E14+'22'!E14+'23'!E14+'24'!E14+'25'!E14+'26'!E14+'27'!E14+'28'!E14+'29'!E14+'30'!E14+'31'!E14 -> 0 | F14: ='1'!F14+'2'!F14+'3'!F14+'4'!F14+'5'!F14+'6'!F14+'7'!F14+'8'!F14+'9'!F14+'10'!F14+'11'!F14+'12'!F14+'13'!F14+'14'!F14+'15'!F14+'16'!F14+'17'!F14+'18'!F14+'19'!F14+'20'!F14+'21'!F14+'22'!F14+'23'!F14+'24'!F14+'25'!F14+'26'!F14+'27'!F14+'28'!F14+'29'!F14+'30'!F14+'31'!F14 -> 8254 | G14: ='1'!G14+'2'!G14+'3'!G14+'4'!G14+'5'!G14+'6'!G14+'7'!G14+'8'!G14+'9'!G14+'10'!G14+'11'!G14+'12'!G14+'13'!G14+'14'!G14+'15'!G14+'16'!G14+'17'!G14+'18'!G14+'19'!G14+'20'!G14+'21'!G14+'22'!G14+'23'!G14+'24'!G14+'25'!G14+'26'!G14+'27'!G14+'28'!G14+'29'!G14+'30'!G14+'31'!G14 -> 8690 | H14: ='1'!H14+'2'!H14+'3'!H14+'4'!H14+'5'!H14+'6'!H14+'7'!H14+'8'!H14+'9'!H14+'10'!H14+'11'!H14+'12'!H14+'13'!H14+'14'!H14+'15'!H14+'16'!H14+'17'!H14+'18'!H14+'19'!H14+'20'!H14+'21'!H14+'22'!H14+'23'!H14+'24'!H14+'25'!H14+'26'!H14+'27'!H14+'28'!H14+'29'!H14+'30'!H14+'31'!H14 -> 12165 | I14: ='1'!I14+'2'!I14+'3'!I14+'4'!I14+'5'!I14+'6'!I14+'7'!I14+'8'!I14+'9'!I14+'10'!I14+'11'!I14+'12'!I14+'13'!I14+'14'!I14+'15'!I14+'16'!I14+'17'!I14+'18'!I14+'19'!I14+'20'!I14+'21'!I14+'22'!I14+'23'!I14+'24'!I14+'25'!I14+'26'!I14+'27'!I14+'28'!I14+'29'!I14+'30'!I14+'31'!I14 -> 12767 | J14: ='1'!J14+'2'!J14+'3'!J14+'4'!J14+'5'!J14+'6'!J14+'7'!J14+'8'!J14+'9'!J14+'10'!J14+'11'!J14+'12'!J14+'13'!J14+'14'!J14+'15'!J14+'16'!J14+'17'!J14+'18'!J14+'19'!J14+'20'!J14+'21'!J14+'22'!J14+'23'!J14+'24'!J14+'25'!J14+'26'!J14+'27'!J14+'28'!J14+'29'!J14+'30'!J14+'31'!J14 -> 10715 | K14: ='1'!K14+'2'!K14+'3'!K14+'4'!K14+'5'!K14+'6'!K14+'7'!K14+'8'!K14+'9'!K14+'10'!K14+'11'!K14+'12'!K14+'13'!K14+'14'!K14+'15'!K14+'16'!K14+'17'!K14+'18'!K14+'19'!K14+'20'!K14+'21'!K14+'22'!K14+'23'!K14+'24'!K14+'25'!K14+'26'!K14+'27'!K14+'28'!K14+'29'!K14+'30'!K14+'31'!K14 -> 15015 | L14: =SUM(C14:K14)/40 -> 1724.15 | M14: =SUMPRODUCT($C$4:$K$4,$C14:$K14) -> 4376905.8 | N14: =SUMPRODUCT($C$3:$K$3,$C14:$K14)/1000 -> 6738.87 | Q14: =SUMPRODUCT($C$4:$E$4,$C$6:$E$6)*$Q$3 -> 1031.749 | R14: =SUMPRODUCT($F$4:$H$4,$F$6:$H$6)*$R$3 -> 3739.527 | S14: =SUMPRODUCT($I$4:$K$4,$I$6:$K$6)*$S$3 -> 7171.0208 | T14: =SUM(Q14:S14) -> 11942.297 | U14: =SUM(C14:E14)*$U$3 -> 47.6 | V14: =SUM(F14:H14)*$V$3 -> 0 | W14: =SUM(I14:K14)*$W$3 -> 0 | X14: =SUM(U14:W14) -> 47.6 | AB14: =AA14/Z14 -> #DIV/0! | AC14: =M14/AA14 -> #DIV/0! | AF14: =SUM(C14:E14)/40 -> 34 | AG14: =SUM(F14:H14)/40 -> 727.725 | AH14: =SUM(E14:G14)/40 -> 423.6 | AJ14: =AF14/SUM(AF14:AH14) -> 0.028684116 | AK14: =AG14/SUM(AF14:AH14) -> 0.61394554 | AL14: =AH14/SUM(AF14:AH14) -> 0.35737034
A15: 10 | B15: Nabeel Traders | C15: ='1'!C15+'2'!C15+'3'!C15+'4'!C15+'5'!C15+'6'!C15+'7'!C15+'8'!C15+'9'!C15+'10'!C15+'11'!C15+'12'!C15+'13'!C15+'14'!C15+'15'!C15+'16'!C15+'17'!C15+'18'!C15+'19'!C15+'20'!C15+'21'!C15+'22'!C15+'23'!C15+'24'!C15+'25'!C15+'26'!C15+'27'!C15+'28'!C15+'29'!C15+'30'!C15+'31'!C15 -> 0 | D15: ='1'!D15+'2'!D15+'3'!D15+'4'!D15+'5'!D15+'6'!D15+'7'!D15+'8'!D15+'9'!D15+'10'!D15+'11'!D15+'12'!D15+'13'!D15+'14'!D15+'15'!D15+'16'!D15+'17'!D15+'18'!D15+'19'!D15+'20'!D15+'21'!D15+'22'!D15+'23'!D15+'24'!D15+'25'!D15+'26'!D15+'27'!D15+'28'!D15+'29'!D15+'30'!D15+'31'!D15 -> 0 | E15: ='1'!E15+'2'!E15+'3'!E15+'4'!E15+'5'!E15+'6'!E15+'7'!E15+'8'!E15+'9'!E15+'10'!E15+'11'!E15+'12'!E15+'13'!E15+'14'!E15+'15'!E15+'16'!E15+'17'!E15+'18'!E15+'19'!E15+'20'!E15+'21'!E15+'22'!E15+'23'!E15+'24'!E15+'25'!E15+'26'!E15+'27'!E15+'28'!E15+'29'!E15+'30'!E15+'31'!E15 -> 0 | F15: ='1'!F15+'2'!F15+'3'!F15+'4'!F15+'5'!F15+'6'!F15+'7'!F15+'8'!F15+'9'!F15+'10'!F15+'11'!F15+'12'!F15+'13'!F15+'14'!F15+'15'!F15+'16'!F15+'17'!F15+'18'!F15+'19'!F15+'20'!F15+'21'!F15+'22'!F15+'23'!F15+'24'!F15+'25'!F15+'26'!F15+'27'!F15+'28'!F15+'29'!F15+'30'!F15+'31'!F15 -> 1880 | G15: ='1'!G15+'2'!G15+'3'!G15+'4'!G15+'5'!G15+'6'!G15+'7'!G15+'8'!G15+'9'!G15+'10'!G15+'11'!G15+'12'!G15+'13'!G15+'14'!G15+'15'!G15+'16'!G15+'17'!G15+'18'!G15+'19'!G15+'20'!G15+'21'!G15+'22'!G15+'23'!G15+'24'!G15+'25'!G15+'26'!G15+'27'!G15+'28'!G15+'29'!G15+'30'!G15+'31'!G15 -> 600 | H15: ='1'!H15+'2'!H15+'3'!H15+'4'!H15+'5'!H15+'6'!H15+'7'!H15+'8'!H15+'9'!H15+'10'!H15+'11'!H15+'12'!H15+'13'!H15+'14'!H15+'15'!H15+'16'!H15+'17'!H15+'18'!H15+'19'!H15+'20'!H15+'21'!H15+'22'!H15+'23'!H15+'24'!H15+'25'!H15+'26'!H15+'27'!H15+'28'!H15+'29'!H15+'30'!H15+'31'!H15 -> 2120 | I15: ='1'!I15+'2'!I15+'3'!I15+'4'!I15+'5'!I15+'6'!I15+'7'!I15+'8'!I15+'9'!I15+'10'!I15+'11'!I15+'12'!I15+'13'!I15+'14'!I15+'15'!I15+'16'!I15+'17'!I15+'18'!I15+'19'!I15+'20'!I15+'21'!I15+'22'!I15+'23'!I15+'24'!I15+'25'!I15+'26'!I15+'27'!I15+'28'!I15+'29'!I15+'30'!I15+'31'!I15 -> 3400 | J15: ='1'!J15+'2'!J15+'3'!J15+'4'!J15+'5'!J15+'6'!J15+'7'!J15+'8'!J15+'9'!J15+'10'!J15+'11'!J15+'12'!J15+'13'!J15+'14'!J15+'15'!J15+'16'!J15+'17'!J15+'18'!J15+'19'!J15+'20'!J15+'21'!J15+'22'!J15+'23'!J15+'24'!J15+'25'!J15+'26'!J15+'27'!J15+'28'!J15+'29'!J15+'30'!J15+'31'!J15 -> 3000 | K15: ='1'!K15+'2'!K15+'3'!K15+'4'!K15+'5'!K15+'6'!K15+'7'!K15+'8'!K15+'9'!K15+'10'!K15+'11'!K15+'12'!K15+'13'!K15+'14'!K15+'15'!K15+'16'!K15+'17'!K15+'18'!K15+'19'!K15+'20'!K15+'21'!K15+'22'!K15+'23'!K15+'24'!K15+'25'!K15+'26'!K15+'27'!K15+'28'!K15+'29'!K15+'30'!K15+'31'!K15 -> 5000 | L15: =SUM(C15:K15)/40 -> 400 | M15: =SUMPRODUCT($C$4:$K$4,$C15:$K15) -> 1069423.5 | N15: =SUMPRODUCT($C$3:$K$3,$C15:$K15)/1000 -> 1690 | Q15: =SUMPRODUCT($C$4:$E$4,$C$6:$E$6)*$Q$3 -> 1031.749 | R15: =SUMPRODUCT($F$4:$H$4,$F$6:$H$6)*$R$3 -> 3739.527 | S15: =SUMPRODUCT($I$4:$K$4,$I$6:$K$6)*$S$3 -> 7171.0208 | T15: =SUM(Q15:S15) -> 11942.297 | U15: =SUM(C15:E15)*$U$3 -> 0 | V15: =SUM(F15:H15)*$V$3 -> 0 | W15: =SUM(I15:K15)*$W$3 -> 0 | X15: =SUM(U15:W15) -> 0 | AB15: =AA15/Z15 -> #DIV/0! | AC15: =M15/AA15 -> #DIV/0! | AF15: =SUM(C15:E15)/40 -> 0 | AG15: =SUM(F15:H15)/40 -> 115 | AH15: =SUM(E15:G15)/40 -> 62 | AJ15: =AF15/SUM(AF15:AH15) -> 0 | AK15: =AG15/SUM(AF15:AH15) -> 0.64971751 | AL15: =AH15/SUM(AF15:AH15) -> 0.35028249
A16: 11 | B16: Abdullah Traders | C16: ='1'!C16+'2'!C16+'3'!C16+'4'!C16+'5'!C16+'6'!C16+'7'!C16+'8'!C16+'9'!C16+'10'!C16+'11'!C16+'12'!C16+'13'!C16+'14'!C16+'15'!C16+'16'!C16+'17'!C16+'18'!C16+'19'!C16+'20'!C16+'21'!C16+'22'!C16+'23'!C16+'24'!C16+'25'!C16+'26'!C16+'27'!C16+'28'!C16+'29'!C16+'30'!C16+'31'!C16 -> 1400 | D16: ='1'!D16+'2'!D16+'3'!D16+'4'!D16+'5'!D16+'6'!D16+'7'!D16+'8'!D16+'9'!D16+'10'!D16+'11'!D16+'12'!D16+'13'!D16+'14'!D16+'15'!D16+'16'!D16+'17'!D16+'18'!D16+'19'!D16+'20'!D16+'21'!D16+'22'!D16+'23'!D16+'24'!D16+'25'!D16+'26'!D16+'27'!D16+'28'!D16+'29'!D16+'30'!D16+'31'!D16 -> 0 | E16: ='1'!E16+'2'!E16+'3'!E16+'4'!E16+'5'!E16+'6'!E16+'7'!E16+'8'!E16+'9'!E16+'10'!E16+'11'!E16+'12'!E16+'13'!E16+'14'!E16+'15'!E16+'16'!E16+'17'!E16+'18'!E16+'19'!E16+'20'!E16+'21'!E16+'22'!E16+'23'!E16+'24'!E16+'25'!E16+'26'!E16+'27'!E16+'28'!E16+'29'!E16+'30'!E16+'31'!E16 -> 0 | F16: ='1'!F16+'2'!F16+'3'!F16+'4'!F16+'5'!F16+'6'!F16+'7'!F16+'8'!F16+'9'!F16+'10'!F16+'11'!F16+'12'!F16+'13'!F16+'14'!F16+'15'!F16+'16'!F16+'17'!F16+'18'!F16+'19'!F16+'20'!F16+'21'!F16+'22'!F16+'23'!F16+'24'!F16+'25'!F16+'26'!F16+'27'!F16+'28'!F16+'29'!F16+'30'!F16+'31'!F16 -> 400 | G16: ='1'!G16+'2'!G16+'3'!G16+'4'!G16+'5'!G16+'6'!G16+'7'!G16+'8'!G16+'9'!G16+'10'!G16+'11'!G16+'12'!G16+'13'!G16+'14'!G16+'15'!G16+'16'!G16+'17'!G16+'18'!G16+'19'!G16+'20'!G16+'21'!G16+'22'!G16+'23'!G16+'24'!G16+'25'!G16+'26'!G16+'27'!G16+'28'!G16+'29'!G16+'30'!G16+'31'!G16 -> 400 | H16: ='1'!H16+'2'!H16+'3'!H16+'4'!H16+'5'!H16+'6'!H16+'7'!H16+'8'!H16+'9'!H16+'10'!H16+'11'!H16+'12'!H16+'13'!H16+'14'!H16+'15'!H16+'16'!H16+'17'!H16+'18'!H16+'19'!H16+'20'!H16+'21'!H16+'22'!H16+'23'!H16+'24'!H16+'25'!H16+'26'!H16+'27'!H16+'28'!H16+'29'!H16+'30'!H16+'31'!H16 -> 0 | I16: ='1'!I16+'2'!I16+'3'!I16+'4'!I16+'5'!I16+'6'!I16+'7'!I16+'8'!I16+'9'!I16+'10'!I16+'11'!I16+'12'!I16+'13'!I16+'14'!I16+'15'!I16+'16'!I16+'17'!I16+'18'!I16+'19'!I16+'20'!I16+'21'!I16+'22'!I16+'23'!I16+'24'!I16+'25'!I16+'26'!I16+'27'!I16+'28'!I16+'29'!I16+'30'!I16+'31'!I16 -> 400 | J16: ='1'!J16+'2'!J16+'3'!J16+'4'!J16+'5'!J16+'6'!J16+'7'!J16+'8'!J16+'9'!J16+'10'!J16+'11'!J16+'12'!J16+'13'!J16+'14'!J16+'15'!J16+'16'!J16+'17'!J16+'18'!J16+'19'!J16+'20'!J16+'21'!J16+'22'!J16+'23'!J16+'24'!J16+'25'!J16+'26'!J16+'27'!J16+'28'!J16+'29'!J16+'30'!J16+'31'!J16 -> 400 | K16: ='1'!K16+'2'!K16+'3'!K16+'4'!K16+'5'!K16+'6'!K16+'7'!K16+'8'!K16+'9'!K16+'10'!K16+'11'!K16+'12'!K16+'13'!K16+'14'!K16+'15'!K16+'16'!K16+'17'!K16+'18'!K16+'19'!K16+'20'!K16+'21'!K16+'22'!K16+'23'!K16+'24'!K16+'25'!K16+'26'!K16+'27'!K16+'28'!K16+'29'!K16+'30'!K16+'31'!K16 -> 600 | L16: =SUM(C16:K16)/40 -> 90 | M16: =SUMPRODUCT($C$4:$K$4,$C16:$K16) -> 198588 | N16: =SUMPRODUCT($C$3:$K$3,$C16:$K16)/1000 -> 308 | Q16: =SUMPRODUCT($C$4:$E$4,$C$6:$E$6)*$Q$3 -> 1031.749 | R16: =SUMPRODUCT($F$4:$H$4,$F$6:$H$6)*$R$3 -> 3739.527 | S16: =SUMPRODUCT($I$4:$K$4,$I$6:$K$6)*$S$3 -> 7171.0208 | T16: =SUM(Q16:S16) -> 11942.297 | U16: =SUM(C16:E16)*$U$3 -> 49 | V16: =SUM(F16:H16)*$V$3 -> 0 | W16: =SUM(I16:K16)*$W$3 -> 0 | X16: =SUM(U16:W16) -> 49 | AB16: =AA16/Z16 -> #DIV/0! | AC16: =M16/AA16 -> #DIV/0! | AF16: =SUM(C16:E16)/40 -> 35 | AG16: =SUM(F16:H16)/40 -> 20 | AH16: =SUM(E16:G16)/40 -> 20 | AJ16: =AF16/SUM(AF16:AH16) -> 0.46666667 | AK16: =AG16/SUM(AF16:AH16) -> 0.26666667 | AL16: =AH16/SUM(AF16:AH16) -> 0.26666667
A17: 12 | B17: Sohail Traders | C17: ='1'!C17+'2'!C17+'3'!C17+'4'!C17+'5'!C17+'6'!C17+'7'!C17+'8'!C17+'9'!C17+'10'!C17+'11'!C17+'12'!C17+'13'!C17+'14'!C17+'15'!C17+'16'!C17+'17'!C17+'18'!C17+'19'!C17+'20'!C17+'21'!C17+'22'!C17+'23'!C17+'24'!C17+'25'!C17+'26'!C17+'27'!C17+'28'!C17+'29'!C17+'30'!C17+'31'!C17 -> 1600 | D17: ='1'!D17+'2'!D17+'3'!D17+'4'!D17+'5'!D17+'6'!D17+'7'!D17+'8'!D17+'9'!D17+'10'!D17+'11'!D17+'12'!D17+'13'!D17+'14'!D17+'15'!D17+'16'!D17+'17'!D17+'18'!D17+'19'!D17+'20'!D17+'21'!D17+'22'!D17+'23'!D17+'24'!D17+'25'!D17+'26'!D17+'27'!D17+'28'!D17+'29'!D17+'30'!D17+'31'!D17 -> 0 | E17: ='1'!E17+'2'!E17+'3'!E17+'4'!E17+'5'!E17+'6'!E17+'7'!E17+'8'!E17+'9'!E17+'10'!E17+'11'!E17+'12'!E17+'13'!E17+'14'!E17+'15'!E17+'16'!E17+'17'!E17+'18'!E17+'19'!E17+'20'!E17+'21'!E17+'22'!E17+'23'!E17+'24'!E17+'25'!E17+'26'!E17+'27'!E17+'28'!E17+'29'!E17+'30'!E17+'31'!E17 -> 0 | F17: ='1'!F17+'2'!F17+'3'!F17+'4'!F17+'5'!F17+'6'!F17+'7'!F17+'8'!F17+'9'!F17+'10'!F17+'11'!F17+'12'!F17+'13'!F17+'14'!F17+'15'!F17+'16'!F17+'17'!F17+'18'!F17+'19'!F17+'20'!F17+'21'!F17+'22'!F17+'23'!F17+'24'!F17+'25'!F17+'26'!F17+'27'!F17+'28'!F17+'29'!F17+'30'!F17+'31'!F17 -> 0 | G17: ='1'!G17+'2'!G17+'3'!G17+'4'!G17+'5'!G17+'6'!G17+'7'!G17+'8'!G17+'9'!G17+'10'!G17+'11'!G17+'12'!G17+'13'!G17+'14'!G17+'15'!G17+'16'!G17+'17'!G17+'18'!G17+'19'!G17+'20'!G17+'21'!G17+'22'!G17+'23'!G17+'24'!G17+'25'!G17+'26'!G17+'27'!G17+'28'!G17+'29'!G17+'30'!G17+'31'!G17 -> 0 | H17: ='1'!H17+'2'!H17+'3'!H17+'4'!H17+'5'!H17+'6'!H17+'7'!H17+'8'!H17+'9'!H17+'10'!H17+'11'!H17+'12'!H17+'13'!H17+'14'!H17+'15'!H17+'16'!H17+'17'!H17+'18'!H17+'19'!H17+'20'!H17+'21'!H17+'22'!H17+'23'!H17+'24'!H17+'25'!H17+'26'!H17+'27'!H17+'28'!H17+'29'!H17+'30'!H17+'31'!H17 -> 0 | I17: ='1'!I17+'2'!I17+'3'!I17+'4'!I17+'5'!I17+'6'!I17+'7'!I17+'8'!I17+'9'!I17+'10'!I17+'11'!I17+'12'!I17+'13'!I17+'14'!I17+'15'!I17+'16'!I17+'17'!I17+'18'!I17+'19'!I17+'20'!I17+'21'!I17+'22'!I17+'23'!I17+'24'!I17+'25'!I17+'26'!I17+'27'!I17+'28'!I17+'29'!I17+'30'!I17+'31'!I17 -> 520 | J17: ='1'!J17+'2'!J17+'3'!J17+'4'!J17+'5'!J17+'6'!J17+'7'!J17+'8'!J17+'9'!J17+'10'!J17+'11'!J17+'12'!J17+'13'!J17+'14'!J17+'15'!J17+'16'!J17+'17'!J17+'18'!J17+'19'!J17+'20'!J17+'21'!J17+'22'!J17+'23'!J17+'24'!J17+'25'!J17+'26'!J17+'27'!J17+'28'!J17+'29'!J17+'30'!J17+'31'!J17 -> 920 | K17: ='1'!K17+'2'!K17+'3'!K17+'4'!K17+'5'!K17+'6'!K17+'7'!K17+'8'!K17+'9'!K17+'10'!K17+'11'!K17+'12'!K17+'13'!K17+'14'!K17+'15'!K17+'16'!K17+'17'!K17+'18'!K17+'19'!K17+'20'!K17+'21'!K17+'22'!K17+'23'!K17+'24'!K17+'25'!K17+'26'!K17+'27'!K17+'28'!K17+'29'!K17+'30'!K17+'31'!K17 -> 960 | L17: =SUM(C17:K17)/40 -> 100 | M17: =SUMPRODUCT($C$4:$K$4,$C17:$K17) -> 237104 | N17: =SUMPRODUCT($C$3:$K$3,$C17:$K17)/1000 -> 384 | Q17: =SUMPRODUCT($C$4:$E$4,$C$6:$E$6)*$Q$3 -> 1031.749 | R17: =SUMPRODUCT($F$4:$H$4,$F$6:$H$6)*$R$3 -> 3739.527 | S17: =SUMPRODUCT($I$4:$K$4,$I$6:$K$6)*$S$3 -> 7171.0208 | T17: =SUM(Q17:S17) -> 11942.297 | U17: =SUM(C17:E17)*$U$3 -> 56 | V17: =SUM(F17:H17)*$V$3 -> 0 | W17: =SUM(I17:K17)*$W$3 -> 0 | X17: =SUM(U17:W17) -> 56 | AB17: =AA17/Z17 -> #DIV/0! | AC17: =M17/AA17 -> #DIV/0! | AF17: =SUM(C17:E17)/40 -> 40 | AG17: =SUM(F17:H17)/40 -> 0 | AH17: =SUM(E17:G17)/40 -> 0 | AJ17: =AF17/SUM(AF17:AH17) -> 1 | AK17: =AG17/SUM(AF17:AH17) -> 0 | AL17: =AH17/SUM(AF17:AH17) -> 0
A18: Total | C18: =SUM(C6:C17) -> 7935 | D18: =SUM(D6:D17) -> 0 | E18: =SUM(E6:E17) -> 0 | F18: =SUM(F6:F17) -> 12914 | G18: =SUM(G6:G17) -> 12064 | H18: =SUM(H6:H17) -> 16306 | I18: =SUM(I6:I17) -> 21897 | J18: =SUM(J6:J17) -> 18866 | K18: =SUM(K6:K17) -> 26486 | L18: =SUM(C18:K18)/40 -> 2911.7 | M18: =SUM(M6:M17) -> 7362119.3 | N18: =SUM(N6:N17) -> 11435.86 | O18: =SUM(O6:O17) -> 0 | P18: =SUM(P6:P17) -> 0 | Q18: =SUM(Q6:Q17) -> 12380.988 | R18: =SUM(R6:R17) -> 44874.324 | S18: =SUM(S6:S17) -> 86052.25 | T18: =SUM(T6:T17) -> 143307.56 | ... AA18: =SUM(AA6:AA17) -> 0 | AB18: =AA18/Z18 -> #DIV/0! | AC18: =M18/AA18 -> #DIV/0! | AD18: =SUM(AD6:AD17) -> 0 | AF18: =SUM(C18:E18)/40 -> 198.375 | AG18: =SUM(F18:H18)/40 -> 1032.1 | AH18: =SUM(E18:G18)/40 -> 624.45 | AJ18: =AF18/SUM(AF18:AH18) -> 0.10694502 | AK18: =AG18/SUM(AF18:AH18) -> 0.55641064 | AL18: =AH18/SUM(AF18:AH18) -> 0.33664434
A21: ID | B21: Customer name | C21: 60gm | F21: 70 Gmm | I21: 120Gm | L21: Total | Q21: Discount | U21: Trader offer
C22: CHk | D22: LEM | E22: Meat | F22: CHk | G22: LEM | H22: Meat | I22: CHk | J22: LEM | K22: Meat | L22: CTN | M22: Amount | N22: Volume | O22: 70 | P22: 120 | Q22: 60 | R22: 70 | S22: 120 | T22: Total | U22: 60 | V22: 70 | W22: 120 | X22: Total | Y22: 3907 | Z22: 2021
C23: 10 | L23: =SUM(C23:K23)/40 -> 0.25 | M23: =SUMPRODUCT($C$4:$K$4,$C$6:$K$6) -> 157016.83 | N23: =SUMPRODUCT($C$3:$K$3,$C$6:$K$6)/1000 -> 242.01 | Q23: =SUMPRODUCT($C$4:$E$4,$C$6:$E$6)*$Q$3 -> 1031.749 | R23: =SUMPRODUCT($F$4:$H$4,$F$6:$H$6)*$R$3 -> 3739.527 | S23: =SUMPRODUCT($I$4:$K$4,$I$6:$K$6)*$S$3 -> 7171.0208 | T23: =SUM(Q23:S23) -> 11942.297 | U23: =SUM(C23:E23)*$U$3 -> 0.35 | V23: =SUM(F23:H23)*$V$3 -> 0 | W23: =SUM(I23:K23)*$W$3 -> 0 | X23: =SUM(U23:W23) -> 0.35 | Y23: =Y22/40 -> 97.675 | Z23: =Z22/40 -> 50.525 | AB23: =Y23-Z23 -> 47.15
L24: =SUM(C24:K24)/40 -> 0 | M24: =SUMPRODUCT($C$4:$K$4,$C$6:$K$6) -> 157016.83 | N24: =SUMPRODUCT($C$3:$K$3,$C$6:$K$6)/1000 -> 242.01 | Q24: =SUMPRODUCT($C$4:$E$4,$C$6:$E$6)*$Q$3 -> 1031.749 | R24: =SUMPRODUCT($F$4:$H$4,$F$6:$H$6)*$R$3 -> 3739.527 | S24: =SUMPRODUCT($I$4:$K$4,$I$6:$K$6)*$S$3 -> 7171.0208 | T24: =SUM(Q24:S24) -> 11942.297 | U24: =SUM(C24:E24)*$U$3 -> 0 | V24: =SUM(F24:H24)*$V$3 -> 0 | W24: =SUM(I24:K24)*$W$3 -> 0 | X24: =SUM(U24:W24) -> 0
L25: =SUM(C25:K25)/40 -> 0 | M25: =SUMPRODUCT($C$4:$K$4,$C$6:$K$6) -> 157016.83 | N25: =SUMPRODUCT($C$3:$K$3,$C$6:$K$6)/1000 -> 242.01 | Q25: =SUMPRODUCT($C$4:$E$4,$C$6:$E$6)*$Q$3 -> 1031.749 | R25: =SUMPRODUCT($F$4:$H$4,$F$6:$H$6)*$R$3 -> 3739.527 | S25: =SUMPRODUCT($I$4:$K$4,$I$6:$K$6)*$S$3 -> 7171.0208 | T25: =SUM(Q25:S25) -> 11942.297 | U25: =SUM(C25:E25)*$U$3 -> 0 | V25: =SUM(F25:H25)*$V$3 -> 0 | W25: =SUM(I25:K25)*$W$3 -> 0 | X25: =SUM(U25:W25) -> 0
L26: =SUM(C26:K26)/40 -> 0 | M26: =SUMPRODUCT($C$4:$K$4,$C$6:$K$6) -> 157016.83 | N26: =SUMPRODUCT($C$3:$K$3,$C$6:$K$6)/1000 -> 242.01 | Q26: =SUMPRODUCT($C$4:$E$4,$C$6:$E$6)*$Q$3 -> 1031.749 | R26: =SUMPRODUCT($F$4:$H$4,$F$6:$H$6)*$R$3 -> 3739.527 | S26: =SUMPRODUCT($I$4:$K$4,$I$6:$K$6)*$S$3 -> 7171.0208 | T26: =SUM(Q26:S26) -> 11942.297 | U26: =SUM(C26:E26)*$U$3 -> 0 | V26: =SUM(F26:H26)*$V$3 -> 0 | W26: =SUM(I26:K26)*$W$3 -> 0 | X26: =SUM(U26:W26) -> 0
L27: =SUM(C27:K27)/40 -> 0 | M27: =SUMPRODUCT($C$4:$K$4,$C$6:$K$6) -> 157016.83 | N27: =SUMPRODUCT($C$3:$K$3,$C$6:$K$6)/1000 -> 242.01 | Q27: =SUMPRODUCT($C$4:$E$4,$C$6:$E$6)*$Q$3 -> 1031.749 | R27: =SUMPRODUCT($F$4:$H$4,$F$6:$H$6)*$R$3 -> 3739.527 | S27: =SUMPRODUCT($I$4:$K$4,$I$6:$K$6)*$S$3 -> 7171.0208 | T27: =SUM(Q27:S27) -> 11942.297 | U27: =SUM(C27:E27)*$U$3 -> 0 | V27: =SUM(F27:H27)*$V$3 -> 0 | W27: =SUM(I27:K27)*$W$3 -> 0 | X27: =SUM(U27:W27) -> 0
L28: =SUM(C28:K28)/40 -> 0 | M28: =SUMPRODUCT($C$4:$K$4,$C$6:$K$6) -> 157016.83 | N28: =SUMPRODUCT($C$3:$K$3,$C$6:$K$6)/1000 -> 242.01 | Q28: =SUMPRODUCT($C$4:$E$4,$C$6:$E$6)*$Q$3 -> 1031.749 | R28: =SUMPRODUCT($F$4:$H$4,$F$6:$H$6)*$R$3 -> 3739.527 | S28: =SUMPRODUCT($I$4:$K$4,$I$6:$K$6)*$S$3 -> 7171.0208 | T28: =SUM(Q28:S28) -> 11942.297 | U28: =SUM(C28:E28)*$U$3 -> 0 | V28: =SUM(F28:H28)*$V$3 -> 0 | W28: =SUM(I28:K28)*$W$3 -> 0 | X28: =SUM(U28:W28) -> 0
L29: =SUM(C29:K29)/40 -> 0 | M29: =SUMPRODUCT($C$4:$K$4,$C$6:$K$6) -> 157016.83 | N29: =SUMPRODUCT($C$3:$K$3,$C$6:$K$6)/1000 -> 242.01 | Q29: =SUMPRODUCT($C$4:$E$4,$C$6:$E$6)*$Q$3 -> 1031.749 | R29: =SUMPRODUCT($F$4:$H$4,$F$6:$H$6)*$R$3 -> 3739.527 | S29: =SUMPRODUCT($I$4:$K$4,$I$6:$K$6)*$S$3 -> 7171.0208 | T29: =SUM(Q29:S29) -> 11942.297 | U29: =SUM(C29:E29)*$U$3 -> 0 | V29: =SUM(F29:H29)*$V$3 -> 0 | W29: =SUM(I29:K29)*$W$3 -> 0 | X29: =SUM(U29:W29) -> 0
L30: =SUM(C30:K30)/40 -> 0 | M30: =SUMPRODUCT($C$4:$K$4,$C$6:$K$6) -> 157016.83 | N30: =SUMPRODUCT($C$3:$K$3,$C$6:$K$6)/1000 -> 242.01 | Q30: =SUMPRODUCT($C$4:$E$4,$C$6:$E$6)*$Q$3 -> 1031.749 | R30: =SUMPRODUCT($F$4:$H$4,$F$6:$H$6)*$R$3 -> 3739.527 | S30: =SUMPRODUCT($I$4:$K$4,$I$6:$K$6)*$S$3 -> 7171.0208 | T30: =SUM(Q30:S30) -> 11942.297 | U30: =SUM(C30:E30)*$U$3 -> 0 | V30: =SUM(F30:H30)*$V$3 -> 0 | W30: =SUM(I30:K30)*$W$3 -> 0 | X30: =SUM(U30:W30) -> 0
L31: =SUM(C31:K31)/40 -> 0 | M31: =SUMPRODUCT($C$4:$K$4,$C$6:$K$6) -> 157016.83 | N31: =SUMPRODUCT($C$3:$K$3,$C$6:$K$6)/1000 -> 242.01 | Q31: =SUMPRODUCT($C$4:$E$4,$C$6:$E$6)*$Q$3 -> 1031.749 | R31: =SUMPRODUCT($F$4:$H$4,$F$6:$H$6)*$R$3 -> 3739.527 | S31: =SUMPRODUCT($I$4:$K$4,$I$6:$K$6)*$S$3 -> 7171.0208 | T31: =SUM(Q31:S31) -> 11942.297 | U31: =SUM(C31:E31)*$U$3 -> 0 | V31: =SUM(F31:H31)*$V$3 -> 0 | W31: =SUM(I31:K31)*$W$3 -> 0 | X31: =SUM(U31:W31) -> 0
L32: =SUM(C32:K32)/40 -> 0 | M32: =SUMPRODUCT($C$4:$K$4,$C$6:$K$6) -> 157016.83 | N32: =SUMPRODUCT($C$3:$K$3,$C$6:$K$6)/1000 -> 242.01 | Q32: =SUMPRODUCT($C$4:$E$4,$C$6:$E$6)*$Q$3 -> 1031.749 | R32: =SUMPRODUCT($F$4:$H$4,$F$6:$H$6)*$R$3 -> 3739.527 | S32: =SUMPRODUCT($I$4:$K$4,$I$6:$K$6)*$S$3 -> 7171.0208 | T32: =SUM(Q32:S32) -> 11942.297 | U32: =SUM(C32:E32)*$U$3 -> 0 | V32: =SUM(F32:H32)*$V$3 -> 0 | W32: =SUM(I32:K32)*$W$3 -> 0 | X32: =SUM(U32:W32) -> 0
L33: =SUM(C33:K33)/40 -> 0 | M33: =SUMPRODUCT($C$4:$K$4,$C$6:$K$6) -> 157016.83 | N33: =SUMPRODUCT($C$3:$K$3,$C$6:$K$6)/1000 -> 242.01 | Q33: =SUMPRODUCT($C$4:$E$4,$C$6:$E$6)*$Q$3 -> 1031.749 | R33: =SUMPRODUCT($F$4:$H$4,$F$6:$H$6)*$R$3 -> 3739.527 | S33: =SUMPRODUCT($I$4:$K$4,$I$6:$K$6)*$S$3 -> 7171.0208 | T33: =SUM(Q33:S33) -> 11942.297 | U33: =SUM(C33:E33)*$U$3 -> 0 | V33: =SUM(F33:H33)*$V$3 -> 0 | W33: =SUM(I33:K33)*$W$3 -> 0 | X33: =SUM(U33:W33) -> 0
L34: =SUM(C34:K34)/40 -> 0 | M34: =SUMPRODUCT($C$4:$K$4,$C$6:$K$6) -> 157016.83 | N34: =SUMPRODUCT($C$3:$K$3,$C$6:$K$6)/1000 -> 242.01 | Q34: =SUMPRODUCT($C$4:$E$4,$C$6:$E$6)*$Q$3 -> 1031.749 | R34: =SUMPRODUCT($F$4:$H$4,$F$6:$H$6)*$R$3 -> 3739.527 | S34: =SUMPRODUCT($I$4:$K$4,$I$6:$K$6)*$S$3 -> 7171.0208 | T34: =SUM(Q34:S34) -> 11942.297 | U34: =SUM(C34:E34)*$U$3 -> 0 | V34: =SUM(F34:H34)*$V$3 -> 0 | W34: =SUM(I34:K34)*$W$3 -> 0 | X34: =SUM(U34:W34) -> 0
L35: =SUM(C35:K35)/40 -> 0 | M35: =SUMPRODUCT($C$4:$K$4,$C$6:$K$6) -> 157016.83 | N35: =SUMPRODUCT($C$3:$K$3,$C$6:$K$6)/1000 -> 242.01 | Q35: =SUMPRODUCT($C$4:$E$4,$C$6:$E$6)*$Q$3 -> 1031.749 | R35: =SUMPRODUCT($F$4:$H$4,$F$6:$H$6)*$R$3 -> 3739.527 | S35: =SUMPRODUCT($I$4:$K$4,$I$6:$K$6)*$S$3 -> 7171.0208 | T35: =SUM(Q35:S35) -> 11942.297 | U35: =SUM(C35:E35)*$U$3 -> 0 | V35: =SUM(F35:H35)*$V$3 -> 0 | W35: =SUM(I35:K35)*$W$3 -> 0 | X35: =SUM(U35:W35) -> 0
... L502: =SUM(C502:K502)/40 -> 0 | M502: =SUMPRODUCT($C$4:$K$4,$C$6:$K$6) -> 157016.83 | N502: =SUMPRODUCT($C$3:$K$3,$C$6:$K$6)/1000 -> 242.01 | Q502: =SUMPRODUCT($C$4:$E$4,$C$6:$E$6)*$Q$3 -> 1031.749 | R502: =SUMPRODUCT($F$4:$H$4,$F$6:$H$6)*$R$3 -> 3739.527 | S502: =SUMPRODUCT($I$4:$K$4,$I$6:$K$6)*$S$3 -> 7171.0208 | T502: =SUM(Q502:S502) -> 11942.297 | U502: =SUM(C502:E502)*$U$3 -> 0 | V502: =SUM(F502:H502)*$V$3 -> 0 | W502: =SUM(I502:K502)*$W$3 -> 0 | X502: =SUM(U502:W502) -> 0

Sheet 1
A2: 46174
A3: ID | B3: Gm | C3: 60 | D3: 60 | E3: 60 | F3: 70 | G3: 70 | H3: 70 | I3: 120 | J3: 120 | K3: 120 | O3: FOC | Q3: 0.05 | R3: 0.08 | S3: 0.08 | U3: 0.035 | Y3: Section Name | Z3: KPI's
B4: TP Excl. GST | C4: 39.23 | D4: 39.23 | E4: 39.23 | F4: 52.4625 | G4: 52.4625 | H4: 52.4625 | I4: 72.64 | J4: 72.64 | K4: 72.64 | L4: Total | Q4: Discount | U4: Trader offer | Z4: Unique | AC4: Drop Size | AD4: SKU/Call | AF4: Sales | AJ4: Contribution
B5: Booker Name | C5: CHK | D5: LEM | E5: Meat | F5: Meat | G5: LEM | H5: CHK | I5: Meat | J5: LEM | K5: CHK | L5: CTN | M5: Amount | N5: Volume | O5: 70 | P5: 120 | Q5: 60 | R5: 70 | S5: 120 | T5: Total | U5: 60 | V5: 70 | W5: 120 | X5: Total | Z5: Plan Shop | AA5: Productivity | AB5: % | AF5: 60 | AG5: 70 | AH5: 120 | AJ5: 60 | AK5: 70 | AL5: 120
A6: 1 | B6: Zahid Rafique | C6: 110 | F6: 16 | G6: 10 | H6: 10 | I6: 25 | J6: 17 | K6: 21 | L6: =SUM(C6:K6)/40 -> 5.225 | M6: =SUMPRODUCT($C$4:$K$4,$C6:$K6) -> 10780.27 | N6: =SUMPRODUCT($C$3:$K$3,$C6:$K6)/1000 -> 16.68 | O6: =SUM(F6:H6)/20 -> 1.8 | P6: =SUM(I6:K6)/20 -> 3.15 | Q6: =SUMPRODUCT($C$4:$E$4,$C$6:$E$6)*$Q$3 -> 215.765 | R6: =SUMPRODUCT($F$4:$H$4,$F$6:$H$6)*$R$3 -> 151.092 | S6: =SUMPRODUCT($I$4:$K$4,$I$6:$K$6)*$S$3 -> 366.1056 | T6: =SUM(Q6:S6) -> 732.9626 | U6: =SUM(C6:E6)*$U$3 -> 3.85 | V6: =SUM(F6:H6)*$V$3 -> 0 | W6: =SUM(I6:K6)*$W$3 -> 0 | X6: =SUM(U6:W6) -> 3.85 | Z6: 40 | AA6: 6 | AB6: =AA6/Z6 -> 0.15 | AC6: =M6/AA6 -> 1796.7117 | AF6: =SUM(C6:E6)/40 -> 2.75 | AG6: =SUM(F6:H6)/40 -> 0.9 | AH6: =SUM(E6:G6)/40 -> 0.65 | AJ6: =AF6/SUM(AF6:AH6) -> 0.63953488 | AK6: =AG6/SUM(AF6:AH6) -> 0.20930233 | AL6: =AH6/SUM(AF6:AH6) -> 0.15116279
A7: 2 | B7: salman | L7: =SUM(C7:K7)/40 -> 0 | M7: =SUMPRODUCT($C$4:$K$4,$C7:$K7) -> 0 | N7: =SUMPRODUCT($C$3:$K$3,$C7:$K7)/1000 -> 0 | O7: =SUM(F7:H7)/20 -> 0 | P7: =SUM(I7:K7)/20 -> 0 | Q7: =SUMPRODUCT($C$4:$E$4,$C$6:$E$6)*$Q$3 -> 215.765 | R7: =SUMPRODUCT($F$4:$H$4,$F$6:$H$6)*$R$3 -> 151.092 | S7: =SUMPRODUCT($I$4:$K$4,$I$6:$K$6)*$S$3 -> 366.1056 | T7: =SUM(Q7:S7) -> 732.9626 | U7: =SUM(C7:E7)*$U$3 -> 0 | V7: =SUM(F7:H7)*$V$3 -> 0 | W7: =SUM(I7:K7)*$W$3 -> 0 | X7: =SUM(U7:W7) -> 0 | Z7: 40 | AA7: 10 | AB7: =AA7/Z7 -> 0.25 | AC7: =M7/AA7 -> 0 | AF7: =SUM(C7:E7)/40 -> 0 | AG7: =SUM(F7:H7)/40 -> 0 | AH7: =SUM(E7:G7)/40 -> 0 | AJ7: =AF7/SUM(AF7:AH7) -> #DIV/0! | AK7: =AG7/SUM(AF7:AH7) -> #DIV/0! | AL7: =AH7/SUM(AF7:AH7) -> #DIV/0!
A8: 3 | B8: zeeshan | L8: =SUM(C8:K8)/40 -> 0 | M8: =SUMPRODUCT($C$4:$K$4,$C8:$K8) -> 0 | N8: =SUMPRODUCT($C$3:$K$3,$C8:$K8)/1000 -> 0 | O8: =SUM(F8:H8)/20 -> 0 | P8: =SUM(I8:K8)/20 -> 0 | Q8: =SUMPRODUCT($C$4:$E$4,$C$6:$E$6)*$Q$3 -> 215.765 | R8: =SUMPRODUCT($F$4:$H$4,$F$6:$H$6)*$R$3 -> 151.092 | S8: =SUMPRODUCT($I$4:$K$4,$I$6:$K$6)*$S$3 -> 366.1056 | T8: =SUM(Q8:S8) -> 732.9626 | U8: =SUM(C8:E8)*$U$3 -> 0 | V8: =SUM(F8:H8)*$V$3 -> 0 | W8: =SUM(I8:K8)*$W$3 -> 0 | X8: =SUM(U8:W8) -> 0 | AB8: =AA8/Z8 -> #DIV/0! | AC8: =M8/AA8 -> #DIV/0! | AF8: =SUM(C8:E8)/40 -> 0 | AG8: =SUM(F8:H8)/40 -> 0 | AH8: =SUM(E8:G8)/40 -> 0 | AJ8: =AF8/SUM(AF8:AH8) -> #DIV/0! | AK8: =AG8/SUM(AF8:AH8) -> #DIV/0! | AL8: =AH8/SUM(AF8:AH8) -> #DIV/0!
