Workbook

Sheet Dist Price List (2)
A2: DEMAND FOR SAMPLES
A3: SNACK FOOD SKU UPDATED LIST | J3: 1.1 | K3: 0.18 | L3: 1.18 | M3: 0.045 | N3: 0.12 | O3: Ex. Price | S3: 0.06 | U3: =K3 -> 0.18
A4: Sr.No | B4: SKUs | C4: Weight gms | E4: Price PKR | F4: Packets / Cartons | G4: Packets | H4: Cartons | J4: Trade Price | K4: GST | L4: Exclusive GST | M4: Adv. TO / Pack | N4: Dis. Margin | O4: Pack | P4: CTN
A5: 1 | B5: DAAL SEV | C5: 16 | D5: gm | E5: 20 | F5: 72 | G5: 100 | J5: =E5/$J$3 -> 18.181818 | K5: =L5*18% -> 2.7734977 | L5: =J5/$L$3 -> 15.40832 | M5: =L5-L5/1.045 -> 0.66351619 | N5: =L5-L5/1.12 -> 1.6508915 | O5: =J5-M5-N5 -> 15.867411 | P5: =O5*F5 -> 1142.4536 | Q5: =L5-M5-N5 -> 13.093913 | S5: =L5*S3 -> 0.92449923 | T5: =L5-S5 -> 14.483821 | U5: =T5+T5*U3 -> 17.090909
A6: 2 | B6: POTATO STICK (CHATPATA) | C6: 16 | D6: gm | E6: 20 | F6: 72 | G6: 100 | J6: =E6/$J$3 -> 18.181818 | K6: =L6*18% -> 2.7734977 | L6: =J6/$L$3 -> 15.40832 | M6: =L6-L6/1.06 -> 0.87216908 | N6: =J6*$N$3 -> 2.1818182 | O6: =J6-M6-N6 -> 15.127831 | P6: =O6*F6 -> 1089.2038 | U6: =U5*12 -> 205.09091
A7: 3 | B7: SPICY MIX NIMKO | C7: 16 | D7: gm | E7: 20 | F7: 72 | G7: 100 | J7: =E7/$J$3 -> 18.181818 | K7: =L7*18% -> 2.7734977 | L7: =J7/$L$3 -> 15.40832 | M7: =L7-L7/1.06 -> 0.87216908 | N7: =J7*$N$3 -> 2.1818182 | O7: =J7-M7-N7 -> 15.127831 | P7: =O7*F7 -> 1089.2038
A8: 4 | B8: NIMBOO DAAL | C8: 16 | D8: gm | E8: 20 | F8: 72 | G8: 100 | J8: =E8/$J$3 -> 18.181818 | K8: =L8*18% -> 2.7734977 | L8: =J8/$L$3 -> 15.40832 | M8: =L8-L8/1.06 -> 0.87216908 | N8: =J8*$N$3 -> 2.1818182 | O8: =J8-M8-N8 -> 15.127831 | P8: =O8*F8 -> 1089.2038
A9: 5 | B9: NIMKO MIX HOT & SPICY | C9: 16 | D9: gm | E9: 20 | F9: 72 | G9: 0 | J9: =E9/$J$3 -> 18.181818 | K9: =L9*18% -> 2.7734977 | L9: =J9/$L$3 -> 15.40832 | M9: =L9-L9/1.06 -> 0.87216908 | N9: =J9*$N$3 -> 2.1818182 | O9: =J9-M9-N9 -> 15.127831 | P9: =O9*F9 -> 1089.2038
A10: 6 | B10: NIMKO MIX LEMON & CHILLI | C10: 16 | D10: gm | E10: 20 | F10: 72 | G10: 0 | J10: =E10/$J$3 -> 18.181818 | K10: =L10*18% -> 2.7734977 | L10: =J10/$L$3 -> 15.40832 | M10: =L10-L10/1.06 -> 0.87216908 | N10: =J10*$N$3 -> 2.1818182 | O10: =J10-M10-N10 -> 15.127831 | P10: =O10*F10 -> 1089.2038
A11: 7 | B11: SLANTY (SALTED) | C11: 10 | D11: gm | E11: 20 | F11: 45 | G11: 0 | J11: =E11/$J$3 -> 18.181818 | K11: =L11*18% -> 2.7734977 | L11: =J11/$L$3 -> 15.40832 | M11: =L11-L11/1.06 -> 0.87216908 | N11: =J11*$N$3 -> 2.1818182 | O11: =J11-M11-N11 -> 15.127831 | P11: =O11*F11 -> 680.75239
A12: 8 | B12: SLANTY (VEGETABLE EU) | C12: 10 | D12: gm | E12: 20 | F12: 45 | G12: 0 | J12: =E12/$J$3 -> 18.181818 | K12: =L12*18% -> 2.7734977 | L12: =J12/$L$3 -> 15.40832 | M12: =L12-L12/1.06 -> 0.87216908 | N12: =J12*$N$3 -> 2.1818182 | O12: =J12-M12-N12 -> 15.127831 | P12: =O12*F12 -> 680.75239
A13: 9 | B13: SLANTY (KETCHUP) | C13: 10 | D13: gm | E13: 20 | F13: 45 | G13: Hold For Printing | J13: =E13/$J$3 -> 18.181818 | K13: =L13*18% -> 2.7734977 | L13: =J13/$L$3 -> 15.40832 | M13: =L13-L13/1.06 -> 0.87216908 | N13: =J13*$N$3 -> 2.1818182 | O13: =J13-M13-N13 -> 15.127831 | P13: =O13*F13 -> 680.75239
A15: 10 | B15: NIMBOO DAAL | C15: 24 | D15: gm | E15: 30 | F15: 45 | G15: 0 | J15: =E15/$J$3 -> 27.272727 | K15: =L15*18% -> 4.1602465 | L15: =J15/$L$3 -> 23.112481 | M15: =L15-L15/1.06 -> 1.3082536 | N15: =J15*$N$3 -> 3.2727273 | O15: =J15-M15-N15 -> 22.691746 | P15: =O15*F15 -> 1021.1286
A16: 11 | B16: DAAL MOUNG | C16: 18 | D16: gm | E16: 30 | F16: 72 | G16: 100 | J16: =E16/$J$3 -> 27.272727 | K16: =L16*18% -> 4.1602465 | L16: =J16/$L$3 -> 23.112481 | M16: =L16-L16/1.06 -> 1.3082536 | N16: =J16*$N$3 -> 3.2727273 | O16: =J16-M16-N16 -> 22.691746 | P16: =O16*F16 -> 1633.8057
A17: 12 | B17: NIMKO MIX HOT & SPICY | C17: 24 | D17: gm | E17: 30 | F17: 45 | G17: 100 | J17: =E17/$J$3 -> 27.272727 | K17: =L17*18% -> 4.1602465 | L17: =J17/$L$3 -> 23.112481 | M17: =L17-L17/1.06 -> 1.3082536 | N17: =J17*$N$3 -> 3.2727273 | O17: =J17-M17-N17 -> 22.691746 | P17: =O17*F17 -> 1021.1286
A18: 13 | B18: POTATO STICK (SALT & PEPPER) | C18: 24 | D18: gm | E18: 30 | F18: 45 | G18: 100 | J18: =E18/$J$3 -> 27.272727 | K18: =L18*18% -> 4.1602465 | L18: =J18/$L$3 -> 23.112481 | M18: =L18-L18/1.06 -> 1.3082536 | N18: =J18*$N$3 -> 3.2727273 | O18: =J18-M18-N18 -> 22.691746 | P18: =O18*F18 -> 1021.1286
A19: 14 | B19: SALTED PEANUT | C19: 16 | D19: gm | E19: 30 | F19: 85 | G19: 100 | J19: =E19/$J$3 -> 27.272727 | K19: =L19*18% -> 4.1602465 | L19: =J19/$L$3 -> 23.112481 | M19: =L19-L19/1.06 -> 1.3082536 | N19: =J19*$N$3 -> 3.2727273 | O19: =J19-M19-N19 -> 22.691746 | P19: =O19*F19 -> 1928.7984
A20: 15 | B20: PEANUT UNSALTED | C20: 16 | D20: gm | E20: 30 | F20: 85 | G20: 100 | J20: =E20/$J$3 -> 27.272727 | K20: =L20*18% -> 4.1602465 | L20: =J20/$L$3 -> 23.112481 | M20: =L20-L20/1.06 -> 1.3082536 | N20: =J20*$N$3 -> 3.2727273 | O20: =J20-M20-N20 -> 22.691746 | P20: =O20*F20 -> 1928.7984
A21: 16 | B21: NIMKO MIX LEMON & CHILLI | C21: 24 | D21: gm | E21: 30 | F21: 45 | G21: 0 | J21: =E21/$J$3 -> 27.272727 | K21: =L21*18% -> 4.1602465 | L21: =J21/$L$3 -> 23.112481 | M21: =L21-L21/1.06 -> 1.3082536 | N21: =J21*$N$3 -> 3.2727273 | O21: =J21-M21-N21 -> 22.691746 | P21: =O21*F21 -> 1021.1286
A22: 17 | B22: SPICY MIX NIMKO | C22: 24 | D22: gm | E22: 30 | F22: 45 | G22: 0 | J22: =E22/$J$3 -> 27.272727 | K22: =L22*18% -> 4.1602465 | L22: =J22/$L$3 -> 23.112481 | M22: =L22-L22/1.06 -> 1.3082536 | N22: =J22*$N$3 -> 3.2727273 | O22: =J22-M22-N22 -> 22.691746 | P22: =O22*F22 -> 1021.1286
A23: 18 | B23: DAAL SEV | C23: 24 | D23: gm | E23: 30 | F23: 45 | G23: 0 | J23: =E23/$J$3 -> 27.272727 | K23: =L23*18% -> 4.1602465 | L23: =J23/$L$3 -> 23.112481 | M23: =L23-L23/1.06 -> 1.3082536 | N23: =J23*$N$3 -> 3.2727273 | O23: =J23-M23-N23 -> 22.691746 | P23: =O23*F23 -> 1021.1286
A24: 19 | B24: SLANTY (SALTED) | C24: 15 | D24: gm | E24: 30 | F24: 30 | G24: 0 | J24: =E24/$J$3 -> 27.272727 | K24: =L24*18% -> 4.1602465 | L24: =J24/$L$3 -> 23.112481 | M24: =L24-L24/1.06 -> 1.3082536 | N24: =J24*$N$3 -> 3.2727273 | O24: =J24-M24-N24 -> 22.691746 | P24: =O24*F24 -> 680.75239
A25: 20 | B25: SLANTY (VEGETABLE EU) | C25: 15 | D25: gm | E25: 30 | F25: 30 | G25: 0 | J25: =E25/$J$3 -> 27.272727 | K25: =L25*18% -> 4.1602465 | L25: =J25/$L$3 -> 23.112481 | M25: =L25-L25/1.06 -> 1.3082536 | N25: =J25*$N$3 -> 3.2727273 | O25: =J25-M25-N25 -> 22.691746 | P25: =O25*F25 -> 680.75239
A26: 21 | B26: SLANTY (KETCHUP) | C26: 15 | D26: gm | E26: 30 | F26: 30 | G26: Hold For Printing | J26: =E26/$J$3 -> 27.272727 | K26: =L26*18% -> 4.1602465 | L26: =J26/$L$3 -> 23.112481 | M26: =L26-L26/1.06 -> 1.3082536 | N26: =J26*$N$3 -> 3.2727273 | O26: =J26-M26-N26 -> 22.691746 | P26: =O26*F26 -> 680.75239
A28: 22 | B28: NIMKO SALT & PEPPER | C28: 40 | D28: gm | E28: 50 | F28: 30 | G28: 100 | J28: =E28/$J$3 -> 45.454545 | K28: =L28*18% -> 6.9337442 | L28: =J28/$L$3 -> 38.520801 | M28: =L28-L28/1.06 -> 2.1804227 | N28: =J28*$N$3 -> 5.4545455 | O28: =J28-M28-N28 -> 37.819577 | P28: =O28*F28 -> 1134.5873
A29: 23 | B29: CHEWRA NIMKO | C29: 30 | D29: gm | E29: 50 | F29: 30 | G29: 100 | J29: =E29/$J$3 -> 45.454545 | K29: =L29*18% -> 6.9337442 | L29: =J29/$L$3 -> 38.520801 | M29: =L29-L29/1.06 -> 2.1804227 | N29: =J29*$N$3 -> 5.4545455 | O29: =J29-M29-N29 -> 37.819577 | P29: =O29*F29 -> 1134.5873
A30: 24 | B30: DAAL MOUNG | C30: 30 | D30: gm | E30: 50 | F30: 45 | G30: 0 | J30: =E30/$J$3 -> 45.454545 | K30: =L30*18% -> 6.9337442 | L30: =J30/$L$3 -> 38.520801 | M30: =L30-L30/1.06 -> 2.1804227 | N30: =J30*$N$3 -> 5.4545455 | O30: =J30-M30-N30 -> 37.819577 | P30: =O30*F30 -> 1701.881
A31: 25 | B31: SALTED PEANUT | C31: 25 | D31: gm | E31: 50 | F31: 45 | G31: 50 | J31: =E31/$J$3 -> 45.454545 | K31: =L31*18% -> 6.9337442 | L31: =J31/$L$3 -> 38.520801 | M31: =L31-L31/1.06 -> 2.1804227 | N31: =J31*$N$3 -> 5.4545455 | O31: =J31-M31-N31 -> 37.819577 | P31: =O31*F31 -> 1701.881
A32: 26 | B32: PEANUT UNSALTED | C32: 25 | D32: gm | E32: 50 | F32: 45 | G32: 50 | J32: =E32/$J$3 -> 45.454545 | K32: =L32*18% -> 6.9337442 | L32: =J32/$L$3 -> 38.520801 | M32: =L32-L32/1.06 -> 2.1804227 | N32: =J32*$N$3 -> 5.4545455 | O32: =J32-M32-N32 -> 37.819577 | P32: =O32*F32 -> 1701.881
A33: 27 | B33: KHAT MITHA | C33: 30 | D33: gm | E33: 50 | F33: 30 | G33: 100 | J33: =E33/$J$3 -> 45.454545 | K33: =L33*18% -> 6.9337442 | L33: =J33/$L$3 -> 38.520801 | M33: =L33-L33/1.06 -> 2.1804227 | N33: =J33*$N$3 -> 5.4545455 | O33: =J33-M33-N33 -> 37.819577 | P33: =O33*F33 -> 1134.5873
A34: 28 | B34: KARACHI NIMCO MIX | C34: 40 | D34: gm | E34: 50 | F34: 30 | G34: 0 | J34: =E34/$J$3 -> 45.454545 | K34: =L34*18% -> 6.9337442 | L34: =J34/$L$3 -> 38.520801 | M34: =L34-L34/1.06 -> 2.1804227 | N34: =J34*$N$3 -> 5.4545455 | O34: =J34-M34-N34 -> 37.819577 | P34: =O34*F34 -> 1134.5873
A35: 29 | B35: SLANTY (SALTED) | C35: 28 | D35: gm | E35: 50 | F35: 24 | G35: 0 | J35: =E35/$J$3 -> 45.454545 | K35: =L35*18% -> 6.9337442 | L35: =J35/$L$3 -> 38.520801 | M35: =L35-L35/1.06 -> 2.1804227 | N35: =J35*$N$3 -> 5.4545455 | O35: =J35-M35-N35 -> 37.819577 | P35: =O35*F35 -> 907.66985
A36: 30 | B36: SLANTY (VEGETABLE EU) | C36: 28 | D36: gm | E36: 50 | F36: 24 | G36: 0 | J36: =E36/$J$3 -> 45.454545 | K36: =L36*18% -> 6.9337442 | L36: =J36/$L$3 -> 38.520801 | M36: =L36-L36/1.06 -> 2.1804227 | N36: =J36*$N$3 -> 5.4545455 | O36: =J36-M36-N36 -> 37.819577 | P36: =O36*F36 -> 907.66985
A37: 31 | B37: SLANTY (KETCHUP) | C37: 28 | D37: gm | E37: 50 | G37: Hold For Printing | J37: =E37/$J$3 -> 45.454545 | K37: =L37*18% -> 6.9337442 | L37: =J37/$L$3 -> 38.520801 | M37: =L37-L37/1.06 -> 2.1804227 | N37: =J37*$N$3 -> 5.4545455 | O37: =J37-M37-N37 -> 37.819577 | P37: =O37*F37 -> 0
A39: 32 | B39: SALTED PEANUT | C39: 40 | D39: gm | E39: 80 | F39: 30 | G39: 50 | J39: =E39/$J$3 -> 72.727273 | K39: =L39*18% -> 11.093991 | L39: =J39/$L$3 -> 61.633282 | M39: =L39-L39/1.06 -> 3.4886763 | N39: =J39*$N$3 -> 8.7272727 | O39: =J39-M39-N39 -> 60.511324 | P39: =O39*F39 -> 1815.3397
A40: 33 | B40: PEANUT UNSALTED | C40: 40 | D40: gm | E40: 80 | F40: 30 | G40: 50 | J40: =E40/$J$3 -> 72.727273 | K40: =L40*18% -> 11.093991 | L40: =J40/$L$3 -> 61.633282 | M40: =L40-L40/1.06 -> 3.4886763 | N40: =J40*$N$3 -> 8.7272727 | O40: =J40-M40-N40 -> 60.511324 | P40: =O40*F40 -> 1815.3397
A42: 34 | B42: SHAHI MIX | C42: 80 | D42: gm | E42: 250 | F42: 40 | G42: 100 | J42: =E42/$J$3 -> 227.27273 | K42: =L42*18% -> 34.668721 | L42: =J42/$L$3 -> 192.60401 | M42: =L42-L42/1.06 -> 10.902114 | N42: =J42*$N$3 -> 27.272727 | O42: =J42-M42-N42 -> 189.09789 | P42: =O42*F42 -> 7563.9155
A43: 35 | B43: LAHORI MIX | C43: 80 | D43: gm | E43: 180 | F43: 40 | G43: 100 | J43: =E43/$J$3 -> 163.63636 | K43: =L43*18% -> 24.961479 | L43: =J43/$L$3 -> 138.67488 | M43: =L43-L43/1.06 -> 7.8495218 | N43: =J43*$N$3 -> 19.636364 | O43: =J43-M43-N43 -> 136.15048 | P43: =O43*F43 -> 5446.0191
A44: 36 | B44: NIMKO SALT & PEPPER | C44: 80 | D44: gm | E44: 120 | F44: 40 | G44: 50 | J44: =E44/$J$3 -> 109.09091 | K44: =L44*18% -> 16.640986 | L44: =J44/$L$3 -> 92.449923 | M44: =L44-L44/1.06 -> 5.2330145 | N44: =J44*$N$3 -> 13.090909 | O44: =J44-M44-N44 -> 90.766985 | P44: =O44*F44 -> 3630.6794
A46: 37 | B46: SHAHI MIX | C46: 180 | D46: gm | E46: 500 | F46: 27 | G46: 0 | J46: =E46/$J$3 -> 454.54545 | K46: =L46*18% -> 69.337442 | L46: =J46/$L$3 -> 385.20801 | M46: =L46-L46/1.06 -> 21.804227 | N46: =J46*$N$3 -> 54.545455 | O46: =J46-M46-N46 -> 378.19577 | P46: =O46*F46 -> 10211.286
...

Sheet Dist Price List
A2: DEMAND FOR SAMPLES
A3: SNACK FOOD SKU UPDATED LIST | J3: 1.1 | K3: 0.18 | L3: 1.18 | M3: 0.045 | N3: 0.12 | O3: Ex. Price | S3: 0.06 | U3: =K3 -> 0.18
A4: Sr.No | B4: SKUs | C4: Weight gms | E4: Price PKR | F4: Packets / Cartons | G4: Packets | H4: Cartons | J4: Trade Price | K4: GST | L4: Exclusive GST | M4: Adv. TO / Pack | N4: Dis. Margin | O4: Pack | P4: CTN
A5: 1 | B5: DAAL SEV | C5: 16 | D5: gm | E5: 20 | F5: 72 | G5: 100 | J5: =E5/$J$3 -> 18.181818 | K5: =L5*18% -> 2.7734977 | L5: =J5/$L$3 -> 15.40832 | M5: =L5-L5/1.045 -> 0.66351619 | N5: =L5-L5/1.12 -> 1.6508915 | O5: =J5-M5-N5 -> 15.867411 | P5: =O5*F5 -> 1142.4536 | Q5: =L5-M5-N5 -> 13.093913 | S5: =L5*S3 -> 0.92449923 | T5: =L5-S5 -> 14.483821 | U5: =T5+T5*U3 -> 17.090909
A6: 2 | B6: POTATO STICK (CHATPATA) | C6: 16 | D6: gm | E6: 20 | F6: 72 | G6: 100 | J6: =E6/$J$3 -> 18.181818 | K6: =L6*18% -> 2.7734977 | L6: =J6/$L$3 -> 15.40832 | M6: =L6-L6/1.06 -> 0.87216908 | N6: =J6*$N$3 -> 2.1818182 | O6: =J6-M6-N6 -> 15.127831 | P6: =O6*F6 -> 1089.2038 | U6: =U5*12 -> 205.09091
A7: 3 | B7: SPICY MIX NIMKO | C7: 16 | D7: gm | E7: 20 | F7: 72 | G7: 100 | J7: =E7/$J$3 -> 18.181818 | K7: =L7*18% -> 2.7734977 | L7: =J7/$L$3 -> 15.40832 | M7: =L7-L7/1.06 -> 0.87216908 | N7: =J7*$N$3 -> 2.1818182 | O7: =J7-M7-N7 -> 15.127831 | P7: =O7*F7 -> 1089.2038
A8: 4 | B8: NIMBOO DAAL | C8: 16 | D8: gm | E8: 20 | F8: 72 | G8: 100 | J8: =E8/$J$3 -> 18.181818 | K8: =L8*18% -> 2.7734977 | L8: =J8/$L$3 -> 15.40832 | M8: =L8-L8/1.06 -> 0.87216908 | N8: =J8*$N$3 -> 2.1818182 | O8: =J8-M8-N8 -> 15.127831 | P8: =O8*F8 -> 1089.2038
A9: 5 | B9: NIMKO MIX HOT & SPICY | C9: 16 | D9: gm | E9: 20 | F9: 72 | G9: 0 | J9: =E9/$J$3 -> 18.181818 | K9: =L9*18% -> 2.7734977 | L9: =J9/$L$3 -> 15.40832 | M9: =L9-L9/1.06 -> 0.87216908 | N9: =J9*$N$3 -> 2.1818182 | O9: =J9-M9-N9 -> 15.127831 | P9: =O9*F9 -> 1089.2038
A10: 6 | B10: NIMKO MIX LEMON & CHILLI | C10: 16 | D10: gm | E10: 20 | F10: 72 | G10: 0 | J10: =E10/$J$3 -> 18.181818 | K10: =L10*18% -> 2.7734977 | L10: =J10/$L$3 -> 15.40832 | M10: =L10-L10/1.06 -> 0.87216908 | N10: =J10*$N$3 -> 2.1818182 | O10: =J10-M10-N10 -> 15.127831 | P10: =O10*F10 -> 1089.2038
A11: 7 | B11: SLANTY (SALTED) | C11: 10 | D11: gm | E11: 20 | F11: 45 | G11: 0 | J11: =E11/$J$3 -> 18.181818 | K11: =L11*18% -> 2.7734977 | L11: =J11/$L$3 -> 15.40832 | M11: =L11-L11/1.06 -> 0.87216908 | N11: =J11*$N$3 -> 2.1818182 | O11: =J11-M11-N11 -> 15.127831 | P11: =O11*F11 -> 680.75239
A12: 8 | B12: SLANTY (VEGETABLE EU) | C12: 10 | D12: gm | E12: 20 | F12: 45 | G12: 0 | J12: =E12/$J$3 -> 18.181818 | K12: =L12*18% -> 2.7734977 | L12: =J12/$L$3 -> 15.40832 | M12: =L12-L12/1.06 -> 0.87216908 | N12: =J12*$N$3 -> 2.1818182 | O12: =J12-M12-N12 -> 15.127831 | P12: =O12*F12 -> 680.75239
A13: 9 | B13: SLANTY (KETCHUP) | C13: 10 | D13: gm | E13: 20 | F13: 45 | G13: Hold For Printing | J13: =E13/$J$3 -> 18.181818 | K13: =L13*18% -> 2.7734977 | L13: =J13/$L$3 -> 15.40832 | M13: =L13-L13/1.06 -> 0.87216908 | N13: =J13*$N$3 -> 2.1818182 | O13: =J13-M13-N13 -> 15.127831 | P13: =O13*F13 -> 680.75239
A15: 10 | B15: NIMBOO DAAL | C15: 24 | D15: gm | E15: 30 | F15: 45 | G15: 0 | J15: =E15/$J$3 -> 27.272727 | K15: =L15*18% -> 4.1602465 | L15: =J15/$L$3 -> 23.112481 | M15: =L15-L15/1.06 -> 1.3082536 | N15: =J15*$N$3 -> 3.2727273 | O15: =J15-M15-N15 -> 22.691746 | P15: =O15*F15 -> 1021.1286
A16: 11 | B16: DAAL MOUNG | C16: 18 | D16: gm | E16: 30 | F16: 72 | G16: 100 | J16: =E16/$J$3 -> 27.272727 | K16: =L16*18% -> 4.1602465 | L16: =J16/$L$3 -> 23.112481 | M16: =L16-L16/1.06 -> 1.3082536 | N16: =J16*$N$3 -> 3.2727273 | O16: =J16-M16-N16 -> 22.691746 | P16: =O16*F16 -> 1633.8057
A17: 12 | B17: NIMKO MIX HOT & SPICY | C17: 24 | D17: gm | E17: 30 | F17: 45 | G17: 100 | J17: =E17/$J$3 -> 27.272727 | K17: =L17*18% -> 4.1602465 | L17: =J17/$L$3 -> 23.112481 | M17: =L17-L17/1.06 -> 1.3082536 | N17: =J17*$N$3 -> 3.2727273 | O17: =J17-M17-N17 -> 22.691746 | P17: =O17*F17 -> 1021.1286
A18: 13 | B18: POTATO STICK (SALT & PEPPER) | C18: 24 | D18: gm | E18: 30 | F18: 45 | G18: 100 | J18: =E18/$J$3 -> 27.272727 | K18: =L18*18% -> 4.1602465 | L18: =J18/$L$3 -> 23.112481 | M18: =L18-L18/1.06 -> 1.3082536 | N18: =J18*$N$3 -> 3.2727273 | O18: =J18-M18-N18 -> 22.691746 | P18: =O18*F18 -> 1021.1286
A19: 14 | B19: SALTED PEANUT | C19: 16 | D19: gm | E19: 30 | F19: 85 | G19: 100 | J19: =E19/$J$3 -> 27.272727 | K19: =L19*18% -> 4.1602465 | L19: =J19/$L$3 -> 23.112481 | M19: =L19-L19/1.06 -> 1.3082536 | N19: =J19*$N$3 -> 3.2727273 | O19: =J19-M19-N19 -> 22.691746 | P19: =O19*F19 -> 1928.7984
A20: 15 | B20: PEANUT UNSALTED | C20: 16 | D20: gm | E20: 30 | F20: 85 | G20: 100 | J20: =E20/$J$3 -> 27.272727 | K20: =L20*18% -> 4.1602465 | L20: =J20/$L$3 -> 23.112481 | M20: =L20-L20/1.06 -> 1.3082536 | N20: =J20*$N$3 -> 3.2727273 | O20: =J20-M20-N20 -> 22.691746 | P20: =O20*F20 -> 1928.7984
A21: 16 | B21: NIMKO MIX LEMON & CHILLI | C21: 24 | D21: gm | E21: 30 | F21: 45 | G21: 0 | J21: =E21/$J$3 -> 27.272727 | K21: =L21*18% -> 4.1602465 | L21: =J21/$L$3 -> 23.112481 | M21: =L21-L21/1.06 -> 1.3082536 | N21: =J21*$N$3 -> 3.2727273 | O21: =J21-M21-N21 -> 22.691746 | P21: =O21*F21 -> 1021.1286
A22: 17 | B22: SPICY MIX NIMKO | C22: 24 | D22: gm | E22: 30 | F22: 45 | G22: 0 | J22: =E22/$J$3 -> 27.272727 | K22: =L22*18% -> 4.1602465 | L22: =J22/$L$3 -> 23.112481 | M22: =L22-L22/1.06 -> 1.3082536 | N22: =J22*$N$3 -> 3.2727273 | O22: =J22-M22-N22 -> 22.691746 | P22: =O22*F22 -> 1021.1286
A23: 18 | B23: DAAL SEV | C23: 24 | D23: gm | E23: 30 | F23: 45 | G23: 0 | J23: =E23/$J$3 -> 27.272727 | K23: =L23*18% -> 4.1602465 | L23: =J23/$L$3 -> 23.112481 | M23: =L23-L23/1.06 -> 1.3082536 | N23: =J23*$N$3 -> 3.2727273 | O23: =J23-M23-N23 -> 22.691746 | P23: =O23*F23 -> 1021.1286
A24: 19 | B24: SLANTY (SALTED) | C24: 15 | D24: gm | E24: 30 | F24: 30 | G24: 0 | J24: =E24/$J$3 -> 27.272727 | K24: =L24*18% -> 4.1602465 | L24: =J24/$L$3 -> 23.112481 | M24: =L24-L24/1.06 -> 1.3082536 | N24: =J24*$N$3 -> 3.2727273 | O24: =J24-M24-N24 -> 22.691746 | P24: =O24*F24 -> 680.75239
A25: 20 | B25: SLANTY (VEGETABLE EU) | C25: 15 | D25: gm | E25: 30 | F25: 30 | G25: 0 | J25: =E25/$J$3 -> 27.272727 | K25: =L25*18% -> 4.1602465 | L25: =J25/$L$3 -> 23.112481 | M25: =L25-L25/1.06 -> 1.3082536 | N25: =J25*$N$3 -> 3.2727273 | O25: =J25-M25-N25 -> 22.691746 | P25: =O25*F25 -> 680.75239
A26: 21 | B26: SLANTY (KETCHUP) | C26: 15 | D26: gm | E26: 30 | F26: 30 | G26: Hold For Printing | J26: =E26/$J$3 -> 27.272727 | K26: =L26*18% -> 4.1602465 | L26: =J26/$L$3 -> 23.112481 | M26: =L26-L26/1.06 -> 1.3082536 | N26: =J26*$N$3 -> 3.2727273 | O26: =J26-M26-N26 -> 22.691746 | P26: =O26*F26 -> 680.75239
A28: 22 | B28: NIMKO SALT & PEPPER | C28: 40 | D28: gm | E28: 50 | F28: 30 | G28: 100 | J28: =E28/$J$3 -> 45.454545 | K28: =L28*18% -> 6.9337442 | L28: =J28/$L$3 -> 38.520801 | M28: =L28-L28/1.06 -> 2.1804227 | N28: =J28*$N$3 -> 5.4545455 | O28: =J28-M28-N28 -> 37.819577 | P28: =O28*F28 -> 1134.5873
A29: 23 | B29: CHEWRA NIMKO | C29: 30 | D29: gm | E29: 50 | F29: 30 | G29: 100 | J29: =E29/$J$3 -> 45.454545 | K29: =L29*18% -> 6.9337442 | L29: =J29/$L$3 -> 38.520801 | M29: =L29-L29/1.06 -> 2.1804227 | N29: =J29*$N$3 -> 5.4545455 | O29: =J29-M29-N29 -> 37.819577 | P29: =O29*F29 -> 1134.5873
A30: 24 | B30: DAAL MOUNG | C30: 30 | D30: gm | E30: 50 | F30: 45 | G30: 0 | J30: =E30/$J$3 -> 45.454545 | K30: =L30*18% -> 6.9337442 | L30: =J30/$L$3 -> 38.520801 | M30: =L30-L30/1.06 -> 2.1804227 | N30: =J30*$N$3 -> 5.4545455 | O30: =J30-M30-N30 -> 37.819577 | P30: =O30*F30 -> 1701.881
A31: 25 | B31: SALTED PEANUT | C31: 25 | D31: gm | E31: 50 | F31: 45 | G31: 50 | J31: =E31/$J$3 -> 45.454545 | K31: =L31*18% -> 6.9337442 | L31: =J31/$L$3 -> 38.520801 | M31: =L31-L31/1.06 -> 2.1804227 | N31: =J31*$N$3 -> 5.4545455 | O31: =J31-M31-N31 -> 37.819577 | P31: =O31*F31 -> 1701.881
A32: 26 | B32: PEANUT UNSALTED | C32: 25 | D32: gm | E32: 50 | F32: 45 | G32: 50 | J32: =E32/$J$3 -> 45.454545 | K32: =L32*18% -> 6.9337442 | L32: =J32/$L$3 -> 38.520801 | M32: =L32-L32/1.06 -> 2.1804227 | N32: =J32*$N$3 -> 5.4545455 | O32: =J32-M32-N32 -> 37.819577 | P32: =O32*F32 -> 1701.881
A33: 27 | B33: KHAT MITHA | C33: 30 | D33: gm | E33: 50 | F33: 30 | G33: 100 | J33: =E33/$J$3 -> 45.454545 | K33: =L33*18% -> 6.9337442 | L33: =J33/$L$3 -> 38.520801 | M33: =L33-L33/1.06 -> 2.1804227 | N33: =J33*$N$3 -> 5.4545455 | O33: =J33-M33-N33 -> 37.819577 | P33: =O33*F33 -> 1134.5873
A34: 28 | B34: KARACHI NIMCO MIX | C34: 40 | D34: gm | E34: 50 | F34: 30 | G34: 0 | J34: =E34/$J$3 -> 45.454545 | K34: =L34*18% -> 6.9337442 | L34: =J34/$L$3 -> 38.520801 | M34: =L34-L34/1.06 -> 2.1804227 | N34: =J34*$N$3 -> 5.4545455 | O34: =J34-M34-N34 -> 37.819577 | P34: =O34*F34 -> 1134.5873
A35: 29 | B35: SLANTY (SALTED) | C35: 28 | D35: gm | E35: 50 | F35: 24 | G35: 0 | J35: =E35/$J$3 -> 45.454545 | K35: =L35*18% -> 6.9337442 | L35: =J35/$L$3 -> 38.520801 | M35: =L35-L35/1.06 -> 2.1804227 | N35: =J35*$N$3 -> 5.4545455 | O35: =J35-M35-N35 -> 37.819577 | P35: =O35*F35 -> 907.66985
A36: 30 | B36: SLANTY (VEGETABLE EU) | C36: 28 | D36: gm | E36: 50 | F36: 24 | G36: 0 | J36: =E36/$J$3 -> 45.454545 | K36: =L36*18% -> 6.9337442 | L36: =J36/$L$3 -> 38.520801 | M36: =L36-L36/1.06 -> 2.1804227 | N36: =J36*$N$3 -> 5.4545455 | O36: =J36-M36-N36 -> 37.819577 | P36: =O36*F36 -> 907.66985
A37: 31 | B37: SLANTY (KETCHUP) | C37: 28 | D37: gm | E37: 50 | G37: Hold For Printing | J37: =E37/$J$3 -> 45.454545 | K37: =L37*18% -> 6.9337442 | L37: =J37/$L$3 -> 38.520801 | M37: =L37-L37/1.06 -> 2.1804227 | N37: =J37*$N$3 -> 5.4545455 | O37: =J37-M37-N37 -> 37.819577 | P37: =O37*F37 -> 0
A39: 32 | B39: SALTED PEANUT | C39: 40 | D39: gm | E39: 80 | F39: 30 | G39: 50 | J39: =E39/$J$3 -> 72.727273 | K39: =L39*18% -> 11.093991 | L39: =J39/$L$3 -> 61.633282 | M39: =L39-L39/1.06 -> 3.4886763 | N39: =J39*$N$3 -> 8.7272727 | O39: =J39-M39-N39 -> 60.511324 | P39: =O39*F39 -> 1815.3397
A40: 33 | B40: PEANUT UNSALTED | C40: 40 | D40: gm | E40: 80 | F40: 30 | G40: 50 | J40: =E40/$J$3 -> 72.727273 | K40: =L40*18% -> 11.093991 | L40: =J40/$L$3 -> 61.633282 | M40: =L40-L40/1.06 -> 3.4886763 | N40: =J40*$N$3 -> 8.7272727 | O40: =J40-M40-N40 -> 60.511324 | P40: =O40*F40 -> 1815.3397
A42: 34 | B42: SHAHI MIX | C42: 80 | D42: gm | E42: 250 | F42: 40 | G42: 100 | J42: =E42/$J$3 -> 227.27273 | K42: =L42*18% -> 34.668721 | L42: =J42/$L$3 -> 192.60401 | M42: =L42-L42/1.06 -> 10.902114 | N42: =J42*$N$3 -> 27.272727 | O42: =J42-M42-N42 -> 189.09789 | P42: =O42*F42 -> 7563.9155
A43: 35 | B43: LAHORI MIX | C43: 80 | D43: gm | E43: 180 | F43: 40 | G43: 100 | J43: =E43/$J$3 -> 163.63636 | K43: =L43*18% -> 24.961479 | L43: =J43/$L$3 -> 138.67488 | M43: =L43-L43/1.06 -> 7.8495218 | N43: =J43*$N$3 -> 19.636364 | O43: =J43-M43-N43 -> 136.15048 | P43: =O43*F43 -> 5446.0191
A44: 36 | B44: NIMKO SALT & PEPPER | C44: 80 | D44: gm | E44: 120 | F44: 40 | G44: 50 | J44: =E44/$J$3 -> 109.09091 | K44: =L44*18% -> 16.640986 | L44: =J44/$L$3 -> 92.449923 | M44: =L44-L44/1.06 -> 5.2330145 | N44: =J44*$N$3 -> 13.090909 | O44: =J44-M44-N44 -> 90.766985 | P44: =O44*F44 -> 3630.6794
A46: 37 | B46: SHAHI MIX | C46: 180 | D46: gm | E46: 500 | F46: 27 | G46: 0 | J46: =E46/$J$3 -> 454.54545 | K46: =L46*18% -> 69.337442 | L46: =J46/$L$3 -> 385.20801 | M46: =L46-L46/1.06 -> 21.804227 | N46: =J46*$N$3 -> 54.545455 | O46: =J46-M46-N46 -> 378.19577 | P46: =O46*F46 -> 10211.286
...

Sheet Cust. Price List
V2: 0.18
A4: S# | B4: Code | D4: SKU | E4: SKUs Description | F4: Unit | H4: Retail Price | J4: TP Incl. | L4: TP Excl. | N4: Dist Margin | P4: Trade Offre | R4: Stale | T4: Ex-Fac | V4: S.Tax | X4: Dist. Price
B5: Bar | C5: SKU | F5: Gm | G5: CTN | H5: Ctn | I5: Pk | J5: Ctn | K5: Pk | L5: Ctn | M5: Pk | N5: 0.19 | O5: Amount | P5: 0.04 | Q5: Amount | R5: 0.005 | S5: Amount | T5: Ctn | U5: Pk | V5: Ctn | W5: Pk | X5: Ctn | Y5: Pk | AA5: Weight/ctn
A6: 1 | C6: CCN | D6: CCN | E6: Meat Masala | F6: 70 | G6: 40 | H6: =I6*G6 -> 2600 | I6: 65 | J6: =K6*G6 -> 2560.17 | K6: =M6*1.22 -> 64.00425 | L6: 2098.5 | M6: =L6/G6 -> 52.4625 | N6: 0.11 | O6: =N6*M6 -> 5.770875 | Q6: =P6*M6 -> 0 | S6: =R6*M6 -> 0 | T6: =U6*G6 -> 1867.665 | U6: =M6-O6-Q6-S6 -> 46.691625 | V6: =T6*$V$2 -> 336.1797 | W6: =U6*$V$2 -> 8.4044925 | X6: =T6+V6 -> 2203.8447 | Y6: =U6+W6 -> 55.096118 | AA6: =(F6*G6)/1000 -> 2.8 | AB6: 2000 | AC6: =X6*AB6 -> 4407689.4
A7: =+A6+1 -> 2 | C7: VTN | D7: VTN | E7: Lemon Tarka | F7: 70 | G7: 40 | H7: =I7*G7 -> 2600 | I7: 65 | J7: =K7*G7 -> 2560.17 | K7: =M7*1.22 -> 64.00425 | L7: 2098.5 | M7: =L7/G7 -> 52.4625 | N7: =+N6 -> 0.11 | O7: =N7*M7 -> 5.770875 | Q7: =P7*M7 -> 0 | S7: =R7*M7 -> 0 | T7: =U7*G7 -> 1867.665 | U7: =M7-O7-Q7-S7 -> 46.691625 | V7: =T7*$V$2 -> 336.1797 | W7: =U7*$V$2 -> 8.4044925 | X7: =T7+V7 -> 2203.8447 | Y7: =U7+W7 -> 55.096118 | AA7: =(F7*G7)/1000 -> 2.8
A8: =+A7+1 -> 3 | C8: BCN | D8: BCN | E8: Chicken Chatkhara | F8: 70 | G8: 40 | H8: =I8*G8 -> 2600 | I8: 65 | J8: =K8*G8 -> 2560.17 | K8: =M8*1.22 -> 64.00425 | L8: 2098.5 | M8: =L8/G8 -> 52.4625 | N8: =+N7 -> 0.11 | O8: =N8*M8 -> 5.770875 | Q8: =P8*M8 -> 0 | S8: =R8*M8 -> 0 | T8: =U8*G8 -> 1867.665 | U8: =M8-O8-Q8-S8 -> 46.691625 | V8: =T8*$V$2 -> 336.1797 | W8: =U8*$V$2 -> 8.4044925 | X8: =T8+V8 -> 2203.8447 | Y8: =U8+W8 -> 55.096118 | AA8: =(F8*G8)/1000 -> 2.8
A9: =+A8+1 -> 4 | C9: CCNJ | D9: CCNJ | E9: Meat Masala (Jumbo) | F9: 120 | G9: 40 | H9: =I9*G9 -> 3600 | I9: 90 | J9: =K9*G9 -> 3544.832 | K9: =M9*1.22 -> 88.6208 | L9: 2905.6 | M9: =L9/G9 -> 72.64 | N9: =+N8 -> 0.11 | O9: =N9*M9 -> 7.9904 | Q9: =P9*M9 -> 0 | S9: =R9*M9 -> 0 | T9: =U9*G9 -> 2585.984 | U9: =M9-O9-Q9-S9 -> 64.6496 | V9: =T9*$V$2 -> 465.47712 | W9: =U9*$V$2 -> 11.636928 | X9: =T9+V9 -> 3051.4611 | Y9: =U9+W9 -> 76.286528 | AA9: =(F9*G9)/1000 -> 4.8 | AB9: 1000 | AC9: =X9*AB9 -> 3051461.1
A10: =+A9+1 -> 5 | C10: VTNJ | D10: VTNJ | E10: Lemon Tarka (Jumbo) | F10: 120 | G10: 40 | H10: =I10*G10 -> 3600 | I10: 90 | J10: =K10*G10 -> 3544.832 | K10: =M10*1.22 -> 88.6208 | L10: 2905.6 | M10: =L10/G10 -> 72.64 | N10: =+N9 -> 0.11 | O10: =N10*M10 -> 7.9904 | Q10: =P10*M10 -> 0 | S10: =R10*M10 -> 0 | T10: =U10*G10 -> 2585.984 | U10: =M10-O10-Q10-S10 -> 64.6496 | V10: =T10*$V$2 -> 465.47712 | W10: =U10*$V$2 -> 11.636928 | X10: =T10+V10 -> 3051.4611 | Y10: =U10+W10 -> 76.286528 | AA10: =(F10*G10)/1000 -> 4.8
A11: =+A10+1 -> 6 | C11: BCNJ | D11: BCNJ | E11: Chicken Chatkhara (Jumbo) | F11: 120 | G11: 40 | H11: =I11*G11 -> 3600 | I11: 90 | J11: =K11*G11 -> 3544.832 | K11: =M11*1.22 -> 88.6208 | L11: 2905.6 | M11: =L11/G11 -> 72.64 | N11: =+N10 -> 0.11 | O11: =N11*M11 -> 7.9904 | Q11: =P11*M11 -> 0 | S11: =R11*M11 -> 0 | T11: =U11*G11 -> 2585.984 | U11: =M11-O11-Q11-S11 -> 64.6496 | V11: =T11*$V$2 -> 465.47712 | W11: =U11*$V$2 -> 11.636928 | X11: =T11+V11 -> 3051.4611 | Y11: =U11+W11 -> 76.286528 | AA11: =(F11*G11)/1000 -> 4.8
A12: =+A11+1 -> 7 | C12: CCE | D12: CCE | E12: Chicken Chatkhara (ECO) | F12: 60 | G12: 40 | H12: =I12*G12 -> 2000 | I12: 50 | J12: =K12*G12 -> 1914.424 | K12: =M12*1.22 -> 47.8606 | L12: 1569.2 | M12: =L12/G12 -> 39.23 | N12: =+N11 -> 0.11 | O12: =N12*M12 -> 4.3153 | Q12: =P12*M12 -> 0 | S12: =R12*M12 -> 0 | T12: =U12*G12 -> 1396.588 | U12: =M12-O12-Q12-S12 -> 34.9147 | V12: =T12*$V$2 -> 251.38584 | W12: =U12*$V$2 -> 6.284646 | X12: =T12+V12 -> 1647.9738 | Y12: =U12+W12 -> 41.199346 | AA12: =(F12*G12)/1000 -> 2.4 | AB12: 2000 | AC12: =X12*AB12 -> 3295947.7
A13: =+A12+1 -> 8 | C13: VTE | D13: VTE | E13: Lemon Tarka (ECO) | F13: 60 | G13: 40 | H13: =I13*G13 -> 2000 | I13: 50 | J13: =K13*G13 -> 1914.424 | K13: =M13*1.22 -> 47.8606 | L13: 1569.2 | M13: =L13/G13 -> 39.23 | N13: =+N12 -> 0.11 | O13: =N13*M13 -> 4.3153 | Q13: =P13*M13 -> 0 | S13: =R13*M13 -> 0 | T13: =U13*G13 -> 1396.588 | U13: =M13-O13-Q13-S13 -> 34.9147 | V13: =T13*$V$2 -> 251.38584 | W13: =U13*$V$2 -> 6.284646 | X13: =T13+V13 -> 1647.9738 | Y13: =U13+W13 -> 41.199346 | AA13: =(F13*G13)/1000 -> 2.4 | AC13: =SUM(AC6:AC12) -> 10755098
A14: =+A13+1 -> 9 | C14: BCE | D14: BCE | E14: Meat Masala (ECO) | F14: 60 | G14: 40 | H14: =I14*G14 -> 2000 | I14: 50 | J14: =K14*G14 -> 1914.424 | K14: =M14*1.22 -> 47.8606 | L14: 1569.2 | M14: =L14/G14 -> 39.23 | N14: =+N13 -> 0.11 | O14: =N14*M14 -> 4.3153 | Q14: =P14*M14 -> 0 | S14: =R14*M14 -> 0 | T14: =U14*G14 -> 1396.588 | U14: =M14-O14-Q14-S14 -> 34.9147 | V14: =T14*$V$2 -> 251.38584 | W14: =U14*$V$2 -> 6.284646 | X14: =T14+V14 -> 1647.9738 | Y14: =U14+W14 -> 41.199346 | AA14: =(F14*G14)/1000 -> 2.4
A15: =+A14+1 -> 10
A16: =+A15+1 -> 11
A17: =+A16+1 -> 12
A18: =+A17+1 -> 13
A19: =+A18+1 -> 14
A20: =+A19+1 -> 15
A22: =+A20+1 -> 16
A23: =+A22+1 -> 17
A24: =+A23+1 -> 18
A25: =+A24+1 -> 19
A26: =+A25+1 -> 20
A27: =+A26+1 -> 21
A28: =+A27+1 -> 22
A29: =+A28+1 -> 23
A30: =+A29+1 -> 24
A31: =+A30+1 -> 25
A32: =+A31+1 -> 26
A33: =+A32+1 -> 27
A34: =+A33+1 -> 28
A36: =+A34+1 -> 29
A37: =+A36+1 -> 30
A38: =+A37+1 -> 31
A39: =+A38+1 -> 32
A40: =+A39+1 -> 33
A41: =+A40+1 -> 34
A42: =+A41+1 -> 35
A43: =+A42+1 -> 36
A44: =+A43+1 -> 37
...

Sheet Summary
A2: Elite MARKETING | E2: Booker Name | H2: Shakoor | R2: Shop Summary
A3: 44A- Gulberg Lahore | E3: Dated | H3: 46268 | K3: Invoice No # : | R3: 1 | S3: =+'1'!A6:A6 -> Sana Cash & Carrry | T3: =+'1'!P35 -> 12824.233 | XEW3: Filer | XEX3: 0.005
N4: 46258 | R4: 2 | S4: =+'2'!A6:A6 -> Sana Cash & Carrry | T4: =+'2'!P35 -> 0 | XEX4: Tuesday / Wednesday
A5: Product Code/Description | C5: GM/ Pack | D5: CTN | E5: Unit | G5: Sale QTY | I5: Gross Amount Excl. Taxes | J5: Trade Offer & Discount | M5: After Discount Amount | N5: GST 18% | O5: Adv. Tax 236H | P5: Invoice | Q5: QTY | R5: 3 | S5: =+'3'!A6:A6 -> Sana Cash & Carrry | T5: =+'3'!P35 -> 0 | XEX5: Wednesday/Thursday
D6: SIZE | E6: MRP | F6: T.P Per | G6: CTN | H6: Pack | J6: Pass On | K6: Trade Offer | L6: additional | O6: =IF(#REF!="Filer",0.5%,2.5%) -> #REF! | P6: Amount | Q6: Return | R6: 4 | S6: =+'4'!A6:A6 -> Sana Cash & Carrry | T6: =+'4'!P35 -> 0 | XEX6: Thursday /Friday
A7: CCN | B7: =VLOOKUP($A7,'Cust. Price List'!$D$6:$O$14,2,0) -> Meat Masala | C7: =VLOOKUP(A7,'Cust. Price List'!D6:M14,3,0) -> 70 | D7: =VLOOKUP(A7,'Cust. Price List'!D6:M14,4,0) -> 40 | E7: =VLOOKUP(A7,'Cust. Price List'!D6:M14,6,0) -> 65 | F7: =VLOOKUP(A7,'Cust. Price List'!D6:M14,10,0) -> 52.4625 | G7: =+'1'!G16+'2'!G16+'3'!G16+'4'!G16+'5'!G16+'6'!G16+'7'!G16+'8'!G16+'9'!G16+'10'!G16+'11'!G16+'12'!G16+'13'!G16+'14'!G16+'15'!G16+'16'!G16+'17'!G16+'18'!G16+'19'!G16+'20'!G16+'21'!G16+'22'!G16+'23'!G16+'24'!G16+'25'!G16+'26'!G16+'27'!G16+'28'!G16+'29'!G16+'30'!G16 -> 0 | H7: =+'1'!Q16+'2'!H16+'3'!H16+'4'!H16+'5'!H16+'6'!H16+'7'!H16+'8'!H16+'9'!H16+'10'!H16+'11'!H16+'12'!H16+'13'!H16+'14'!H16+'15'!H16+'16'!H16+'17'!H16+'18'!H16+'19'!H16+'20'!H16+'21'!H16+'22'!H16+'23'!H16+'24'!H16+'25'!H16+'26'!H16+'27'!H16+'28'!H16+'29'!H16+'30'!H16 -> 40 | I7: =(G7*D7)*F7+H7*F7 -> 2098.5 | J7: =+'1'!J16+'2'!J16+'3'!J16+'4'!J16+'5'!J16+'6'!J16+'7'!J16+'8'!J16+'9'!J16+'10'!J16+'11'!J16+'12'!J16+'13'!J16+'14'!J16+'15'!J16+'16'!J16+'17'!J16+'18'!J16+'19'!J16+'20'!J16+'21'!J16+'22'!J16+'23'!J16+'24'!J16+'25'!J16+'26'!J16+'27'!J16+'28'!J16+'29'!J16+'30'!J16 -> 209.85 | K7: =+'1'!K16+'2'!K16+'3'!K16+'4'!K16+'5'!K16+'6'!K16+'7'!K16+'8'!K16+'9'!K16+'10'!K16+'11'!K16+'12'!K16+'13'!K16+'14'!K16+'15'!K16+'16'!K16+'17'!K16+'18'!K16+'19'!K16+'20'!K16+'21'!K16+'22'!K16+'23'!K16+'24'!K16+'25'!K16+'26'!K16+'27'!K16+'28'!K16+'29'!K16+'30'!K16 -> 73.4475 | L7: =+'1'!L16+'2'!L16+'3'!L16+'4'!L16+'5'!L16+'6'!L16+'7'!L16+'8'!L16+'9'!L16+'10'!L16+'11'!L16+'12'!L16+'13'!L16+'14'!L16+'15'!L16+'16'!L16+'17'!L16+'18'!L16+'19'!L16+'20'!L16+'21'!L16+'22'!L16+'23'!L16+'24'!L16+'25'!L16+'26'!L16+'27'!L16+'28'!L16+'29'!L16+'30'!L16 -> 0 | M7: =I7-SUM(J7:L7) -> 1815.2025 | N7: =+'1'!N16+'2'!N16+'3'!N16+'4'!N16+'5'!N16+'6'!N16+'7'!N16+'8'!N16+'9'!N16+'10'!N16+'11'!N16+'12'!N16+'13'!N16+'14'!N16+'15'!N16+'16'!N16+'17'!N16+'18'!N16+'19'!N16+'20'!N16+'21'!N16+'22'!N16+'23'!N16+'24'!N16+'25'!N16+'26'!N16+'27'!N16+'28'!N16+'29'!N16+'30'!N16 -> 396.61017 | O7: =+'1'!O16+'2'!O16+'3'!O16+'4'!O16+'5'!O16+'6'!O16+'7'!O16+'8'!O16+'9'!O16+'10'!O16+'11'!O16+'12'!O16+'13'!O16+'14'!O16+'15'!O16+'16'!O16+'17'!O16+'18'!O16+'19'!O16+'20'!O16+'21'!O16+'22'!O16+'23'!O16+'24'!O16+'25'!O16+'26'!O16+'27'!O16+'28'!O16+'29'!O16+'30'!O16 -> 11.059063 | P7: =M7+N7+O7 -> 2222.8717 | Q7: =+'1'!#REF!+'2'!Q16+'3'!Q16+'4'!Q16+'5'!Q16+'6'!Q16+'7'!Q16+'8'!Q16+'9'!Q16+'10'!Q16+'11'!Q16+'12'!Q16+'13'!Q16+'14'!Q16+'15'!Q16+'16'!Q16+'17'!Q16+'18'!Q16+'19'!Q16+'20'!Q16+'21'!Q16+'22'!Q16+'23'!Q16+'24'!Q16+'25'!Q16+'26'!Q16+'27'!Q16+'28'!Q16+'29'!Q16+'30'!Q16 -> #REF! | R7: 5 | S7: =+'5'!A6:A6 -> Sana Cash & Carrry | T7: =+'5'!P35 -> 0 | XEX7: Friday / Saturday
A8: VTN | B8: =VLOOKUP($A8,'Cust. Price List'!$D$6:$O$14,2,0) -> Lemon Tarka | C8: =VLOOKUP(B8,'Cust. Price List'!E7:P15,2,0) -> 70 | D8: =VLOOKUP(A8,'Cust. Price List'!D7:M15,4,0) -> 40 | E8: =VLOOKUP(A8,'Cust. Price List'!D7:M15,6,0) -> 65 | F8: =VLOOKUP(A8,'Cust. Price List'!D7:M15,10,0) -> 52.4625 | G8: =+'1'!G17+'2'!G17+'3'!G17+'4'!G17+'5'!G17+'6'!G17+'7'!G17+'8'!G17+'9'!G17+'10'!G17+'11'!G17+'12'!G17+'13'!G17+'14'!G17+'15'!G17+'16'!G17+'17'!G17+'18'!G17+'19'!G17+'20'!G17+'21'!G17+'22'!G17+'23'!G17+'24'!G17+'25'!G17+'26'!G17+'27'!G17+'28'!G17+'29'!G17+'30'!G17 -> 0 | H8: =+'1'!Q17+'2'!H17+'3'!H17+'4'!H17+'5'!H17+'6'!H17+'7'!H17+'8'!H17+'9'!H17+'10'!H17+'11'!H17+'12'!H17+'13'!H17+'14'!H17+'15'!H17+'16'!H17+'17'!H17+'18'!H17+'19'!H17+'20'!H17+'21'!H17+'22'!H17+'23'!H17+'24'!H17+'25'!H17+'26'!H17+'27'!H17+'28'!H17+'29'!H17+'30'!H17 -> 40 | I8: =(G8*D8)*F8+H8*F8 -> 2098.5 | J8: =+'1'!J17+'2'!J17+'3'!J17+'4'!J17+'5'!J17+'6'!J17+'7'!J17+'8'!J17+'9'!J17+'10'!J17+'11'!J17+'12'!J17+'13'!J17+'14'!J17+'15'!J17+'16'!J17+'17'!J17+'18'!J17+'19'!J17+'20'!J17+'21'!J17+'22'!J17+'23'!J17+'24'!J17+'25'!J17+'26'!J17+'27'!J17+'28'!J17+'29'!J17+'30'!J17 -> 209.85 | K8: =+'1'!K17+'2'!K17+'3'!K17+'4'!K17+'5'!K17+'6'!K17+'7'!K17+'8'!K17+'9'!K17+'10'!K17+'11'!K17+'12'!K17+'13'!K17+'14'!K17+'15'!K17+'16'!K17+'17'!K17+'18'!K17+'19'!K17+'20'!K17+'21'!K17+'22'!K17+'23'!K17+'24'!K17+'25'!K17+'26'!K17+'27'!K17+'28'!K17+'29'!K17+'30'!K17 -> 73.4475 | L8: =+'1'!L17+'2'!L17+'3'!L17+'4'!L17+'5'!L17+'6'!L17+'7'!L17+'8'!L17+'9'!L17+'10'!L17+'11'!L17+'12'!L17+'13'!L17+'14'!L17+'15'!L17+'16'!L17+'17'!L17+'18'!L17+'19'!L17+'20'!L17+'21'!L17+'22'!L17+'23'!L17+'24'!L17+'25'!L17+'26'!L17+'27'!L17+'28'!L17+'29'!L17+'30'!L17 -> 0 | M8: =I8-SUM(J8:L8) -> 1815.2025 | N8: =+'1'!N17+'2'!N17+'3'!N17+'4'!N17+'5'!N17+'6'!N17+'7'!N17+'8'!N17+'9'!N17+'10'!N17+'11'!N17+'12'!N17+'13'!N17+'14'!N17+'15'!N17+'16'!N17+'17'!N17+'18'!N17+'19'!N17+'20'!N17+'21'!N17+'22'!N17+'23'!N17+'24'!N17+'25'!N17+'26'!N17+'27'!N17+'28'!N17+'29'!N17+'30'!N17 -> 396.61017 | O8: =+'1'!O17+'2'!O17+'3'!O17+'4'!O17+'5'!O17+'6'!O17+'7'!O17+'8'!O17+'9'!O17+'10'!O17+'11'!O17+'12'!O17+'13'!O17+'14'!O17+'15'!O17+'16'!O17+'17'!O17+'18'!O17+'19'!O17+'20'!O17+'21'!O17+'22'!O17+'23'!O17+'24'!O17+'25'!O17+'26'!O17+'27'!O17+'28'!O17+'29'!O17+'30'!O17 -> 11.059063 | P8: =M8+N8+O8 -> 2222.8717 | Q8: =+'1'!#REF!+'2'!Q17+'3'!Q17+'4'!Q17+'5'!Q17+'6'!Q17+'7'!Q17+'8'!Q17+'9'!Q17+'10'!Q17+'11'!Q17+'12'!Q17+'13'!Q17+'14'!Q17+'15'!Q17+'16'!Q17+'17'!Q17+'18'!Q17+'19'!Q17+'20'!Q17+'21'!Q17+'22'!Q17+'23'!Q17+'24'!Q17+'25'!Q17+'26'!Q17+'27'!Q17+'28'!Q17+'29'!Q17+'30'!Q17 -> #REF! | R8: 6 | S8: =+'6'!A6:A6 -> Sana Cash & Carrry | T8: =+'6'!P35 -> 0 | XEX8: Saturday /Monday
A9: BCN | B9: =VLOOKUP($A9,'Cust. Price List'!$D$6:$O$14,2,0) -> Chicken Chatkhara | C9: =VLOOKUP(B9,'Cust. Price List'!E8:P16,2,0) -> 70 | D9: =VLOOKUP(A9,'Cust. Price List'!D8:M16,4,0) -> 40 | E9: =VLOOKUP(A9,'Cust. Price List'!D8:M16,6,0) -> 65 | F9: =VLOOKUP(A9,'Cust. Price List'!D8:M16,10,0) -> 52.4625 | G9: =+'1'!G18+'2'!G18+'3'!G18+'4'!G18+'5'!G18+'6'!G18+'7'!G18+'8'!G18+'9'!G18+'10'!G18+'11'!G18+'12'!G18+'13'!G18+'14'!G18+'15'!G18+'16'!G18+'17'!G18+'18'!G18+'19'!G18+'20'!G18+'21'!G18+'22'!G18+'23'!G18+'24'!G18+'25'!G18+'26'!G18+'27'!G18+'28'!G18+'29'!G18+'30'!G18 -> 0 | H9: =+'1'!Q18+'2'!H18+'3'!H18+'4'!H18+'5'!H18+'6'!H18+'7'!H18+'8'!H18+'9'!H18+'10'!H18+'11'!H18+'12'!H18+'13'!H18+'14'!H18+'15'!H18+'16'!H18+'17'!H18+'18'!H18+'19'!H18+'20'!H18+'21'!H18+'22'!H18+'23'!H18+'24'!H18+'25'!H18+'26'!H18+'27'!H18+'28'!H18+'29'!H18+'30'!H18 -> 40 | I9: =(G9*D9)*F9+H9*F9 -> 2098.5 | J9: =+'1'!J18+'2'!J18+'3'!J18+'4'!J18+'5'!J18+'6'!J18+'7'!J18+'8'!J18+'9'!J18+'10'!J18+'11'!J18+'12'!J18+'13'!J18+'14'!J18+'15'!J18+'16'!J18+'17'!J18+'18'!J18+'19'!J18+'20'!J18+'21'!J18+'22'!J18+'23'!J18+'24'!J18+'25'!J18+'26'!J18+'27'!J18+'28'!J18+'29'!J18+'30'!J18 -> 209.85 | K9: =+'1'!K18+'2'!K18+'3'!K18+'4'!K18+'5'!K18+'6'!K18+'7'!K18+'8'!K18+'9'!K18+'10'!K18+'11'!K18+'12'!K18+'13'!K18+'14'!K18+'15'!K18+'16'!K18+'17'!K18+'18'!K18+'19'!K18+'20'!K18+'21'!K18+'22'!K18+'23'!K18+'24'!K18+'25'!K18+'26'!K18+'27'!K18+'28'!K18+'29'!K18+'30'!K18 -> 73.4475 | L9: =+'1'!L18+'2'!L18+'3'!L18+'4'!L18+'5'!L18+'6'!L18+'7'!L18+'8'!L18+'9'!L18+'10'!L18+'11'!L18+'12'!L18+'13'!L18+'14'!L18+'15'!L18+'16'!L18+'17'!L18+'18'!L18+'19'!L18+'20'!L18+'21'!L18+'22'!L18+'23'!L18+'24'!L18+'25'!L18+'26'!L18+'27'!L18+'28'!L18+'29'!L18+'30'!L18 -> 0 | M9: =I9-SUM(J9:L9) -> 1815.2025 | N9: =+'1'!N18+'2'!N18+'3'!N18+'4'!N18+'5'!N18+'6'!N18+'7'!N18+'8'!N18+'9'!N18+'10'!N18+'11'!N18+'12'!N18+'13'!N18+'14'!N18+'15'!N18+'16'!N18+'17'!N18+'18'!N18+'19'!N18+'20'!N18+'21'!N18+'22'!N18+'23'!N18+'24'!N18+'25'!N18+'26'!N18+'27'!N18+'28'!N18+'29'!N18+'30'!N18 -> 396.61017 | O9: =+'1'!O18+'2'!O18+'3'!O18+'4'!O18+'5'!O18+'6'!O18+'7'!O18+'8'!O18+'9'!O18+'10'!O18+'11'!O18+'12'!O18+'13'!O18+'14'!O18+'15'!O18+'16'!O18+'17'!O18+'18'!O18+'19'!O18+'20'!O18+'21'!O18+'22'!O18+'23'!O18+'24'!O18+'25'!O18+'26'!O18+'27'!O18+'28'!O18+'29'!O18+'30'!O18 -> 11.059063 | P9: =M9+N9+O9 -> 2222.8717 | Q9: =+'1'!#REF!+'2'!Q18+'3'!Q18+'4'!Q18+'5'!Q18+'6'!Q18+'7'!Q18+'8'!Q18+'9'!Q18+'10'!Q18+'11'!Q18+'12'!Q18+'13'!Q18+'14'!Q18+'15'!Q18+'16'!Q18+'17'!Q18+'18'!Q18+'19'!Q18+'20'!Q18+'21'!Q18+'22'!Q18+'23'!Q18+'24'!Q18+'25'!Q18+'26'!Q18+'27'!Q18+'28'!Q18+'29'!Q18+'30'!Q18 -> #REF! | R9: 7 | S9: =+'7'!A6:A6 -> Sana Cash & Carrry | T9: =+'7'!P35 -> 0
A10: CCNJ | B10: =VLOOKUP($A10,'Cust. Price List'!$D$6:$O$14,2,0) -> Meat Masala (Jumbo) | C10: =VLOOKUP(B10,'Cust. Price List'!E9:P17,2,0) -> 120 | D10: =VLOOKUP(A10,'Cust. Price List'!D9:M17,4,0) -> 40 | E10: =VLOOKUP(A10,'Cust. Price List'!D9:M17,6,0) -> 90 | F10: =VLOOKUP(A10,'Cust. Price List'!D9:M17,10,0) -> 72.64 | G10: =+'1'!G19+'2'!G19+'3'!G19+'4'!G19+'5'!G19+'6'!G19+'7'!G19+'8'!G19+'9'!G19+'10'!G19+'11'!G19+'12'!G19+'13'!G19+'14'!G19+'15'!G19+'16'!G19+'17'!G19+'18'!G19+'19'!G19+'20'!G19+'21'!G19+'22'!G19+'23'!G19+'24'!G19+'25'!G19+'26'!G19+'27'!G19+'28'!G19+'29'!G19+'30'!G19 -> 0 | H10: =+'1'!Q19+'2'!H19+'3'!H19+'4'!H19+'5'!H19+'6'!H19+'7'!H19+'8'!H19+'9'!H19+'10'!H19+'11'!H19+'12'!H19+'13'!H19+'14'!H19+'15'!H19+'16'!H19+'17'!H19+'18'!H19+'19'!H19+'20'!H19+'21'!H19+'22'!H19+'23'!H19+'24'!H19+'25'!H19+'26'!H19+'27'!H19+'28'!H19+'29'!H19+'30'!H19 -> 40 | I10: =(G10*D10)*F10+H10*F10 -> 2905.6 | J10: =+'1'!J19+'2'!J19+'3'!J19+'4'!J19+'5'!J19+'6'!J19+'7'!J19+'8'!J19+'9'!J19+'10'!J19+'11'!J19+'12'!J19+'13'!J19+'14'!J19+'15'!J19+'16'!J19+'17'!J19+'18'!J19+'19'!J19+'20'!J19+'21'!J19+'22'!J19+'23'!J19+'24'!J19+'25'!J19+'26'!J19+'27'!J19+'28'!J19+'29'!J19+'30'!J19 -> 290.56 | K10: =+'1'!K19+'2'!K19+'3'!K19+'4'!K19+'5'!K19+'6'!K19+'7'!K19+'8'!K19+'9'!K19+'10'!K19+'11'!K19+'12'!K19+'13'!K19+'14'!K19+'15'!K19+'16'!K19+'17'!K19+'18'!K19+'19'!K19+'20'!K19+'21'!K19+'22'!K19+'23'!K19+'24'!K19+'25'!K19+'26'!K19+'27'!K19+'28'!K19+'29'!K19+'30'!K19 -> 101.696 | L10: =+'1'!L19+'2'!L19+'3'!L19+'4'!L19+'5'!L19+'6'!L19+'7'!L19+'8'!L19+'9'!L19+'10'!L19+'11'!L19+'12'!L19+'13'!L19+'14'!L19+'15'!L19+'16'!L19+'17'!L19+'18'!L19+'19'!L19+'20'!L19+'21'!L19+'22'!L19+'23'!L19+'24'!L19+'25'!L19+'26'!L19+'27'!L19+'28'!L19+'29'!L19+'30'!L19 -> 0 | M10: =I10-SUM(J10:L10) -> 2513.344 | N10: =+'1'!N19+'2'!N19+'3'!N19+'4'!N19+'5'!N19+'6'!N19+'7'!N19+'8'!N19+'9'!N19+'10'!N19+'11'!N19+'12'!N19+'13'!N19+'14'!N19+'15'!N19+'16'!N19+'17'!N19+'18'!N19+'19'!N19+'20'!N19+'21'!N19+'22'!N19+'23'!N19+'24'!N19+'25'!N19+'26'!N19+'27'!N19+'28'!N19+'29'!N19+'30'!N19 -> 549.15254 | O10: =+'1'!O19+'2'!O19+'3'!O19+'4'!O19+'5'!O19+'6'!O19+'7'!O19+'8'!O19+'9'!O19+'10'!O19+'11'!O19+'12'!O19+'13'!O19+'14'!O19+'15'!O19+'16'!O19+'17'!O19+'18'!O19+'19'!O19+'20'!O19+'21'!O19+'22'!O19+'23'!O19+'24'!O19+'25'!O19+'26'!O19+'27'!O19+'28'!O19+'29'!O19+'30'!O19 -> 15.312483 | P10: =M10+N10+O10 -> 3077.809 | Q10: =+'1'!#REF!+'2'!Q19+'3'!Q19+'4'!Q19+'5'!Q19+'6'!Q19+'7'!Q19+'8'!Q19+'9'!Q19+'10'!Q19+'11'!Q19+'12'!Q19+'13'!Q19+'14'!Q19+'15'!Q19+'16'!Q19+'17'!Q19+'18'!Q19+'19'!Q19+'20'!Q19+'21'!Q19+'22'!Q19+'23'!Q19+'24'!Q19+'25'!Q19+'26'!Q19+'27'!Q19+'28'!Q19+'29'!Q19+'30'!Q19 -> #REF! | R10: 8 | S10: =+'8'!A6:A6 -> Sana Cash & Carrry | T10: =+'8'!P35 -> 0
A11: VTNJ | B11: =VLOOKUP($A11,'Cust. Price List'!$D$6:$O$14,2,0) -> Lemon Tarka (Jumbo) | C11: =VLOOKUP(B11,'Cust. Price List'!E10:P18,2,0) -> 120 | D11: =VLOOKUP(A11,'Cust. Price List'!D10:M18,4,0) -> 40 | E11: =VLOOKUP(A11,'Cust. Price List'!D10:M18,6,0) -> 90 | F11: =VLOOKUP(A11,'Cust. Price List'!D10:M18,10,0) -> 72.64 | G11: =+'1'!G20+'2'!G20+'3'!G20+'4'!G20+'5'!G20+'6'!G20+'7'!G20+'8'!G20+'9'!G20+'10'!G20+'11'!G20+'12'!G20+'13'!G20+'14'!G20+'15'!G20+'16'!G20+'17'!G20+'18'!G20+'19'!G20+'20'!G20+'21'!G20+'22'!G20+'23'!G20+'24'!G20+'25'!G20+'26'!G20+'27'!G20+'28'!G20+'29'!G20+'30'!G20 -> 0 | H11: =+'1'!Q20+'2'!H20+'3'!H20+'4'!H20+'5'!H20+'6'!H20+'7'!H20+'8'!H20+'9'!H20+'10'!H20+'11'!H20+'12'!H20+'13'!H20+'14'!H20+'15'!H20+'16'!H20+'17'!H20+'18'!H20+'19'!H20+'20'!H20+'21'!H20+'22'!H20+'23'!H20+'24'!H20+'25'!H20+'26'!H20+'27'!H20+'28'!H20+'29'!H20+'30'!H20 -> 40 | I11: =(G11*D11)*F11+H11*F11 -> 2905.6 | J11: =+'1'!J20+'2'!J20+'3'!J20+'4'!J20+'5'!J20+'6'!J20+'7'!J20+'8'!J20+'9'!J20+'10'!J20+'11'!J20+'12'!J20+'13'!J20+'14'!J20+'15'!J20+'16'!J20+'17'!J20+'18'!J20+'19'!J20+'20'!J20+'21'!J20+'22'!J20+'23'!J20+'24'!J20+'25'!J20+'26'!J20+'27'!J20+'28'!J20+'29'!J20+'30'!J20 -> 290.56 | K11: =+'1'!K20+'2'!K20+'3'!K20+'4'!K20+'5'!K20+'6'!K20+'7'!K20+'8'!K20+'9'!K20+'10'!K20+'11'!K20+'12'!K20+'13'!K20+'14'!K20+'15'!K20+'16'!K20+'17'!K20+'18'!K20+'19'!K20+'20'!K20+'21'!K20+'22'!K20+'23'!K20+'24'!K20+'25'!K20+'26'!K20+'27'!K20+'28'!K20+'29'!K20+'30'!K20 -> 101.696 | L11: =+'1'!L20+'2'!L20+'3'!L20+'4'!L20+'5'!L20+'6'!L20+'7'!L20+'8'!L20+'9'!L20+'10'!L20+'11'!L20+'12'!L20+'13'!L20+'14'!L20+'15'!L20+'16'!L20+'17'!L20+'18'!L20+'19'!L20+'20'!L20+'21'!L20+'22'!L20+'23'!L20+'24'!L20+'25'!L20+'26'!L20+'27'!L20+'28'!L20+'29'!L20+'30'!L20 -> 0 | M11: =I11-SUM(J11:L11) -> 2513.344 | N11: =+'1'!N20+'2'!N20+'3'!N20+'4'!N20+'5'!N20+'6'!N20+'7'!N20+'8'!N20+'9'!N20+'10'!N20+'11'!N20+'12'!N20+'13'!N20+'14'!N20+'15'!N20+'16'!N20+'17'!N20+'18'!N20+'19'!N20+'20'!N20+'21'!N20+'22'!N20+'23'!N20+'24'!N20+'25'!N20+'26'!N20+'27'!N20+'28'!N20+'29'!N20+'30'!N20 -> 549.15254 | O11: =+'1'!O20+'2'!O20+'3'!O20+'4'!O20+'5'!O20+'6'!O20+'7'!O20+'8'!O20+'9'!O20+'10'!O20+'11'!O20+'12'!O20+'13'!O20+'14'!O20+'15'!O20+'16'!O20+'17'!O20+'18'!O20+'19'!O20+'20'!O20+'21'!O20+'22'!O20+'23'!O20+'24'!O20+'25'!O20+'26'!O20+'27'!O20+'28'!O20+'29'!O20+'30'!O20 -> 15.312483 | P11: =M11+N11+O11 -> 3077.809 | Q11: =+'1'!#REF!+'2'!Q20+'3'!Q20+'4'!Q20+'5'!Q20+'6'!Q20+'7'!Q20+'8'!Q20+'9'!Q20+'10'!Q20+'11'!Q20+'12'!Q20+'13'!Q20+'14'!Q20+'15'!Q20+'16'!Q20+'17'!Q20+'18'!Q20+'19'!Q20+'20'!Q20+'21'!Q20+'22'!Q20+'23'!Q20+'24'!Q20+'25'!Q20+'26'!Q20+'27'!Q20+'28'!Q20+'29'!Q20+'30'!Q20 -> #REF! | R11: 9 | S11: =+'9'!A6:A6 -> Sana Cash & Carrry | T11: =+'9'!P35 -> 0
A12: BCNJ | B12: =VLOOKUP($A12,'Cust. Price List'!$D$6:$O$14,2,0) -> Chicken Chatkhara (Jumbo) | C12: =VLOOKUP(B12,'Cust. Price List'!E11:P19,2,0) -> 120 | D12: =VLOOKUP(A12,'Cust. Price List'!D11:M19,4,0) -> 40 | E12: =VLOOKUP(A12,'Cust. Price List'!D11:M19,6,0) -> 90 | F12: =VLOOKUP(A12,'Cust. Price List'!D11:M19,10,0) -> 72.64 | G12: =+'1'!G21+'2'!G21+'3'!G21+'4'!G21+'5'!G21+'6'!G21+'7'!G21+'8'!G21+'9'!G21+'10'!G21+'11'!G21+'12'!G21+'13'!G21+'14'!G21+'15'!G21+'16'!G21+'17'!G21+'18'!G21+'19'!G21+'20'!G21+'21'!G21+'22'!G21+'23'!G21+'24'!G21+'25'!G21+'26'!G21+'27'!G21+'28'!G21+'29'!G21+'30'!G21 -> 0 | H12: =+'1'!H21+'2'!H21+'3'!H21+'4'!H21+'5'!H21+'6'!H21+'7'!H21+'8'!H21+'9'!H21+'10'!H21+'11'!H21+'12'!H21+'13'!H21+'14'!H21+'15'!H21+'16'!H21+'17'!H21+'18'!H21+'19'!H21+'20'!H21+'21'!H21+'22'!H21+'23'!H21+'24'!H21+'25'!H21+'26'!H21+'27'!H21+'28'!H21+'29'!H21+'30'!H21 -> 0 | I12: =(G12*D12)*F12+H12*F12 -> 0 | J12: =+'1'!J21+'2'!J21+'3'!J21+'4'!J21+'5'!J21+'6'!J21+'7'!J21+'8'!J21+'9'!J21+'10'!J21+'11'!J21+'12'!J21+'13'!J21+'14'!J21+'15'!J21+'16'!J21+'17'!J21+'18'!J21+'19'!J21+'20'!J21+'21'!J21+'22'!J21+'23'!J21+'24'!J21+'25'!J21+'26'!J21+'27'!J21+'28'!J21+'29'!J21+'30'!J21 -> 0 | K12: =+'1'!K21+'2'!K21+'3'!K21+'4'!K21+'5'!K21+'6'!K21+'7'!K21+'8'!K21+'9'!K21+'10'!K21+'11'!K21+'12'!K21+'13'!K21+'14'!K21+'15'!K21+'16'!K21+'17'!K21+'18'!K21+'19'!K21+'20'!K21+'21'!K21+'22'!K21+'23'!K21+'24'!K21+'25'!K21+'26'!K21+'27'!K21+'28'!K21+'29'!K21+'30'!K21 -> 0 | L12: =+'1'!L21+'2'!L21+'3'!L21+'4'!L21+'5'!L21+'6'!L21+'7'!L21+'8'!L21+'9'!L21+'10'!L21+'11'!L21+'12'!L21+'13'!L21+'14'!L21+'15'!L21+'16'!L21+'17'!L21+'18'!L21+'19'!L21+'20'!L21+'21'!L21+'22'!L21+'23'!L21+'24'!L21+'25'!L21+'26'!L21+'27'!L21+'28'!L21+'29'!L21+'30'!L21 -> 0 | M12: =I12-SUM(J12:L12) -> 0 | N12: =+'1'!N21+'2'!N21+'3'!N21+'4'!N21+'5'!N21+'6'!N21+'7'!N21+'8'!N21+'9'!N21+'10'!N21+'11'!N21+'12'!N21+'13'!N21+'14'!N21+'15'!N21+'16'!N21+'17'!N21+'18'!N21+'19'!N21+'20'!N21+'21'!N21+'22'!N21+'23'!N21+'24'!N21+'25'!N21+'26'!N21+'27'!N21+'28'!N21+'29'!N21+'30'!N21 -> 0 | O12: =+'1'!O21+'2'!O21+'3'!O21+'4'!O21+'5'!O21+'6'!O21+'7'!O21+'8'!O21+'9'!O21+'10'!O21+'11'!O21+'12'!O21+'13'!O21+'14'!O21+'15'!O21+'16'!O21+'17'!O21+'18'!O21+'19'!O21+'20'!O21+'21'!O21+'22'!O21+'23'!O21+'24'!O21+'25'!O21+'26'!O21+'27'!O21+'28'!O21+'29'!O21+'30'!O21 -> 0 | P12: =M12+N12+O12 -> 0 | Q12: =+'1'!Q21+'2'!Q21+'3'!Q21+'4'!Q21+'5'!Q21+'6'!Q21+'7'!Q21+'8'!Q21+'9'!Q21+'10'!Q21+'11'!Q21+'12'!Q21+'13'!Q21+'14'!Q21+'15'!Q21+'16'!Q21+'17'!Q21+'18'!Q21+'19'!Q21+'20'!Q21+'21'!Q21+'22'!Q21+'23'!Q21+'24'!Q21+'25'!Q21+'26'!Q21+'27'!Q21+'28'!Q21+'29'!Q21+'30'!Q21 -> 0 | R12: 10 | S12: =+'10'!A6:A6 -> Sana Cash & Carrry | T12: =+'10'!P35 -> 0
A13: CCE | B13: =VLOOKUP($A13,'Cust. Price List'!$D$6:$O$14,2,0) -> Chicken Chatkhara (ECO) | C13: =VLOOKUP(B13,'Cust. Price List'!E12:P20,2,0) -> 60 | D13: =VLOOKUP(A13,'Cust. Price List'!D12:M20,4,0) -> 40 | E13: =VLOOKUP(A13,'Cust. Price List'!D12:M20,6,0) -> 50 | F13: =VLOOKUP(A13,'Cust. Price List'!D12:M20,10,0) -> 39.23 | G13: =+'1'!G22+'2'!G22+'3'!G22+'4'!G22+'5'!G22+'6'!G22+'7'!G22+'8'!G22+'9'!G22+'10'!G22+'11'!G22+'12'!G22+'13'!G22+'14'!G22+'15'!G22+'16'!G22+'17'!G22+'18'!G22+'19'!G22+'20'!G22+'21'!G22+'22'!G22+'23'!G22+'24'!G22+'25'!G22+'26'!G22+'27'!G22+'28'!G22+'29'!G22+'30'!G22 -> 0 | H13: =+'1'!H22+'2'!H22+'3'!H22+'4'!H22+'5'!H22+'6'!H22+'7'!H22+'8'!H22+'9'!H22+'10'!H22+'11'!H22+'12'!H22+'13'!H22+'14'!H22+'15'!H22+'16'!H22+'17'!H22+'18'!H22+'19'!H22+'20'!H22+'21'!H22+'22'!H22+'23'!H22+'24'!H22+'25'!H22+'26'!H22+'27'!H22+'28'!H22+'29'!H22+'30'!H22 -> 0 | I13: =(G13*D13)*F13+H13*F13 -> 0 | J13: =+'1'!J22+'2'!J22+'3'!J22+'4'!J22+'5'!J22+'6'!J22+'7'!J22+'8'!J22+'9'!J22+'10'!J22+'11'!J22+'12'!J22+'13'!J22+'14'!J22+'15'!J22+'16'!J22+'17'!J22+'18'!J22+'19'!J22+'20'!J22+'21'!J22+'22'!J22+'23'!J22+'24'!J22+'25'!J22+'26'!J22+'27'!J22+'28'!J22+'29'!J22+'30'!J22 -> 0 | K13: =+'1'!K22+'2'!K22+'3'!K22+'4'!K22+'5'!K22+'6'!K22+'7'!K22+'8'!K22+'9'!K22+'10'!K22+'11'!K22+'12'!K22+'13'!K22+'14'!K22+'15'!K22+'16'!K22+'17'!K22+'18'!K22+'19'!K22+'20'!K22+'21'!K22+'22'!K22+'23'!K22+'24'!K22+'25'!K22+'26'!K22+'27'!K22+'28'!K22+'29'!K22+'30'!K22 -> 0 | L13: =+'1'!L22+'2'!L22+'3'!L22+'4'!L22+'5'!L22+'6'!L22+'7'!L22+'8'!L22+'9'!L22+'10'!L22+'11'!L22+'12'!L22+'13'!L22+'14'!L22+'15'!L22+'16'!L22+'17'!L22+'18'!L22+'19'!L22+'20'!L22+'21'!L22+'22'!L22+'23'!L22+'24'!L22+'25'!L22+'26'!L22+'27'!L22+'28'!L22+'29'!L22+'30'!L22 -> 0 | M13: =I13-SUM(J13:L13) -> 0 | N13: =+'1'!N22+'2'!N22+'3'!N22+'4'!N22+'5'!N22+'6'!N22+'7'!N22+'8'!N22+'9'!N22+'10'!N22+'11'!N22+'12'!N22+'13'!N22+'14'!N22+'15'!N22+'16'!N22+'17'!N22+'18'!N22+'19'!N22+'20'!N22+'21'!N22+'22'!N22+'23'!N22+'24'!N22+'25'!N22+'26'!N22+'27'!N22+'28'!N22+'29'!N22+'30'!N22 -> 0 | O13: =+'1'!O22+'2'!O22+'3'!O22+'4'!O22+'5'!O22+'6'!O22+'7'!O22+'8'!O22+'9'!O22+'10'!O22+'11'!O22+'12'!O22+'13'!O22+'14'!O22+'15'!O22+'16'!O22+'17'!O22+'18'!O22+'19'!O22+'20'!O22+'21'!O22+'22'!O22+'23'!O22+'24'!O22+'25'!O22+'26'!O22+'27'!O22+'28'!O22+'29'!O22+'30'!O22 -> 0 | P13: =M13+N13+O13 -> 0 | Q13: =+'1'!Q22+'2'!Q22+'3'!Q22+'4'!Q22+'5'!Q22+'6'!Q22+'7'!Q22+'8'!Q22+'9'!Q22+'10'!Q22+'11'!Q22+'12'!Q22+'13'!Q22+'14'!Q22+'15'!Q22+'16'!Q22+'17'!Q22+'18'!Q22+'19'!Q22+'20'!Q22+'21'!Q22+'22'!Q22+'23'!Q22+'24'!Q22+'25'!Q22+'26'!Q22+'27'!Q22+'28'!Q22+'29'!Q22+'30'!Q22 -> 0 | R13: 11 | S13: =+'11'!A6:A6 -> Sana Cash & Carrry | T13: =+'11'!P35 -> 0
A14: VTE | B14: =VLOOKUP($A14,'Cust. Price List'!$D$6:$O$14,2,0) -> Lemon Tarka (ECO) | C14: =VLOOKUP(B14,'Cust. Price List'!E13:P21,2,0) -> 60 | D14: =VLOOKUP(A14,'Cust. Price List'!D13:M21,4,0) -> 40 | E14: =VLOOKUP(A14,'Cust. Price List'!D13:M21,6,0) -> 50 | F14: =VLOOKUP(A14,'Cust. Price List'!D13:M21,10,0) -> 39.23 | G14: =+'1'!G23+'2'!G23+'3'!G23+'4'!G23+'5'!G23+'6'!G23+'7'!G23+'8'!G23+'9'!G23+'10'!G23+'11'!G23+'12'!G23+'13'!G23+'14'!G23+'15'!G23+'16'!G23+'17'!G23+'18'!G23+'19'!G23+'20'!G23+'21'!G23+'22'!G23+'23'!G23+'24'!G23+'25'!G23+'26'!G23+'27'!G23+'28'!G23+'29'!G23+'30'!G23 -> 0 | H14: =+'1'!H23+'2'!H23+'3'!H23+'4'!H23+'5'!H23+'6'!H23+'7'!H23+'8'!H23+'9'!H23+'10'!H23+'11'!H23+'12'!H23+'13'!H23+'14'!H23+'15'!H23+'16'!H23+'17'!H23+'18'!H23+'19'!H23+'20'!H23+'21'!H23+'22'!H23+'23'!H23+'24'!H23+'25'!H23+'26'!H23+'27'!H23+'28'!H23+'29'!H23+'30'!H23 -> 0 | I14: =(G14*D14)*F14+H14*F14 -> 0 | J14: =+'1'!J23+'2'!J23+'3'!J23+'4'!J23+'5'!J23+'6'!J23+'7'!J23+'8'!J23+'9'!J23+'10'!J23+'11'!J23+'12'!J23+'13'!J23+'14'!J23+'15'!J23+'16'!J23+'17'!J23+'18'!J23+'19'!J23+'20'!J23+'21'!J23+'22'!J23+'23'!J23+'24'!J23+'25'!J23+'26'!J23+'27'!J23+'28'!J23+'29'!J23+'30'!J23 -> 0 | K14: =+'1'!K23+'2'!K23+'3'!K23+'4'!K23+'5'!K23+'6'!K23+'7'!K23+'8'!K23+'9'!K23+'10'!K23+'11'!K23+'12'!K23+'13'!K23+'14'!K23+'15'!K23+'16'!K23+'17'!K23+'18'!K23+'19'!K23+'20'!K23+'21'!K23+'22'!K23+'23'!K23+'24'!K23+'25'!K23+'26'!K23+'27'!K23+'28'!K23+'29'!K23+'30'!K23 -> 0 | L14: =+'1'!L23+'2'!L23+'3'!L23+'4'!L23+'5'!L23+'6'!L23+'7'!L23+'8'!L23+'9'!L23+'10'!L23+'11'!L23+'12'!L23+'13'!L23+'14'!L23+'15'!L23+'16'!L23+'17'!L23+'18'!L23+'19'!L23+'20'!L23+'21'!L23+'22'!L23+'23'!L23+'24'!L23+'25'!L23+'26'!L23+'27'!L23+'28'!L23+'29'!L23+'30'!L23 -> 0 | M14: =I14-SUM(J14:L14) -> 0 | N14: =+'1'!N23+'2'!N23+'3'!N23+'4'!N23+'5'!N23+'6'!N23+'7'!N23+'8'!N23+'9'!N23+'10'!N23+'11'!N23+'12'!N23+'13'!N23+'14'!N23+'15'!N23+'16'!N23+'17'!N23+'18'!N23+'19'!N23+'20'!N23+'21'!N23+'22'!N23+'23'!N23+'24'!N23+'25'!N23+'26'!N23+'27'!N23+'28'!N23+'29'!N23+'30'!N23 -> 0 | O14: =+'1'!O23+'2'!O23+'3'!O23+'4'!O23+'5'!O23+'6'!O23+'7'!O23+'8'!O23+'9'!O23+'10'!O23+'11'!O23+'12'!O23+'13'!O23+'14'!O23+'15'!O23+'16'!O23+'17'!O23+'18'!O23+'19'!O23+'20'!O23+'21'!O23+'22'!O23+'23'!O23+'24'!O23+'25'!O23+'26'!O23+'27'!O23+'28'!O23+'29'!O23+'30'!O23 -> 0 | P14: =M14+N14+O14 -> 0 | Q14: =+'1'!Q23+'2'!Q23+'3'!Q23+'4'!Q23+'5'!Q23+'6'!Q23+'7'!Q23+'8'!Q23+'9'!Q23+'10'!Q23+'11'!Q23+'12'!Q23+'13'!Q23+'14'!Q23+'15'!Q23+'16'!Q23+'17'!Q23+'18'!Q23+'19'!Q23+'20'!Q23+'21'!Q23+'22'!Q23+'23'!Q23+'24'!Q23+'25'!Q23+'26'!Q23+'27'!Q23+'28'!Q23+'29'!Q23+'30'!Q23 -> 0 | R14: 12 | S14: =+'12'!A6:A6 -> Sana Cash & Carrry | T14: =+'12'!P35 -> 0
A15: BCE | B15: =VLOOKUP($A15,'Cust. Price List'!$D$6:$O$14,2,0) -> Meat Masala (ECO) | C15: =VLOOKUP(B15,'Cust. Price List'!E14:P22,2,0) -> 60 | D15: =VLOOKUP(A15,'Cust. Price List'!D14:M22,4,0) -> 40 | E15: =VLOOKUP(A15,'Cust. Price List'!D14:M22,6,0) -> 50 | F15: =VLOOKUP(A15,'Cust. Price List'!D14:M22,10,0) -> 39.23 | G15: =+'1'!G24+'2'!G24+'3'!G24+'4'!G24+'5'!G24+'6'!G24+'7'!G24+'8'!G24+'9'!G24+'10'!G24+'11'!G24+'12'!G24+'13'!G24+'14'!G24+'15'!G24+'16'!G24+'17'!G24+'18'!G24+'19'!G24+'20'!G24+'21'!G24+'22'!G24+'23'!G24+'24'!G24+'25'!G24+'26'!G24+'27'!G24+'28'!G24+'29'!G24+'30'!G24 -> 0 | H15: =+'1'!H24+'2'!H24+'3'!H24+'4'!H24+'5'!H24+'6'!H24+'7'!H24+'8'!H24+'9'!H24+'10'!H24+'11'!H24+'12'!H24+'13'!H24+'14'!H24+'15'!H24+'16'!H24+'17'!H24+'18'!H24+'19'!H24+'20'!H24+'21'!H24+'22'!H24+'23'!H24+'24'!H24+'25'!H24+'26'!H24+'27'!H24+'28'!H24+'29'!H24+'30'!H24 -> 0 | I15: =(G15*D15)*F15+H15*F15 -> 0 | J15: =+'1'!J24+'2'!J24+'3'!J24+'4'!J24+'5'!J24+'6'!J24+'7'!J24+'8'!J24+'9'!J24+'10'!J24+'11'!J24+'12'!J24+'13'!J24+'14'!J24+'15'!J24+'16'!J24+'17'!J24+'18'!J24+'19'!J24+'20'!J24+'21'!J24+'22'!J24+'23'!J24+'24'!J24+'25'!J24+'26'!J24+'27'!J24+'28'!J24+'29'!J24+'30'!J24 -> 0 | K15: =+'1'!K24+'2'!K24+'3'!K24+'4'!K24+'5'!K24+'6'!K24+'7'!K24+'8'!K24+'9'!K24+'10'!K24+'11'!K24+'12'!K24+'13'!K24+'14'!K24+'15'!K24+'16'!K24+'17'!K24+'18'!K24+'19'!K24+'20'!K24+'21'!K24+'22'!K24+'23'!K24+'24'!K24+'25'!K24+'26'!K24+'27'!K24+'28'!K24+'29'!K24+'30'!K24 -> 0 | L15: =+'1'!L24+'2'!L24+'3'!L24+'4'!L24+'5'!L24+'6'!L24+'7'!L24+'8'!L24+'9'!L24+'10'!L24+'11'!L24+'12'!L24+'13'!L24+'14'!L24+'15'!L24+'16'!L24+'17'!L24+'18'!L24+'19'!L24+'20'!L24+'21'!L24+'22'!L24+'23'!L24+'24'!L24+'25'!L24+'26'!L24+'27'!L24+'28'!L24+'29'!L24+'30'!L24 -> 0 | M15: =I15-SUM(J15:L15) -> 0 | N15: =+'1'!N24+'2'!N24+'3'!N24+'4'!N24+'5'!N24+'6'!N24+'7'!N24+'8'!N24+'9'!N24+'10'!N24+'11'!N24+'12'!N24+'13'!N24+'14'!N24+'15'!N24+'16'!N24+'17'!N24+'18'!N24+'19'!N24+'20'!N24+'21'!N24+'22'!N24+'23'!N24+'24'!N24+'25'!N24+'26'!N24+'27'!N24+'28'!N24+'29'!N24+'30'!N24 -> 0 | O15: =+'1'!O24+'2'!O24+'3'!O24+'4'!O24+'5'!O24+'6'!O24+'7'!O24+'8'!O24+'9'!O24+'10'!O24+'11'!O24+'12'!O24+'13'!O24+'14'!O24+'15'!O24+'16'!O24+'17'!O24+'18'!O24+'19'!O24+'20'!O24+'21'!O24+'22'!O24+'23'!O24+'24'!O24+'25'!O24+'26'!O24+'27'!O24+'28'!O24+'29'!O24+'30'!O24 -> 0 | P15: =M15+N15+O15 -> 0 | Q15: =+'1'!Q24+'2'!Q24+'3'!Q24+'4'!Q24+'5'!Q24+'6'!Q24+'7'!Q24+'8'!Q24+'9'!Q24+'10'!Q24+'11'!Q24+'12'!Q24+'13'!Q24+'14'!Q24+'15'!Q24+'16'!Q24+'17'!Q24+'18'!Q24+'19'!Q24+'20'!Q24+'21'!Q24+'22'!Q24+'23'!Q24+'24'!Q24+'25'!Q24+'26'!Q24+'27'!Q24+'28'!Q24+'29'!Q24+'30'!Q24 -> 0 | R15: 13 | S15: =+'13'!A6:A6 -> Sana Cash & Carrry | T15: =+'13'!P35 -> 0
A16: =COUNT(A7:A15) -> 0 | C16: Total | G16: =H16/40 -> 5 | H16: =SUM(H7:H15) -> 200 | I16: =SUM(I7:I15) -> 12106.7 | J16: =SUM(J7:J15) -> 1210.67 | K16: =SUM(K7:K15) -> 423.7345 | L16: =SUM(L7:L15) -> 0 | M16: =SUM(M7:M15) -> 10472.296 | N16: =SUM(N7:N15) -> 2288.1356 | O16: =SUM(O7:O15) -> 63.802155 | ... Q16: =SUM(Q7:Q15) -> #REF! | R16: 14 | S16: =+'14'!A6:A6 -> Sana Cash & Carrry | T16: =+'14'!P35 -> 0
R17: 15 | S17: =+'15'!A6:A6 -> Sana Cash & Carrry | T17: =+'15'!P35 -> 0
R18: 16 | S18: =+'16'!A6:A6 -> Sana Cash & Carrry | T18: =+'16'!P35 -> 0
B19: یکم جولائی 2024سے نئی ٹیکس ترمیم کے مطابق، ایف بی آر سیکشن 236 ایچ کے مطابق، فائلرز کے لیے ہر سیل انوائس پر 0.5% اور نان فائلرز کے لیے 2.5% ایڈوانس ود ہولڈنگ ٹیکس وصول کیا جائے گا۔ | N19: Gross Amount: | P19: =I16 -> 12106.7 | R19: 17 | S19: =+'17'!A6:A6 -> Sana Cash & Carrry | T19: =+'17'!P35 -> 0
N20: Regular Discount | P20: =+J16 -> 1210.67 | R20: 18 | S20: =+'18'!A6:A6 -> Sana Cash & Carrry | T20: =+'18'!P35 -> 0
N21: Trade Offre | P21: =+K16+L16 -> 423.7345 | R21: 19 | S21: =+'19'!A6:A6 -> Sana Cash & Carrry | T21: =+'19'!P35 -> 0
N22: After Dis. Amount | P22: =P19-P20-P21 -> 10472.296 | R22: 20 | S22: =+'20'!A6:A6 -> Sana Cash & Carrry | T22: =+'20'!P35 -> 0
N23: Total GST: | O23: 0.18 | P23: =+N16 -> 2288.1356 | R23: 21 | S23: =+'21'!A6:A6 -> Sana Cash & Carrry | T23: =+'21'!P35 -> 0
N24: Net Amount: | P24: =P22+P23 -> 12760.431 | R24: 22 | S24: =+'22'!A6:A6 -> Sana Cash & Carrry | T24: =+'22'!P35 -> 0
N25: Ad.Tax | O25: =IF(#REF!="Filer",0.5%,2.5%) -> #REF! | P25: =+O16 -> 63.802155 | R25: 23 | S25: =+'23'!A6:A6 -> Sana Cash & Carrry | T25: =+'23'!P35 -> 0
N26: Net Amount with Ad.Tax | P26: =+P24+P25 -> 12824.233 | R26: 24 | S26: =+'24'!A6:A6 -> Sana Cash & Carrry | T26: =+'24'!P35 -> 0
B27: Delivered By | R27: 25 | S27: =+'25'!A6:A6 -> Sana Cash & Carrry | T27: =+'25'!P35 -> 0
R28: 26 | S28: =+'26'!A6:A6 -> Sana Cash & Carrry | T28: =+'26'!P35 -> 0
L29: 0 | R29: 27 | S29: =+'27'!A6:A6 -> Sana Cash & Carrry | T29: =+'27'!P35 -> 0
R30: 28 | S30: =+'28'!A6:A6 -> Sana Cash & Carrry | T30: =+'28'!P35 -> 0
R31: 29 | S31: =+'29'!A6:A6 -> Sana Cash & Carrry | T31: =+'29'!P35 -> 0
R32: 30 | S32: =+'30'!A6:A6 -> Sana Cash & Carrry | T32: =+'30'!P35 -> 0
S33: Total Amount | T33: =SUM(T3:T32) -> 12824.233
B44: Shakoor Hussain
B45: Zeshan Meharban
B46: Umair Rehman
B47: Salman Butt
B48: Bilal
B49: Jabbar Akhtar
B50: Jibran Iqbal
B51: Maher Waqar

Sheet 1
A2: Elite MARKETING
A3: 44A- Gulberg Lahore | K3: Invoice No # : 15613 | XFC3: Filer | XFD3: 0.005
A4: STRN / NTN : 3808207-1 | K4: Date/Day : | N4: =Summary!H3 -> 46268 | XFC4: Non-filer | XFD4: 0.025
A5: Customer Code : | K5: Order Date : | N5: =N4-1 -> 46267
A6: Sana Cash & Carrry | K6: Order Name : | N6: =Summary!H2 -> Shakoor | XFC6: Registered | XFD6: 0.18
A7: NTN #: 040250-2 | K7: Route Name : | N7: #### | XFC7: Un-registered | XFD7: 0.22
A8: Address: IQBAL AVENUE CANAL ROAD | K8: Section Name: | N8: ####
A9: Channel Type:Retail/LMT | K9: Visit & Delivery Day | N9: Monday/Tuesday | XFD9: Yes
A10: Sub-Channel:General/medical/LMT Store / | K10: Invoice Status : | N10: Serviced | XFD10: No
A11: NTN Status: | B11: Filer | C11: =IF($O34>2.49%,"No","Yes") -> Yes | K11: Order at Original Location : | N11: Yes
A12: STRN Status: | B12: Registered | C12: =IF($O32>21.99%,"No","Yes") -> Yes | K12: Reference Invoice : | XFD12: Monday/Tuesday
XFD13: Tuesday / Wednesday
A14: Product Code/Description | C14: GM/ Pack | D14: CTN | E14: Unit | G14: Sale QTY | I14: Gross Amount Excl. Taxes | J14: Trade Offer & Discount | M14: After Discount Amount | N14: GST 18% | O14: Adv. Tax 236H | P14: Invoice | Q14: QTY | XFD14: Wednesday/Thursday
D15: SIZE | E15: MRP | F15: T.P Per | G15: CTN | H15: Pack | J15: 0.1 | K15: Trade Offer | L15: additional | O15: =IF(B11="Filer",0.5%,2.5%) -> 0.005 | P15: Amount | Q15: Return | S15: Pass On | T15: Trade Offer | U15: additional | V15: GST | XFD15: Thursday /Friday
A16: CCN | B16: =VLOOKUP($A16,'Cust. Price List'!$D$6:$O$14,2,0) -> Meat Masala | C16: =VLOOKUP(A16,'Cust. Price List'!D6:M14,3,0) -> 70 | D16: =VLOOKUP(A16,'Cust. Price List'!D6:M14,4,0) -> 40 | E16: =VLOOKUP(A16,'Cust. Price List'!D6:M14,6,0) -> 65 | F16: =VLOOKUP(A16,'Cust. Price List'!D6:M14,10,0) -> 52.4625 | I16: =(G16*D16)*F16+Q16*F16 -> 2098.5 | J16: =$I16*S16 -> 209.85 | K16: =$I16*T16 -> 73.4475 | L16: =$I16*U16 -> 0 | M16: =I16-SUM(J16:L16) -> 1815.2025 | N16: =+(G16*D16+Q16)*V16 -> 396.61017 | O16: =(N16+M16)*$O$15 -> 11.059063 | P16: =M16+N16+O16 -> 2222.8717 | Q16: 40 | S16: 0.1 | T16: 0.035 | V16: =+E16-E16/1.18 -> 9.9152542 | XFD16: Friday / Saturday
A17: VTN | B17: =VLOOKUP($A17,'Cust. Price List'!$D$6:$O$14,2,0) -> Lemon Tarka | C17: =VLOOKUP(B17,'Cust. Price List'!E7:P15,2,0) -> 70 | D17: =VLOOKUP(A17,'Cust. Price List'!D7:M15,4,0) -> 40 | E17: =VLOOKUP(A17,'Cust. Price List'!D7:M15,6,0) -> 65 | F17: =VLOOKUP(A17,'Cust. Price List'!D7:M15,10,0) -> 52.4625 | I17: =(G17*D17)*F17+Q17*F17 -> 2098.5 | J17: =$I17*S17 -> 209.85 | K17: =$I17*T17 -> 73.4475 | L17: =$I17*U17 -> 0 | M17: =I17-SUM(J17:L17) -> 1815.2025 | N17: =+(G17*D17+Q17)*V17 -> 396.61017 | O17: =(N17+M17)*$O$15 -> 11.059063 | P17: =M17+N17+O17 -> 2222.8717 | Q17: 40 | S17: =+S16 -> 0.1 | T17: =+T16 -> 0.035 | V17: =+E17-E17/1.18 -> 9.9152542 | XFD17: Saturday /Monday
A18: BCN | B18: =VLOOKUP($A18,'Cust. Price List'!$D$6:$O$14,2,0) -> Chicken Chatkhara | C18: =VLOOKUP(B18,'Cust. Price List'!E8:P16,2,0) -> 70 | D18: =VLOOKUP(A18,'Cust. Price List'!D8:M16,4,0) -> 40 | E18: =VLOOKUP(A18,'Cust. Price List'!D8:M16,6,0) -> 65 | F18: =VLOOKUP(A18,'Cust. Price List'!D8:M16,10,0) -> 52.4625 | I18: =(G18*D18)*F18+Q18*F18 -> 2098.5 | J18: =$I18*S18 -> 209.85 | K18: =$I18*T18 -> 73.4475 | L18: =$I18*U18 -> 0 | M18: =I18-SUM(J18:L18) -> 1815.2025 | N18: =+(G18*D18+Q18)*V18 -> 396.61017 | O18: =(N18+M18)*$O$15 -> 11.059063 | P18: =M18+N18+O18 -> 2222.8717 | Q18: 40 | S18: =+S17 -> 0.1 | T18: =+T17 -> 0.035 | V18: =+E18-E18/1.18 -> 9.9152542
