Workbook

Sheet Dist Price List (2)
A2: DEMAND FOR SAMPLES
A3: SNACK FOOD SKU UPDATED LIST | J3: 1.1 | K3: 0.18 | L3: 1.18 | M3: 0.045 | N3: 0.12 | O3: Ex. Price | S3: 0.06 | U3: =K3 -> 0.18
A4: Sr.No | B4: SKUs | C4: Weight gms | E4: Price PKR | F4: Packets / Cartons | G4: Packets | H4: Cartons | J4: Trade Price | K4: GST | L4: Exclusive GST | M4: Adv. TO / Pack | N4: Dis. Margin | O4: Pack | P4: CTN
A5: 1 | B5: DAAL SEV | C5: 16 | D5: gm | E5: 20 | F5: 72 | G5: 100 | J5: =E5/$J$3 -> 18.181818 | K5: =L5*18% -> 2.7734977 | L5: =J5/$L$3 -> 15.40832 | M5: =L5-L5/1.045 -> 0.66351619 | N5: =L5-L5/1.12 -> 1.6508915 | O5: =J5-M5-N5 -> 15.867411 | P5: =O5*F5 -> 1142.4536 | Q5: =L5-M5-N5 -> 13.093913 | S5: =L5*S3 -> 0.92449923 | T5: =L5-S5 -> 14.483821 | U5: =T5+T5*U3 -> 17.090909
A6: 2 | B6: POTATO STICK (CHATPATA) | C6: 16 | D6: gm | E6: 20 | F6: 72 | G6: 100 | J6: =E6/$J$3 -> 18.181818 | K6: =L6*18% -> 2.7734977 | L6: =J6/$L$3 -> 15.40832 | M6: =L6-L6/1.06 -> 0.87216908 | N6: =J6*$N$3 -> 2.1818182 | O6: =J6-M6-N6 -> 15.127831 | P6: =O6*F6 -> 1089.2038 | U6: =U5*12 -> 205.09091
A7: 3 | B7: SPICY MIX NIMKO | C7: 16 | D7: gm | E7: 20 | F7: 72 | G7: 100 | J7: =E7/$J$3 -> 18.181818 | K7: =L7*18% -> 2.7734977 | L7: =J7/$L$3 -> 15.40832 | M7: =L7-L7/1.06 -> 0.87216908 | N7: =J7*$N$3 -> 2.1818182 | O7: =J7-M7-N7 -> 15.127831 | P7: =O7*F7 -> 1089.2038
A8: 4 | B8: NIMBOO DAAL | C8: 16 | D8: gm | E8: 20 | F8: 72 | G8: 100 | J8: =E8/$J$3 -> 18.181818 | K8: =L8*18% -> 2.7734977 | L8: =J8/$L$3 -> 15.40832 | M8: =L8-L8/1.06 -> 0.87216908 | N8: =J8*$N$3 -> 2.1818182 | O8: =J8-M8-N8 -> 15.127831 | P8: =O8*F8 -> 1089.2038
A9: 5 | B9: NIMKO MIX HOT & SPICY | C9: 16 | D9: gm | E9: 20 | F9: 72 | G9: 0 | J9: =E9/$J$3 -> 18.181818 | K9: =L9*18% -> 2.7734977 | L9: =J9/$L$3 -> 15.40832 | M9: =L9-L9/1.06 -> 0.87216908 | N9: =J9*$N$3 -> 2.1818182 | O9: =J9-M9-N9 -> 15.127831 | P9: =O9*F9 -> 1089.2038
A10: 6 | B10: NIMKO MIX LEMON & CHILLI | C10: 16 | D10: gm | E10: 20 | F10: 72 | G10: 0 | J10: =E10/$J$3 -> 18.181818 | K10: =L10*18% -> 2.7734977 | L10: =J10/$L$3 -> 15.40832 | M10: =L10-L10/1.06 -> 0.87216908 | N10: =J10*$N$3 -> 2.1818182 | O10: =J10-M10-N10 -> 15.127831 | P10: =O10*F10 -> 1089.2038
A11: 7 | B11: SLANTY (SALTED) | C11: 10 | D11: gm | E11: 20 | F11: 45 | G11: 0 | J11: =E11/$J$3 -> 18.181818 | K11: =L11*18% -> 2.7734977 | L11: =J11/$L$3 -> 15.40832 | M11: =L11-L11/1.06 -> 0.87216908 | N11: =J11*$N$3 -> 2.1818182 | O11: =J11-M11-N11 -> 15.127831 | P11: =O11*F11 -> 680.75239
A12: 8 | B12: SLANTY (VEGETABLE EU) | C12: 10 | D12: gm | E12: 20 | F12: 45 | G12: 0 | J12: =E12/$J$3 -> 18.181818 | K12: =L12*18% -> 2.7734977 | L12: =J12/$L$3 -> 15.40832 | M12: =L12-L12/1.06 -> 0.87216908 | N12: =J12*$N$3 -> 2.1818182 | O12: =J12-M12-N12 -> 15.127831 | P12: =O12*F12 -> 680.75239
A13: 9 | B13: SLANTY (KETCHUP) | C13: 10 | D13: gm | E13: 20 | F13: 45 | G13: Hold For Printing | J13: =E13/$J$3 -> 18.181818 | K13: =L13*18% -> 2.7734977 | L13: =J13/$L$3 -> 15.40832 | M13: =L13-L13/1.06 -> 0.87216908 | N13: =J13*$N$3 -> 2.1818182 | O13: =J13-M13-N13 -> 15.127831 | P13: =O13*F13 -> 680.75239
A15: 10 | B15: NIMBOO DAAL | C15: 24 | D15: gm | E15: 30 | F15: 45 | G15: 0 | J15: =E15/$J$3 -> 27.272727 | K15: =L15*18% -> 4.1602465 | L15: =J15/$L$3 -> 23.112481 | M15: =L15-L15/1.06 -> 1.3082536 | N15: =J15*$N$3 -> 3.2727273 | O15: =J15-M15-N15 -> 22.691746 | P15: =O15*F15 -> 1021.1286
A16: 11 | B16: DAAL MOUNG | C16: 18 | D16: gm | E16: 30 | F16: 72 | G16: 100 | J16: =E16/$J$3 -> 27.272727 | K16: =L16*18% -> 4.1602465 | L16: =J16/$L$3 -> 23.112481 | M16: =L16-L16/1.06 -> 1.3082536 | N16: =J16*$N$3 -> 3.2727273 | O16: =J16-M16-N16 -> 22.691746 | P16: =O16*F16 -> 1633.8057
A17: 12 | B17: NIMKO MIX HOT & SPICY | C17: 24 | D17: gm | E17: 30 | F17: 45 | G17: 100 | J17: =E17/$J$3 -> 27.272727 | K17: =L17*18% -> 4.1602465 | L17: =J17/$L$3 -> 23.112481 | M17: =L17-L17/1.06 -> 1.3082536 | N17: =J17*$N$3 -> 3.2727273 | O17: =J17-M17-N17 -> 22.691746 | P17: =O17*F17 -> 1021.1286
A18: 13 | B18: POTATO STICK (SALT & PEPPER) | C18: 24 | D18: gm | E18: 30 | F18: 45 | G18: 100 | J18: =E18/$J$3 -> 27.272727 | K18: =L18*18% -> 4.1602465 | L18: =J18/$L$3 -> 23.112481 | M18: =L18-L18/1.06 -> 1.3082536 | N18: =J18*$N$3 -> 3.2727273 | O18: =J18-M18-N18 -> 22.691746 | P18: =O18*F18 -> 1021.1286
A19: 14 | B19: SALTED PEANUT | C19: 16 | D19: gm | E19: 30 | F19: 85 | G19: 100 | J19: =E19/$J$3 -> 27.272727 | K19: =L19*18% -> 4.1602465 | L19: =J19/$L$3 -> 23.112481 | M19: =L19-L19/1.06 -> 1.3082536 | N19: =J19*$N$3 -> 3.2727273 | O19: =J19-M19-N19 -> 22.691746 | P19: =O19*F19 -> 1928.7984
A20: 15 | B20: PEANUT UNSALTED | C20: 16 | D20: gm | E20: 30 | F20: 85 | G20: 100 | J20: =E20/$J$3 -> 27.272727 | K20: =L20*18% -> 4.1602465 | L20: =J20/$L$3 -> 23.112481 | M20: =L20-L20/1.06 -> 1.3082536 | N20: =J20*$N$3 -> 3.2727273 | O20: =J20-M20-N20 -> 22.691746 | P20: =O20*F20 -> 1928.7984
A21: 16 | B21: NIMKO MIX LEMON & CHILLI | C21: 24 | D21: gm | E21: 30 | F21: 45 | G21: 0 | J21: =E21/$J$3 -> 27.272727 | K21: =L21*18% -> 4.1602465 | L21: =J21/$L$3 -> 23.112481 | M21: =L21-L21/1.06 -> 1.3082536 | N21: =J21*$N$3 -> 3.2727273 | O21: =J21-M21-N21 -> 22.691746 | P21: =O21*F21 -> 1021.1286
A22: 17 | B22: SPICY MIX NIMKO | C22: 24 | D22: gm | E22: 30 | F22: 45 | G22: 0 | J22: =E22/$J$3 -> 27.272727 | K22: =L22*18% -> 4.1602465 | L22: =J22/$L$3 -> 23.112481 | M22: =L22-L22/1.06 -> 1.3082536 | N22: =J22*$N$3 -> 3.2727273 | O22: =J22-M22-N22 -> 22.691746 | P22: =O22*F22 -> 1021.1286
A23: 18 | B23: DAAL SEV | C23: 24 | D23: gm | E23: 30 | F23: 45 | G23: 0 | J23: =E23/$J$3 -> 27.272727 | K23: =L23*18% -> 4.1602465 | L23: =J23/$L$3 -> 23.112481 | M23: =L23-L23/1.06 -> 1.3082536 | N23: =J23*$N$3 -> 3.2727273 | O23: =J23-M23-N23 -> 22.691746 | P23: =O23*F23 -> 1021.1286
A24: 19 | B24: SLANTY (SALTED) | C24: 15 | D24: gm | E24: 30 | F24: 30 | G24: 0 | J24: =E24/$J$3 -> 27.272727 | K24: =L24*18% -> 4.1602465 | L24: =J24/$L$3 -> 23.112481 | M24: =L24-L24/1.06 -> 1.3082536 | N24: =J24*$N$3 -> 3.2727273 | O24: =J24-M24-N24 -> 22.691746 | P24: =O24*F24 -> 680.75239
A25: 20 | B25: SLANTY (VEGETABLE EU) | C25: 15 | D25: gm | E25: 30 | F25: 30 | G25: 0 | J25: =E25/$J$3 -> 27.272727 | K25: =L25*18% -> 4.1602465 | L25: =J25/$L$3 -> 23.112481 | M25: =L25-L25/1.06 -> 1.3082536 | N25: =J25*$N$3 -> 3.2727273 | O25: =J25-M25-N25 -> 22.691746 | P25: =O25*F25 -> 680.75239
A26: 21 | B26: SLANTY (KETCHUP) | C26: 15 | D26: gm | E26: 30 | F26: 30 | G26: Hold For Printing | J26: =E26/$J$3 -> 27.272727 | K26: =L26*18% -> 4.1602465 | L26: =J26/$L$3 -> 23.112481 | M26: =L26-L26/1.06 -> 1.3082536 | N26: =J26*$N$3 -> 3.2727273 | O26: =J26-M26-N26 -> 22.691746 | P26: =O26*F26 -> 680.75239
A28: 22 | B28: NIMKO SALT & PEPPER | C28: 40 | D28: gm | E28: 50 | F28: 30 | G28: 100 | J28: =E28/$J$3 -> 45.454545 | K28: =L28*18% -> 6.9337442 | L28: =J28/$L$3 -> 38.520801 | M28: =L28-L28/1.06 -> 2.1804227 | N28: =J28*$N$3 -> 5.4545455 | O28: =J28-M28-N28 -> 37.819577 | P28: =O28*F28 -> 1134.5873
A29: 23 | B29: CHEWRA NIMKO | C29: 30 | D29: gm | E29: 50 | F29: 30 | G29: 100 | J29: =E29/$J$3 -> 45.454545 | K29: =L29*18% -> 6.9337442 | L29: =J29/$L$3 -> 38.520801 | M29: =L29-L29/1.06 -> 2.1804227 | N29: =J29*$N$3 -> 5.4545455 | O29: =J29-M29-N29 -> 37.819577 | P29: =O29*F29 -> 1134.5873
A30: 24 | B30: DAAL MOUNG | C30: 30 | D30: gm | E30: 50 | F30: 45 | G30: 0 | J30: =E30/$J$3 -> 45.454545 | K30: =L30*18% -> 6.9337442 | L30: =J30/$L$3 -> 38.520801 | M30: =L30-L30/1.06 -> 2.1804227 | N30: =J30*$N$3 -> 5.4545455 | O30: =J30-M30-N30 -> 37.819577 | P30: =O30*F30 -> 1701.881
A31: 25 | B31: SALTED PEANUT | C31: 25 | D31: gm | E31: 50 | F31: 45 | G31: 50 | J31: =E31/$J$3 -> 45.454545 | K31: =L31*18% -> 6.9337442 | L31: =J31/$L$3 -> 38.520801 | M31: =L31-L31/1.06 -> 2.1804227 | N31: =J31*$N$3 -> 5.4545455 | O31: =J31-M31-N31 -> 37.819577 | P31: =O31*F31 -> 1701.881
A32: 26 | B32: PEANUT UNSALTED | C32: 25 | D32: gm | E32: 50 | F32: 45 | G32: 50 | J32: =E32/$J$3 -> 45.454545 | K32: =L32*18% -> 6.9337442 | L32: =J32/$L$3 -> 38.520801 | M32: =L32-L32/1.06 -> 2.1804227 | N32: =J32*$N$3 -> 5.4545455 | O32: =J32-M32-N32 -> 37.819577 | P32: =O32*F32 -> 1701.881
A33: 27 | B33: KHAT MITHA | C33: 30 | D33: gm | E33: 50 | F33: 30 | G33: 100 | J33: =E33/$J$3 -> 45.454545 | K33: =L33*18% -> 6.9337442 | L33: =J33/$L$3 -> 38.520801 | M33: =L33-L33/1.06 -> 2.1804227 | N33: =J33*$N$3 -> 5.4545455 | O33: =J33-M33-N33 -> 37.819577 | P33: =O33*F33 -> 1134.5873
A34: 28 | B34: KARACHI NIMCO MIX | C34: 40 | D34: gm | E34: 50 | F34: 30 | G34: 0 | J34: =E34/$J$3 -> 45.454545 | K34: =L34*18% -> 6.9337442 | L34: =J34/$L$3 -> 38.520801 | M34: =L34-L34/1.06 -> 2.1804227 | N34: =J34*$N$3 -> 5.4545455 | O34: =J34-M34-N34 -> 37.819577 | P34: =O34*F34 -> 1134.5873
A35: 29 | B35: SLANTY (SALTED) | C35: 28 | D35: gm | E35: 50 | F35: 24 | G35: 0 | J35: =E35/$J$3 -> 45.454545 | K35: =L35*18% -> 6.9337442 | L35: =J35/$L$3 -> 38.520801 | M35: =L35-L35/1.06 -> 2.1804227 | N35: =J35*$N$3 -> 5.4545455 | O35: =J35-M35-N35 -> 37.819577 | P35: =O35*F35 -> 907.66985
A36: 30 | B36: SLANTY (VEGETABLE EU) | C36: 28 | D36: gm | E36: 50 | F36: 24 | G36: 0 | J36: =E36/$J$3 -> 45.454545 | K36: =L36*18% -> 6.9337442 | L36: =J36/$L$3 -> 38.520801 | M36: =L36-L36/1.06 -> 2.1804227 | N36: =J36*$N$3 -> 5.4545455 | O36: =J36-M36-N36 -> 37.819577 | P36: =O36*F36 -> 907.66985
A37: 31 | B37: SLANTY (KETCHUP) | C37: 28 | D37: gm | E37: 50 | G37: Hold For Printing | J37: =E37/$J$3 -> 45.454545 | K37: =L37*18% -> 6.9337442 | L37: =J37/$L$3 -> 38.520801 | M37: =L37-L37/1.06 -> 2.1804227 | N37: =J37*$N$3 -> 5.4545455 | O37: =J37-M37-N37 -> 37.819577 | P37: =O37*F37 -> 0
A39: 32 | B39: SALTED PEANUT | C39: 40 | D39: gm | E39: 80 | F39: 30 | G39: 50 | J39: =E39/$J$3 -> 72.727273 | K39: =L39*18% -> 11.093991 | L39: =J39/$L$3 -> 61.633282 | M39: =L39-L39/1.06 -> 3.4886763 | N39: =J39*$N$3 -> 8.7272727 | O39: =J39-M39-N39 -> 60.511324 | P39: =O39*F39 -> 1815.3397
A40: 33 | B40: PEANUT UNSALTED | C40: 40 | D40: gm | E40: 80 | F40: 30 | G40: 50 | J40: =E40/$J$3 -> 72.727273 | K40: =L40*18% -> 11.093991 | L40: =J40/$L$3 -> 61.633282 | M40: =L40-L40/1.06 -> 3.4886763 | N40: =J40*$N$3 -> 8.7272727 | O40: =J40-M40-N40 -> 60.511324 | P40: =O40*F40 -> 1815.3397
A42: 34 | B42: SHAHI MIX | C42: 80 | D42: gm | E42: 250 | F42: 40 | G42: 100 | J42: =E42/$J$3 -> 227.27273 | K42: =L42*18% -> 34.668721 | L42: =J42/$L$3 -> 192.60401 | M42: =L42-L42/1.06 -> 10.902114 | N42: =J42*$N$3 -> 27.272727 | O42: =J42-M42-N42 -> 189.09789 | P42: =O42*F42 -> 7563.9155
A43: 35 | B43: LAHORI MIX | C43: 80 | D43: gm | E43: 180 | F43: 40 | G43: 100 | J43: =E43/$J$3 -> 163.63636 | K43: =L43*18% -> 24.961479 | L43: =J43/$L$3 -> 138.67488 | M43: =L43-L43/1.06 -> 7.8495218 | N43: =J43*$N$3 -> 19.636364 | O43: =J43-M43-N43 -> 136.15048 | P43: =O43*F43 -> 5446.0191
A44: 36 | B44: NIMKO SALT & PEPPER | C44: 80 | D44: gm | E44: 120 | F44: 40 | G44: 50 | J44: =E44/$J$3 -> 109.09091 | K44: =L44*18% -> 16.640986 | L44: =J44/$L$3 -> 92.449923 | M44: =L44-L44/1.06 -> 5.2330145 | N44: =J44*$N$3 -> 13.090909 | O44: =J44-M44-N44 -> 90.766985 | P44: =O44*F44 -> 3630.6794
A46: 37 | B46: SHAHI MIX | C46: 180 | D46: gm | E46: 500 | F46: 27 | G46: 0 | J46: =E46/$J$3 -> 454.54545 | K46: =L46*18% -> 69.337442 | L46: =J46/$L$3 -> 385.20801 | M46: =L46-L46/1.06 -> 21.804227 | N46: =J46*$N$3 -> 54.545455 | O46: =J46-M46-N46 -> 378.19577 | P46: =O46*F46 -> 10211.286
...

Sheet Dist Price List
A2: DEMAND FOR SAMPLES
A3: SNACK FOOD SKU UPDATED LIST | J3: 1.1 | K3: 0.18 | L3: 1.18 | M3: 0.045 | N3: 0.12 | O3: Ex. Price | S3: 0.06 | U3: =K3 -> 0.18
A4: Sr.No | B4: SKUs | C4: Weight gms | E4: Price PKR | F4: Packets / Cartons | G4: Packets | H4: Cartons | J4: Trade Price | K4: GST | L4: Exclusive GST | M4: Adv. TO / Pack | N4: Dis. Margin | O4: Pack | P4: CTN
A5: 1 | B5: DAAL SEV | C5: 16 | D5: gm | E5: 20 | F5: 72 | G5: 100 | J5: =E5/$J$3 -> 18.181818 | K5: =L5*18% -> 2.7734977 | L5: =J5/$L$3 -> 15.40832 | M5: =L5-L5/1.045 -> 0.66351619 | N5: =L5-L5/1.12 -> 1.6508915 | O5: =J5-M5-N5 -> 15.867411 | P5: =O5*F5 -> 1142.4536 | Q5: =L5-M5-N5 -> 13.093913 | S5: =L5*S3 -> 0.92449923 | T5: =L5-S5 -> 14.483821 | U5: =T5+T5*U3 -> 17.090909
A6: 2 | B6: POTATO STICK (CHATPATA) | C6: 16 | D6: gm | E6: 20 | F6: 72 | G6: 100 | J6: =E6/$J$3 -> 18.181818 | K6: =L6*18% -> 2.7734977 | L6: =J6/$L$3 -> 15.40832 | M6: =L6-L6/1.06 -> 0.87216908 | N6: =J6*$N$3 -> 2.1818182 | O6: =J6-M6-N6 -> 15.127831 | P6: =O6*F6 -> 1089.2038 | U6: =U5*12 -> 205.09091
A7: 3 | B7: SPICY MIX NIMKO | C7: 16 | D7: gm | E7: 20 | F7: 72 | G7: 100 | J7: =E7/$J$3 -> 18.181818 | K7: =L7*18% -> 2.7734977 | L7: =J7/$L$3 -> 15.40832 | M7: =L7-L7/1.06 -> 0.87216908 | N7: =J7*$N$3 -> 2.1818182 | O7: =J7-M7-N7 -> 15.127831 | P7: =O7*F7 -> 1089.2038
A8: 4 | B8: NIMBOO DAAL | C8: 16 | D8: gm | E8: 20 | F8: 72 | G8: 100 | J8: =E8/$J$3 -> 18.181818 | K8: =L8*18% -> 2.7734977 | L8: =J8/$L$3 -> 15.40832 | M8: =L8-L8/1.06 -> 0.87216908 | N8: =J8*$N$3 -> 2.1818182 | O8: =J8-M8-N8 -> 15.127831 | P8: =O8*F8 -> 1089.2038
A9: 5 | B9: NIMKO MIX HOT & SPICY | C9: 16 | D9: gm | E9: 20 | F9: 72 | G9: 0 | J9: =E9/$J$3 -> 18.181818 | K9: =L9*18% -> 2.7734977 | L9: =J9/$L$3 -> 15.40832 | M9: =L9-L9/1.06 -> 0.87216908 | N9: =J9*$N$3 -> 2.1818182 | O9: =J9-M9-N9 -> 15.127831 | P9: =O9*F9 -> 1089.2038
A10: 6 | B10: NIMKO MIX LEMON & CHILLI | C10: 16 | D10: gm | E10: 20 | F10: 72 | G10: 0 | J10: =E10/$J$3 -> 18.181818 | K10: =L10*18% -> 2.7734977 | L10: =J10/$L$3 -> 15.40832 | M10: =L10-L10/1.06 -> 0.87216908 | N10: =J10*$N$3 -> 2.1818182 | O10: =J10-M10-N10 -> 15.127831 | P10: =O10*F10 -> 1089.2038
A11: 7 | B11: SLANTY (SALTED) | C11: 10 | D11: gm | E11: 20 | F11: 45 | G11: 0 | J11: =E11/$J$3 -> 18.181818 | K11: =L11*18% -> 2.7734977 | L11: =J11/$L$3 -> 15.40832 | M11: =L11-L11/1.06 -> 0.87216908 | N11: =J11*$N$3 -> 2.1818182 | O11: =J11-M11-N11 -> 15.127831 | P11: =O11*F11 -> 680.75239
A12: 8 | B12: SLANTY (VEGETABLE EU) | C12: 10 | D12: gm | E12: 20 | F12: 45 | G12: 0 | J12: =E12/$J$3 -> 18.181818 | K12: =L12*18% -> 2.7734977 | L12: =J12/$L$3 -> 15.40832 | M12: =L12-L12/1.06 -> 0.87216908 | N12: =J12*$N$3 -> 2.1818182 | O12: =J12-M12-N12 -> 15.127831 | P12: =O12*F12 -> 680.75239
A13: 9 | B13: SLANTY (KETCHUP) | C13: 10 | D13: gm | E13: 20 | F13: 45 | G13: Hold For Printing | J13: =E13/$J$3 -> 18.181818 | K13: =L13*18% -> 2.7734977 | L13: =J13/$L$3 -> 15.40832 | M13: =L13-L13/1.06 -> 0.87216908 | N13: =J13*$N$3 -> 2.1818182 | O13: =J13-M13-N13 -> 15.127831 | P13: =O13*F13 -> 680.75239
A15: 10 | B15: NIMBOO DAAL | C15: 24 | D15: gm | E15: 30 | F15: 45 | G15: 0 | J15: =E15/$J$3 -> 27.272727 | K15: =L15*18% -> 4.1602465 | L15: =J15/$L$3 -> 23.112481 | M15: =L15-L15/1.06 -> 1.3082536 | N15: =J15*$N$3 -> 3.2727273 | O15: =J15-M15-N15 -> 22.691746 | P15: =O15*F15 -> 1021.1286
A16: 11 | B16: DAAL MOUNG | C16: 18 | D16: gm | E16: 30 | F16: 72 | G16: 100 | J16: =E16/$J$3 -> 27.272727 | K16: =L16*18% -> 4.1602465 | L16: =J16/$L$3 -> 23.112481 | M16: =L16-L16/1.06 -> 1.3082536 | N16: =J16*$N$3 -> 3.2727273 | O16: =J16-M16-N16 -> 22.691746 | P16: =O16*F16 -> 1633.8057
A17: 12 | B17: NIMKO MIX HOT & SPICY | C17: 24 | D17: gm | E17: 30 | F17: 45 | G17: 100 | J17: =E17/$J$3 -> 27.272727 | K17: =L17*18% -> 4.1602465 | L17: =J17/$L$3 -> 23.112481 | M17: =L17-L17/1.06 -> 1.3082536 | N17: =J17*$N$3 -> 3.2727273 | O17: =J17-M17-N17 -> 22.691746 | P17: =O17*F17 -> 1021.1286
A18: 13 | B18: POTATO STICK (SALT & PEPPER) | C18: 24 | D18: gm | E18: 30 | F18: 45 | G18: 100 | J18: =E18/$J$3 -> 27.272727 | K18: =L18*18% -> 4.1602465 | L18: =J18/$L$3 -> 23.112481 | M18: =L18-L18/1.06 -> 1.3082536 | N18: =J18*$N$3 -> 3.2727273 | O18: =J18-M18-N18 -> 22.691746 | P18: =O18*F18 -> 1021.1286
A19: 14 | B19: SALTED PEANUT | C19: 16 | D19: gm | E19: 30 | F19: 85 | G19: 100 | J19: =E19/$J$3 -> 27.272727 | K19: =L19*18% -> 4.1602465 | L19: =J19/$L$3 -> 23.112481 | M19: =L19-L19/1.06 -> 1.3082536 | N19: =J19*$N$3 -> 3.2727273 | O19: =J19-M19-N19 -> 22.691746 | P19: =O19*F19 -> 1928.7984
A20: 15 | B20: PEANUT UNSALTED | C20: 16 | D20: gm | E20: 30 | F20: 85 | G20: 100 | J20: =E20/$J$3 -> 27.272727 | K20: =L20*18% -> 4.1602465 | L20: =J20/$L$3 -> 23.112481 | M20: =L20-L20/1.06 -> 1.3082536 | N20: =J20*$N$3 -> 3.2727273 | O20: =J20-M20-N20 -> 22.691746 | P20: =O20*F20 -> 1928.7984
A21: 16 | B21: NIMKO MIX LEMON & CHILLI | C21: 24 | D21: gm | E21: 30 | F21: 45 | G21: 0 | J21: =E21/$J$3 -> 27.272727 | K21: =L21*18% -> 4.1602465 | L21: =J21/$L$3 -> 23.112481 | M21: =L21-L21/1.06 -> 1.3082536 | N21: =J21*$N$3 -> 3.2727273 | O21: =J21-M21-N21 -> 22.691746 | P21: =O21*F21 -> 1021.1286
A22: 17 | B22: SPICY MIX NIMKO | C22: 24 | D22: gm | E22: 30 | F22: 45 | G22: 0 | J22: =E22/$J$3 -> 27.272727 | K22: =L22*18% -> 4.1602465 | L22: =J22/$L$3 -> 23.112481 | M22: =L22-L22/1.06 -> 1.3082536 | N22: =J22*$N$3 -> 3.2727273 | O22: =J22-M22-N22 -> 22.691746 | P22: =O22*F22 -> 1021.1286
A23: 18 | B23: DAAL SEV | C23: 24 | D23: gm | E23: 30 | F23: 45 | G23: 0 | J23: =E23/$J$3 -> 27.272727 | K23: =L23*18% -> 4.1602465 | L23: =J23/$L$3 -> 23.112481 | M23: =L23-L23/1.06 -> 1.3082536 | N23: =J23*$N$3 -> 3.2727273 | O23: =J23-M23-N23 -> 22.691746 | P23: =O23*F23 -> 1021.1286
A24: 19 | B24: SLANTY (SALTED) | C24: 15 | D24: gm | E24: 30 | F24: 30 | G24: 0 | J24: =E24/$J$3 -> 27.272727 | K24: =L24*18% -> 4.1602465 | L24: =J24/$L$3 -> 23.112481 | M24: =L24-L24/1.06 -> 1.3082536 | N24: =J24*$N$3 -> 3.2727273 | O24: =J24-M24-N24 -> 22.691746 | P24: =O24*F24 -> 680.75239
A25: 20 | B25: SLANTY (VEGETABLE EU) | C25: 15 | D25: gm | E25: 30 | F25: 30 | G25: 0 | J25: =E25/$J$3 -> 27.272727 | K25: =L25*18% -> 4.1602465 | L25: =J25/$L$3 -> 23.112481 | M25: =L25-L25/1.06 -> 1.3082536 | N25: =J25*$N$3 -> 3.2727273 | O25: =J25-M25-N25 -> 22.691746 | P25: =O25*F25 -> 680.75239
A26: 21 | B26: SLANTY (KETCHUP) | C26: 15 | D26: gm | E26: 30 | F26: 30 | G26: Hold For Printing | J26: =E26/$J$3 -> 27.272727 | K26: =L26*18% -> 4.1602465 | L26: =J26/$L$3 -> 23.112481 | M26: =L26-L26/1.06 -> 1.3082536 | N26: =J26*$N$3 -> 3.2727273 | O26: =J26-M26-N26 -> 22.691746 | P26: =O26*F26 -> 680.75239
A28: 22 | B28: NIMKO SALT & PEPPER | C28: 40 | D28: gm | E28: 50 | F28: 30 | G28: 100 | J28: =E28/$J$3 -> 45.454545 | K28: =L28*18% -> 6.9337442 | L28: =J28/$L$3 -> 38.520801 | M28: =L28-L28/1.06 -> 2.1804227 | N28: =J28*$N$3 -> 5.4545455 | O28: =J28-M28-N28 -> 37.819577 | P28: =O28*F28 -> 1134.5873
A29: 23 | B29: CHEWRA NIMKO | C29: 30 | D29: gm | E29: 50 | F29: 30 | G29: 100 | J29: =E29/$J$3 -> 45.454545 | K29: =L29*18% -> 6.9337442 | L29: =J29/$L$3 -> 38.520801 | M29: =L29-L29/1.06 -> 2.1804227 | N29: =J29*$N$3 -> 5.4545455 | O29: =J29-M29-N29 -> 37.819577 | P29: =O29*F29 -> 1134.5873
A30: 24 | B30: DAAL MOUNG | C30: 30 | D30: gm | E30: 50 | F30: 45 | G30: 0 | J30: =E30/$J$3 -> 45.454545 | K30: =L30*18% -> 6.9337442 | L30: =J30/$L$3 -> 38.520801 | M30: =L30-L30/1.06 -> 2.1804227 | N30: =J30*$N$3 -> 5.4545455 | O30: =J30-M30-N30 -> 37.819577 | P30: =O30*F30 -> 1701.881
A31: 25 | B31: SALTED PEANUT | C31: 25 | D31: gm | E31: 50 | F31: 45 | G31: 50 | J31: =E31/$J$3 -> 45.454545 | K31: =L31*18% -> 6.9337442 | L31: =J31/$L$3 -> 38.520801 | M31: =L31-L31/1.06 -> 2.1804227 | N31: =J31*$N$3 -> 5.4545455 | O31: =J31-M31-N31 -> 37.819577 | P31: =O31*F31 -> 1701.881
A32: 26 | B32: PEANUT UNSALTED | C32: 25 | D32: gm | E32: 50 | F32: 45 | G32: 50 | J32: =E32/$J$3 -> 45.454545 | K32: =L32*18% -> 6.9337442 | L32: =J32/$L$3 -> 38.520801 | M32: =L32-L32/1.06 -> 2.1804227 | N32: =J32*$N$3 -> 5.4545455 | O32: =J32-M32-N32 -> 37.819577 | P32: =O32*F32 -> 1701.881
A33: 27 | B33: KHAT MITHA | C33: 30 | D33: gm | E33: 50 | F33: 30 | G33: 100 | J33: =E33/$J$3 -> 45.454545 | K33: =L33*18% -> 6.9337442 | L33: =J33/$L$3 -> 38.520801 | M33: =L33-L33/1.06 -> 2.1804227 | N33: =J33*$N$3 -> 5.4545455 | O33: =J33-M33-N33 -> 37.819577 | P33: =O33*F33 -> 1134.5873
A34: 28 | B34: KARACHI NIMCO MIX | C34: 40 | D34: gm | E34: 50 | F34: 30 | G34: 0 | J34: =E34/$J$3 -> 45.454545 | K34: =L34*18% -> 6.9337442 | L34: =J34/$L$3 -> 38.520801 | M34: =L34-L34/1.06 -> 2.1804227 | N34: =J34*$N$3 -> 5.4545455 | O34: =J34-M34-N34 -> 37.819577 | P34: =O34*F34 -> 1134.5873
A35: 29 | B35: SLANTY (SALTED) | C35: 28 | D35: gm | E35: 50 | F35: 24 | G35: 0 | J35: =E35/$J$3 -> 45.454545 | K35: =L35*18% -> 6.9337442 | L35: =J35/$L$3 -> 38.520801 | M35: =L35-L35/1.06 -> 2.1804227 | N35: =J35*$N$3 -> 5.4545455 | O35: =J35-M35-N35 -> 37.819577 | P35: =O35*F35 -> 907.66985
A36: 30 | B36: SLANTY (VEGETABLE EU) | C36: 28 | D36: gm | E36: 50 | F36: 24 | G36: 0 | J36: =E36/$J$3 -> 45.454545 | K36: =L36*18% -> 6.9337442 | L36: =J36/$L$3 -> 38.520801 | M36: =L36-L36/1.06 -> 2.1804227 | N36: =J36*$N$3 -> 5.4545455 | O36: =J36-M36-N36 -> 37.819577 | P36: =O36*F36 -> 907.66985
A37: 31 | B37: SLANTY (KETCHUP) | C37: 28 | D37: gm | E37: 50 | G37: Hold For Printing | J37: =E37/$J$3 -> 45.454545 | K37: =L37*18% -> 6.9337442 | L37: =J37/$L$3 -> 38.520801 | M37: =L37-L37/1.06 -> 2.1804227 | N37: =J37*$N$3 -> 5.4545455 | O37: =J37-M37-N37 -> 37.819577 | P37: =O37*F37 -> 0
A39: 32 | B39: SALTED PEANUT | C39: 40 | D39: gm | E39: 80 | F39: 30 | G39: 50 | J39: =E39/$J$3 -> 72.727273 | K39: =L39*18% -> 11.093991 | L39: =J39/$L$3 -> 61.633282 | M39: =L39-L39/1.06 -> 3.4886763 | N39: =J39*$N$3 -> 8.7272727 | O39: =J39-M39-N39 -> 60.511324 | P39: =O39*F39 -> 1815.3397
A40: 33 | B40: PEANUT UNSALTED | C40: 40 | D40: gm | E40: 80 | F40: 30 | G40: 50 | J40: =E40/$J$3 -> 72.727273 | K40: =L40*18% -> 11.093991 | L40: =J40/$L$3 -> 61.633282 | M40: =L40-L40/1.06 -> 3.4886763 | N40: =J40*$N$3 -> 8.7272727 | O40: =J40-M40-N40 -> 60.511324 | P40: =O40*F40 -> 1815.3397
A42: 34 | B42: SHAHI MIX | C42: 80 | D42: gm | E42: 250 | F42: 40 | G42: 100 | J42: =E42/$J$3 -> 227.27273 | K42: =L42*18% -> 34.668721 | L42: =J42/$L$3 -> 192.60401 | M42: =L42-L42/1.06 -> 10.902114 | N42: =J42*$N$3 -> 27.272727 | O42: =J42-M42-N42 -> 189.09789 | P42: =O42*F42 -> 7563.9155
A43: 35 | B43: LAHORI MIX | C43: 80 | D43: gm | E43: 180 | F43: 40 | G43: 100 | J43: =E43/$J$3 -> 163.63636 | K43: =L43*18% -> 24.961479 | L43: =J43/$L$3 -> 138.67488 | M43: =L43-L43/1.06 -> 7.8495218 | N43: =J43*$N$3 -> 19.636364 | O43: =J43-M43-N43 -> 136.15048 | P43: =O43*F43 -> 5446.0191
A44: 36 | B44: NIMKO SALT & PEPPER | C44: 80 | D44: gm | E44: 120 | F44: 40 | G44: 50 | J44: =E44/$J$3 -> 109.09091 | K44: =L44*18% -> 16.640986 | L44: =J44/$L$3 -> 92.449923 | M44: =L44-L44/1.06 -> 5.2330145 | N44: =J44*$N$3 -> 13.090909 | O44: =J44-M44-N44 -> 90.766985 | P44: =O44*F44 -> 3630.6794
A46: 37 | B46: SHAHI MIX | C46: 180 | D46: gm | E46: 500 | F46: 27 | G46: 0 | J46: =E46/$J$3 -> 454.54545 | K46: =L46*18% -> 69.337442 | L46: =J46/$L$3 -> 385.20801 | M46: =L46-L46/1.06 -> 21.804227 | N46: =J46*$N$3 -> 54.545455 | O46: =J46-M46-N46 -> 378.19577 | P46: =O46*F46 -> 10211.286
...

Sheet Cust. Price List
V2: 0.18
A4: S# | B4: Code | D4: SKU | E4: SKUs Description | F4: Unit | H4: Retail Price | J4: TP Incl. | L4: TP Excl. | N4: Dist Margin | P4: Trade Offre | R4: Stale | T4: Ex-Fac | V4: S.Tax | X4: Dist. Price
B5: Bar | C5: SKU | F5: Gm | G5: CTN | H5: Ctn | I5: Pk | J5: Ctn | K5: Pk | L5: Ctn | M5: Pk | N5: 0.19 | O5: Amount | P5: 0.04 | Q5: Amount | R5: 0.005 | S5: Amount | T5: Ctn | U5: Pk | V5: Ctn | W5: Pk | X5: Ctn | Y5: Pk | AA5: Weight/ctn
A6: 1 | C6: CCN | D6: CCN | E6: Meat Masala | F6: 70 | G6: 40 | H6: =I6*G6 -> 2600 | I6: 65 | J6: =K6*G6 -> 2560.17 | K6: =M6*1.22 -> 64.00425 | L6: 2098.5 | M6: =L6/G6 -> 52.4625 | N6: 0.11 | O6: =N6*M6 -> 5.770875 | Q6: =P6*M6 -> 0 | S6: =R6*M6 -> 0 | T6: =U6*G6 -> 1867.665 | U6: =M6-O6-Q6-S6 -> 46.691625 | V6: =T6*$V$2 -> 336.1797 | W6: =U6*$V$2 -> 8.4044925 | X6: =T6+V6 -> 2203.8447 | Y6: =U6+W6 -> 55.096118 | AA6: =(F6*G6)/1000 -> 2.8 | AB6: 2000 | AC6: =X6*AB6 -> 4407689.4
A7: =+A6+1 -> 2 | C7: VTN | D7: VTN | E7: Lemon Tarka | F7: 70 | G7: 40 | H7: =I7*G7 -> 2600 | I7: 65 | J7: =K7*G7 -> 2560.17 | K7: =M7*1.22 -> 64.00425 | L7: 2098.5 | M7: =L7/G7 -> 52.4625 | N7: =+N6 -> 0.11 | O7: =N7*M7 -> 5.770875 | Q7: =P7*M7 -> 0 | S7: =R7*M7 -> 0 | T7: =U7*G7 -> 1867.665 | U7: =M7-O7-Q7-S7 -> 46.691625 | V7: =T7*$V$2 -> 336.1797 | W7: =U7*$V$2 -> 8.4044925 | X7: =T7+V7 -> 2203.8447 | Y7: =U7+W7 -> 55.096118 | AA7: =(F7*G7)/1000 -> 2.8
A8: =+A7+1 -> 3 | C8: BCN | D8: BCN | E8: Chicken Chatkhara | F8: 70 | G8: 40 | H8: =I8*G8 -> 2600 | I8: 65 | J8: =K8*G8 -> 2560.17 | K8: =M8*1.22 -> 64.00425 | L8: 2098.5 | M8: =L8/G8 -> 52.4625 | N8: =+N7 -> 0.11 | O8: =N8*M8 -> 5.770875 | Q8: =P8*M8 -> 0 | S8: =R8*M8 -> 0 | T8: =U8*G8 -> 1867.665 | U8: =M8-O8-Q8-S8 -> 46.691625 | V8: =T8*$V$2 -> 336.1797 | W8: =U8*$V$2 -> 8.4044925 | X8: =T8+V8 -> 2203.8447 | Y8: =U8+W8 -> 55.096118 | AA8: =(F8*G8)/1000 -> 2.8
A9: =+A8+1 -> 4 | C9: CCNJ | D9: CCNJ | E9: Meat Masala (Jumbo) | F9: 120 | G9: 40 | H9: =I9*G9 -> 3600 | I9: 90 | J9: =K9*G9 -> 3544.832 | K9: =M9*1.22 -> 88.6208 | L9: 2905.6 | M9: =L9/G9 -> 72.64 | N9: =+N8 -> 0.11 | O9: =N9*M9 -> 7.9904 | Q9: =P9*M9 -> 0 | S9: =R9*M9 -> 0 | T9: =U9*G9 -> 2585.984 | U9: =M9-O9-Q9-S9 -> 64.6496 | V9: =T9*$V$2 -> 465.47712 | W9: =U9*$V$2 -> 11.636928 | X9: =T9+V9 -> 3051.4611 | Y9: =U9+W9 -> 76.286528 | AA9: =(F9*G9)/1000 -> 4.8 | AB9: 1000 | AC9: =X9*AB9 -> 3051461.1
A10: =+A9+1 -> 5 | C10: VTNJ | D10: VTNJ | E10: Lemon Tarka (Jumbo) | F10: 120 | G10: 40 | H10: =I10*G10 -> 3600 | I10: 90 | J10: =K10*G10 -> 3544.832 | K10: =M10*1.22 -> 88.6208 | L10: 2905.6 | M10: =L10/G10 -> 72.64 | N10: =+N9 -> 0.11 | O10: =N10*M10 -> 7.9904 | Q10: =P10*M10 -> 0 | S10: =R10*M10 -> 0 | T10: =U10*G10 -> 2585.984 | U10: =M10-O10-Q10-S10 -> 64.6496 | V10: =T10*$V$2 -> 465.47712 | W10: =U10*$V$2 -> 11.636928 | X10: =T10+V10 -> 3051.4611 | Y10: =U10+W10 -> 76.286528 | AA10: =(F10*G10)/1000 -> 4.8
A11: =+A10+1 -> 6 | C11: BCNJ | D11: BCNJ | E11: Chicken Chatkhara (Jumbo) | F11: 120 | G11: 40 | H11: =I11*G11 -> 3600 | I11: 90 | J11: =K11*G11 -> 3544.832 | K11: =M11*1.22 -> 88.6208 | L11: 2905.6 | M11: =L11/G11 -> 72.64 | N11: =+N10 -> 0.11 | O11: =N11*M11 -> 7.9904 | Q11: =P11*M11 -> 0 | S11: =R11*M11 -> 0 | T11: =U11*G11 -> 2585.984 | U11: =M11-O11-Q11-S11 -> 64.6496 | V11: =T11*$V$2 -> 465.47712 | W11: =U11*$V$2 -> 11.636928 | X11: =T11+V11 -> 3051.4611 | Y11: =U11+W11 -> 76.286528 | AA11: =(F11*G11)/1000 -> 4.8
A12: =+A11+1 -> 7 | C12: CCE | D12: CCE | E12: Chicken Chatkhara (ECO) | F12: 60 | G12: 40 | H12: =I12*G12 -> 2000 | I12: 50 | J12: =K12*G12 -> 1914.424 | K12: =M12*1.22 -> 47.8606 | L12: 1569.2 | M12: =L12/G12 -> 39.23 | N12: =+N11 -> 0.11 | O12: =N12*M12 -> 4.3153 | Q12: =P12*M12 -> 0 | S12: =R12*M12 -> 0 | T12: =U12*G12 -> 1396.588 | U12: =M12-O12-Q12-S12 -> 34.9147 | V12: =T12*$V$2 -> 251.38584 | W12: =U12*$V$2 -> 6.284646 | X12: =T12+V12 -> 1647.9738 | Y12: =U12+W12 -> 41.199346 | AA12: =(F12*G12)/1000 -> 2.4 | AB12: 2000 | AC12: =X12*AB12 -> 3295947.7
A13: =+A12+1 -> 8 | C13: VTE | D13: VTE | E13: Lemon Tarka (ECO) | F13: 60 | G13: 40 | H13: =I13*G13 -> 2000 | I13: 50 | J13: =K13*G13 -> 1914.424 | K13: =M13*1.22 -> 47.8606 | L13: 1569.2 | M13: =L13/G13 -> 39.23 | N13: =+N12 -> 0.11 | O13: =N13*M13 -> 4.3153 | Q13: =P13*M13 -> 0 | S13: =R13*M13 -> 0 | T13: =U13*G13 -> 1396.588 | U13: =M13-O13-Q13-S13 -> 34.9147 | V13: =T13*$V$2 -> 251.38584 | W13: =U13*$V$2 -> 6.284646 | X13: =T13+V13 -> 1647.9738 | Y13: =U13+W13 -> 41.199346 | AA13: =(F13*G13)/1000 -> 2.4 | AC13: =SUM(AC6:AC12) -> 10755098
A14: =+A13+1 -> 9 | C14: BCE | D14: BCE | E14: Meat Masala (ECO) | F14: 60 | G14: 40 | H14: =I14*G14 -> 2000 | I14: 50 | J14: =K14*G14 -> 1914.424 | K14: =M14*1.22 -> 47.8606 | L14: 1569.2 | M14: =L14/G14 -> 39.23 | N14: =+N13 -> 0.11 | O14: =N14*M14 -> 4.3153 | Q14: =P14*M14 -> 0 | S14: =R14*M14 -> 0 | T14: =U14*G14 -> 1396.588 | U14: =M14-O14-Q14-S14 -> 34.9147 | V14: =T14*$V$2 -> 251.38584 | W14: =U14*$V$2 -> 6.284646 | X14: =T14+V14 -> 1647.9738 | Y14: =U14+W14 -> 41.199346 | AA14: =(F14*G14)/1000 -> 2.4
A15: =+A14+1 -> 10
A16: =+A15+1 -> 11
A17: =+A16+1 -> 12
A18: =+A17+1 -> 13
A19: =+A18+1 -> 14
A20: =+A19+1 -> 15
A22: =+A20+1 -> 16
A23: =+A22+1 -> 17
A24: =+A23+1 -> 18
A25: =+A24+1 -> 19
A26: =+A25+1 -> 20
A27: =+A26+1 -> 21
A28: =+A27+1 -> 22
A29: =+A28+1 -> 23
A30: =+A29+1 -> 24
A31: =+A30+1 -> 25
A32: =+A31+1 -> 26
A33: =+A32+1 -> 27
A34: =+A33+1 -> 28
A36: =+A34+1 -> 29
A37: =+A36+1 -> 30
A38: =+A37+1 -> 31
A39: =+A38+1 -> 32
A40: =+A39+1 -> 33
A41: =+A40+1 -> 34
A42: =+A41+1 -> 35
A43: =+A42+1 -> 36
A44: =+A43+1 -> 37
...

Sheet 1
E1: Indomie Price List July
A3: NTN Status: | B3: Filer | C3: =IF($O24>2.49%,"No","Yes") -> Yes | K3: Order at Original Location : | N3: Yes
A4: STRN Status: | B4: Registered | C4: =IF($O22>21.99%,"No","Yes") -> Yes | K4: Reference Invoice : | XFC4: Monday/Tuesday
XFC5: Tuesday / Wednesday
A6: Product Code/Description | C6: GM/ Pack | D6: CTN | E6: Unit | G6: Sale QTY | I6: Gross Amount Excl. Taxes | J6: Trade Offer & Discount | M6: After Discount Amount | N6: GST 18% | O6: Adv. Tax 236H | P6: Invoice | XFC6: Wednesday/Thursday
D7: SIZE | E7: MRP | F7: T.P Per | G7: CTN | H7: Pack | J7: 0.08 | K7: Trade Offer | L7: additional | O7: =IF(B3="Filer",0.5%,2.5%) -> 0.005 | P7: Amount | XFC7: Thursday /Friday
A8: CCN | B8: =VLOOKUP($A8,'Cust. Price List'!$D$6:$O$14,2,0) -> Meat Masala | C8: =VLOOKUP(A8,'Cust. Price List'!D6:M14,3,0) -> 70 | D8: =VLOOKUP(A8,'Cust. Price List'!D6:M14,4,0) -> 40 | E8: =VLOOKUP(A8,'Cust. Price List'!D6:M14,6,0) -> 65 | F8: =VLOOKUP(A8,'Cust. Price List'!D6:M14,10,0) -> 52.4625 | G8: 1 | I8: =(G8*D8)*F8+H8*F8 -> 2098.5 | J8: =I8*J7 -> 167.88 | K8: =$I8*3.5% -> 73.4475 | L8: =$I8*T8 -> 0 | M8: =I8-SUM(J8:L8) -> 1857.1725 | N8: =+(G8*D8+H8)*9.92 -> 396.8 | O8: =(N8+M8)*$O$7 -> 11.269863 | P8: =M8+N8+O8 -> 2265.2424 | XFC8: Friday / Saturday
A9: VTN | B9: =VLOOKUP($A9,'Cust. Price List'!$D$6:$O$14,2,0) -> Lemon Tarka | C9: =VLOOKUP(B9,'Cust. Price List'!E7:P15,2,0) -> 70 | D9: =VLOOKUP(A9,'Cust. Price List'!D7:M15,4,0) -> 40 | E9: =VLOOKUP(A9,'Cust. Price List'!D7:M15,6,0) -> 65 | F9: =VLOOKUP(A9,'Cust. Price List'!D7:M15,10,0) -> 52.4625 | I9: =(G9*D9)*F9+H9*F9 -> 0 | J9: =I9*J7 -> 0 | K9: =$I9*3.5% -> 0 | L9: =$I9*T9 -> 0 | M9: =I9-SUM(J9:L9) -> 0 | N9: =+(G9*D9+H9)*9.92 -> 0 | O9: =(N9+M9)*$O$7 -> 0 | P9: =M9+N9+O9 -> 0 | XFC9: Saturday /Monday
A10: BCN | B10: =VLOOKUP($A10,'Cust. Price List'!$D$6:$O$14,2,0) -> Chicken Chatkhara | C10: =VLOOKUP(B10,'Cust. Price List'!E8:P16,2,0) -> 70 | D10: =VLOOKUP(A10,'Cust. Price List'!D8:M16,4,0) -> 40 | E10: =VLOOKUP(A10,'Cust. Price List'!D8:M16,6,0) -> 65 | F10: =VLOOKUP(A10,'Cust. Price List'!D8:M16,10,0) -> 52.4625 | I10: =(G10*D10)*F10+H10*F10 -> 0 | J10: =I10*J7 -> 0 | K10: =$I10*3.5% -> 0 | L10: =$I10*T10 -> 0 | M10: =I10-SUM(J10:L10) -> 0 | N10: =+(G10*D10+H10)*9.92 -> 0 | O10: =(N10+M10)*$O$7 -> 0 | P10: =M10+N10+O10 -> 0
A11: CCNJ | B11: =VLOOKUP($A11,'Cust. Price List'!$D$6:$O$14,2,0) -> Meat Masala (Jumbo) | C11: =VLOOKUP(B11,'Cust. Price List'!E9:P17,2,0) -> 120 | D11: =VLOOKUP(A11,'Cust. Price List'!D9:M17,4,0) -> 40 | E11: =VLOOKUP(A11,'Cust. Price List'!D9:M17,6,0) -> 90 | F11: =VLOOKUP(A11,'Cust. Price List'!D9:M17,10,0) -> 72.64 | G11: 1 | I11: =(G11*D11)*F11+H11*F11 -> 2905.6 | J11: =I11*J7 -> 232.448 | K11: =$I11*3.5% -> 101.696 | L11: =$I11*T11 -> 0 | M11: =I11-SUM(J11:L11) -> 2571.456 | N11: =+(G11*D11+H11)*13.73 -> 549.2 | O11: =(N11+M11)*$O$7 -> 15.60328 | P11: =M11+N11+O11 -> 3136.2593
A12: VTNJ | B12: =VLOOKUP($A12,'Cust. Price List'!$D$6:$O$14,2,0) -> Lemon Tarka (Jumbo) | C12: =VLOOKUP(B12,'Cust. Price List'!E10:P18,2,0) -> 120 | D12: =VLOOKUP(A12,'Cust. Price List'!D10:M18,4,0) -> 40 | E12: =VLOOKUP(A12,'Cust. Price List'!D10:M18,6,0) -> 90 | F12: =VLOOKUP(A12,'Cust. Price List'!D10:M18,10,0) -> 72.64 | I12: =(G12*D12)*F12+H12*F12 -> 0 | J12: =I12*J7 -> 0 | K12: =$I12*3.5% -> 0 | L12: =$I12*T12 -> 0 | M12: =I12-SUM(J12:L12) -> 0 | N12: =+(G12*D12+H12)*13.73 -> 0 | O12: =(N12+M12)*$O$7 -> 0 | P12: =M12+N12+O12 -> 0
A13: BCNJ | B13: =VLOOKUP($A13,'Cust. Price List'!$D$6:$O$14,2,0) -> Chicken Chatkhara (Jumbo) | C13: =VLOOKUP(B13,'Cust. Price List'!E11:P19,2,0) -> 120 | D13: =VLOOKUP(A13,'Cust. Price List'!D11:M19,4,0) -> 40 | E13: =VLOOKUP(A13,'Cust. Price List'!D11:M19,6,0) -> 90 | F13: =VLOOKUP(A13,'Cust. Price List'!D11:M19,10,0) -> 72.64 | I13: =(G13*D13)*F13+H13*F13 -> 0 | J13: =I13*J7 -> 0 | K13: =$I13*3.5% -> 0 | L13: =$I13*T13 -> 0 | M13: =I13-SUM(J13:L13) -> 0 | N13: =+(G13*D13+H13)*13.73 -> 0 | O13: =(N13+M13)*$O$7 -> 0 | P13: =M13+N13+O13 -> 0
A14: CCE | B14: =VLOOKUP($A14,'Cust. Price List'!$D$6:$O$14,2,0) -> Chicken Chatkhara (ECO) | C14: =VLOOKUP(B14,'Cust. Price List'!E12:P20,2,0) -> 60 | D14: =VLOOKUP(A14,'Cust. Price List'!D12:M20,4,0) -> 40 | E14: =VLOOKUP(A14,'Cust. Price List'!D12:M20,6,0) -> 50 | F14: =VLOOKUP(A14,'Cust. Price List'!D12:M20,10,0) -> 39.23 | G14: 1 | I14: =(G14*D14)*F14+H14*F14 -> 1569.2 | J14: =I14*5% -> 78.46 | K14: =$I14*3.5% -> 54.922 | L14: =$I14*5.1% -> 80.0292 | M14: =I14-SUM(J14:L14) -> 1355.7888 | N14: =+(G14*D14+H14)*7.63 -> 305.2 | O14: =(N14+M14)*$O$7 -> 8.304944 | P14: =M14+N14+O14 -> 1669.2937
A15: =COUNT(A8:A14) -> 0 | C15: Total | G15: =SUM(G8:G14) -> 3 | H15: =SUM(H8:H14) -> 0 | I15: =SUM(I8:I14) -> 6573.3 | J15: =SUM(J8:J14) -> 478.788 | K15: =SUM(K8:K14) -> 230.0655 | L15: =SUM(L8:L14) -> 80.0292 | M15: =SUM(M8:M14) -> 5784.4173 | N15: =SUM(N8:N14) -> 1251.2 | ... P15: =SUM(P8:P14) -> 7070.7954
B18: یکم جولائی 2024سے نئی ٹیکس ترمیم کے مطابق، ایف بی آر سیکشن 236 ایچ کے مطابق، فائلرز کے لیے ہر سیل انوائس پر 0.5% اور نان فائلرز کے لیے 2.5% ایڈوانس ود ہولڈنگ ٹیکس وصول کیا جائے گا۔ | N18: Gross Amount: | P18: =I15 -> 6573.3
N19: Regular Discount | P19: =+J15 -> 478.788
N20: Trade Offre | P20: =+K15+L15 -> 310.0947
N21: After Dis. Amount | P21: =P18-P19-P20 -> 5784.4173
N22: Total GST: | O22: 0.18 | P22: =+N15 -> 1251.2
N23: Net Amount: | P23: =P21+P22 -> 7035.6173
N24: Ad.Tax | O24: =IF(B3="Filer",0.5%,2.5%) -> 0.005 | P24: =O24*P23 -> 35.178087
N25: Net Amount with Ad.Tax | P25: =+P23+P24 -> 7070.7954
B26: Delivered By
L28: 0

Sheet Customer Invoice (2)
A2: Elite MARKETING
A3: 44A- Gulberg Lahore | J3: Invoice No # : | XFB3: Filer | XFC3: 0.005
A4: STRN / NTN : 12345-6789012-3/1234567-3 | J4: Date/Day : | M4: =TODAY()+1 -> 46282 | XFB4: Non-filer | XFC4: 0.025
A5: Customer Name : | J5: Order Date : | M5: =M4-1 -> 46281
A6: Proprietor Name: | J6: Order Name : | M6: Muhammad Hamza | XFB6: Registered | XFC6: 0.18
A7: CNIC #:12345-6789012-3 | J7: Route Name : | M7: Jallo-&-Taiz Ghar-&-Thu | XFB7: Un-registered | XFC7: 0.22
A8: Address: | J8: Section Name: | M8: Taiz Ghar
A9: Channel Type:Retail/LMT | J9: Visit & Delivery Day | M9: Monday/Tuesday | XFC9: Yes
A10: Sub-Channel:General/medical/LMT Store / | J10: Invoice Status : | M10: Serviced | XFC10: No
A11: NTN Status: | B11: Non-filer | C11: =IF($N34>2.49%,"No","Yes") -> No | J11: Order at Original Location : | M11: Yes
A12: STRN Status: | B12: Un-registered | C12: =IF($N32>21.99%,"No","Yes") -> No | J12: Reference Invoice : | XFC12: Monday/Tuesday
J13: 0.035 | XFC13: Tuesday / Wednesday
A14: Product Code/Description | C14: GM/ Pack | D14: CTN | E14: R.P Per | F14: T.P Per | G14: Sale QTY | I14: Gross Amount Excl. Taxes | J14: Trade Offer & Discount | L14: After Discount Amount | M14: GST | N14: Adv. Tax 236H | O14: Invoice | XFC14: Wednesday/Thursday
D15: SIZE | E15: Unit | F15: Unit | G15: CTN | H15: Pack | J15: Trade Offer | K15: Pass On | M15: =IF(B12="Registered",18%,22%) -> 0.22 | N15: =IF(B11="Filer",0.5%,2.5%) -> 0.025 | O15: Amount | XFC15: Thursday /Friday
A16: CCN | B16: =VLOOKUP($A16,'Cust. Price List'!$D$6:$O$14,2,0) -> Meat Masala | C16: =VLOOKUP(A16,'Cust. Price List'!D6:M14,3,0) -> 70 | D16: =VLOOKUP(A16,'Cust. Price List'!D6:M14,4,0) -> 40 | E16: =VLOOKUP(A16,'Cust. Price List'!D6:M14,6,0) -> 65 | F16: =VLOOKUP(A16,'Cust. Price List'!D6:M14,10,0) -> 52.4625 | I16: =(G16*D16)*F16+H16*F16 -> 0 | J16: =I16*$J$13 -> 0 | K16: =I16*$K$13 -> 0 | L16: =I16-J16-K16 -> 0 | M16: =(L16*$M$15) -> 0 | N16: =(M16+L16)*$N$15 -> 0 | O16: =L16+M16+N16 -> 0 | XFC16: Friday / Saturday
A17: VTN | B17: =VLOOKUP($A17,'Cust. Price List'!$D$6:$O$14,2,0) -> Lemon Tarka | C17: =VLOOKUP(B17,'Cust. Price List'!E7:P15,2,0) -> 70 | D17: =VLOOKUP(A17,'Cust. Price List'!D7:M15,4,0) -> 40 | E17: =VLOOKUP(A17,'Cust. Price List'!D7:M15,6,0) -> 65 | F17: =VLOOKUP(A17,'Cust. Price List'!D7:M15,10,0) -> 52.4625 | I17: =(G17*D17)*F17+H17*F17 -> 0 | J17: =I17*$J$13 -> 0 | K17: =I17*$K$13 -> 0 | L17: =I17-J17-K17 -> 0 | M17: =(L17*$M$15) -> 0 | N17: =(M17+L17)*$N$15 -> 0 | O17: =L17+M17+N17 -> 0 | XFC17: Saturday /Monday
A18: BCN | B18: =VLOOKUP($A18,'Cust. Price List'!$D$6:$O$14,2,0) -> Chicken Chatkhara | C18: =VLOOKUP(B18,'Cust. Price List'!E8:P16,2,0) -> 70 | D18: =VLOOKUP(A18,'Cust. Price List'!D8:M16,4,0) -> 40 | E18: =VLOOKUP(A18,'Cust. Price List'!D8:M16,6,0) -> 65 | F18: =VLOOKUP(A18,'Cust. Price List'!D8:M16,10,0) -> 52.4625 | I18: =(G18*D18)*F18+H18*F18 -> 0 | J18: =I18*$J$13 -> 0 | K18: =I18*$K$13 -> 0 | L18: =I18-J18-K18 -> 0 | M18: =(L18*$M$15) -> 0 | N18: =(M18+L18)*$N$15 -> 0 | O18: =L18+M18+N18 -> 0
A19: CCNJ | B19: =VLOOKUP($A19,'Cust. Price List'!$D$6:$O$14,2,0) -> Meat Masala (Jumbo) | C19: =VLOOKUP(B19,'Cust. Price List'!E9:P17,2,0) -> 120 | D19: =VLOOKUP(A19,'Cust. Price List'!D9:M17,4,0) -> 40 | E19: =VLOOKUP(A19,'Cust. Price List'!D9:M17,6,0) -> 90 | F19: =VLOOKUP(A19,'Cust. Price List'!D9:M17,10,0) -> 72.64 | I19: =(G19*D19)*F19+H19*F19 -> 0 | J19: =I19*$J$13 -> 0 | K19: =I19*$K$13 -> 0 | L19: =I19-J19-K19 -> 0 | M19: =(L19*$M$15) -> 0 | N19: =(M19+L19)*$N$15 -> 0 | O19: =L19+M19+N19 -> 0
A20: VTNJ | B20: =VLOOKUP($A20,'Cust. Price List'!$D$6:$O$14,2,0) -> Lemon Tarka (Jumbo) | C20: =VLOOKUP(B20,'Cust. Price List'!E10:P18,2,0) -> 120 | D20: =VLOOKUP(A20,'Cust. Price List'!D10:M18,4,0) -> 40 | E20: =VLOOKUP(A20,'Cust. Price List'!D10:M18,6,0) -> 90 | F20: =VLOOKUP(A20,'Cust. Price List'!D10:M18,10,0) -> 72.64 | H20: 20 | I20: =(G20*D20)*F20+H20*F20 -> 1452.8 | J20: =I20*$J$13 -> 50.848 | K20: =I20*$K$13 -> 0 | L20: =I20-J20-K20 -> 1401.952 | M20: =(L20*$M$15) -> 308.42944 | N20: =(M20+L20)*$N$15 -> 42.759536 | O20: =L20+M20+N20 -> 1753.141
A21: BCNJ | B21: =VLOOKUP($A21,'Cust. Price List'!$D$6:$O$14,2,0) -> Chicken Chatkhara (Jumbo) | C21: =VLOOKUP(B21,'Cust. Price List'!E11:P19,2,0) -> 120 | D21: =VLOOKUP(A21,'Cust. Price List'!D11:M19,4,0) -> 40 | E21: =VLOOKUP(A21,'Cust. Price List'!D11:M19,6,0) -> 90 | F21: =VLOOKUP(A21,'Cust. Price List'!D11:M19,10,0) -> 72.64 | I21: =(G21*D21)*F21+H21*F21 -> 0 | J21: =I21*$J$13 -> 0 | K21: =I21*$K$13 -> 0 | L21: =I21-J21-K21 -> 0 | M21: =(L21*$M$15) -> 0 | N21: =(M21+L21)*$N$15 -> 0 | O21: =L21+M21+N21 -> 0
A22: CCE | B22: =VLOOKUP($A22,'Cust. Price List'!$D$6:$O$14,2,0) -> Chicken Chatkhara (ECO) | C22: =VLOOKUP(B22,'Cust. Price List'!E12:P20,2,0) -> 60 | D22: =VLOOKUP(A22,'Cust. Price List'!D12:M20,4,0) -> 40 | E22: =VLOOKUP(A22,'Cust. Price List'!D12:M20,6,0) -> 50 | F22: =VLOOKUP(A22,'Cust. Price List'!D12:M20,10,0) -> 39.23 | I22: =(G22*D22)*F22+H22*F22 -> 0 | J22: =I22*$J$13 -> 0 | K22: =I22*$K$13 -> 0 | L22: =I22-J22-K22 -> 0 | M22: =(L22*$M$15) -> 0 | N22: =(M22+L22)*$N$15 -> 0 | O22: =L22+M22+N22 -> 0
A23: VTE | B23: =VLOOKUP($A23,'Cust. Price List'!$D$6:$O$14,2,0) -> Lemon Tarka (ECO) | C23: =VLOOKUP(B23,'Cust. Price List'!E13:P21,2,0) -> 60 | D23: =VLOOKUP(A23,'Cust. Price List'!D13:M21,4,0) -> 40 | E23: =VLOOKUP(A23,'Cust. Price List'!D13:M21,6,0) -> 50 | F23: =VLOOKUP(A23,'Cust. Price List'!D13:M21,10,0) -> 39.23 | I23: =(G23*D23)*F23+H23*F23 -> 0 | J23: =I23*$J$13 -> 0 | K23: =I23*$K$13 -> 0 | L23: =I23-J23-K23 -> 0 | M23: =(L23*$M$15) -> 0 | N23: =(M23+L23)*$N$15 -> 0 | O23: =L23+M23+N23 -> 0
A24: BCE | B24: =VLOOKUP($A24,'Cust. Price List'!$D$6:$O$14,2,0) -> Meat Masala (ECO) | C24: =VLOOKUP(B24,'Cust. Price List'!E14:P22,2,0) -> 60 | D24: =VLOOKUP(A24,'Cust. Price List'!D14:M22,4,0) -> 40 | E24: =VLOOKUP(A24,'Cust. Price List'!D14:M22,6,0) -> 50 | F24: =VLOOKUP(A24,'Cust. Price List'!D14:M22,10,0) -> 39.23 | I24: =(G24*D24)*F24+H24*F24 -> 0 | J24: =I24*$J$13 -> 0 | K24: =I24*$K$13 -> 0 | L24: =I24-J24-K24 -> 0 | M24: =(L24*$M$15) -> 0 | N24: =(M24+L24)*$N$15 -> 0 | O24: =L24+M24+N24 -> 0
A25: =COUNT(A16:A24) -> 0 | C25: Total | G25: =SUM(G16:G24) -> 0 | H25: =SUM(H16:H24) -> 20 | I25: =SUM(I16:I24) -> 1452.8 | J25: =SUM(J16:J24) -> 50.848 | K25: =SUM(K16:K24) -> 0 | L25: =SUM(L16:L24) -> 1401.952 | M25: =SUM(M16:M24) -> 308.42944 | N25: =SUM(N16:N24) -> 42.759536 | O25: =SUM(O16:O24) -> 1753.141
B28: یکم جولائی 2024سے نئی ٹیکس ترمیم کے مطابق، ایف بی آر سیکشن 236 ایچ کے مطابق، فائلرز کے لیے ہر سیل انوائس پر 0.5% اور نان فائلرز کے لیے 2.5% ایڈوانس ود ہولڈنگ ٹیکس وصول کیا جائے گا۔ | M28: Gross Amount: | O28: =I25 -> 1452.8
M29: Regular Discount | O29: =K25 -> 0
M30: Trade Offre | O30: =J25 -> 50.848
M31: After Dis. Amount | O31: =O28-O29-O30 -> 1401.952
M32: Total GST: | N32: =IF(B12="Registered",18%,22%) -> 0.22 | O32: =N32*O31 -> 308.42944
M33: Net Amount: | O33: =O31+O32 -> 1710.3814
M34: Ad.Tax | N34: =IF(B11="Filer",0.5%,2.5%) -> 0.025 | O34: =N34*O33 -> 42.759536
M35: Net Amount with Ad.Tax | O35: =O28-O29+O31+O34 -> 2897.5115
B36: Delivered By

Sheet Sheet1
C1: SKU | D1: SKUs Description | E1: Unit | G1: Retail Price | I1: TP Incl. | K1: TP Excl. | M1: Discount & TO
E2: Gm | F2: CTN | G2: Ctn | H2: Pk | I2: Ctn | J2: Pk | K2: Ctn | L2: Pk | M2: Discount | N2: TO | O2: Total
C3: CCN | D3: Meat Masala | E3: 70 | F3: 40 | G3: =H3*F3 -> 2600 | H3: 65 | I3: =J3*F3 -> 2560.17 | J3: =L3*1.22 -> 64.00425 | K3: 2098.5 | L3: =K3/F3 -> 52.4625 | M3: 0.08 | N3: 0.035 | O3: =M3+N3 -> 0.115
C4: CCNJ | D4: Meat Masala (Jumbo) | E4: 120 | F4: 40 | G4: =H4*F4 -> 3600 | H4: 90 | I4: =J4*F4 -> 3544.832 | J4: =L4*1.22 -> 88.6208 | K4: 2905.6 | L4: =K4/F4 -> 72.64 | M4: 0.08 | N4: 0.035 | O4: =M4+N4 -> 0.115
C5: CCE | D5: Chicken Chatkhara (ECO) | E5: 60 | F5: 40 | G5: =H5*F5 -> 2000 | H5: 50 | I5: =J5*F5 -> 1914.424 | J5: =L5*1.22 -> 47.8606 | K5: 1569.2 | L5: =K5/F5 -> 39.23 | M5: 0.05 | N5: 0.035 | O5: =M5+N5 -> 0.085
C6: Unregistered Customer's with Non Filer | T6: 20 Pack | U6: 40 Pack
C7: SKU | D7: SKUs Description | E7: Unit | G7: Retail Price | I7: TP Incl. | K7: TP Excl. | M7: Discount & TO | P7: Net Price | Q7: Adv | R7: Net Price | S7: FOC Tax | T7: Net Amount | U7: Net Amount
E8: Gm | F8: CTN | G8: Ctn | H8: Pk | I8: Ctn | J8: Pk | K8: Ctn | L8: Pk | M8: Discount | N8: TO | O8: Total | P8: Incl. 22% | Q8: 236 H
C9: CCN | D9: Meat Masala | E9: 70 | F9: 40 | G9: =H9*F9 -> 2600 | H9: 65 | I9: =J9*F9 -> 2560.17 | J9: =L9*1.22 -> 64.00425 | K9: 2098.5 | L9: =K9/F9 -> 52.4625 | M9: =M3 -> 0.08 | O9: =M9+N9 -> 0.08 | P9: =(L9-(L9*O9))*1.22 -> 58.88391 | Q9: 0.025 | R9: =P9*Q9+P9 -> 60.356008 | S9: =L9*22% -> 11.54175 | T9: =R9*20+S9 -> 1218.6619 | U9: =T9*2 -> 2437.3238
C10: CCNJ | D10: Meat Masala (Jumbo) | E10: 120 | F10: 40 | G10: =H10*F10 -> 3600 | H10: 90 | I10: =J10*F10 -> 3544.832 | J10: =L10*1.22 -> 88.6208 | K10: 2905.6 | L10: =K10/F10 -> 72.64 | M10: =M4 -> 0.08 | O10: =M10+N10 -> 0.08 | P10: =(L10-(L10*O10))*1.22 -> 81.531136 | Q10: 0.025 | R10: =P10*Q10+P10 -> 83.569414 | S10: =L10*22% -> 15.9808 | T10: =R10*20+S10 -> 1687.3691 | U10: =T10*2 -> 3374.7382
C11: CCE | D11: Chicken Chatkhara (ECO) | E11: 60 | F11: 40 | G11: =H11*F11 -> 2000 | H11: 50 | I11: =J11*F11 -> 1914.424 | J11: =L11*1.22 -> 47.8606 | K11: 1569.2 | L11: =K11/F11 -> 39.23 | M11: 0.05 | N11: =N5 -> 0.035 | O11: =M11+N11 -> 0.085 | P11: =(L11-(L11*O11))*1.22 -> 43.792449 | Q11: 0.025 | R11: =P11*Q11+P11 -> 44.88726 | T11: =R11*20+S11 -> 897.7452 | U11: =T11*2 -> 1795.4904
C12: Unregistered Customer's with Filer
C13: SKU | D13: SKUs Description | E13: Unit | G13: Retail Price | I13: TP Incl. | K13: TP Excl. | M13: Discount & TO | P13: Net Price | Q13: Adv | R13: Net Price | S13: FOC Tax | T13: Net Amount | U13: Net Amount
E14: Gm | F14: CTN | G14: Ctn | H14: Pk | I14: Ctn | J14: Pk | K14: Ctn | L14: Pk | M14: Discount | N14: TO | O14: Total | P14: Incl. 22% | Q14: 236 H
C15: CCN | D15: Meat Masala | E15: 70 | F15: 40 | G15: =H15*F15 -> 2600 | H15: 65 | I15: =J15*F15 -> 2560.17 | J15: =L15*1.22 -> 64.00425 | K15: 2098.5 | L15: =K15/F15 -> 52.4625 | M15: =M3 -> 0.08 | O15: =M15+N15 -> 0.08 | P15: =(L15-(L15*O15))*1.22 -> 58.88391 | Q15: 0.005 | R15: =P15*Q15+P15 -> 59.17833 | S15: =L15*22% -> 11.54175 | T15: =R15*20+S15 -> 1195.1083 | U15: =T15*2 -> 2390.2167
C16: CCNJ | D16: Meat Masala (Jumbo) | E16: 120 | F16: 40 | G16: =H16*F16 -> 3600 | H16: 90 | I16: =J16*F16 -> 3544.832 | J16: =L16*1.22 -> 88.6208 | K16: 2905.6 | L16: =K16/F16 -> 72.64 | M16: =M4 -> 0.08 | O16: =M16+N16 -> 0.08 | P16: =(L16-(L16*O16))*1.22 -> 81.531136 | Q16: 0.005 | R16: =P16*Q16+P16 -> 81.938792 | S16: =L16*22% -> 15.9808 | T16: =R16*20+S16 -> 1654.7566 | U16: =T16*2 -> 3309.5133
C17: CCE | D17: Chicken Chatkhara (ECO) | E17: 60 | F17: 40 | G17: =H17*F17 -> 2000 | H17: 50 | I17: =J17*F17 -> 1914.424 | J17: =L17*1.22 -> 47.8606 | K17: 1569.2 | L17: =K17/F17 -> 39.23 | M17: =M5 -> 0.05 | N17: =N5 -> 0.035 | O17: =M17+N17 -> 0.085 | P17: =(L17-(L17*O17))*1.22 -> 43.792449 | Q17: 0.005 | R17: =P17*Q17+P17 -> 44.011411 | T17: =R17*20+S17 -> 880.22822 | U17: =T17*2 -> 1760.4564
C19: Registered Customer's with Non Filer
C20: SKU | D20: SKUs Description | E20: Unit | G20: Retail Price | I20: TP Incl. | K20: TP Excl. | M20: Discount & TO | P20: Net Price | Q20: Adv | R20: Net Price | S20: FOC Tax | T20: Net Amount | U20: Net Amount
E21: Gm | F21: CTN | G21: Ctn | H21: Pk | I21: Ctn | J21: Pk | K21: Ctn | L21: Pk | M21: Discount | N21: TO | O21: Total | P21: Incl. 18% | Q21: 236 H
C22: CCN | D22: Meat Masala | E22: 70 | F22: 40 | G22: =H22*F22 -> 2600 | H22: 65 | I22: =J22*F22 -> 2560.17 | J22: =L22*1.22 -> 64.00425 | K22: 2098.5 | L22: =K22/F22 -> 52.4625 | M22: =M3 -> 0.08 | O22: =M22+N22 -> 0.08 | P22: =(L22-(L22*O22))*1.18 -> 56.95329 | Q22: 0.025 | R22: =P22*Q22+P22 -> 58.377122 | S22: =L22*18% -> 9.44325 | T22: =R22*20+S22 -> 1176.9857 | U22: =T22*2 -> 2353.9714
C23: CCNJ | D23: Meat Masala (Jumbo) | E23: 120 | F23: 40 | G23: =H23*F23 -> 3600 | H23: 90 | I23: =J23*F23 -> 3544.832 | J23: =L23*1.22 -> 88.6208 | K23: 2905.6 | L23: =K23/F23 -> 72.64 | M23: =M4 -> 0.08 | O23: =M23+N23 -> 0.08 | P23: =(L23-(L23*O23))*1.18 -> 78.857984 | Q23: 0.025 | R23: =P23*Q23+P23 -> 80.829434 | S23: =L23*18% -> 13.0752 | T23: =R23*20+S23 -> 1629.6639 | U23: =T23*2 -> 3259.3277
C24: CCE | D24: Chicken Chatkhara (ECO) | E24: 60 | F24: 40 | G24: =H24*F24 -> 2000 | H24: 50 | I24: =J24*F24 -> 1914.424 | J24: =L24*1.22 -> 47.8606 | K24: 1569.2 | L24: =K24/F24 -> 39.23 | M24: =M5 -> 0.05 | N24: =N5 -> 0.035 | O24: =M24+N24 -> 0.085 | P24: =(L24-(L24*O24))*1.18 -> 42.356631 | Q24: 0.025 | R24: =P24*Q24+P24 -> 43.415547 | T24: =R24*20+S24 -> 868.31094 | U24: =T24*2 -> 1736.6219
C26: Registered Customer's with Filer
C27: SKU | D27: SKUs Description | E27: Unit | G27: Retail Price | I27: TP Incl. | K27: TP Excl. | M27: Discount & TO | P27: Net Price | Q27: Adv | R27: Net Price | S27: FOC Tax | T27: Net Amount | U27: Net Amount
E28: Gm | F28: CTN | G28: Ctn | H28: Pk | I28: Ctn | J28: Pk | K28: Ctn | L28: Pk | M28: Discount | N28: TO | O28: Total | P28: Incl. 18% | Q28: 236 H
C29: CCN | D29: Meat Masala | E29: 70 | F29: 40 | G29: =H29*F29 -> 2600 | H29: 65 | I29: =J29*F29 -> 2560.17 | J29: =L29*1.22 -> 64.00425 | K29: 2098.5 | L29: =K29/F29 -> 52.4625 | M29: =M3 -> 0.08 | O29: =M29+N29 -> 0.08 | P29: =(L29-(L29*O29))*1.18 -> 56.95329 | Q29: 0.005 | R29: =P29*Q29+P29 -> 57.238056 | S29: =L29*18% -> 9.44325 | T29: =R29*20+S29 -> 1154.2044 | U29: =T29*2 -> 2308.4088
C30: CCNJ | D30: Meat Masala (Jumbo) | E30: 120 | F30: 40 | G30: =H30*F30 -> 3600 | H30: 90 | I30: =J30*F30 -> 3544.832 | J30: =L30*1.22 -> 88.6208 | K30: 2905.6 | L30: =K30/F30 -> 72.64 | M30: =M4 -> 0.08 | O30: =M30+N30 -> 0.08 | P30: =(L30-(L30*O30))*1.18 -> 78.857984 | Q30: 0.005 | R30: =P30*Q30+P30 -> 79.252274 | S30: =L30*18% -> 13.0752 | T30: =R30*20+S30 -> 1598.1207 | U30: =T30*2 -> 3196.2414
C31: CCE | D31: Chicken Chatkhara (ECO) | E31: 60 | F31: 40 | G31: =H31*F31 -> 2000 | H31: 50 | I31: =J31*F31 -> 1914.424 | J31: =L31*1.22 -> 47.8606 | K31: 1569.2 | L31: =K31/F31 -> 39.23 | M31: =M5 -> 0.05 | N31: =N5 -> 0.035 | O31: =M31+N31 -> 0.085 | P31: =(L31-(L31*O31))*1.18 -> 42.356631 | Q31: 0.005 | R31: =P31*Q31+P31 -> 42.568414 | T31: =R31*20+S31 -> 851.36828 | U31: =T31*2 -> 1702.7366

Sheet Sheet3
B1: SKU | C1: SKUs Description | D1: Unit | F1: Retail Price | H1: TP Incl. | J1: TP Excl. | L1: Discount & TO
D2: Gm | E2: CTN | F2: Ctn | G2: Pk | H2: Ctn | I2: Pk | J2: Ctn | K2: Pk | L2: Discount | M2: TO | N2: Total | P2: SD | Q2: Pass on
B3: CCN | C3: Meat Masala | D3: 70 | E3: 40 | F3: =G3*E3 -> 2600 | G3: 65 | H3: =I3*E3 -> 2560.17 | I3: =K3*1.22 -> 64.00425 | J3: 2098.5 | K3: =J3/E3 -> 52.4625 | L3: 0.08 | N3: =L3+M3 -> 0.08 | P3: 0.14 | Q3: 0.08
B4: CCNJ | C4: Meat Masala (Jumbo) | D4: 120 | E4: 40 | F4: =G4*E4 -> 3600 | G4: 90 | H4: =I4*E4 -> 3544.832 | I4: =K4*1.22 -> 88.6208 | J4: 2905.6 | K4: =J4/E4 -> 72.64 | L4: 0.08 | N4: =L4+M4 -> 0.08 | P4: 0.14 | Q4: 0.08
B5: CCE | C5: Chicken Chatkhara (ECO) | D5: 60 | E5: 40 | F5: =G5*E5 -> 2000 | G5: 50 | H5: =I5*E5 -> 1914.424 | I5: =K5*1.22 -> 47.8606 | J5: 1569.2 | K5: =J5/E5 -> 39.23 | L5: 0.05 | M5: 0.035 | N5: =L5+M5 -> 0.085 | P5: 0.115 | Q5: 0.05

Sheet Sheet2
B4: OB Name | E4: AppUserCode | F4: Route | G4: Section | H4: Day
A5: 1 | B5: Tariq | E5: D0004OB1 | F5: Harbans Pura | G5: Harbans Pura | H5: Monday
A6: 2 | B6: Azam | E6: D0004OB1 | G6: Jallo | H6: Tuesday
A7: 3 | B7: Sohail | E7: D0004OB1 | G7: Pir Naseer | H7: Wednesday
A8: 4 | B8: Waseem | E8: D0004OB1 | G8: Altuf Colony | H8: Thursday
A9: 5 | B9: Adeel | E9: D0004OB1 | G9: Chungi Dugech | H9: Friday
A10: 6 | B10: Tahir | E10: D0004OB1 | G10: Bahar Shah Road | H10: Saturday
A11: 7 | B11: Amjad | E11: D0004OB2 | F11: Taj Pura Canal Road | G11: Mughal Pura | H11: Monday
A12: 8 | B12: Adil | E12: D0004OB2 | G12: Ghaziabad | H12: Tuesday
A13: 9 | B13: Murtaza | E13: D0004OB2 | G13: Taj Pura Scheem | H13: Wednesday
A14: 10 | E14: D0004OB2 | G14: Taj Bagh | H14: Thursday
E15: D0004OB2 | G15: Pepsi Road | H15: Friday
E16: D0004OB2 | G16: Al-Fasail Town | H16: Saturday
E17: D0004OB3 | F17: Dhuram Pura | G17: DHARAMPURA | H17: Monday
E18: D0004OB3 | G18: REHMAT COLONY | H18: Tuesday
E19: D0004OB3 | G19: Upper Mall | H19: Wednesday
E20: D0004OB3 | G20: Saddar | H20: Thursday
E21: D0004OB3 | G21: Cantt | H21: Friday
E22: D0004OB3 | G22: Cavalary Ground | H22: Saturday
E23: D0004OB4 | F23: Bedian Road | G23: Nadirabad | H23: Monday
E24: D0004OB4 | G24: Bedian Road | H24: Tuesday
E25: D0004OB4 | G25: Shah Khawer Town | H25: Wednesday
E26: D0004OB4 | G26: Al Falah Town | H26: Thursday
E27: D0004OB4 | G27: Air Port Road | H27: Friday
E28: D0004OB4 | G28: Govawa Pind | H28: Saturday
E29: D0004OB5 | F29: Barki | G29: Green city | H29: Monday
E30: D0004OB5 | G30: Paragone City | H30: Tuesday
E31: D0004OB5 | G31: DHA # 4 | H31: Wednesday
E32: D0004OB5 | G32: Barki Road | H32: Thursday
E33: D0004OB5 | G33: Hudiara | H33: Friday
E34: D0004OB5 | G34: DHA # 5 | H34: Saturday
E35: D0004OB6 | F35: Gulberg | G35: Gulberg | H35: Monday
E36: D0004OB6 | G36: Libirty Market | H36: Tuesday
E37: D0004OB6 | G37: Ghalib Market | H37: Wednesday
E38: D0004OB6 | G38: Naseeranad | H38: Thursday
E39: D0004OB6 | G39: Firdous Market | H39: Friday
E40: D0004OB6 | G40: Kalama Chowk | H40: Saturday
E41: D0004OB7 | F41: Walton Road | G41: Gulbahar Colony | H41: Monday
E42: D0004OB7 | G42: Rifflr Range Road | H42: Tuesday
E43: D0004OB7 | G43: Peer Colony | H43: Wednesday
...
