Workbook

Sheet SKU Details
V2: 0.18
A4: S# | B4: Code | D4: SKU | E4: SKUs Description | F4: Unit | H4: Retail Price | J4: TP Incl. | L4: TP Excl. | N4: Dist Margin | P4: Trade Offre | R4: Stale | T4: Ex-Fac | V4: S.Tax | X4: Dist. Price
B5: Bar | C5: SKU | F5: Gm | G5: CTN | H5: Ctn | I5: Pk | J5: Ctn | K5: Pk | L5: Ctn | M5: Pk | N5: 0.19 | O5: Amount | P5: 0.04 | Q5: Amount | R5: 0.005 | S5: Amount | T5: Ctn | U5: Pk | V5: Ctn | W5: Pk | X5: Ctn | Y5: Pk | AA5: Weight/ctn
A6: 1 | C6: CCN | D6: BCN | E6: Meat Masala | F6: 70 | G6: 40 | H6: =I6*G6 -> 2600 | I6: 65 | J6: =K6*G6 -> 2560.17 | K6: =M6*1.22 -> 64.00425 | L6: 2098.5 | M6: =L6/G6 -> 52.4625 | N6: 0.19 | O6: =N6*M6 -> 9.967875 | Q6: =P6*M6 -> 0 | S6: =R6*M6 -> 0 | T6: =U6*G6 -> 1699.785 | U6: =M6-O6-Q6-S6 -> 42.494625 | V6: =T6*$V$2 -> 305.9613 | W6: =U6*$V$2 -> 7.6490325 | X6: =T6+V6 -> 2005.7463 | Y6: =U6+W6 -> 50.143657 | AA6: =(F6*G6)/1000 -> 2.8
A7: =+A6+1 -> 2 | C7: VTN | D7: VTN | E7: Lemon Tarka | F7: 70 | G7: 40 | H7: =I7*G7 -> 2600 | I7: 65 | J7: =K7*G7 -> 2560.17 | K7: =M7*1.22 -> 64.00425 | L7: 2098.5 | M7: =L7/G7 -> 52.4625 | N7: =+N6 -> 0.19 | O7: =N7*M7 -> 9.967875 | Q7: =P7*M7 -> 0 | S7: =R7*M7 -> 0 | T7: =U7*G7 -> 1699.785 | U7: =M7-O7-Q7-S7 -> 42.494625 | V7: =T7*$V$2 -> 305.9613 | W7: =U7*$V$2 -> 7.6490325 | X7: =T7+V7 -> 2005.7463 | Y7: =U7+W7 -> 50.143657 | AA7: =(F7*G7)/1000 -> 2.8
A8: =+A7+1 -> 3 | C8: BCN | D8: CCN | E8: Chicken Chatkhara | F8: 70 | G8: 40 | H8: =I8*G8 -> 2600 | I8: 65 | J8: =K8*G8 -> 2560.17 | K8: =M8*1.22 -> 64.00425 | L8: 2098.5 | M8: =L8/G8 -> 52.4625 | N8: =+N7 -> 0.19 | O8: =N8*M8 -> 9.967875 | Q8: =P8*M8 -> 0 | S8: =R8*M8 -> 0 | T8: =U8*G8 -> 1699.785 | U8: =M8-O8-Q8-S8 -> 42.494625 | V8: =T8*$V$2 -> 305.9613 | W8: =U8*$V$2 -> 7.6490325 | X8: =T8+V8 -> 2005.7463 | Y8: =U8+W8 -> 50.143657 | AA8: =(F8*G8)/1000 -> 2.8
A9: =+A8+1 -> 4 | C9: CCNJ | D9: BCNJ | E9: Meat Masala (Jumbo) | F9: 120 | G9: 40 | H9: =I9*G9 -> 3600 | I9: 90 | J9: =K9*G9 -> 3544.832 | K9: =M9*1.22 -> 88.6208 | L9: 2905.6 | M9: =L9/G9 -> 72.64 | N9: =+N8 -> 0.19 | O9: =N9*M9 -> 13.8016 | Q9: =P9*M9 -> 0 | S9: =R9*M9 -> 0 | T9: =U9*G9 -> 2353.536 | U9: =M9-O9-Q9-S9 -> 58.8384 | V9: =T9*$V$2 -> 423.63648 | W9: =U9*$V$2 -> 10.590912 | X9: =T9+V9 -> 2777.1725 | Y9: =U9+W9 -> 69.429312 | AA9: =(F9*G9)/1000 -> 4.8
A10: =+A9+1 -> 5 | C10: VTNJ | D10: VTNJ | E10: Lemon Tarka (Jumbo) | F10: 120 | G10: 40 | H10: =I10*G10 -> 3600 | I10: 90 | J10: =K10*G10 -> 3544.832 | K10: =M10*1.22 -> 88.6208 | L10: 2905.6 | M10: =L10/G10 -> 72.64 | N10: =+N9 -> 0.19 | O10: =N10*M10 -> 13.8016 | Q10: =P10*M10 -> 0 | S10: =R10*M10 -> 0 | T10: =U10*G10 -> 2353.536 | U10: =M10-O10-Q10-S10 -> 58.8384 | V10: =T10*$V$2 -> 423.63648 | W10: =U10*$V$2 -> 10.590912 | X10: =T10+V10 -> 2777.1725 | Y10: =U10+W10 -> 69.429312 | AA10: =(F10*G10)/1000 -> 4.8
A11: =+A10+1 -> 6 | C11: BCNJ | D11: CCNJ | E11: Chicken Chatkhara (Jumbo) | F11: 120 | G11: 40 | H11: =I11*G11 -> 3600 | I11: 90 | J11: =K11*G11 -> 3544.832 | K11: =M11*1.22 -> 88.6208 | L11: 2905.6 | M11: =L11/G11 -> 72.64 | N11: =+N10 -> 0.19 | O11: =N11*M11 -> 13.8016 | Q11: =P11*M11 -> 0 | S11: =R11*M11 -> 0 | T11: =U11*G11 -> 2353.536 | U11: =M11-O11-Q11-S11 -> 58.8384 | V11: =T11*$V$2 -> 423.63648 | W11: =U11*$V$2 -> 10.590912 | X11: =T11+V11 -> 2777.1725 | Y11: =U11+W11 -> 69.429312 | AA11: =(F11*G11)/1000 -> 4.8
A12: =+A11+1 -> 7 | C12: CCE | D12: CCE | E12: Chicken Chatkhara (ECO) | F12: 60 | G12: 40 | H12: =I12*G12 -> 2000 | I12: 50 | J12: =K12*G12 -> 1914.424 | K12: =M12*1.22 -> 47.8606 | L12: 1569.2 | M12: =L12/G12 -> 39.23 | N12: 0.115 | O12: =N12*M12 -> 4.51145 | Q12: =P12*M12 -> 0 | S12: =R12*M12 -> 0 | T12: =U12*G12 -> 1388.742 | U12: =M12-O12-Q12-S12 -> 34.71855 | V12: =T12*$V$2 -> 249.97356 | W12: =U12*$V$2 -> 6.249339 | X12: =T12+V12 -> 1638.7156 | Y12: =U12+W12 -> 40.967889 | AA12: =(F12*G12)/1000 -> 2.4
A13: =+A12+1 -> 8 | C13: VTE | D13: VTE | E13: Lemon Tarka (ECO) | F13: 60 | G13: 40 | H13: =I13*G13 -> 2000 | I13: 50 | J13: =K13*G13 -> 1914.424 | K13: =M13*1.22 -> 47.8606 | L13: 1569.2 | M13: =L13/G13 -> 39.23 | N13: =+N12 -> 0.115 | O13: =N13*M13 -> 4.51145 | Q13: =P13*M13 -> 0 | S13: =R13*M13 -> 0 | T13: =U13*G13 -> 1388.742 | U13: =M13-O13-Q13-S13 -> 34.71855 | V13: =T13*$V$2 -> 249.97356 | W13: =U13*$V$2 -> 6.249339 | X13: =T13+V13 -> 1638.7156 | Y13: =U13+W13 -> 40.967889 | AA13: =(F13*G13)/1000 -> 2.4
A14: =+A13+1 -> 9 | C14: BCE | D14: BCE | E14: Meat Masala (ECO) | F14: 60 | G14: 40 | H14: =I14*G14 -> 2000 | I14: 50 | J14: =K14*G14 -> 1914.424 | K14: =M14*1.22 -> 47.8606 | L14: 1569.2 | M14: =L14/G14 -> 39.23 | N14: =+N13 -> 0.115 | O14: =N14*M14 -> 4.51145 | Q14: =P14*M14 -> 0 | S14: =R14*M14 -> 0 | T14: =U14*G14 -> 1388.742 | U14: =M14-O14-Q14-S14 -> 34.71855 | V14: =T14*$V$2 -> 249.97356 | W14: =U14*$V$2 -> 6.249339 | X14: =T14+V14 -> 1638.7156 | Y14: =U14+W14 -> 40.967889 | AA14: =(F14*G14)/1000 -> 2.4
A15: =+A14+1 -> 10
A16: =+A15+1 -> 11
A17: =+A16+1 -> 12
A18: =+A17+1 -> 13
A19: =+A18+1 -> 14
A20: =+A19+1 -> 15
A22: =+A20+1 -> 16
A23: =+A22+1 -> 17
A24: =+A23+1 -> 18
A25: =+A24+1 -> 19
A26: =+A25+1 -> 20
A27: =+A26+1 -> 21
A28: =+A27+1 -> 22
A29: =+A28+1 -> 23
A30: =+A29+1 -> 24
A31: =+A30+1 -> 25
A32: =+A31+1 -> 26
A33: =+A32+1 -> 27
A34: =+A33+1 -> 28
A36: =+A34+1 -> 29
A37: =+A36+1 -> 30
A38: =+A37+1 -> 31
A39: =+A38+1 -> 32
A40: =+A39+1 -> 33
A41: =+A40+1 -> 34
A42: =+A41+1 -> 35
A43: =+A42+1 -> 36
A44: =+A43+1 -> 37
...

Sheet PO
B2: Order Format | J2: Total CTN | L2: =SUM(H13:H22) -> 1000
C3: Distributor Name | E3: Elite Marketing Lahore | J3: Net Amount | L3: =SUM(J13:J22) -> 2353536
C4: Order Date | E4: =TODAY() -> 46302 | J4: GST 18% | L4: =SUM(L13:L19) -> 549152.54
C5: Order Delivery Date | E5: =+E4+1 -> 46303 | J5: Deposit Amount | L5: =L4+L3 -> 2902688.5
C6: Order No # | E6: 4th | J6: Adv.Tax | L6: =L5*0.1% -> 2902.6885
J7: Ledger Balance
J8: Balance | L8: =+L5+L6 -> 2905591.2
J9: 0.6 | L9: =L8*J9 -> 1743354.7
J10: 0.4 | L10: =L8*J10 -> 1162236.5
A12: BMS Code | B12: BMS Code | C12: SKU Description | D12: GM | E12: Packs/ Ctn | F12: Retail Price/Unit | G12: Price/ CTN | H12: Order Quantity (Cartons) | J12: Amount | L12: GST %
B13: BCN | C13: =VLOOKUP(B13,'SKU Details'!D6:AA66,2,0) -> Meat Masala | D13: =VLOOKUP($B13,'SKU Details'!D6:Y58,3,0) -> 70 | E13: =VLOOKUP($B13,'SKU Details'!D6:Y58,4,0) -> 40 | F13: =VLOOKUP($B13,'SKU Details'!D6:Y58,6,0) -> 65 | G13: =VLOOKUP($B13,'SKU Details'!D6:Y58,17,0) -> 1699.785 | J13: =(H13*G13) -> 0 | L13: =+P13 -> 0 | O13: =+F13-F13/1.18 -> 9.9152542 | P13: =+O13*Q13 -> 0 | Q13: =+E13*H13 -> 0
B14: VTN | C14: =VLOOKUP(B14,'SKU Details'!D7:AA67,2,0) -> Lemon Tarka | D14: =VLOOKUP($B14,'SKU Details'!D7:Y59,3,0) -> 70 | E14: =VLOOKUP($B14,'SKU Details'!D7:Y59,4,0) -> 40 | F14: =VLOOKUP($B14,'SKU Details'!D7:Y59,6,0) -> 65 | G14: =VLOOKUP($B14,'SKU Details'!D7:Y59,17,0) -> 1699.785 | J14: =(H14*G14) -> 0 | L14: =+P14 -> 0 | O14: =+F14-F14/1.18 -> 9.9152542 | P14: =+O14*Q14 -> 0 | Q14: =+E14*H14 -> 0
B15: CCN | C15: =VLOOKUP(B15,'SKU Details'!D8:AA68,2,0) -> Chicken Chatkhara | D15: =VLOOKUP($B15,'SKU Details'!D8:Y60,3,0) -> 70 | E15: =VLOOKUP($B15,'SKU Details'!D8:Y60,4,0) -> 40 | F15: =VLOOKUP($B15,'SKU Details'!D8:Y60,6,0) -> 65 | G15: =VLOOKUP($B15,'SKU Details'!D8:Y60,17,0) -> 1699.785 | J15: =(H15*G15) -> 0 | L15: =+P15 -> 0 | O15: =+F15-F15/1.18 -> 9.9152542 | P15: =+O15*Q15 -> 0 | Q15: =+E15*H15 -> 0
B16: BCNJ | C16: =VLOOKUP(B16,'SKU Details'!D9:AA69,2,0) -> Meat Masala (Jumbo) | D16: =VLOOKUP($B16,'SKU Details'!D9:Y61,3,0) -> 120 | E16: =VLOOKUP($B16,'SKU Details'!D9:Y61,4,0) -> 40 | F16: =VLOOKUP($B16,'SKU Details'!D9:Y61,6,0) -> 90 | G16: =VLOOKUP($B16,'SKU Details'!D9:Y61,17,0) -> 2353.536 | H16: 350 | J16: =(H16*G16) -> 823737.6 | L16: =+P16 -> 192203.39 | O16: =+F16-F16/1.18 -> 13.728814 | P16: =+O16*Q16 -> 192203.39 | Q16: =+E16*H16 -> 14000
B17: VTNJ | C17: =VLOOKUP(B17,'SKU Details'!D10:AA70,2,0) -> Lemon Tarka (Jumbo) | D17: =VLOOKUP($B17,'SKU Details'!D10:Y62,3,0) -> 120 | E17: =VLOOKUP($B17,'SKU Details'!D10:Y62,4,0) -> 40 | F17: =VLOOKUP($B17,'SKU Details'!D10:Y62,6,0) -> 90 | G17: =VLOOKUP($B17,'SKU Details'!D10:Y62,17,0) -> 2353.536 | H17: 300 | J17: =(H17*G17) -> 706060.8 | L17: =+P17 -> 164745.76 | O17: =+F17-F17/1.18 -> 13.728814 | P17: =+O17*Q17 -> 164745.76 | Q17: =+E17*H17 -> 12000
B18: CCNJ | C18: =VLOOKUP(B18,'SKU Details'!D11:AA71,2,0) -> Chicken Chatkhara (Jumbo) | D18: =VLOOKUP($B18,'SKU Details'!D11:Y63,3,0) -> 120 | E18: =VLOOKUP($B18,'SKU Details'!D11:Y63,4,0) -> 40 | F18: =VLOOKUP($B18,'SKU Details'!D11:Y63,6,0) -> 90 | G18: =VLOOKUP($B18,'SKU Details'!D11:Y63,17,0) -> 2353.536 | H18: 350 | J18: =(H18*G18) -> 823737.6 | L18: =+P18 -> 192203.39 | O18: =+F18-F18/1.18 -> 13.728814 | P18: =+O18*Q18 -> 192203.39 | Q18: =+E18*H18 -> 14000
B19: CCE | C19: =VLOOKUP(B19,'SKU Details'!D12:AA72,2,0) -> Chicken Chatkhara (ECO) | D19: =VLOOKUP($B19,'SKU Details'!D12:Y64,3,0) -> 60 | E19: =VLOOKUP($B19,'SKU Details'!D12:Y64,4,0) -> 40 | F19: =VLOOKUP($B19,'SKU Details'!D12:Y64,6,0) -> 50 | G19: =VLOOKUP($B19,'SKU Details'!D12:Y64,17,0) -> 1388.742 | J19: =(H19*G19) -> 0 | L19: =+P19 -> 0 | O19: =+F19-F19/1.18 -> 7.6271186 | P19: =+O19*Q19 -> 0 | Q19: =+E19*H19 -> 0
B20: VTE | C20: =VLOOKUP(B20,'SKU Details'!D13:AA73,2,0) -> Lemon Tarka (ECO) | D20: =VLOOKUP($B20,'SKU Details'!D13:Y65,3,0) -> 60 | E20: =VLOOKUP($B20,'SKU Details'!D13:Y65,4,0) -> 40 | F20: =VLOOKUP($B20,'SKU Details'!D13:Y65,6,0) -> 50 | G20: =VLOOKUP($B20,'SKU Details'!D13:Y65,17,0) -> 1388.742 | J20: =(H20*G20) -> 0 | L20: =(VLOOKUP(B20,'SKU Details'!D13:AA65,24,0)/1000)*H20 -> 0
B21: BCE | C21: =VLOOKUP(B21,'SKU Details'!D14:AA74,2,0) -> Meat Masala (ECO) | D21: =VLOOKUP($B21,'SKU Details'!D14:Y66,3,0) -> 60 | E21: =VLOOKUP($B21,'SKU Details'!D14:Y66,4,0) -> 40 | F21: =VLOOKUP($B21,'SKU Details'!D14:Y66,6,0) -> 50 | G21: =VLOOKUP($B21,'SKU Details'!D14:Y66,17,0) -> 1388.742 | J21: =(H21*G21) -> 0 | L21: =(VLOOKUP(B21,'SKU Details'!D14:AA66,24,0)/1000)*H21 -> 0
E22: =IFERROR(VLOOKUP(B22,'SKU Details'!A:F,3,0),"") | G22: =IFERROR(VLOOKUP(B22,'SKU Details'!A:F,4,0),"")

Sheet PO 
B2: Order Format | J2: Total CTN | L2: =SUM(H11:H20) -> 0
C3: Distributor Name | E3: Ayyan Gujrat | J3: Net Amount | L3: =SUM(J11:J20) -> 0
C4: Order Date | J4: GST 18% | L4: =SUM(L11:L17) -> 0
C5: Order Delivery Date | J5: Deposit Amount | L5: =L4+L3 -> 0
C6: Order No # | J6: Adv.Tax | L6: =L5*0.1% -> 0
J7: Ledger Balance
J8: Balance | L8: =+L5+L6 -> 0
A10: BMS Code | B10: BMS Code | C10: SKU Description | D10: GM | E10: Packs/ Ctn | F10: Retail Price/Unit | G10: Price/ CTN | H10: Order Quantity (Cartons) | J10: Amount | L10: GST %
B11: BCN | C11: =VLOOKUP(B11,'SKU Details'!D6:AA66,2,0) -> Meat Masala | D11: =VLOOKUP($B11,'SKU Details'!D6:Y58,3,0) -> 70 | E11: =VLOOKUP($B11,'SKU Details'!D6:Y58,4,0) -> 40 | F11: =VLOOKUP($B11,'SKU Details'!D6:Y58,6,0) -> 65 | G11: =VLOOKUP($B11,'SKU Details'!D6:Y58,17,0) -> 1699.785 | J11: =(H11*G11) -> 0 | L11: =+P11 -> 0 | O11: =+F11-F11/1.18 -> 9.9152542 | P11: =+O11*Q11 -> 0 | Q11: =+E11*H11 -> 0
B12: VTN | C12: =VLOOKUP(B12,'SKU Details'!D7:AA67,2,0) -> Lemon Tarka | D12: =VLOOKUP($B12,'SKU Details'!D7:Y59,3,0) -> 70 | E12: =VLOOKUP($B12,'SKU Details'!D7:Y59,4,0) -> 40 | F12: =VLOOKUP($B12,'SKU Details'!D7:Y59,6,0) -> 65 | G12: =VLOOKUP($B12,'SKU Details'!D7:Y59,17,0) -> 1699.785 | J12: =(H12*G12) -> 0 | L12: =+P12 -> 0 | O12: =+F12-F12/1.18 -> 9.9152542 | P12: =+O12*Q12 -> 0 | Q12: =+E12*H12 -> 0
B13: CCN | C13: =VLOOKUP(B13,'SKU Details'!D8:AA68,2,0) -> Chicken Chatkhara | D13: =VLOOKUP($B13,'SKU Details'!D8:Y60,3,0) -> 70 | E13: =VLOOKUP($B13,'SKU Details'!D8:Y60,4,0) -> 40 | F13: =VLOOKUP($B13,'SKU Details'!D8:Y60,6,0) -> 65 | G13: =VLOOKUP($B13,'SKU Details'!D8:Y60,17,0) -> 1699.785 | J13: =(H13*G13) -> 0 | L13: =+P13 -> 0 | O13: =+F13-F13/1.18 -> 9.9152542 | P13: =+O13*Q13 -> 0 | Q13: =+E13*H13 -> 0
B14: BCNJ | C14: =VLOOKUP(B14,'SKU Details'!D9:AA69,2,0) -> Meat Masala (Jumbo) | D14: =VLOOKUP($B14,'SKU Details'!D9:Y61,3,0) -> 120 | E14: =VLOOKUP($B14,'SKU Details'!D9:Y61,4,0) -> 40 | F14: =VLOOKUP($B14,'SKU Details'!D9:Y61,6,0) -> 90 | G14: =VLOOKUP($B14,'SKU Details'!D9:Y61,17,0) -> 2353.536 | J14: =(H14*G14) -> 0 | L14: =+P14 -> 0 | O14: =+F14-F14/1.18 -> 13.728814 | P14: =+O14*Q14 -> 0 | Q14: =+E14*H14 -> 0
B15: VTNJ | C15: =VLOOKUP(B15,'SKU Details'!D10:AA70,2,0) -> Lemon Tarka (Jumbo) | D15: =VLOOKUP($B15,'SKU Details'!D10:Y62,3,0) -> 120 | E15: =VLOOKUP($B15,'SKU Details'!D10:Y62,4,0) -> 40 | F15: =VLOOKUP($B15,'SKU Details'!D10:Y62,6,0) -> 90 | G15: =VLOOKUP($B15,'SKU Details'!D10:Y62,17,0) -> 2353.536 | J15: =(H15*G15) -> 0 | L15: =+P15 -> 0 | O15: =+F15-F15/1.18 -> 13.728814 | P15: =+O15*Q15 -> 0 | Q15: =+E15*H15 -> 0
B16: CCNJ | C16: =VLOOKUP(B16,'SKU Details'!D11:AA71,2,0) -> Chicken Chatkhara (Jumbo) | D16: =VLOOKUP($B16,'SKU Details'!D11:Y63,3,0) -> 120 | E16: =VLOOKUP($B16,'SKU Details'!D11:Y63,4,0) -> 40 | F16: =VLOOKUP($B16,'SKU Details'!D11:Y63,6,0) -> 90 | G16: =VLOOKUP($B16,'SKU Details'!D11:Y63,17,0) -> 2353.536 | J16: =(H16*G16) -> 0 | L16: =+P16 -> 0 | O16: =+F16-F16/1.18 -> 13.728814 | P16: =+O16*Q16 -> 0 | Q16: =+E16*H16 -> 0
B17: CCE | C17: =VLOOKUP(B17,'SKU Details'!D12:AA72,2,0) -> Chicken Chatkhara (ECO) | D17: =VLOOKUP($B17,'SKU Details'!D12:Y64,3,0) -> 60 | E17: =VLOOKUP($B17,'SKU Details'!D12:Y64,4,0) -> 40 | F17: =VLOOKUP($B17,'SKU Details'!D12:Y64,6,0) -> 50 | G17: =VLOOKUP($B17,'SKU Details'!D12:Y64,17,0) -> 1388.742 | J17: =(H17*G17) -> 0 | L17: =+P17 -> 0 | O17: =+F17-F17/1.18 -> 7.6271186 | P17: =+O17*Q17 -> 0 | Q17: =+E17*H17 -> 0
B18: VTE | C18: =VLOOKUP(B18,'SKU Details'!D13:AA73,2,0) -> Lemon Tarka (ECO) | D18: =VLOOKUP($B18,'SKU Details'!D13:Y65,3,0) -> 60 | E18: =VLOOKUP($B18,'SKU Details'!D13:Y65,4,0) -> 40 | F18: =VLOOKUP($B18,'SKU Details'!D13:Y65,6,0) -> 50 | G18: =VLOOKUP($B18,'SKU Details'!D13:Y65,17,0) -> 1388.742 | J18: =(H18*G18) -> 0 | L18: =(VLOOKUP(B18,'SKU Details'!D13:AA65,24,0)/1000)*H18 -> 0
B19: BCE | C19: =VLOOKUP(B19,'SKU Details'!D14:AA74,2,0) -> Meat Masala (ECO) | D19: =VLOOKUP($B19,'SKU Details'!D14:Y66,3,0) -> 60 | E19: =VLOOKUP($B19,'SKU Details'!D14:Y66,4,0) -> 40 | F19: =VLOOKUP($B19,'SKU Details'!D14:Y66,6,0) -> 50 | G19: =VLOOKUP($B19,'SKU Details'!D14:Y66,17,0) -> 1388.742 | J19: =(H19*G19) -> 0 | L19: =(VLOOKUP(B19,'SKU Details'!D14:AA66,24,0)/1000)*H19 -> 0
E20: =IFERROR(VLOOKUP(B20,'SKU Details'!A:F,3,0),"") | G20: =IFERROR(VLOOKUP(B20,'SKU Details'!A:F,4,0),"")
